Workbook

Sheet ورقة2

Sheet الطفل السليم
A2: مراكزمستشفى شرق جدة | E2: شهر | F2: 1 | G2: عام | H2: 1447 | K2: هـ | P2: مراكزمستشفى شرق جدة | T2: شهر | U2: 2 | V2: عام | W2: 1447 | Z2: هـ | AE2: مراكزمستشفى شرق جدة | AI2: شهر | AJ2: 3 | AK2: عام | AL2: 1447 | AO2: هـ | AT2: مراكزمستشفى شرق جدة | AX2: شهر | AY2: 4 | AZ2: عام | BA2: 1447 | BD2: هـ | BI2: مراكزمستشفى شرق جدة | BM2: شهر | BN2: 5 | BO2: عام | BP2: 1447 | BS2: هـ | BX2: مراكزمستشفى شرق جدة | CB2: شهر | CC2: 6 | CD2: عام | CE2: 1447 | CH2: هـ | CM2: مراكزمستشفى شرق جدة | CQ2: شهر | CR2: 7 | CS2: عام | CT2: 1447 | CW2: هـ | DB2: مراكزمستشفى شرق جدة | DF2: شهر | DG2: 8 | DH2: عام | DI2: 1447 | DL2: هـ | DQ2: مراكزمستشفى شرق جدة | DU2: شهر | DV2: 9 | DW2: عام | DX2: 1447 | EA2: هـ | EF2: مراكزمستشفى شرق جدة | EJ2: شهر | EK2: 10 | EL2: عام | EM2: 1447 | EP2: هـ | EU2: مراكزمستشفى شرق جدة | EY2: شهر | EZ2: 11 | FA2: عام | FB2: 1447 | FE2: هـ | FJ2: مراكزمستشفى شرق جدة | FN2: شهر | FO2: 12 | FP2: عام | FQ2: 1447 | FT2: هـ | FY2: =(FJ2) -> مراكزمستشفى شرق جدة | GE2: عام | GF2: =SUM(FQ2) -> 1447
A3: المركز الصحي | D3: عدد الأطفال المسجلين أقل من عام | E3: التحصينات الأساسية | G3: عدد الأطفال المسجلين أقل من 5 أعوام | H3: عدد من رضعوا طبيعياً | I3: عدد المعرضين للخطر أقل من 5 سنوات | J3: زيارات عيادة الطفل السليم خلال الشهر | K3: وفيات الأطفال | P3: المركز الصحي | S3: عدد الأطفال المسجلين أقل من عام | T3: التحصينات الأساسية | V3: عدد الأطفال المسجلين أقل من 5 أعوام | W3: عدد من رضعوا طبيعياً | X3: عدد المعرضين للخطر أقل من 5 سنوات | Y3: زيارات عيادة الطفل السليم خلال الشهر | Z3: وفيات الأطفال | AE3: المركز الصحي | AH3: عدد الأطفال المسجلين أقل من عام | AI3: التحصينات الأساسية | AK3: عدد الأطفال المسجلين أقل من 5 أعوام | AL3: عدد من رضعوا طبيعياً | AM3: عدد المعرضين للخطر أقل من 5 سنوات | AN3: زيارات عيادة الطفل السليم خلال الشهر | AO3: وفيات الأطفال | AT3: المركز الصحي | AW3: عدد الأطفال المسجلين أقل من عام | AX3: التحصينات الأساسية | AZ3: عدد الأطفال المسجلين أقل من 5 أعوام | BA3: عدد من رضعوا طبيعياً | BB3: عدد المعرضين للخطر أقل من 5 سنوات | BC3: زيارات عيادة الطفل السليم خلال الشهر | BD3: وفيات الأطفال | BI3: المركز الصحي | BL3: عدد الأطفال المسجلين أقل من عام | BM3: التحصينات الأساسية | BO3: عدد الأطفال المسجلين أقل من 5 أعوام | BP3: عدد من رضعوا طبيعياً | BQ3: عدد المعرضين للخطر أقل من 5 سنوات | BR3: زيارات عيادة الطفل السليم خلال الشهر | BS3: وفيات الأطفال | BX3: المركز الصحي | CA3: عدد الأطفال المسجلين أقل من عام | CB3: التحصينات الأساسية | CD3: عدد الأطفال المسجلين أقل من 5 أعوام | CE3: عدد من رضعوا طبيعياً | CF3: عدد المعرضين للخطر أقل من 5 سنوات | CG3: زيارات عيادة الطفل السليم خلال الشهر | CH3: وفيات الأطفال | CM3: المركز الصحي | CP3: عدد الأطفال المسجلين أقل من عام | CQ3: التحصينات الأساسية | CS3: عدد الأطفال المسجلين أقل من 5 أعوام | CT3: عدد من رضعوا طبيعياً | CU3: عدد المعرضين للخطر أقل من 5 سنوات | CV3: زيارات عيادة الطفل السليم خلال الشهر | CW3: وفيات الأطفال | DB3: المركز الصحي | DE3: عدد الأطفال المسجلين أقل من عام | DF3: التحصينات الأساسية | DH3: عدد الأطفال المسجلين أقل من 5 أعوام | DI3: عدد من رضعوا طبيعياً | DJ3: عدد المعرضين للخطر أقل من 5 سنوات | DK3: زيارات عيادة الطفل السليم خلال الشهر | DL3: وفيات الأطفال | DQ3: المركز الصحي | DT3: عدد الأطفال المسجلين أقل من عام | DU3: التحصينات الأساسية | DW3: عدد الأطفال المسجلين أقل من 5 أعوام | DX3: عدد من رضعوا طبيعياً | DY3: عدد المعرضين للخطر أقل من 5 سنوات | DZ3: زيارات عيادة الطفل السليم خلال الشهر | EA3: وفيات الأطفال | EF3: المركز الصحي | EI3: عدد الأطفال المسجلين أقل من عام | EJ3: التحصينات الأساسية | EL3: عدد الأطفال المسجلين أقل من 5 أعوام | EM3: عدد من رضعوا طبيعياً | EN3: عدد المعرضين للخطر أقل من 5 سنوات | EO3: زيارات عيادة الطفل السليم خلال الشهر | EP3: وفيات الأطفال | EU3: المركز الصحي | EX3: عدد الأطفال المسجلين أقل من عام | EY3: التحصينات الأساسية | FA3: عدد الأطفال المسجلين أقل من 5 أعوام | FB3: عدد من رضعوا طبيعياً | FC3: عدد المعرضين للخطر أقل من 5 سنوات | FD3: زيارات عيادة الطفل السليم خلال الشهر | FE3: وفيات الأطفال | FJ3: المركز الصحي | FM3: عدد الأطفال المسجلين أقل من عام | FN3: التحصينات الأساسية | FP3: عدد الأطفال المسجلين أقل من 5 أعوام | FQ3: عدد من رضعوا طبيعياً | FR3: عدد المعرضين للخطر أقل من 5 سنوات | FS3: زيارات عيادة الطفل السليم خلال الشهر | FT3: وفيات الأطفال | FY3: المركز الصحي | FZ3: الجنسية | GA3: الجنس | GB3: عدد الأطفال المسجلين أقل من عام | GC3: التحصينات الأساسية | GE3: عدد الأطفال المسجلين أقل من 5 أعوام | GF3: عدد من رضعوا طبيعياً | GG3: عدد المعرضين للخطر أقل من 5 سنوات | GH3: زيارات عيادة الطفل السليم خلال العام | GI3: وفيات الأطفال
E4: أكلموا التحصينات الأساسية خلال الشهر | F4: بلغ عمرهم 15 شهراً ولم يكملوا التحصينات الأساسية | K4: من الولادة إلى أقل من 7 آيام | L4: من 7 أيام إلى أقل من شهر | M4: من شهر إلى أقل من عام | N4: من عام إلى أقل من 5 سنوات | T4: أكلموا التحصينات الأساسية خلال الشهر | U4: بلغ عمرهم 15 شهراً ولم يكملوا التحصينات الأساسية | Z4: من الولادة إلى أقل من 7 آيام | AA4: من 7 أيام إلى أقل من شهر | AB4: من شهر إلى أقل من عام | AC4: من عام إلى أقل من 5 سنوات | AI4: أكلموا التحصينات الأساسية خلال الشهر | AJ4: بلغ عمرهم 15 شهراً ولم يكملوا التحصينات الأساسية | AO4: من الولادة إلى أقل من 7 آيام | AP4: من 7 أيام إلى أقل من شهر | AQ4: من شهر إلى أقل من عام | AR4: من عام إلى أقل من 5 سنوات | AX4: أكلموا التحصينات الأساسية خلال الشهر | AY4: بلغ عمرهم 15 شهراً ولم يكملوا التحصينات الأساسية | BD4: من الولادة إلى أقل من 7 آيام | BE4: من 7 أيام إلى أقل من شهر | BF4: من شهر إلى أقل من عام | BG4: من عام إلى أقل من 5 سنوات | BM4: أكلموا التحصينات الأساسية خلال الشهر | BN4: بلغ عمرهم 15 شهراً ولم يكملوا التحصينات الأساسية | BS4: من الولادة إلى أقل من 7 آيام | BT4: من 7 أيام إلى أقل من شهر | BU4: من شهر إلى أقل من عام | BV4: من عام إلى أقل من 5 سنوات | CB4: أكلموا التحصينات الأساسية خلال الشهر | CC4: بلغ عمرهم 15 شهراً ولم يكملوا التحصينات الأساسية | CH4: من الولادة إلى أقل من 7 آيام | CI4: من 7 أيام إلى أقل من شهر | CJ4: من شهر إلى أقل من عام | CK4: من عام إلى أقل من 5 سنوات | CQ4: أكلموا التحصينات الأساسية خلال الشهر | CR4: بلغ عمرهم 15 شهراً ولم يكملوا التحصينات الأساسية | CW4: من الولادة إلى أقل من 7 آيام | CX4: من 7 أيام إلى أقل من شهر | CY4: من شهر إلى أقل من عام | CZ4: من عام إلى أقل من 5 سنوات | DF4: أكلموا التحصينات الأساسية خلال الشهر | DG4: بلغ عمرهم 15 شهراً ولم يكملوا التحصينات الأساسية | DL4: من الولادة إلى أقل من 7 آيام | DM4: من 7 أيام إلى أقل من شهر | DN4: من شهر إلى أقل من عام | DO4: من عام إلى أقل من 5 سنوات | DU4: أكلموا التحصينات الأساسية خلال الشهر | DV4: بلغ عمرهم 15 شهراً ولم يكملوا التحصينات الأساسية | EA4: من الولادة إلى أقل من 7 آيام | EB4: من 7 أيام إلى أقل من شهر | EC4: من شهر إلى أقل من عام | ED4: من عام إلى أقل من 5 سنوات | EJ4: أكلموا التحصينات الأساسية خلال الشهر | EK4: بلغ عمرهم 15 شهراً ولم يكملوا التحصينات الأساسية | EP4: من الولادة إلى أقل من 7 آيام | EQ4: من 7 أيام إلى أقل من شهر | ER4: من شهر إلى أقل من عام | ES4: من عام إلى أقل من 5 سنوات | EY4: أكلموا التحصينات الأساسية خلال الشهر | EZ4: بلغ عمرهم 15 شهراً ولم يكملوا التحصينات الأساسية | FE4: من الولادة إلى أقل من 7 آيام | FF4: من 7 أيام إلى أقل من شهر | FG4: من شهر إلى أقل من عام | FH4: من عام إلى أقل من 5 سنوات | FN4: أكلموا التحصينات الأساسية خلال الشهر | FO4: بلغ عمرهم 15 شهراً ولم يكملوا التحصينات الأساسية | FT4: من الولادة إلى أقل من 7 آيام | FU4: من 7 أيام إلى أقل من شهر | FV4: من شهر إلى أقل من عام | FW4: من عام إلى أقل من 5 سنوات | GC4: أكلموا التحصينات الأساسية خلال العام | GD4: بلغ عمرهم 15 شهراً ولم يكملوا التحصينات الأساسية | GI4: من الولادة إلى أقل من 7 آيام | GJ4: من 7 أيام إلى أقل من شهر | GK4: من شهر إلى أقل من عام | GL4: من عام إلى أقل من 5 سنوات
A5: الربيع والتوفيق | B5: سعودي | C5: ذكر | D5: 7 | E5: 3 | F5: 1 | G5: 335 | H5: 1 | I5: 23 | J5: 338 | K5: 0 | L5: 0 | M5: 0 | N5: 0 | P5: الربيع والتوفيق | Q5: سعودي | R5: ذكر | S5: 40 | T5: 45 | U5: 3 | V5: 242 | W5: 12 | X5: 0 | Y5: 74 | Z5: 0 | AA5: 0 | AB5: 0 | AC5: 0 | AE5: الربيع والتوفيق | AF5: سعودي | AG5: ذكر | AH5: 42 | AI5: 72 | AJ5: 0 | AK5: 614 | AL5: 7 | AM5: 0 | AN5: 69 | AO5: 0 | AP5: 0 | AQ5: 0 | AR5: 0 | AT5: الربيع والتوفيق | AU5: سعودي | AV5: ذكر | AW5: 185 | AX5: 32 | AY5: 0 | AZ5: 459 | BA5: 7 | BB5: 31 | BC5: 94 | BD5: 0 | BE5: 0 | BF5: 0 | BG5: 0 | BI5: الربيع والتوفيق | BJ5: سعودي | BK5: ذكر | BL5: 185 | BM5: 32 | BN5: 0 | BO5: 459 | BP5: 7 | BQ5: 31 | BR5: 48 | BS5: 0 | BT5: 0 | BU5: 0 | BV5: 0 | BX5: الربيع والتوفيق | BY5: سعودي | BZ5: ذكر | CA5: 185 | CB5: 44 | CC5: 0 | CD5: 466 | CE5: 0 | CF5: 0 | CG5: 32 | CH5: 0 | CI5: 0 | CJ5: 0 | CK5: 0 | CM5: الربيع والتوفيق | CN5: سعودي | CO5: ذكر | CP5: 26 | CQ5: 26 | CR5: 26 | CS5: 26 | CT5: 26 | CU5: 26 | CV5: 26 | CW5: 0 | CX5: 0 | CY5: 0 | CZ5: 0 | DB5: الربيع والتوفيق | DC5: سعودي | DD5: ذكر | DE5: 190 | DF5: 58 | DG5: 0 | DH5: 557 | DI5: 7 | DJ5: 0 | DK5: 32 | DL5: 0 | DM5: 0 | DN5: 0 | DO5: 0 | DQ5: الربيع والتوفيق | DR5: سعودي | DS5: ذكر | DT5: 88 | DU5: 10 | DV5: 0 | DW5: 350 | DX5: 4 | DY5: 3 | DZ5: 180 | EA5: 0 | EB5: 0 | EC5: 0 | ED5: 0 | EF5: الربيع والتوفيق | EG5: سعودي | EH5: ذكر | EI5: 88 | EJ5: 10 | EK5: 0 | EL5: 350 | EM5: 4 | EN5: 3 | EO5: 500 | EP5: 0 | EQ5: 0 | ER5: 0 | ES5: 0 | EU5: الربيع والتوفيق | EV5: سعودي | EW5: ذكر | EX5: 0 | EY5: 0 | EZ5: 0 | FA5: 0 | FB5: 0 | FC5: 0 | FD5: 0 | FE5: 0 | FF5: 0 | FG5: 0 | FH5: 0 | FJ5: الربيع والتوفيق | FK5: سعودي | FL5: ذكر | FM5: 0 | FN5: 0 | FO5: 0 | FP5: 0 | FQ5: 0 | FR5: 0 | FS5: 0 | FT5: 0 | FU5: 0 | FV5: 0 | FW5: 0 | FY5: =(FJ5) -> الربيع والتوفيق | FZ5: سعودي | GA5: ذكر | GB5: =SUM(FM5) -> 0 | GC5: =(E5+T5+AI5+AX5+BM5+CB5+CQ5+DF5+DU5+EJ5+EY5+FN5) -> 332 | GD5: =(F5+U5+AJ5+AY5+BN5+CC5+CR5+DG5+DV5+EK5+EZ5+FO5) -> 30 | GE5: =SUM(FP5) -> 0 | GF5: =SUM(FQ5) -> 0 | GG5: =SUM(FR5) -> 0 | GH5: =(J5+Y5+AN5+BC5+BR5+CG5+CV5+DK5+DZ5+EO5+FD5+FS5) -> 1393 | GI5: =(K5+Z5+AO5+BD5+BS5+CH5+CW5+DL5+EA5+EP5+FE5+FT5) -> 0 | GJ5: =(L5+AA5+AP5+BE5+BT5+CI5+CX5+DM5+EB5+EQ5+FF5+FU5) -> 0 | GK5: =(M5+AB5+AQ5+BF5+BU5+CJ5+CY5+DN5+EC5+ER5+FG5+FV5) -> 0 | GL5: =(N5+AC5+AR5+BG5+BV5+CK5+CZ5+DO5+ED5+ES5+FH5+FW5) -> 0
C6: أنثى | D6: 5 | E6: 2 | F6: 6 | G6: 333 | H6: 2 | I6: 18 | J6: 305 | K6: 0 | L6: 0 | M6: 0 | N6: 0 | R6: أنثى | S6: 52 | T6: 61 | U6: 1 | V6: 286 | W6: 9 | X6: 0 | Y6: 96 | Z6: 0 | AA6: 0 | AB6: 0 | AC6: 0 | AG6: أنثى | AH6: 46 | AI6: 56 | AJ6: 0 | AK6: 513 | AL6: 9 | AM6: 0 | AN6: 55 | AO6: 0 | AP6: 0 | AQ6: 0 | AR6: 0 | AV6: أنثى | AW6: 238 | AX6: 42 | AY6: 0 | AZ6: 672 | BA6: 13 | BB6: 43 | BC6: 116 | BD6: 0 | BE6: 0 | BF6: 0 | BG6: 0 | BK6: أنثى | BL6: 238 | BM6: 42 | BN6: 0 | BO6: 672 | BP6: 13 | BQ6: 43 | BR6: 45 | BS6: 0 | BT6: 0 | BU6: 0 | BV6: 0 | BZ6: أنثى | CA6: 238 | CB6: 39 | CC6: 0 | CD6: 680 | CE6: 0 | CF6: 0 | CG6: 42 | CH6: 0 | CI6: 0 | CJ6: 0 | CK6: 0 | CO6: أنثى | CP6: 31 | CQ6: 71 | CR6: 0 | CS6: 260 | CT6: 7 | CU6: 9 | CV6: 58 | CW6: 0 | CX6: 0 | CY6: 0 | CZ6: 0 | DD6: أنثى | DE6: 172 | DF6: 53 | DG6: 0 | DH6: 652 | DI6: 8 | DJ6: 0 | DK6: 42 | DL6: 0 | DM6: 0 | DN6: 0 | DO6: 0 | DS6: أنثى | DT6: 12 | DU6: 5 | DV6: 0 | DW6: 322 | DX6: 2 | DY6: 5 | DZ6: 164 | EA6: 0 | EB6: 0 | EC6: 0 | ED6: 0 | EH6: أنثى | EI6: 12 | EJ6: 5 | EK6: 0 | EL6: 322 | EM6: 2 | EN6: 5 | EO6: 216 | EP6: 0 | EQ6: 0 | ER6: 0 | ES6: 0 | EW6: أنثى | EX6: 0 | EY6: 0 | EZ6: 0 | FA6: 0 | FB6: 0 | FC6: 0 | FD6: 0 | FE6: 0 | FF6: 0 | FG6: 0 | FH6: 0 | FL6: أنثى | FM6: 0 | FN6: 0 | FO6: 0 | FP6: 0 | FQ6: 0 | FR6: 0 | FS6: 0 | FT6: 0 | FU6: 0 | FV6: 0 | FW6: 0 | GA6: أنثى | GB6: =SUM(FM6) -> 0 | GC6: =(E6+T6+AI6+AX6+BM6+CB6+CQ6+DF6+DU6+EJ6+EY6+FN6) -> 376 | GD6: =(F6+U6+AJ6+AY6+BN6+CC6+CR6+DG6+DV6+EK6+EZ6+FO6) -> 7 | GE6: =SUM(FP6) -> 0 | GF6: =SUM(FQ6) -> 0 | GG6: =SUM(FR6) -> 0 | GH6: =(J6+Y6+AN6+BC6+BR6+CG6+CV6+DK6+DZ6+EO6+FD6+FS6) -> 1139 | GI6: =(K6+Z6+AO6+BD6+BS6+CH6+CW6+DL6+EA6+EP6+FE6+FT6) -> 0 | GJ6: =(L6+AA6+AP6+BE6+BT6+CI6+CX6+DM6+EB6+EQ6+FF6+FU6) -> 0 | GK6: =(M6+AB6+AQ6+BF6+BU6+CJ6+CY6+DN6+EC6+ER6+FG6+FV6) -> 0 | GL6: =(N6+AC6+AR6+BG6+BV6+CK6+CZ6+DO6+ED6+ES6+FH6+FW6) -> 0
B7: غير | C7: ذكر | D7: 0 | E7: 0 | F7: 0 | G7: 0 | H7: 0 | I7: 0 | J7: 0 | K7: 0 | L7: 0 | M7: 0 | N7: 0 | Q7: غير | R7: ذكر | S7: 17 | T7: 27 | U7: 5 | V7: 14 | W7: 6 | X7: 0 | Y7: 12 | Z7: 0 | AA7: 0 | AB7: 0 | AC7: 0 | AF7: غير | AG7: ذكر | AH7: 0 | AI7: 0 | AJ7: 0 | AK7: 0 | AL7: 0 | AM7: 0 | AN7: 29 | AO7: 0 | AP7: 0 | AQ7: 0 | AR7: 0 | AU7: غير | AV7: ذكر | AW7: 0 | AX7: 0 | AY7: 0 | AZ7: 0 | BA7: 0 | BB7: 0 | BC7: 0 | BD7: 0 | BE7: 0 | BF7: 0 | BG7: 0 | BJ7: غير | BK7: ذكر | BL7: 0 | BM7: 0 | BN7: 0 | BO7: 0 | BP7: 0 | BQ7: 0 | BR7: 0 | BS7: 0 | BT7: 0 | BU7: 0 | BV7: 0 | BY7: غير | BZ7: ذكر | CA7: 0 | CB7: 0 | CC7: 0 | CD7: 0 | CE7: 0 | CF7: 0 | CG7: 14 | CH7: 0 | CI7: 0 | CJ7: 0 | CK7: 0 | CN7: غير | CO7: ذكر | CP7: 12 | CQ7: 13 | CR7: 1 | CS7: 21 | CT7: 1 | CU7: 0 | CV7: 23 | CW7: 0 | CX7: 0 | CY7: 0 | CZ7: 0 | DC7: غير | DD7: ذكر | DE7: 0 | DF7: 0 | DG7: 0 | DH7: 0 | DI7: 0 | DJ7: 0 | DK7: 14 | DL7: 0 | DM7: 0 | DN7: 0 | DO7: 0 | DR7: غير | DS7: ذكر | DT7: 4 | DU7: 1 | DV7: 0 | DW7: 0 | DX7: 0 | DY7: 0 | DZ7: 0 | EA7: 0 | EB7: 0 | EC7: 0 | ED7: 0 | EG7: غير | EH7: ذكر | EI7: 4 | EJ7: 1 | EK7: 0 | EL7: 0 | EM7: 0 | EN7: 0 | EO7: 59 | EP7: 0 | EQ7: 0 | ER7: 0 | ES7: 0 | EV7: غير | EW7: ذكر | EX7: 0 | EY7: 0 | EZ7: 0 | FA7: 0 | FB7: 0 | FC7: 0 | FD7: 0 | FE7: 0 | FF7: 0 | FG7: 0 | FH7: 0 | FK7: غير | FL7: ذكر | FM7: 0 | FN7: 0 | FO7: 0 | FP7: 0 | FQ7: 0 | FR7: 0 | FS7: 0 | FT7: 0 | FU7: 0 | FV7: 0 | FW7: 0 | FZ7: غير | GA7: ذكر | GB7: =SUM(FM7) -> 0 | GC7: =(E7+T7+AI7+AX7+BM7+CB7+CQ7+DF7+DU7+EJ7+EY7+FN7) -> 42 | GD7: =(F7+U7+AJ7+AY7+BN7+CC7+CR7+DG7+DV7+EK7+EZ7+FO7) -> 6 | GE7: =SUM(FP7) -> 0 | GF7: =SUM(FQ7) -> 0 | GG7: =SUM(FR7) -> 0 | GH7: =(J7+Y7+AN7+BC7+BR7+CG7+CV7+DK7+DZ7+EO7+FD7+FS7) -> 151 | GI7: =(K7+Z7+AO7+BD7+BS7+CH7+CW7+DL7+EA7+EP7+FE7+FT7) -> 0 | GJ7: =(L7+AA7+AP7+BE7+BT7+CI7+CX7+DM7+EB7+EQ7+FF7+FU7) -> 0 | GK7: =(M7+AB7+AQ7+BF7+BU7+CJ7+CY7+DN7+EC7+ER7+FG7+FV7) -> 0 | GL7: =(N7+AC7+AR7+BG7+BV7+CK7+CZ7+DO7+ED7+ES7+FH7+FW7) -> 0
B8: سعودي | C8: أنثى | D8: 0 | E8: 0 | F8: 0 | G8: 0 | H8: 0 | I8: 0 | J8: 0 | K8: 0 | L8: 0 | M8: 0 | N8: 0 | Q8: سعودي | R8: أنثى | S8: 23 | T8: 32 | U8: 3 | V8: 21 | W8: 8 | X8: 0 | Y8: 18 | Z8: 0 | AA8: 0 | AB8: 0 | AC8: 0 | AF8: سعودي | AG8: أنثى | AH8: 0 | AI8: 0 | AJ8: 0 | AK8: 0 | AL8: 0 | AM8: 0 | AN8: 47 | AO8: 0 | AP8: 0 | AQ8: 0 | AR8: 0 | AU8: سعودي | AV8: أنثى | AW8: 0 | AX8: 0 | AY8: 0 | AZ8: 0 | BA8: 0 | BB8: 0 | BC8: 0 | BD8: 0 | BE8: 0 | BF8: 0 | BG8: 0 | BJ8: سعودي | BK8: أنثى | BL8: 0 | BM8: 0 | BN8: 0 | BO8: 0 | BP8: 0 | BQ8: 0 | BR8: 2 | BS8: 0 | BT8: 0 | BU8: 0 | BV8: 0 | BY8: سعودي | BZ8: أنثى | CA8: 0 | CB8: 0 | CC8: 0 | CD8: 0 | CE8: 0 | CF8: 0 | CG8: 15 | CH8: 0 | CI8: 0 | CJ8: 0 | CK8: 0 | CN8: سعودي | CO8: أنثى | CP8: 19 | CQ8: 18 | CR8: 2 | CS8: 25 | CT8: 3 | CU8: 3 | CV8: 40 | CW8: 0 | CX8: 0 | CY8: 0 | CZ8: 0 | DC8: سعودي | DD8: أنثى | DE8: 0 | DF8: 0 | DG8: 0 | DH8: 0 | DI8: 0 | DJ8: 0 | DK8: 15 | DL8: 0 | DM8: 0 | DN8: 0 | DO8: 0 | DR8: سعودي | DS8: أنثى | DT8: 5 | DU8: 2 | DV8: 0 | DW8: 0 | DX8: 0 | DY8: 0 | DZ8: 0 | EA8: 0 | EB8: 0 | EC8: 0 | ED8: 0 | EG8: سعودي | EH8: أنثى | EI8: 5 | EJ8: 2 | EK8: 0 | EL8: 0 | EM8: 0 | EN8: 0 | EO8: 53 | EP8: 0 | EQ8: 0 | ER8: 0 | ES8: 0 | EV8: سعودي | EW8: أنثى | EX8: 0 | EY8: 0 | EZ8: 0 | FA8: 0 | FB8: 0 | FC8: 0 | FD8: 0 | FE8: 0 | FF8: 0 | FG8: 0 | FH8: 0 | FK8: سعودي | FL8: أنثى | FM8: 0 | FN8: 0 | FO8: 0 | FP8: 0 | FQ8: 0 | FR8: 0 | FS8: 0 | FT8: 0 | FU8: 0 | FV8: 0 | FW8: 0 | FZ8: سعودي | GA8: أنثى | GB8: =SUM(FM8) -> 0 | GC8: =(E8+T8+AI8+AX8+BM8+CB8+CQ8+DF8+DU8+EJ8+EY8+FN8) -> 54 | GD8: =(F8+U8+AJ8+AY8+BN8+CC8+CR8+DG8+DV8+EK8+EZ8+FO8) -> 5 | GE8: =SUM(FP8) -> 0 | GF8: =SUM(FQ8) -> 0 | GG8: =SUM(FR8) -> 0 | GH8: =(J8+Y8+AN8+BC8+BR8+CG8+CV8+DK8+DZ8+EO8+FD8+FS8) -> 190 | GI8: =(K8+Z8+AO8+BD8+BS8+CH8+CW8+DL8+EA8+EP8+FE8+FT8) -> 0 | GJ8: =(L8+AA8+AP8+BE8+BT8+CI8+CX8+DM8+EB8+EQ8+FF8+FU8) -> 0 | GK8: =(M8+AB8+AQ8+BF8+BU8+CJ8+CY8+DN8+EC8+ER8+FG8+FV8) -> 0 | GL8: =(N8+AC8+AR8+BG8+BV8+CK8+CZ8+DO8+ED8+ES8+FH8+FW8) -> 0
B9: المجموع | D9: =SUM(D5:D8) -> 12 | E9: =SUM(E5:E8) -> 5 | F9: =SUM(F5:F8) -> 7 | G9: =SUM(G5:G8) -> 668 | H9: =SUM(H5:H8) -> 3 | I9: =SUM(I5:I8) -> 41 | J9: =SUM(J5:J8) -> 643 | K9: =SUM(K5:K8) -> 0 | ... N9: =SUM(N5:N8) -> 0 | Q9: المجموع | S9: =SUM(S5:S8) -> 132 | T9: =SUM(T5:T8) -> 165 | U9: =SUM(U5:U8) -> 12 | V9: =SUM(V5:V8) -> 563 | W9: =SUM(W5:W8) -> 35 | X9: =SUM(X5:X8) -> 0 | Y9: =SUM(Y5:Y8) -> 200 | Z9: =SUM(Z5:Z8) -> 0 | ... AC9: =SUM(AC5:AC8) -> 0 | AF9: المجموع | AH9: =SUM(AH5:AH8) -> 88 | AI9: =SUM(AI5:AI8) -> 128 | AJ9: =SUM(AJ5:AJ8) -> 0 | AK9: =SUM(AK5:AK8) -> 1127 | AL9: =SUM(AL5:AL8) -> 16 | AM9: =SUM(AM5:AM8) -> 0 | AN9: =SUM(AN5:AN8) -> 200 | AO9: =SUM(AO5:AO8) -> 0 | ... AR9: =SUM(AR5:AR8) -> 0 | AU9: المجموع | AW9: =SUM(AW5:AW8) -> 423 | AX9: =SUM(AX5:AX8) -> 74 | AY9: =SUM(AY5:AY8) -> 0 | AZ9: =SUM(AZ5:AZ8) -> 1131 | BA9: =SUM(BA5:BA8) -> 20 | BB9: =SUM(BB5:BB8) -> 74 | BC9: =SUM(BC5:BC8) -> 210 | BD9: =SUM(BD5:BD8) -> 0 | ... BG9: =SUM(BG5:BG8) -> 0 | BJ9: المجموع | BL9: =SUM(BL5:BL8) -> 423 | BM9: =SUM(BM5:BM8) -> 74 | BN9: =SUM(BN5:BN8) -> 0 | BO9: =SUM(BO5:BO8) -> 1131 | BP9: =SUM(BP5:BP8) -> 20 | BQ9: =SUM(BQ5:BQ8) -> 74 | BR9: =SUM(BR5:BR8) -> 95 | BS9: =SUM(BS5:BS8) -> 0 | ... BV9: =SUM(BV5:BV8) -> 0 | BY9: المجموع | CA9: =SUM(CA5:CA8) -> 423 | CB9: =SUM(CB5:CB8) -> 83 | CC9: =SUM(CC5:CC8) -> 0 | CD9: =SUM(CD5:CD8) -> 1146 | CE9: =SUM(CE5:CE8) -> 0 | CF9: =SUM(CF5:CF8) -> 0 | CG9: 103 | CH9: =SUM(CH5:CH8) -> 0 | CI9: =SUM(CI5:CI8) -> 0 | CJ9: =SUM(CJ5:CJ8) -> 0 | CK9: =SUM(CK5:CK8) -> 0 | CN9: المجموع | CP9: 88 | CQ9: 128 | CR9: 29 | CS9: 332 | CT9: 37 | CU9: 38 | CV9: 147 | CW9: 0 | CX9: 0 | CY9: 0 | CZ9: 0 | DC9: المجموع | DE9: =SUM(DE5:DE8) -> 362 | DF9: =SUM(DF5:DF8) -> 111 | DG9: =SUM(DG5:DG8) -> 0 | DH9: =SUM(DH5:DH8) -> 1209 | DI9: =SUM(DI5:DI8) -> 15 | DJ9: =SUM(DJ5:DJ8) -> 0 | DK9: =SUM(DK5:DK8) -> 103 | DL9: =SUM(DL5:DL8) -> 0 | ... DO9: =SUM(DO5:DO8) -> 0 | DR9: المجموع | DT9: =SUM(DT5:DT8) -> 109 | DU9: =SUM(DU5:DU8) -> 18 | DV9: =SUM(DV5:DV8) -> 0 | DW9: =SUM(DW5:DW8) -> 672 | DX9: =SUM(DX5:DX8) -> 6 | DY9: =SUM(DY5:DY8) -> 8 | DZ9: =SUM(DZ5:DZ8) -> 344 | EA9: =SUM(EA5:EA8) -> 0 | ... ED9: =SUM(ED5:ED8) -> 0 | EG9: المجموع | EI9: =SUM(EI5:EI8) -> 109 | EJ9: =SUM(EJ5:EJ8) -> 18 | EK9: =SUM(EK5:EK8) -> 0 | EL9: =SUM(EL5:EL8) -> 672 | EM9: =SUM(EM5:EM8) -> 6 | EN9: =SUM(EN5:EN8) -> 8 | EO9: =SUM(EO5:EO8) -> 828 | EP9: =SUM(EP5:EP8) -> 0 | ... ES9: =SUM(ES5:ES8) -> 0 | EV9: المجموع | EX9: =SUM(EX5:EX8) -> 0 | EY9: =SUM(EY5:EY8) -> 0 | EZ9: =SUM(EZ5:EZ8) -> 0 | FA9: =SUM(FA5:FA8) -> 0 | FB9: =SUM(FB5:FB8) -> 0 | FC9: =SUM(FC5:FC8) -> 0 | FD9: =SUM(FD5:FD8) -> 0 | FE9: =SUM(FE5:FE8) -> 0 | ... FH9: =SUM(FH5:FH8) -> 0 | FK9: المجموع | FM9: =SUM(FM5:FM8) -> 0 | FN9: =SUM(FN5:FN8) -> 0 | FO9: =SUM(FO5:FO8) -> 0 | FP9: =SUM(FP5:FP8) -> 0 | FQ9: =SUM(FQ5:FQ8) -> 0 | FR9: =SUM(FR5:FR8) -> 0 | FS9: =SUM(FS5:FS8) -> 0 | FT9: =SUM(FT5:FT8) -> 0 | ... FW9: =SUM(FW5:FW8) -> 0 | FZ9: المجموع | GB9: =SUM(GB5:GB8) -> 0 | GC9: =SUM(GC5:GC8) -> 804 | GD9: =SUM(GD5:GD8) -> 48 | GE9: =SUM(GE5:GE8) -> 0 | GF9: =SUM(GF5:GF8) -> 0 | GG9: =SUM(GG5:GG8) -> 0 | GH9: =SUM(GH5:GH8) -> 2873 | GI9: =SUM(GI5:GI8) -> 0 | ... GL9: =SUM(GL5:GL8) -> 0
B10: عدد الأطفال الذين يقل وزنهم بالنسبة لعمرهم ( تحت المنطقة C في منحنى النمو خلال الشهر | K10: ذكر | L10: 0 | M10: أنثى | N10: 0 | Q10: عدد الأطفال الذين يقل وزنهم بالنسبة لعمرهم ( تحت المنطقة C في منحنى النمو خلال الشهر | Z10: ذكر | AA10: 0 | AB10: أنثى | AC10: 0 | AF10: عدد الأطفال الذين يقل وزنهم بالنسبة لعمرهم ( تحت المنطقة C في منحنى النمو خلال الشهر | AO10: ذكر | AP10: 0 | AQ10: أنثى | AR10: 0 | AU10: عدد الأطفال الذين يقل وزنهم بالنسبة لعمرهم ( تحت المنطقة C في منحنى النمو خلال الشهر | BD10: ذكر | BE10: 0 | BF10: أنثى | BG10: 0 | BJ10: عدد الأطفال الذين يقل وزنهم بالنسبة لعمرهم ( تحت المنطقة C في منحنى النمو خلال الشهر | BS10: ذكر | BT10: 0 | BU10: أنثى | BV10: 0 | BY10: عدد الأطفال الذين يقل وزنهم بالنسبة لعمرهم ( تحت المنطقة C في منحنى النمو خلال الشهر | CH10: ذكر | CI10: 0 | CJ10: أنثى | CK10: 0 | CN10: عدد الأطفال الذين يقل وزنهم بالنسبة لعمرهم ( تحت المنطقة C في منحنى النمو خلال الشهر | CW10: ذكر | CX10: 0 | CY10: أنثى | CZ10: 0 | DC10: عدد الأطفال الذين يقل وزنهم بالنسبة لعمرهم ( تحت المنطقة C في منحنى النمو خلال الشهر | DL10: ذكر | DM10: 0 | DN10: أنثى | DO10: 0 | DR10: عدد الأطفال الذين يقل وزنهم بالنسبة لعمرهم ( تحت المنطقة C في منحنى النمو خلال الشهر | EA10: ذكر | EB10: 0 | EC10: أنثى | ED10: 0 | EG10: عدد الأطفال الذين يقل وزنهم بالنسبة لعمرهم ( تحت المنطقة C في منحنى النمو خلال الشهر | EP10: ذكر | EQ10: 0 | ER10: أنثى | ES10: 0 | EV10: عدد الأطفال الذين يقل وزنهم بالنسبة لعمرهم ( تحت المنطقة C في منحنى النمو خلال الشهر | FE10: ذكر | FF10: 0 | FG10: أنثى | FH10: 0 | FK10: عدد الأطفال الذين يقل وزنهم بالنسبة لعمرهم ( تحت المنطقة C في منحنى النمو خلال الشهر | FT10: ذكر | FU10: 0 | FV10: أنثى | FW10: 0 | FZ10: عدد الأطفال الذين يقل وزنهم بالنسبة لعمرهم ( تحت المنطقة C في منحنى النمو خلال العام | GI10: ذكر | GJ10: =(L10+AA10+AP10+BE10+BT10+CI10+CX10+DM10+EB10+EQ10+FF10+FU10) -> 0 | GK10: أنثى | GL10: =(N10+AC10+AR10+BG10+BV10+CK10+CZ10+DO10+ED10+ES10+FH10+FW10) -> 0
A11: الجامعة | B11: سعودي | C11: ذكر | D11: 9 | E11: 3 | F11: 2 | G11: 202 | H11: 6 | I11: 14 | J11: 178 | K11: 0 | L11: 0 | M11: 0 | N11: 0 | P11: الجامعة | Q11: سعودي | R11: ذكر | S11: 250 | T11: 70 | U11: 4 | V11: 210 | W11: 70 | X11: 15 | Y11: 250 | Z11: 0 | AA11: 0 | AB11: 0 | AC11: 0 | AE11: الجامعة | AF11: سعودي | AG11: ذكر | AH11: 26 | AI11: 14 | AJ11: 1 | AK11: 209 | AL11: 11 | AM11: 0 | AN11: 223 | AO11: 0 | AP11: 0 | AQ11: 0 | AR11: 0 | AT11: الجامعة | AU11: سعودي | AV11: ذكر | AW11: 25 | AX11: 9 | AY11: 0 | AZ11: 168 | BA11: 12 | BB11: 0 | BC11: 175 | BD11: 0 | BE11: 0 | BF11: 0 | BG11: 0 | BI11: الجامعة | BJ11: سعودي | BK11: ذكر | BL11: 25 | BM11: 9 | BN11: 0 | BO11: 168 | BP11: 12 | BQ11: 0 | BR11: 0 | BS11: 0 | BT11: 0 | BU11: 0 | BV11: 0 | BX11: الجامعة | BY11: سعودي | BZ11: ذكر | CA11: 25 | CB11: 0 | CC11: 0 | CD11: 0 | CE11: 0 | CF11: 0 | CG11: 154 | CH11: 0 | CI11: 0 | CJ11: 0 | CK11: 0 | CM11: الجامعة | CN11: سعودي | CO11: ذكر | CP11: 9 | CQ11: 3 | CR11: 2 | CS11: 202 | CT11: 6 | CU11: 14 | CV11: 178 | CW11: 0 | CX11: 0 | CY11: 0 | CZ11: 0 | DB11: الجامعة | DC11: سعودي | DD11: ذكر | DE11: 18 | DF11: 10 | DG11: 3 | DH11: 123 | DI11: 12 | DJ11: 0 | DK11: 154 | DL11: 0 | DM11: 0 | DN11: 0 | DO11: 0 | DQ11: الجامعة | DR11: سعودي | DS11: ذكر | DT11: 15 | DU11: 6 | DV11: 0 | DW11: 273 | DX11: 5 | DY11: 0 | DZ11: 108 | EA11: 0 | EB11: 0 | EC11: 0 | ED11: 0 | EF11: الجامعة | EG11: سعودي | EH11: ذكر | EI11: 0 | EJ11: 0 | EK11: 0 | EL11: 0 | EM11: 0 | EN11: 0 | EO11: 0 | EP11: 0 | EQ11: 0 | ER11: 0 | ES11: 0 | EU11: الجامعة | EV11: سعودي | EW11: ذكر | EX11: 0 | EY11: 0 | EZ11: 0 | FA11: 0 | FB11: 0 | FC11: 0 | FD11: 0 | FE11: 0 | FF11: 0 | FG11: 0 | FH11: 0 | FJ11: الجامعة | FK11: سعودي | FL11: ذكر | FM11: 0 | FN11: 0 | FO11: 0 | FP11: 0 | FQ11: 0 | FR11: 0 | FS11: 0 | FT11: 0 | FU11: 0 | FV11: 0 | FW11: 0 | FY11: =(FJ11) -> الجامعة | FZ11: سعودي | GA11: ذكر | GB11: =SUM(FM11) -> 0 | GC11: =(E11+T11+AI11+AX11+BM11+CB11+CQ11+DF11+DU11+EJ11+EY11+FN11) -> 124 | GD11: =(F11+U11+AJ11+AY11+BN11+CC11+CR11+DG11+DV11+EK11+EZ11+FO11) -> 12 | GE11: =SUM(FP11) -> 0 | GF11: =SUM(FQ11) -> 0 | GG11: =SUM(FR11) -> 0 | GH11: =(J11+Y11+AN11+BC11+BR11+CG11+CV11+DK11+DZ11+EO11+FD11+FS11) -> 1420 | GI11: =(K11+Z11+AO11+BD11+BS11+CH11+CW11+DL11+EA11+EP11+FE11+FT11) -> 0 | GJ11: =(L11+AA11+AP11+BE11+BT11+CI11+CX11+DM11+EB11+EQ11+FF11+FU11) -> 0 | GK11: =(M11+AB11+AQ11+BF11+BU11+CJ11+CY11+DN11+EC11+ER11+FG11+FV11) -> 0 | GL11: =(N11+AC11+AR11+BG11+BV11+CK11+CZ11+DO11+ED11+ES11+FH11+FW11) -> 0
C12: أنثى | D12: 11 | E12: 2 | F12: 0 | G12: 243 | H12: 3 | I12: 15 | J12: 174 | K12: 0 | L12: 0 | M12: 0 | N12: 0 | R12: أنثى | S12: 230 | T12: 95 | U12: 0 | V12: 200 | W12: 40 | X12: 13 | Y12: 230 | Z12: 0 | AA12: 0 | AB12: 0 | AC12: 0 | AG12: أنثى | AH12: 24 | AI12: 9 | AJ12: 1 | AK12: 211 | AL12: 10 | AM12: 0 | AN12: 233 | AO12: 0 | AP12: 0 | AQ12: 0 | AR12: 0 | AV12: أنثى | AW12: 14 | AX12: 6 | AY12: 0 | AZ12: 193 | BA12: 10 | BB12: 0 | BC12: 203 | BD12: 0 | BE12: 0 | BF12: 0 | BG12: 0 | BK12: أنثى | BL12: 14 | BM12: 6 | BN12: 0 | BO12: 193 | BP12: 10 | BQ12: 0 | BR12: 0 | BS12: 0 | BT12: 0 | BU12: 0 | BV12: 0 | BZ12: أنثى | CA12: 19 | CB12: 0 | CC12: 0 | CD12: 0 | CE12: 0 | CF12: 0 | CG12: 176 | CH12: 0 | CI12: 0 | CJ12: 0 | CK12: 0 | CO12: أنثى | CP12: 11 | CQ12: 2 | CR12: 0 | CS12: 243 | CT12: 3 | CU12: 15 | CV12: 174 | CW12: 0 | CX12: 0 | CY12: 0 | CZ12: 0 | DD12: أنثى | DE12: 12 | DF12: 14 | DG12: 5 | DH12: 179 | DI12: 15 | DJ12: 0 | DK12: 176 | DL12: 0 | DM12: 0 | DN12: 0 | DO12: 0 | DS12: أنثى | DT12: 14 | DU12: 8 | DV12: 0 | DW12: 409 | DX12: 20 | DY12: 3 | DZ12: 116 | EA12: 0 | EB12: 0 | EC12: 0 | ED12: 0 | EH12: أنثى | EI12: 0 | EJ12: 0 | EK12: 0 | EL12: 0 | EM12: 0 | EN12: 0 | EO12: 0 | EP12: 0 | EQ12: 0 | ER12: 0 | ES12: 0 | EW12: أنثى | EX12: 0 | EY12: 0 | EZ12: 0 | FA12: 0 | FB12: 0 | FC12: 0 | FD12: 0 | FE12: 0 | FF12: 0 | FG12: 0 | FH12: 0 | FL12: أنثى | FM12: 0 | FN12: 0 | FO12: 0 | FP12: 0 | FQ12: 0 | FR12: 0 | FS12: 0 | FT12: 0 | FU12: 0 | FV12: 0 | FW12: 0 | GA12: أنثى | GB12: =SUM(FM12) -> 0 | GC12: =(E12+T12+AI12+AX12+BM12+CB12+CQ12+DF12+DU12+EJ12+EY12+FN12) -> 142 | GD12: =(F12+U12+AJ12+AY12+BN12+CC12+CR12+DG12+DV12+EK12+EZ12+FO12) -> 6 | GE12: =SUM(FP12) -> 0 | GF12: =SUM(FQ12) -> 0 | GG12: =SUM(FR12) -> 0 | GH12: =(J12+Y12+AN12+BC12+BR12+CG12+CV12+DK12+DZ12+EO12+FD12+FS12) -> 1482 | GI12: =(K12+Z12+AO12+BD12+BS12+CH12+CW12+DL12+EA12+EP12+FE12+FT12) -> 0 | GJ12: =(L12+AA12+AP12+BE12+BT12+CI12+CX12+DM12+EB12+EQ12+FF12+FU12) -> 0 | GK12: =(M12+AB12+AQ12+BF12+BU12+CJ12+CY12+DN12+EC12+ER12+FG12+FV12) -> 0 | GL12: =(N12+AC12+AR12+BG12+BV12+CK12+CZ12+DO12+ED12+ES12+FH12+FW12) -> 0
B13: غير | C13: ذكر | D13: 0 | E13: 0 | F13: 0 | G13: 0 | H13: 0 | I13: 0 | J13: 182 | K13: 0 | L13: 0 | M13: 0 | N13: 0 | Q13: غير | R13: ذكر | S13: 350 | T13: 100 | U13: 0 | V13: 150 | W13: 0 | X13: 0 | Y13: 350 | Z13: 0 | AA13: 0 | AB13: 0 | AC13: 0 | AF13: غير | AG13: ذكر | AH13: 0 | AI13: 0 | AJ13: 0 | AK13: 0 | AL13: 0 | AM13: 0 | AN13: 0 | AO13: 0 | AP13: 0 | AQ13: 0 | AR13: 0 | AU13: غير | AV13: ذكر | AW13: 0 | AX13: 0 | AY13: 0 | AZ13: 0 | BA13: 0 | BB13: 0 | BC13: 0 | BD13: 0 | BE13: 0 | BF13: 0 | BG13: 0 | BJ13: غير | BK13: ذكر | BL13: 0 | BM13: 0 | BN13: 0 | BO13: 0 | BP13: 0 | BQ13: 0 | BR13: 0 | BS13: 0 | BT13: 0 | BU13: 0 | BV13: 0 | BY13: غير | BZ13: ذكر | CA13: 0 | CB13: 0 | CC13: 0 | CD13: 0 | CE13: 0 | CF13: 0 | CG13: 0 | CH13: 0 | CI13: 0 | CJ13: 0 | CK13: 0 | CN13: غير | CO13: ذكر | CP13: 0 | CQ13: 0 | CR13: 0 | CS13: 0 | CT13: 0 | CU13: 0 | CV13: 182 | CW13: 0 | CX13: 0 | CY13: 0 | CZ13: 0 | DC13: غير | DD13: ذكر | DE13: 0 | DF13: 0 | DG13: 0 | DH13: 0 | DI13: 0 | DJ13: 0 | DK13: 0 | DL13: 0 | DM13: 0 | DN13: 0 | DO13: 0 | DR13: غير | DS13: ذكر | DT13: 0 | DU13: 0 | DV13: 0 | DW13: 0 | DX13: 0 | DY13: 0 | DZ13: 0 | EA13: 0 | EB13: 0 | EC13: 0 | ED13: 0 | EG13: غير | EH13: ذكر | EI13: 0 | EJ13: 0 | EK13: 0 | EL13: 0 | EM13: 0 | EN13: 0 | EO13: 0 | EP13: 0 | EQ13: 0 | ER13: 0 | ES13: 0 | EV13: غير | EW13: ذكر | EX13: 0 | EY13: 0 | EZ13: 0 | FA13: 0 | FB13: 0 | FC13: 0 | FD13: 0 | FE13: 0 | FF13: 0 | FG13: 0 | FH13: 0 | FK13: غير | FL13: ذكر | FM13: 0 | FN13: 0 | FO13: 0 | FP13: 0 | FQ13: 0 | FR13: 0 | FS13: 0 | FT13: 0 | FU13: 0 | FV13: 0 | FW13: 0 | FZ13: غير | GA13: ذكر | GB13: =SUM(FM13) -> 0 | GC13: =(E13+T13+AI13+AX13+BM13+CB13+CQ13+DF13+DU13+EJ13+EY13+FN13) -> 100 | GD13: =(F13+U13+AJ13+AY13+BN13+CC13+CR13+DG13+DV13+EK13+EZ13+FO13) -> 0 | GE13: =SUM(FP13) -> 0 | GF13: =SUM(FQ13) -> 0 | GG13: =SUM(FR13) -> 0 | GH13: =(J13+Y13+AN13+BC13+BR13+CG13+CV13+DK13+DZ13+EO13+FD13+FS13) -> 714 | GI13: =(K13+Z13+AO13+BD13+BS13+CH13+CW13+DL13+EA13+EP13+FE13+FT13) -> 0 | GJ13: =(L13+AA13+AP13+BE13+BT13+CI13+CX13+DM13+EB13+EQ13+FF13+FU13) -> 0 | GK13: =(M13+AB13+AQ13+BF13+BU13+CJ13+CY13+DN13+EC13+ER13+FG13+FV13) -> 0 | GL13: =(N13+AC13+AR13+BG13+BV13+CK13+CZ13+DO13+ED13+ES13+FH13+FW13) -> 0
B14: سعودي | C14: أنثى | D14: 0 | E14: 0 | F14: 0 | G14: 0 | H14: 0 | I14: 0 | J14: 189 | K14: 0 | L14: 0 | M14: 0 | N14: 0 | Q14: سعودي | R14: أنثى | S14: 300 | T14: 90 | U14: 0 | V14: 190 | W14: 0 | X14: 0 | Y14: 300 | Z14: 0 | AA14: 0 | AB14: 0 | AC14: 0 | AF14: سعودي | AG14: أنثى | AH14: 0 | AI14: 0 | AJ14: 0 | AK14: 0 | AL14: 0 | AM14: 0 | AN14: 0 | AO14: 0 | AP14: 0 | AQ14: 0 | AR14: 0 | AU14: سعودي | AV14: أنثى | AW14: 0 | AX14: 0 | AY14: 0 | AZ14: 0 | BA14: 0 | BB14: 0 | BC14: 0 | BD14: 0 | BE14: 0 | BF14: 0 | BG14: 0 | BJ14: سعودي | BK14: أنثى | BL14: 0 | BM14: 0 | BN14: 0 | BO14: 0 | BP14: 0 | BQ14: 0 | BR14: 0 | BS14: 0 | BT14: 0 | BU14: 0 | BV14: 0 | BY14: سعودي | BZ14: أنثى | CA14: 0 | CB14: 0 | CC14: 0 | CD14: 0 | CE14: 0 | CF14: 0 | CG14: 0 | CH14: 0 | CI14: 0 | CJ14: 0 | CK14: 0 | CN14: سعودي | CO14: أنثى | CP14: 0 | CQ14: 0 | CR14: 0 | CS14: 0 | CT14: 0 | CU14: 0 | CV14: 189 | CW14: 0 | CX14: 0 | CY14: 0 | CZ14: 0 | DC14: سعودي | DD14: أنثى | DE14: 0 | DF14: 0 | DG14: 0 | DH14: 0 | DI14: 0 | DJ14: 0 | DK14: 0 | DL14: 0 | DM14: 0 | DN14: 0 | DO14: 0 | DR14: سعودي | DS14: أنثى | DT14: 0 | DU14: 0 | DV14: 0 | DW14: 0 | DX14: 0 | DY14: 0 | DZ14: 0 | EA14: 0 | EB14: 0 | EC14: 0 | ED14: 0 | EG14: سعودي | EH14: أنثى | EI14: 0 | EJ14: 0 | EK14: 0 | EL14: 0 | EM14: 0 | EN14: 0 | EO14: 0 | EP14: 0 | EQ14: 0 | ER14: 0 | ES14: 0 | EV14: سعودي | EW14: أنثى | EX14: 0 | EY14: 0 | EZ14: 0 | FA14: 0 | FB14: 0 | FC14: 0 | FD14: 0 | FE14: 0 | FF14: 0 | FG14: 0 | FH14: 0 | FK14: سعودي | FL14: أنثى | FM14: 0 | FN14: 0 | FO14: 0 | FP14: 0 | FQ14: 0 | FR14: 0 | FS14: 0 | FT14: 0 | FU14: 0 | FV14: 0 | FW14: 0 | FZ14: سعودي | GA14: أنثى | GB14: =SUM(FM14) -> 0 | GC14: =(E14+T14+AI14+AX14+BM14+CB14+CQ14+DF14+DU14+EJ14+EY14+FN14) -> 90 | GD14: =(F14+U14+AJ14+AY14+BN14+CC14+CR14+DG14+DV14+EK14+EZ14+FO14) -> 0 | GE14: =SUM(FP14) -> 0 | GF14: =SUM(FQ14) -> 0 | GG14: =SUM(FR14) -> 0 | GH14: =(J14+Y14+AN14+BC14+BR14+CG14+CV14+DK14+DZ14+EO14+FD14+FS14) -> 678 | GI14: =(K14+Z14+AO14+BD14+BS14+CH14+CW14+DL14+EA14+EP14+FE14+FT14) -> 0 | GJ14: =(L14+AA14+AP14+BE14+BT14+CI14+CX14+DM14+EB14+EQ14+FF14+FU14) -> 0 | GK14: =(M14+AB14+AQ14+BF14+BU14+CJ14+CY14+DN14+EC14+ER14+FG14+FV14) -> 0 | GL14: =(N14+AC14+AR14+BG14+BV14+CK14+CZ14+DO14+ED14+ES14+FH14+FW14) -> 0
B15: المجموع | D15: =SUM(D11:D14) -> 20 | E15: =SUM(E11:E14) -> 5 | F15: =SUM(F11:F14) -> 2 | G15: =SUM(G11:G14) -> 445 | H15: =SUM(H11:H14) -> 9 | I15: =SUM(I11:I14) -> 29 | J15: =SUM(J11:J14) -> 723 | K15: =SUM(K11:K14) -> 0 | ... N15: =SUM(N11:N14) -> 0 | Q15: المجموع | S15: =SUM(S11:S14) -> 1130 | T15: =SUM(T11:T14) -> 355 | U15: =SUM(U11:U14) -> 4 | V15: =SUM(V11:V14) -> 750 | W15: =SUM(W11:W14) -> 110 | X15: =SUM(X11:X14) -> 28 | Y15: =SUM(Y11:Y14) -> 1130 | Z15: =SUM(Z11:Z14) -> 0 | ... AC15: =SUM(AC11:AC14) -> 0 | AF15: المجموع | AH15: =SUM(AH11:AH14) -> 50 | AI15: =SUM(AI11:AI14) -> 23 | AJ15: =SUM(AJ11:AJ14) -> 2 | AK15: =SUM(AK11:AK14) -> 420 | AL15: =SUM(AL11:AL14) -> 21 | AM15: =SUM(AM11:AM14) -> 0 | AN15: =SUM(AN11:AN14) -> 456 | AO15: =SUM(AO11:AO14) -> 0 | ... AR15: =SUM(AR11:AR14) -> 0 | AU15: المجموع | AW15: =SUM(AW11:AW14) -> 39 | AX15: =SUM(AX11:AX14) -> 15 | AY15: =SUM(AY11:AY14) -> 0 | AZ15: =SUM(AZ11:AZ14) -> 361 | BA15: =SUM(BA11:BA14) -> 22 | BB15: =SUM(BB11:BB14) -> 0 | BC15: =SUM(BC11:BC14) -> 378 | BD15: =SUM(BD11:BD14) -> 0 | ... BG15: =SUM(BG11:BG14) -> 0 | BJ15: المجموع | BL15: =SUM(BL11:BL14) -> 39 | BM15: =SUM(BM11:BM14) -> 15 | BN15: =SUM(BN11:BN14) -> 0 | BO15: =SUM(BO11:BO14) -> 361 | BP15: =SUM(BP11:BP14) -> 22 | BQ15: =SUM(BQ11:BQ14) -> 0 | BR15: =SUM(BR11:BR14) -> 0 | BS15: =SUM(BS11:BS14) -> 0 | ... BV15: =SUM(BV11:BV14) -> 0 | BY15: المجموع | CA15: =SUM(CA11:CA14) -> 44 | CB15: =SUM(CB11:CB14) -> 0 | CC15: =SUM(CC11:CC14) -> 0 | CD15: =SUM(CD11:CD14) -> 0 | CE15: =SUM(CE11:CE14) -> 0 | CF15: =SUM(CF11:CF14) -> 0 | CG15: 330 | CH15: =SUM(CH11:CH14) -> 0 | CI15: =SUM(CI11:CI14) -> 0 | CJ15: =SUM(CJ11:CJ14) -> 0 | CK15: =SUM(CK11:CK14) -> 0 | CN15: المجموع | CP15: 20 | CQ15: 5 | CR15: 2 | CS15: 445 | CT15: 9 | CU15: 29 | CV15: 723 | CW15: 0 | CX15: 0 | CY15: 0 | CZ15: 0 | DC15: المجموع | DE15: =SUM(DE11:DE14) -> 30 | DF15: =SUM(DF11:DF14) -> 24 | DG15: =SUM(DG11:DG14) -> 8 | DH15: =SUM(DH11:DH14) -> 302 | DI15: =SUM(DI11:DI14) -> 27 | DJ15: =SUM(DJ11:DJ14) -> 0 | DK15: =SUM(DK11:DK14) -> 330 | DL15: =SUM(DL11:DL14) -> 0 | ... DO15: =SUM(DO11:DO14) -> 0 | DR15: المجموع | DT15: =SUM(DT11:DT14) -> 29 | DU15: =SUM(DU11:DU14) -> 14 | DV15: =SUM(DV11:DV14) -> 0 | DW15: =SUM(DW11:DW14) -> 682 | DX15: =SUM(DX11:DX14) -> 25 | DY15: =SUM(DY11:DY14) -> 3 | DZ15: =SUM(DZ11:DZ14) -> 224 | EA15: =SUM(EA11:EA14) -> 0 | ... ED15: =SUM(ED11:ED14) -> 0 | EG15: المجموع | EI15: =SUM(EI11:EI14) -> 0 | EJ15: =SUM(EJ11:EJ14) -> 0 | EK15: =SUM(EK11:EK14) -> 0 | EL15: =SUM(EL11:EL14) -> 0 | EM15: =SUM(EM11:EM14) -> 0 | EN15: =SUM(EN11:EN14) -> 0 | EO15: =SUM(EO11:EO14) -> 0 | EP15: =SUM(EP11:EP14) -> 0 | ... ES15: =SUM(ES11:ES14) -> 0 | EV15: المجموع | EX15: =SUM(EX11:EX14) -> 0 | EY15: =SUM(EY11:EY14) -> 0 | EZ15: =SUM(EZ11:EZ14) -> 0 | FA15: =SUM(FA11:FA14) -> 0 | FB15: =SUM(FB11:FB14) -> 0 | FC15: =SUM(FC11:FC14) -> 0 | FD15: =SUM(FD11:FD14) -> 0 | FE15: =SUM(FE11:FE14) -> 0 | ... FH15: =SUM(FH11:FH14) -> 0 | FK15: المجموع | FM15: =SUM(FM11:FM14) -> 0 | FN15: =SUM(FN11:FN14) -> 0 | FO15: =SUM(FO11:FO14) -> 0 | FP15: =SUM(FP11:FP14) -> 0 | FQ15: =SUM(FQ11:FQ14) -> 0 | FR15: =SUM(FR11:FR14) -> 0 | FS15: =SUM(FS11:FS14) -> 0 | FT15: =SUM(FT11:FT14) -> 0 | ... FW15: =SUM(FW11:FW14) -> 0 | FZ15: المجموع | GB15: =SUM(GB11:GB14) -> 0 | GC15: =SUM(GC11:GC14) -> 456 | GD15: =SUM(GD11:GD14) -> 18 | GE15: =SUM(GE11:GE14) -> 0 | GF15: =SUM(GF11:GF14) -> 0 | GG15: =SUM(GG11:GG14) -> 0 | GH15: =SUM(GH11:GH14) -> 4294 | GI15: =SUM(GI11:GI14) -> 0 | ... GL15: =SUM(GL11:GL14) -> 0
B16: عدد الأطفال الذين يقل وزنهم بالنسبة لعمرهم ( تحت المنطقة C في منحنى النمو خلال الشهر | K16: ذكر | L16: 0 | M16: أنثى | N16: 0 | Q16: عدد الأطفال الذين يقل وزنهم بالنسبة لعمرهم ( تحت المنطقة C في منحنى النمو خلال الشهر | Z16: ذكر | AA16: 0 | AB16: أنثى | AC16: 0 | AF16: عدد الأطفال الذين يقل وزنهم بالنسبة لعمرهم ( تحت المنطقة C في منحنى النمو خلال الشهر | AO16: ذكر | AP16: 0 | AQ16: أنثى | AR16: 0 | AU16: عدد الأطفال الذين يقل وزنهم بالنسبة لعمرهم ( تحت المنطقة C في منحنى النمو خلال الشهر | BD16: ذكر | BE16: 0 | BF16: أنثى | BG16: 0 | BJ16: عدد الأطفال الذين يقل وزنهم بالنسبة لعمرهم ( تحت المنطقة C في منحنى النمو خلال الشهر | BS16: ذكر | BT16: 0 | BU16: أنثى | BV16: 0 | BY16: عدد الأطفال الذين يقل وزنهم بالنسبة لعمرهم ( تحت المنطقة C في منحنى النمو خلال الشهر | CH16: ذكر | CI16: 0 | CJ16: أنثى | CK16: 0 | CN16: عدد الأطفال الذين يقل وزنهم بالنسبة لعمرهم ( تحت المنطقة C في منحنى النمو خلال الشهر | CW16: ذكر | CX16: 0 | CY16: أنثى | CZ16: 0 | DC16: عدد الأطفال الذين يقل وزنهم بالنسبة لعمرهم ( تحت المنطقة C في منحنى النمو خلال الشهر | DL16: ذكر | DM16: 0 | DN16: أنثى | DO16: 0 | DR16: عدد الأطفال الذين يقل وزنهم بالنسبة لعمرهم ( تحت المنطقة C في منحنى النمو خلال الشهر | EA16: ذكر | EB16: 0 | EC16: أنثى | ED16: 0 | EG16: عدد الأطفال الذين يقل وزنهم بالنسبة لعمرهم ( تحت المنطقة C في منحنى النمو خلال الشهر | EP16: ذكر | EQ16: 0 | ER16: أنثى | ES16: 0 | EV16: عدد الأطفال الذين يقل وزنهم بالنسبة لعمرهم ( تحت المنطقة C في منحنى النمو خلال الشهر | FE16: ذكر | FF16: 0 | FG16: أنثى | FH16: 0 | FK16: عدد الأطفال الذين يقل وزنهم بالنسبة لعمرهم ( تحت المنطقة C في منحنى النمو خلال الشهر | FT16: ذكر | FU16: 0 | FV16: أنثى | FW16: 0 | FZ16: عدد الأطفال الذين يقل وزنهم بالنسبة لعمرهم ( تحت المنطقة C في منحنى النمو خلال العام | GI16: ذكر | GJ16: =(L16+AA16+AP16+BE16+BT16+CI16+CX16+DM16+EB16+EQ16+FF16+FU16) -> 0 | GK16: أنثى | GL16: =(N16+AC16+AR16+BG16+BV16+CK16+CZ16+DO16+ED16+ES16+FH16+FW16) -> 0
A17: السليمانية | B17: سعودي | C17: ذكر | D17: 15 | E17: 0 | F17: 0 | G17: 0 | H17: 28 | I17: 30 | J17: 122 | K17: 0 | L17: 0 | M17: 0 | N17: 0 | P17: السليمانية | Q17: سعودي | R17: ذكر | S17: 0 | T17: 0 | U17: 0 | V17: 0 | W17: 0 | X17: 192 | Y17: 79 | Z17: 51 | AA17: 160 | AB17: 0 | AC17: 0 | AE17: السليمانية | AF17: سعودي | AG17: ذكر | AH17: 0 | AI17: 0 | AJ17: 0 | AK17: 0 | AL17: 0 | AM17: 0 | AN17: 0 | AO17: 0 | AP17: 0 | AQ17: 0 | AR17: 0 | AT17: السليمانية | AU17: سعودي | AV17: ذكر | AW17: 0 | AX17: 0 | AY17: 0 | AZ17: 0 | BA17: 0 | BB17: 0 | BC17: 0 | BD17: 0 | BE17: 0 | BF17: 0 | BG17: 0 | BI17: السليمانية | BJ17: سعودي | BK17: ذكر | BL17: 0 | BM17: 0 | BN17: 0 | BO17: 0 | BP17: 0 | BQ17: 0 | BR17: 58 | BS17: 0 | BT17: 0 | BU17: 0 | BV17: 0 | BX17: السليمانية | BY17: سعودي | BZ17: ذكر | CA17: 0 | CB17: 0 | CC17: 0 | CD17: 0 | CE17: 0 | CF17: 0 | CG17: 0 | CH17: 0 | CI17: 0 | CJ17: 0 | CK17: 0 | CM17: السليمانية | CN17: سعودي | CO17: ذكر | CP17: 0 | CQ17: 0 | CR17: 0 | CS17: 196 | CT17: 80 | CU17: 51 | CV17: 132 | CW17: 0 | CX17: 0 | CY17: 0 | CZ17: 0 | DB17: السليمانية | DC17: سعودي | DD17: ذكر | DE17: 0 | DF17: 0 | DG17: 0 | DH17: 0 | DI17: 0 | DJ17: 0 | DK17: 0 | DL17: 0 | DM17: 0 | DN17: 0 | DO17: 0 | DQ17: السليمانية | DR17: سعودي | DS17: ذكر | DT17: 68 | DU17: 44 | DV17: 26 | DW17: 1289 | DX17: 35 | DY17: 10 | DZ17: 18 | EA17: 0 | EB17: 0 | EC17: 0 | ED17: 0 | EF17: السليمانية | EG17: سعودي | EH17: ذكر | EI17: 68 | EJ17: 44 | EK17: 26 | EL17: 1289 | EM17: 35 | EN17: 10 | EO17: 686 | EP17: 0 | EQ17: 0 | ER17: 0 | ES17: 0 | EU17: السليمانية | EV17: سعودي | EW17: ذكر | EX17: 0 | EY17: 0 | EZ17: 0 | FA17: 0 | FB17: 0 | FC17: 0 | FD17: 0 | FE17: 0 | FF17: 0 | FG17: 0 | FH17: 0 | FJ17: السليمانية | FK17: سعودي | FL17: ذكر | FM17: 0 | FN17: 0 | FO17: 0 | FP17: 0 | FQ17: 0 | FR17: 0 | FS17: 0 | FT17: 0 | FU17: 0 | FV17: 0 | FW17: 0 | FY17: =(FJ17) -> السليمانية | FZ17: سعودي | GA17: ذكر | GB17: =SUM(FM17) -> 0 | GC17: =(E17+T17+AI17+AX17+BM17+CB17+CQ17+DF17+DU17+EJ17+EY17+FN17) -> 88 | GD17: =(F17+U17+AJ17+AY17+BN17+CC17+CR17+DG17+DV17+EK17+EZ17+FO17) -> 52 | GE17: =SUM(FP17) -> 0 | GF17: =SUM(FQ17) -> 0 | GG17: =SUM(FR17) -> 0 | GH17: =(J17+Y17+AN17+BC17+BR17+CG17+CV17+DK17+DZ17+EO17+FD17+FS17) -> 1095 | GI17: =(K17+Z17+AO17+BD17+BS17+CH17+CW17+DL17+EA17+EP17+FE17+FT17) -> 51 | GJ17: =(L17+AA17+AP17+BE17+BT17+CI17+CX17+DM17+EB17+EQ17+FF17+FU17) -> 160 | GK17: =(M17+AB17+AQ17+BF17+BU17+CJ17+CY17+DN17+EC17+ER17+FG17+FV17) -> 0 | GL17: =(N17+AC17+AR17+BG17+BV17+CK17+CZ17+DO17+ED17+ES17+FH17+FW17) -> 0
C18: أنثى | D18: 10 | E18: 0 | F18: 0 | G18: 0 | H18: 32 | I18: 40 | J18: 133 | K18: 0 | L18: 0 | M18: 0 | N18: 0 | R18: أنثى | S18: 0 | T18: 0 | U18: 0 | V18: 0 | W18: 0 | X18: 224 | Y18: 55 | Z18: 41 | AA18: 120 | AB18: 0 | AC18: 0 | AG18: أنثى | AH18: 0 | AI18: 0 | AJ18: 0 | AK18: 0 | AL18: 0 | AM18: 0 | AN18: 0 | AO18: 0 | AP18: 0 | AQ18: 0 | AR18: 0 | AV18: أنثى | AW18: 0 | AX18: 0 | AY18: 0 | AZ18: 0 | BA18: 0 | BB18: 0 | BC18: 0 | BD18: 0 | BE18: 0 | BF18: 0 | BG18: 0 | BK18: أنثى | BL18: 0 | BM18: 0 | BN18: 0 | BO18: 0 | BP18: 0 | BQ18: 0 | BR18: 31 | BS18: 0 | BT18: 0 | BU18: 0 | BV18: 0 | BZ18: أنثى | CA18: 0 | CB18: 0 | CC18: 0 | CD18: 0 | CE18: 0 | CF18: 0 | CG18: 0 | CH18: 0 | CI18: 0 | CJ18: 0 | CK18: 0 | CO18: أنثى | CP18: 0 | CQ18: 0 | CR18: 0 | CS18: 225 | CT18: 55 | CU18: 41 | CV18: 110 | CW18: 0 | CX18: 0 | CY18: 0 | CZ18: 0 | DD18: أنثى | DE18: 0 | DF18: 0 | DG18: 0 | DH18: 0 | DI18: 0 | DJ18: 0 | DK18: 0 | DL18: 0 | DM18: 0 | DN18: 0 | DO18: 0 | DS18: أنثى | DT18: 52 | DU18: 21 | DV18: 25 | DW18: 1303 | DX18: 32 | DY18: 12 | DZ18: 10 | EA18: 0 | EB18: 0 | EC18: 0 | ED18: 0 | EH18: أنثى | EI18: 52 | EJ18: 21 | EK18: 25 | EL18: 1303 | EM18: 32 | EN18: 12 | EO18: 532 | EP18: 0 | EQ18: 0 | ER18: 0 | ES18: 0 | EW18: أنثى | EX18: 0 | EY18: 0 | EZ18: 0 | FA18: 0 | FB18: 0 | FC18: 0 | FD18: 0 | FE18: 0 | FF18: 0 | FG18: 0 | FH18: 0 | FL18: أنثى | FM18: 0 | FN18: 0 | FO18: 0 | FP18: 0 | FQ18: 0 | FR18: 0 | FS18: 0 | FT18: 0 | FU18: 0 | FV18: 0 | FW18: 0 | GA18: أنثى | GB18: =SUM(FM18) -> 0 | GC18: =(E18+T18+AI18+AX18+BM18+CB18+CQ18+DF18+DU18+EJ18+EY18+FN18) -> 42 | GD18: =(F18+U18+AJ18+AY18+BN18+CC18+CR18+DG18+DV18+EK18+EZ18+FO18) -> 50 | GE18: =SUM(FP18) -> 0 | GF18: =SUM(FQ18) -> 0 | GG18: =SUM(FR18) -> 0 | GH18: =(J18+Y18+AN18+BC18+BR18+CG18+CV18+DK18+DZ18+EO18+FD18+FS18) -> 871 | GI18: =(K18+Z18+AO18+BD18+BS18+CH18+CW18+DL18+EA18+EP18+FE18+FT18) -> 41 | GJ18: =(L18+AA18+AP18+BE18+BT18+CI18+CX18+DM18+EB18+EQ18+FF18+FU18) -> 120 | GK18: =(M18+AB18+AQ18+BF18+BU18+CJ18+CY18+DN18+EC18+ER18+FG18+FV18) -> 0 | GL18: =(N18+AC18+AR18+BG18+BV18+CK18+CZ18+DO18+ED18+ES18+FH18+FW18) -> 0
B19: غير | C19: ذكر | D19: 0 | E19: 0 | F19: 0 | G19: 0 | H19: 50 | I19: 39 | J19: 137 | K19: 0 | L19: 0 | M19: 0 | N19: 0 | Q19: غير | R19: ذكر | S19: 0 | T19: 0 | U19: 0 | V19: 0 | W19: 0 | X19: 0 | Y19: 0 | Z19: 0 | AA19: 179 | AB19: 0 | AC19: 0 | AF19: غير | AG19: ذكر | AH19: 0 | AI19: 0 | AJ19: 0 | AK19: 0 | AL19: 0 | AM19: 0 | AN19: 0 | AO19: 0 | AP19: 0 | AQ19: 0 | AR19: 0 | AU19: غير | AV19: ذكر | AW19: 0 | AX19: 0 | AY19: 0 | AZ19: 0 | BA19: 0 | BB19: 0 | BC19: 0 | BD19: 0 | BE19: 0 | BF19: 0 | BG19: 0 | BJ19: غير | BK19: ذكر | BL19: 0 | BM19: 0 | BN19: 0 | BO19: 0 | BP19: 0 | BQ19: 0 | BR19: 6 | BS19: 0 | BT19: 0 | BU19: 0 | BV19: 0 | BY19: غير | BZ19: ذكر | CA19: 0 | CB19: 0 | CC19: 0 | CD19: 0 | CE19: 0 | CF19: 0 | CG19: 0 | CH19: 0 | CI19: 0 | CJ19: 0 | CK19: 0 | CN19: غير | CO19: ذكر | CP19: 0 | CQ19: 0 | CR19: 0 | CS19: 0 | CT19: 0 | CU19: 0 | CV19: 138 | CW19: 0 | CX19: 0 | CY19: 0 | CZ19: 0 | DC19: غير | DD19: ذكر | DE19: 0 | DF19: 0 | DG19: 0 | DH19: 0 | DI19: 0 | DJ19: 0 | DK19: 0 | DL19: 0 | DM19: 0 | DN19: 0 | DO19: 0 | DR19: غير | DS19: ذكر | DT19: 41 | DU19: 25 | DV19: 20 | DW19: 150 | DX19: 20 | DY19: 15 | DZ19: 22 | EA19: 0 | EB19: 0 | EC19: 0 | ED19: 0 | EG19: غير | EH19: ذكر | EI19: 41 | EJ19: 25 | EK19: 20 | EL19: 150 | EM19: 20 | EN19: 15 | EO19: 255 | EP19: 0 | EQ19: 0 | ER19: 0 | ES19: 0 | EV19: غير | EW19: ذكر | EX19: 0 | EY19: 0 | EZ19: 0 | FA19: 0 | FB19: 0 | FC19: 0 | FD19: 0 | FE19: 0 | FF19: 0 | FG19: 0 | FH19: 0 | FK19: غير | FL19: ذكر | FM19: 0 | FN19: 0 | FO19: 0 | FP19: 0 | FQ19: 0 | FR19: 0 | FS19: 0 | FT19: 0 | FU19: 0 | FV19: 0 | FW19: 0 | FZ19: غير | GA19: ذكر | GB19: =SUM(FM19) -> 0 | GC19: =(E19+T19+AI19+AX19+BM19+CB19+CQ19+DF19+DU19+EJ19+EY19+FN19) -> 50 | GD19: =(F19+U19+AJ19+AY19+BN19+CC19+CR19+DG19+DV19+EK19+EZ19+FO19) -> 40 | GE19: =SUM(FP19) -> 0 | GF19: =SUM(FQ19) -> 0 | GG19: =SUM(FR19) -> 0 | GH19: =(J19+Y19+AN19+BC19+BR19+CG19+CV19+DK19+DZ19+EO19+FD19+FS19) -> 558 | GI19: =(K19+Z19+AO19+BD19+BS19+CH19+CW19+DL19+EA19+EP19+FE19+FT19) -> 0 | GJ19: =(L19+AA19+AP19+BE19+BT19+CI19+CX19+DM19+EB19+EQ19+FF19+FU19) -> 179 | GK19: =(M19+AB19+AQ19+BF19+BU19+CJ19+CY19+DN19+EC19+ER19+FG19+FV19) -> 0 | GL19: =(N19+AC19+AR19+BG19+BV19+CK19+CZ19+DO19+ED19+ES19+FH19+FW19) -> 0
B20: سعودي | C20: أنثى | D20: 0 | E20: 0 | F20: 0 | G20: 0 | H20: 60 | I20: 41 | J20: 138 | K20: 0 | L20: 0 | M20: 0 | N20: 0 | Q20: سعودي | R20: أنثى | S20: 0 | T20: 0 | U20: 0 | V20: 0 | W20: 0 | X20: 0 | Y20: 0 | Z20: 0 | AA20: 170 | AB20: 0 | AC20: 0 | AF20: سعودي | AG20: أنثى | AH20: 0 | AI20: 0 | AJ20: 0 | AK20: 0 | AL20: 0 | AM20: 0 | AN20: 0 | AO20: 0 | AP20: 0 | AQ20: 0 | AR20: 0 | AU20: سعودي | AV20: أنثى | AW20: 0 | AX20: 0 | AY20: 0 | AZ20: 0 | BA20: 0 | BB20: 0 | BC20: 0 | BD20: 0 | BE20: 0 | BF20: 0 | BG20: 0 | BJ20: سعودي | BK20: أنثى | BL20: 0 | BM20: 0 | BN20: 0 | BO20: 0 | BP20: 0 | BQ20: 0 | BR20: 7 | BS20: 0 | BT20: 0 | BU20: 0 | BV20: 0 | BY20: سعودي | BZ20: أنثى | CA20: 0 | CB20: 0 | CC20: 0 | CD20: 0 | CE20: 0 | CF20: 0 | CG20: 0 | CH20: 0 | CI20: 0 | CJ20: 0 | CK20: 0 | CN20: سعودي | CO20: أنثى | CP20: 0 | CQ20: 0 | CR20: 0 | CS20: 0 | CT20: 0 | CU20: 0 | CV20: 162 | CW20: 0 | CX20: 0 | CY20: 0 | CZ20: 0 | DC20: سعودي | DD20: أنثى | DE20: 0 | DF20: 0 | DG20: 0 | DH20: 0 | DI20: 0 | DJ20: 0 | DK20: 0 | DL20: 0 | DM20: 0 | DN20: 0 | DO20: 0 | DR20: سعودي | DS20: أنثى | DT20: 55 | DU20: 20 | DV20: 17 | DW20: 142 | DX20: 25 | DY20: 18 | DZ20: 20 | EA20: 0 | EB20: 0 | EC20: 0 | ED20: 0 | EG20: سعودي | EH20: أنثى | EI20: 55 | EJ20: 20 | EK20: 17 | EL20: 142 | EM20: 25 | EN20: 18 | EO20: 163 | EP20: 0 | EQ20: 0 | ER20: 0 | ES20: 0 | EV20: سعودي | EW20: أنثى | EX20: 0 | EY20: 0 | EZ20: 0 | FA20: 0 | FB20: 0 | FC20: 0 | FD20: 0 | FE20: 0 | FF20: 0 | FG20: 0 | FH20: 0 | FK20: سعودي | FL20: أنثى | FM20: 0 | FN20: 0 | FO20: 0 | FP20: 0 | FQ20: 0 | FR20: 0 | FS20: 0 | FT20: 0 | FU20: 0 | FV20: 0 | FW20: 0 | FZ20: سعودي | GA20: أنثى | GB20: =SUM(FM20) -> 0 | GC20: =(E20+T20+AI20+AX20+BM20+CB20+CQ20+DF20+DU20+EJ20+EY20+FN20) -> 40 | GD20: =(F20+U20+AJ20+AY20+BN20+CC20+CR20+DG20+DV20+EK20+EZ20+FO20) -> 34 | GE20: =SUM(FP20) -> 0 | GF20: =SUM(FQ20) -> 0 | GG20: =SUM(FR20) -> 0 | GH20: =(J20+Y20+AN20+BC20+BR20+CG20+CV20+DK20+DZ20+EO20+FD20+FS20) -> 490 | GI20: =(K20+Z20+AO20+BD20+BS20+CH20+CW20+DL20+EA20+EP20+FE20+FT20) -> 0 | GJ20: =(L20+AA20+AP20+BE20+BT20+CI20+CX20+DM20+EB20+EQ20+FF20+FU20) -> 170 | GK20: =(M20+AB20+AQ20+BF20+BU20+CJ20+CY20+DN20+EC20+ER20+FG20+FV20) -> 0 | GL20: =(N20+AC20+AR20+BG20+BV20+CK20+CZ20+DO20+ED20+ES20+FH20+FW20) -> 0
B21: المجموع | D21: =SUM(D17:D20) -> 25 | E21: =SUM(E17:E20) -> 0 | F21: =SUM(F17:F20) -> 0 | G21: =SUM(G17:G20) -> 0 | H21: =SUM(H17:H20) -> 170 | I21: =SUM(I17:I20) -> 150 | J21: =SUM(J17:J20) -> 530 | K21: =SUM(K17:K20) -> 0 | ... N21: =SUM(N17:N20) -> 0 | Q21: المجموع | S21: =SUM(S17:S20) -> 0 | T21: =SUM(T17:T20) -> 0 | U21: =SUM(U17:U20) -> 0 | V21: =SUM(V17:V20) -> 0 | W21: =SUM(W17:W20) -> 0 | X21: =SUM(X17:X20) -> 416 | Y21: =SUM(Y17:Y20) -> 134 | Z21: =SUM(Z17:Z20) -> 92 | ... AC21: =SUM(AC17:AC20) -> 0 | AF21: المجموع | AH21: =SUM(AH17:AH20) -> 0 | AI21: =SUM(AI17:AI20) -> 0 | AJ21: =SUM(AJ17:AJ20) -> 0 | AK21: =SUM(AK17:AK20) -> 0 | AL21: =SUM(AL17:AL20) -> 0 | AM21: =SUM(AM17:AM20) -> 0 | AN21: =SUM(AN17:AN20) -> 0 | AO21: =SUM(AO17:AO20) -> 0 | ... AR21: =SUM(AR17:AR20) -> 0 | AU21: المجموع | AW21: =SUM(AW17:AW20) -> 0 | AX21: =SUM(AX17:AX20) -> 0 | AY21: =SUM(AY17:AY20) -> 0 | AZ21: =SUM(AZ17:AZ20) -> 0 | BA21: =SUM(BA17:BA20) -> 0 | BB21: =SUM(BB17:BB20) -> 0 | BC21: =SUM(BC17:BC20) -> 0 | BD21: =SUM(BD17:BD20) -> 0 | ... BG21: =SUM(BG17:BG20) -> 0 | BJ21: المجموع | BL21: =SUM(BL17:BL20) -> 0 | BM21: =SUM(BM17:BM20) -> 0 | BN21: =SUM(BN17:BN20) -> 0 | BO21: =SUM(BO17:BO20) -> 0 | BP21: =SUM(BP17:BP20) -> 0 | BQ21: =SUM(BQ17:BQ20) -> 0 | BR21: =SUM(BR17:BR20) -> 102 | BS21: =SUM(BS17:BS20) -> 0 | ... BV21: =SUM(BV17:BV20) -> 0 | BY21: المجموع | CA21: =SUM(CA17:CA20) -> 0 | CB21: =SUM(CB17:CB20) -> 0 | CC21: =SUM(CC17:CC20) -> 0 | CD21: =SUM(CD17:CD20) -> 0 | CE21: =SUM(CE17:CE20) -> 0 | CF21: =SUM(CF17:CF20) -> 0 | CG21: 0 | CH21: =SUM(CH17:CH20) -> 0 | CI21: =SUM(CI17:CI20) -> 0 | CJ21: =SUM(CJ17:CJ20) -> 0 | CK21: =SUM(CK17:CK20) -> 0 | CN21: المجموع | CP21: 0 | CQ21: 0 | CR21: 0 | CS21: 421 | CT21: 135 | CU21: 92 | CV21: 542 | CW21: 0 | CX21: 0 | CY21: 0 | CZ21: 0 | DC21: المجموع | DE21: =SUM(DE17:DE20) -> 0 | DF21: =SUM(DF17:DF20) -> 0 | DG21: =SUM(DG17:DG20) -> 0 | DH21: =SUM(DH17:DH20) -> 0 | DI21: =SUM(DI17:DI20) -> 0 | DJ21: =SUM(DJ17:DJ20) -> 0 | DK21: =SUM(DK17:DK20) -> 0 | DL21: =SUM(DL17:DL20) -> 0 | ... DO21: =SUM(DO17:DO20) -> 0 | DR21: المجموع | DT21: =SUM(DT17:DT20) -> 216 | DU21: =SUM(DU17:DU20) -> 110 | DV21: =SUM(DV17:DV20) -> 88 | DW21: =SUM(DW17:DW20) -> 2884 | DX21: =SUM(DX17:DX20) -> 112 | DY21: =SUM(DY17:DY20) -> 55 | DZ21: =SUM(DZ17:DZ20) -> 70 | EA21: =SUM(EA17:EA20) -> 0 | ... ED21: =SUM(ED17:ED20) -> 0 | EG21: المجموع | EI21: =SUM(EI17:EI20) -> 216 | EJ21: =SUM(EJ17:EJ20) -> 110 | EK21: =SUM(EK17:EK20) -> 88 | EL21: =SUM(EL17:EL20) -> 2884 | EM21: =SUM(EM17:EM20) -> 112 | EN21: =SUM(EN17:EN20) -> 55 | EO21: =SUM(EO17:EO20) -> 1636 | EP21: =SUM(EP17:EP20) -> 0 | ... ES21: =SUM(ES17:ES20) -> 0 | EV21: المجموع | EX21: =SUM(EX17:EX20) -> 0 | EY21: =SUM(EY17:EY20) -> 0 | EZ21: =SUM(EZ17:EZ20) -> 0 | FA21: =SUM(FA17:FA20) -> 0 | FB21: =SUM(FB17:FB20) -> 0 | FC21: =SUM(FC17:FC20) -> 0 | FD21: =SUM(FD17:FD20) -> 0 | FE21: =SUM(FE17:FE20) -> 0 | ... FH21: =SUM(FH17:FH20) -> 0 | FK21: المجموع | FM21: =SUM(FM17:FM20) -> 0 | FN21: =SUM(FN17:FN20) -> 0 | FO21: =SUM(FO17:FO20) -> 0 | FP21: =SUM(FP17:FP20) -> 0 | FQ21: =SUM(FQ17:FQ20) -> 0 | FR21: =SUM(FR17:FR20) -> 0 | FS21: =SUM(FS17:FS20) -> 0 | FT21: =SUM(FT17:FT20) -> 0 | ... FW21: =SUM(FW17:FW20) -> 0 | FZ21: المجموع | GB21: =SUM(GB17:GB20) -> 0 | GC21: =SUM(GC17:GC20) -> 220 | GD21: =SUM(GD17:GD20) -> 176 | GE21: =SUM(GE17:GE20) -> 0 | GF21: =SUM(GF17:GF20) -> 0 | GG21: =SUM(GG17:GG20) -> 0 | GH21: =SUM(GH17:GH20) -> 3014 | GI21: =SUM(GI17:GI20) -> 92 | ... GL21: =SUM(GL17:GL20) -> 0
B22: عدد الأطفال الذين يقل وزنهم بالنسبة لعمرهم ( تحت المنطقة C في منحنى النمو خلال الشهر | K22: ذكر | L22: 0 | M22: أنثى | N22: 0 | Q22: عدد الأطفال الذين يقل وزنهم بالنسبة لعمرهم ( تحت المنطقة C في منحنى النمو خلال الشهر | Z22: ذكر | AA22: 0 | AB22: أنثى | AC22: 0 | AF22: عدد الأطفال الذين يقل وزنهم بالنسبة لعمرهم ( تحت المنطقة C في منحنى النمو خلال الشهر | AO22: ذكر | AP22: 0 | AQ22: أنثى | AR22: 0 | AU22: عدد الأطفال الذين يقل وزنهم بالنسبة لعمرهم ( تحت المنطقة C في منحنى النمو خلال الشهر | BD22: ذكر | BE22: 0 | BF22: أنثى | BG22: 0 | BJ22: عدد الأطفال الذين يقل وزنهم بالنسبة لعمرهم ( تحت المنطقة C في منحنى النمو خلال الشهر | BS22: ذكر | BT22: 0 | BU22: أنثى | BV22: 0 | BY22: عدد الأطفال الذين يقل وزنهم بالنسبة لعمرهم ( تحت المنطقة C في منحنى النمو خلال الشهر | CH22: ذكر | CI22: 0 | CJ22: أنثى | CK22: 0 | CN22: عدد الأطفال الذين يقل وزنهم بالنسبة لعمرهم ( تحت المنطقة C في منحنى النمو خلال الشهر | CW22: ذكر | CX22: 0 | CY22: أنثى | CZ22: 0 | DC22: عدد الأطفال الذين يقل وزنهم بالنسبة لعمرهم ( تحت المنطقة C في منحنى النمو خلال الشهر | DL22: ذكر | DM22: 0 | DN22: أنثى | DO22: 0 | DR22: عدد الأطفال الذين يقل وزنهم بالنسبة لعمرهم ( تحت المنطقة C في منحنى النمو خلال الشهر | EA22: ذكر | EB22: 0 | EC22: أنثى | ED22: 0 | EG22: عدد الأطفال الذين يقل وزنهم بالنسبة لعمرهم ( تحت المنطقة C في منحنى النمو خلال الشهر | EP22: ذكر | EQ22: 0 | ER22: أنثى | ES22: 0 | EV22: عدد الأطفال الذين يقل وزنهم بالنسبة لعمرهم ( تحت المنطقة C في منحنى النمو خلال الشهر | FE22: ذكر | FF22: 0 | FG22: أنثى | FH22: 0 | FK22: عدد الأطفال الذين يقل وزنهم بالنسبة لعمرهم ( تحت المنطقة C في منحنى النمو خلال الشهر | FT22: ذكر | FU22: 0 | FV22: أنثى | FW22: 0 | FZ22: عدد الأطفال الذين يقل وزنهم بالنسبة لعمرهم ( تحت المنطقة C في منحنى النمو خلال العام | GI22: ذكر | GJ22: =(L22+AA22+AP22+BE22+BT22+CI22+CX22+DM22+EB22+EQ22+FF22+FU22) -> 0 | GK22: أنثى | GL22: =(N22+AC22+AR22+BG22+BV22+CK22+CZ22+DO22+ED22+ES22+FH22+FW22) -> 0
A23: المطار القديم | B23: سعودي | C23: ذكر | D23: 4 | E23: 1 | F23: 0 | G23: 218 | H23: 91 | I23: 0 | J23: 120 | K23: 0 | L23: 0 | M23: 0 | N23: 0 | P23: المطار القديم | Q23: سعودي | R23: ذكر | S23: 4 | T23: 1 | U23: 0 | V23: 218 | W23: 91 | X23: 0 | Y23: 209 | Z23: 0 | AA23: 0 | AB23: 0 | AC23: 0 | AE23: المطار القديم | AF23: سعودي | AG23: ذكر | AH23: 10 | AI23: 6 | AJ23: 0 | AK23: 215 | AL23: 51 | AM23: 149 | AN23: 201 | AO23: 0 | AP23: 0 | AQ23: 0 | AR23: 0 | AT23: المطار القديم | AU23: سعودي | AV23: ذكر | AW23: 0 | AX23: 0 | AY23: 0 | AZ23: 0 | BA23: 0 | BB23: 0 | BC23: 0 | BD23: 0 | BE23: 0 | BF23: 0 | BG23: 0 | BI23: المطار القديم | BJ23: سعودي | BK23: ذكر | BL23: 0 | BM23: 0 | BN23: 0 | BO23: 0 | BP23: 0 | BQ23: 0 | BR23: 99 | BS23: 0 | BT23: 0 | BU23: 0 | BV23: 0 | BX23: المطار القديم | BY23: سعودي | BZ23: ذكر | CA23: 0 | CB23: 0 | CC23: 0 | CD23: 0 | CE23: 0 | CF23: 0 | CG23: 0 | CH23: 0 | CI23: 0 | CJ23: 0 | CK23: 0 | CM23: المطار القديم | CN23: سعودي | CO23: ذكر | CP23: 4 | CQ23: 1 | CR23: 0 | CS23: 218 | CT23: 91 | CU23: 0 | CV23: 136 | CW23: 0 | CX23: 0 | CY23: 0 | CZ23: 0 | DB23: المطار القديم | DC23: سعودي | DD23: ذكر | DE23: 10 | DF23: 1 | DG23: 200 | DH23: 16 | DI23: 0 | DJ23: 0 | DK23: 101 | DL23: 99 | DM23: 0 | DN23: 0 | DO23: 0 | DQ23: المطار القديم | DR23: سعودي | DS23: ذكر | DT23: 50 | DU23: 35 | DV23: 25 | DW23: 1364 | DX23: 34 | DY23: 14 | DZ23: 19 | EA23: 0 | EB23: 0 | EC23: 0 | ED23: 0 | EF23: المطار القديم | EG23: سعودي | EH23: ذكر | EI23: 50 | EJ23: 35 | EK23: 25 | EL23: 1364 | EM23: 34 | EN23: 14 | EO23: 19 | EP23: 0 | EQ23: 0 | ER23: 0 | ES23: 0 | EU23: المطار القديم | EV23: سعودي | EW23: ذكر | EX23: 0 | EY23: 0 | EZ23: 0 | FA23: 0 | FB23: 0 | FC23: 0 | FD23: 0 | FE23: 0 | FF23: 0 | FG23: 0 | FH23: 0 | FJ23: المطار القديم | FK23: سعودي | FL23: ذكر | FM23: 0 | FN23: 0 | FO23: 0 | FP23: 0 | FQ23: 0 | FR23: 0 | FS23: 0 | FT23: 0 | FU23: 0 | FV23: 0 | FW23: 0 | FY23: =(FJ23) -> المطار القديم | FZ23: سعودي | GA23: ذكر | GB23: =SUM(FM23) -> 0 | GC23: =(E23+T23+AI23+AX23+BM23+CB23+CQ23+DF23+DU23+EJ23+EY23+FN23) -> 80 | GD23: =(F23+U23+AJ23+AY23+BN23+CC23+CR23+DG23+DV23+EK23+EZ23+FO23) -> 250 | GE23: =SUM(FP23) -> 0 | GF23: =SUM(FQ23) -> 0 | GG23: =SUM(FR23) -> 0 | GH23: =(J23+Y23+AN23+BC23+BR23+CG23+CV23+DK23+DZ23+EO23+FD23+FS23) -> 904 | GI23: =(K23+Z23+AO23+BD23+BS23+CH23+CW23+DL23+EA23+EP23+FE23+FT23) -> 99 | GJ23: =(L23+AA23+AP23+BE23+BT23+CI23+CX23+DM23+EB23+EQ23+FF23+FU23) -> 0 | GK23: =(M23+AB23+AQ23+BF23+BU23+CJ23+CY23+DN23+EC23+ER23+FG23+FV23) -> 0 | GL23: =(N23+AC23+AR23+BG23+BV23+CK23+CZ23+DO23+ED23+ES23+FH23+FW23) -> 0
C24: أنثى | D24: 2 | E24: 0 | F24: 0 | G24: 88 | H24: 52 | I24: 0 | J24: 199 | K24: 0 | L24: 0 | M24: 0 | N24: 0 | R24: أنثى | S24: 2 | T24: 0 | U24: 0 | V24: 88 | W24: 52 | X24: 0 | Y24: 319 | Z24: 0 | AA24: 0 | AB24: 0 | AC24: 0 | AG24: أنثى | AH24: 2 | AI24: 19 | AJ24: 0 | AK24: 128 | AL24: 13 | AM24: 183 | AN24: 115 | AO24: 0 | AP24: 0 | AQ24: 0 | AR24: 0 | AV24: أنثى | AW24: 0 | AX24: 0 | AY24: 0 | AZ24: 0 | BA24: 0 | BB24: 0 | BC24: 0 | BD24: 0 | BE24: 0 | BF24: 0 | BG24: 0 | BK24: أنثى | BL24: 0 | BM24: 0 | BN24: 0 | BO24: 0 | BP24: 0 | BQ24: 0 | BR24: 110 | BS24: 0 | BT24: 0 | BU24: 0 | BV24: 0 | BZ24: أنثى | CA24: 0 | CB24: 0 | CC24: 0 | CD24: 0 | CE24: 0 | CF24: 0 | CG24: 0 | CH24: 0 | CI24: 0 | CJ24: 0 | CK24: 0 | CO24: أنثى | CP24: 2 | CQ24: 0 | CR24: 0 | CS24: 88 | CT24: 52 | CU24: 0 | CV24: 200 | CW24: 0 | CX24: 0 | CY24: 0 | CZ24: 0 | DD24: أنثى | DE24: 20 | DF24: 0 | DG24: 90 | DH24: 0 | DI24: 0 | DJ24: 0 | DK24: 60 | DL24: 100 | DM24: 0 | DN24: 0 | DO24: 0 | DS24: أنثى | DT24: 72 | DU24: 19 | DV24: 18 | DW24: 1328 | DX24: 15 | DY24: 18 | DZ24: 12 | EA24: 0 | EB24: 0 | EC24: 0 | ED24: 0 | EH24: أنثى | EI24: 72 | EJ24: 19 | EK24: 18 | EL24: 1328 | EM24: 15 | EN24: 18 | EO24: 9 | EP24: 0 | EQ24: 0 | ER24: 0 | ES24: 0 | EW24: أنثى | EX24: 0 | EY24: 0 | EZ24: 0 | FA24: 0 | FB24: 0 | FC24: 0 | FD24: 0 | FE24: 0 | FF24: 0 | FG24: 0 | FH24: 0 | FL24: أنثى | FM24: 0 | FN24: 0 | FO24: 0 | FP24: 0 | FQ24: 0 | FR24: 0 | FS24: 0 | FT24: 0 | FU24: 0 | FV24: 0 | FW24: 0 | GA24: أنثى | GB24: =SUM(FM24) -> 0 | GC24: =(E24+T24+AI24+AX24+BM24+CB24+CQ24+DF24+DU24+EJ24+EY24+FN24) -> 57 | GD24: =(F24+U24+AJ24+AY24+BN24+CC24+CR24+DG24+DV24+EK24+EZ24+FO24) -> 126 | GE24: =SUM(FP24) -> 0 | GF24: =SUM(FQ24) -> 0 | GG24: =SUM(FR24) -> 0 | GH24: =(J24+Y24+AN24+BC24+BR24+CG24+CV24+DK24+DZ24+EO24+FD24+FS24) -> 1024 | GI24: =(K24+Z24+AO24+BD24+BS24+CH24+CW24+DL24+EA24+EP24+FE24+FT24) -> 100 | GJ24: =(L24+AA24+AP24+BE24+BT24+CI24+CX24+DM24+EB24+EQ24+FF24+FU24) -> 0 | GK24: =(M24+AB24+AQ24+BF24+BU24+CJ24+CY24+DN24+EC24+ER24+FG24+FV24) -> 0 | GL24: =(N24+AC24+AR24+BG24+BV24+CK24+CZ24+DO24+ED24+ES24+FH24+FW24) -> 0
B25: غير | C25: ذكر | D25: 0 | E25: 0 | F25: 0 | G25: 0 | H25: 0 | I25: 0 | J25: 52 | K25: 0 | L25: 0 | M25: 0 | N25: 0 | Q25: غير | R25: ذكر | S25: 0 | T25: 0 | U25: 0 | V25: 0 | W25: 0 | X25: 0 | Y25: 0 | Z25: 0 | AA25: 0 | AB25: 0 | AC25: 0 | AF25: غير | AG25: ذكر | AH25: 3 | AI25: 2 | AJ25: 0 | AK25: 18 | AL25: 2 | AM25: 101 | AN25: 103 | AO25: 0 | AP25: 0 | AQ25: 0 | AR25: 0 | AU25: غير | AV25: ذكر | AW25: 0 | AX25: 0 | AY25: 0 | AZ25: 0 | BA25: 0 | BB25: 0 | BC25: 0 | BD25: 0 | BE25: 0 | BF25: 0 | BG25: 0 | BJ25: غير | BK25: ذكر | BL25: 0 | BM25: 0 | BN25: 0 | BO25: 0 | BP25: 0 | BQ25: 0 | BR25: 100 | BS25: 0 | BT25: 0 | BU25: 0 | BV25: 0 | BY25: غير | BZ25: ذكر | CA25: 0 | CB25: 0 | CC25: 0 | CD25: 0 | CE25: 0 | CF25: 0 | CG25: 0 | CH25: 0 | CI25: 0 | CJ25: 0 | CK25: 0 | CN25: غير | CO25: ذكر | CP25: 0 | CQ25: 0 | CR25: 0 | CS25: 0 | CT25: 0 | CU25: 0 | CV25: 36 | CW25: 0 | CX25: 0 | CY25: 0 | CZ25: 0 | DC25: غير | DD25: ذكر | DE25: 0 | DF25: 0 | DG25: 3 | DH25: 0 | DI25: 0 | DJ25: 0 | DK25: 18 | DL25: 9 | DM25: 0 | DN25: 0 | DO25: 0 | DR25: غير | DS25: ذكر | DT25: 61 | DU25: 22 | DV25: 16 | DW25: 33 | DX25: 25 | DY25: 22 | DZ25: 23 | EA25: 0 | EB25: 0 | EC25: 0 | ED25: 0 | EG25: غير | EH25: ذكر | EI25: 61 | EJ25: 22 | EK25: 16 | EL25: 33 | EM25: 25 | EN25: 22 | EO25: 4 | EP25: 0 | EQ25: 0 | ER25: 0 | ES25: 0 | EV25: غير | EW25: ذكر | EX25: 0 | EY25: 0 | EZ25: 0 | FA25: 0 | FB25: 0 | FC25: 0 | FD25: 0 | FE25: 0 | FF25: 0 | FG25: 0 | FH25: 0 | FK25: غير | FL25: ذكر | FM25: 0 | FN25: 0 | FO25: 0 | FP25: 0 | FQ25: 0 | FR25: 0 | FS25: 0 | FT25: 0 | FU25: 0 | FV25: 0 | FW25: 0 | FZ25: غير | GA25: ذكر | GB25: =SUM(FM25) -> 0 | GC25: =(E25+T25+AI25+AX25+BM25+CB25+CQ25+DF25+DU25+EJ25+EY25+FN25) -> 46 | GD25: =(F25+U25+AJ25+AY25+BN25+CC25+CR25+DG25+DV25+EK25+EZ25+FO25) -> 35 | GE25: =SUM(FP25) -> 0 | GF25: =SUM(FQ25) -> 0 | GG25: =SUM(FR25) -> 0 | GH25: =(J25+Y25+AN25+BC25+BR25+CG25+CV25+DK25+DZ25+EO25+FD25+FS25) -> 336 | GI25: =(K25+Z25+AO25+BD25+BS25+CH25+CW25+DL25+EA25+EP25+FE25+FT25) -> 9 | GJ25: =(L25+AA25+AP25+BE25+BT25+CI25+CX25+DM25+EB25+EQ25+FF25+FU25) -> 0 | GK25: =(M25+AB25+AQ25+BF25+BU25+CJ25+CY25+DN25+EC25+ER25+FG25+FV25) -> 0 | GL25: =(N25+AC25+AR25+BG25+BV25+CK25+CZ25+DO25+ED25+ES25+FH25+FW25) -> 0
B26: سعودي | C26: أنثى | D26: 0 | E26: 0 | F26: 0 | G26: 0 | H26: 0 | I26: 0 | J26: 40 | K26: 0 | L26: 0 | M26: 0 | N26: 0 | Q26: سعودي | R26: أنثى | S26: 0 | T26: 0 | U26: 0 | V26: 0 | W26: 0 | X26: 0 | Y26: 0 | Z26: 0 | AA26: 0 | AB26: 0 | AC26: 0 | AF26: سعودي | AG26: أنثى | AH26: 9 | AI26: 1 | AJ26: 0 | AK26: 0 | AL26: 0 | AM26: 119 | AN26: 99 | AO26: 0 | AP26: 0 | AQ26: 0 | AR26: 0 | AU26: سعودي | AV26: أنثى | AW26: 0 | AX26: 0 | AY26: 0 | AZ26: 0 | BA26: 0 | BB26: 0 | BC26: 0 | BD26: 0 | BE26: 0 | BF26: 0 | BG26: 0 | BJ26: سعودي | BK26: أنثى | BL26: 0 | BM26: 0 | BN26: 0 | BO26: 0 | BP26: 0 | BQ26: 0 | BR26: 90 | BS26: 0 | BT26: 0 | BU26: 0 | BV26: 0 | BY26: سعودي | BZ26: أنثى | CA26: 0 | CB26: 0 | CC26: 0 | CD26: 0 | CE26: 0 | CF26: 0 | CG26: 0 | CH26: 0 | CI26: 0 | CJ26: 0 | CK26: 0 | CN26: سعودي | CO26: أنثى | CP26: 0 | CQ26: 0 | CR26: 0 | CS26: 0 | CT26: 0 | CU26: 0 | CV26: 40 | CW26: 0 | CX26: 0 | CY26: 0 | CZ26: 0 | DC26: سعودي | DD26: أنثى | DE26: 0 | DF26: 0 | DG26: 1 | DH26: 0 | DI26: 0 | DJ26: 0 | DK26: 10 | DL26: 7 | DM26: 0 | DN26: 0 | DO26: 0 | DR26: سعودي | DS26: أنثى | DT26: 44 | DU26: 15 | DV26: 11 | DW26: 44 | DX26: 42 | DY26: 11 | DZ26: 15 | EA26: 0 | EB26: 0 | EC26: 0 | ED26: 0 | EG26: سعودي | EH26: أنثى | EI26: 44 | EJ26: 15 | EK26: 11 | EL26: 44 | EM26: 42 | EN26: 11 | EO26: 1 | EP26: 0 | EQ26: 0 | ER26: 0 | ES26: 0 | EV26: سعودي | EW26: أنثى | EX26: 0 | EY26: 0 | EZ26: 0 | FA26: 0 | FB26: 0 | FC26: 0 | FD26: 0 | FE26: 0 | FF26: 0 | FG26: 0 | FH26: 0 | FK26: سعودي | FL26: أنثى | FM26: 0 | FN26: 0 | FO26: 0 | FP26: 0 | FQ26: 0 | FR26: 0 | FS26: 0 | FT26: 0 | FU26: 0 | FV26: 0 | FW26: 0 | FZ26: سعودي | GA26: أنثى | GB26: =SUM(FM26) -> 0 | GC26: =(E26+T26+AI26+AX26+BM26+CB26+CQ26+DF26+DU26+EJ26+EY26+FN26) -> 31 | GD26: =(F26+U26+AJ26+AY26+BN26+CC26+CR26+DG26+DV26+EK26+EZ26+FO26) -> 23 | GE26: =SUM(FP26) -> 0 | GF26: =SUM(FQ26) -> 0 | GG26: =SUM(FR26) -> 0 | GH26: =(J26+Y26+AN26+BC26+BR26+CG26+CV26+DK26+DZ26+EO26+FD26+FS26) -> 295 | GI26: =(K26+Z26+AO26+BD26+BS26+CH26+CW26+DL26+EA26+EP26+FE26+FT26) -> 7 | GJ26: =(L26+AA26+AP26+BE26+BT26+CI26+CX26+DM26+EB26+EQ26+FF26+FU26) -> 0 | GK26: =(M26+AB26+AQ26+BF26+BU26+CJ26+CY26+DN26+EC26+ER26+FG26+FV26) -> 0 | GL26: =(N26+AC26+AR26+BG26+BV26+CK26+CZ26+DO26+ED26+ES26+FH26+FW26) -> 0
