Workbook

Sheet الأمراض المزمنة
F2: شهر | G2: 1 | H2: عام | I2: 1447 | N2: مراجعي الأمراض المزمنة | V2: شهر | W2: 2 | X2: عام | Y2: 1447 | AD2: مراجعي الأمراض المزمنة | AL2: شهر | AM2: 3 | AN2: عام | AO2: 1447 | AT2: مراجعي الأمراض المزمنة | BB2: شهر | BC2: 4 | BD2: عام | BE2: 1447 | BJ2: مراجعي الأمراض المزمنة | BR2: شهر | BS2: 5 | BT2: عام | BU2: 1447 | BZ2: مراجعي الأمراض المزمنة | CH2: شهر | CI2: 6 | CJ2: عام | CK2: 1447 | CP2: مراجعي الأمراض المزمنة | CX2: شهر | CY2: 7 | CZ2: عام | DA2: 1447 | DF2: مراجعي الأمراض المزمنة | DN2: شهر | DO2: 8 | DP2: عام | DQ2: 1447 | DV2: مراجعي الأمراض المزمنة | ED2: شهر | EE2: 9 | EF2: عام | EG2: 1447 | EL2: مراجعي الأمراض المزمنة | ET2: شهر | EU2: 10 | EV2: عام | EW2: 1447 | FB2: مراجعي الأمراض المزمنة | FJ2: شهر | FK2: 11 | FL2: عام | FM2: 1447 | FR2: مراجعي الأمراض المزمنة | FZ2: شهر | GA2: 12 | GB2: عام | GC2: 1447 | GH2: مراجعي الأمراض المزمنة | GS2: عام | GT2: =SUM(GC2) -> 1447 | GX2: مراجعي الأمراض المزمنة
A3: المركز الصحي | B3: الجنسية | C3: الجنس | D3: مرضى السكري | H3: مرضى ضغط الدم | L3: مرضى الربو | Q3: المركز الصحي | R3: الجنسية | S3: الجنس | T3: مرضى السكري | X3: مرضى ضغط الدم | AB3: مرضى الربو | AG3: المركز الصحي | AH3: الجنسية | AI3: الجنس | AJ3: مرضى السكري | AN3: مرضى ضغط الدم | AR3: مرضى الربو | AW3: المركز الصحي | AX3: الجنسية | AY3: الجنس | AZ3: مرضى السكري | BD3: مرضى ضغط الدم | BH3: مرضى الربو | BM3: المركز الصحي | BN3: الجنسية | BO3: الجنس | BP3: مرضى السكري | BT3: مرضى ضغط الدم | BX3: مرضى الربو | CC3: المركز الصحي | CD3: الجنسية | CE3: الجنس | CF3: مرضى السكري | CJ3: مرضى ضغط الدم | CN3: مرضى الربو | CS3: المركز الصحي | CT3: الجنسية | CU3: الجنس | CV3: مرضى السكري | CZ3: مرضى ضغط الدم | DD3: مرضى الربو | DI3: المركز الصحي | DJ3: الجنسية | DK3: الجنس | DL3: مرضى السكري | DP3: مرضى ضغط الدم | DT3: مرضى الربو | DY3: المركز الصحي | DZ3: الجنسية | EA3: الجنس | EB3: مرضى السكري | EF3: مرضى ضغط الدم | EJ3: مرضى الربو | EO3: المركز الصحي | EP3: الجنسية | EQ3: الجنس | ER3: مرضى السكري | EV3: مرضى ضغط الدم | EZ3: مرضى الربو | FE3: المركز الصحي | FF3: الجنسية | FG3: الجنس | FH3: مرضى السكري | FL3: مرضى ضغط الدم | FP3: مرضى الربو | FU3: المركز الصحي | FV3: الجنسية | FW3: الجنس | FX3: مرضى السكري | GB3: مرضى ضغط الدم | GF3: مرضى الربو | GK3: المركز الصحي | GL3: الجنسية | GM3: الجنس | GN3: مرضى السكري | GR3: مرضى ضغط الدم | GV3: مرضى الربو
D4: المسجلين | E4: الجدد | F4: المحالين | G4: عدد الزيارات خلال الشهر | H4: المسجلين | I4: الجدد | J4: المحالين | K4: عدد الزيارات خلال الشهر | L4: المسجلين | M4: الجدد | N4: المحالين | O4: عدد الزيارات خلال الشهر | T4: المسجلين | U4: الجدد | V4: المحالين | W4: عدد الزيارات خلال الشهر | X4: المسجلين | Y4: الجدد | Z4: المحالين | AA4: عدد الزيارات خلال الشهر | AB4: المسجلين | AC4: الجدد | AD4: المحالين | AE4: عدد الزيارات خلال الشهر | AJ4: المسجلين | AK4: الجدد | AL4: المحالين | AM4: عدد الزيارات خلال الشهر | AN4: المسجلين | AO4: الجدد | AP4: المحالين | AQ4: عدد الزيارات خلال الشهر | AR4: المسجلين | AS4: الجدد | AT4: المحالين | AU4: عدد الزيارات خلال الشهر | AZ4: المسجلين | BA4: الجدد | BB4: المحالين | BC4: عدد الزيارات خلال الشهر | BD4: المسجلين | BE4: الجدد | BF4: المحالين | BG4: عدد الزيارات خلال الشهر | BH4: المسجلين | BI4: الجدد | BJ4: المحالين | BK4: عدد الزيارات خلال الشهر | BP4: المسجلين | BQ4: الجدد | BR4: المحالين | BS4: عدد الزيارات خلال الشهر | BT4: المسجلين | BU4: الجدد | BV4: المحالين | BW4: عدد الزيارات خلال الشهر | BX4: المسجلين | BY4: الجدد | BZ4: المحالين | CA4: عدد الزيارات خلال الشهر | CF4: المسجلين | CG4: الجدد | CH4: المحالين | CI4: عدد الزيارات خلال الشهر | CJ4: المسجلين | CK4: الجدد | CL4: المحالين | CM4: عدد الزيارات خلال الشهر | CN4: المسجلين | CO4: الجدد | CP4: المحالين | CQ4: عدد الزيارات خلال الشهر | CV4: المسجلين | CW4: الجدد | CX4: المحالين | CY4: عدد الزيارات خلال الشهر | CZ4: المسجلين | DA4: الجدد | DB4: المحالين | DC4: عدد الزيارات خلال الشهر | DD4: المسجلين | DE4: الجدد | DF4: المحالين | DG4: عدد الزيارات خلال الشهر | DL4: المسجلين | DM4: الجدد | DN4: المحالين | DO4: عدد الزيارات خلال الشهر | DP4: المسجلين | DQ4: الجدد | DR4: المحالين | DS4: عدد الزيارات خلال الشهر | DT4: المسجلين | DU4: الجدد | DV4: المحالين | DW4: عدد الزيارات خلال الشهر | EB4: المسجلين | EC4: الجدد | ED4: المحالين | EE4: عدد الزيارات خلال الشهر | EF4: المسجلين | EG4: الجدد | EH4: المحالين | EI4: عدد الزيارات خلال الشهر | EJ4: المسجلين | EK4: الجدد | EL4: المحالين | EM4: عدد الزيارات خلال الشهر | ER4: المسجلين | ES4: الجدد | ET4: المحالين | EU4: عدد الزيارات خلال الشهر | EV4: المسجلين | EW4: الجدد | EX4: المحالين | EY4: عدد الزيارات خلال الشهر | EZ4: المسجلين | FA4: الجدد | FB4: المحالين | FC4: عدد الزيارات خلال الشهر | FH4: المسجلين | FI4: الجدد | FJ4: المحالين | FK4: عدد الزيارات خلال الشهر | FL4: المسجلين | FM4: الجدد | FN4: المحالين | FO4: عدد الزيارات خلال الشهر | FP4: المسجلين | FQ4: الجدد | FR4: المحالين | FS4: عدد الزيارات خلال الشهر | FX4: المسجلين | FY4: الجدد | FZ4: المحالين | GA4: عدد الزيارات خلال الشهر | GB4: المسجلين | GC4: الجدد | GD4: المحالين | GE4: عدد الزيارات خلال الشهر | GF4: المسجلين | GG4: الجدد | GH4: المحالين | GI4: عدد الزيارات خلال الشهر | GN4: المسجلين | GO4: الجدد | GP4: المحالين | GQ4: عدد الزيارات خلال العام | GR4: المسجلين | GS4: الجدد | GT4: المحالين | GU4: عدد الزيارات خلال العام | GV4: المسجلين | GW4: الجدد | GX4: المحالين | GY4: عدد الزيارات خلال العام
A5: الربيع والتوفيق | C5: ذكر | D5: 270 | E5: 2 | F5: 0 | G5: 150 | H5: 324 | I5: 0 | J5: 0 | K5: 100 | L5: 4 | M5: 0 | N5: 0 | O5: 0 | Q5: الربيع والتوفيق | S5: ذكر | T5: 275 | U5: 2 | V5: 11 | W5: 145 | X5: 239 | Y5: 3 | Z5: 11 | AA5: 108 | AB5: 28 | AC5: 0 | AD5: 0 | AE5: 2 | AG5: الربيع والتوفيق | AI5: ذكر | AJ5: 289 | AK5: 2 | AL5: 7 | AM5: 156 | AN5: 249 | AO5: 1 | AP5: 7 | AQ5: 143 | AR5: 28 | AS5: 0 | AT5: 0 | AU5: 2 | AW5: الربيع والتوفيق | AY5: ذكر | AZ5: 285 | BA5: 2 | BB5: 10 | BC5: 169 | BD5: 248 | BE5: 0 | BF5: 6 | BG5: 110 | BH5: 28 | BI5: 0 | BJ5: 0 | BK5: 0 | BM5: الربيع والتوفيق | BO5: ذكر | BP5: 289 | BQ5: 3 | BR5: 11 | BS5: 46 | BT5: 248 | BU5: 1501 | BV5: 9 | BW5: 33 | BX5: 28 | BY5: 1 | BZ5: 0 | CA5: 0 | CC5: الربيع والتوفيق | CE5: ذكر | CF5: 0 | CG5: 0 | CH5: 0 | CI5: 0 | CJ5: 0 | CK5: 0 | CL5: 0 | CM5: 0 | CN5: 0 | CO5: 0 | CP5: 0 | CQ5: 0 | CS5: الربيع والتوفيق | CU5: ذكر | CV5: 272 | CW5: 3 | CX5: 18 | CY5: 191 | CZ5: 237 | DA5: 2 | DB5: 16 | DC5: 101 | DD5: 4 | DE5: 1 | DF5: 0 | DG5: 2 | DI5: الربيع والتوفيق | DK5: ذكر | DL5: 289 | DM5: 1 | DN5: 5 | DO5: 88 | DP5: 284 | DQ5: 0 | DR5: 5 | DS5: 85 | DT5: 28 | DU5: 0 | DV5: 0 | DW5: 0 | DY5: الربيع والتوفيق | EA5: ذكر | EB5: 387 | EC5: 4 | ED5: 9 | EE5: 199 | EF5: 301 | EG5: 1 | EH5: 19 | EI5: 269 | EJ5: 7 | EK5: 0 | EL5: 0 | EM5: 1 | EO5: الربيع والتوفيق | EQ5: ذكر | ER5: 387 | ES5: 4 | ET5: 9 | EU5: 66 | EV5: 301 | EW5: 1 | EX5: 19 | EY5: 69 | EZ5: 7 | FA5: 0 | FB5: 0 | FC5: 0 | FE5: الربيع والتوفيق | FG5: ذكر | FH5: 0 | FI5: 0 | FJ5: 0 | FK5: 0 | FL5: 0 | FM5: 0 | FN5: 0 | FO5: 0 | FP5: 0 | FQ5: 0 | FR5: 0 | FS5: 0 | FU5: الربيع والتوفيق | FW5: ذكر | FX5: 0 | FY5: 0 | FZ5: 0 | GA5: 0 | GB5: 0 | GC5: 0 | GD5: 0 | GE5: 0 | GF5: 0 | GG5: 0 | GH5: 0 | GI5: 0 | GK5: =FU5 -> الربيع والتوفيق | GM5: ذكر | GN5: =FX5 -> 0 | GO5: =E5+U5+AK5+BA5+BQ5+CG5++CW5+DM5+EC5+ES5+FI5+FY5 -> 23 | GP5: =F5+V5+AL5+BB5+BR5+CH5++CX5+DN5+ED5+ET5+FJ5+FZ5 -> 80 | GQ5: =G5+W5+AM5+BC5+BS5+CI5++CY5+DO5+EE5+EU5+FK5+GA5 -> 1210 | GR5: =GB5 -> 0 | GS5: =I5+Y5+AO5+BE5+BU5+CK5++DA5+DQ5+EG5+EW5+FM5+GC5 -> 1509 | GT5: =J5+Z5+AP5+BF5+BV5+CL5++DB5+DR5+EH5+EX5+FN5+GD5 -> 92 | GU5: =K5+AA5+AQ5+BG5+BW5+CM5++DC5+DS5+EI5+EY5+FO5+GE5 -> 1018 | GV5: =GF5 -> 0 | GW5: =M5+AC5+AS5+BI5+BY5+CO5++DE5+DU5+EK5+FA5+FQ5+GG5 -> 2 | GX5: =N5+AD5+AT5+BJ5+BZ5+CP5++DF5+DV5+EL5+FB5+FR5+GH5 -> 0 | GY5: =O5+AE5+AU5+BK5+CA5+CQ5++DG5+DW5+EM5+FC5+FS5+GI5 -> 7
B6: سعودي | C6: أنثى | D6: 209 | E6: 3 | F6: 0 | G6: 120 | H6: 206 | I6: 0 | J6: 0 | K6: 80 | L6: 4 | M6: 0 | N6: 0 | O6: 0 | R6: سعودي | S6: أنثى | T6: 209 | U6: 0 | V6: 13 | W6: 177 | X6: 206 | Y6: 0 | Z6: 7 | AA6: 148 | AB6: 8 | AC6: 0 | AD6: 0 | AE6: 0 | AH6: سعودي | AI6: أنثى | AJ6: 217 | AK6: 1 | AL6: 8 | AM6: 97 | AN6: 209 | AO6: 0 | AP6: 5 | AQ6: 123 | AR6: 9 | AS6: 0 | AT6: 0 | AU6: 0 | AX6: سعودي | AY6: أنثى | AZ6: 214 | BA6: 2 | BB6: 9 | BC6: 155 | BD6: 208 | BE6: 1 | BF6: 0 | BG6: 133 | BH6: 8 | BI6: 1 | BJ6: 0 | BK6: 1 | BN6: سعودي | BO6: أنثى | BP6: 219 | BQ6: 2 | BR6: 10 | BS6: 56 | BT6: 208 | BU6: 1 | BV6: 6 | BW6: 29 | BX6: 8 | BY6: 0 | BZ6: 0 | CA6: 0 | CD6: سعودي | CE6: أنثى | CF6: 0 | CG6: 0 | CH6: 0 | CI6: 0 | CJ6: 0 | CK6: 0 | CL6: 0 | CM6: 0 | CN6: 0 | CO6: 0 | CP6: 0 | CQ6: 0 | CT6: سعودي | CU6: أنثى | CV6: 209 | CW6: 0 | CX6: 15 | CY6: 219 | CZ6: 206 | DA6: 0 | DB6: 11 | DC6: 94 | DD6: 3 | DE6: 1 | DF6: 0 | DG6: 0 | DJ6: سعودي | DK6: أنثى | DL6: 233 | DM6: 0 | DN6: 3 | DO6: 58 | DP6: 243 | DQ6: 0 | DR6: 4 | DS6: 67 | DT6: 8 | DU6: 0 | DV6: 0 | DW6: 0 | DZ6: سعودي | EA6: أنثى | EB6: 275 | EC6: 3 | ED6: 7 | EE6: 98 | EF6: 266 | EG6: 3 | EH6: 12 | EI6: 132 | EJ6: 13 | EK6: 0 | EL6: 0 | EM6: 0 | EP6: سعودي | EQ6: أنثى | ER6: 275 | ES6: 3 | ET6: 7 | EU6: 90 | EV6: 266 | EW6: 3 | EX6: 12 | EY6: 80 | EZ6: 13 | FA6: 0 | FB6: 0 | FC6: 0 | FF6: سعودي | FG6: أنثى | FH6: 0 | FI6: 0 | FJ6: 0 | FK6: 0 | FL6: 0 | FM6: 0 | FN6: 0 | FO6: 0 | FP6: 0 | FQ6: 0 | FR6: 0 | FS6: 0 | FV6: سعودي | FW6: أنثى | FX6: 0 | FY6: 0 | FZ6: 0 | GA6: 0 | GB6: 0 | GC6: 0 | GD6: 0 | GE6: 0 | GF6: 0 | GG6: 0 | GH6: 0 | GI6: 0 | GL6: سعودي | GM6: أنثى | GN6: =FX6 -> 0 | GO6: =E6+U6+AK6+BA6+BQ6+CG6++CW6+DM6+EC6+ES6+FI6+FY6 -> 14 | GP6: =F6+V6+AL6+BB6+BR6+CH6++CX6+DN6+ED6+ET6+FJ6+FZ6 -> 72 | GQ6: =G6+W6+AM6+BC6+BS6+CI6++CY6+DO6+EE6+EU6+FK6+GA6 -> 1070 | GR6: =GB6 -> 0 | GS6: =I6+Y6+AO6+BE6+BU6+CK6++DA6+DQ6+EG6+EW6+FM6+GC6 -> 8 | GT6: =J6+Z6+AP6+BF6+BV6+CL6++DB6+DR6+EH6+EX6+FN6+GD6 -> 57 | GU6: =K6+AA6+AQ6+BG6+BW6+CM6++DC6+DS6+EI6+EY6+FO6+GE6 -> 886 | GV6: =GF6 -> 0 | GW6: =M6+AC6+AS6+BI6+BY6+CO6++DE6+DU6+EK6+FA6+FQ6+GG6 -> 2 | GX6: =N6+AD6+AT6+BJ6+BZ6+CP6++DF6+DV6+EL6+FB6+FR6+GH6 -> 0 | GY6: =O6+AE6+AU6+BK6+CA6+CQ6++DG6+DW6+EM6+FC6+FS6+GI6 -> 1
B7: غير | C7: ذكر | D7: 0 | E7: 0 | F7: 0 | G7: 0 | H7: 0 | I7: 0 | J7: 0 | K7: 0 | L7: 0 | M7: 0 | N7: 0 | O7: 0 | R7: غير | S7: ذكر | T7: 177 | U7: 0 | V7: 0 | W7: 27 | X7: 114 | Y7: 0 | Z7: 0 | AA7: 19 | AB7: 3 | AC7: 0 | AD7: 0 | AE7: 0 | AH7: غير | AI7: ذكر | AJ7: 177 | AK7: 0 | AL7: 0 | AM7: 31 | AN7: 114 | AO7: 0 | AP7: 0 | AQ7: 12 | AR7: 3 | AS7: 0 | AT7: 0 | AU7: 0 | AX7: غير | AY7: ذكر | AZ7: 177 | BA7: 3 | BB7: 0 | BC7: 28 | BD7: 119 | BE7: 3 | BF7: 1 | BG7: 23 | BH7: 3 | BI7: 0 | BJ7: 0 | BK7: 0 | BN7: غير | BO7: ذكر | BP7: 177 | BQ7: 2 | BR7: 3 | BS7: 8 | BT7: 119 | BU7: 3 | BV7: 1 | BW7: 4 | BX7: 3 | BY7: 0 | BZ7: 0 | CA7: 0 | CD7: غير | CE7: ذكر | CF7: 0 | CG7: 0 | CH7: 0 | CI7: 0 | CJ7: 0 | CK7: 0 | CL7: 0 | CM7: 0 | CN7: 0 | CO7: 0 | CP7: 0 | CQ7: 0 | CT7: غير | CU7: ذكر | CV7: 177 | CW7: 0 | CX7: 0 | CY7: 16 | CZ7: 114 | DA7: 0 | DB7: 2 | DC7: 33 | DD7: 0 | DE7: 0 | DF7: 0 | DG7: 0 | DJ7: غير | DK7: ذكر | DL7: 86 | DM7: 0 | DN7: 0 | DO7: 22 | DP7: 67 | DQ7: 0 | DR7: 0 | DS7: 11 | DT7: 3 | DU7: 0 | DV7: 0 | DW7: 0 | DZ7: غير | EA7: ذكر | EB7: 27 | EC7: 0 | ED7: 0 | EE7: 53 | EF7: 16 | EG7: 0 | EH7: 0 | EI7: 0 | EJ7: 2 | EK7: 0 | EL7: 0 | EM7: 0 | EP7: غير | EQ7: ذكر | ER7: 27 | ES7: 0 | ET7: 0 | EU7: 50 | EV7: 16 | EW7: 0 | EX7: 0 | EY7: 0 | EZ7: 2 | FA7: 0 | FB7: 0 | FC7: 0 | FF7: غير | FG7: ذكر | FH7: 0 | FI7: 0 | FJ7: 0 | FK7: 0 | FL7: 0 | FM7: 0 | FN7: 0 | FO7: 0 | FP7: 0 | FQ7: 0 | FR7: 0 | FS7: 0 | FV7: غير | FW7: ذكر | FX7: 0 | FY7: 0 | FZ7: 0 | GA7: 0 | GB7: 0 | GC7: 0 | GD7: 0 | GE7: 0 | GF7: 0 | GG7: 0 | GH7: 0 | GI7: 0 | GL7: غير | GM7: ذكر | GN7: =FX7 -> 0 | GO7: =E7+U7+AK7+BA7+BQ7+CG7++CW7+DM7+EC7+ES7+FI7+FY7 -> 5 | GP7: =F7+V7+AL7+BB7+BR7+CH7++CX7+DN7+ED7+ET7+FJ7+FZ7 -> 3 | GQ7: =G7+W7+AM7+BC7+BS7+CI7++CY7+DO7+EE7+EU7+FK7+GA7 -> 235 | GR7: =GB7 -> 0 | GS7: =I7+Y7+AO7+BE7+BU7+CK7++DA7+DQ7+EG7+EW7+FM7+GC7 -> 6 | GT7: =J7+Z7+AP7+BF7+BV7+CL7++DB7+DR7+EH7+EX7+FN7+GD7 -> 4 | GU7: =K7+AA7+AQ7+BG7+BW7+CM7++DC7+DS7+EI7+EY7+FO7+GE7 -> 102 | GV7: =GF7 -> 0 | GW7: =M7+AC7+AS7+BI7+BY7+CO7++DE7+DU7+EK7+FA7+FQ7+GG7 -> 0 | GX7: =N7+AD7+AT7+BJ7+BZ7+CP7++DF7+DV7+EL7+FB7+FR7+GH7 -> 0 | GY7: =O7+AE7+AU7+BK7+CA7+CQ7++DG7+DW7+EM7+FC7+FS7+GI7 -> 0
B8: سعودي | C8: أنثى | D8: 0 | E8: 0 | F8: 0 | G8: 0 | H8: 0 | I8: 0 | J8: 0 | K8: 0 | L8: 0 | M8: 0 | N8: 0 | O8: 0 | R8: سعودي | S8: أنثى | T8: 90 | U8: 0 | V8: 0 | W8: 6 | X8: 77 | Y8: 0 | Z8: 0 | AA8: 4 | AB8: 1 | AC8: 0 | AD8: 0 | AE8: 0 | AH8: سعودي | AI8: أنثى | AJ8: 92 | AK8: 0 | AL8: 0 | AM8: 28 | AN8: 77 | AO8: 0 | AP8: 0 | AQ8: 8 | AR8: 2 | AS8: 0 | AT8: 0 | AU8: 0 | AX8: سعودي | AY8: أنثى | AZ8: 92 | BA8: 1 | BB8: 0 | BC8: 9 | BD8: 77 | BE8: 1 | BF8: 0 | BG8: 7 | BH8: 1 | BI8: 0 | BJ8: 0 | BK8: 0 | BN8: سعودي | BO8: أنثى | BP8: 92 | BQ8: 2 | BR8: 1 | BS8: 6 | BT8: 77 | BU8: 1 | BV8: 0 | BW8: 1 | BX8: 1 | BY8: 0 | BZ8: 0 | CA8: 0 | CD8: سعودي | CE8: أنثى | CF8: 0 | CG8: 0 | CH8: 0 | CI8: 0 | CJ8: 0 | CK8: 0 | CL8: 0 | CM8: 0 | CN8: 0 | CO8: 0 | CP8: 0 | CQ8: 0 | CT8: سعودي | CU8: أنثى | CV8: 90 | CW8: 0 | CX8: 1 | CY8: 14 | CZ8: 77 | DA8: 0 | DB8: 0 | DC8: 22 | DD8: 0 | DE8: 0 | DF8: 0 | DG8: 0 | DJ8: سعودي | DK8: أنثى | DL8: 67 | DM8: 0 | DN8: 0 | DO8: 18 | DP8: 57 | DQ8: 0 | DR8: 0 | DS8: 4 | DT8: 1 | DU8: 0 | DV8: 0 | DW8: 0 | DZ8: سعودي | EA8: أنثى | EB8: 186 | EC8: 0 | ED8: 0 | EE8: 48 | EF8: 15 | EG8: 0 | EH8: 0 | EI8: 0 | EJ8: 0 | EK8: 0 | EL8: 0 | EM8: 0 | EP8: سعودي | EQ8: أنثى | ER8: 186 | ES8: 0 | ET8: 0 | EU8: 30 | EV8: 15 | EW8: 0 | EX8: 0 | EY8: 0 | EZ8: 0 | FA8: 0 | FB8: 0 | FC8: 0 | FF8: سعودي | FG8: أنثى | FH8: 0 | FI8: 0 | FJ8: 0 | FK8: 0 | FL8: 0 | FM8: 0 | FN8: 0 | FO8: 0 | FP8: 0 | FQ8: 0 | FR8: 0 | FS8: 0 | FV8: سعودي | FW8: أنثى | FX8: 0 | FY8: 0 | FZ8: 0 | GA8: 0 | GB8: 0 | GC8: 0 | GD8: 0 | GE8: 0 | GF8: 0 | GG8: 0 | GH8: 0 | GI8: 0 | GL8: سعودي | GM8: أنثى | GN8: =FX8 -> 0 | GO8: =E8+U8+AK8+BA8+BQ8+CG8++CW8+DM8+EC8+ES8+FI8+FY8 -> 3 | GP8: =F8+V8+AL8+BB8+BR8+CH8++CX8+DN8+ED8+ET8+FJ8+FZ8 -> 2 | GQ8: =G8+W8+AM8+BC8+BS8+CI8++CY8+DO8+EE8+EU8+FK8+GA8 -> 159 | GR8: =GB8 -> 0 | GS8: =I8+Y8+AO8+BE8+BU8+CK8++DA8+DQ8+EG8+EW8+FM8+GC8 -> 2 | GT8: =J8+Z8+AP8+BF8+BV8+CL8++DB8+DR8+EH8+EX8+FN8+GD8 -> 0 | GU8: =K8+AA8+AQ8+BG8+BW8+CM8++DC8+DS8+EI8+EY8+FO8+GE8 -> 46 | GV8: =GF8 -> 0 | GW8: =M8+AC8+AS8+BI8+BY8+CO8++DE8+DU8+EK8+FA8+FQ8+GG8 -> 0 | GX8: =N8+AD8+AT8+BJ8+BZ8+CP8++DF8+DV8+EL8+FB8+FR8+GH8 -> 0 | GY8: =O8+AE8+AU8+BK8+CA8+CQ8++DG8+DW8+EM8+FC8+FS8+GI8 -> 0
B9: المجموع | D9: =SUM(D5:D8) -> 479 | E9: =SUM(E5:E8) -> 5 | F9: =SUM(F5:F8) -> 0 | G9: =SUM(G5:G8) -> 270 | H9: =SUM(H5:H8) -> 530 | I9: =SUM(I5:I8) -> 0 | J9: =SUM(J5:J8) -> 0 | K9: =SUM(K5:K8) -> 180 | ... O9: =SUM(O5:O8) -> 0 | R9: المجموع | T9: =SUM(T5:T8) -> 751 | U9: =SUM(U5:U8) -> 2 | V9: =SUM(V5:V8) -> 24 | W9: =SUM(W5:W8) -> 355 | X9: =SUM(X5:X8) -> 636 | Y9: =SUM(Y5:Y8) -> 3 | Z9: =SUM(Z5:Z8) -> 18 | AA9: =SUM(AA5:AA8) -> 279 | ... AE9: =SUM(AE5:AE8) -> 2 | AH9: المجموع | AJ9: 775 | AK9: 3 | AL9: 15 | AM9: 312 | AN9: 649 | AO9: 1 | AP9: 12 | AQ9: 286 | AR9: 42 | AS9: 0 | AT9: 0 | AU9: 2 | AX9: المجموع | AZ9: =SUM(AZ5:AZ8) -> 768 | BA9: =SUM(BA5:BA8) -> 8 | BB9: =SUM(BB5:BB8) -> 19 | BC9: =SUM(BC5:BC8) -> 361 | BD9: =SUM(BD5:BD8) -> 652 | BE9: =SUM(BE5:BE8) -> 5 | BF9: =SUM(BF5:BF8) -> 7 | BG9: =SUM(BG5:BG8) -> 273 | ... BK9: =SUM(BK5:BK8) -> 1 | BN9: المجموع | BP9: =SUM(BP5:BP8) -> 777 | BQ9: =SUM(BQ5:BQ8) -> 9 | BR9: =SUM(BR5:BR8) -> 25 | BS9: =SUM(BS5:BS8) -> 116 | BT9: =SUM(BT5:BT8) -> 652 | BU9: =SUM(BU5:BU8) -> 1506 | BV9: =SUM(BV5:BV8) -> 16 | BW9: =SUM(BW5:BW8) -> 67 | ... CA9: =SUM(CA5:CA8) -> 0 | CD9: المجموع | CF9: =SUM(CF5:CF8) -> 0 | CG9: =SUM(CG5:CG8) -> 0 | CH9: =SUM(CH5:CH8) -> 0 | CI9: =SUM(CI5:CI8) -> 0 | CJ9: =SUM(CJ5:CJ8) -> 0 | CK9: =SUM(CK5:CK8) -> 0 | CL9: =SUM(CL5:CL8) -> 0 | CM9: =SUM(CM5:CM8) -> 0 | ... CQ9: =SUM(CQ5:CQ8) -> 0 | CT9: المجموع | CV9: 748 | CW9: 3 | CX9: 34 | CY9: 440 | CZ9: 634 | DA9: 2 | DB9: 29 | DC9: 250 | DD9: 7 | DE9: 2 | DF9: 0 | DG9: 2 | DJ9: المجموع | DL9: =SUM(DL5:DL8) -> 675 | DM9: =SUM(DM5:DM8) -> 1 | DN9: =SUM(DN5:DN8) -> 8 | DO9: =SUM(DO5:DO8) -> 186 | DP9: =SUM(DP5:DP8) -> 651 | DQ9: =SUM(DQ5:DQ8) -> 0 | DR9: =SUM(DR5:DR8) -> 9 | DS9: =SUM(DS5:DS8) -> 167 | ... DW9: =SUM(DW5:DW8) -> 0 | DZ9: المجموع | EB9: =SUM(EB5:EB8) -> 875 | EC9: =SUM(EC5:EC8) -> 7 | ED9: =SUM(ED5:ED8) -> 16 | EE9: =SUM(EE5:EE8) -> 398 | EF9: =SUM(EF5:EF8) -> 598 | EG9: =SUM(EG5:EG8) -> 4 | EH9: =SUM(EH5:EH8) -> 31 | EI9: =SUM(EI5:EI8) -> 401 | ... EM9: =SUM(EM5:EM8) -> 1 | EP9: المجموع | ER9: =SUM(ER5:ER8) -> 875 | ES9: =SUM(ES5:ES8) -> 7 | ET9: =SUM(ET5:ET8) -> 16 | EU9: =SUM(EU5:EU8) -> 236 | EV9: =SUM(EV5:EV8) -> 598 | EW9: =SUM(EW5:EW8) -> 4 | EX9: =SUM(EX5:EX8) -> 31 | EY9: =SUM(EY5:EY8) -> 149 | ... FC9: =SUM(FC5:FC8) -> 0 | FF9: المجموع | FH9: =SUM(FH5:FH8) -> 0 | FI9: =SUM(FI5:FI8) -> 0 | FJ9: =SUM(FJ5:FJ8) -> 0 | FK9: =SUM(FK5:FK8) -> 0 | FL9: =SUM(FL5:FL8) -> 0 | FM9: =SUM(FM5:FM8) -> 0 | FN9: =SUM(FN5:FN8) -> 0 | FO9: =SUM(FO5:FO8) -> 0 | ... FS9: =SUM(FS5:FS8) -> 0 | FV9: المجموع | FX9: =SUM(FX5:FX8) -> 0 | FY9: =SUM(FY5:FY8) -> 0 | FZ9: =SUM(FZ5:FZ8) -> 0 | GA9: =SUM(GA5:GA8) -> 0 | GB9: =SUM(GB5:GB8) -> 0 | GC9: =SUM(GC5:GC8) -> 0 | GD9: =SUM(GD5:GD8) -> 0 | GE9: =SUM(GE5:GE8) -> 0 | ... GI9: =SUM(GI5:GI8) -> 0 | GL9: المجموع | GN9: =SUM(GN5:GN8) -> 0 | GO9: =SUM(GO5:GO8) -> 45 | GP9: =SUM(GP5:GP8) -> 157 | GQ9: =SUM(GQ5:GQ8) -> 2674 | GR9: =SUM(GR5:GR8) -> 0 | GS9: =SUM(GS5:GS8) -> 1525 | GT9: =SUM(GT5:GT8) -> 153 | GU9: =SUM(GU5:GU8) -> 2052 | ... GY9: =SUM(GY5:GY8) -> 8
B10: العدد المتوقع للمصابين : | E10: مرضى السكري | G10: 0 | I10: مرضى الضغط | K10: 0 | M10: م.الربو | N10: 0 | R10: العدد المتوقع للمصابين : | U10: مرضى السكري | W10: 0 | Y10: مرضى الضغط | AA10: 0 | AC10: م.الربو | AD10: 0 | AH10: العدد المتوقع للمصابين : | AK10: مرضى السكري | AM10: 0 | AO10: مرضى الضغط | AQ10: 0 | AS10: م.الربو | AT10: 0 | AX10: العدد المتوقع للمصابين : | BA10: مرضى السكري | BC10: 0 | BE10: مرضى الضغط | BG10: 0 | BI10: م.الربو | BJ10: 0 | BN10: العدد المتوقع للمصابين : | BQ10: مرضى السكري | BS10: 0 | BU10: مرضى الضغط | BW10: 0 | BY10: م.الربو | BZ10: 0 | CD10: العدد المتوقع للمصابين : | CG10: مرضى السكري | CI10: 0 | CK10: مرضى الضغط | CM10: 0 | CO10: م.الربو | CP10: 0 | CT10: العدد المتوقع للمصابين : | CW10: مرضى السكري | CY10: 0 | DA10: مرضى الضغط | DC10: 0 | DE10: م.الربو | DF10: 0 | DJ10: العدد المتوقع للمصابين : | DM10: مرضى السكري | DO10: 0 | DQ10: مرضى الضغط | DS10: 0 | DU10: م.الربو | DV10: 0 | DZ10: العدد المتوقع للمصابين : | EC10: مرضى السكري | EE10: 0 | EG10: مرضى الضغط | EI10: 0 | EK10: م.الربو | EL10: 0 | EP10: العدد المتوقع للمصابين : | ES10: مرضى السكري | EU10: 0 | EW10: مرضى الضغط | EY10: 0 | FA10: م.الربو | FB10: 0 | FF10: العدد المتوقع للمصابين : | FI10: مرضى السكري | FK10: 0 | FM10: مرضى الضغط | FO10: 0 | FQ10: م.الربو | FR10: 0 | FV10: العدد المتوقع للمصابين : | FY10: مرضى السكري | GA10: 0 | GC10: مرضى الضغط | GE10: 0 | GG10: م.الربو | GH10: 0 | GL10: العدد المتوقع للمصابين : | GO10: مرضى السكري | GR10: =G10+W10+AM10+BC10+BS10+CI10+CY10+DO10+EE10+EU10+FK10+GA10 -> 0 | GS10: مرضى الضغط | GV10: =K10+AA10+AQ10+BG10+BW10+CM10+DC10+DS10+EI10+EY10+FO10+GE10 -> 0 | GW10: م.الربو | GY10: =N10+AD10+AT10+BJ10+BZ10+CP10+DF10+DV10+EL10+FB10+FR10+GH10 -> 0
A11: الجامعة | C11: ذكر | D11: 352 | E11: 0 | F11: 0 | G11: 156 | H11: 214 | I11: 0 | J11: 0 | K11: 99 | L11: 12 | M11: 0 | N11: 0 | O11: 0 | Q11: الجامعة | S11: ذكر | T11: 352 | U11: 0 | V11: 0 | W11: 75 | X11: 214 | Y11: 0 | Z11: 0 | AA11: 69 | AB11: 15 | AC11: 0 | AD11: 352 | AE11: 4 | AG11: الجامعة | AI11: ذكر | AJ11: 357 | AK11: 0 | AL11: 0 | AM11: 162 | AN11: 216 | AO11: 0 | AP11: 0 | AQ11: 102 | AR11: 15 | AS11: 0 | AT11: 0 | AU11: 15 | AW11: الجامعة | AY11: ذكر | AZ11: 357 | BA11: 0 | BB11: 0 | BC11: 102 | BD11: 216 | BE11: 0 | BF11: 0 | BG11: 98 | BH11: 15 | BI11: 0 | BJ11: 0 | BK11: 9 | BM11: الجامعة | BO11: ذكر | BP11: 357 | BQ11: 3 | BR11: 0 | BS11: 73 | BT11: 216 | BU11: 1 | BV11: 0 | BW11: 40 | BX11: 12 | BY11: 0 | BZ11: 0 | CA11: 4 | CC11: الجامعة | CE11: ذكر | CF11: 0 | CG11: 0 | CH11: 0 | CI11: 0 | CJ11: 0 | CK11: 0 | CL11: 0 | CM11: 0 | CN11: 0 | CO11: 0 | CP11: 0 | CQ11: 0 | CS11: الجامعة | CU11: ذكر | CV11: 352 | CW11: 0 | CX11: 0 | CY11: 135 | CZ11: 214 | DA11: 0 | DB11: 0 | DC11: 75 | DD11: 18 | DE11: 3 | DF11: 0 | DG11: 4 | DI11: الجامعة | DK11: ذكر | DL11: 357 | DM11: 0 | DN11: 0 | DO11: 176 | DP11: 216 | DQ11: 0 | DR11: 0 | DS11: 96 | DT11: 15 | DU11: 0 | DV11: 0 | DW11: 17 | DY11: الجامعة | EA11: ذكر | EB11: 278 | EC11: 10 | ED11: 0 | EE11: 33 | EF11: 178 | EG11: 5 | EH11: 0 | EI11: 0 | EJ11: 13 | EK11: 0 | EL11: 0 | EM11: 3 | EO11: الجامعة | EQ11: ذكر | ER11: 0 | ES11: 0 | ET11: 0 | EU11: 0 | EV11: 0 | EW11: 0 | EX11: 0 | EY11: 0 | EZ11: 0 | FA11: 0 | FB11: 0 | FC11: 0 | FE11: الجامعة | FG11: ذكر | FH11: 0 | FI11: 0 | FJ11: 0 | FK11: 0 | FL11: 0 | FM11: 0 | FN11: 0 | FO11: 0 | FP11: 0 | FQ11: 0 | FR11: 0 | FS11: 0 | FU11: الجامعة | FW11: ذكر | FX11: 0 | FY11: 0 | FZ11: 0 | GA11: 0 | GB11: 0 | GC11: 0 | GD11: 0 | GE11: 0 | GF11: 0 | GG11: 0 | GH11: 0 | GI11: 0 | GK11: =FU11 -> الجامعة | GM11: ذكر | GN11: =FX11 -> 0 | GO11: =E11+U11+AK11+BA11+BQ11+CG11++CW11+DM11+EC11+ES11+FI11+FY11 -> 13 | GP11: =F11+V11+AL11+BB11+BR11+CH11++CX11+DN11+ED11+ET11+FJ11+FZ11 -> 0 | GQ11: =G11+W11+AM11+BC11+BS11+CI11++CY11+DO11+EE11+EU11+FK11+GA11 -> 912 | GR11: =GB11 -> 0 | GS11: =I11+Y11+AO11+BE11+BU11+CK11++DA11+DQ11+EG11+EW11+FM11+GC11 -> 6 | GT11: =J11+Z11+AP11+BF11+BV11+CL11++DB11+DR11+EH11+EX11+FN11+GD11 -> 0 | GU11: =K11+AA11+AQ11+BG11+BW11+CM11++DC11+DS11+EI11+EY11+FO11+GE11 -> 579 | GV11: =GF11 -> 0 | GW11: =M11+AC11+AS11+BI11+BY11+CO11++DE11+DU11+EK11+FA11+FQ11+GG11 -> 3 | GX11: =N11+AD11+AT11+BJ11+BZ11+CP11++DF11+DV11+EL11+FB11+FR11+GH11 -> 352 | GY11: =O11+AE11+AU11+BK11+CA11+CQ11++DG11+DW11+EM11+FC11+FS11+GI11 -> 56
B12: سعودي | C12: أنثى | D12: 382 | E12: 0 | F12: 0 | G12: 85 | H12: 321 | I12: 0 | J12: 0 | K12: 39 | L12: 23 | M12: 0 | N12: 0 | O12: 0 | R12: سعودي | S12: أنثى | T12: 382 | U12: 0 | V12: 0 | W12: 63 | X12: 321 | Y12: 0 | Z12: 0 | AA12: 43 | AB12: 24 | AC12: 0 | AD12: 0 | AE12: 3 | AH12: سعودي | AI12: أنثى | AJ12: 384 | AK12: 0 | AL12: 0 | AM12: 48 | AN12: 325 | AO12: 0 | AP12: 0 | AQ12: 53 | AR12: 24 | AS12: 0 | AT12: 0 | AU12: 12 | AX12: سعودي | AY12: أنثى | AZ12: 384 | BA12: 0 | BB12: 0 | BC12: 75 | BD12: 325 | BE12: 0 | BF12: 0 | BG12: 30 | BH12: 24 | BI12: 0 | BJ12: 0 | BK12: 4 | BN12: سعودي | BO12: أنثى | BP12: 384 | BQ12: 2 | BR12: 0 | BS12: 53 | BT12: 325 | BU12: 2 | BV12: 0 | BW12: 19 | BX12: 23 | BY12: 0 | BZ12: 0 | CA12: 3 | CD12: سعودي | CE12: أنثى | CF12: 0 | CG12: 0 | CH12: 0 | CI12: 0 | CJ12: 0 | CK12: 0 | CL12: 0 | CM12: 0 | CN12: 0 | CO12: 0 | CP12: 0 | CQ12: 0 | CT12: سعودي | CU12: أنثى | CV12: 382 | CW12: 0 | CX12: 0 | CY12: 72 | CZ12: 321 | DA12: 0 | DB12: 0 | DC12: 33 | DD12: 24 | DE12: 1 | DF12: 0 | DG12: 3 | DJ12: سعودي | DK12: أنثى | DL12: 384 | DM12: 0 | DN12: 0 | DO12: 45 | DP12: 325 | DQ12: 0 | DR12: 0 | DS12: 60 | DT12: 24 | DU12: 0 | DV12: 0 | DW12: 10 | DZ12: سعودي | EA12: أنثى | EB12: 327 | EC12: 5 | ED12: 0 | EE12: 20 | EF12: 291 | EG12: 4 | EH12: 0 | EI12: 0 | EJ12: 20 | EK12: 0 | EL12: 0 | EM12: 4 | EP12: سعودي | EQ12: أنثى | ER12: 0 | ES12: 0 | ET12: 0 | EU12: 0 | EV12: 0 | EW12: 0 | EX12: 0 | EY12: 0 | EZ12: 0 | FA12: 0 | FB12: 0 | FC12: 0 | FF12: سعودي | FG12: أنثى | FH12: 0 | FI12: 0 | FJ12: 0 | FK12: 0 | FL12: 0 | FM12: 0 | FN12: 0 | FO12: 0 | FP12: 0 | FQ12: 0 | FR12: 0 | FS12: 0 | FV12: سعودي | FW12: أنثى | FX12: 0 | FY12: 0 | FZ12: 0 | GA12: 0 | GB12: 0 | GC12: 0 | GD12: 0 | GE12: 0 | GF12: 0 | GG12: 0 | GH12: 0 | GI12: 0 | GL12: سعودي | GM12: أنثى | GN12: =FX12 -> 0 | GO12: =E12+U12+AK12+BA12+BQ12+CG12++CW12+DM12+EC12+ES12+FI12+FY12 -> 7 | GP12: =F12+V12+AL12+BB12+BR12+CH12++CX12+DN12+ED12+ET12+FJ12+FZ12 -> 0 | GQ12: =G12+W12+AM12+BC12+BS12+CI12++CY12+DO12+EE12+EU12+FK12+GA12 -> 461 | GR12: =GB12 -> 0 | GS12: =I12+Y12+AO12+BE12+BU12+CK12++DA12+DQ12+EG12+EW12+FM12+GC12 -> 6 | GT12: =J12+Z12+AP12+BF12+BV12+CL12++DB12+DR12+EH12+EX12+FN12+GD12 -> 0 | GU12: =K12+AA12+AQ12+BG12+BW12+CM12++DC12+DS12+EI12+EY12+FO12+GE12 -> 277 | GV12: =GF12 -> 0 | GW12: =M12+AC12+AS12+BI12+BY12+CO12++DE12+DU12+EK12+FA12+FQ12+GG12 -> 1 | GX12: =N12+AD12+AT12+BJ12+BZ12+CP12++DF12+DV12+EL12+FB12+FR12+GH12 -> 0 | GY12: =O12+AE12+AU12+BK12+CA12+CQ12++DG12+DW12+EM12+FC12+FS12+GI12 -> 39
B13: غير | C13: ذكر | D13: 167 | E13: 0 | F13: 0 | G13: 78 | H13: 99 | I13: 0 | J13: 0 | K13: 75 | L13: 0 | M13: 0 | N13: 0 | O13: 0 | R13: غير | S13: ذكر | T13: 167 | U13: 0 | V13: 0 | W13: 51 | X13: 99 | Y13: 0 | Z13: 0 | AA13: 51 | AB13: 5 | AC13: 0 | AD13: 0 | AE13: 3 | AH13: غير | AI13: ذكر | AJ13: 170 | AK13: 0 | AL13: 0 | AM13: 55 | AN13: 10 | AO13: 0 | AP13: 0 | AQ13: 59 | AR13: 5 | AS13: 0 | AT13: 0 | AU13: 8 | AX13: غير | AY13: ذكر | AZ13: 170 | BA13: 0 | BB13: 0 | BC13: 49 | BD13: 100 | BE13: 0 | BF13: 0 | BG13: 76 | BH13: 5 | BI13: 0 | BJ13: 0 | BK13: 4 | BN13: غير | BO13: ذكر | BP13: 170 | BQ13: 0 | BR13: 0 | BS13: 39 | BT13: 100 | BU13: 2 | BV13: 0 | BW13: 29 | BX13: 0 | BY13: 0 | BZ13: 0 | CA13: 3 | CD13: غير | CE13: ذكر | CF13: 0 | CG13: 0 | CH13: 0 | CI13: 0 | CJ13: 0 | CK13: 0 | CL13: 0 | CM13: 0 | CN13: 0 | CO13: 0 | CP13: 0 | CQ13: 0 | CT13: غير | CU13: ذكر | CV13: 167 | CW13: 0 | CX13: 0 | CY13: 55 | CZ13: 99 | DA13: 0 | DB13: 0 | DC13: 61 | DD13: 5 | DE13: 5 | DF13: 0 | DG13: 3 | DJ13: غير | DK13: ذكر | DL13: 170 | DM13: 0 | DN13: 0 | DO13: 56 | DP13: 100 | DQ13: 0 | DR13: 0 | DS13: 50 | DT13: 5 | DU13: 0 | DV13: 0 | DW13: 7 | DZ13: غير | EA13: ذكر | EB13: 132 | EC13: 2 | ED13: 0 | EE13: 17 | EF13: 52 | EG13: 2 | EH13: 0 | EI13: 0 | EJ13: 0 | EK13: 0 | EL13: 0 | EM13: 4 | EP13: غير | EQ13: ذكر | ER13: 0 | ES13: 0 | ET13: 0 | EU13: 0 | EV13: 0 | EW13: 0 | EX13: 0 | EY13: 0 | EZ13: 0 | FA13: 0 | FB13: 0 | FC13: 0 | FF13: غير | FG13: ذكر | FH13: 0 | FI13: 0 | FJ13: 0 | FK13: 0 | FL13: 0 | FM13: 0 | FN13: 0 | FO13: 0 | FP13: 0 | FQ13: 0 | FR13: 0 | FS13: 0 | FV13: غير | FW13: ذكر | FX13: 0 | FY13: 0 | FZ13: 0 | GA13: 0 | GB13: 0 | GC13: 0 | GD13: 0 | GE13: 0 | GF13: 0 | GG13: 0 | GH13: 0 | GI13: 0 | GL13: غير | GM13: ذكر | GN13: =FX13 -> 0 | GO13: =E13+U13+AK13+BA13+BQ13+CG13++CW13+DM13+EC13+ES13+FI13+FY13 -> 2 | GP13: =F13+V13+AL13+BB13+BR13+CH13++CX13+DN13+ED13+ET13+FJ13+FZ13 -> 0 | GQ13: =G13+W13+AM13+BC13+BS13+CI13++CY13+DO13+EE13+EU13+FK13+GA13 -> 400 | GR13: =GB13 -> 0 | GS13: =I13+Y13+AO13+BE13+BU13+CK13++DA13+DQ13+EG13+EW13+FM13+GC13 -> 4 | GT13: =J13+Z13+AP13+BF13+BV13+CL13++DB13+DR13+EH13+EX13+FN13+GD13 -> 0 | GU13: =K13+AA13+AQ13+BG13+BW13+CM13++DC13+DS13+EI13+EY13+FO13+GE13 -> 401 | GV13: =GF13 -> 0 | GW13: =M13+AC13+AS13+BI13+BY13+CO13++DE13+DU13+EK13+FA13+FQ13+GG13 -> 5 | GX13: =N13+AD13+AT13+BJ13+BZ13+CP13++DF13+DV13+EL13+FB13+FR13+GH13 -> 0 | GY13: =O13+AE13+AU13+BK13+CA13+CQ13++DG13+DW13+EM13+FC13+FS13+GI13 -> 32
B14: سعودي | C14: أنثى | D14: 986 | E14: 0 | F14: 0 | G14: 56 | H14: 77 | I14: 0 | J14: 0 | K14: 52 | L14: 2 | M14: 0 | N14: 0 | O14: 0 | R14: سعودي | S14: أنثى | T14: 986 | U14: 0 | V14: 0 | W14: 46 | X14: 77 | Y14: 0 | Z14: 0 | AA14: 23 | AB14: 4 | AC14: 0 | AD14: 0 | AH14: سعودي | AI14: أنثى | AJ14: 990 | AK14: 0 | AL14: 0 | AM14: 35 | AN14: 77 | AO14: 0 | AP14: 0 | AQ14: 34 | AR14: 4 | AS14: 0 | AT14: 0 | AU14: 5 | AX14: سعودي | AY14: أنثى | AZ14: 990 | BA14: 0 | BB14: 0 | BC14: 40 | BD14: 77 | BE14: 0 | BF14: 0 | BG14: 19 | BH14: 4 | BI14: 0 | BJ14: 0 | BK14: 6 | BN14: سعودي | BO14: أنثى | BP14: 990 | BQ14: 1 | BR14: 0 | BS14: 13 | BT14: 77 | BU14: 0 | BV14: 0 | BW14: 21 | BX14: 2 | BY14: 0 | BZ14: 0 | CA14: 5 | CD14: سعودي | CE14: أنثى | CF14: 0 | CG14: 0 | CH14: 0 | CI14: 0 | CJ14: 0 | CK14: 0 | CL14: 0 | CM14: 0 | CN14: 0 | CO14: 0 | CP14: 0 | CQ14: 0 | CT14: سعودي | CU14: أنثى | CV14: 986 | CW14: 0 | CX14: 0 | CY14: 68 | CZ14: 77 | DA14: 0 | DB14: 0 | DC14: 43 | DD14: 4 | DE14: 2 | DF14: 0 | DG14: 5 | DJ14: سعودي | DK14: أنثى | DL14: 990 | DM14: 0 | DN14: 0 | DO14: 49 | DP14: 77 | DQ14: 0 | DR14: 0 | DS14: 52 | DT14: 4 | DU14: 0 | DV14: 0 | DW14: 4 | DZ14: سعودي | EA14: أنثى | EB14: 84 | EC14: 2 | ED14: 0 | EE14: 15 | EF14: 50 | EG14: 3 | EH14: 0 | EI14: 0 | EJ14: 2 | EK14: 0 | EL14: 0 | EM14: 2 | EP14: سعودي | EQ14: أنثى | ER14: 0 | ES14: 0 | ET14: 0 | EU14: 0 | EV14: 0 | EW14: 0 | EX14: 0 | EY14: 0 | EZ14: 0 | FA14: 0 | FB14: 0 | FC14: 0 | FF14: سعودي | FG14: أنثى | FH14: 0 | FI14: 0 | FJ14: 0 | FK14: 0 | FL14: 0 | FM14: 0 | FN14: 0 | FO14: 0 | FP14: 0 | FQ14: 0 | FR14: 0 | FS14: 0 | FV14: سعودي | FW14: أنثى | FX14: 0 | FY14: 0 | FZ14: 0 | GA14: 0 | GB14: 0 | GC14: 0 | GD14: 0 | GE14: 0 | GF14: 0 | GG14: 0 | GH14: 0 | GI14: 0 | GL14: سعودي | GM14: أنثى | GN14: =FX14 -> 0 | GO14: =E14+U14+AK14+BA14+BQ14+CG14++CW14+DM14+EC14+ES14+FI14+FY14 -> 3 | GP14: =F14+V14+AL14+BB14+BR14+CH14++CX14+DN14+ED14+ET14+FJ14+FZ14 -> 0 | GQ14: =G14+W14+AM14+BC14+BS14+CI14++CY14+DO14+EE14+EU14+FK14+GA14 -> 322 | GR14: =GB14 -> 0 | GS14: =I14+Y14+AO14+BE14+BU14+CK14++DA14+DQ14+EG14+EW14+FM14+GC14 -> 3 | GT14: =J14+Z14+AP14+BF14+BV14+CL14++DB14+DR14+EH14+EX14+FN14+GD14 -> 0 | GU14: =K14+AA14+AQ14+BG14+BW14+CM14++DC14+DS14+EI14+EY14+FO14+GE14 -> 244 | GV14: =GF14 -> 0 | GW14: =M14+AC14+AS14+BI14+BY14+CO14++DE14+DU14+EK14+FA14+FQ14+GG14 -> 2 | GX14: =N14+AD14+AT14+BJ14+BZ14+CP14++DF14+DV14+EL14+FB14+FR14+GH14 -> 0 | GY14: =O14+AE14+AU14+BK14+CA14+CQ14++DG14+DW14+EM14+FC14+FS14+GI14 -> 27
B15: المجموع | D15: =SUM(D11:D14) -> 1887 | E15: =SUM(E11:E14) -> 0 | F15: =SUM(F11:F14) -> 0 | G15: =SUM(G11:G14) -> 375 | H15: =SUM(H11:H14) -> 711 | I15: =SUM(I11:I14) -> 0 | J15: =SUM(J11:J14) -> 0 | K15: =SUM(K11:K14) -> 265 | ... O15: =SUM(O11:O14) -> 0 | R15: المجموع | T15: =SUM(T11:T14) -> 1887 | U15: =SUM(U11:U14) -> 0 | V15: =SUM(V11:V14) -> 0 | W15: =SUM(W11:W14) -> 235 | X15: =SUM(X11:X14) -> 711 | Y15: =SUM(Y11:Y14) -> 0 | Z15: =SUM(Z11:Z14) -> 0 | AA15: =SUM(AA11:AA14) -> 186 | ... AE15: =SUM(AE11:AE14) -> 10 | AH15: المجموع | AJ15: 1901 | AK15: 0 | AL15: 0 | AM15: 300 | AN15: 628 | AO15: 0 | AP15: 0 | AQ15: 248 | AR15: 48 | AS15: 0 | AT15: 0 | AU15: 40 | AX15: المجموع | AZ15: =SUM(AZ11:AZ14) -> 1901 | BA15: =SUM(BA11:BA14) -> 0 | BB15: =SUM(BB11:BB14) -> 0 | BC15: =SUM(BC11:BC14) -> 266 | BD15: =SUM(BD11:BD14) -> 718 | BE15: =SUM(BE11:BE14) -> 0 | BF15: =SUM(BF11:BF14) -> 0 | BG15: =SUM(BG11:BG14) -> 223 | ... BK15: =SUM(BK11:BK14) -> 23 | BN15: المجموع | BP15: =SUM(BP11:BP14) -> 1901 | BQ15: =SUM(BQ11:BQ14) -> 6 | BR15: =SUM(BR11:BR14) -> 0 | BS15: =SUM(BS11:BS14) -> 178 | BT15: =SUM(BT11:BT14) -> 718 | BU15: =SUM(BU11:BU14) -> 5 | BV15: =SUM(BV11:BV14) -> 0 | BW15: =SUM(BW11:BW14) -> 109 | ... CA15: =SUM(CA11:CA14) -> 15 | CD15: المجموع | CF15: =SUM(CF11:CF14) -> 0 | CG15: =SUM(CG11:CG14) -> 0 | CH15: =SUM(CH11:CH14) -> 0 | CI15: =SUM(CI11:CI14) -> 0 | CJ15: =SUM(CJ11:CJ14) -> 0 | CK15: =SUM(CK11:CK14) -> 0 | CL15: =SUM(CL11:CL14) -> 0 | CM15: =SUM(CM11:CM14) -> 0 | ... CQ15: =SUM(CQ11:CQ14) -> 0 | CT15: المجموع | CV15: 1887 | CW15: 0 | CX15: 0 | CY15: 330 | CZ15: 711 | DA15: 0 | DB15: 0 | DC15: 212 | DD15: 51 | DE15: 11 | DF15: 0 | DG15: 15 | DJ15: المجموع | DL15: =SUM(DL11:DL14) -> 1901 | DM15: =SUM(DM11:DM14) -> 0 | DN15: =SUM(DN11:DN14) -> 0 | DO15: =SUM(DO11:DO14) -> 326 | DP15: =SUM(DP11:DP14) -> 718 | DQ15: =SUM(DQ11:DQ14) -> 0 | DR15: =SUM(DR11:DR14) -> 0 | DS15: =SUM(DS11:DS14) -> 258 | ... DW15: =SUM(DW11:DW14) -> 38 | DZ15: المجموع | EB15: =SUM(EB11:EB14) -> 821 | EC15: =SUM(EC11:EC14) -> 19 | ED15: =SUM(ED11:ED14) -> 0 | EE15: =SUM(EE11:EE14) -> 85 | EF15: =SUM(EF11:EF14) -> 571 | EG15: =SUM(EG11:EG14) -> 14 | EH15: =SUM(EH11:EH14) -> 0 | EI15: =SUM(EI11:EI14) -> 0 | ... EM15: =SUM(EM11:EM14) -> 13 | EP15: المجموع | ER15: =SUM(ER11:ER14) -> 0 | ES15: =SUM(ES11:ES14) -> 0 | ET15: =SUM(ET11:ET14) -> 0 | EU15: =SUM(EU11:EU14) -> 0 | EV15: =SUM(EV11:EV14) -> 0 | EW15: =SUM(EW11:EW14) -> 0 | EX15: =SUM(EX11:EX14) -> 0 | EY15: =SUM(EY11:EY14) -> 0 | ... FC15: =SUM(FC11:FC14) -> 0 | FF15: المجموع | FH15: =SUM(FH11:FH14) -> 0 | FI15: =SUM(FI11:FI14) -> 0 | FJ15: =SUM(FJ11:FJ14) -> 0 | FK15: =SUM(FK11:FK14) -> 0 | FL15: =SUM(FL11:FL14) -> 0 | FM15: =SUM(FM11:FM14) -> 0 | FN15: =SUM(FN11:FN14) -> 0 | FO15: =SUM(FO11:FO14) -> 0 | ... FS15: =SUM(FS11:FS14) -> 0 | FV15: المجموع | FX15: =SUM(FX11:FX14) -> 0 | FY15: =SUM(FY11:FY14) -> 0 | FZ15: =SUM(FZ11:FZ14) -> 0 | GA15: =SUM(GA11:GA14) -> 0 | GB15: =SUM(GB11:GB14) -> 0 | GC15: =SUM(GC11:GC14) -> 0 | GD15: =SUM(GD11:GD14) -> 0 | GE15: =SUM(GE11:GE14) -> 0 | ... GI15: =SUM(GI11:GI14) -> 0 | GL15: المجموع | GN15: =SUM(GN11:GN14) -> 0 | GO15: =SUM(GO11:GO14) -> 25 | GP15: =SUM(GP11:GP14) -> 0 | GQ15: =SUM(GQ11:GQ14) -> 2095 | GR15: =SUM(GR11:GR14) -> 0 | GS15: =SUM(GS11:GS14) -> 19 | GT15: =SUM(GT11:GT14) -> 0 | GU15: =SUM(GU11:GU14) -> 1501 | ... GY15: =SUM(GY11:GY14) -> 154
B16: العدد المتوقع للمصابين : | E16: مرضى السكري | G16: 0 | I16: مرضى الضغط | K16: 0 | M16: م.الربو | N16: 0 | R16: العدد المتوقع للمصابين : | U16: مرضى السكري | W16: 0 | Y16: مرضى الضغط | AA16: 0 | AC16: م.الربو | AD16: 0 | AH16: العدد المتوقع للمصابين : | AK16: مرضى السكري | AM16: 0 | AO16: مرضى الضغط | AQ16: 0 | AS16: م.الربو | AT16: 0 | AX16: العدد المتوقع للمصابين : | BA16: مرضى السكري | BC16: 0 | BE16: مرضى الضغط | BG16: 0 | BI16: م.الربو | BJ16: 0 | BN16: العدد المتوقع للمصابين : | BQ16: مرضى السكري | BS16: 0 | BU16: مرضى الضغط | BW16: 0 | BY16: م.الربو | BZ16: 0 | CD16: العدد المتوقع للمصابين : | CG16: مرضى السكري | CI16: 0 | CK16: مرضى الضغط | CM16: 0 | CO16: م.الربو | CP16: 0 | CT16: العدد المتوقع للمصابين : | CW16: مرضى السكري | CY16: 0 | DA16: مرضى الضغط | DC16: 0 | DE16: م.الربو | DF16: 0 | DJ16: العدد المتوقع للمصابين : | DM16: مرضى السكري | DO16: 0 | DQ16: مرضى الضغط | DS16: 0 | DU16: م.الربو | DV16: 0 | DZ16: العدد المتوقع للمصابين : | EC16: مرضى السكري | EE16: 0 | EG16: مرضى الضغط | EI16: 0 | EK16: م.الربو | EL16: 0 | EP16: العدد المتوقع للمصابين : | ES16: مرضى السكري | EU16: 0 | EW16: مرضى الضغط | EY16: 0 | FA16: م.الربو | FB16: 0 | FF16: العدد المتوقع للمصابين : | FI16: مرضى السكري | FK16: 0 | FM16: مرضى الضغط | FO16: 0 | FQ16: م.الربو | FR16: 0 | FV16: العدد المتوقع للمصابين : | FY16: مرضى السكري | GA16: 0 | GC16: مرضى الضغط | GE16: 0 | GG16: م.الربو | GH16: 0 | GL16: العدد المتوقع للمصابين : | GO16: مرضى السكري | GR16: =G16+W16+AM16+BC16+BS16+CI16+CY16+DO16+EE16+EU16+FK16+GA16 -> 0 | GS16: مرضى الضغط | GV16: =K16+AA16+AQ16+BG16+BW16+CM16+DC16+DS16+EI16+EY16+FO16+GE16 -> 0 | GW16: م.الربو | GY16: =N16+AD16+AT16+BJ16+BZ16+CP16+DF16+DV16+EL16+FB16+FR16+GH16 -> 0
A17: السليمانية | C17: ذكر | D17: 90 | E17: 9 | F17: 20 | G17: 152 | H17: 78 | I17: 2 | J17: 25 | K17: 237 | L17: 0 | M17: 0 | N17: 0 | O17: 0 | Q17: السليمانية | S17: ذكر | T17: 0 | U17: 0 | V17: 0 | W17: 0 | X17: 0 | Y17: 0 | Z17: 0 | AA17: 0 | AB17: 0 | AC17: 0 | AD17: 0 | AE17: 0 | AG17: السليمانية | AI17: ذكر | AJ17: 0 | AK17: 0 | AL17: 0 | AM17: 0 | AN17: 0 | AO17: 0 | AP17: 0 | AQ17: 0 | AR17: 0 | AS17: 0 | AT17: 0 | AU17: 0 | AW17: السليمانية | AY17: ذكر | AZ17: 184 | BA17: 10 | BB17: 49 | BC17: 122 | BD17: 254 | BE17: 7 | BF17: 18 | BG17: 135 | BH17: 0 | BI17: 0 | BJ17: 0 | BK17: 1 | BM17: السليمانية | BO17: ذكر | BP17: 184 | BQ17: 2 | BR17: 31 | BS17: 258 | BT17: 259 | BU17: 1 | BV17: 9 | BW17: 214 | BX17: 3 | BY17: 1 | BZ17: 0 | CA17: 1 | CC17: السليمانية | CE17: ذكر | CF17: 125 | CG17: 5 | CH17: 35 | CI17: 122 | CJ17: 158 | CK17: 7 | CL17: 10 | CM17: 135 | CN17: 0 | CO17: 0 | CP17: 0 | CQ17: 1 | CS17: السليمانية | CU17: ذكر | CV17: 180 | CW17: 9 | CX17: 58 | CY17: 0 | CZ17: 190 | DA17: 9000 | DB17: 40 | DC17: 0 | DD17: 0 | DE17: 0 | DF17: 0 | DG17: 0 | DI17: السليمانية | DK17: ذكر | DM17: مرضى السكري | DO17: 0 | DQ17: مرضى الضغط | DS17: 0 | DU17: م.الربو | DV17: 0 | DY17: السليمانية | EA17: ذكر | EB17: 255 | EC17: 4 | ED17: 0 | EE17: 42 | EF17: 185 | EG17: 2 | EH17: 0 | EI17: 0 | EJ17: 5 | EK17: 0 | EL17: 0 | EM17: 0 | EO17: السليمانية | EQ17: ذكر | ER17: 255 | ES17: 4 | ET17: 0 | EU17: 80 | EV17: 185 | EW17: 2 | EX17: 0 | EY17: 0 | EZ17: 5 | FA17: 0 | FB17: 0 | FC17: 0 | FE17: السليمانية | FG17: ذكر | FH17: 0 | FI17: 0 | FJ17: 0 | FK17: 0 | FL17: 0 | FM17: 0 | FN17: 0 | FO17: 0 | FP17: 0 | FQ17: 0 | FR17: 0 | FS17: 0 | FU17: السليمانية | FW17: ذكر | FX17: 0 | FY17: 0 | FZ17: 0 | GA17: 0 | GB17: 0 | GC17: 0 | GD17: 0 | GE17: 0 | GF17: 0 | GG17: 0 | GH17: 0 | GI17: 0 | GK17: =FU17 -> السليمانية | GM17: ذكر | GN17: =FX17 -> 0 | GO17: =E17+U17+AK17+BA17+BQ17+CG17++CW17+DM17+EC17+ES17+FI17+FY17 -> #VALUE! | GP17: =F17+V17+AL17+BB17+BR17+CH17++CX17+DN17+ED17+ET17+FJ17+FZ17 -> 193 | GQ17: =G17+W17+AM17+BC17+BS17+CI17++CY17+DO17+EE17+EU17+FK17+GA17 -> 776 | GR17: =GB17 -> 0 | GS17: =I17+Y17+AO17+BE17+BU17+CK17++DA17+DQ17+EG17+EW17+FM17+GC17 -> #VALUE! | GT17: =J17+Z17+AP17+BF17+BV17+CL17++DB17+DR17+EH17+EX17+FN17+GD17 -> 102 | GU17: =K17+AA17+AQ17+BG17+BW17+CM17++DC17+DS17+EI17+EY17+FO17+GE17 -> 721 | GV17: =GF17 -> 0 | GW17: =M17+AC17+AS17+BI17+BY17+CO17++DE17+DU17+EK17+FA17+FQ17+GG17 -> #VALUE! | GX17: =N17+AD17+AT17+BJ17+BZ17+CP17++DF17+DV17+EL17+FB17+FR17+GH17 -> 0 | GY17: =O17+AE17+AU17+BK17+CA17+CQ17++DG17+DW17+EM17+FC17+FS17+GI17 -> 3
B18: سعودي | C18: أنثى | D18: 75 | E18: 6 | F18: 22 | G18: 120 | H18: 200 | I18: 4 | J18: 20 | K18: 188 | L18: 0 | M18: 0 | N18: 0 | O18: 0 | R18: سعودي | S18: أنثى | T18: 0 | U18: 0 | V18: 0 | W18: 0 | X18: 0 | Y18: 0 | Z18: 0 | AA18: 0 | AB18: 0 | AC18: 0 | AD18: 0 | AE18: 0 | AH18: سعودي | AI18: أنثى | AJ18: 0 | AK18: 0 | AL18: 0 | AM18: 0 | AN18: 0 | AO18: 0 | AP18: 0 | AQ18: 0 | AR18: 0 | AS18: 0 | AT18: 0 | AU18: 0 | AX18: سعودي | AY18: أنثى | AZ18: 129 | BA18: 5 | BB18: 35 | BC18: 135 | BD18: 146 | BE18: 2 | BF18: 4 | BG18: 124 | BH18: 0 | BI18: 0 | BJ18: 0 | BK18: 0 | BN18: سعودي | BO18: أنثى | BP18: 129 | BQ18: 1 | BR18: 12 | BS18: 207 | BT18: 149 | BU18: 0 | BV18: 5 | BW18: 187 | BX18: 2 | BY18: 0 | BZ18: 0 | CA18: 0 | CD18: سعودي | CE18: أنثى | CF18: 125 | CG18: 2 | CH18: 20 | CI18: 135 | CJ18: 163 | CK18: 2 | CL18: 4 | CM18: 124 | CN18: 0 | CO18: 0 | CP18: 0 | CQ18: 0 | CT18: سعودي | CU18: أنثى | CV18: 125 | CW18: 11 | CX18: 56 | CY18: 0 | CZ18: 345 | DA18: 600 | DB18: 25 | DC18: 0 | DD18: 0 | DE18: 0 | DF18: 0 | DG18: 0 | DJ18: سعودي | DK18: أنثى | DL18: 125 | DM18: 5 | DN18: 35 | DO18: 122 | DP18: 158 | DQ18: 7 | DR18: 10 | DS18: 135 | DT18: 0 | DU18: 0 | DV18: 0 | DW18: 1 | DZ18: سعودي | EA18: أنثى | EB18: 240 | EC18: 5 | ED18: 0 | EE18: 40 | EF18: 171 | EG18: 4 | EH18: 0 | EI18: 0 | EJ18: 7 | EK18: 0 | EL18: 0 | EM18: 0 | EP18: سعودي | EQ18: أنثى | ER18: 240 | ES18: 5 | ET18: 0 | EU18: 66 | EV18: 171 | EW18: 4 | EX18: 0 | EY18: 0 | EZ18: 7 | FA18: 0 | FB18: 0 | FC18: 0 | FF18: سعودي | FG18: أنثى | FH18: 0 | FI18: 0 | FJ18: 0 | FK18: 0 | FL18: 0 | FM18: 0 | FN18: 0 | FO18: 0 | FP18: 0 | FQ18: 0 | FR18: 0 | FS18: 0 | FV18: سعودي | FW18: أنثى | FX18: 0 | FY18: 0 | FZ18: 0 | GA18: 0 | GB18: 0 | GC18: 0 | GD18: 0 | GE18: 0 | GF18: 0 | GG18: 0 | GH18: 0 | GI18: 0 | GL18: سعودي | GM18: أنثى | GN18: =FX18 -> 0 | GO18: =E18+U18+AK18+BA18+BQ18+CG18++CW18+DM18+EC18+ES18+FI18+FY18 -> 40 | GP18: =F18+V18+AL18+BB18+BR18+CH18++CX18+DN18+ED18+ET18+FJ18+FZ18 -> 180 | GQ18: =G18+W18+AM18+BC18+BS18+CI18++CY18+DO18+EE18+EU18+FK18+GA18 -> 825 | GR18: =GB18 -> 0 | GS18: =I18+Y18+AO18+BE18+BU18+CK18++DA18+DQ18+EG18+EW18+FM18+GC18 -> 623 | GT18: =J18+Z18+AP18+BF18+BV18+CL18++DB18+DR18+EH18+EX18+FN18+GD18 -> 68 | GU18: =K18+AA18+AQ18+BG18+BW18+CM18++DC18+DS18+EI18+EY18+FO18+GE18 -> 758 | GV18: =GF18 -> 0 | GW18: =M18+AC18+AS18+BI18+BY18+CO18++DE18+DU18+EK18+FA18+FQ18+GG18 -> 0 | GX18: =N18+AD18+AT18+BJ18+BZ18+CP18++DF18+DV18+EL18+FB18+FR18+GH18 -> 0 | GY18: =O18+AE18+AU18+BK18+CA18+CQ18++DG18+DW18+EM18+FC18+FS18+GI18 -> 1
B19: غير | C19: ذكر | D19: 70 | E19: 0 | F19: 10 | G19: 109 | H19: 140 | I19: 0 | J19: 8 | K19: 190 | L19: 0 | M19: 0 | N19: 0 | O19: 0 | R19: غير | S19: ذكر | T19: 0 | U19: 0 | V19: 0 | W19: 0 | X19: 0 | Y19: 0 | Z19: 0 | AA19: 0 | AB19: 0 | AC19: 0 | AD19: 0 | AE19: 0 | AH19: غير | AI19: ذكر | AJ19: 0 | AK19: 0 | AL19: 0 | AM19: 0 | AN19: 0 | AO19: 0 | AP19: 0 | AQ19: 0 | AR19: 0 | AS19: 0 | AT19: 0 | AU19: 0 | AX19: غير | AY19: ذكر | AZ19: 0 | BA19: 3 | BB19: 15 | BC19: 114 | BD19: 44 | BE19: 4 | BF19: 9 | BG19: 95 | BH19: 0 | BI19: 0 | BJ19: 0 | BK19: 0 | BN19: غير | BO19: ذكر | BP19: 0 | BQ19: 0 | BR19: 8 | BS19: 52 | BT19: 44 | BU19: 0 | BV19: 3 | BW19: 42 | BX19: 0 | BY19: 0 | BZ19: 0 | CA19: 0 | CD19: غير | CE19: ذكر | CF19: 0 | CG19: 3 | CH19: 9 | CI19: 114 | CJ19: 44 | CK19: 4 | CL19: 9 | CM19: 95 | CN19: 0 | CO19: 0 | CP19: 0 | CQ19: 0 | CT19: غير | CU19: ذكر | CV19: 52 | CW19: 0 | CX19: 0 | CY19: 0 | CZ19: 45 | DA19: 0 | DB19: 0 | DC19: 0 | DD19: 0 | DE19: 0 | DF19: 0 | DG19: 0 | DJ19: غير | DK19: ذكر | DL19: 125 | DM19: 2 | DN19: 20 | DO19: 135 | DP19: 163 | DQ19: 2 | DR19: 4 | DS19: 124 | DT19: 0 | DU19: 0 | DV19: 0 | DW19: 0 | DZ19: غير | EA19: ذكر | EB19: 56 | EC19: 1 | ED19: 0 | EE19: 5 | EF19: 32 | EG19: 0 | EH19: 0 | EI19: 0 | EJ19: 2 | EK19: 0 | EL19: 0 | EM19: 0 | EP19: غير | EQ19: ذكر | ER19: 56 | ES19: 1 | ET19: 0 | EU19: 9 | EV19: 32 | EW19: 0 | EX19: 0 | EY19: 0 | EZ19: 2 | FA19: 0 | FB19: 0 | FC19: 0 | FF19: غير | FG19: ذكر | FH19: 0 | FI19: 0 | FJ19: 0 | FK19: 0 | FL19: 0 | FM19: 0 | FN19: 0 | FO19: 0 | FP19: 0 | FQ19: 0 | FR19: 0 | FS19: 0 | FV19: غير | FW19: ذكر | FX19: 0 | FY19: 0 | FZ19: 0 | GA19: 0 | GB19: 0 | GC19: 0 | GD19: 0 | GE19: 0 | GF19: 0 | GG19: 0 | GH19: 0 | GI19: 0 | GL19: غير | GM19: ذكر | GN19: =FX19 -> 0 | GO19: =E19+U19+AK19+BA19+BQ19+CG19++CW19+DM19+EC19+ES19+FI19+FY19 -> 10 | GP19: =F19+V19+AL19+BB19+BR19+CH19++CX19+DN19+ED19+ET19+FJ19+FZ19 -> 62 | GQ19: =G19+W19+AM19+BC19+BS19+CI19++CY19+DO19+EE19+EU19+FK19+GA19 -> 538 | GR19: =GB19 -> 0 | GS19: =I19+Y19+AO19+BE19+BU19+CK19++DA19+DQ19+EG19+EW19+FM19+GC19 -> 10 | GT19: =J19+Z19+AP19+BF19+BV19+CL19++DB19+DR19+EH19+EX19+FN19+GD19 -> 33 | GU19: =K19+AA19+AQ19+BG19+BW19+CM19++DC19+DS19+EI19+EY19+FO19+GE19 -> 546 | GV19: =GF19 -> 0 | GW19: =M19+AC19+AS19+BI19+BY19+CO19++DE19+DU19+EK19+FA19+FQ19+GG19 -> 0 | GX19: =N19+AD19+AT19+BJ19+BZ19+CP19++DF19+DV19+EL19+FB19+FR19+GH19 -> 0 | GY19: =O19+AE19+AU19+BK19+CA19+CQ19++DG19+DW19+EM19+FC19+FS19+GI19 -> 0
B20: سعودي | C20: أنثى | D20: 45 | E20: 0 | F20: 2 | G20: 30 | H20: 100 | I20: 0 | J20: 5 | K20: 26 | L20: 0 | M20: 0 | N20: 0 | O20: 0 | R20: سعودي | S20: أنثى | T20: 0 | U20: 0 | V20: 0 | W20: 0 | X20: 0 | Y20: 0 | Z20: 0 | AA20: 0 | AB20: 0 | AC20: 0 | AD20: 0 | AE20: 0 | AH20: سعودي | AI20: أنثى | AJ20: 0 | AK20: 0 | AL20: 0 | AM20: 0 | AN20: 0 | AO20: 0 | AP20: 0 | AQ20: 0 | AR20: 0 | AS20: 0 | AT20: 0 | AU20: 0 | AX20: سعودي | AY20: أنثى | AZ20: 0 | BA20: 7 | BB20: 17 | BC20: 50 | BD20: 98 | BE20: 1 | BF20: 11 | BG20: 60 | BH20: 0 | BI20: 0 | BJ20: 0 | BK20: 0 | BN20: سعودي | BO20: أنثى | BP20: 0 | BQ20: 0 | BR20: 4 | BS20: 39 | BT20: 98 | BU20: 0 | BV20: 0 | BW20: 29 | BX20: 0 | BY20: 0 | BZ20: 0 | CA20: 0 | CD20: سعودي | CE20: أنثى | CF20: 0 | CG20: 7 | CH20: 10 | CI20: 50 | CJ20: 98 | CK20: 1 | CL20: 11 | CM20: 60 | CN20: 0 | CO20: 0 | CP20: 0 | CQ20: 0 | CT20: سعودي | CU20: أنثى | CV20: 66 | CW20: 0 | CX20: 0 | CY20: 0 | CZ20: 200 | DA20: 0 | DB20: 0 | DC20: 0 | DD20: 0 | DE20: 0 | DF20: 0 | DG20: 0 | DJ20: سعودي | DK20: أنثى | DL20: 0 | DM20: 3 | DN20: 9 | DO20: 114 | DP20: 44 | DQ20: 4 | DR20: 9 | DS20: 95 | DT20: 0 | DU20: 0 | DV20: 0 | DW20: 0 | DZ20: سعودي | EA20: أنثى | EB20: 45 | EC20: 2 | ED20: 0 | EE20: 4 | EF20: 15 | EG20: 0 | EH20: 0 | EI20: 0 | EJ20: 1 | EK20: 0 | EL20: 0 | EM20: 0 | EP20: سعودي | EQ20: أنثى | ER20: 45 | ES20: 2 | ET20: 0 | EU20: 10 | EV20: 15 | EW20: 0 | EX20: 0 | EY20: 0 | EZ20: 1 | FA20: 0 | FB20: 0 | FC20: 0 | FF20: سعودي | FG20: أنثى | FH20: 0 | FI20: 0 | FJ20: 0 | FK20: 0 | FL20: 0 | FM20: 0 | FN20: 0 | FO20: 0 | FP20: 0 | FQ20: 0 | FR20: 0 | FS20: 0 | FV20: سعودي | FW20: أنثى | FX20: 0 | FY20: 0 | FZ20: 0 | GA20: 0 | GB20: 0 | GC20: 0 | GD20: 0 | GE20: 0 | GF20: 0 | GG20: 0 | GH20: 0 | GI20: 0 | GL20: سعودي | GM20: أنثى | GN20: =FX20 -> 0 | GO20: =E20+U20+AK20+BA20+BQ20+CG20++CW20+DM20+EC20+ES20+FI20+FY20 -> 21 | GP20: =F20+V20+AL20+BB20+BR20+CH20++CX20+DN20+ED20+ET20+FJ20+FZ20 -> 42 | GQ20: =G20+W20+AM20+BC20+BS20+CI20++CY20+DO20+EE20+EU20+FK20+GA20 -> 297 | GR20: =GB20 -> 0 | GS20: =I20+Y20+AO20+BE20+BU20+CK20++DA20+DQ20+EG20+EW20+FM20+GC20 -> 6 | GT20: =J20+Z20+AP20+BF20+BV20+CL20++DB20+DR20+EH20+EX20+FN20+GD20 -> 36 | GU20: =K20+AA20+AQ20+BG20+BW20+CM20++DC20+DS20+EI20+EY20+FO20+GE20 -> 270 | GV20: =GF20 -> 0 | GW20: =M20+AC20+AS20+BI20+BY20+CO20++DE20+DU20+EK20+FA20+FQ20+GG20 -> 0 | GX20: =N20+AD20+AT20+BJ20+BZ20+CP20++DF20+DV20+EL20+FB20+FR20+GH20 -> 0 | GY20: =O20+AE20+AU20+BK20+CA20+CQ20++DG20+DW20+EM20+FC20+FS20+GI20 -> 0
B21: المجموع | D21: =SUM(D17:D20) -> 280 | E21: =SUM(E17:E20) -> 15 | F21: =SUM(F17:F20) -> 54 | G21: =SUM(G17:G20) -> 411 | H21: =SUM(H17:H20) -> 518 | I21: =SUM(I17:I20) -> 6 | J21: =SUM(J17:J20) -> 58 | K21: =SUM(K17:K20) -> 641 | ... O21: =SUM(O17:O20) -> 0 | R21: المجموع | T21: =SUM(T17:T20) -> 0 | U21: =SUM(U17:U20) -> 0 | V21: =SUM(V17:V20) -> 0 | W21: =SUM(W17:W20) -> 0 | X21: =SUM(X17:X20) -> 0 | Y21: =SUM(Y17:Y20) -> 0 | Z21: =SUM(Z17:Z20) -> 0 | AA21: =SUM(AA17:AA20) -> 0 | ... AE21: =SUM(AE17:AE20) -> 0 | AH21: المجموع | AJ21: 0 | AK21: 0 | AL21: 0 | AM21: 0 | AN21: 0 | AO21: 0 | AP21: 0 | AQ21: 0 | AR21: 0 | AS21: 0 | AT21: 0 | AU21: 0 | AX21: المجموع | AZ21: =SUM(AZ17:AZ20) -> 313 | BA21: =SUM(BA17:BA20) -> 25 | BB21: =SUM(BB17:BB20) -> 116 | BC21: =SUM(BC17:BC20) -> 421 | BD21: =SUM(BD17:BD20) -> 542 | BE21: =SUM(BE17:BE20) -> 14 | BF21: =SUM(BF17:BF20) -> 42 | BG21: =SUM(BG17:BG20) -> 414 | ... BK21: =SUM(BK17:BK20) -> 1 | BN21: المجموع | BP21: =SUM(BP17:BP20) -> 313 | BQ21: =SUM(BQ17:BQ20) -> 3 | BR21: =SUM(BR17:BR20) -> 55 | BS21: =SUM(BS17:BS20) -> 556 | BT21: =SUM(BT17:BT20) -> 550 | BU21: =SUM(BU17:BU20) -> 1 | BV21: =SUM(BV17:BV20) -> 17 | BW21: =SUM(BW17:BW20) -> 472 | ... CA21: =SUM(CA17:CA20) -> 1 | CD21: المجموع | CF21: 250 | CG21: 17 | CH21: 74 | CI21: 421 | CJ21: 463 | CK21: 14 | CL21: 34 | CM21: 414 | CN21: 0 | CO21: 0 | CP21: 0 | CQ21: 1 | CT21: المجموع | CV21: 423 | CW21: 20 | CX21: 114 | CY21: 0 | CZ21: 557 | DA21: 9600 | DB21: 65 | DC21: 0 | DD21: 0 | DE21: 0 | DF21: 0 | DG21: 0 | DJ21: المجموع | DL21: 0 | DM21: 7 | DN21: 10 | DO21: 50 | DP21: 98 | DQ21: 1 | DR21: 11 | DS21: 60 | DT21: 0 | DU21: 0 | DV21: 0 | DW21: 0 | DZ21: المجموع | EB21: =SUM(EB17:EB20) -> 596 | EC21: =SUM(EC17:EC20) -> 12 | ED21: =SUM(ED17:ED20) -> 0 | EE21: =SUM(EE17:EE20) -> 91 | EF21: =SUM(EF17:EF20) -> 403 | EG21: =SUM(EG17:EG20) -> 6 | EH21: =SUM(EH17:EH20) -> 0 | EI21: =SUM(EI17:EI20) -> 0 | ... EM21: =SUM(EM17:EM20) -> 0 | EP21: المجموع | ER21: =SUM(ER17:ER20) -> 596 | ES21: =SUM(ES17:ES20) -> 12 | ET21: =SUM(ET17:ET20) -> 0 | EU21: =SUM(EU17:EU20) -> 165 | EV21: =SUM(EV17:EV20) -> 403 | EW21: =SUM(EW17:EW20) -> 6 | EX21: =SUM(EX17:EX20) -> 0 | EY21: =SUM(EY17:EY20) -> 0 | ... FC21: =SUM(FC17:FC20) -> 0 | FF21: المجموع | FH21: =SUM(FH17:FH20) -> 0 | FI21: =SUM(FI17:FI20) -> 0 | FJ21: =SUM(FJ17:FJ20) -> 0 | FK21: =SUM(FK17:FK20) -> 0 | FL21: =SUM(FL17:FL20) -> 0 | FM21: =SUM(FM17:FM20) -> 0 | FN21: =SUM(FN17:FN20) -> 0 | FO21: =SUM(FO17:FO20) -> 0 | ... FS21: =SUM(FS17:FS20) -> 0 | FV21: المجموع | FX21: =SUM(FX17:FX20) -> 0 | FY21: =SUM(FY17:FY20) -> 0 | FZ21: =SUM(FZ17:FZ20) -> 0 | GA21: =SUM(GA17:GA20) -> 0 | GB21: =SUM(GB17:GB20) -> 0 | GC21: =SUM(GC17:GC20) -> 0 | GD21: =SUM(GD17:GD20) -> 0 | GE21: =SUM(GE17:GE20) -> 0 | ... GI21: =SUM(GI17:GI20) -> 0 | GL21: المجموع | GN21: =SUM(GN17:GN20) -> 0 | GO21: =SUM(GO17:GO20) -> #VALUE! | GP21: =SUM(GP17:GP20) -> 477 | GQ21: =SUM(GQ17:GQ20) -> 2436 | GR21: =SUM(GR17:GR20) -> 0 | GS21: =SUM(GS17:GS20) -> #VALUE! | GT21: =SUM(GT17:GT20) -> 239 | GU21: =SUM(GU17:GU20) -> 2295 | ... GY21: =SUM(GY17:GY20) -> 4
B22: العدد المتوقع للمصابين : | E22: مرضى السكري | G22: 0 | I22: مرضى الضغط | K22: 0 | M22: م.الربو | N22: 0 | R22: العدد المتوقع للمصابين : | U22: مرضى السكري | W22: 0 | Y22: مرضى الضغط | AA22: 0 | AC22: م.الربو | AD22: 0 | AH22: العدد المتوقع للمصابين : | AK22: مرضى السكري | AM22: 0 | AO22: مرضى الضغط | AQ22: 0 | AS22: م.الربو | AT22: 0 | AX22: العدد المتوقع للمصابين : | BA22: مرضى السكري | BC22: 0 | BE22: مرضى الضغط | BG22: 0 | BI22: م.الربو | BJ22: 0 | BN22: العدد المتوقع للمصابين : | BQ22: مرضى السكري | BS22: 0 | BU22: مرضى الضغط | BW22: 0 | BY22: م.الربو | BZ22: 0 | CD22: العدد المتوقع للمصابين : | CG22: مرضى السكري | CI22: 0 | CK22: مرضى الضغط | CM22: 0 | CO22: م.الربو | CP22: 0 | CT22: العدد المتوقع للمصابين : | CW22: مرضى السكري | CY22: 0 | DA22: مرضى الضغط | DC22: 0 | DE22: م.الربو | DF22: 0 | DJ22: العدد المتوقع للمصابين : | DM22: مرضى السكري | DO22: 0 | DQ22: مرضى الضغط | DS22: 0 | DU22: م.الربو | DV22: 0 | DZ22: العدد المتوقع للمصابين : | EC22: مرضى السكري | EE22: 0 | EG22: مرضى الضغط | EI22: 0 | EK22: م.الربو | EL22: 0 | EP22: العدد المتوقع للمصابين : | ES22: مرضى السكري | EU22: 0 | EW22: مرضى الضغط | EY22: 0 | FA22: م.الربو | FB22: 0 | FF22: العدد المتوقع للمصابين : | FI22: مرضى السكري | FK22: 0 | FM22: مرضى الضغط | FO22: 0 | FQ22: م.الربو | FR22: 0 | FV22: العدد المتوقع للمصابين : | FY22: مرضى السكري | GA22: 0 | GC22: مرضى الضغط | GE22: 0 | GG22: م.الربو | GH22: 0 | GL22: العدد المتوقع للمصابين : | GO22: مرضى السكري | GR22: =G22+W22+AM22+BC22+BS22+CI22+CY22+DO22+EE22+EU22+FK22+GA22 -> 0 | GS22: مرضى الضغط | GV22: =K22+AA22+AQ22+BG22+BW22+CM22+DC22+DS22+EI22+EY22+FO22+GE22 -> 0 | GW22: م.الربو | GY22: =N22+AD22+AT22+BJ22+BZ22+CP22+DF22+DV22+EL22+FB22+FR22+GH22 -> 0
A23: المطار القديم | C23: ذكر | D23: 310 | E23: 11 | F23: 15 | G23: 0 | H23: 287 | I23: 1 | J23: 6 | K23: 0 | L23: 8 | M23: 0 | N23: 0 | O23: 0 | Q23: المطار القديم | S23: ذكر | T23: 310 | U23: 14 | V23: 15 | W23: 110 | X23: 287 | Y23: 1 | Z23: 6 | AA23: 98 | AB23: 8 | AC23: 0 | AD23: 0 | AE23: 0 | AG23: المطار القديم | AI23: ذكر | AJ23: 157 | AK23: 2 | AL23: 0 | AM23: 0 | AN23: 110 | AO23: 1 | AP23: 0 | AQ23: 0 | AR23: 42 | AS23: 2 | AT23: 0 | AU23: 0 | AW23: المطار القديم | AY23: ذكر | AZ23: 310 | BA23: 11 | BB23: 15 | BC23: 115 | BD23: 287 | BE23: 1 | BF23: 6 | BG23: 100 | BH23: 8 | BI23: 0 | BJ23: 0 | BK23: 0 | BM23: المطار القديم | BO23: ذكر | BP23: 410 | BQ23: 0 | BR23: 1 | BS23: 60 | BT23: 397 | BU23: 0 | BV23: 6 | BW23: 60 | BX23: 61 | BY23: 0 | BZ23: 0 | CA23: 6 | CC23: المطار القديم | CE23: ذكر | CF23: 263 | CG23: 0 | CH23: 1 | CI23: 18 | CJ23: 133 | CK23: 0 | CL23: 1 | CM23: 11 | CN23: 33 | CO23: 0 | CP23: 0 | CQ23: 0 | CS23: المطار القديم | CU23: ذكر | CV23: 310 | CW23: 14 | CX23: 15 | CY23: 110 | CZ23: 287 | DA23: 1 | DB23: 6 | DC23: 98 | DD23: 8 | DE23: 0 | DF23: 0 | DG23: 1 | DI23: المطار القديم | DK23: ذكر | DL23: 320 | DM23: 0 | DN23: 1 | DO23: 50 | DP23: 21 | DQ23: 0 | DR23: 0 | DS23: 72 | DT23: 40 | DU23: 0 | DV23: 0 | DW23: 0 | DY23: المطار القديم | EA23: ذكر | EB23: 1343 | EC23: 4 | ED23: 0 | EE23: 48 | EF23: 968 | EG23: 12 | EH23: 0 | EI23: 23 | EJ23: 23 | EK23: 2 | EL23: 0 | EM23: 3 | EO23: المطار القديم | EQ23: ذكر | ER23: 1343 | ES23: 4 | ET23: 0 | EU23: 30 | EV23: 968 | EW23: 12 | EX23: 0 | EY23: 20 | EZ23: 23 | FA23: 2 | FB23: 0 | FC23: 0 | FE23: المطار القديم | FG23: ذكر | FH23: 0 | FI23: 0 | FJ23: 0 | FK23: 0 | FL23: 0 | FM23: 0 | FN23: 0 | FO23: 0 | FP23: 0 | FQ23: 0 | FR23: 0 | FS23: 0 | FU23: المطار القديم | FW23: ذكر | FX23: 0 | FY23: 0 | FZ23: 0 | GA23: 0 | GB23: 0 | GC23: 0 | GD23: 0 | GE23: 0 | GF23: 0 | GG23: 0 | GH23: 0 | GI23: 0 | GK23: =FU23 -> المطار القديم | GM23: ذكر | GN23: =FX23 -> 0 | GO23: =E23+U23+AK23+BA23+BQ23+CG23++CW23+DM23+EC23+ES23+FI23+FY23 -> 60 | GP23: =F23+V23+AL23+BB23+BR23+CH23++CX23+DN23+ED23+ET23+FJ23+FZ23 -> 63 | GQ23: =G23+W23+AM23+BC23+BS23+CI23++CY23+DO23+EE23+EU23+FK23+GA23 -> 541 | GR23: =GB23 -> 0 | GS23: =I23+Y23+AO23+BE23+BU23+CK23++DA23+DQ23+EG23+EW23+FM23+GC23 -> 29 | GT23: =J23+Z23+AP23+BF23+BV23+CL23++DB23+DR23+EH23+EX23+FN23+GD23 -> 31 | GU23: =K23+AA23+AQ23+BG23+BW23+CM23++DC23+DS23+EI23+EY23+FO23+GE23 -> 482 | GV23: =GF23 -> 0 | GW23: =M23+AC23+AS23+BI23+BY23+CO23++DE23+DU23+EK23+FA23+FQ23+GG23 -> 6 | GX23: =N23+AD23+AT23+BJ23+BZ23+CP23++DF23+DV23+EL23+FB23+FR23+GH23 -> 0 | GY23: =O23+AE23+AU23+BK23+CA23+CQ23++DG23+DW23+EM23+FC23+FS23+GI23 -> 10
B24: سعودي | C24: أنثى | D24: 298 | E24: 7 | F24: 7 | G24: 0 | H24: 108 | I24: 0 | J24: 0 | K24: 0 | L24: 0 | M24: 0 | N24: 0 | O24: 0 | R24: سعودي | S24: أنثى | T24: 298 | U24: 9 | V24: 8 | W24: 95 | X24: 108 | Y24: 0 | Z24: 0 | AA24: 96 | AB24: 0 | AC24: 0 | AD24: 0 | AE24: 0 | AH24: سعودي | AI24: أنثى | AJ24: 110 | AK24: 10 | AL24: 0 | AM24: 0 | AN24: 130 | AO24: 7 | AP24: 0 | AQ24: 0 | AR24: 3 | AS24: 0 | AT24: 0 | AU24: 0 | AX24: سعودي | AY24: أنثى | AZ24: 298 | BA24: 7 | BB24: 8 | BC24: 80 | BD24: 108 | BE24: 0 | BF24: 0 | BG24: 91 | BH24: 0 | BI24: 0 | BJ24: 0 | BK24: 0 | BN24: سعودي | BO24: أنثى | BP24: 308 | BQ24: 0 | BR24: 30 | BS24: 45 | BT24: 206 | BU24: 0 | BV24: 5 | BW24: 61 | BX24: 62 | BY24: 0 | BZ24: 0 | CA24: 2 | CD24: سعودي | CE24: أنثى | CF24: 315 | CG24: 0 | CH24: 1 | CI24: 22 | CJ24: 216 | CK24: 0 | CL24: 0 | CM24: 20 | CN24: 36 | CO24: 0 | CP24: 0 | CQ24: 0 | CT24: سعودي | CU24: أنثى | CV24: 298 | CW24: 9 | CX24: 8 | CY24: 95 | CZ24: 108 | DA24: 0 | DB24: 0 | DC24: 96 | DD24: 0 | DE24: 0 | DF24: 0 | DG24: 0 | DJ24: سعودي | DK24: أنثى | DL24: 100 | DM24: 0 | DN24: 1 | DO24: 46 | DP24: 7 | DQ24: 0 | DR24: 0 | DS24: 44 | DT24: 30 | DU24: 0 | DV24: 0 | DW24: 0 | DZ24: سعودي | EA24: أنثى | EB24: 0 | EC24: 3 | ED24: 0 | EE24: 29 | EF24: 755 | EG24: 11 | EH24: 0 | EI24: 11 | EJ24: 20 | EK24: 1 | EL24: 0 | EM24: 3 | EP24: سعودي | EQ24: أنثى | ER24: 0 | ES24: 3 | ET24: 0 | EU24: 20 | EV24: 755 | EW24: 11 | EX24: 0 | EY24: 10 | EZ24: 20 | FA24: 1 | FB24: 0 | FC24: 0 | FF24: سعودي | FG24: أنثى | FH24: 0 | FI24: 0 | FJ24: 0 | FK24: 0 | FL24: 0 | FM24: 0 | FN24: 0 | FO24: 0 | FP24: 0 | FQ24: 0 | FR24: 0 | FS24: 0 | FV24: سعودي | FW24: أنثى | FX24: 0 | FY24: 0 | FZ24: 0 | GA24: 0 | GB24: 0 | GC24: 0 | GD24: 0 | GE24: 0 | GF24: 0 | GG24: 0 | GH24: 0 | GI24: 0 | GL24: سعودي | GM24: أنثى | GN24: =FX24 -> 0 | GO24: =E24+U24+AK24+BA24+BQ24+CG24++CW24+DM24+EC24+ES24+FI24+FY24 -> 48 | GP24: =F24+V24+AL24+BB24+BR24+CH24++CX24+DN24+ED24+ET24+FJ24+FZ24 -> 63 | GQ24: =G24+W24+AM24+BC24+BS24+CI24++CY24+DO24+EE24+EU24+FK24+GA24 -> 432 | GR24: =GB24 -> 0 | GS24: =I24+Y24+AO24+BE24+BU24+CK24++DA24+DQ24+EG24+EW24+FM24+GC24 -> 29 | GT24: =J24+Z24+AP24+BF24+BV24+CL24++DB24+DR24+EH24+EX24+FN24+GD24 -> 5 | GU24: =K24+AA24+AQ24+BG24+BW24+CM24++DC24+DS24+EI24+EY24+FO24+GE24 -> 429 | GV24: =GF24 -> 0 | GW24: =M24+AC24+AS24+BI24+BY24+CO24++DE24+DU24+EK24+FA24+FQ24+GG24 -> 2 | GX24: =N24+AD24+AT24+BJ24+BZ24+CP24++DF24+DV24+EL24+FB24+FR24+GH24 -> 0 | GY24: =O24+AE24+AU24+BK24+CA24+CQ24++DG24+DW24+EM24+FC24+FS24+GI24 -> 5
B25: غير | C25: ذكر | D25: 189 | E25: 7 | F25: 2 | G25: 0 | H25: 87 | I25: 0 | J25: 1 | K25: 0 | L25: 0 | M25: 0 | N25: 0 | O25: 0 | R25: غير | S25: ذكر | T25: 189 | U25: 8 | V25: 2 | W25: 69 | X25: 87 | Y25: 0 | Z25: 1 | AA25: 8 | AB25: 0 | AC25: 0 | AD25: 0 | AE25: 0 | AH25: غير | AI25: ذكر | AJ25: 9 | AK25: 0 | AL25: 0 | AM25: 0 | AN25: 14 | AO25: 0 | AP25: 0 | AQ25: 0 | AR25: 0 | AS25: 0 | AT25: 0 | AU25: 0 | AX25: غير | AY25: ذكر | AZ25: 189 | BA25: 7 | BB25: 2 | BC25: 40 | BD25: 77 | BE25: 0 | BF25: 1 | BG25: 10 | BH25: 0 | BI25: 0 | BJ25: 0 | BK25: 0 | BN25: غير | BO25: ذكر | BP25: 100 | BQ25: 0 | BR25: 1 | BS25: 1 | BT25: 61 | BU25: 0 | BV25: 3 | BW25: 13 | BX25: 13 | BY25: 0 | BZ25: 0 | CA25: 4 | CD25: غير | CE25: ذكر | CF25: 31 | CG25: 0 | CH25: 0 | CI25: 2 | CJ25: 22 | CK25: 0 | CL25: 0 | CM25: 0 | CN25: 1 | CO25: 0 | CP25: 0 | CQ25: 0 | CT25: غير | CU25: ذكر | CV25: 189 | CW25: 8 | CX25: 2 | CY25: 69 | CZ25: 87 | DA25: 0 | DB25: 1 | DC25: 8 | DD25: 0 | DE25: 0 | DF25: 0 | DG25: 0 | DJ25: غير | DK25: ذكر | DL25: 29 | DM25: 0 | DN25: 2 | DO25: 12 | DP25: 10 | DQ25: 0 | DR25: 0 | DS25: 23 | DT25: 6 | DU25: 0 | DV25: 0 | DW25: 0 | DZ25: غير | EA25: ذكر | EB25: 0 | EC25: 1 | ED25: 0 | EE25: 17 | EF25: 721 | EG25: 2 | EH25: 0 | EI25: 2 | EJ25: 5 | EK25: 0 | EL25: 0 | EM25: 1 | EP25: غير | EQ25: ذكر | ER25: 0 | ES25: 1 | ET25: 0 | EU25: 10 | EV25: 721 | EW25: 2 | EX25: 0 | EY25: 0 | EZ25: 5 | FA25: 0 | FB25: 0 | FC25: 0 | FF25: غير | FG25: ذكر | FH25: 0 | FI25: 0 | FJ25: 0 | FK25: 0 | FL25: 0 | FM25: 0 | FN25: 0 | FO25: 0 | FP25: 0 | FQ25: 0 | FR25: 0 | FS25: 0 | FV25: غير | FW25: ذكر | FX25: 0 | FY25: 0 | FZ25: 0 | GA25: 0 | GB25: 0 | GC25: 0 | GD25: 0 | GE25: 0 | GF25: 0 | GG25: 0 | GH25: 0 | GI25: 0 | GL25: غير | GM25: ذكر | GN25: =FX25 -> 0 | GO25: =E25+U25+AK25+BA25+BQ25+CG25++CW25+DM25+EC25+ES25+FI25+FY25 -> 32 | GP25: =F25+V25+AL25+BB25+BR25+CH25++CX25+DN25+ED25+ET25+FJ25+FZ25 -> 11 | GQ25: =G25+W25+AM25+BC25+BS25+CI25++CY25+DO25+EE25+EU25+FK25+GA25 -> 220 | GR25: =GB25 -> 0 | GS25: =I25+Y25+AO25+BE25+BU25+CK25++DA25+DQ25+EG25+EW25+FM25+GC25 -> 4 | GT25: =J25+Z25+AP25+BF25+BV25+CL25++DB25+DR25+EH25+EX25+FN25+GD25 -> 7 | GU25: =K25+AA25+AQ25+BG25+BW25+CM25++DC25+DS25+EI25+EY25+FO25+GE25 -> 64 | GV25: =GF25 -> 0 | GW25: =M25+AC25+AS25+BI25+BY25+CO25++DE25+DU25+EK25+FA25+FQ25+GG25 -> 0 | GX25: =N25+AD25+AT25+BJ25+BZ25+CP25++DF25+DV25+EL25+FB25+FR25+GH25 -> 0 | GY25: =O25+AE25+AU25+BK25+CA25+CQ25++DG25+DW25+EM25+FC25+FS25+GI25 -> 5
B26: سعودي | C26: أنثى | D26: 110 | E26: 0 | F26: 0 | G26: 0 | H26: 30 | I26: 0 | J26: 0 | K26: 0 | L26: 0 | M26: 0 | N26: 0 | O26: 0 | R26: سعودي | S26: أنثى | T26: 110 | U26: 0 | V26: 0 | W26: 40 | X26: 30 | Y26: 0 | Z26: 0 | AA26: 14 | AB26: 0 | AC26: 0 | AD26: 0 | AE26: 0 | AH26: سعودي | AI26: أنثى | AJ26: 16 | AK26: 3 | AL26: 0 | AM26: 0 | AN26: 10 | AO26: 2 | AP26: 0 | AQ26: 0 | AR26: 0 | AS26: 0 | AT26: 0 | AU26: 0 | AX26: سعودي | AY26: أنثى | AZ26: 100 | BA26: 0 | BB26: 0 | BC26: 20 | BD26: 35 | BE26: 0 | BF26: 0 | BG26: 19 | BH26: 0 | BI26: 0 | BJ26: 0 | BK26: 0 | BN26: سعودي | BO26: أنثى | BP26: 110 | BQ26: 0 | BR26: 0 | BS26: 0 | BT26: 109 | BU26: 0 | BV26: 0 | BW26: 0 | BX26: 6 | BY26: 0 | BZ26: 0 | CA26: 0 | CD26: سعودي | CE26: أنثى | CF26: 25 | CG26: 0 | CH26: 0 | CI26: 3 | CJ26: 25 | CK26: 0 | CL26: 0 | CM26: 0 | CN26: 2 | CO26: 0 | CP26: 0 | CQ26: 0 | CT26: سعودي | CU26: أنثى | CV26: 110 | CW26: 0 | CX26: 0 | CY26: 40 | CZ26: 30 | DA26: 0 | DB26: 0 | DC26: 14 | DD26: 0 | DE26: 0 | DF26: 0 | DG26: 0 | DJ26: سعودي | DK26: أنثى | DL26: 7 | DM26: 0 | DN26: 0 | DO26: 27 | DP26: 5 | DQ26: 0 | DR26: 0 | DS26: 9 | DT26: 0 | DU26: 0 | DV26: 0 | DW26: 0 | DZ26: سعودي | EA26: أنثى | EB26: 0 | EC26: 0 | ED26: 0 | EE26: 12 | EF26: 90 | EG26: 3 | EH26: 0 | EI26: 2 | EJ26: 5 | EK26: 1 | EL26: 0 | EM26: 2 | EP26: سعودي | EQ26: أنثى | ER26: 0 | ES26: 0 | ET26: 0 | EU26: 8 | EV26: 90 | EW26: 3 | EX26: 0 | EY26: 0 | EZ26: 5 | FA26: 1 | FB26: 0 | FC26: 0 | FF26: سعودي | FG26: أنثى | FH26: 0 | FI26: 0 | FJ26: 0 | FK26: 0 | FL26: 0 | FM26: 0 | FN26: 0 | FO26: 0 | FP26: 0 | FQ26: 0 | FR26: 0 | FS26: 0 | FV26: سعودي | FW26: أنثى | FX26: 0 | FY26: 0 | FZ26: 0 | GA26: 0 | GB26: 0 | GC26: 0 | GD26: 0 | GE26: 0 | GF26: 0 | GG26: 0 | GH26: 0 | GI26: 0 | GL26: سعودي | GM26: أنثى | GN26: =FX26 -> 0 | GO26: =E26+U26+AK26+BA26+BQ26+CG26++CW26+DM26+EC26+ES26+FI26+FY26 -> 3 | GP26: =F26+V26+AL26+BB26+BR26+CH26++CX26+DN26+ED26+ET26+FJ26+FZ26 -> 0 | GQ26: =G26+W26+AM26+BC26+BS26+CI26++CY26+DO26+EE26+EU26+FK26+GA26 -> 150 | GR26: =GB26 -> 0 | GS26: =I26+Y26+AO26+BE26+BU26+CK26++DA26+DQ26+EG26+EW26+FM26+GC26 -> 8 | GT26: =J26+Z26+AP26+BF26+BV26+CL26++DB26+DR26+EH26+EX26+FN26+GD26 -> 0 | GU26: =K26+AA26+AQ26+BG26+BW26+CM26++DC26+DS26+EI26+EY26+FO26+GE26 -> 58 | GV26: =GF26 -> 0 | GW26: =M26+AC26+AS26+BI26+BY26+CO26++DE26+DU26+EK26+FA26+FQ26+GG26 -> 2 | GX26: =N26+AD26+AT26+BJ26+BZ26+CP26++DF26+DV26+EL26+FB26+FR26+GH26 -> 0 | GY26: =O26+AE26+AU26+BK26+CA26+CQ26++DG26+DW26+EM26+FC26+FS26+GI26 -> 2
