Workbook

Sheet شرق جدة
C1: الأمراض الشائعة في الرعاية الصحية الأولية | P1: الأمراض الشائعة في الرعاية الصحية الأولية | AC1: الأمراض الشائعة في الرعاية الصحية الأولية | AP1: الأمراض الشائعة في الرعاية الصحية الأولية | BC1: الأمراض الشائعة في الرعاية الصحية الأولية | BP1: الأمراض الشائعة في الرعاية الصحية الأولية | CC1: الأمراض الشائعة في الرعاية الصحية الأولية | CP1: الأمراض الشائعة في الرعاية الصحية الأولية | DC1: الأمراض الشائعة في الرعاية الصحية الأولية | DP1: الأمراض الشائعة في الرعاية الصحية الأولية | EC1: الأمراض الشائعة في الرعاية الصحية الأولية | EP1: الأمراض الشائعة في الرعاية الصحية الأولية
B2: الربيع والتوفيق | F2: شهر | G2: 1 | H2: عام | I2: 1447 | K2: هـ | O2: =B2 -> الربيع والتوفيق | S2: شهر | T2: 2 | U2: عام | V2: 1447 | X2: هـ | AB2: =O2 -> الربيع والتوفيق | AF2: شهر | AG2: 3 | AH2: عام | AI2: 1447 | AK2: هـ | AO2: =AB2 -> الربيع والتوفيق | AS2: شهر | AT2: 4 | AU2: عام | AV2: 1447 | AX2: هـ | BB2: =AO2 -> الربيع والتوفيق | BF2: شهر | BG2: 5 | BH2: عام | BI2: 1447 | BK2: هـ | BO2: =BB2 -> الربيع والتوفيق | BS2: شهر | BT2: 6 | BU2: عام | BV2: 1447 | BX2: هـ | CB2: =BO2 -> الربيع والتوفيق | CF2: شهر | CG2: 7 | CH2: عام | CI2: 1447 | CK2: هـ | CO2: =CB2 -> الربيع والتوفيق | CS2: شهر | CT2: 8 | CU2: عام | CV2: 1447 | CX2: هـ | DB2: =CO2 -> الربيع والتوفيق | DF2: شهر | DG2: 9 | DH2: عام | DI2: 1447 | DK2: هـ | DO2: =DB2 -> الربيع والتوفيق | DS2: شهر | DT2: 10 | DU2: عام | DV2: 1447 | DX2: هـ | EB2: =DO2 -> الربيع والتوفيق | EF2: شهر | EG2: 11 | EH2: عام | EI2: 1447 | EK2: هـ | EO2: =EB2 -> الربيع والتوفيق | ES2: شهر | ET2: 12 | EU2: عام | EV2: 1447 | EX2: هـ | FC2: =(EO2) -> الربيع والتوفيق | FE2: الأمراض الشائعة في الرعاية الصحية الأولية ( ترددات ) | FK2: إجمالي عام | FM2: =SUM(EV2) -> 1447
A3: الرقم | B3: الجنسية والجنس | F3: المجموع | G3: العمر بالسنين | N3: الرقم | O3: الجنسية والجنس | S3: المجموع | T3: العمر بالسنين | AA3: الرقم | AB3: الجنسية والجنس | AF3: المجموع | AG3: العمر بالسنين | AN3: الرقم | AO3: الجنسية والجنس | AS3: المجموع | AT3: العمر بالسنين | BA3: الرقم | BB3: الجنسية والجنس | BF3: المجموع | BG3: العمر بالسنين | BN3: الرقم | BO3: الجنسية والجنس | BS3: المجموع | BT3: العمر بالسنين | CA3: الرقم | CB3: الجنسية والجنس | CF3: المجموع | CG3: العمر بالسنين | CN3: الرقم | CO3: الجنسية والجنس | CS3: المجموع | CT3: العمر بالسنين | DA3: الرقم | DB3: الجنسية والجنس | DF3: المجموع | DG3: العمر بالسنين | DN3: الرقم | DO3: الجنسية والجنس | DS3: المجموع | DT3: العمر بالسنين | EA3: الرقم | EB3: الجنسية والجنس | EF3: المجموع | EG3: العمر بالسنين | EN3: الرقم | EO3: الجنسية والجنس | ES3: المجموع | ET3: العمر بالسنين | FA3: المرض | FB3: الرقم | FC3: الجنسية والجنس | FG3: المجموع | FH3: العمر بالسنين
A4: الكودي | B4: سعودي | D4: غير سعودي | G4: 1< | H4: 5<:1 | I4: 15<:5 | J4: 45<15 | K4: 60<:45 | L4: أكثر من60 | N4: الكودي | O4: سعودي | Q4: غير سعودي | T4: 1< | U4: 5<:1 | V4: 15<:5 | W4: 45<15 | X4: 60<:45 | Y4: أكثر من60 | AA4: الكودي | AB4: سعودي | AD4: غير سعودي | AG4: 1< | AH4: 5<:1 | AI4: 15<:5 | AJ4: 45<15 | AK4: 60<:45 | AL4: أكثر من60 | AN4: الكودي | AO4: سعودي | AQ4: غير سعودي | AT4: 1< | AU4: 5<:1 | AV4: 15<:5 | AW4: 45<15 | AX4: 60<:45 | AY4: أكثر من60 | BA4: الكودي | BB4: سعودي | BD4: غير سعودي | BG4: 1< | BH4: 5<:1 | BI4: 15<:5 | BJ4: 45<15 | BK4: 60<:45 | BL4: أكثر من60 | BN4: الكودي | BO4: سعودي | BQ4: غير سعودي | BT4: 1< | BU4: 5<:1 | BV4: 15<:5 | BW4: 45<15 | BX4: 60<:45 | BY4: أكثر من60 | CA4: الكودي | CB4: سعودي | CD4: غير سعودي | CG4: 1< | CH4: 5<:1 | CI4: 15<:5 | CJ4: 45<15 | CK4: 60<:45 | CL4: أكثر من60 | CN4: الكودي | CO4: سعودي | CQ4: غير سعودي | CT4: 1< | CU4: 5<:1 | CV4: 15<:5 | CW4: 45<15 | CX4: 60<:45 | CY4: أكثر من60 | DA4: الكودي | DB4: سعودي | DD4: غير سعودي | DG4: 1< | DH4: 5<:1 | DI4: 15<:5 | DJ4: 45<15 | DK4: 60<:45 | DL4: أكثر من60 | DN4: الكودي | DO4: سعودي | DQ4: غير سعودي | DT4: 1< | DU4: 5<:1 | DV4: 15<:5 | DW4: 45<15 | DX4: 60<:45 | DY4: أكثر من60 | EA4: الكودي | EB4: سعودي | ED4: غير سعودي | EG4: 1< | EH4: 5<:1 | EI4: 15<:5 | EJ4: 45<15 | EK4: 60<:45 | EL4: أكثر من60 | EN4: الكودي | EO4: سعودي | EQ4: غير سعودي | ET4: 1< | EU4: 5<:1 | EV4: 15<:5 | EW4: 45<15 | EX4: 60<:45 | EY4: أكثر من60 | FB4: الكودي | FC4: سعودي | FE4: غير سعودي | FH4: 1< | FI4: 5<:1 | FJ4: 15<:5 | FK4: 45<15 | FL4: 60<:45 | FM4: أكثر من60
B5: ذكر | C5: أنثى | D5: ذكر | E5: أنثى | O5: ذكر | P5: أنثى | Q5: ذكر | R5: أنثى | AB5: ذكر | AC5: أنثى | AD5: ذكر | AE5: أنثى | AO5: ذكر | AP5: أنثى | AQ5: ذكر | AR5: أنثى | BB5: ذكر | BC5: أنثى | BD5: ذكر | BE5: أنثى | BO5: ذكر | BP5: أنثى | BQ5: ذكر | BR5: أنثى | CB5: ذكر | CC5: أنثى | CD5: ذكر | CE5: أنثى | CO5: ذكر | CP5: أنثى | CQ5: ذكر | CR5: أنثى | DB5: ذكر | DC5: أنثى | DD5: ذكر | DE5: أنثى | DO5: ذكر | DP5: أنثى | DQ5: ذكر | DR5: أنثى | EB5: ذكر | EC5: أنثى | ED5: ذكر | EE5: أنثى | EO5: ذكر | EP5: أنثى | EQ5: ذكر | ER5: أنثى | FC5: ذكر | FD5: أنثى | FE5: ذكر | FF5: أنثى
A6: 11 | B6: 5 | C6: 4 | D6: 0 | E6: 0 | F6: =SUM(B6:E6) -> 9 | G6: 0 | H6: 0 | I6: 0 | J6: 9 | K6: 0 | L6: 0 | M6: =SUM(G6:L6) -> 9 | N6: 11 | O6: 7 | P6: 5 | Q6: 0 | R6: 0 | S6: 9 | T6: 0 | U6: 0 | V6: 0 | W6: 9 | X6: 0 | Y6: 0 | Z6: =SUM(T6:Y6) -> 9 | AA6: 11 | AB6: 0 | AC6: 0 | AD6: 0 | AE6: 0 | AF6: =SUM(AB6:AE6) -> 0 | AG6: 0 | AH6: 0 | AI6: 0 | AJ6: 0 | AK6: 0 | AL6: 0 | AM6: =SUM(AG6:AL6) -> 0 | AN6: 11 | AO6: 0 | AP6: 0 | AQ6: 0 | AR6: 0 | AS6: =SUM(AO6:AR6) -> 0 | AT6: 0 | AU6: 0 | AV6: 0 | AW6: 0 | AX6: 0 | AZ6: =SUM(AT6:AY6) -> 0 | BA6: 11 | BB6: 0 | BC6: 0 | BD6: 0 | BE6: 0 | BF6: =SUM(BB6:BE6) -> 0 | BG6: 0 | BH6: 0 | BI6: 0 | BJ6: 0 | BK6: 0 | BL6: 0 | BM6: =SUM(BG6:BL6) -> 0 | BN6: 11 | BO6: 73 | BP6: 66 | BQ6: 29 | BR6: 36 | BS6: 204 | BT6: 23 | BU6: 56 | BV6: 62 | BW6: 33 | BX6: 21 | BY6: 9 | BZ6: =SUM(BT6:BY6) -> 204 | CA6: 11 | CB6: 0 | CC6: 0 | CD6: 0 | CE6: 0 | CF6: =SUM(CB6:CE6) -> 0 | CG6: 0 | CH6: 0 | CI6: 0 | CJ6: 0 | CK6: 0 | CL6: 0 | CM6: =SUM(CG6:CL6) -> 0 | CN6: 11 | CO6: 5 | CP6: 4 | CQ6: 0 | CR6: 0 | CS6: 9 | CT6: 0 | CU6: 0 | CV6: 0 | CW6: 9 | CX6: 0 | CY6: 0 | CZ6: =SUM(CT6:CY6) -> 9 | DA6: 11 | DB6: 9 | DC6: 3 | DD6: 1 | DE6: 0 | DF6: =SUM(DB6:DE6) -> 13 | DG6: 0 | DH6: 0 | DI6: 4 | DJ6: 4 | DK6: 5 | DL6: 0 | DM6: =SUM(DG6:DL6) -> 13 | DN6: 11 | DO6: 5 | DP6: 4 | DQ6: 0 | DR6: 0 | DS6: 9 | DT6: 0 | DU6: 0 | DV6: 0 | DW6: 9 | DX6: 0 | DY6: 0 | DZ6: =SUM(DT6:DY6) -> 9 | EA6: 11 | EB6: 0 | EC6: 0 | ED6: 0 | EE6: 0 | EF6: =SUM(EB6:EE6) -> 0 | EG6: 0 | EH6: 0 | EI6: 0 | EJ6: 0 | EK6: 0 | EL6: 0 | EM6: =SUM(EG6:EL6) -> 0 | EN6: 11 | EO6: 0 | EP6: 0 | EQ6: 0 | ER6: 0 | ES6: =SUM(EO6:ER6) -> 0 | ET6: 0 | EU6: 0 | EV6: 0 | EW6: 0 | EX6: 0 | EY6: 0 | EZ6: =SUM(ET6:EY6) -> 0 | FA6: الأمراض الطفيلية والمعدية | FB6: 11 | FC6: =B6+O6+AB6+AO6+BB6+BO6+CB6+CO6+DB6+DO6+EB6+EO6 -> 104 | FD6: =C6+P6+AC6+AP6+BC6+BP6+CC6+CP6+DC6+DP6+EC6+EP6 -> 86 | FE6: =D6+Q6+AD6+AQ6+BD6+BQ6+CD6+CQ6+DD6+DQ6+ED6+EQ6 -> 30 | FF6: =E6+R6+AE6+AR6+BE6+BR6+CE6+CR6+DE6+DR6+EE6+ER6 -> 36 | FG6: =SUM(FC6:FF6) -> 256 | FH6: =G6+T6+AG6+AT6+BG6+BT6+CG6+CT6+DG6+DT6+EG6+ET6 -> 23 | FI6: =H6+U6+AH6+AU6+BH6+BU6+CH6+CU6+DH6+DU6+EH6+EU6 -> 56 | FJ6: =I6+V6+AI6+AV6+BI6+BV6+CI6+CV6+DI6+DV6+EI6+EV6 -> 66 | FK6: =J6+W6+AJ6+AW6+BJ6+BW6+CJ6+CW6+DJ6+DW6+EJ6+EW6 -> 73 | FL6: =K6+X6+AK6+AX6+BK6+BX6+CK6+CX6+DK6+DX6+EK6+EX6 -> 26 | FM6: =L6+Y6+AL6+AY6+BL6+BY6+CL6+CY6+DL6+DY6+EL6+EY6 -> 9 | FN6: =SUM(FH6:FM6) -> 253
A7: 12 | B7: 9 | C7: 8 | D7: 0 | E7: 0 | F7: =SUM(B7:E7) -> 17 | G7: 0 | H7: 0 | I7: 0 | J7: 17 | K7: 0 | L7: 0 | M7: =SUM(G7:L7) -> 17 | N7: 12 | O7: 10 | P7: 7 | Q7: 0 | R7: 0 | S7: 17 | T7: 0 | U7: 0 | V7: 0 | W7: 17 | X7: 0 | Y7: 0 | Z7: =SUM(T7:Y7) -> 17 | AA7: 12 | AB7: 0 | AC7: 0 | AD7: 0 | AE7: 0 | AF7: =SUM(AB7:AE7) -> 0 | AG7: 0 | AH7: 0 | AI7: 0 | AJ7: 0 | AK7: 0 | AL7: 0 | AM7: =SUM(AG7:AL7) -> 0 | AN7: 12 | AO7: 0 | AP7: 1 | AQ7: 0 | AR7: 0 | AS7: =SUM(AO7:AR7) -> 1 | AT7: 0 | AU7: 0 | AV7: 1 | AW7: 0 | AX7: 0 | AY7: 0 | AZ7: =SUM(AT7:AY7) -> 1 | BA7: 12 | BB7: 5 | BC7: 11 | BD7: 2 | BE7: 2 | BF7: =SUM(BB7:BE7) -> 20 | BG7: 0 | BH7: 0 | BI7: 10 | BJ7: 10 | BK7: 0 | BL7: 0 | BM7: =SUM(BG7:BL7) -> 20 | BN7: 12 | BO7: 142 | BP7: 198 | BQ7: 24 | BR7: 44 | BS7: 408 | BT7: 32 | BU7: 64 | BV7: 54 | BW7: 87 | BX7: 107 | BY7: 64 | BZ7: =SUM(BT7:BY7) -> 408 | CA7: 12 | CB7: 0 | CC7: 1 | CD7: 0 | CE7: 0 | CF7: =SUM(CB7:CE7) -> 1 | CG7: 0 | CH7: 0 | CI7: 1 | CJ7: 0 | CK7: 0 | CL7: 0 | CM7: =SUM(CG7:CL7) -> 1 | CN7: 12 | CO7: 9 | CP7: 8 | CQ7: 0 | CR7: 0 | CS7: 17 | CT7: 0 | CU7: 0 | CV7: 0 | CW7: 17 | CX7: 0 | CY7: 0 | CZ7: =SUM(CT7:CY7) -> 17 | DA7: 12 | DB7: 10 | DC7: 4 | DD7: 0 | DE7: 0 | DF7: =SUM(DB7:DE7) -> 14 | DG7: 0 | DH7: 0 | DI7: 0 | DJ7: 4 | DK7: 10 | DL7: 0 | DM7: =SUM(DG7:DL7) -> 14 | DN7: 12 | DO7: 9 | DP7: 8 | DQ7: 0 | DR7: 0 | DS7: 17 | DT7: 0 | DU7: 0 | DV7: 0 | DW7: 17 | DX7: 0 | DY7: 0 | DZ7: =SUM(DT7:DY7) -> 17 | EA7: 12 | EB7: 0 | EC7: 0 | ED7: 0 | EE7: 0 | EF7: =SUM(EB7:EE7) -> 0 | EG7: 0 | EH7: 0 | EI7: 0 | EJ7: 0 | EK7: 0 | EL7: 0 | EM7: =SUM(EG7:EL7) -> 0 | EN7: 12 | EO7: 0 | EP7: 0 | EQ7: 0 | ER7: 0 | ES7: =SUM(EO7:ER7) -> 0 | ET7: 0 | EU7: 0 | EV7: 0 | EW7: 0 | EX7: 0 | EY7: 0 | EZ7: =SUM(ET7:EY7) -> 0 | FA7: الديدان المعوية | FB7: 12 | FC7: =B7+O7+AB7+AO7+BB7+BO7+CB7+CO7+DB7+DO7+EB7+EO7 -> 194 | FD7: =C7+P7+AC7+AP7+BC7+BP7+CC7+CP7+DC7+DP7+EC7+EP7 -> 246 | FE7: =D7+Q7+AD7+AQ7+BD7+BQ7+CD7+CQ7+DD7+DQ7+ED7+EQ7 -> 26 | FF7: =E7+R7+AE7+AR7+BE7+BR7+CE7+CR7+DE7+DR7+EE7+ER7 -> 46 | FG7: =SUM(FC7:FF7) -> 512 | FH7: =G7+T7+AG7+AT7+BG7+BT7+CG7+CT7+DG7+DT7+EG7+ET7 -> 32 | FI7: =H7+U7+AH7+AU7+BH7+BU7+CH7+CU7+DH7+DU7+EH7+EU7 -> 64 | FJ7: =I7+V7+AI7+AV7+BI7+BV7+CI7+CV7+DI7+DV7+EI7+EV7 -> 66 | FK7: =J7+W7+AJ7+AW7+BJ7+BW7+CJ7+CW7+DJ7+DW7+EJ7+EW7 -> 169 | FL7: =K7+X7+AK7+AX7+BK7+BX7+CK7+CX7+DK7+DX7+EK7+EX7 -> 117 | FM7: =L7+Y7+AL7+AY7+BL7+BY7+CL7+CY7+DL7+DY7+EL7+EY7 -> 64 | FN7: =SUM(FH7:FM7) -> 512
A8: 13 | B8: 0 | C8: 0 | D8: 0 | E8: 0 | F8: =SUM(B8:E8) -> 0 | G8: 0 | H8: 0 | I8: 0 | J8: 0 | K8: 0 | L8: 0 | M8: =SUM(G8:L8) -> 0 | N8: 13 | O8: 0 | P8: 0 | Q8: 0 | R8: 0 | S8: 0 | T8: 0 | U8: 0 | V8: 0 | W8: 0 | X8: 0 | Y8: 0 | Z8: =SUM(T8:Y8) -> 0 | AA8: 13 | AB8: 0 | AC8: 0 | AD8: 0 | AE8: 0 | AF8: =SUM(AB8:AE8) -> 0 | AG8: 0 | AH8: 0 | AI8: 0 | AJ8: 0 | AK8: 0 | AL8: 0 | AM8: =SUM(AG8:AL8) -> 0 | AN8: 13 | AO8: 205 | AP8: 136 | AQ8: 72 | AR8: 14 | AS8: =SUM(AO8:AR8) -> 427 | AT8: 0 | AU8: 1 | AV8: 12 | AW8: 88 | AX8: 132 | AY8: 194 | AZ8: =SUM(AT8:AY8) -> 427 | BA8: 13 | BB8: 122 | BC8: 230 | BD8: 52 | BE8: 11 | BF8: =SUM(BB8:BE8) -> 415 | BG8: 0 | BH8: 5 | BI8: 20 | BJ8: 220 | BK8: 100 | BL8: 70 | BM8: =SUM(BG8:BL8) -> 415 | BN8: 13 | BO8: 157 | BP8: 153 | BQ8: 7 | BR8: 11 | BS8: 328 | BT8: 0 | BU8: 0 | BV8: 0 | BW8: 93 | BX8: 146 | BY8: 89 | BZ8: =SUM(BT8:BY8) -> 328 | CA8: 13 | CB8: 205 | CC8: 136 | CD8: 72 | CE8: 14 | CF8: =SUM(CB8:CE8) -> 427 | CG8: 0 | CH8: 1 | CI8: 12 | CJ8: 88 | CK8: 132 | CL8: 194 | CM8: =SUM(CG8:CL8) -> 427 | CN8: 13 | CO8: 0 | CP8: 0 | CQ8: 0 | CR8: 0 | CS8: 0 | CT8: 0 | CU8: 0 | CV8: 0 | CW8: 0 | CX8: 0 | CY8: 0 | CZ8: =SUM(CT8:CY8) -> 0 | DA8: 13 | DB8: 130 | DC8: 110 | DD8: 98 | DE8: 60 | DF8: =SUM(DB8:DE8) -> 398 | DG8: 0 | DH8: 0 | DI8: 2 | DJ8: 105 | DK8: 235 | DL8: 56 | DM8: =SUM(DG8:DL8) -> 398 | DN8: 13 | DO8: 0 | DP8: 0 | DQ8: 0 | DR8: 0 | DS8: 0 | DT8: 0 | DU8: 0 | DV8: 0 | DW8: 0 | DX8: 0 | DY8: 0 | DZ8: =SUM(DT8:DY8) -> 0 | EA8: 13 | EB8: 0 | EC8: 0 | ED8: 0 | EE8: 0 | EF8: =SUM(EB8:EE8) -> 0 | EG8: 0 | EH8: 0 | EI8: 0 | EJ8: 0 | EK8: 0 | EL8: 0 | EM8: =SUM(EG8:EL8) -> 0 | EN8: 13 | EO8: 0 | EP8: 0 | EQ8: 0 | ER8: 0 | ES8: =SUM(EO8:ER8) -> 0 | ET8: 0 | EU8: 0 | EV8: 0 | EW8: 0 | EX8: 0 | EY8: 0 | EZ8: =SUM(ET8:EY8) -> 0 | FA8: مرض السكري | FB8: 13 | FC8: =B8+O8+AB8+AO8+BB8+BO8+CB8+CO8+DB8+DO8+EB8+EO8 -> 819 | FD8: =C8+P8+AC8+AP8+BC8+BP8+CC8+CP8+DC8+DP8+EC8+EP8 -> 765 | FE8: =D8+Q8+AD8+AQ8+BD8+BQ8+CD8+CQ8+DD8+DQ8+ED8+EQ8 -> 301 | FF8: =E8+R8+AE8+AR8+BE8+BR8+CE8+CR8+DE8+DR8+EE8+ER8 -> 110 | FG8: =SUM(FC8:FF8) -> 1995 | FH8: =G8+T8+AG8+AT8+BG8+BT8+CG8+CT8+DG8+DT8+EG8+ET8 -> 0 | FI8: =H8+U8+AH8+AU8+BH8+BU8+CH8+CU8+DH8+DU8+EH8+EU8 -> 7 | FJ8: =I8+V8+AI8+AV8+BI8+BV8+CI8+CV8+DI8+DV8+EI8+EV8 -> 46 | FK8: =J8+W8+AJ8+AW8+BJ8+BW8+CJ8+CW8+DJ8+DW8+EJ8+EW8 -> 594 | FL8: =K8+X8+AK8+AX8+BK8+BX8+CK8+CX8+DK8+DX8+EK8+EX8 -> 745 | FM8: =L8+Y8+AL8+AY8+BL8+BY8+CL8+CY8+DL8+DY8+EL8+EY8 -> 603 | FN8: =SUM(FH8:FM8) -> 1995
A9: 14 | B9: 0 | C9: 0 | D9: 0 | E9: 0 | F9: =SUM(B9:E9) -> 0 | G9: 0 | H9: 0 | I9: 0 | J9: 0 | K9: 0 | L9: 0 | M9: =SUM(G9:L9) -> 0 | N9: 14 | O9: 0 | P9: 0 | Q9: 0 | R9: 0 | S9: 0 | T9: 0 | U9: 0 | V9: 0 | W9: 0 | X9: 0 | Y9: 0 | Z9: =SUM(T9:Y9) -> 0 | AA9: 14 | AB9: 0 | AC9: 0 | AD9: 0 | AE9: 0 | AF9: =SUM(AB9:AE9) -> 0 | AG9: 0 | AH9: 0 | AI9: 0 | AJ9: 0 | AK9: 0 | AL9: 0 | AM9: =SUM(AG9:AL9) -> 0 | AN9: 14 | AO9: 1 | AP9: 30 | AQ9: 0 | AR9: 2 | AS9: =SUM(AO9:AR9) -> 33 | AT9: 0 | AU9: 0 | AV9: 2 | AW9: 29 | AX9: 2 | AY9: 0 | AZ9: =SUM(AT9:AY9) -> 33 | BA9: 14 | BB9: 0 | BC9: 0 | BD9: 0 | BE9: 0 | BF9: =SUM(BB9:BE9) -> 0 | BG9: 0 | BH9: 0 | BI9: 0 | BJ9: 0 | BK9: 0 | BL9: 0 | BM9: =SUM(BG9:BL9) -> 0 | BN9: 14 | BO9: 139 | BP9: 168 | BQ9: 27 | BR9: 25 | BS9: 359 | BT9: 40 | BU9: 68 | BV9: 92 | BW9: 61 | BX9: 78 | BY9: 20 | BZ9: =SUM(BT9:BY9) -> 359 | CA9: 14 | CB9: 1 | CC9: 30 | CD9: 0 | CE9: 2 | CF9: =SUM(CB9:CE9) -> 33 | CG9: 0 | CH9: 0 | CI9: 2 | CJ9: 29 | CK9: 2 | CL9: 0 | CM9: =SUM(CG9:CL9) -> 33 | CN9: 14 | CO9: 0 | CP9: 0 | CQ9: 0 | CR9: 0 | CS9: 0 | CT9: 0 | CU9: 0 | CV9: 0 | CW9: 0 | CX9: 0 | CY9: 0 | CZ9: =SUM(CT9:CY9) -> 0 | DA9: 14 | DB9: 6 | DC9: 4 | DD9: 6 | DE9: 0 | DF9: =SUM(DB9:DE9) -> 16 | DG9: 0 | DH9: 0 | DI9: 0 | DJ9: 10 | DK9: 6 | DL9: 0 | DM9: =SUM(DG9:DL9) -> 16 | DN9: 14 | DO9: 0 | DP9: 0 | DQ9: 0 | DR9: 0 | DS9: 0 | DT9: 0 | DU9: 0 | DV9: 0 | DW9: 0 | DX9: 0 | DY9: 0 | DZ9: =SUM(DT9:DY9) -> 0 | EA9: 14 | EB9: 0 | EC9: 0 | ED9: 0 | EE9: 0 | EF9: =SUM(EB9:EE9) -> 0 | EG9: 0 | EH9: 0 | EI9: 0 | EJ9: 0 | EK9: 0 | EL9: 0 | EM9: =SUM(EG9:EL9) -> 0 | EN9: 14 | EO9: 0 | EP9: 0 | EQ9: 0 | ER9: 0 | ES9: =SUM(EO9:ER9) -> 0 | ET9: 0 | EU9: 0 | EV9: 0 | EW9: 0 | EX9: 0 | EY9: 0 | EZ9: =SUM(ET9:EY9) -> 0 | FA9: أمراض الدم والجهاز المناعي | FB9: 14 | FC9: =B9+O9+AB9+AO9+BB9+BO9+CB9+CO9+DB9+DO9+EB9+EO9 -> 147 | FD9: =C9+P9+AC9+AP9+BC9+BP9+CC9+CP9+DC9+DP9+EC9+EP9 -> 232 | FE9: =D9+Q9+AD9+AQ9+BD9+BQ9+CD9+CQ9+DD9+DQ9+ED9+EQ9 -> 33 | FF9: =E9+R9+AE9+AR9+BE9+BR9+CE9+CR9+DE9+DR9+EE9+ER9 -> 29 | FG9: =SUM(FC9:FF9) -> 441 | FH9: =G9+T9+AG9+AT9+BG9+BT9+CG9+CT9+DG9+DT9+EG9+ET9 -> 40 | FI9: =H9+U9+AH9+AU9+BH9+BU9+CH9+CU9+DH9+DU9+EH9+EU9 -> 68 | FJ9: =I9+V9+AI9+AV9+BI9+BV9+CI9+CV9+DI9+DV9+EI9+EV9 -> 96 | FK9: =J9+W9+AJ9+AW9+BJ9+BW9+CJ9+CW9+DJ9+DW9+EJ9+EW9 -> 129 | FL9: =K9+X9+AK9+AX9+BK9+BX9+CK9+CX9+DK9+DX9+EK9+EX9 -> 88 | FM9: =L9+Y9+AL9+AY9+BL9+BY9+CL9+CY9+DL9+DY9+EL9+EY9 -> 20 | FN9: =SUM(FH9:FM9) -> 441
A10: 15 | B10: 0 | C10: 0 | D10: 0 | E10: 0 | F10: =SUM(B10:E10) -> 0 | G10: 0 | H10: 0 | I10: 0 | J10: 0 | K10: 0 | L10: 0 | M10: =SUM(G10:L10) -> 0 | N10: 15 | O10: 0 | P10: 0 | Q10: 0 | R10: 0 | S10: 0 | T10: 0 | U10: 0 | V10: 0 | W10: 0 | X10: 0 | Y10: 0 | Z10: =SUM(T10:Y10) -> 0 | AA10: 15 | AB10: 0 | AC10: 0 | AD10: 0 | AE10: 0 | AF10: =SUM(AB10:AE10) -> 0 | AG10: 0 | AH10: 0 | AI10: 0 | AJ10: 0 | AK10: 0 | AL10: 0 | AM10: =SUM(AG10:AL10) -> 0 | AN10: 15 | AO10: 223 | AP10: 115 | AQ10: 53 | AR10: 21 | AS10: =SUM(AO10:AR10) -> 412 | AT10: 0 | AU10: 0 | AV10: 0 | AW10: 102 | AX10: 191 | AY10: 119 | AZ10: =SUM(AT10:AY10) -> 412 | BA10: 15 | BB10: 201 | BC10: 74 | BD10: 30 | BE10: 25 | BF10: =SUM(BB10:BE10) -> 330 | BG10: 0 | BH10: 0 | BI10: 16 | BJ10: 130 | BK10: 104 | BL10: 80 | BM10: =SUM(BG10:BL10) -> 330 | BN10: 15 | BO10: 138 | BP10: 139 | BQ10: 9 | BR10: 13 | BS10: 299 | BV10: 0 | BW10: 82 | BX10: 134 | BY10: 83 | BZ10: =SUM(BT10:BY10) -> 299 | CA10: 15 | CB10: 223 | CC10: 115 | CD10: 53 | CE10: 21 | CF10: =SUM(CB10:CE10) -> 412 | CG10: 0 | CH10: 0 | CI10: 0 | CJ10: 102 | CK10: 191 | CL10: 119 | CM10: =SUM(CG10:CL10) -> 412 | CN10: 15 | CO10: 0 | CP10: 0 | CQ10: 0 | CR10: 0 | CS10: 0 | CT10: 0 | CU10: 0 | CV10: 0 | CW10: 0 | CX10: 0 | CY10: 0 | CZ10: =SUM(CT10:CY10) -> 0 | DA10: 15 | DB10: 120 | DC10: 125 | DD10: 50 | DE10: 0 | DF10: =SUM(DB10:DE10) -> 295 | DG10: 0 | DH10: 0 | DI10: 0 | DJ10: 97 | DK10: 198 | DL10: 0 | DM10: =SUM(DG10:DL10) -> 295 | DN10: 15 | DO10: 0 | DP10: 0 | DQ10: 0 | DR10: 0 | DS10: 0 | DT10: 0 | DU10: 0 | DV10: 0 | DW10: 0 | DX10: 0 | DY10: 0 | DZ10: =SUM(DT10:DY10) -> 0 | EA10: 15 | EB10: 0 | EC10: 0 | ED10: 0 | EE10: 0 | EF10: =SUM(EB10:EE10) -> 0 | EG10: 0 | EH10: 0 | EI10: 0 | EJ10: 0 | EK10: 0 | EL10: 0 | EM10: =SUM(EG10:EL10) -> 0 | EN10: 15 | EO10: 0 | EP10: 0 | EQ10: 0 | ER10: 0 | ES10: =SUM(EO10:ER10) -> 0 | ET10: 0 | EU10: 0 | EV10: 0 | EW10: 0 | EX10: 0 | EY10: 0 | EZ10: =SUM(ET10:EY10) -> 0 | FA10: ضغط الدم المرتفع | FB10: 15 | FC10: =B10+O10+AB10+AO10+BB10+BO10+CB10+CO10+DB10+DO10+EB10+EO10 -> 905 | FD10: =C10+P10+AC10+AP10+BC10+BP10+CC10+CP10+DC10+DP10+EC10+EP10 -> 568 | FE10: =D10+Q10+AD10+AQ10+BD10+BQ10+CD10+CQ10+DD10+DQ10+ED10+EQ10 -> 195 | FF10: =E10+R10+AE10+AR10+BE10+BR10+CE10+CR10+DE10+DR10+EE10+ER10 -> 80 | FG10: =SUM(FC10:FF10) -> 1748 | FH10: =G10+T10+AG10+AT10+BG10+BT10+CG10+CT10+DG10+DT10+EG10+ET10 -> 0 | FI10: =H10+U10+AH10+AU10+BH10+BU10+CH10+CU10+DH10+DU10+EH10+EU10 -> 0 | FJ10: =I10+V10+AI10+AV10+BI10+BV10+CI10+CV10+DI10+DV10+EI10+EV10 -> 16 | FK10: =J10+W10+AJ10+AW10+BJ10+BW10+CJ10+CW10+DJ10+DW10+EJ10+EW10 -> 513 | FL10: =K10+X10+AK10+AX10+BK10+BX10+CK10+CX10+DK10+DX10+EK10+EX10 -> 818 | FM10: =L10+Y10+AL10+AY10+BL10+BY10+CL10+CY10+DL10+DY10+EL10+EY10 -> 401 | FN10: =SUM(FH10:FM10) -> 1748
A11: 16 | B11: 0 | C11: 0 | D11: 0 | E11: 0 | F11: =SUM(B11:E11) -> 0 | G11: 0 | H11: 0 | I11: 0 | J11: 0 | K11: 0 | L11: 0 | M11: =SUM(G11:L11) -> 0 | N11: 16 | O11: 0 | P11: 0 | Q11: 0 | R11: 0 | S11: 0 | T11: 0 | U11: 0 | V11: 0 | W11: 0 | X11: 0 | Y11: 0 | Z11: =SUM(T11:Y11) -> 0 | AA11: 16 | AB11: 0 | AC11: 0 | AD11: 0 | AE11: 0 | AF11: =SUM(AB11:AE11) -> 0 | AG11: 0 | AH11: 0 | AI11: 0 | AJ11: 0 | AK11: 0 | AL11: 0 | AM11: =SUM(AG11:AL11) -> 0 | AN11: 16 | AO11: 11 | AP11: 16 | AQ11: 0 | AR11: 1 | AS11: =SUM(AO11:AR11) -> 28 | AT11: 0 | AU11: 0 | AV11: 0 | AW11: 13 | AX11: 15 | AY11: 0 | AZ11: =SUM(AT11:AY11) -> 28 | BA11: 16 | BB11: 80 | BC11: 70 | BD11: 10 | BE11: 5 | BF11: =SUM(BB11:BE11) -> 165 | BG11: 0 | BH11: 0 | BI11: 50 | BJ11: 50 | BK11: 60 | BL11: 5 | BM11: =SUM(BG11:BL11) -> 165 | BN11: 16 | BO11: 123 | BP11: 174 | BQ11: 10 | BR11: 17 | BS11: 324 | BT11: 8 | BU11: 16 | BV11: 13 | BW11: 98 | BX11: 84 | BY11: 105 | BZ11: =SUM(BT11:BY11) -> 324 | CA11: 16 | CB11: 11 | CC11: 16 | CD11: 0 | CE11: 1 | CF11: =SUM(CB11:CE11) -> 28 | CG11: 0 | CH11: 0 | CI11: 0 | CJ11: 13 | CK11: 15 | CL11: 0 | CM11: =SUM(CG11:CL11) -> 28 | CN11: 16 | CO11: 0 | CP11: 0 | CQ11: 0 | CR11: 0 | CS11: 0 | CT11: 0 | CU11: 0 | CV11: 0 | CW11: 0 | CX11: 0 | CY11: 0 | CZ11: =SUM(CT11:CY11) -> 0 | DA11: 16 | DB11: 31 | DC11: 29 | DD11: 1 | DE11: 0 | DF11: =SUM(DB11:DE11) -> 61 | DG11: 0 | DH11: 0 | DI11: 0 | DJ11: 1 | DK11: 60 | DL11: 0 | DM11: =SUM(DG11:DL11) -> 61 | DN11: 16 | DO11: 0 | DP11: 0 | DQ11: 0 | DR11: 0 | DS11: 0 | DT11: 0 | DU11: 0 | DV11: 0 | DW11: 0 | DX11: 0 | DY11: 0 | DZ11: =SUM(DT11:DY11) -> 0 | EA11: 16 | EB11: 0 | EC11: 0 | ED11: 0 | EE11: 0 | EF11: =SUM(EB11:EE11) -> 0 | EG11: 0 | EH11: 0 | EI11: 0 | EJ11: 0 | EK11: 0 | EL11: 0 | EM11: =SUM(EG11:EL11) -> 0 | EN11: 16 | EO11: 0 | EP11: 0 | EQ11: 0 | ER11: 0 | ES11: =SUM(EO11:ER11) -> 0 | ET11: 0 | EU11: 0 | EV11: 0 | EW11: 0 | EX11: 0 | EY11: 0 | EZ11: =SUM(ET11:EY11) -> 0 | FA11: أمراض القلب والأوعية الدموية | FB11: 16 | FC11: =B11+O11+AB11+AO11+BB11+BO11+CB11+CO11+DB11+DO11+EB11+EO11 -> 256 | FD11: =C11+P11+AC11+AP11+BC11+BP11+CC11+CP11+DC11+DP11+EC11+EP11 -> 305 | FE11: =D11+Q11+AD11+AQ11+BD11+BQ11+CD11+CQ11+DD11+DQ11+ED11+EQ11 -> 21 | FF11: =E11+R11+AE11+AR11+BE11+BR11+CE11+CR11+DE11+DR11+EE11+ER11 -> 24 | FG11: =SUM(FC11:FF11) -> 606 | FH11: =G11+T11+AG11+AT11+BG11+BT11+CG11+CT11+DG11+DT11+EG11+ET11 -> 8 | FI11: =H11+U11+AH11+AU11+BH11+BU11+CH11+CU11+DH11+DU11+EH11+EU11 -> 16 | FJ11: =I11+V11+AI11+AV11+BI11+BV11+CI11+CV11+DI11+DV11+EI11+EV11 -> 63 | FK11: =J11+W11+AJ11+AW11+BJ11+BW11+CJ11+CW11+DJ11+DW11+EJ11+EW11 -> 175 | FL11: =K11+X11+AK11+AX11+BK11+BX11+CK11+CX11+DK11+DX11+EK11+EX11 -> 234 | FM11: =L11+Y11+AL11+AY11+BL11+BY11+CL11+CY11+DL11+DY11+EL11+EY11 -> 110 | FN11: =SUM(FH11:FM11) -> 606
A12: 17 | B12: 0 | C12: 0 | D12: 0 | E12: 0 | F12: =SUM(B12:E12) -> 0 | G12: 0 | H12: 0 | I12: 0 | J12: 0 | K12: 0 | L12: 0 | M12: =SUM(G12:L12) -> 0 | N12: 17 | O12: 0 | P12: 0 | Q12: 0 | R12: 0 | S12: 0 | T12: 0 | U12: 0 | V12: 0 | W12: 0 | X12: 0 | Y12: 0 | Z12: =SUM(T12:Y12) -> 0 | AA12: 17 | AB12: 0 | AC12: 0 | AD12: 0 | AE12: 0 | AF12: =SUM(AB12:AE12) -> 0 | AG12: 0 | AH12: 0 | AI12: 0 | AJ12: 0 | AK12: 0 | AL12: 0 | AM12: =SUM(AG12:AL12) -> 0 | AN12: 17 | AO12: 28 | AP12: 22 | AQ12: 2 | AR12: 4 | AS12: =SUM(AO12:AR12) -> 56 | AT12: 0 | AU12: 1 | AV12: 3 | AW12: 46 | AX12: 1 | AY12: 5 | AZ12: =SUM(AT12:AY12) -> 56 | BA12: 17 | BB12: 36 | BC12: 50 | BD12: 20 | BE12: 30 | BF12: =SUM(BB12:BE12) -> 136 | BG12: 0 | BH12: 0 | BI12: 39 | BJ12: 47 | BK12: 50 | BL12: 0 | BM12: =SUM(BG12:BL12) -> 136 | BN12: 17 | BO12: 123 | BP12: 136 | BQ12: 32 | BR12: 35 | BS12: 326 | BT12: 36 | BU12: 49 | BV12: 52 | BW12: 69 | BX12: 67 | BY12: 53 | BZ12: =SUM(BT12:BY12) -> 326 | CA12: 17 | CB12: 28 | CC12: 22 | CD12: 2 | CE12: 4 | CF12: =SUM(CB12:CE12) -> 56 | CG12: 0 | CH12: 1 | CI12: 3 | CJ12: 46 | CK12: 1 | CL12: 5 | CM12: =SUM(CG12:CL12) -> 56 | CN12: 17 | CO12: 0 | CP12: 0 | CQ12: 0 | CR12: 0 | CS12: 0 | CT12: 0 | CU12: 0 | CV12: 0 | CW12: 0 | CX12: 0 | CY12: 0 | CZ12: =SUM(CT12:CY12) -> 0 | DA12: 17 | DB12: 45 | DC12: 29 | DD12: 0 | DE12: 0 | DF12: =SUM(DB12:DE12) -> 74 | DG12: 0 | DH12: 5 | DI12: 5 | DJ12: 40 | DK12: 24 | DL12: 0 | DM12: =SUM(DG12:DL12) -> 74 | DN12: 17 | DO12: 0 | DP12: 0 | DQ12: 0 | DR12: 0 | DS12: 0 | DT12: 0 | DU12: 0 | DV12: 0 | DW12: 0 | DX12: 0 | DY12: 0 | DZ12: =SUM(DT12:DY12) -> 0 | EA12: 17 | EB12: 0 | EC12: 0 | ED12: 0 | EE12: 0 | EF12: =SUM(EB12:EE12) -> 0 | EG12: 0 | EH12: 0 | EI12: 0 | EJ12: 0 | EK12: 0 | EL12: 0 | EM12: =SUM(EG12:EL12) -> 0 | EN12: 17 | EO12: 0 | EP12: 0 | EQ12: 0 | ER12: 0 | ES12: =SUM(EO12:ER12) -> 0 | ET12: 0 | EU12: 0 | EV12: 0 | EW12: 0 | EX12: 0 | EY12: 0 | EZ12: =SUM(ET12:EY12) -> 0 | FA12: أمراض العين | FB12: 17 | FC12: =B12+O12+AB12+AO12+BB12+BO12+CB12+CO12+DB12+DO12+EB12+EO12 -> 260 | FD12: =C12+P12+AC12+AP12+BC12+BP12+CC12+CP12+DC12+DP12+EC12+EP12 -> 259 | FE12: =D12+Q12+AD12+AQ12+BD12+BQ12+CD12+CQ12+DD12+DQ12+ED12+EQ12 -> 56 | FF12: =E12+R12+AE12+AR12+BE12+BR12+CE12+CR12+DE12+DR12+EE12+ER12 -> 73 | FG12: =SUM(FC12:FF12) -> 648 | FH12: =G12+T12+AG12+AT12+BG12+BT12+CG12+CT12+DG12+DT12+EG12+ET12 -> 36 | FI12: =H12+U12+AH12+AU12+BH12+BU12+CH12+CU12+DH12+DU12+EH12+EU12 -> 56 | FJ12: =I12+V12+AI12+AV12+BI12+BV12+CI12+CV12+DI12+DV12+EI12+EV12 -> 102 | FK12: =J12+W12+AJ12+AW12+BJ12+BW12+CJ12+CW12+DJ12+DW12+EJ12+EW12 -> 248 | FL12: =K12+X12+AK12+AX12+BK12+BX12+CK12+CX12+DK12+DX12+EK12+EX12 -> 143 | FM12: =L12+Y12+AL12+AY12+BL12+BY12+CL12+CY12+DL12+DY12+EL12+EY12 -> 63 | FN12: =SUM(FH12:FM12) -> 648
A13: 18 | B13: 85 | C13: 87 | D13: 0 | E13: 0 | F13: =SUM(B13:E13) -> 172 | G13: 0 | H13: 2 | I13: 10 | J13: 160 | K13: 0 | L13: 0 | M13: =SUM(G13:L13) -> 172 | N13: 18 | O13: 91 | P13: 85 | Q13: 0 | R13: 0 | S13: 172 | T13: 0 | U13: 2 | V13: 10 | W13: 160 | X13: 0 | Y13: 0 | Z13: =SUM(T13:Y13) -> 172 | AA13: 18 | AB13: 0 | AC13: 0 | AD13: 0 | AE13: 0 | AF13: =SUM(AB13:AE13) -> 0 | AG13: 0 | AH13: 0 | AI13: 0 | AJ13: 0 | AK13: 0 | AL13: 0 | AM13: =SUM(AG13:AL13) -> 0 | AN13: 18 | AO13: 16 | AP13: 43 | AQ13: 5 | AR13: 2 | AS13: =SUM(AO13:AR13) -> 66 | AT13: 0 | AU13: 6 | AV13: 13 | AW13: 44 | AX13: 3 | AY13: 0 | AZ13: =SUM(AT13:AY13) -> 66 | BA13: 18 | BB13: 33 | BC13: 54 | BD13: 11 | BE13: 20 | BF13: =SUM(BB13:BE13) -> 118 | BG13: 0 | BH13: 0 | BI13: 56 | BJ13: 33 | BK13: 21 | BL13: 8 | BM13: =SUM(BG13:BL13) -> 118 | BN13: 18 | BO13: 167 | BP13: 170 | BQ13: 41 | BR13: 38 | BS13: 416 | BT13: 58 | BU13: 78 | BV13: 72 | BW13: 90 | BX13: 79 | BY13: 39 | BZ13: =SUM(BT13:BY13) -> 416 | CA13: 18 | CB13: 16 | CC13: 43 | CD13: 5 | CE13: 2 | CF13: =SUM(CB13:CE13) -> 66 | CG13: 0 | CH13: 6 | CI13: 13 | CJ13: 44 | CK13: 3 | CL13: 0 | CM13: =SUM(CG13:CL13) -> 66 | CN13: 18 | CO13: 80 | CP13: 87 | CQ13: 0 | CR13: 0 | CS13: 172 | CT13: 0 | CU13: 2 | CV13: 10 | CW13: 160 | CX13: 0 | CY13: 0 | CZ13: =SUM(CT13:CY13) -> 172 | DA13: 18 | DB13: 29 | DC13: 29 | DD13: 0 | DE13: 0 | DF13: =SUM(DB13:DE13) -> 58 | DG13: 0 | DH13: 0 | DI13: 10 | DJ13: 20 | DK13: 28 | DL13: 0 | DM13: =SUM(DG13:DL13) -> 58 | DN13: 18 | DO13: 85 | DP13: 87 | DQ13: 0 | DR13: 0 | DS13: 172 | DT13: 0 | DU13: 2 | DV13: 10 | DW13: 160 | DX13: 0 | DY13: 0 | DZ13: =SUM(DT13:DY13) -> 172 | EA13: 18 | EB13: 0 | EC13: 0 | ED13: 0 | EE13: 0 | EF13: =SUM(EB13:EE13) -> 0 | EG13: 0 | EH13: 0 | EI13: 0 | EJ13: 0 | EK13: 0 | EL13: 0 | EM13: =SUM(EG13:EL13) -> 0 | EN13: 18 | EO13: 0 | EP13: 0 | EQ13: 0 | ER13: 0 | ES13: =SUM(EO13:ER13) -> 0 | ET13: 0 | EU13: 0 | EV13: 0 | EW13: 0 | EX13: 0 | EY13: 0 | EZ13: =SUM(ET13:EY13) -> 0 | FA13: أمراض الأذن والماستويد | FB13: 18 | FC13: =B13+O13+AB13+AO13+BB13+BO13+CB13+CO13+DB13+DO13+EB13+EO13 -> 602 | FD13: =C13+P13+AC13+AP13+BC13+BP13+CC13+CP13+DC13+DP13+EC13+EP13 -> 685 | FE13: =D13+Q13+AD13+AQ13+BD13+BQ13+CD13+CQ13+DD13+DQ13+ED13+EQ13 -> 62 | FF13: =E13+R13+AE13+AR13+BE13+BR13+CE13+CR13+DE13+DR13+EE13+ER13 -> 62 | FG13: =SUM(FC13:FF13) -> 1411 | FH13: =G13+T13+AG13+AT13+BG13+BT13+CG13+CT13+DG13+DT13+EG13+ET13 -> 58 | FI13: =H13+U13+AH13+AU13+BH13+BU13+CH13+CU13+DH13+DU13+EH13+EU13 -> 98 | FJ13: =I13+V13+AI13+AV13+BI13+BV13+CI13+CV13+DI13+DV13+EI13+EV13 -> 204 | FK13: =J13+W13+AJ13+AW13+BJ13+BW13+CJ13+CW13+DJ13+DW13+EJ13+EW13 -> 871 | FL13: =K13+X13+AK13+AX13+BK13+BX13+CK13+CX13+DK13+DX13+EK13+EX13 -> 134 | FM13: =L13+Y13+AL13+AY13+BL13+BY13+CL13+CY13+DL13+DY13+EL13+EY13 -> 47 | FN13: =SUM(FH13:FM13) -> 1412
A14: 19 | B14: 70 | C14: 79 | D14: 0 | E14: 0 | F14: =SUM(B14:E14) -> 149 | G14: 0 | H14: 7 | I14: 11 | J14: 120 | K14: 11 | L14: 0 | M14: =SUM(G14:L14) -> 149 | N14: 19 | O14: 80 | P14: 71 | Q14: 0 | R14: 0 | S14: 149 | T14: 0 | U14: 7 | V14: 11 | W14: 120 | X14: 11 | Y14: 0 | Z14: =SUM(T14:Y14) -> 149 | AA14: 19 | AB14: 0 | AC14: 0 | AD14: 0 | AE14: 0 | AF14: =SUM(AB14:AE14) -> 0 | AG14: 0 | AH14: 0 | AI14: 0 | AJ14: 0 | AK14: 0 | AL14: 0 | AM14: =SUM(AG14:AL14) -> 0 | AN14: 19 | AO14: 656 | AP14: 748 | AQ14: 31 | AR14: 21 | AS14: =SUM(AO14:AR14) -> 1456 | AT14: 16 | AU14: 169 | AV14: 426 | AW14: 721 | AX14: 124 | AY14: 0 | AZ14: =SUM(AT14:AY14) -> 1456 | BA14: 19 | BB14: 410 | BC14: 350 | BD14: 100 | BE14: 61 | BF14: =SUM(BB14:BE14) -> 921 | BG14: 0 | BH14: 0 | BI14: 252 | BJ14: 300 | BK14: 340 | BL14: 29 | BM14: =SUM(BG14:BL14) -> 921 | BN14: 19 | BO14: 696 | BP14: 792 | BQ14: 56 | BR14: 51 | BS14: 1595 | BT14: 155 | BU14: 508 | BV14: 399 | BW14: 294 | BX14: 190 | BY14: 49 | BZ14: =SUM(BT14:BY14) -> 1595 | CA14: 19 | CB14: 656 | CC14: 748 | CD14: 31 | CE14: 21 | CF14: =SUM(CB14:CE14) -> 1456 | CG14: 16 | CH14: 169 | CI14: 426 | CJ14: 721 | CK14: 124 | CL14: 0 | CM14: =SUM(CG14:CL14) -> 1456 | CN14: 19 | CO14: 70 | CP14: 79 | CQ14: 0 | CR14: 0 | CS14: 149 | CT14: 0 | CU14: 7 | CV14: 11 | CW14: 120 | CX14: 11 | CY14: 0 | CZ14: =SUM(CT14:CY14) -> 149 | DA14: 19 | DB14: 115 | DC14: 95 | DD14: 35 | DE14: 29 | DF14: =SUM(DB14:DE14) -> 274 | DG14: 0 | DH14: 0 | DI14: 20 | DJ14: 154 | DK14: 100 | DL14: 0 | DM14: =SUM(DG14:DL14) -> 274 | DN14: 19 | DO14: 70 | DP14: 79 | DQ14: 0 | DR14: 0 | DS14: 149 | DT14: 0 | DU14: 7 | DV14: 11 | DW14: 120 | DX14: 11 | DY14: 0 | DZ14: =SUM(DT14:DY14) -> 149 | EA14: 19 | EB14: 0 | EC14: 0 | ED14: 0 | EE14: 0 | EF14: =SUM(EB14:EE14) -> 0 | EG14: 0 | EH14: 0 | EI14: 0 | EJ14: 0 | EK14: 0 | EL14: 0 | EM14: =SUM(EG14:EL14) -> 0 | EN14: 19 | EO14: 0 | EP14: 0 | EQ14: 0 | ER14: 0 | ES14: =SUM(EO14:ER14) -> 0 | ET14: 0 | EU14: 0 | EV14: 0 | EW14: 0 | EX14: 0 | EY14: 0 | EZ14: =SUM(ET14:EY14) -> 0 | FA14: إلتهاب الجهاز التنفسي العلوي | FB14: 19 | FC14: =B14+O14+AB14+AO14+BB14+BO14+CB14+CO14+DB14+DO14+EB14+EO14 -> 2823 | FD14: =C14+P14+AC14+AP14+BC14+BP14+CC14+CP14+DC14+DP14+EC14+EP14 -> 3041 | FE14: =D14+Q14+AD14+AQ14+BD14+BQ14+CD14+CQ14+DD14+DQ14+ED14+EQ14 -> 253 | FF14: =E14+R14+AE14+AR14+BE14+BR14+CE14+CR14+DE14+DR14+EE14+ER14 -> 183 | FG14: =SUM(FC14:FF14) -> 6300 | FH14: =G14+T14+AG14+AT14+BG14+BT14+CG14+CT14+DG14+DT14+EG14+ET14 -> 187 | FI14: =H14+U14+AH14+AU14+BH14+BU14+CH14+CU14+DH14+DU14+EH14+EU14 -> 874 | FJ14: =I14+V14+AI14+AV14+BI14+BV14+CI14+CV14+DI14+DV14+EI14+EV14 -> 1567 | FK14: =J14+W14+AJ14+AW14+BJ14+BW14+CJ14+CW14+DJ14+DW14+EJ14+EW14 -> 2670 | FL14: =K14+X14+AK14+AX14+BK14+BX14+CK14+CX14+DK14+DX14+EK14+EX14 -> 922 | FM14: =L14+Y14+AL14+AY14+BL14+BY14+CL14+CY14+DL14+DY14+EL14+EY14 -> 78 | FN14: =SUM(FH14:FM14) -> 6298
A15: 20 | B15: 78 | C15: 71 | D15: 0 | E15: 0 | F15: =SUM(B15:E15) -> 149 | G15: 2 | H15: 5 | I15: 9 | J15: 130 | K15: 3 | L15: 0 | M15: =SUM(G15:L15) -> 149 | N15: 20 | O15: 70 | P15: 75 | Q15: 0 | R15: 0 | S15: 149 | T15: 2 | U15: 5 | V15: 9 | W15: 130 | X15: 3 | Y15: 0 | Z15: =SUM(T15:Y15) -> 149 | AA15: 20 | AB15: 0 | AC15: 0 | AD15: 0 | AE15: 0 | AF15: =SUM(AB15:AE15) -> 0 | AG15: 0 | AH15: 0 | AI15: 0 | AJ15: 0 | AK15: 0 | AL15: 0 | AM15: =SUM(AG15:AL15) -> 0 | AN15: 20 | AO15: 11 | AP15: 7 | AQ15: 2 | AR15: 0 | AS15: =SUM(AO15:AR15) -> 20 | AT15: 0 | AU15: 0 | AV15: 2 | AW15: 7 | AX15: 11 | AY15: 0 | AZ15: =SUM(AT15:AY15) -> 20 | BA15: 20 | BB15: 10 | BC15: 5 | BD15: 0 | BE15: 0 | BF15: =SUM(BB15:BE15) -> 15 | BG15: 0 | BH15: 0 | BI15: 5 | BJ15: 10 | BK15: 0 | BL15: 0 | BM15: =SUM(BG15:BL15) -> 15 | BN15: 20 | BO15: 104 | BP15: 164 | BQ15: 34 | BR15: 24 | BS15: 326 | BT15: 38 | BU15: 71 | BV15: 77 | BW15: 64 | BX15: 61 | BY15: 15 | BZ15: =SUM(BT15:BY15) -> 326 | CA15: 20 | CB15: 11 | CC15: 7 | CD15: 2 | CE15: 0 | CF15: =SUM(CB15:CE15) -> 20 | CG15: 0 | CH15: 0 | CI15: 2 | CJ15: 7 | CK15: 11 | CL15: 0 | CM15: =SUM(CG15:CL15) -> 20 | CN15: 20 | CO15: 70 | CP15: 71 | CQ15: 0 | CR15: 0 | CS15: 149 | CT15: 2 | CU15: 5 | CV15: 9 | CW15: 130 | CX15: 3 | CY15: 0 | CZ15: =SUM(CT15:CY15) -> 149 | DA15: 20 | DB15: 40 | DC15: 4 | DD15: 19 | DE15: 10 | DF15: =SUM(DB15:DE15) -> 73 | DG15: 0 | DH15: 0 | DI15: 0 | DJ15: 40 | DK15: 33 | DL15: 0 | DM15: =SUM(DG15:DL15) -> 73 | DN15: 20 | DO15: 78 | DP15: 71 | DQ15: 0 | DR15: 0 | DS15: 149 | DT15: 2 | DU15: 5 | DV15: 9 | DW15: 130 | DX15: 3 | DY15: 0 | DZ15: =SUM(DT15:DY15) -> 149 | EA15: 20 | EB15: 0 | EC15: 0 | ED15: 0 | EE15: 0 | EF15: =SUM(EB15:EE15) -> 0 | EG15: 0 | EH15: 0 | EI15: 0 | EJ15: 0 | EK15: 0 | EL15: 0 | EM15: =SUM(EG15:EL15) -> 0 | EN15: 20 | EO15: 0 | EP15: 0 | EQ15: 0 | ER15: 0 | ES15: =SUM(EO15:ER15) -> 0 | ET15: 0 | EU15: 0 | EV15: 0 | EW15: 0 | EX15: 0 | EY15: 0 | EZ15: =SUM(ET15:EY15) -> 0 | FA15: الإلتهابات الرئوية | FB15: 20 | FC15: =B15+O15+AB15+AO15+BB15+BO15+CB15+CO15+DB15+DO15+EB15+EO15 -> 472 | FD15: =C15+P15+AC15+AP15+BC15+BP15+CC15+CP15+DC15+DP15+EC15+EP15 -> 475 | FE15: =D15+Q15+AD15+AQ15+BD15+BQ15+CD15+CQ15+DD15+DQ15+ED15+EQ15 -> 57 | FF15: =E15+R15+AE15+AR15+BE15+BR15+CE15+CR15+DE15+DR15+EE15+ER15 -> 34 | FG15: =SUM(FC15:FF15) -> 1038 | FH15: =G15+T15+AG15+AT15+BG15+BT15+CG15+CT15+DG15+DT15+EG15+ET15 -> 46 | FI15: =H15+U15+AH15+AU15+BH15+BU15+CH15+CU15+DH15+DU15+EH15+EU15 -> 91 | FJ15: =I15+V15+AI15+AV15+BI15+BV15+CI15+CV15+DI15+DV15+EI15+EV15 -> 122 | FK15: =J15+W15+AJ15+AW15+BJ15+BW15+CJ15+CW15+DJ15+DW15+EJ15+EW15 -> 648 | FL15: =K15+X15+AK15+AX15+BK15+BX15+CK15+CX15+DK15+DX15+EK15+EX15 -> 128 | FM15: =L15+Y15+AL15+AY15+BL15+BY15+CL15+CY15+DL15+DY15+EL15+EY15 -> 15 | FN15: =SUM(FH15:FM15) -> 1050
A16: 21 | B16: 0 | C16: 0 | D16: 0 | E16: 0 | F16: =SUM(B16:E16) -> 0 | G16: 0 | H16: 0 | I16: 0 | J16: 0 | K16: 0 | L16: 0 | M16: =SUM(G16:L16) -> 0 | N16: 21 | O16: 0 | P16: 0 | Q16: 0 | R16: 0 | S16: 0 | T16: 0 | U16: 0 | V16: 0 | W16: 0 | X16: 0 | Y16: 0 | Z16: =SUM(T16:Y16) -> 0 | AA16: 21 | AB16: 0 | AC16: 0 | AD16: 0 | AE16: 0 | AF16: =SUM(AB16:AE16) -> 0 | AG16: 0 | AH16: 0 | AI16: 0 | AJ16: 0 | AK16: 0 | AL16: 0 | AM16: =SUM(AG16:AL16) -> 0 | AN16: 21 | AO16: 29 | AP16: 38 | AQ16: 6 | AR16: 11 | AS16: =SUM(AO16:AR16) -> 84 | AT16: 0 | AU16: 7 | AV16: 38 | AW16: 37 | AX16: 2 | AY16: 0 | AZ16: =SUM(AT16:AY16) -> 84 | BA16: 21 | BB16: 11 | BC16: 15 | BD16: 30 | BE16: 10 | BF16: =SUM(BB16:BE16) -> 66 | BG16: 0 | BH16: 1 | BI16: 12 | BJ16: 27 | BK16: 15 | BL16: 11 | BM16: =SUM(BG16:BL16) -> 66 | BN16: 21 | BO16: 0 | BP16: 0 | BQ16: 0 | BR16: 0 | BS16: 0 | BT16: 0 | BU16: 0 | BV16: 0 | BW16: 0 | BX16: 0 | BY16: 0 | BZ16: =SUM(BT16:BY16) -> 0 | CA16: 21 | CB16: 29 | CC16: 38 | CD16: 6 | CE16: 11 | CF16: =SUM(CB16:CE16) -> 84 | CG16: 0 | CH16: 7 | CI16: 38 | CJ16: 37 | CK16: 2 | CL16: 0 | CM16: =SUM(CG16:CL16) -> 84 | CN16: 21 | CO16: 0 | CP16: 0 | CQ16: 0 | CR16: 0 | CS16: 0 | CT16: 0 | CU16: 0 | CV16: 0 | CW16: 0 | CX16: 0 | CY16: 0 | CZ16: =SUM(CT16:CY16) -> 0 | DA16: 21 | DB16: 22 | DC16: 19 | DD16: 0 | DE16: 0 | DF16: =SUM(DB16:DE16) -> 41 | DG16: 0 | DH16: 0 | DI16: 0 | DJ16: 11 | DK16: 30 | DL16: 0 | DM16: =SUM(DG16:DL16) -> 41 | DN16: 21 | DO16: 0 | DP16: 0 | DQ16: 0 | DR16: 0 | DS16: 0 | DT16: 0 | DU16: 0 | DV16: 0 | DW16: 0 | DX16: 0 | DY16: 0 | DZ16: =SUM(DT16:DY16) -> 0 | EA16: 21 | EB16: 0 | EC16: 0 | ED16: 0 | EE16: 0 | EF16: =SUM(EB16:EE16) -> 0 | EG16: 0 | EH16: 0 | EI16: 0 | EJ16: 0 | EK16: 0 | EL16: 0 | EM16: =SUM(EG16:EL16) -> 0 | EN16: 21 | EO16: 0 | EP16: 0 | EQ16: 0 | ER16: 0 | ES16: =SUM(EO16:ER16) -> 0 | ET16: 0 | EU16: 0 | EV16: 0 | EW16: 0 | EX16: 0 | EY16: 0 | EZ16: =SUM(ET16:EY16) -> 0 | FA16: الربو | FB16: 21 | FC16: =B16+O16+AB16+AO16+BB16+BO16+CB16+CO16+DB16+DO16+EB16+EO16 -> 91 | FD16: =C16+P16+AC16+AP16+BC16+BP16+CC16+CP16+DC16+DP16+EC16+EP16 -> 110 | FE16: =D16+Q16+AD16+AQ16+BD16+BQ16+CD16+CQ16+DD16+DQ16+ED16+EQ16 -> 42 | FF16: =E16+R16+AE16+AR16+BE16+BR16+CE16+CR16+DE16+DR16+EE16+ER16 -> 32 | FG16: =SUM(FC16:FF16) -> 275 | FH16: =G16+T16+AG16+AT16+BG16+BT16+CG16+CT16+DG16+DT16+EG16+ET16 -> 0 | FI16: =H16+U16+AH16+AU16+BH16+BU16+CH16+CU16+DH16+DU16+EH16+EU16 -> 15 | FJ16: =I16+V16+AI16+AV16+BI16+BV16+CI16+CV16+DI16+DV16+EI16+EV16 -> 88 | FK16: =J16+W16+AJ16+AW16+BJ16+BW16+CJ16+CW16+DJ16+DW16+EJ16+EW16 -> 112 | FL16: =K16+X16+AK16+AX16+BK16+BX16+CK16+CX16+DK16+DX16+EK16+EX16 -> 49 | FM16: =L16+Y16+AL16+AY16+BL16+BY16+CL16+CY16+DL16+DY16+EL16+EY16 -> 11 | FN16: =SUM(FH16:FM16) -> 275
A17: 22 | B17: 0 | C17: 0 | D17: 0 | E17: 0 | F17: =SUM(B17:E17) -> 0 | G17: 0 | H17: 0 | I17: 0 | J17: 0 | K17: 0 | L17: 0 | M17: =SUM(G17:L17) -> 0 | N17: 22 | O17: 0 | P17: 0 | Q17: 0 | R17: 0 | S17: 0 | T17: 0 | U17: 0 | V17: 0 | W17: 0 | X17: 0 | Y17: 0 | Z17: =SUM(T17:Y17) -> 0 | AA17: 22 | AB17: 0 | AC17: 0 | AD17: 0 | AE17: 0 | AF17: =SUM(AB17:AE17) -> 0 | AG17: 0 | AH17: 0 | AI17: 0 | AJ17: 0 | AK17: 0 | AL17: 0 | AM17: =SUM(AG17:AL17) -> 0 | AN17: 22 | AO17: 49 | AP17: 56 | AQ17: 1 | AR17: 0 | AS17: =SUM(AO17:AR17) -> 106 | AT17: 0 | AU17: 0 | AV17: 67 | AW17: 23 | AX17: 16 | AY17: 0 | AZ17: =SUM(AT17:AY17) -> 106 | BA17: 22 | BB17: 20 | BC17: 20 | BD17: 4 | BE17: 1 | BF17: =SUM(BB17:BE17) -> 45 | BG17: 0 | BH17: 0 | BI17: 11 | BJ17: 14 | BK17: 17 | BL17: 3 | BM17: =SUM(BG17:BL17) -> 45 | BN17: 22 | BO17: 126 | BP17: 99 | BQ17: 0 | BR17: 0 | BS17: 225 | BT17: 0 | BU17: 45 | BV17: 50 | BW17: 55 | BX17: 55 | BY17: 20 | BZ17: =SUM(BT17:BY17) -> 225 | CA17: 22 | CB17: 49 | CC17: 56 | CD17: 1 | CE17: 0 | CF17: =SUM(CB17:CE17) -> 106 | CG17: 0 | CH17: 0 | CI17: 67 | CJ17: 23 | CK17: 16 | CL17: 0 | CM17: =SUM(CG17:CL17) -> 106 | CN17: 22 | CO17: 0 | CP17: 0 | CQ17: 0 | CR17: 0 | CS17: 0 | CT17: 0 | CU17: 0 | CV17: 0 | CW17: 0 | CX17: 0 | CY17: 0 | CZ17: =SUM(CT17:CY17) -> 0 | DA17: 22 | DB17: 16 | DC17: 45 | DD17: 0 | DE17: 0 | DF17: =SUM(DB17:DE17) -> 61 | DG17: 0 | DH17: 0 | DI17: 10 | DJ17: 20 | DK17: 31 | DL17: 0 | DM17: =SUM(DG17:DL17) -> 61 | DN17: 22 | DO17: 0 | DP17: 0 | DQ17: 0 | DR17: 0 | DS17: 0 | DT17: 0 | DU17: 0 | DV17: 0 | DW17: 0 | DX17: 0 | DY17: 0 | DZ17: =SUM(DT17:DY17) -> 0 | EA17: 22 | EB17: 0 | EC17: 0 | ED17: 0 | EE17: 0 | EF17: =SUM(EB17:EE17) -> 0 | EG17: 0 | EH17: 0 | EI17: 0 | EJ17: 0 | EK17: 0 | EL17: 0 | EM17: =SUM(EG17:EL17) -> 0 | EN17: 22 | EO17: 0 | EP17: 0 | EQ17: 0 | ER17: 0 | ES17: =SUM(EO17:ER17) -> 0 | ET17: 0 | EU17: 0 | EV17: 0 | EW17: 0 | EX17: 0 | EY17: 0 | EZ17: =SUM(ET17:EY17) -> 0 | FA17: أمراض الفم والأسنان | FB17: 22 | FC17: =B17+O17+AB17+AO17+BB17+BO17+CB17+CO17+DB17+DO17+EB17+EO17 -> 260 | FD17: =C17+P17+AC17+AP17+BC17+BP17+CC17+CP17+DC17+DP17+EC17+EP17 -> 276 | FE17: =D17+Q17+AD17+AQ17+BD17+BQ17+CD17+CQ17+DD17+DQ17+ED17+EQ17 -> 6 | FF17: =E17+R17+AE17+AR17+BE17+BR17+CE17+CR17+DE17+DR17+EE17+ER17 -> 1 | FG17: =SUM(FC17:FF17) -> 543 | FH17: =G17+T17+AG17+AT17+BG17+BT17+CG17+CT17+DG17+DT17+EG17+ET17 -> 0 | FI17: =H17+U17+AH17+AU17+BH17+BU17+CH17+CU17+DH17+DU17+EH17+EU17 -> 45 | FJ17: =I17+V17+AI17+AV17+BI17+BV17+CI17+CV17+DI17+DV17+EI17+EV17 -> 205 | FK17: =J17+W17+AJ17+AW17+BJ17+BW17+CJ17+CW17+DJ17+DW17+EJ17+EW17 -> 135 | FL17: =K17+X17+AK17+AX17+BK17+BX17+CK17+CX17+DK17+DX17+EK17+EX17 -> 135 | FM17: =L17+Y17+AL17+AY17+BL17+BY17+CL17+CY17+DL17+DY17+EL17+EY17 -> 23 | FN17: =SUM(FH17:FM17) -> 543
A18: 23 | B18: 0 | C18: 0 | D18: 0 | E18: 0 | F18: =SUM(B18:E18) -> 0 | G18: 0 | H18: 0 | I18: 0 | J18: 0 | K18: 0 | L18: 0 | M18: =SUM(G18:L18) -> 0 | N18: 23 | O18: 0 | P18: 0 | Q18: 0 | R18: 0 | S18: 0 | T18: 0 | U18: 0 | V18: 0 | W18: 0 | X18: 0 | Y18: 0 | Z18: =SUM(T18:Y18) -> 0 | AA18: 23 | AB18: 0 | AC18: 0 | AD18: 0 | AE18: 0 | AF18: =SUM(AB18:AE18) -> 0 | AG18: 0 | AH18: 0 | AI18: 0 | AJ18: 0 | AK18: 0 | AL18: 0 | AM18: =SUM(AG18:AL18) -> 0 | AN18: 23 | AO18: 123 | AP18: 196 | AQ18: 59 | AR18: 6 | AS18: =SUM(AO18:AR18) -> 384 | AT18: 0 | AU18: 7 | AV18: 27 | AW18: 256 | AX18: 94 | AY18: 0 | AZ18: =SUM(AT18:AY18) -> 384 | BA18: 23 | BB18: 90 | BC18: 74 | BD18: 11 | BE18: 11 | BF18: =SUM(BB18:BE18) -> 186 | BG18: 0 | BH18: 0 | BI18: 6 | BJ18: 22 | BK18: 88 | BL18: 70 | BM18: =SUM(BG18:BL18) -> 186 | BN18: 23 | BO18: 59 | BP18: 21 | BQ18: 32 | BR18: 31 | BS18: 143 | BT18: 25 | BU18: 13 | BV18: 10 | BW18: 11 | BX18: 55 | BY18: 29 | BZ18: =SUM(BT18:BY18) -> 143 | CA18: 23 | CB18: 123 | CC18: 196 | CD18: 59 | CE18: 6 | CF18: =SUM(CB18:CE18) -> 384 | CG18: 0 | CH18: 7 | CI18: 27 | CJ18: 256 | CK18: 94 | CL18: 0 | CM18: =SUM(CG18:CL18) -> 384 | CN18: 23 | CO18: 0 | CP18: 0 | CQ18: 0 | CR18: 0 | CS18: 0 | CT18: 0 | CU18: 0 | CV18: 0 | CW18: 0 | CX18: 0 | CY18: 0 | CZ18: =SUM(CT18:CY18) -> 0 | DA18: 23 | DB18: 9 | DC18: 4 | DD18: 0 | DE18: 0 | DF18: =SUM(DB18:DE18) -> 13 | DG18: 0 | DH18: 0 | DI18: 3 | DJ18: 0 | DK18: 10 | DL18: 0 | DM18: =SUM(DG18:DL18) -> 13 | DN18: 23 | DO18: 0 | DP18: 0 | DQ18: 0 | DR18: 0 | DS18: 0 | DT18: 0 | DU18: 0 | DV18: 0 | DW18: 0 | DX18: 0 | DY18: 0 | DZ18: =SUM(DT18:DY18) -> 0 | EA18: 23 | EB18: 0 | EC18: 0 | ED18: 0 | EE18: 0 | EF18: =SUM(EB18:EE18) -> 0 | EG18: 0 | EH18: 0 | EI18: 0 | EJ18: 0 | EK18: 0 | EL18: 0 | EM18: =SUM(EG18:EL18) -> 0 | EN18: 23 | EO18: 0 | EP18: 0 | EQ18: 0 | ER18: 0 | ES18: =SUM(EO18:ER18) -> 0 | ET18: 0 | EU18: 0 | EV18: 0 | EW18: 0 | EX18: 0 | EY18: 0 | EZ18: =SUM(ET18:EY18) -> 0 | FA18: أمراض المعدة والمريء والأمعاء الدقيقة | FB18: 23 | FC18: =B18+O18+AB18+AO18+BB18+BO18+CB18+CO18+DB18+DO18+EB18+EO18 -> 404 | FD18: =C18+P18+AC18+AP18+BC18+BP18+CC18+CP18+DC18+DP18+EC18+EP18 -> 491 | FE18: =D18+Q18+AD18+AQ18+BD18+BQ18+CD18+CQ18+DD18+DQ18+ED18+EQ18 -> 161 | FF18: =E18+R18+AE18+AR18+BE18+BR18+CE18+CR18+DE18+DR18+EE18+ER18 -> 54 | FG18: =SUM(FC18:FF18) -> 1110 | FH18: =G18+T18+AG18+AT18+BG18+BT18+CG18+CT18+DG18+DT18+EG18+ET18 -> 25 | FI18: =H18+U18+AH18+AU18+BH18+BU18+CH18+CU18+DH18+DU18+EH18+EU18 -> 27 | FJ18: =I18+V18+AI18+AV18+BI18+BV18+CI18+CV18+DI18+DV18+EI18+EV18 -> 73 | FK18: =J18+W18+AJ18+AW18+BJ18+BW18+CJ18+CW18+DJ18+DW18+EJ18+EW18 -> 545 | FL18: =K18+X18+AK18+AX18+BK18+BX18+CK18+CX18+DK18+DX18+EK18+EX18 -> 341 | FM18: =L18+Y18+AL18+AY18+BL18+BY18+CL18+CY18+DL18+DY18+EL18+EY18 -> 99 | FN18: =SUM(FH18:FM18) -> 1110
A19: 24 | B19: 0 | C19: 0 | D19: 0 | E19: 0 | F19: =SUM(B19:E19) -> 0 | G19: 0 | H19: 0 | I19: 0 | J19: 0 | K19: 0 | L19: 0 | M19: =SUM(G19:L19) -> 0 | N19: 24 | O19: 0 | P19: 0 | Q19: 0 | R19: 0 | S19: 0 | T19: 0 | U19: 0 | V19: 0 | W19: 0 | X19: 0 | Y19: 0 | Z19: =SUM(T19:Y19) -> 0 | AA19: 24 | AB19: 0 | AC19: 0 | AD19: 0 | AE19: 0 | AF19: =SUM(AB19:AE19) -> 0 | AG19: 0 | AH19: 0 | AI19: 0 | AJ19: 0 | AK19: 0 | AL19: 0 | AM19: =SUM(AG19:AL19) -> 0 | AN19: 24 | AO19: 87 | AP19: 106 | AQ19: 43 | AR19: 5 | AS19: =SUM(AO19:AR19) -> 241 | AT19: 0 | AU19: 0 | AV19: 0 | AW19: 204 | AX19: 31 | AY19: 6 | AZ19: =SUM(AT19:AY19) -> 241 | BA19: 24 | BB19: 0 | BC19: 0 | BD19: 0 | BE19: 0 | BF19: =SUM(BB19:BE19) -> 0 | BG19: 0 | BH19: 0 | BI19: 0 | BJ19: 0 | BK19: 0 | BL19: 0 | BM19: =SUM(BG19:BL19) -> 0 | BN19: 24 | BO19: 96 | BP19: 71 | BQ19: 19 | BR19: 23 | BS19: 209 | BT19: 27 | BU19: 34 | BV19: 46 | BW19: 44 | BX19: 26 | BY19: 32 | BZ19: =SUM(BT19:BY19) -> 209 | CA19: 24 | CB19: 87 | CC19: 106 | CD19: 43 | CE19: 5 | CF19: =SUM(CB19:CE19) -> 241 | CG19: 0 | CH19: 0 | CI19: 0 | CJ19: 204 | CK19: 31 | CL19: 6 | CM19: =SUM(CG19:CL19) -> 241 | CN19: 24 | CO19: 0 | CP19: 0 | CQ19: 0 | CR19: 0 | CS19: 0 | CT19: 0 | CU19: 0 | CV19: 0 | CW19: 0 | CX19: 0 | CY19: 0 | CZ19: =SUM(CT19:CY19) -> 0 | DA19: 24 | DB19: 20 | DC19: 11 | DD19: 0 | DE19: 0 | DF19: =SUM(DB19:DE19) -> 31 | DG19: 0 | DH19: 0 | DI19: 0 | DJ19: 31 | DK19: 0 | DL19: 0 | DM19: =SUM(DG19:DL19) -> 31 | DN19: 24 | DO19: 0 | DP19: 0 | DQ19: 0 | DR19: 0 | DS19: 0 | DT19: 0 | DU19: 0 | DV19: 0 | DW19: 0 | DX19: 0 | DY19: 0 | DZ19: =SUM(DT19:DY19) -> 0 | EA19: 24 | EB19: 0 | EC19: 0 | ED19: 0 | EE19: 0 | EF19: =SUM(EB19:EE19) -> 0 | EG19: 0 | EH19: 0 | EI19: 0 | EJ19: 0 | EK19: 0 | EL19: 0 | EM19: =SUM(EG19:EL19) -> 0 | EN19: 24 | EO19: 0 | EP19: 0 | EQ19: 0 | ER19: 0 | ES19: =SUM(EO19:ER19) -> 0 | ET19: 0 | EU19: 0 | EV19: 0 | EW19: 0 | EX19: 0 | EY19: 0 | EZ19: =SUM(ET19:EY19) -> 0 | FA19: أمراض القالون والمستقيم والشرج | FB19: 24 | FC19: =B19+O19+AB19+AO19+BB19+BO19+CB19+CO19+DB19+DO19+EB19+EO19 -> 290 | FD19: =C19+P19+AC19+AP19+BC19+BP19+CC19+CP19+DC19+DP19+EC19+EP19 -> 294 | FE19: =D19+Q19+AD19+AQ19+BD19+BQ19+CD19+CQ19+DD19+DQ19+ED19+EQ19 -> 105 | FF19: =E19+R19+AE19+AR19+BE19+BR19+CE19+CR19+DE19+DR19+EE19+ER19 -> 33 | FG19: =SUM(FC19:FF19) -> 722 | FH19: =G19+T19+AG19+AT19+BG19+BT19+CG19+CT19+DG19+DT19+EG19+ET19 -> 27 | FI19: =H19+U19+AH19+AU19+BH19+BU19+CH19+CU19+DH19+DU19+EH19+EU19 -> 34 | FJ19: =I19+V19+AI19+AV19+BI19+BV19+CI19+CV19+DI19+DV19+EI19+EV19 -> 46 | FK19: =J19+W19+AJ19+AW19+BJ19+BW19+CJ19+CW19+DJ19+DW19+EJ19+EW19 -> 483 | FL19: =K19+X19+AK19+AX19+BK19+BX19+CK19+CX19+DK19+DX19+EK19+EX19 -> 88 | FM19: =L19+Y19+AL19+AY19+BL19+BY19+CL19+CY19+DL19+DY19+EL19+EY19 -> 44 | FN19: =SUM(FH19:FM19) -> 722
A20: 25 | B20: 0 | C20: 0 | D20: 0 | E20: 0 | F20: =SUM(B20:E20) -> 0 | G20: 0 | H20: 0 | I20: 0 | J20: 0 | K20: 0 | L20: 0 | M20: =SUM(G20:L20) -> 0 | N20: 25 | O20: 0 | P20: 0 | Q20: 0 | R20: 0 | S20: 0 | T20: 0 | U20: 0 | V20: 0 | W20: 0 | X20: 0 | Y20: 0 | Z20: =SUM(T20:Y20) -> 0 | AA20: 25 | AB20: 0 | AC20: 0 | AD20: 0 | AE20: 0 | AF20: =SUM(AB20:AE20) -> 0 | AG20: 0 | AH20: 0 | AI20: 0 | AJ20: 0 | AK20: 0 | AL20: 0 | AM20: =SUM(AG20:AL20) -> 0 | AN20: 25 | AO20: 76 | AP20: 51 | AQ20: 22 | AR20: 6 | AS20: =SUM(AO20:AR20) -> 155 | AT20: 0 | AU20: 0 | AV20: 14 | AW20: 26 | AX20: 91 | AY20: 24 | AZ20: =SUM(AT20:AY20) -> 155 | BA20: 25 | BB20: 20 | BC20: 25 | BD20: 8 | BE20: 0 | BF20: =SUM(BB20:BE20) -> 53 | BG20: 0 | BH20: 0 | BI20: 1 | BJ20: 24 | BK20: 22 | BL20: 6 | BM20: =SUM(BG20:BL20) -> 53 | BN20: 25 | BO20: 118 | BP20: 117 | BQ20: 34 | BR20: 25 | BS20: 294 | BT20: 26 | BU20: 76 | BV20: 58 | BW20: 33 | BX20: 58 | BY20: 43 | BZ20: =SUM(BT20:BY20) -> 294 | CA20: 25 | CB20: 76 | CC20: 51 | CD20: 22 | CE20: 6 | CF20: =SUM(CB20:CE20) -> 155 | CG20: 0 | CH20: 0 | CI20: 14 | CJ20: 26 | CK20: 91 | CL20: 24 | CM20: =SUM(CG20:CL20) -> 155 | CN20: 25 | CO20: 0 | CP20: 0 | CQ20: 0 | CR20: 0 | CS20: 0 | CT20: 0 | CU20: 0 | CV20: 0 | CW20: 0 | CX20: 0 | CY20: 0 | CZ20: =SUM(CT20:CY20) -> 0 | DA20: 25 | DB20: 16 | DC20: 12 | DD20: 0 | DE20: 0 | DF20: =SUM(DB20:DE20) -> 28 | DG20: 0 | DH20: 0 | DI20: 8 | DJ20: 10 | DK20: 10 | DL20: 0 | DM20: =SUM(DG20:DL20) -> 28 | DN20: 25 | DO20: 0 | DP20: 0 | DQ20: 0 | DR20: 0 | DS20: 0 | DT20: 0 | DU20: 0 | DV20: 0 | DW20: 0 | DX20: 0 | DY20: 0 | DZ20: =SUM(DT20:DY20) -> 0 | EA20: 25 | EB20: 0 | EC20: 0 | ED20: 0 | EE20: 0 | EF20: =SUM(EB20:EE20) -> 0 | EG20: 0 | EH20: 0 | EI20: 0 | EJ20: 0 | EK20: 0 | EL20: 0 | EM20: =SUM(EG20:EL20) -> 0 | EN20: 25 | EO20: 0 | EP20: 0 | EQ20: 0 | ER20: 0 | ES20: =SUM(EO20:ER20) -> 0 | ET20: 0 | EU20: 0 | EV20: 0 | EW20: 0 | EX20: 0 | EY20: 0 | EZ20: =SUM(ET20:EY20) -> 0 | FA20: أمراض الجهاز البولي | FB20: 25 | FC20: =B20+O20+AB20+AO20+BB20+BO20+CB20+CO20+DB20+DO20+EB20+EO20 -> 306 | FD20: =C20+P20+AC20+AP20+BC20+BP20+CC20+CP20+DC20+DP20+EC20+EP20 -> 256 | FE20: =D20+Q20+AD20+AQ20+BD20+BQ20+CD20+CQ20+DD20+DQ20+ED20+EQ20 -> 86 | FF20: =E20+R20+AE20+AR20+BE20+BR20+CE20+CR20+DE20+DR20+EE20+ER20 -> 37 | FG20: =SUM(FC20:FF20) -> 685 | FH20: =G20+T20+AG20+AT20+BG20+BT20+CG20+CT20+DG20+DT20+EG20+ET20 -> 26 | FI20: =H20+U20+AH20+AU20+BH20+BU20+CH20+CU20+DH20+DU20+EH20+EU20 -> 76 | FJ20: =I20+V20+AI20+AV20+BI20+BV20+CI20+CV20+DI20+DV20+EI20+EV20 -> 95 | FK20: =J20+W20+AJ20+AW20+BJ20+BW20+CJ20+CW20+DJ20+DW20+EJ20+EW20 -> 119 | FL20: =K20+X20+AK20+AX20+BK20+BX20+CK20+CX20+DK20+DX20+EK20+EX20 -> 272 | FM20: =L20+Y20+AL20+AY20+BL20+BY20+CL20+CY20+DL20+DY20+EL20+EY20 -> 97 | FN20: =SUM(FH20:FM20) -> 685
A21: 26 | B21: 0 | C21: 0 | D21: 0 | E21: 0 | F21: =SUM(B21:E21) -> 0 | G21: 0 | H21: 0 | I21: 0 | J21: 0 | K21: 0 | L21: 0 | M21: =SUM(G21:L21) -> 0 | N21: 26 | O21: 0 | P21: 0 | Q21: 0 | R21: 0 | S21: 0 | T21: 0 | U21: 0 | V21: 0 | W21: 0 | X21: 0 | Y21: 0 | Z21: =SUM(T21:Y21) -> 0 | AA21: 26 | AB21: 0 | AC21: 0 | AD21: 0 | AE21: 0 | AF21: =SUM(AB21:AE21) -> 0 | AG21: 0 | AH21: 0 | AI21: 0 | AJ21: 0 | AK21: 0 | AL21: 0 | AM21: =SUM(AG21:AL21) -> 0 | AN21: 26 | AO21: 0 | AP21: 8 | AQ21: 0 | AR21: 1 | AS21: =SUM(AO21:AR21) -> 9 | AT21: 0 | AU21: 0 | AV21: 0 | AW21: 9 | AX21: 0 | AY21: 0 | AZ21: =SUM(AT21:AY21) -> 9 | BA21: 26 | BB21: 0 | BC21: 4 | BD21: 0 | BE21: 4 | BF21: =SUM(BB21:BE21) -> 8 | BG21: 0 | BH21: 0 | BI21: 0 | BJ21: 2 | BK21: 6 | BL21: 0 | BM21: =SUM(BG21:BL21) -> 8 | BN21: 26 | BP21: 22 | BR21: 8 | BS21: 30 | BV21: 1 | BW21: 13 | BX21: 16 | BY21: 0 | BZ21: =SUM(BT21:BY21) -> 30 | CA21: 26 | CB21: 0 | CC21: 8 | CD21: 0 | CE21: 1 | CF21: =SUM(CB21:CE21) -> 9 | CG21: 0 | CH21: 0 | CI21: 0 | CJ21: 9 | CK21: 0 | CL21: 0 | CM21: =SUM(CG21:CL21) -> 9 | CN21: 26 | CO21: 0 | CP21: 0 | CQ21: 0 | CR21: 0 | CS21: 0 | CT21: 0 | CU21: 0 | CV21: 0 | CW21: 0 | CX21: 0 | CY21: 0 | CZ21: =SUM(CT21:CY21) -> 0 | DA21: 26 | DB21: 0 | DC21: 9 | DD21: 0 | DE21: 0 | DF21: =SUM(DB21:DE21) -> 9 | DG21: 0 | DH21: 0 | DI21: 0 | DJ21: 0 | DK21: 9 | DL21: 0 | DM21: =SUM(DG21:DL21) -> 9 | DN21: 26 | DO21: 0 | DP21: 0 | DQ21: 0 | DR21: 0 | DS21: 0 | DT21: 0 | DU21: 0 | DV21: 0 | DW21: 0 | DX21: 0 | DY21: 0 | DZ21: =SUM(DT21:DY21) -> 0 | EA21: 26 | EB21: 0 | EC21: 0 | ED21: 0 | EE21: 0 | EF21: =SUM(EB21:EE21) -> 0 | EG21: 0 | EH21: 0 | EI21: 0 | EJ21: 0 | EK21: 0 | EL21: 0 | EM21: =SUM(EG21:EL21) -> 0 | EN21: 26 | EO21: 0 | EP21: 0 | EQ21: 0 | ER21: 0 | ES21: =SUM(EO21:ER21) -> 0 | ET21: 0 | EU21: 0 | EV21: 0 | EW21: 0 | EX21: 0 | EY21: 0 | EZ21: =SUM(ET21:EY21) -> 0 | FA21: أمراض الثدي | FB21: 26 | FC21: =B21+O21+AB21+AO21+BB21+BO21+CB21+CO21+DB21+DO21+EB21+EO21 -> 0 | FD21: =C21+P21+AC21+AP21+BC21+BP21+CC21+CP21+DC21+DP21+EC21+EP21 -> 51 | FE21: =D21+Q21+AD21+AQ21+BD21+BQ21+CD21+CQ21+DD21+DQ21+ED21+EQ21 -> 0 | FF21: =E21+R21+AE21+AR21+BE21+BR21+CE21+CR21+DE21+DR21+EE21+ER21 -> 14 | FG21: =SUM(FC21:FF21) -> 65 | FH21: =G21+T21+AG21+AT21+BG21+BT21+CG21+CT21+DG21+DT21+EG21+ET21 -> 0 | FI21: =H21+U21+AH21+AU21+BH21+BU21+CH21+CU21+DH21+DU21+EH21+EU21 -> 0 | FJ21: =I21+V21+AI21+AV21+BI21+BV21+CI21+CV21+DI21+DV21+EI21+EV21 -> 1 | FK21: =J21+W21+AJ21+AW21+BJ21+BW21+CJ21+CW21+DJ21+DW21+EJ21+EW21 -> 33 | FL21: =K21+X21+AK21+AX21+BK21+BX21+CK21+CX21+DK21+DX21+EK21+EX21 -> 31 | FM21: =L21+Y21+AL21+AY21+BL21+BY21+CL21+CY21+DL21+DY21+EL21+EY21 -> 0 | FN21: =SUM(FH21:FM21) -> 65
A22: 27 | B22: 0 | C22: 0 | D22: 0 | E22: 0 | F22: =SUM(B22:E22) -> 0 | G22: 0 | H22: 0 | I22: 0 | J22: 0 | K22: 0 | L22: 0 | M22: =SUM(G22:L22) -> 0 | N22: 27 | O22: 0 | P22: 0 | Q22: 0 | R22: 0 | S22: 0 | T22: 0 | U22: 0 | V22: 0 | W22: 0 | X22: 0 | Y22: 0 | Z22: =SUM(T22:Y22) -> 0 | AA22: 27 | AB22: 0 | AC22: 0 | AD22: 0 | AE22: 0 | AF22: =SUM(AB22:AE22) -> 0 | AG22: 0 | AH22: 0 | AI22: 0 | AJ22: 0 | AK22: 0 | AL22: 0 | AM22: =SUM(AG22:AL22) -> 0 | AN22: 27 | AO22: 0 | AP22: 0 | AQ22: 0 | AR22: 0 | AS22: =SUM(AO22:AR22) -> 0 | AT22: 0 | AU22: 0 | AV22: 0 | AW22: 0 | AX22: 0 | AY22: 0 | AZ22: =SUM(AT22:AY22) -> 0 | BA22: 27 | BB22: 0 | BC22: 0 | BD22: 0 | BE22: 0 | BF22: =SUM(BB22:BE22) -> 0 | BG22: 0 | BH22: 0 | BI22: 0 | BJ22: 0 | BK22: 0 | BL22: 0 | BM22: =SUM(BG22:BL22) -> 0 | BN22: 27 | BP22: 89 | BR22: 32 | BS22: 121 | BV22: 6 | BW22: 59 | BX22: 53 | BY22: 3 | BZ22: =SUM(BT22:BY22) -> 121 | CA22: 27 | CB22: 0 | CC22: 0 | CD22: 0 | CE22: 0 | CF22: =SUM(CB22:CE22) -> 0 | CG22: 0 | CH22: 0 | CI22: 0 | CJ22: 0 | CK22: 0 | CL22: 0 | CM22: =SUM(CG22:CL22) -> 0 | CN22: 27 | CO22: 0 | CP22: 0 | CQ22: 0 | CR22: 0 | CS22: 0 | CT22: 0 | CU22: 0 | CV22: 0 | CW22: 0 | CX22: 0 | CY22: 0 | CZ22: =SUM(CT22:CY22) -> 0 | DA22: 27 | DB22: 0 | DC22: 2 | DD22: 0 | DE22: 0 | DF22: =SUM(DB22:DE22) -> 2 | DG22: 0 | DH22: 0 | DI22: 0 | DJ22: 0 | DK22: 2 | DL22: 0 | DM22: =SUM(DG22:DL22) -> 2 | DN22: 27 | DO22: 0 | DP22: 0 | DQ22: 0 | DR22: 0 | DS22: 0 | DT22: 0 | DU22: 0 | DV22: 0 | DW22: 0 | DX22: 0 | DY22: 0 | DZ22: =SUM(DT22:DY22) -> 0 | EA22: 27 | EB22: 0 | EC22: 0 | ED22: 0 | EE22: 0 | EF22: =SUM(EB22:EE22) -> 0 | EG22: 0 | EH22: 0 | EI22: 0 | EJ22: 0 | EK22: 0 | EL22: 0 | EM22: =SUM(EG22:EL22) -> 0 | EN22: 27 | EO22: 0 | EP22: 0 | EQ22: 0 | ER22: 0 | ES22: =SUM(EO22:ER22) -> 0 | ET22: 0 | EU22: 0 | EV22: 0 | EW22: 0 | EX22: 0 | EY22: 0 | EZ22: =SUM(ET22:EY22) -> 0 | FA22: أمراض أعضاء الحوض عند النساء | FB22: 27 | FC22: =B22+O22+AB22+AO22+BB22+BO22+CB22+CO22+DB22+DO22+EB22+EO22 -> 0 | FD22: =C22+P22+AC22+AP22+BC22+BP22+CC22+CP22+DC22+DP22+EC22+EP22 -> 91 | FE22: =D22+Q22+AD22+AQ22+BD22+BQ22+CD22+CQ22+DD22+DQ22+ED22+EQ22 -> 0 | FF22: =E22+R22+AE22+AR22+BE22+BR22+CE22+CR22+DE22+DR22+EE22+ER22 -> 32 | FG22: =SUM(FC22:FF22) -> 123 | FH22: =G22+T22+AG22+AT22+BG22+BT22+CG22+CT22+DG22+DT22+EG22+ET22 -> 0 | FI22: =H22+U22+AH22+AU22+BH22+BU22+CH22+CU22+DH22+DU22+EH22+EU22 -> 0 | FJ22: =I22+V22+AI22+AV22+BI22+BV22+CI22+CV22+DI22+DV22+EI22+EV22 -> 6 | FK22: =J22+W22+AJ22+AW22+BJ22+BW22+CJ22+CW22+DJ22+DW22+EJ22+EW22 -> 59 | FL22: =K22+X22+AK22+AX22+BK22+BX22+CK22+CX22+DK22+DX22+EK22+EX22 -> 55 | FM22: =L22+Y22+AL22+AY22+BL22+BY22+CL22+CY22+DL22+DY22+EL22+EY22 -> 3 | FN22: =SUM(FH22:FM22) -> 123
A23: 28 | B23: 0 | C23: 0 | D23: 0 | E23: 0 | F23: =SUM(B23:E23) -> 0 | G23: 0 | H23: 0 | I23: 0 | J23: 0 | K23: 0 | L23: 0 | M23: =SUM(G23:L23) -> 0 | N23: 28 | O23: 0 | P23: 0 | Q23: 0 | R23: 0 | S23: 0 | T23: 0 | U23: 0 | V23: 0 | W23: 0 | X23: 0 | Y23: 0 | Z23: =SUM(T23:Y23) -> 0 | AA23: 28 | AB23: 0 | AC23: 0 | AD23: 0 | AE23: 0 | AF23: =SUM(AB23:AE23) -> 0 | AG23: 0 | AH23: 0 | AI23: 0 | AJ23: 0 | AK23: 0 | AL23: 0 | AM23: =SUM(AG23:AL23) -> 0 | AN23: 28 | AO23: 0 | AP23: 2 | AQ23: 0 | AR23: 0 | AS23: =SUM(AO23:AR23) -> 2 | AT23: 0 | AU23: 0 | AV23: 0 | AW23: 2 | AX23: 0 | AY23: 0 | AZ23: =SUM(AT23:AY23) -> 2 | BA23: 28 | BB23: 0 | BC23: 2 | BD23: 0 | BE23: 0 | BF23: =SUM(BB23:BE23) -> 2 | BG23: 0 | BH23: 0 | BI23: 0 | BJ23: 1 | BK23: 1 | BL23: 0 | BM23: =SUM(BG23:BL23) -> 2 | BN23: 28 | BP23: 79 | BR23: 26 | BS23: 105 | BV23: 0 | BW23: 56 | BX23: 49 | BZ23: =SUM(BT23:BY23) -> 105 | CA23: 28 | CB23: 0 | CC23: 2 | CD23: 0 | CE23: 0 | CF23: =SUM(CB23:CE23) -> 2 | CG23: 0 | CH23: 0 | CI23: 0 | CJ23: 2 | CK23: 0 | CL23: 0 | CM23: =SUM(CG23:CL23) -> 2 | CN23: 28 | CO23: 0 | CP23: 0 | CQ23: 0 | CR23: 0 | CS23: 0 | CT23: 0 | CU23: 0 | CV23: 0 | CW23: 0 | CX23: 0 | CY23: 0 | CZ23: =SUM(CT23:CY23) -> 0 | DA23: 28 | DB23: 0 | DC23: 1 | DD23: 0 | DE23: 0 | DF23: =SUM(DB23:DE23) -> 1 | DG23: 0 | DH23: 0 | DI23: 0 | DJ23: 0 | DK23: 1 | DL23: 0 | DM23: =SUM(DG23:DL23) -> 1 | DN23: 28 | DO23: 0 | DP23: 0 | DQ23: 0 | DR23: 0 | DS23: 0 | DT23: 0 | DU23: 0 | DV23: 0 | DW23: 0 | DX23: 0 | DY23: 0 | DZ23: =SUM(DT23:DY23) -> 0 | EA23: 28 | EB23: 0 | EC23: 0 | ED23: 0 | EE23: 0 | EF23: =SUM(EB23:EE23) -> 0 | EG23: 0 | EH23: 0 | EI23: 0 | EJ23: 0 | EK23: 0 | EL23: 0 | EM23: =SUM(EG23:EL23) -> 0 | EN23: 28 | EO23: 0 | EP23: 0 | EQ23: 0 | ER23: 0 | ES23: =SUM(EO23:ER23) -> 0 | ET23: 0 | EU23: 0 | EV23: 0 | EW23: 0 | EX23: 0 | EY23: 0 | EZ23: =SUM(ET23:EY23) -> 0 | FA23: مضاعفات الحمل | FB23: 28 | FC23: =B23+O23+AB23+AO23+BB23+BO23+CB23+CO23+DB23+DO23+EB23+EO23 -> 0 | FD23: =C23+P23+AC23+AP23+BC23+BP23+CC23+CP23+DC23+DP23+EC23+EP23 -> 86 | FE23: =D23+Q23+AD23+AQ23+BD23+BQ23+CD23+CQ23+DD23+DQ23+ED23+EQ23 -> 0 | FF23: =E23+R23+AE23+AR23+BE23+BR23+CE23+CR23+DE23+DR23+EE23+ER23 -> 26 | FG23: =SUM(FC23:FF23) -> 112 | FH23: =G23+T23+AG23+AT23+BG23+BT23+CG23+CT23+DG23+DT23+EG23+ET23 -> 0 | FI23: =H23+U23+AH23+AU23+BH23+BU23+CH23+CU23+DH23+DU23+EH23+EU23 -> 0 | FJ23: =I23+V23+AI23+AV23+BI23+BV23+CI23+CV23+DI23+DV23+EI23+EV23 -> 0 | FK23: =J23+W23+AJ23+AW23+BJ23+BW23+CJ23+CW23+DJ23+DW23+EJ23+EW23 -> 61 | FL23: =K23+X23+AK23+AX23+BK23+BX23+CK23+CX23+DK23+DX23+EK23+EX23 -> 51 | FM23: =L23+Y23+AL23+AY23+BL23+BY23+CL23+CY23+DL23+DY23+EL23+EY23 -> 0 | FN23: =SUM(FH23:FM23) -> 112
A24: 29 | B24: 0 | C24: 0 | D24: 0 | E24: 0 | F24: =SUM(B24:E24) -> 0 | G24: 0 | H24: 0 | I24: 0 | J24: 0 | K24: 0 | L24: 0 | M24: =SUM(G24:L24) -> 0 | N24: 29 | O24: 0 | P24: 0 | Q24: 0 | R24: 0 | S24: 0 | T24: 0 | U24: 0 | V24: 0 | W24: 0 | X24: 0 | Y24: 0 | Z24: =SUM(T24:Y24) -> 0 | AA24: 29 | AB24: 0 | AC24: 0 | AD24: 0 | AE24: 0 | AF24: =SUM(AB24:AE24) -> 0 | AG24: 0 | AH24: 0 | AI24: 0 | AJ24: 0 | AK24: 0 | AL24: 0 | AM24: =SUM(AG24:AL24) -> 0 | AN24: 29 | AO24: 14 | AP24: 0 | AQ24: 0 | AR24: 0 | AS24: =SUM(AO24:AR24) -> 14 | AT24: 0 | AU24: 0 | AV24: 0 | AW24: 9 | AX24: 3 | AY24: 2 | AZ24: =SUM(AT24:AY24) -> 14 | BA24: 29 | BB24: 0 | BC24: 0 | BD24: 0 | BE24: 0 | BF24: =SUM(BB24:BE24) -> 0 | BG24: 0 | BH24: 0 | BI24: 0 | BJ24: 0 | BK24: 0 | BL24: 0 | BM24: =SUM(BG24:BL24) -> 0 | BN24: 29 | BO24: 53 | BQ24: 16 | BS24: 69 | BV24: 0 | BW24: 27 | BX24: 38 | BY24: 4 | BZ24: =SUM(BT24:BY24) -> 69 | CA24: 29 | CB24: 14 | CC24: 0 | CD24: 0 | CE24: 0 | CF24: =SUM(CB24:CE24) -> 14 | CG24: 0 | CH24: 0 | CI24: 0 | CJ24: 9 | CK24: 3 | CL24: 2 | CM24: =SUM(CG24:CL24) -> 14 | CN24: 29 | CO24: 0 | CP24: 0 | CQ24: 0 | CR24: 0 | CS24: 0 | CT24: 0 | CU24: 0 | CV24: 0 | CW24: 0 | CX24: 0 | CY24: 0 | CZ24: =SUM(CT24:CY24) -> 0 | DA24: 29 | DB24: 23 | DC24: 0 | DD24: 0 | DE24: 0 | DF24: =SUM(DB24:DE24) -> 23 | DG24: 0 | DH24: 0 | DI24: 0 | DJ24: 0 | DK24: 23 | DL24: 0 | DM24: =SUM(DG24:DL24) -> 23 | DN24: 29 | DO24: 0 | DP24: 0 | DQ24: 0 | DR24: 0 | DS24: 0 | DT24: 0 | DU24: 0 | DV24: 0 | DW24: 0 | DX24: 0 | DY24: 0 | DZ24: =SUM(DT24:DY24) -> 0 | EA24: 29 | EB24: 0 | EC24: 0 | ED24: 0 | EE24: 0 | EF24: =SUM(EB24:EE24) -> 0 | EG24: 0 | EH24: 0 | EI24: 0 | EJ24: 0 | EK24: 0 | EL24: 0 | EM24: =SUM(EG24:EL24) -> 0 | EN24: 29 | EO24: 0 | EP24: 0 | EQ24: 0 | ER24: 0 | ES24: =SUM(EO24:ER24) -> 0 | ET24: 0 | EU24: 0 | EV24: 0 | EW24: 0 | EX24: 0 | EY24: 0 | EZ24: =SUM(ET24:EY24) -> 0 | FA24: أمراض الجهاز التناسلي عند الرجال | FB24: 29 | FC24: =B24+O24+AB24+AO24+BB24+BO24+CB24+CO24+DB24+DO24+EB24+EO24 -> 104 | FD24: =C24+P24+AC24+AP24+BC24+BP24+CC24+CP24+DC24+DP24+EC24+EP24 -> 0 | FE24: =D24+Q24+AD24+AQ24+BD24+BQ24+CD24+CQ24+DD24+DQ24+ED24+EQ24 -> 16 | FF24: =E24+R24+AE24+AR24+BE24+BR24+CE24+CR24+DE24+DR24+EE24+ER24 -> 0 | FG24: =SUM(FC24:FF24) -> 120 | FH24: =G24+T24+AG24+AT24+BG24+BT24+CG24+CT24+DG24+DT24+EG24+ET24 -> 0 | FI24: =H24+U24+AH24+AU24+BH24+BU24+CH24+CU24+DH24+DU24+EH24+EU24 -> 0 | FJ24: =I24+V24+AI24+AV24+BI24+BV24+CI24+CV24+DI24+DV24+EI24+EV24 -> 0 | FK24: =J24+W24+AJ24+AW24+BJ24+BW24+CJ24+CW24+DJ24+DW24+EJ24+EW24 -> 45 | FL24: =K24+X24+AK24+AX24+BK24+BX24+CK24+CX24+DK24+DX24+EK24+EX24 -> 67 | FM24: =L24+Y24+AL24+AY24+BL24+BY24+CL24+CY24+DL24+DY24+EL24+EY24 -> 8 | FN24: =SUM(FH24:FM24) -> 120
A25: 30 | B25: 0 | C25: 0 | D25: 0 | E25: 0 | F25: =SUM(B25:E25) -> 0 | G25: 0 | H25: 0 | I25: 0 | J25: 0 | K25: 0 | L25: 0 | M25: =SUM(G25:L25) -> 0 | N25: 30 | O25: 0 | P25: 0 | Q25: 0 | R25: 0 | S25: 0 | T25: 0 | U25: 0 | V25: 0 | W25: 0 | X25: 0 | Y25: 0 | Z25: =SUM(T25:Y25) -> 0 | AA25: 30 | AB25: 0 | AC25: 0 | AD25: 0 | AE25: 0 | AF25: =SUM(AB25:AE25) -> 0 | AG25: 0 | AH25: 0 | AI25: 0 | AJ25: 0 | AK25: 0 | AL25: 0 | AM25: =SUM(AG25:AL25) -> 0 | AN25: 30 | AO25: 121 | AP25: 174 | AQ25: 49 | AR25: 24 | AS25: =SUM(AO25:AR25) -> 368 | AT25: 0 | AU25: 6 | AV25: 23 | AW25: 206 | AX25: 92 | AY25: 41 | AZ25: =SUM(AT25:AY25) -> 368 | BA25: 30 | BB25: 36 | BC25: 20 | BD25: 8 | BE25: 10 | BF25: =SUM(BB25:BE25) -> 74 | BG25: 0 | BH25: 0 | BI25: 21 | BJ25: 23 | BK25: 30 | BL25: 0 | BM25: =SUM(BG25:BL25) -> 74 | BN25: 30 | BO25: 69 | BP25: 84 | BQ25: 23 | BR25: 19 | BS25: 195 | BT25: 6 | BU25: 38 | BV25: 44 | BW25: 57 | BX25: 43 | BY25: 7 | BZ25: =SUM(BT25:BY25) -> 195 | CA25: 30 | CB25: 121 | CC25: 174 | CD25: 49 | CE25: 24 | CF25: =SUM(CB25:CE25) -> 368 | CG25: 0 | CH25: 6 | CI25: 23 | CJ25: 206 | CK25: 92 | CL25: 41 | CM25: =SUM(CG25:CL25) -> 368 | CN25: 30 | CO25: 0 | CP25: 0 | CQ25: 0 | CR25: 0 | CS25: 0 | CT25: 0 | CU25: 0 | CV25: 0 | CW25: 0 | CX25: 0 | CY25: 0 | CZ25: =SUM(CT25:CY25) -> 0 | DA25: 30 | DB25: 11 | DC25: 40 | DD25: 0 | DE25: 0 | DF25: =SUM(DB25:DE25) -> 51 | DG25: 0 | DH25: 0 | DI25: 9 | DJ25: 5 | DK25: 37 | DL25: 0 | DM25: =SUM(DG25:DL25) -> 51 | DN25: 30 | DO25: 0 | DP25: 0 | DQ25: 0 | DR25: 0 | DS25: 0 | DT25: 0 | DU25: 0 | DV25: 0 | DW25: 0 | DX25: 0 | DY25: 0 | DZ25: =SUM(DT25:DY25) -> 0 | EA25: 30 | EB25: 0 | EC25: 0 | ED25: 0 | EE25: 0 | EF25: =SUM(EB25:EE25) -> 0 | EG25: 0 | EH25: 0 | EI25: 0 | EJ25: 0 | EK25: 0 | EL25: 0 | EM25: =SUM(EG25:EL25) -> 0 | EN25: 30 | EO25: 0 | EP25: 0 | EQ25: 0 | ER25: 0 | ES25: =SUM(EO25:ER25) -> 0 | ET25: 0 | EU25: 0 | EV25: 0 | EW25: 0 | EX25: 0 | EY25: 0 | EZ25: =SUM(ET25:EY25) -> 0 | FA25: أمراض الجلد والنسيج الخلوي | FB25: 30 | FC25: =B25+O25+AB25+AO25+BB25+BO25+CB25+CO25+DB25+DO25+EB25+EO25 -> 358 | FD25: =C25+P25+AC25+AP25+BC25+BP25+CC25+CP25+DC25+DP25+EC25+EP25 -> 492 | FE25: =D25+Q25+AD25+AQ25+BD25+BQ25+CD25+CQ25+DD25+DQ25+ED25+EQ25 -> 129 | FF25: =E25+R25+AE25+AR25+BE25+BR25+CE25+CR25+DE25+DR25+EE25+ER25 -> 77 | FG25: =SUM(FC25:FF25) -> 1056 | FH25: =G25+T25+AG25+AT25+BG25+BT25+CG25+CT25+DG25+DT25+EG25+ET25 -> 6 | FI25: =H25+U25+AH25+AU25+BH25+BU25+CH25+CU25+DH25+DU25+EH25+EU25 -> 50 | FJ25: =I25+V25+AI25+AV25+BI25+BV25+CI25+CV25+DI25+DV25+EI25+EV25 -> 120 | FK25: =J25+W25+AJ25+AW25+BJ25+BW25+CJ25+CW25+DJ25+DW25+EJ25+EW25 -> 497 | FL25: =K25+X25+AK25+AX25+BK25+BX25+CK25+CX25+DK25+DX25+EK25+EX25 -> 294 | FM25: =L25+Y25+AL25+AY25+BL25+BY25+CL25+CY25+DL25+DY25+EL25+EY25 -> 89 | FN25: =SUM(FH25:FM25) -> 1056
