Workbook

Sheet أسنان 
A1: عيادة الأسنان | F1: شهر | G1: 1 | H1: عام | J1: 1447 | M1: عيادة الأسنان | R1: شهر | S1: 2 | T1: عام | V1: 1447 | Y1: عيادة الأسنان | AD1: شهر | AE1: 3 | AF1: عام | AH1: 1447 | AK1: عيادة الأسنان | AP1: شهر | AQ1: 4 | AR1: عام | AT1: 1447 | AW1: عيادة الأسنان | BB1: شهر | BC1: 5 | BD1: عام | BF1: 1447 | BI1: عيادة الأسنان | BN1: شهر | BO1: 6 | BP1: عام | BR1: 1447 | BU1: عيادة الأسنان | BZ1: شهر | CA1: 7 | CB1: عام | CD1: 1447 | CG1: عيادة الأسنان | CL1: شهر | CM1: 8 | CN1: عام | CP1: 1447 | CS1: عيادة الأسنان | CX1: شهر | CY1: 9 | CZ1: عام | DB1: 1447 | DE1: عيادة الأسنان | DJ1: شهر | DK1: 10 | DL1: عام | DN1: 1447 | DQ1: عيادة الأسنان | DV1: شهر | DW1: 11 | DX1: عام | DZ1: 1447 | EC1: عيادة الأسنان | EH1: شهر | EI1: 12 | EJ1: عام | EL1: 1447 | EO1: عيادة الأسنان | EV1: عام | EX1: 1447
A2: مركز صحي | C2: الربيع والتوفيق | M2: مركز صحي | O2: الربيع والتوفيق | Y2: مركز صحي | AA2: الربيع والتوفيق | AK2: مركز صحي | AM2: الربيع والتوفيق | AW2: مركز صحي | AY2: الربيع والتوفيق | BI2: مركز صحي | BK2: الربيع والتوفيق | BU2: مركز صحي | BW2: الربيع والتوفيق | CG2: مركز صحي | CI2: الربيع والتوفيق | CS2: مركز صحي | CU2: الربيع والتوفيق | DE2: مركز صحي | DG2: الربيع والتوفيق | DQ2: مركز صحي | DS2: الربيع والتوفيق | EC2: مركز صحي | EE2: الربيع والتوفيق | EO2: مركز صحي | EQ2: =EE2 -> الربيع والتوفيق
A3: نوع الخدمة | F3: عدد المراجعين | I3: بالغين | J3: ذكور | K3: 147 | M3: نوع الخدمة | R3: عدد المراجعين | U3: بالغين | V3: ذكور | W3: 97 | Y3: نوع الخدمة | AD3: عدد المراجعين | AG3: بالغين | AH3: ذكور | AI3: 78 | AK3: نوع الخدمة | AP3: عدد المراجعين | AS3: بالغين | AT3: ذكور | AU3: 151 | AW3: نوع الخدمة | BB3: عدد المراجعين | BE3: بالغين | BF3: ذكور | BG3: 126 | BI3: نوع الخدمة | BN3: عدد المراجعين | BQ3: بالغين | BR3: ذكور | BS3: 62 | BU3: نوع الخدمة | BZ3: عدد المراجعين | CC3: بالغين | CD3: ذكور | CE3: 154 | CG3: نوع الخدمة | CL3: عدد المراجعين | CO3: بالغين | CP3: ذكور | CQ3: 62 | CS3: نوع الخدمة | CX3: عدد المراجعين | DA3: بالغين | DB3: ذكور | DC3: 0 | DE3: نوع الخدمة | DJ3: عدد المراجعين | DM3: بالغين | DN3: ذكور | DO3: 0 | DQ3: نوع الخدمة | DV3: عدد المراجعين | DY3: بالغين | DZ3: ذكور | EA3: 0 | EC3: نوع الخدمة | EH3: عدد المراجعين | EK3: بالغين | EL3: ذكور | EM3: 0 | EO3: نوع الخدمة | ET3: عدد المراجعين | EW3: بالغين | EX3: ذكور | EY3: =K3+W3+AI3+AU3+BG3+BS3+CE3+CQ3+DC3+DO3+EA3+EM3 -> 877
A4: الأشعة | D4: إطباقية | F4: 0 | M4: الأشعة | P4: إطباقية | R4: 0 | Y4: الأشعة | AB4: إطباقية | AD4: 0 | AK4: الأشعة | AN4: إطباقية | AP4: 0 | AW4: الأشعة | AZ4: إطباقية | BB4: 0 | BI4: الأشعة | BL4: إطباقية | BN4: 0 | BU4: الأشعة | BX4: إطباقية | BZ4: 0 | CG4: الأشعة | CJ4: إطباقية | CL4: 0 | CS4: الأشعة | CV4: إطباقية | CX4: 0 | DE4: الأشعة | DH4: إطباقية | DJ4: 0 | DQ4: الأشعة | DT4: إطباقية | DV4: 0 | EC4: الأشعة | EF4: إطباقية | EH4: 0 | EO4: الأشعة | ER4: إطباقية | ET4: =F4+R4+AD4+AP4+BB4+BN4+BZ4+CL4+CX4+DJ4+DV4+EH4 -> 0
D5: ذروية | F5: 11 | J5: إناث | K5: 201 | P5: ذروية | R5: 19 | V5: إناث | W5: 148 | AB5: ذروية | AD5: 0 | AH5: إناث | AI5: 109 | AN5: ذروية | AP5: 0 | AT5: إناث | AU5: 201 | AZ5: ذروية | BB5: 0 | BF5: إناث | BG5: 184 | BL5: ذروية | BR5: إناث | BS5: 83 | BX5: ذروية | BZ5: 17 | CD5: إناث | CE5: 232 | CJ5: ذروية | CL5: 17 | CP5: إناث | CQ5: 83 | CV5: ذروية | CX5: 0 | DB5: إناث | DC5: 0 | DH5: ذروية | DJ5: 0 | DN5: إناث | DO5: 0 | DT5: ذروية | DV5: 0 | DZ5: إناث | EA5: 0 | EF5: ذروية | EH5: 0 | EL5: إناث | EM5: 0 | ER5: ذروية | ET5: =F5+R5+AD5+AP5+BB5+BN5+BZ5+CL5+CX5+DJ5+DV5+EH5 -> 64 | EX5: إناث | EY5: =K5+W5+AI5+AU5+BG5+BS5+CE5+CQ5+DC5+DO5+EA5+EM5 -> #VALUE!
D6: خارج الفم | F6: 0 | P6: خارج الفم | R6: 0 | AB6: خارج الفم | AD6: 10 | AN6: خارج الفم | AP6: 0 | AZ6: خارج الفم | BB6: 30 | BL6: خارج الفم | BN6: 0 | BX6: خارج الفم | BZ6: 0 | CJ6: خارج الفم | CL6: 0 | CV6: خارج الفم | CX6: 0 | DH6: خارج الفم | DJ6: 0 | DT6: خارج الفم | DV6: 0 | EF6: خارج الفم | EH6: 0 | ER6: خارج الفم | ET6: =F6+R6+AD6+AP6+BB6+BN6+BZ6+CL6+CX6+DJ6+DV6+EH6 -> 40
A7: الإجراءات العلاجية | B7: الخلع | D7: لبني | F7: 40 | I7: أطفال | J7: ذكور | K7: 35 | M7: الإجراءات العلاجية | N7: الخلع | P7: لبني | R7: 11 | U7: أطفال | V7: ذكور | W7: 26 | Y7: الإجراءات العلاجية | Z7: الخلع | AB7: لبني | AD7: 30 | AG7: أطفال | AH7: ذكور | AI7: 18 | AK7: الإجراءات العلاجية | AL7: الخلع | AN7: لبني | AP7: 29 | AS7: أطفال | AT7: ذكور | AU7: 68 | AW7: الإجراءات العلاجية | AX7: الخلع | AZ7: لبني | BB7: 39 | BE7: أطفال | BF7: ذكور | BG7: 59 | BI7: الإجراءات العلاجية | BJ7: الخلع | BL7: لبني | BN7: 0 | BQ7: أطفال | BR7: ذكور | BS7: 16 | BU7: الإجراءات العلاجية | BV7: الخلع | BX7: لبني | BZ7: 27 | CC7: أطفال | CD7: ذكور | CE7: 19 | CG7: الإجراءات العلاجية | CH7: الخلع | CJ7: لبني | CL7: 0 | CO7: أطفال | CP7: ذكور | CQ7: 16 | CS7: الإجراءات العلاجية | CT7: الخلع | CV7: لبني | CX7: 0 | DA7: أطفال | DB7: ذكور | DC7: 0 | DE7: الإجراءات العلاجية | DF7: الخلع | DH7: لبني | DJ7: 0 | DM7: أطفال | DN7: ذكور | DO7: 0 | DQ7: الإجراءات العلاجية | DR7: الخلع | DT7: لبني | DV7: 0 | DY7: أطفال | DZ7: ذكور | EA7: 0 | EC7: الإجراءات العلاجية | ED7: الخلع | EF7: لبني | EH7: 0 | EK7: أطفال | EL7: ذكور | EM7: 0 | EO7: الإجراءات العلاجية | EP7: الخلع | ER7: لبني | ET7: =F7+R7+AD7+AP7+BB7+BN7+BZ7+CL7+CX7+DJ7+DV7+EH7 -> 176 | EW7: أطفال | EX7: ذكور | EY7: =K7+W7+AI7+AU7+BG7+BS7+CE7+CQ7+DC7+DO7+EA7+EM7 -> 257
D8: دائم | F8: 0 | P8: دائم | R8: 2 | AB8: دائم | AD8: 12 | AN8: دائم | AP8: 3 | AZ8: دائم | BB8: 31 | BL8: دائم | BN8: 9 | BX8: دائم | BZ8: 6 | CJ8: دائم | CL8: 9 | CV8: دائم | CX8: 0 | DH8: دائم | DJ8: 0 | DT8: دائم | DV8: 0 | EF8: دائم | EH8: 0 | ER8: دائم | ET8: =F8+R8+AD8+AP8+BB8+BN8+BZ8+CL8+CX8+DJ8+DV8+EH8 -> 72
D9: جراحي | F9: 0 | J9: إناث | K9: 60 | P9: جراحي | R9: 0 | V9: إناث | W9: 71 | AB9: جراحي | AD9: 0 | AH9: إناث | AI9: 31 | AN9: جراحي | AP9: 0 | AT9: إناث | AU9: 73 | AZ9: جراحي | BB9: 0 | BF9: إناث | BG9: 71 | BL9: جراحي | BN9: 0 | BR9: إناث | BS9: 30 | BX9: جراحي | BZ9: 0 | CD9: إناث | CE9: 33 | CJ9: جراحي | CL9: 0 | CP9: إناث | CQ9: 30 | CV9: جراحي | CX9: 0 | DB9: إناث | DC9: 0 | DH9: جراحي | DJ9: 0 | DN9: إناث | DO9: 0 | DT9: جراحي | DV9: 0 | DZ9: إناث | EA9: 0 | EF9: جراحي | EH9: 0 | EL9: إناث | EM9: 0 | ER9: جراحي | ET9: =F9+R9+AD9+AP9+BB9+BN9+BZ9+CL9+CX9+DJ9+DV9+EH9 -> 0 | EX9: إناث | EY9: =K9+W9+AI9+AU9+BG9+BS9+CE9+CQ9+DC9+DO9+EA9+EM9 -> 399
B10: الجراحة | D10: جراحة | F10: 0 | N10: الجراحة | P10: جراحة | R10: 0 | Z10: الجراحة | AB10: جراحة | AD10: 0 | AL10: الجراحة | AN10: جراحة | AP10: 0 | AX10: الجراحة | AZ10: جراحة | BB10: 0 | BJ10: الجراحة | BL10: جراحة | BN10: 0 | BV10: الجراحة | BX10: جراحة | BZ10: 0 | CH10: الجراحة | CJ10: جراحة | CL10: 0 | CT10: الجراحة | CV10: جراحة | CX10: 0 | DF10: الجراحة | DH10: جراحة | DJ10: 0 | DR10: الجراحة | DT10: جراحة | DV10: 0 | ED10: الجراحة | EF10: جراحة | EH10: 0 | EP10: الجراحة | ER10: جراحة | ET10: =F10+R10+AD10+AP10+BB10+BN10+BZ10+CL10+CX10+DJ10+DV10+EH10 -> 0
D11: متابعة | F11: 0 | I11: المجموع | K11: =SUM(K3:K10) -> 242 | P11: متابعة | R11: 0 | U11: المجموع | W11: =SUM(W3:W10) -> 342 | AB11: متابعة | AD11: 0 | AG11: المجموع | AI11: =SUM(AI3:AI10) -> 236 | AN11: متابعة | AP11: 0 | AS11: المجموع | AU11: =SUM(AU3:AU10) -> 493 | AZ11: متابعة | BB11: 0 | BE11: المجموع | BG11: =SUM(BG3:BG10) -> 440 | BL11: متابعة | BN11: 0 | BQ11: المجموع | BS11: =SUM(BS3:BS10) -> 191 | BX11: متابعة | BZ11: 0 | CC11: المجموع | CE11: =SUM(CE3:CE10) -> 438 | CJ11: متابعة | CL11: 0 | CO11: المجموع | CQ11: =SUM(CQ3:CQ10) -> 191 | CV11: متابعة | CX11: 0 | DA11: المجموع | DC11: =SUM(DC3:DC10) -> 0 | DH11: متابعة | DJ11: 0 | DM11: المجموع | DO11: =SUM(DO3:DO10) -> 0 | DT11: متابعة | DV11: 0 | DY11: المجموع | EA11: =SUM(EA3:EA10) -> 0 | EF11: متابعة | EH11: 0 | EK11: المجموع | EM11: =SUM(EM3:EM10) -> 0 | ER11: متابعة | ET11: =F11+R11+AD11+AP11+BB11+BN11+BZ11+CL11+CX11+DJ11+DV11+EH11 -> 0 | EW11: المجموع | EY11: =SUM(EY3:EY10) -> #VALUE!
B12: الحشو | D12: مؤقت | F12: 18 | N12: الحشو | P12: مؤقت | R12: 11 | Z12: الحشو | AB12: مؤقت | AD12: 21 | AL12: الحشو | AN12: مؤقت | AP12: 12 | AX12: الحشو | AZ12: مؤقت | BB12: 16 | BJ12: الحشو | BL12: مؤقت | BN12: 5 | BV12: الحشو | BX12: مؤقت | BZ12: 11 | CH12: الحشو | CJ12: مؤقت | CL12: 5 | CT12: الحشو | CV12: مؤقت | CX12: 0 | DF12: الحشو | DH12: مؤقت | DJ12: 0 | DR12: الحشو | DT12: مؤقت | DV12: 0 | ED12: الحشو | EF12: مؤقت | EH12: 0 | EP12: الحشو | ER12: مؤقت | ET12: =F12+R12+AD12+AP12+BB12+BN12+BZ12+CL12+CX12+DJ12+DV12+EH12 -> 99
D13: أملجم | F13: 0 | P13: أملجم | R13: 0 | AB13: أملجم | AD13: 0 | AN13: أملجم | AP13: 0 | AZ13: أملجم | BB13: 0 | BL13: أملجم | BN13: 0 | BX13: أملجم | BZ13: 0 | CJ13: أملجم | CL13: 0 | CV13: أملجم | CX13: 0 | DH13: أملجم | DJ13: 0 | DT13: أملجم | DV13: 0 | EF13: أملجم | EH13: 0 | ER13: أملجم | ET13: =F13+R13+AD13+AP13+BB13+BN13+BZ13+CL13+CX13+DJ13+DV13+EH13 -> 0
D14: كومبوزيت | F14: 40 | I14: سعودي | K14: 443 | P14: كومبوزيت | R14: 35 | U14: سعودي | W14: 342 | AB14: كومبوزيت | AD14: 35 | AG14: سعودي | AI14: 236 | AN14: كومبوزيت | AP14: 122 | AS14: سعودي | AU14: 493 | AZ14: كومبوزيت | BB14: 51 | BE14: سعودي | BG14: 130 | BL14: كومبوزيت | BN14: 34 | BQ14: سعودي | BS14: 191 | BX14: كومبوزيت | BZ14: 37 | CC14: سعودي | CE14: 438 | CJ14: كومبوزيت | CL14: 34 | CO14: سعودي | CQ14: 191 | CV14: كومبوزيت | CX14: 0 | DA14: سعودي | DC14: 0 | DH14: كومبوزيت | DJ14: 0 | DM14: سعودي | DO14: 0 | DT14: كومبوزيت | DV14: 0 | DY14: سعودي | EA14: 0 | EF14: كومبوزيت | EH14: 0 | EK14: سعودي | EM14: 0 | ER14: كومبوزيت | ET14: =F14+R14+AD14+AP14+BB14+BN14+BZ14+CL14+CX14+DJ14+DV14+EH14 -> 388 | EW14: سعودي | EY14: =K14+W14+AI14+AU14+BG14+BS14+CE14+CQ14+DC14+DO14+EA14+EM14 -> 2464
D15: لا ينومر زجاج | F15: 96 | P15: لا ينومر زجاج | R15: 41 | AB15: لا ينومر زجاج | AD15: 122 | AN15: لا ينومر زجاج | AP15: 95 | AZ15: لا ينومر زجاج | BB15: 72 | BL15: لا ينومر زجاج | BN15: 47 | BX15: لا ينومر زجاج | BZ15: 86 | CJ15: لا ينومر زجاج | CL15: 47 | CV15: لا ينومر زجاج | CX15: 0 | DH15: لا ينومر زجاج | DJ15: 0 | DT15: لا ينومر زجاج | DV15: 0 | EF15: لا ينومر زجاج | EH15: 0 | ER15: لا ينومر زجاج | ET15: =F15+R15+AD15+AP15+BB15+BN15+BZ15+CL15+CX15+DJ15+DV15+EH15 -> 606
B16: علاج العصب | D16: لبني | F16: 0 | N16: علاج العصب | P16: لبني | R16: 0 | Z16: علاج العصب | AB16: لبني | AD16: 4 | AL16: علاج العصب | AN16: لبني | AP16: 0 | AX16: علاج العصب | AZ16: لبني | BB16: 2 | BJ16: علاج العصب | BL16: لبني | BN16: 0 | BV16: علاج العصب | BX16: لبني | BZ16: 0 | CH16: علاج العصب | CJ16: لبني | CL16: 0 | CT16: علاج العصب | CV16: لبني | CX16: 0 | DF16: علاج العصب | DH16: لبني | DJ16: 0 | DR16: علاج العصب | DT16: لبني | DV16: 0 | ED16: علاج العصب | EF16: لبني | EH16: 0 | EP16: علاج العصب | ER16: لبني | ET16: =F16+R16+AD16+AP16+BB16+BN16+BZ16+CL16+CX16+DJ16+DV16+EH16 -> 6
D17: تهيئة | F17: 17 | I17: غير سعودي | K17: 0 | P17: تهيئة | R17: 2 | U17: غير سعودي | W17: 0 | AB17: تهيئة | AD17: 21 | AG17: غير سعودي | AI17: 0 | AN17: تهيئة | AP17: 31 | AS17: غير سعودي | AU17: 0 | AZ17: تهيئة | BB17: 23 | BE17: غير سعودي | BG17: 310 | BL17: تهيئة | BN17: 11 | BQ17: غير سعودي | BS17: 0 | BX17: تهيئة | BZ17: 12 | CC17: غير سعودي | CE17: 0 | CJ17: تهيئة | CL17: 11 | CO17: غير سعودي | CQ17: 0 | CV17: تهيئة | CX17: 0 | DA17: غير سعودي | DC17: 0 | DH17: تهيئة | DJ17: 0 | DM17: غير سعودي | DO17: 0 | DT17: تهيئة | DV17: 0 | DY17: غير سعودي | EA17: 0 | EF17: تهيئة | EH17: 0 | EK17: غير سعودي | EM17: 0 | ER17: تهيئة | ET17: =F17+R17+AD17+AP17+BB17+BN17+BZ17+CL17+CX17+DJ17+DV17+EH17 -> 128 | EW17: غير سعودي | EY17: =K17+W17+AI17+AU17+BG17+BS17+CE17+CQ17+DC17+DO17+EA17+EM17 -> 310
D18: حشو | F18: 0 | P18: حشو | R18: 0 | AB18: حشو | AD18: 0 | AN18: حشو | AP18: 0 | AZ18: حشو | BB18: 0 | BL18: حشو | BN18: 0 | BX18: حشو | BZ18: 0 | CJ18: حشو | CL18: 0 | CV18: حشو | CX18: 0 | DH18: حشو | DJ18: 0 | DT18: حشو | DV18: 0 | EF18: حشو | EH18: 0 | ER18: حشو | ET18: =F18+R18+AD18+AP18+BB18+BN18+BZ18+CL18+CX18+DJ18+DV18+EH18 -> 0
B19: علاج اللثة | D19: كحت جير | F19: 0 | N19: علاج اللثة | P19: كحت جير | R19: 9 | Z19: علاج اللثة | AB19: كحت جير | AD19: 28 | AL19: علاج اللثة | AN19: كحت جير | AP19: 60 | AX19: علاج اللثة | AZ19: كحت جير | BB19: 44 | BJ19: علاج اللثة | BL19: كحت جير | BN19: 0 | BV19: علاج اللثة | BX19: كحت جير | BZ19: 12 | CH19: علاج اللثة | CJ19: كحت جير | CL19: 0 | CT19: علاج اللثة | CV19: كحت جير | CX19: 0 | DF19: علاج اللثة | DH19: كحت جير | DJ19: 0 | DR19: علاج اللثة | DT19: كحت جير | DV19: 0 | ED19: علاج اللثة | EF19: كحت جير | EH19: 0 | EP19: علاج اللثة | ER19: كحت جير | ET19: =F19+R19+AD19+AP19+BB19+BN19+BZ19+CL19+CX19+DJ19+DV19+EH19 -> 153
D20: جراحة لثة | F20: 0 | K20: =SUM(K14:K19) -> 443 | P20: جراحة لثة | R20: 0 | W20: =SUM(W14:W19) -> 342 | AB20: جراحة لثة | AD20: 0 | AI20: =SUM(AI14:AI19) -> 236 | AN20: جراحة لثة | AP20: 0 | AU20: =SUM(AU14:AU19) -> 493 | AZ20: جراحة لثة | BB20: 0 | BG20: =SUM(BG14:BG19) -> 440 | BL20: جراحة لثة | BN20: 0 | BS20: =SUM(BS14:BS19) -> 191 | BX20: جراحة لثة | BZ20: 0 | CE20: =SUM(CE14:CE19) -> 438 | CJ20: جراحة لثة | CL20: 0 | CQ20: =SUM(CQ14:CQ19) -> 191 | CV20: جراحة لثة | CX20: 0 | DC20: =SUM(DC14:DC19) -> 0 | DH20: جراحة لثة | DJ20: 0 | DO20: =SUM(DO14:DO19) -> 0 | DT20: جراحة لثة | DV20: 0 | EA20: =SUM(EA14:EA19) -> 0 | EF20: جراحة لثة | EH20: 0 | EM20: =SUM(EM14:EM19) -> 0 | ER20: جراحة لثة | ET20: =F20+R20+AD20+AP20+BB20+BN20+BZ20+CL20+CX20+DJ20+DV20+EH20 -> 0 | EY20: =SUM(EY14:EY19) -> 2774
B21: أمراض الفم | F21: 0 | I21: جديد | K21: 110 | N21: أمراض الفم | R21: 0 | U21: جديد | W21: 55 | Z21: أمراض الفم | AD21: 0 | AG21: جديد | AI21: 96 | AL21: أمراض الفم | AP21: 0 | AS21: جديد | AU21: 140 | AX21: أمراض الفم | BB21: 0 | BE21: جديد | BG21: 0 | BJ21: أمراض الفم | BN21: 0 | BQ21: جديد | BS21: 191 | BV21: أمراض الفم | BZ21: 0 | CC21: جديد | CE21: 80 | CH21: أمراض الفم | CL21: 0 | CO21: جديد | CQ21: 145 | CT21: أمراض الفم | CX21: 0 | DA21: جديد | DC21: 0 | DF21: أمراض الفم | DJ21: 0 | DM21: جديد | DO21: 0 | DR21: أمراض الفم | DV21: 0 | DY21: جديد | EA21: 0 | ED21: أمراض الفم | EH21: 0 | EK21: جديد | EM21: 0 | EP21: أمراض الفم | ET21: =F21+R21+AD21+AP21+BB21+BN21+BZ21+CL21+CX21+DJ21+DV21+EH21 -> 0 | EW21: جديد | EY21: =K21+W21+AI21+AU21+BG21+BS21+CE21+CQ21+DC21+DO21+EA21+EM21 -> 817
A22: الإجراءات الوقائية | D22: توعية صحية | F22: 443 | M22: الإجراءات الوقائية | P22: توعية صحية | R22: 342 | Y22: الإجراءات الوقائية | AB22: توعية صحية | AD22: 245 | AK22: الإجراءات الوقائية | AN22: توعية صحية | AP22: 493 | AW22: الإجراءات الوقائية | AZ22: توعية صحية | BB22: 440 | BI22: الإجراءات الوقائية | BL22: توعية صحية | BN22: 191 | BU22: الإجراءات الوقائية | BX22: توعية صحية | BZ22: 438 | CG22: الإجراءات الوقائية | CJ22: توعية صحية | CL22: 191 | CS22: الإجراءات الوقائية | CV22: توعية صحية | CX22: 0 | DE22: الإجراءات الوقائية | DH22: توعية صحية | DJ22: 0 | DQ22: الإجراءات الوقائية | DT22: توعية صحية | DV22: 0 | EC22: الإجراءات الوقائية | EF22: توعية صحية | EH22: 0 | EO22: الإجراءات الوقائية | ER22: توعية صحية | ET22: =F22+R22+AD22+AP22+BB22+BN22+BZ22+CL22+CX22+DJ22+DV22+EH22 -> 2783
D23: رعاية حوامل | F23: 0 | P23: رعاية حوامل | R23: 0 | AB23: رعاية حوامل | AD23: 0 | AN23: رعاية حوامل | AP23: 0 | AZ23: رعاية حوامل | BB23: 12 | BL23: رعاية حوامل | BN23: 0 | BX23: رعاية حوامل | BZ23: 0 | CJ23: رعاية حوامل | CL23: 0 | CV23: رعاية حوامل | CX23: 0 | DH23: رعاية حوامل | DJ23: 0 | DT23: رعاية حوامل | DV23: 0 | EF23: رعاية حوامل | EH23: 0 | ER23: رعاية حوامل | ET23: =F23+R23+AD23+AP23+BB23+BN23+BZ23+CL23+CX23+DJ23+DV23+EH23 -> 12
D24: حشو الحفر | F24: 0 | I24: متابعة | K24: 333 | P24: حشو الحفر | R24: 2 | U24: متابعة | W24: 287 | AB24: حشو الحفر | AD24: 3 | AG24: متابعة | AI24: 140 | AN24: حشو الحفر | AP24: 3 | AS24: متابعة | AU24: 353 | AZ24: حشو الحفر | BB24: 2 | BE24: متابعة | BG24: 0 | BL24: حشو الحفر | BN24: 0 | BQ24: متابعة | BS24: 0 | BX24: حشو الحفر | BZ24: 11 | CC24: متابعة | CE24: 358 | CJ24: حشو الحفر | CL24: 0 | CO24: متابعة | CQ24: 46 | CV24: حشو الحفر | CX24: 0 | DA24: متابعة | DC24: 0 | DH24: حشو الحفر | DJ24: 0 | DM24: متابعة | DO24: 0 | DT24: حشو الحفر | DV24: 0 | DY24: متابعة | EA24: 0 | EF24: حشو الحفر | EH24: 0 | EK24: متابعة | EM24: 0 | ER24: حشو الحفر | ET24: =F24+R24+AD24+AP24+BB24+BN24+BZ24+CL24+CX24+DJ24+DV24+EH24 -> 21 | EW24: متابعة | EY24: =K24+W24+AI24+AU24+BG24+BS24+CE24+CQ24+DC24+DO24+EA24+EM24 -> 1517
D25: فلوريد موضعي | F25: 0 | P25: فلوريد موضعي | R25: 4 | AB25: فلوريد موضعي | AD25: 13 | AN25: فلوريد موضعي | AP25: 24 | AZ25: فلوريد موضعي | BB25: 21 | BL25: فلوريد موضعي | BN25: 0 | BX25: فلوريد موضعي | BZ25: 14 | CJ25: فلوريد موضعي | CL25: 0 | CV25: فلوريد موضعي | CX25: 0 | DH25: فلوريد موضعي | DJ25: 0 | DT25: فلوريد موضعي | DV25: 0 | EF25: فلوريد موضعي | EH25: 0 | ER25: فلوريد موضعي | ET25: =F25+R25+AD25+AP25+BB25+BN25+BZ25+CL25+CX25+DJ25+DV25+EH25 -> 76
A26: أدوية منصرفة | B26: =1 -> 1 | C26: 2 | D26: 3 | E26: 4 | F26: 5 | G26: 6 | M26: أدوية منصرفة | N26: =1 -> 1 | O26: 2 | P26: 3 | Q26: 4 | R26: 5 | S26: 6 | Y26: أدوية منصرفة | Z26: =1 -> 1 | AA26: 2 | AB26: 3 | AC26: 4 | AD26: 5 | AE26: 6 | AK26: أدوية منصرفة | AL26: =1 -> 1 | AM26: 2 | AN26: 3 | AO26: 4 | AP26: 5 | AQ26: 6 | AW26: أدوية منصرفة | AX26: =1 -> 1 | AY26: 2 | AZ26: 3 | BA26: 4 | BB26: 5 | BC26: 6 | BI26: أدوية منصرفة | BJ26: =1 -> 1 | BK26: 2 | BL26: 3 | BM26: 4 | BN26: 5 | BO26: 6 | BU26: أدوية منصرفة | BV26: =1 -> 1 | BW26: 2 | BX26: 3 | BY26: 4 | BZ26: 5 | CA26: 6 | CG26: أدوية منصرفة | CH26: =1 -> 1 | CI26: 2 | CJ26: 3 | CK26: 4 | CL26: 5 | CM26: 6 | CS26: أدوية منصرفة | CT26: =1 -> 1 | CU26: 2 | CV26: 3 | CW26: 4 | CX26: 5 | CY26: 6 | DE26: أدوية منصرفة | DF26: =1 -> 1 | DG26: 2 | DH26: 3 | DI26: 4 | DJ26: 5 | DK26: 6 | DQ26: أدوية منصرفة | DR26: =1 -> 1 | DS26: 2 | DT26: 3 | DU26: 4 | DV26: 5 | DW26: 6 | EC26: أدوية منصرفة | ED26: =1 -> 1 | EE26: 2 | EF26: 3 | EG26: 4 | EH26: 5 | EI26: 6 | EO26: أدوية منصرفة | EP26: =1 -> 1 | EQ26: 2 | ER26: 3 | ES26: 4 | ET26: 5 | EU26: 6
B27: 30 | C27: 55 | D27: 0 | E27: 0 | F27: 0 | G27: 0 | K27: =SUM(K21:K26) -> 443 | N27: 45 | O27: 17 | P27: 34 | Q27: 0 | R27: 0 | S27: 0 | W27: =SUM(W21:W26) -> 342 | Z27: مضاد | AA27: غسول | AB27: مسكن | AC27: 0 | AD27: 0 | AE27: 0 | AI27: =SUM(AI21:AI26) -> 236 | AL27: 57 | AM27: 94 | AN27: 0 | AO27: 0 | AP27: 0 | AQ27: 0 | AU27: =SUM(AU21:AU26) -> 493 | AX27: 45 | AY27: 60 | AZ27: 14 | BA27: 0 | BB27: 0 | BC27: 0 | BG27: =SUM(BG21:BG26) -> 0 | BJ27: 6 | BK27: 10 | BL27: 3 | BM27: 0 | BN27: 0 | BO27: 0 | BS27: =SUM(BS21:BS26) -> 191 | BV27: 18 | BW27: 48 | BX27: 6 | BY27: 0 | BZ27: 0 | CA27: 0 | CE27: =SUM(CE21:CE26) -> 438 | CH27: 6 | CI27: 10 | CJ27: 3 | CK27: 0 | CL27: 0 | CM27: 0 | CQ27: =SUM(CQ21:CQ26) -> 191 | CT27: 0 | CU27: 0 | CV27: 0 | CW27: 0 | CX27: 0 | CY27: 0 | DC27: =SUM(DC21:DC26) -> 0 | DF27: 0 | DG27: 0 | DH27: 0 | DI27: 0 | DJ27: 0 | DK27: 0 | DO27: =SUM(DO21:DO26) -> 0 | DR27: 0 | DS27: 0 | DT27: 0 | DU27: 0 | DV27: 0 | DW27: 0 | EA27: =SUM(EA21:EA26) -> 0 | ED27: 0 | EE27: 0 | EF27: 0 | EG27: 0 | EH27: 0 | EI27: 0 | EM27: =SUM(EM21:EM26) -> 0 | EP27: =B27+N27+Z27+AL27+AX27+BJ27+BV27+CH27+CT27+DF27+DR27+ED27 -> #VALUE! | EQ27: =C27+O27+AA27+AM27+AY27+BK27+BW27+CI27+CU27+DG27+DS27+EE27 -> #VALUE! | ER27: =D27+P27+AB27+AN27+AZ27+BL27+BX27+CJ27+CV27+DH27+DT27+EF27 -> #VALUE! | ES27: =E27+Q27+AC27+AO27+BA27+BM27+BY27+CK27+CW27+DI27+DU27+EG27 -> 0 | ET27: =F27+R27+AD27+AP27+BB27+BN27+BZ27+CL27+CX27+DJ27+DV27+EH27 -> 0 | EU27: =G27+S27+AE27+AQ27+BC27+BO27+CA27+CM27+CY27+DK27+DW27+EI27 -> 0 | EY27: =SUM(EY21:EY26) -> 2334
A28: مركز صحي | C28: الجامعة | M28: مركز صحي | O28: الجامعة | Y28: مركز صحي | AA28: الجامعة | AK28: مركز صحي | AM28: الجامعة | AW28: مركز صحي | AY28: الجامعة | BI28: مركز صحي | BK28: الجامعة | BU28: مركز صحي | BW28: الجامعة | CG28: مركز صحي | CI28: الجامعة | CS28: مركز صحي | CU28: الجامعة | DE28: مركز صحي | DG28: الجامعة | DQ28: مركز صحي | DS28: الجامعة | EC28: مركز صحي | EE28: الجامعة | EO28: مركز صحي | EQ28: =EE28 -> الجامعة
A29: نوع الخدمة | F29: عدد المراجعين | I29: بالغين | J29: ذكور | K29: 93 | M29: نوع الخدمة | R29: عدد المراجعين | U29: بالغين | V29: ذكور | W29: 87 | Y29: نوع الخدمة | AD29: عدد المراجعين | AG29: بالغين | AH29: ذكور | AI29: 60 | AK29: نوع الخدمة | AP29: عدد المراجعين | AS29: بالغين | AT29: ذكور | AU29: 121 | AW29: نوع الخدمة | BB29: عدد المراجعين | BE29: بالغين | BF29: ذكور | BG29: 60 | BI29: نوع الخدمة | BN29: عدد المراجعين | BQ29: بالغين | BR29: ذكور | BS29: 514 | BU29: نوع الخدمة | BZ29: عدد المراجعين | CC29: بالغين | CD29: ذكور | CE29: 85 | CG29: نوع الخدمة | CL29: عدد المراجعين | CO29: بالغين | CP29: ذكور | CQ29: 514 | CS29: نوع الخدمة | CX29: عدد المراجعين | DA29: بالغين | DB29: ذكور | DC29: 0 | DE29: نوع الخدمة | DJ29: عدد المراجعين | DM29: بالغين | DN29: ذكور | DO29: 0 | DQ29: نوع الخدمة | DV29: عدد المراجعين | DY29: بالغين | DZ29: ذكور | EA29: 0 | EC29: نوع الخدمة | EH29: عدد المراجعين | EK29: بالغين | EL29: ذكور | EM29: 0 | EO29: نوع الخدمة | ET29: عدد المراجعين | EW29: بالغين | EX29: ذكور | EY29: =K29+W29+AI29+AU29+BG29+BS29+CE29+CQ29+DC29+DO29+EA29+EM29 -> 1534
A30: الأشعة | D30: إطباقية | F30: 0 | M30: الأشعة | P30: إطباقية | R30: 0 | Y30: الأشعة | AB30: إطباقية | AD30: 0 | AK30: الأشعة | AN30: إطباقية | AP30: 0 | AW30: الأشعة | AZ30: إطباقية | BB30: 0 | BI30: الأشعة | BL30: إطباقية | BN30: 0 | BU30: الأشعة | BX30: إطباقية | BZ30: 0 | CG30: الأشعة | CJ30: إطباقية | CL30: 0 | CS30: الأشعة | CV30: إطباقية | CX30: 0 | DE30: الأشعة | DH30: إطباقية | DJ30: 0 | DQ30: الأشعة | DT30: إطباقية | DV30: 0 | EC30: الأشعة | EF30: إطباقية | EH30: 0 | EO30: الأشعة | ER30: إطباقية | ET30: =F30+R30+AD30+AP30+BB30+BN30+BZ30+CL30+CX30+DJ30+DV30+EH30 -> 0
D31: ذروية | F31: 0 | J31: إناث | K31: 152 | P31: ذروية | R31: 0 | V31: إناث | W31: 152 | AB31: ذروية | AD31: 15 | AH31: إناث | AI31: 98 | AN31: ذروية | AP31: 13 | AT31: إناث | AU31: 186 | AZ31: ذروية | BB31: 7 | BF31: إناث | BG31: 89 | BL31: ذروية | BN31: 25 | BR31: إناث | BS31: 361 | BX31: ذروية | BZ31: 0 | CD31: إناث | CE31: 173 | CJ31: ذروية | CL31: 25 | CP31: إناث | CQ31: 361 | CV31: ذروية | CX31: 0 | DB31: إناث | DC31: 0 | DH31: ذروية | DJ31: 0 | DN31: إناث | DO31: 0 | DT31: ذروية | DV31: 0 | DZ31: إناث | EA31: 0 | EF31: ذروية | EH31: 0 | EL31: إناث | EM31: 0 | ER31: ذروية | ET31: =F31+R31+AD31+AP31+BB31+BN31+BZ31+CL31+CX31+DJ31+DV31+EH31 -> 85 | EX31: إناث | EY31: =K31+W31+AI31+AU31+BG31+BS31+CE31+CQ31+DC31+DO31+EA31+EM31 -> 1572
D32: خارج الفم | F32: 0 | P32: خارج الفم | R32: 0 | AB32: خارج الفم | AD32: 0 | AN32: خارج الفم | AP32: 0 | AZ32: خارج الفم | BB32: 0 | BL32: خارج الفم | BN32: 0 | BX32: خارج الفم | BZ32: 0 | CJ32: خارج الفم | CL32: 0 | CV32: خارج الفم | CX32: 0 | DH32: خارج الفم | DJ32: 0 | DT32: خارج الفم | DV32: 0 | EF32: خارج الفم | EH32: 0 | ER32: خارج الفم | ET32: =F32+R32+AD32+AP32+BB32+BN32+BZ32+CL32+CX32+DJ32+DV32+EH32 -> 0
A33: الإجراءات العلاجية | B33: الخلع | D33: لبني | F33: 51 | I33: أطفال | J33: ذكور | K33: 14 | M33: الإجراءات العلاجية | N33: الخلع | P33: لبني | R33: 13 | U33: أطفال | V33: ذكور | W33: 26 | Y33: الإجراءات العلاجية | Z33: الخلع | AB33: لبني | AD33: 20 | AG33: أطفال | AH33: ذكور | AI33: 23 | AK33: الإجراءات العلاجية | AL33: الخلع | AN33: لبني | AP33: 48 | AS33: أطفال | AT33: ذكور | AU33: 39 | AW33: الإجراءات العلاجية | AX33: الخلع | AZ33: لبني | BB33: 15 | BE33: أطفال | BF33: ذكور | BG33: 20 | BI33: الإجراءات العلاجية | BJ33: الخلع | BL33: لبني | BN33: 9 | BQ33: أطفال | BR33: ذكور | BS33: 45 | BU33: الإجراءات العلاجية | BV33: الخلع | BX33: لبني | BZ33: 37 | CC33: أطفال | CD33: ذكور | CE33: 44 | CG33: الإجراءات العلاجية | CH33: الخلع | CJ33: لبني | CL33: 9 | CO33: أطفال | CP33: ذكور | CQ33: 45 | CS33: الإجراءات العلاجية | CT33: الخلع | CV33: لبني | CX33: 0 | DA33: أطفال | DB33: ذكور | DC33: 0 | DE33: الإجراءات العلاجية | DF33: الخلع | DH33: لبني | DJ33: 0 | DM33: أطفال | DN33: ذكور | DO33: 0 | DQ33: الإجراءات العلاجية | DR33: الخلع | DT33: لبني | DV33: 0 | DY33: أطفال | DZ33: ذكور | EA33: 0 | EC33: الإجراءات العلاجية | ED33: الخلع | EF33: لبني | EH33: 0 | EK33: أطفال | EL33: ذكور | EM33: 0 | EO33: الإجراءات العلاجية | EP33: الخلع | ER33: لبني | ET33: =F33+R33+AD33+AP33+BB33+BN33+BZ33+CL33+CX33+DJ33+DV33+EH33 -> 202 | EW33: أطفال | EX33: ذكور | EY33: =K33+W33+AI33+AU33+BG33+BS33+CE33+CQ33+DC33+DO33+EA33+EM33 -> 256
D34: دائم | F34: 20 | P34: دائم | R34: 8 | AB34: دائم | AD34: 15 | AN34: دائم | AP34: 26 | AZ34: دائم | BB34: 24 | BL34: دائم | BN34: 45 | BX34: دائم | BZ34: 24 | CJ34: دائم | CL34: 45 | CV34: دائم | CX34: 0 | DH34: دائم | DJ34: 0 | DT34: دائم | DV34: 0 | EF34: دائم | EH34: 0 | ER34: دائم | ET34: =F34+R34+AD34+AP34+BB34+BN34+BZ34+CL34+CX34+DJ34+DV34+EH34 -> 207
D35: جراحي | F35: 0 | J35: إناث | K35: 31 | P35: جراحي | R35: 0 | V35: إناث | W35: 34 | AB35: جراحي | AD35: 0 | AH35: إناث | AI35: 27 | AN35: جراحي | AP35: 0 | AT35: إناث | AU35: 52 | AZ35: جراحي | BB35: 0 | BF35: إناث | BG35: 22 | BL35: جراحي | BN35: 0 | BR35: إناث | BS35: 33 | BX35: جراحي | BZ35: 0 | CD35: إناث | CE35: 40 | CJ35: جراحي | CL35: 0 | CP35: إناث | CQ35: 33 | CV35: جراحي | CX35: 0 | DB35: إناث | DC35: 0 | DH35: جراحي | DJ35: 0 | DN35: إناث | DO35: 0 | DT35: جراحي | DV35: 0 | DZ35: إناث | EA35: 0 | EF35: جراحي | EH35: 0 | EL35: إناث | EM35: 0 | ER35: جراحي | ET35: =F35+R35+AD35+AP35+BB35+BN35+BZ35+CL35+CX35+DJ35+DV35+EH35 -> 0 | EX35: إناث | EY35: =K35+W35+AI35+AU35+BG35+BS35+CE35+CQ35+DC35+DO35+EA35+EM35 -> 272
B36: الجراحة | D36: جراحة | F36: 0 | N36: الجراحة | P36: جراحة | R36: 0 | Z36: الجراحة | AB36: جراحة | AD36: 0 | AL36: الجراحة | AN36: جراحة | AP36: 0 | AX36: الجراحة | AZ36: جراحة | BB36: 0 | BJ36: الجراحة | BL36: جراحة | BN36: 0 | BV36: الجراحة | BX36: جراحة | BZ36: 0 | CH36: الجراحة | CJ36: جراحة | CL36: 0 | CT36: الجراحة | CV36: جراحة | CX36: 0 | DF36: الجراحة | DH36: جراحة | DJ36: 0 | DR36: الجراحة | DT36: جراحة | DV36: 0 | ED36: الجراحة | EF36: جراحة | EH36: 0 | EP36: الجراحة | ER36: جراحة | ET36: =F36+R36+AD36+AP36+BB36+BN36+BZ36+CL36+CX36+DJ36+DV36+EH36 -> 0
D37: متابعة | F37: 0 | I37: المجموع | K37: =SUM(K29:K36) -> 290 | P37: متابعة | R37: 0 | U37: المجموع | W37: =SUM(W29:W36) -> 299 | AB37: متابعة | AD37: 0 | AG37: المجموع | AI37: =SUM(AI29:AI36) -> 208 | AN37: متابعة | AP37: 0 | AS37: المجموع | AU37: =SUM(AU29:AU36) -> 398 | AZ37: متابعة | BB37: 0 | BE37: المجموع | BG37: =SUM(BG29:BG36) -> 191 | BL37: متابعة | BN37: 0 | BQ37: المجموع | BS37: =SUM(BS29:BS36) -> 953 | BX37: متابعة | BZ37: 0 | CC37: المجموع | CE37: =SUM(CE29:CE36) -> 342 | CJ37: متابعة | CL37: 0 | CO37: المجموع | CQ37: =SUM(CQ29:CQ36) -> 953 | CV37: متابعة | CX37: 0 | DA37: المجموع | DC37: =SUM(DC29:DC36) -> 0 | DH37: متابعة | DJ37: 0 | DM37: المجموع | DO37: =SUM(DO29:DO36) -> 0 | DT37: متابعة | DV37: 0 | DY37: المجموع | EA37: =SUM(EA29:EA36) -> 0 | EF37: متابعة | EH37: 0 | EK37: المجموع | EM37: =SUM(EM29:EM36) -> 0 | ER37: متابعة | ET37: =F37+R37+AD37+AP37+BB37+BN37+BZ37+CL37+CX37+DJ37+DV37+EH37 -> 0 | EW37: المجموع | EY37: =SUM(EY29:EY36) -> 3634
B38: الحشو | D38: مؤقت | F38: 24 | N38: الحشو | P38: مؤقت | R38: 28 | Z38: الحشو | AB38: مؤقت | AD38: 15 | AL38: الحشو | AN38: مؤقت | AP38: 36 | AX38: الحشو | AZ38: مؤقت | BB38: 7 | BJ38: الحشو | BL38: مؤقت | BN38: 12 | BV38: الحشو | BX38: مؤقت | BZ38: 32 | CH38: الحشو | CJ38: مؤقت | CL38: 12 | CT38: الحشو | CV38: مؤقت | CX38: 0 | DF38: الحشو | DH38: مؤقت | DJ38: 0 | DR38: الحشو | DT38: مؤقت | DV38: 0 | ED38: الحشو | EF38: مؤقت | EH38: 0 | EP38: الحشو | ER38: مؤقت | ET38: =F38+R38+AD38+AP38+BB38+BN38+BZ38+CL38+CX38+DJ38+DV38+EH38 -> 166
D39: أملجم | F39: 0 | P39: أملجم | R39: 0 | AB39: أملجم | AD39: 0 | AN39: أملجم | AP39: 0 | AZ39: أملجم | BB39: 0 | BL39: أملجم | BN39: 51 | BX39: أملجم | BZ39: 0 | CJ39: أملجم | CL39: 51 | CV39: أملجم | CX39: 0 | DH39: أملجم | DJ39: 0 | DT39: أملجم | DV39: 0 | EF39: أملجم | EH39: 0 | ER39: أملجم | ET39: =F39+R39+AD39+AP39+BB39+BN39+BZ39+CL39+CX39+DJ39+DV39+EH39 -> 102
D40: كومبوزيت | F40: 27 | I40: سعودي | K40: 290 | P40: كومبوزيت | R40: 44 | U40: سعودي | W40: 299 | AB40: كومبوزيت | AD40: 32 | AG40: سعودي | AI40: 208 | AN40: كومبوزيت | AP40: 67 | AS40: سعودي | AU40: 398 | AZ40: كومبوزيت | BB40: 20 | BE40: سعودي | BG40: 191 | BL40: كومبوزيت | BN40: 26 | BQ40: سعودي | BS40: 953 | BX40: كومبوزيت | BZ40: 35 | CC40: سعودي | CE40: 342 | CJ40: كومبوزيت | CL40: 26 | CO40: سعودي | CQ40: 953 | CV40: كومبوزيت | CX40: 0 | DA40: سعودي | DC40: 0 | DH40: كومبوزيت | DJ40: 0 | DM40: سعودي | DO40: 0 | DT40: كومبوزيت | DV40: 0 | DY40: سعودي | EA40: 0 | EF40: كومبوزيت | EH40: 0 | EK40: سعودي | EM40: 0 | ER40: كومبوزيت | ET40: =F40+R40+AD40+AP40+BB40+BN40+BZ40+CL40+CX40+DJ40+DV40+EH40 -> 277 | EW40: سعودي | EY40: =K40+W40+AI40+AU40+BG40+BS40+CE40+CQ40+DC40+DO40+EA40+EM40 -> 3634
...

Sheet إلإجمالي
D1: مراكز مستشفى شرق جدة | I1: =SUM('أسنان '!G1) -> 1 | J1: عام | K1: =SUM('أسنان '!J1) -> 1447 | Q1: مراكز مستشفى شرق جدة | U1: =SUM('أسنان '!S1) -> 2 | V1: عام | W1: =SUM('أسنان '!V1) -> 1447 | AB1: مراكز مستشفى شرق جدة | AG1: =SUM('أسنان '!AE1) -> 3 | AH1: عام | AI1: =SUM('أسنان '!AH1) -> 1447 | AN1: مراكز مستشفى شرق جدة | AS1: =SUM('أسنان '!AQ1) -> 4 | AT1: عام | AU1: =SUM('أسنان '!AT1) -> 1447 | AZ1: مراكز مستشفى شرق جدة | BE1: =SUM('أسنان '!BC1) -> 5 | BF1: عام | BG1: =SUM('أسنان '!BF1) -> 1447 | BL1: مراكز مستشفى شرق جدة | BQ1: =SUM('أسنان '!BO1) -> 6 | BR1: عام | BS1: =SUM('أسنان '!BR1) -> 1447 | BX1: مراكز مستشفى شرق جدة | CC1: =SUM('أسنان '!CA1) -> 7 | CD1: عام | CE1: =SUM('أسنان '!CD1) -> 1447 | CJ1: مراكز مستشفى شرق جدة | CO1: =SUM('أسنان '!CM1) -> 8 | CP1: عام | CQ1: =SUM('أسنان '!CP1) -> 1447 | CV1: مراكز مستشفى شرق جدة | DA1: =SUM('أسنان '!CY1) -> 9 | DB1: عام | DC1: =SUM('أسنان '!DB1) -> 1447 | DH1: مراكز مستشفى شرق جدة | DM1: =SUM('أسنان '!DK1) -> 10 | DN1: عام | DO1: =SUM('أسنان '!DN1) -> 1447 | DT1: مراكز مستشفى شرق جدة | DY1: =SUM('أسنان '!DW1) -> 11 | DZ1: عام | EA1: =SUM('أسنان '!DZ1) -> 1447 | EF1: مراكز مستشفى شرق جدة | EK1: =SUM('أسنان '!EI1) -> 12 | EL1: عام | EM1: =SUM('أسنان '!EL1) -> 1447 | ES1: مراكز مستشفى شرق جدة | EY1: عام | EZ1: =SUM(EM1) -> 1447
A2: 6 | B2: عيادة الأسنان | M2: 6 | N2: عيادة الأسنان | Y2: 6 | Z2: عيادة الأسنان | AK2: 6 | AL2: عيادة الأسنان | AW2: 6 | AX2: عيادة الأسنان | BI2: 6 | BJ2: عيادة الأسنان | BU2: 6 | BV2: عيادة الأسنان | CG2: 6 | CH2: عيادة الأسنان | CS2: 6 | CT2: عيادة الأسنان | DE2: 6 | DF2: عيادة الأسنان | DQ2: 6 | DR2: عيادة الأسنان | EC2: 6 | ED2: عيادة الأسنان | EP2: 6 | EQ2: عيادة الأسنان
A4: نوع الخدمة | F4: عدد المراجعين | I4: بالغين | J4: ذكور | K4: =SUM('أسنان '!K315:K316) -> 720 | M4: نوع الخدمة | R4: عدد المراجعين | U4: بالغين | V4: ذكور | W4: =SUM('أسنان '!W315:W316) -> 816 | Y4: نوع الخدمة | AD4: عدد المراجعين | AG4: بالغين | AH4: ذكور | AI4: =SUM('أسنان '!AI315:AI316) -> 814 | AK4: نوع الخدمة | AP4: عدد المراجعين | AS4: بالغين | AT4: ذكور | AU4: =SUM('أسنان '!AU315:AU316) -> 816 | AW4: نوع الخدمة | BB4: عدد المراجعين | BE4: بالغين | BF4: ذكور | BG4: =SUM('أسنان '!BG315:BG316) -> 1024 | BI4: نوع الخدمة | BN4: عدد المراجعين | BQ4: بالغين | BR4: ذكور | BS4: =SUM('أسنان '!BS315:BS316) -> 1068 | BU4: نوع الخدمة | BZ4: عدد المراجعين | CC4: بالغين | CD4: ذكور | CE4: =SUM('أسنان '!CE315:CE316) -> 783 | CG4: نوع الخدمة | CL4: عدد المراجعين | CO4: بالغين | CP4: ذكور | CQ4: =SUM('أسنان '!CQ315:CQ316) -> 576 | CS4: نوع الخدمة | CX4: عدد المراجعين | DA4: بالغين | DB4: ذكور | DC4: =SUM('أسنان '!DC315:DC316) -> 0 | DE4: نوع الخدمة | DJ4: عدد المراجعين | DM4: بالغين | DN4: ذكور | DO4: =SUM('أسنان '!DO315:DO316) -> 711 | DQ4: نوع الخدمة | DV4: عدد المراجعين | DY4: بالغين | DZ4: ذكور | EA4: =SUM('أسنان '!EA315:EA316) -> 0 | EC4: نوع الخدمة | EH4: عدد المراجعين | EK4: بالغين | EL4: ذكور | EM4: =SUM('أسنان '!EM315:EM316) -> 0 | EP4: نوع الخدمة | EU4: عدد المراجعين | EX4: بالغين | EY4: ذكور | EZ4: =SUM(K4+W4+AI4+AU4+BG4+BS4+CE4+CQ4+DC4+DO4+EA4+EM4) -> 7328
A5: الأشعة | C5: إطباقية | F5: ='أسنان '!F316:G316 -> 217 | M5: الأشعة | O5: إطباقية | R5: ='أسنان '!R316:S316 -> 169 | Y5: الأشعة | AA5: إطباقية | AD5: ='أسنان '!AD316:AE316 -> 71 | AK5: الأشعة | AM5: إطباقية | AP5: ='أسنان '!AP316:AQ316 -> 234 | AW5: الأشعة | AY5: إطباقية | BB5: ='أسنان '!BB316:BC316 -> 36 | BI5: الأشعة | BK5: إطباقية | BN5: ='أسنان '!BN316:BO316 -> 86 | BU5: الأشعة | BW5: إطباقية | BZ5: ='أسنان '!BZ316:CA316 -> 234 | CG5: الأشعة | CI5: إطباقية | CL5: ='أسنان '!CL316:CM316 -> 0 | CS5: الأشعة | CU5: إطباقية | CX5: ='أسنان '!CX316:CY316 -> 0 | DE5: الأشعة | DG5: إطباقية | DJ5: ='أسنان '!DJ316:DK316 -> 0 | DQ5: الأشعة | DS5: إطباقية | DV5: ='أسنان '!DV316:DW316 -> 0 | EC5: الأشعة | EE5: إطباقية | EH5: ='أسنان '!EH316:EI316 -> 0 | EP5: الأشعة | ER5: إطباقية | EU5: =SUM(F5+R5+AD5+AP5+BB5+BN5+BZ5+CL5+CX5+DJ5+DV5+EH5) -> 1047
C6: ذروية | F6: ='أسنان '!F317:G317 -> 130 | J6: إناث | K6: =SUM('أسنان '!K317:K318) -> #VALUE! | O6: ذروية | R6: ='أسنان '!R317:S317 -> 129 | V6: إناث | W6: =SUM('أسنان '!W317:W318) -> 1233 | AA6: ذروية | AD6: ='أسنان '!AD317:AE317 -> 188 | AH6: إناث | AI6: =SUM('أسنان '!AI317:AI318) -> 1150 | AM6: ذروية | AP6: ='أسنان '!AP317:AQ317 -> 138 | AT6: إناث | AU6: =SUM('أسنان '!AU317:AU318) -> 1057 | AY6: ذروية | BB6: ='أسنان '!BB317:BC317 -> 7 | BF6: إناث | BG6: =SUM('أسنان '!BG317:BG318) -> 1203 | BK6: ذروية | BN6: ='أسنان '!BN317:BO317 -> 98 | BR6: إناث | BS6: =SUM('أسنان '!BS317:BS318) -> 1048 | BW6: ذروية | BZ6: ='أسنان '!BZ317:CA317 -> 142 | CD6: إناث | CE6: =SUM('أسنان '!CE317:CE318) -> 1075 | CI6: ذروية | CL6: ='أسنان '!CL317:CM317 -> 42 | CP6: إناث | CQ6: =SUM('أسنان '!CQ317:CQ318) -> 444 | CU6: ذروية | CX6: ='أسنان '!CX317:CY317 -> 0 | DB6: إناث | DC6: =SUM('أسنان '!DC317:DC318) -> 0 | DG6: ذروية | DJ6: ='أسنان '!DJ317:DK317 -> 69 | DN6: إناث | DO6: =SUM('أسنان '!DO317:DO318) -> 919 | DS6: ذروية | DV6: ='أسنان '!DV317:DW317 -> 0 | DZ6: إناث | EA6: =SUM('أسنان '!EA317:EA318) -> 0 | EE6: ذروية | EH6: ='أسنان '!EH317:EI317 -> 0 | EL6: إناث | EM6: =SUM('أسنان '!EM317:EM318) -> 0 | ER6: ذروية | EU6: =SUM(F6+R6+AD6+AP6+BB6+BN6+BZ6+CL6+CX6+DJ6+DV6+EH6) -> 943 | EY6: إناث | EZ6: =SUM(K6+W6+AI6+AU6+BG6+BS6+CE6+CQ6+DC6+DO6+EA6+EM6) -> #VALUE!
C7: خارج الفم | F7: ='أسنان '!F318:G318 -> 95 | O7: خارج الفم | R7: ='أسنان '!R318:S318 -> 0 | AA7: خارج الفم | AD7: ='أسنان '!AD318:AE318 -> 71 | AM7: خارج الفم | AP7: ='أسنان '!AP318:AQ318 -> 86 | AY7: خارج الفم | BB7: ='أسنان '!BB318:BC318 -> 286 | BK7: خارج الفم | BN7: ='أسنان '!BN318:BO318 -> 0 | BW7: خارج الفم | BZ7: ='أسنان '!BZ318:CA318 -> 86 | CI7: خارج الفم | CL7: ='أسنان '!CL318:CM318 -> 0 | CU7: خارج الفم | CX7: ='أسنان '!CX318:CY318 -> 0 | DG7: خارج الفم | DJ7: ='أسنان '!DJ318:DK318 -> 100 | DS7: خارج الفم | DV7: ='أسنان '!DV318:DW318 -> 0 | EE7: خارج الفم | EH7: ='أسنان '!EH318:EI318 -> 0 | ER7: خارج الفم | EU7: =SUM(F7+R7+AD7+AP7+BB7+BN7+BZ7+CL7+CX7+DJ7+DV7+EH7) -> 724
A8: =-C1 -> 0 | B8: الخلع | C8: لبني | F8: ='أسنان '!F319:G319 -> 335 | I8: أطفال | J8: ذكور | K8: =SUM('أسنان '!K319:K320) -> 443 | M8: =-O1 -> 0 | N8: الخلع | O8: لبني | R8: ='أسنان '!R319:S319 -> 284 | U8: أطفال | V8: ذكور | W8: =SUM('أسنان '!W319:W320) -> 510 | Y8: =-AA1 -> 0 | Z8: الخلع | AA8: لبني | AD8: ='أسنان '!AD319:AE319 -> 164 | AG8: أطفال | AH8: ذكور | AI8: =SUM('أسنان '!AI319:AI320) -> 350 | AK8: =-AM1 -> 0 | AL8: الخلع | AM8: لبني | AP8: ='أسنان '!AP319:AQ319 -> 309 | AS8: أطفال | AT8: ذكور | AU8: =SUM('أسنان '!AU319:AU320) -> 503 | AW8: =-AY1 -> 0 | AX8: الخلع | AY8: لبني | BB8: ='أسنان '!BB319:BC319 -> 162 | BE8: أطفال | BF8: ذكور | BG8: =SUM('أسنان '!BG319:BG320) -> 446 | BI8: =-BK1 -> 0 | BJ8: الخلع | BK8: لبني | BN8: ='أسنان '!BN319:BO319 -> 83 | BQ8: أطفال | BR8: ذكور | BS8: =SUM('أسنان '!BS319:BS320) -> 170 | BU8: =-BW1 -> 0 | BV8: الخلع | BW8: لبني | BZ8: ='أسنان '!BZ319:CA319 -> 296 | CC8: أطفال | CD8: ذكور | CE8: =SUM('أسنان '!CE319:CE320) -> 459 | CG8: =-CI1 -> 0 | CH8: الخلع | CI8: لبني | CL8: ='أسنان '!CL319:CM319 -> 9 | CO8: أطفال | CP8: ذكور | CQ8: =SUM('أسنان '!CQ319:CQ320) -> 61 | CS8: =-CU1 -> 0 | CT8: الخلع | CU8: لبني | CX8: ='أسنان '!CX319:CY319 -> 0 | DA8: أطفال | DB8: ذكور | DC8: =SUM('أسنان '!DC319:DC320) -> 0 | DE8: =-DG1 -> 0 | DF8: الخلع | DG8: لبني | DJ8: ='أسنان '!DJ319:DK319 -> 156 | DM8: أطفال | DN8: ذكور | DO8: =SUM('أسنان '!DO319:DO320) -> 483 | DQ8: =-DS1 -> 0 | DR8: الخلع | DS8: لبني | DV8: ='أسنان '!DV319:DW319 -> 0 | DY8: أطفال | DZ8: ذكور | EA8: =SUM('أسنان '!EA319:EA320) -> 0 | EC8: =-EE1 -> 0 | ED8: الخلع | EE8: لبني | EH8: ='أسنان '!EH319:EI319 -> 0 | EK8: أطفال | EL8: ذكور | EM8: =SUM('أسنان '!EM319:EM320) -> 0 | EP8: =-ER1 -> 0 | EQ8: الخلع | ER8: لبني | EU8: =SUM(F8+R8+AD8+AP8+BB8+BN8+BZ8+CL8+CX8+DJ8+DV8+EH8) -> 1798 | EX8: أطفال | EY8: ذكور | EZ8: =SUM(K8+W8+AI8+AU8+BG8+BS8+CE8+CQ8+DC8+DO8+EA8+EM8) -> 3425
C9: دائم | F9: ='أسنان '!F320:G320 -> 102 | O9: دائم | R9: ='أسنان '!R320:S320 -> 92 | AA9: دائم | AD9: ='أسنان '!AD320:AE320 -> 55 | AM9: دائم | AP9: ='أسنان '!AP320:AQ320 -> 83 | AY9: دائم | BB9: ='أسنان '!BB320:BC320 -> 115 | BK9: دائم | BN9: ='أسنان '!BN320:BO320 -> 75 | BW9: دائم | BZ9: ='أسنان '!BZ320:CA320 -> 84 | CI9: دائم | CL9: ='أسنان '!CL320:CM320 -> 54 | CU9: دائم | CX9: ='أسنان '!CX320:CY320 -> 0 | DG9: دائم | DJ9: ='أسنان '!DJ320:DK320 -> 98 | DS9: دائم | DV9: ='أسنان '!DV320:DW320 -> 0 | EE9: دائم | EH9: ='أسنان '!EH320:EI320 -> 0 | ER9: دائم | EU9: =SUM(F9+R9+AD9+AP9+BB9+BN9+BZ9+CL9+CX9+DJ9+DV9+EH9) -> 758
C10: جراحي | F10: ='أسنان '!F321:G321 -> 0 | J10: إناث | K10: =SUM('أسنان '!K321:K322) -> 485 | O10: جراحي | R10: ='أسنان '!R321:S321 -> 0 | V10: إناث | W10: =SUM('أسنان '!W321:W322) -> 631 | AA10: جراحي | AD10: ='أسنان '!AD321:AE321 -> 0 | AH10: إناث | AI10: =SUM('أسنان '!AI321:AI322) -> 397 | AM10: جراحي | AP10: ='أسنان '!AP321:AQ321 -> 0 | AT10: إناث | AU10: =SUM('أسنان '!AU321:AU322) -> 541 | AY10: جراحي | BB10: ='أسنان '!BB321:BC321 -> 0 | BF10: إناث | BG10: =SUM('أسنان '!BG321:BG322) -> 284 | BK10: جراحي | BN10: ='أسنان '!BN321:BO321 -> 0 | BR10: إناث | BS10: =SUM('أسنان '!BS321:BS322) -> 186 | BW10: جراحي | BZ10: ='أسنان '!BZ321:CA321 -> 0 | CD10: إناث | CE10: =SUM('أسنان '!CE321:CE322) -> 489 | CI10: جراحي | CL10: ='أسنان '!CL321:CM321 -> 0 | CP10: إناث | CQ10: =SUM('أسنان '!CQ321:CQ322) -> 63 | CU10: جراحي | CX10: ='أسنان '!CX321:CY321 -> 0 | DB10: إناث | DC10: =SUM('أسنان '!DC321:DC322) -> 0 | DG10: جراحي | DJ10: ='أسنان '!DJ321:DK321 -> 0 | DN10: إناث | DO10: =SUM('أسنان '!DO321:DO322) -> 350 | DS10: جراحي | DV10: ='أسنان '!DV321:DW321 -> 0 | DZ10: إناث | EA10: =SUM('أسنان '!EA321:EA322) -> 0 | EE10: جراحي | EH10: ='أسنان '!EH321:EI321 -> 0 | EL10: إناث | EM10: =SUM('أسنان '!EM321:EM322) -> 0 | ER10: جراحي | EU10: =SUM(F10+R10+AD10+AP10+BB10+BN10+BZ10+CL10+CX10+DJ10+DV10+EH10) -> 0 | EY10: إناث | EZ10: =SUM(K10+W10+AI10+AU10+BG10+BS10+CE10+CQ10+DC10+DO10+EA10+EM10) -> 3426
B11: الجراحة | C11: جراحة | F11: ='أسنان '!F322:G322 -> 0 | N11: الجراحة | O11: جراحة | R11: ='أسنان '!R322:S322 -> 0 | Z11: الجراحة | AA11: جراحة | AD11: ='أسنان '!AD322:AE322 -> 0 | AL11: الجراحة | AM11: جراحة | AP11: ='أسنان '!AP322:AQ322 -> 0 | AX11: الجراحة | AY11: جراحة | BB11: ='أسنان '!BB322:BC322 -> 0 | BJ11: الجراحة | BK11: جراحة | BN11: ='أسنان '!BN322:BO322 -> 0 | BV11: الجراحة | BW11: جراحة | BZ11: ='أسنان '!BZ322:CA322 -> 0 | CH11: الجراحة | CI11: جراحة | CL11: ='أسنان '!CL322:CM322 -> 0 | CT11: الجراحة | CU11: جراحة | CX11: ='أسنان '!CX322:CY322 -> 0 | DF11: الجراحة | DG11: جراحة | DJ11: ='أسنان '!DJ322:DK322 -> 0 | DR11: الجراحة | DS11: جراحة | DV11: ='أسنان '!DV322:DW322 -> 0 | ED11: الجراحة | EE11: جراحة | EH11: ='أسنان '!EH322:EI322 -> 0 | EQ11: الجراحة | ER11: جراحة | EU11: =SUM(F11+R11+AD11+AP11+BB11+BN11+BZ11+CL11+CX11+DJ11+DV11+EH11) -> 0
C12: متابعة | F12: ='أسنان '!F323:G323 -> 0 | I12: المجموع | K12: =SUM(K4:K11) -> #VALUE! | O12: متابعة | R12: ='أسنان '!R323:S323 -> 0 | U12: المجموع | W12: =SUM(W4:W11) -> 3190 | AA12: متابعة | AD12: ='أسنان '!AD323:AE323 -> 0 | AG12: المجموع | AI12: =SUM(AI4:AI11) -> 2711 | AM12: متابعة | AP12: ='أسنان '!AP323:AQ323 -> 0 | AS12: المجموع | AU12: =SUM(AU4:AU11) -> 2917 | AY12: متابعة | BB12: ='أسنان '!BB323:BC323 -> 6 | BE12: المجموع | BG12: =SUM(BG4:BG11) -> 2957 | BK12: متابعة | BN12: ='أسنان '!BN323:BO323 -> 0 | BQ12: المجموع | BS12: =SUM(BS4:BS11) -> 2472 | BW12: متابعة | BZ12: ='أسنان '!BZ323:CA323 -> 0 | CC12: المجموع | CE12: =SUM(CE4:CE11) -> 2806 | CI12: متابعة | CL12: ='أسنان '!CL323:CM323 -> 0 | CO12: المجموع | CQ12: =SUM(CQ4:CQ11) -> 1144 | CU12: متابعة | CX12: ='أسنان '!CX323:CY323 -> 0 | DA12: المجموع | DC12: =SUM(DC4:DC11) -> 0 | DG12: متابعة | DJ12: ='أسنان '!DJ323:DK323 -> 0 | DM12: المجموع | DO12: =SUM(DO4:DO11) -> 2463 | DS12: متابعة | DV12: ='أسنان '!DV323:DW323 -> 0 | DY12: المجموع | EA12: =SUM(EA4:EA11) -> 0 | EE12: متابعة | EH12: ='أسنان '!EH323:EI323 -> 0 | EK12: المجموع | EM12: =SUM(EM4:EM11) -> 0 | ER12: متابعة | EU12: =SUM(F12+R12+AD12+AP12+BB12+BN12+BZ12+CL12+CX12+DJ12+DV12+EH12) -> 6 | EX12: المجموع | EZ12: =SUM(EZ4:EZ11) -> #VALUE!
B13: الحشو | C13: مؤقت | F13: ='أسنان '!F324:G324 -> 371 | N13: الحشو | O13: مؤقت | R13: ='أسنان '!R324:S324 -> 353 | Z13: الحشو | AA13: مؤقت | AD13: ='أسنان '!AD324:AE324 -> 196 | AL13: الحشو | AM13: مؤقت | AP13: ='أسنان '!AP324:AQ324 -> 388 | AX13: الحشو | AY13: مؤقت | BB13: ='أسنان '!BB324:BC324 -> 147 | BJ13: الحشو | BK13: مؤقت | BN13: ='أسنان '!BN324:BO324 -> 72 | BV13: الحشو | BW13: مؤقت | BZ13: ='أسنان '!BZ324:CA324 -> 383 | CH13: الحشو | CI13: مؤقت | CL13: ='أسنان '!CL324:CM324 -> 17 | CT13: الحشو | CU13: مؤقت | CX13: ='أسنان '!CX324:CY324 -> 0 | DF13: الحشو | DG13: مؤقت | DJ13: ='أسنان '!DJ324:DK324 -> 216 | DR13: الحشو | DS13: مؤقت | DV13: ='أسنان '!DV324:DW324 -> 0 | ED13: الحشو | EE13: مؤقت | EH13: ='أسنان '!EH324:EI324 -> 0 | EQ13: الحشو | ER13: مؤقت | EU13: =SUM(F13+R13+AD13+AP13+BB13+BN13+BZ13+CL13+CX13+DJ13+DV13+EH13) -> 2143
C14: أملجم | F14: ='أسنان '!F325:G325 -> 112 | O14: أملجم | R14: ='أسنان '!R325:S325 -> 102 | AA14: أملجم | AD14: ='أسنان '!AD325:AE325 -> 107 | AM14: أملجم | AP14: ='أسنان '!AP325:AQ325 -> 111 | AY14: أملجم | BB14: ='أسنان '!BB325:BC325 -> 36 | BK14: أملجم | BN14: ='أسنان '!BN325:BO325 -> 51 | BW14: أملجم | BZ14: ='أسنان '!BZ325:CA325 -> 111 | CI14: أملجم | CL14: ='أسنان '!CL325:CM325 -> 51 | CU14: أملجم | CX14: ='أسنان '!CX325:CY325 -> 0 | DG14: أملجم | DJ14: ='أسنان '!DJ325:DK325 -> 73 | DS14: أملجم | DV14: ='أسنان '!DV325:DW325 -> 0 | EE14: أملجم | EH14: ='أسنان '!EH325:EI325 -> 0 | ER14: أملجم | EU14: =SUM(F14+R14+AD14+AP14+BB14+BN14+BZ14+CL14+CX14+DJ14+DV14+EH14) -> 754
C15: كومبوزيت | F15: ='أسنان '!F326:G326 -> 451 | O15: كومبوزيت | R15: ='أسنان '!R326:S326 -> 570 | AA15: كومبوزيت | AD15: ='أسنان '!AD326:AE326 -> 433 | AM15: كومبوزيت | AP15: ='أسنان '!AP326:AQ326 -> 665 | AY15: كومبوزيت | BB15: ='أسنان '!BB326:BC326 -> 625 | BK15: كومبوزيت | BN15: ='أسنان '!BN326:BO326 -> 210 | BW15: كومبوزيت | BZ15: ='أسنان '!BZ326:CA326 -> 548 | CI15: كومبوزيت | CL15: ='أسنان '!CL326:CM326 -> 60 | CU15: كومبوزيت | CX15: ='أسنان '!CX326:CY326 -> 0 | DG15: كومبوزيت | DJ15: ='أسنان '!DJ326:DK326 -> 317 | DS15: كومبوزيت | DV15: ='أسنان '!DV326:DW326 -> 0 | EE15: كومبوزيت | EH15: ='أسنان '!EH326:EI326 -> 0 | ER15: كومبوزيت | EU15: =SUM(F15+R15+AD15+AP15+BB15+BN15+BZ15+CL15+CX15+DJ15+DV15+EH15) -> 3879
C16: لا ينومر زجاج | F16: ='أسنان '!F327:G327 -> 186 | I16: سعودي | K16: =SUM('أسنان '!K326:K327) -> 2679 | O16: لا ينومر زجاج | R16: ='أسنان '!R327:S327 -> 240 | U16: سعودي | W16: =SUM('أسنان '!W326:W327) -> 2866 | AA16: لا ينومر زجاج | AD16: ='أسنان '!AD327:AE327 -> 261 | AG16: سعودي | AI16: =SUM('أسنان '!AI326:AI327) -> 2711 | AM16: لا ينومر زجاج | AP16: ='أسنان '!AP327:AQ327 -> 274 | AS16: سعودي | AU16: =SUM('أسنان '!AU326:AU327) -> 2917 | AY16: لا ينومر زجاج | BB16: ='أسنان '!BB327:BC327 -> 609 | BE16: سعودي | BG16: =SUM('أسنان '!BG326:BG327) -> 2647 | BK16: لا ينومر زجاج | BN16: ='أسنان '!BN327:BO327 -> 122 | BQ16: سعودي | BS16: =SUM('أسنان '!BS326:BS327) -> 2472 | BW16: لا ينومر زجاج | BZ16: ='أسنان '!BZ327:CA327 -> 259 | CC16: سعودي | CE16: =SUM('أسنان '!CE326:CE327) -> 2806 | CI16: لا ينومر زجاج | CL16: ='أسنان '!CL327:CM327 -> 47 | CO16: سعودي | CQ16: =SUM('أسنان '!CQ326:CQ327) -> 1144 | CU16: لا ينومر زجاج | CX16: ='أسنان '!CX327:CY327 -> 0 | DA16: سعودي | DC16: =SUM('أسنان '!DC326:DC327) -> 0 | DG16: لا ينومر زجاج | DJ16: ='أسنان '!DJ327:DK327 -> 196 | DM16: سعودي | DO16: =SUM('أسنان '!DO326:DO327) -> 2454 | DS16: لا ينومر زجاج | DV16: ='أسنان '!DV327:DW327 -> 0 | DY16: سعودي | EA16: =SUM('أسنان '!EA326:EA327) -> 0 | EE16: لا ينومر زجاج | EH16: ='أسنان '!EH327:EI327 -> 0 | EK16: سعودي | EM16: =SUM('أسنان '!EM326:EM327) -> 0 | ER16: لا ينومر زجاج | EU16: =SUM(F16+R16+AD16+AP16+BB16+BN16+BZ16+CL16+CX16+DJ16+DV16+EH16) -> 2194 | EX16: سعودي | EZ16: =SUM(K16+W16+AI16+AU16+BG16+BS16+CE16+CQ16+DC16+DO16+EA16+EM16) -> 22696
B17: علاج العصب | C17: لبني | F17: ='أسنان '!F328:G328 -> 11 | N17: علاج العصب | O17: لبني | R17: ='أسنان '!R328:S328 -> 5 | Z17: علاج العصب | AA17: لبني | AD17: ='أسنان '!AD328:AE328 -> 47 | AL17: علاج العصب | AM17: لبني | AP17: ='أسنان '!AP328:AQ328 -> 5 | AX17: علاج العصب | AY17: لبني | BB17: ='أسنان '!BB328:BC328 -> 30 | BJ17: علاج العصب | BK17: لبني | BN17: ='أسنان '!BN328:BO328 -> 21 | BV17: علاج العصب | BW17: لبني | BZ17: ='أسنان '!BZ328:CA328 -> 5 | CH17: علاج العصب | CI17: لبني | CL17: ='أسنان '!CL328:CM328 -> 17 | CT17: علاج العصب | CU17: لبني | CX17: ='أسنان '!CX328:CY328 -> 0 | DF17: علاج العصب | DG17: لبني | DJ17: ='أسنان '!DJ328:DK328 -> 5 | DR17: علاج العصب | DS17: لبني | DV17: ='أسنان '!DV328:DW328 -> 0 | ED17: علاج العصب | EE17: لبني | EH17: ='أسنان '!EH328:EI328 -> 0 | EQ17: علاج العصب | ER17: لبني | EU17: =SUM(F17+R17+AD17+AP17+BB17+BN17+BZ17+CL17+CX17+DJ17+DV17+EH17) -> 146
C18: تهيئة | F18: ='أسنان '!F329:G329 -> 353 | I18: غير سعودي | K18: =SUM('أسنان '!K328:K329) -> 0 | O18: تهيئة | R18: ='أسنان '!R329:S329 -> 310 | U18: غير سعودي | W18: =SUM('أسنان '!W328:W329) -> 0 | AA18: تهيئة | AD18: ='أسنان '!AD329:AE329 -> 160 | AG18: غير سعودي | AI18: =SUM('أسنان '!AI328:AI329) -> 0 | AM18: تهيئة | AP18: ='أسنان '!AP329:AQ329 -> 338 | AS18: غير سعودي | AU18: =SUM('أسنان '!AU328:AU329) -> 0 | AY18: تهيئة | BB18: ='أسنان '!BB329:BC329 -> 116 | BE18: غير سعودي | BG18: =SUM('أسنان '!BG328:BG329) -> 310 | BK18: تهيئة | BN18: ='أسنان '!BN329:BO329 -> 75 | BQ18: غير سعودي | BS18: =SUM('أسنان '!BS328:BS329) -> 0 | BW18: تهيئة | BZ18: ='أسنان '!BZ329:CA329 -> 301 | CC18: غير سعودي | CE18: =SUM('أسنان '!CE328:CE329) -> 0 | CI18: تهيئة | CL18: ='أسنان '!CL329:CM329 -> 32 | CO18: غير سعودي | CQ18: =SUM('أسنان '!CQ328:CQ329) -> 0 | CU18: تهيئة | CX18: ='أسنان '!CX329:CY329 -> 0 | DA18: غير سعودي | DC18: =SUM('أسنان '!DC328:DC329) -> 0 | DG18: تهيئة | DJ18: ='أسنان '!DJ329:DK329 -> 224 | DM18: غير سعودي | DO18: =SUM('أسنان '!DO328:DO329) -> 0 | DS18: تهيئة | DV18: ='أسنان '!DV329:DW329 -> 0 | DY18: غير سعودي | EA18: =SUM('أسنان '!EA328:EA329) -> 0 | EE18: تهيئة | EH18: ='أسنان '!EH329:EI329 -> 0 | EK18: غير سعودي | EM18: =SUM('أسنان '!EM328:EM329) -> 0 | ER18: تهيئة | EU18: =SUM(F18+R18+AD18+AP18+BB18+BN18+BZ18+CL18+CX18+DJ18+DV18+EH18) -> 1909 | EX18: غير سعودي | EZ18: =SUM(K18+W18+AI18+AU18+BG18+BS18+CE18+CQ18+DC18+DO18+EA18+EM18) -> 310
C19: حشو | F19: ='أسنان '!F330:G330 -> 51 | O19: حشو | R19: ='أسنان '!R330:S330 -> 42 | AA19: حشو | AD19: ='أسنان '!AD330:AE330 -> 0 | AM19: حشو | AP19: ='أسنان '!AP330:AQ330 -> 52 | AY19: حشو | BB19: ='أسنان '!BB330:BC330 -> 0 | BK19: حشو | BN19: ='أسنان '!BN330:BO330 -> 0 | BW19: حشو | BZ19: ='أسنان '!BZ330:CA330 -> 52 | CI19: حشو | CL19: ='أسنان '!CL330:CM330 -> 0 | CU19: حشو | CX19: ='أسنان '!CX330:CY330 -> 0 | DG19: حشو | DJ19: ='أسنان '!DJ330:DK330 -> 13 | DS19: حشو | DV19: ='أسنان '!DV330:DW330 -> 0 | EE19: حشو | EH19: ='أسنان '!EH330:EI330 -> 0 | ER19: حشو | EU19: =SUM(F19+R19+AD19+AP19+BB19+BN19+BZ19+CL19+CX19+DJ19+DV19+EH19) -> 210
B20: علاج اللثة | C20: كحت جير | F20: ='أسنان '!F331:G331 -> 254 | I20: المجموع | K20: =SUM(K16:K19) -> 2679 | N20: علاج اللثة | O20: كحت جير | R20: ='أسنان '!R331:S331 -> 267 | U20: المجموع | W20: =SUM(W16:W19) -> 2866 | Z20: علاج اللثة | AA20: كحت جير | AD20: ='أسنان '!AD331:AE331 -> 339 | AG20: المجموع | AI20: =SUM(AI16:AI19) -> 2711 | AL20: علاج اللثة | AM20: كحت جير | AP20: ='أسنان '!AP331:AQ331 -> 266 | AS20: المجموع | AU20: =SUM(AU16:AU19) -> 2917 | AX20: علاج اللثة | AY20: كحت جير | BB20: ='أسنان '!BB331:BC331 -> 294 | BE20: المجموع | BG20: =SUM(BG16:BG19) -> 2957 | BJ20: علاج اللثة | BK20: كحت جير | BN20: ='أسنان '!BN331:BO331 -> 111 | BQ20: المجموع | BS20: =SUM(BS16:BS19) -> 2472 | BV20: علاج اللثة | BW20: كحت جير | BZ20: ='أسنان '!BZ331:CA331 -> 237 | CC20: المجموع | CE20: =SUM(CE16:CE19) -> 2806 | CH20: علاج اللثة | CI20: كحت جير | CL20: ='أسنان '!CL331:CM331 -> 21 | CO20: المجموع | CQ20: =SUM(CQ16:CQ19) -> 1144 | CT20: علاج اللثة | CU20: كحت جير | CX20: ='أسنان '!CX331:CY331 -> 0 | DA20: المجموع | DC20: =SUM(DC16:DC19) -> 0 | DF20: علاج اللثة | DG20: كحت جير | DJ20: ='أسنان '!DJ331:DK331 -> 262 | DM20: المجموع | DO20: =SUM(DO16:DO19) -> 2454 | DR20: علاج اللثة | DS20: كحت جير | DV20: ='أسنان '!DV331:DW331 -> 0 | DY20: المجموع | EA20: =SUM(EA16:EA19) -> 0 | ED20: علاج اللثة | EE20: كحت جير | EH20: ='أسنان '!EH331:EI331 -> 0 | EK20: المجموع | EM20: =SUM(EM16:EM19) -> 0 | EQ20: علاج اللثة | ER20: كحت جير | EU20: =SUM(F20+R20+AD20+AP20+BB20+BN20+BZ20+CL20+CX20+DJ20+DV20+EH20) -> 2051 | EX20: المجموع | EZ20: =SUM(EZ16:EZ19) -> 23006
C21: جراحة لثه | F21: ='أسنان '!F332:G332 -> 0 | O21: جراحة لثه | R21: ='أسنان '!R332:S332 -> 0 | AA21: جراحة لثه | AD21: ='أسنان '!AD332:AE332 -> 0 | AM21: جراحة لثه | AP21: ='أسنان '!AP332:AQ332 -> 0 | AY21: جراحة لثه | BB21: ='أسنان '!BB332:BC332 -> 0 | BK21: جراحة لثه | BN21: ='أسنان '!BN332:BO332 -> 0 | BW21: جراحة لثه | BZ21: ='أسنان '!BZ332:CA332 -> 0 | CI21: جراحة لثه | CL21: ='أسنان '!CL332:CM332 -> 0 | CU21: جراحة لثه | CX21: ='أسنان '!CX332:CY332 -> 0 | DG21: جراحة لثه | DJ21: ='أسنان '!DJ332:DK332 -> 0 | DS21: جراحة لثه | DV21: ='أسنان '!DV332:DW332 -> 0 | EE21: جراحة لثه | EH21: ='أسنان '!EH332:EI332 -> 0 | ER21: جراحة لثه | EU21: =SUM(F21+R21+AD21+AP21+BB21+BN21+BZ21+CL21+CX21+DJ21+DV21+EH21) -> 0
B22: أمراض الفم | F22: ='أسنان '!F333:G333 -> 0 | N22: أمراض الفم | R22: ='أسنان '!R333:S333 -> 0 | Z22: أمراض الفم | AD22: ='أسنان '!AD333:AE333 -> 0 | AL22: أمراض الفم | AP22: ='أسنان '!AP333:AQ333 -> 0 | AX22: أمراض الفم | BB22: ='أسنان '!BB333:BC333 -> 0 | BJ22: أمراض الفم | BN22: ='أسنان '!BN333:BO333 -> 0 | BV22: أمراض الفم | BZ22: ='أسنان '!BZ333:CA333 -> 0 | CH22: أمراض الفم | CL22: ='أسنان '!CL333:CM333 -> 0 | CT22: أمراض الفم | CX22: ='أسنان '!CX333:CY333 -> 0 | DF22: أمراض الفم | DJ22: ='أسنان '!DJ333:DK333 -> 0 | DR22: أمراض الفم | DV22: ='أسنان '!DV333:DW333 -> 0 | ED22: أمراض الفم | EH22: ='أسنان '!EH333:EI333 -> 0 | EQ22: أمراض الفم | EU22: =SUM(F22+R22+AD22+AP22+BB22+BN22+BZ22+CL22+CX22+DJ22+DV22+EH22) -> 0
A23: الإجراءات الوقائية | B23: توعية صحية | F23: ='أسنان '!F334:G334 -> 2391 | I23: جديد | K23: =SUM('أسنان '!K333:K334) -> 816 | M23: الإجراءات الوقائية | N23: توعية صحية | R23: ='أسنان '!R334:S334 -> 2870 | U23: جديد | W23: =SUM('أسنان '!W333:W334) -> 1174 | Y23: الإجراءات الوقائية | Z23: توعية صحية | AD23: ='أسنان '!AD334:AE334 -> 2604 | AG23: جديد | AI23: =SUM('أسنان '!AI333:AI334) -> 349 | AK23: الإجراءات الوقائية | AL23: توعية صحية | AP23: ='أسنان '!AP334:AQ334 -> 2718 | AS23: جديد | AU23: =SUM('أسنان '!AU333:AU334) -> 344 | AW23: الإجراءات الوقائية | AX23: توعية صحية | BB23: ='أسنان '!BB334:BC334 -> 2675 | BE23: جديد | BG23: =SUM('أسنان '!BG333:BG334) -> 1349 | BI23: الإجراءات الوقائية | BJ23: توعية صحية | BN23: ='أسنان '!BN334:BO334 -> 1544 | BQ23: جديد | BS23: =SUM('أسنان '!BS333:BS334) -> 1086 | BU23: الإجراءات الوقائية | BV23: توعية صحية | BZ23: ='أسنان '!BZ334:CA334 -> 2516 | CC23: جديد | CE23: =SUM('أسنان '!CE333:CE334) -> 521 | CG23: الإجراءات الوقائية | CH23: توعية صحية | CL23: ='أسنان '!CL334:CM334 -> 216 | CO23: جديد | CQ23: =SUM('أسنان '!CQ333:CQ334) -> 677 | CS23: الإجراءات الوقائية | CT23: توعية صحية | CX23: ='أسنان '!CX334:CY334 -> 0 | DA23: جديد | DC23: =SUM('أسنان '!DC333:DC334) -> 0 | DE23: الإجراءات الوقائية | DF23: توعية صحية | DJ23: ='أسنان '!DJ334:DK334 -> 2310 | DM23: جديد | DO23: =SUM('أسنان '!DO333:DO334) -> 525 | DQ23: الإجراءات الوقائية | DR23: توعية صحية | DV23: ='أسنان '!DV334:DW334 -> 0 | DY23: جديد | EA23: =SUM('أسنان '!EA333:EA334) -> 0 | EC23: الإجراءات الوقائية | ED23: توعية صحية | EH23: ='أسنان '!EH334:EI334 -> 0 | EK23: جديد | EM23: =SUM('أسنان '!EM333:EM334) -> 0 | EP23: الإجراءات الوقائية | EQ23: توعية صحية | EU23: =SUM(F23+R23+AD23+AP23+BB23+BN23+BZ23+CL23+CX23+DJ23+DV23+EH23) -> 19844 | EX23: جديد | EZ23: =SUM(K23+W23+AI23+AU23+BG23+BS23+CE23+CQ23+DC23+DO23+EA23+EM23) -> 6841
B24: رعاية حوامل | F24: ='أسنان '!F335:G335 -> 0 | N24: رعاية حوامل | R24: ='أسنان '!R335:S335 -> 2 | Z24: رعاية حوامل | AD24: ='أسنان '!AD335:AE335 -> 0 | AL24: رعاية حوامل | AP24: ='أسنان '!AP335:AQ335 -> 0 | AX24: رعاية حوامل | BB24: ='أسنان '!BB335:BC335 -> 12 | BJ24: رعاية حوامل | BN24: ='أسنان '!BN335:BO335 -> 0 | BV24: رعاية حوامل | BZ24: ='أسنان '!BZ335:CA335 -> 0 | CH24: رعاية حوامل | CL24: ='أسنان '!CL335:CM335 -> 0 | CT24: رعاية حوامل | CX24: ='أسنان '!CX335:CY335 -> 0 | DF24: رعاية حوامل | DJ24: ='أسنان '!DJ335:DK335 -> 10 | DR24: رعاية حوامل | DV24: ='أسنان '!DV335:DW335 -> 0 | ED24: رعاية حوامل | EH24: ='أسنان '!EH335:EI335 -> 0 | EQ24: رعاية حوامل | EU24: =SUM(F24+R24+AD24+AP24+BB24+BN24+BZ24+CL24+CX24+DJ24+DV24+EH24) -> 24
B25: حشو الحفر | F25: ='أسنان '!F336:G336 -> 0 | I25: متايعة | K25: =SUM('أسنان '!K335:K336) -> 1863 | N25: حشو الحفر | R25: ='أسنان '!R336:S336 -> 4 | U25: متايعة | W25: =SUM('أسنان '!W335:W336) -> 684 | Z25: حشو الحفر | AD25: ='أسنان '!AD336:AE336 -> 118 | AG25: متايعة | AI25: =SUM('أسنان '!AI335:AI336) -> 443 | AL25: حشو الحفر | AP25: ='أسنان '!AP336:AQ336 -> 3 | AS25: متايعة | AU25: =SUM('أسنان '!AU335:AU336) -> 553 | AX25: حشو الحفر | BB25: ='أسنان '!BB336:BC336 -> 113 | BE25: متايعة | BG25: =SUM('أسنان '!BG335:BG336) -> 748 | BJ25: حشو الحفر | BN25: ='أسنان '!BN336:BO336 -> 0 | BQ25: متايعة | BS25: =SUM('أسنان '!BS335:BS336) -> 1029 | BV25: حشو الحفر | BZ25: ='أسنان '!BZ336:CA336 -> 11 | CC25: متايعة | CE25: =SUM('أسنان '!CE335:CE336) -> 866 | CH25: حشو الحفر | CL25: ='أسنان '!CL336:CM336 -> 0 | CO25: متايعة | CQ25: =SUM('أسنان '!CQ335:CQ336) -> 467 | CT25: حشو الحفر | CX25: ='أسنان '!CX336:CY336 -> 0 | DA25: متايعة | DC25: =SUM('أسنان '!DC335:DC336) -> 0 | DF25: حشو الحفر | DJ25: ='أسنان '!DJ336:DK336 -> 5 | DM25: متايعة | DO25: =SUM('أسنان '!DO335:DO336) -> 291 | DR25: حشو الحفر | DV25: ='أسنان '!DV336:DW336 -> 0 | DY25: متايعة | EA25: =SUM('أسنان '!EA335:EA336) -> 0 | ED25: حشو الحفر | EH25: ='أسنان '!EH336:EI336 -> 0 | EK25: متايعة | EM25: =SUM('أسنان '!EM335:EM336) -> 0 | EQ25: حشو الحفر | EU25: =SUM(F25+R25+AD25+AP25+BB25+BN25+BZ25+CL25+CX25+DJ25+DV25+EH25) -> 254 | EX25: متايعة | EZ25: =SUM(K25+W25+AI25+AU25+BG25+BS25+CE25+CQ25+DC25+DO25+EA25+EM25) -> 6944
B26: فلوريد موضعي | F26: ='أسنان '!F337:G337 -> 65 | N26: فلوريد موضعي | R26: ='أسنان '!R337:S337 -> 105 | Z26: فلوريد موضعي | AD26: ='أسنان '!AD337:AE337 -> 116 | AL26: فلوريد موضعي | AP26: ='أسنان '!AP337:AQ337 -> 108 | AX26: فلوريد موضعي | BB26: ='أسنان '!BB337:BC337 -> 97 | BJ26: فلوريد موضعي | BN26: ='أسنان '!BN337:BO337 -> 36 | BV26: فلوريد موضعي | BZ26: ='أسنان '!BZ337:CA337 -> 105 | CH26: فلوريد موضعي | CL26: ='أسنان '!CL337:CM337 -> 9 | CT26: فلوريد موضعي | CX26: ='أسنان '!CX337:CY337 -> 0 | DF26: فلوريد موضعي | DJ26: ='أسنان '!DJ337:DK337 -> 38 | DR26: فلوريد موضعي | DV26: ='أسنان '!DV337:DW337 -> 0 | ED26: فلوريد موضعي | EH26: ='أسنان '!EH337:EI337 -> 0 | EQ26: فلوريد موضعي | EU26: =SUM(F26+R26+AD26+AP26+BB26+BN26+BZ26+CL26+CX26+DJ26+DV26+EH26) -> 679
A27: أدوية منصرفة | B27: 1 | C27: 2 | D27: 3 | E27: 4 | F27: 5 | G27: 6 | I27: المجموع | K27: =SUM(K23:K26) -> 2679 | M27: أدوية منصرفة | N27: 1 | O27: 2 | P27: 3 | Q27: 4 | R27: 5 | S27: 6 | U27: المجموع | W27: =SUM(W23:W26) -> 1858 | Y27: أدوية منصرفة | Z27: 1 | AA27: 2 | AB27: 3 | AC27: 4 | AD27: 5 | AE27: 6 | AG27: المجموع | AI27: =SUM(AI23:AI26) -> 792 | AK27: أدوية منصرفة | AL27: 1 | AM27: 2 | AN27: 3 | AO27: 4 | AP27: 5 | AQ27: 6 | AS27: المجموع | AU27: =SUM(AU23:AU26) -> 897 | AW27: أدوية منصرفة | AX27: 1 | AY27: 2 | AZ27: 3 | BA27: 4 | BB27: 5 | BC27: 6 | BE27: المجموع | BG27: =SUM(BG23:BG26) -> 2097 | BI27: أدوية منصرفة | BJ27: 1 | BK27: 2 | BL27: 3 | BM27: 4 | BN27: 5 | BO27: 6 | BQ27: المجموع | BS27: =SUM(BS23:BS26) -> 2115 | BU27: أدوية منصرفة | BV27: 1 | BW27: 2 | BX27: 3 | BY27: 4 | BZ27: 5 | CA27: 6 | CC27: المجموع | CE27: =SUM(CE23:CE26) -> 1387 | CG27: أدوية منصرفة | CH27: 1 | CI27: 2 | CJ27: 3 | CK27: 4 | CL27: 5 | CM27: 6 | CO27: المجموع | CQ27: =SUM(CQ23:CQ26) -> 1144 | CS27: أدوية منصرفة | CT27: 1 | CU27: 2 | CV27: 3 | CW27: 4 | CX27: 5 | CY27: 6 | DA27: المجموع | DC27: =SUM(DC23:DC26) -> 0 | DE27: أدوية منصرفة | DF27: 1 | DG27: 2 | DH27: 3 | DI27: 4 | DJ27: 5 | DK27: 6 | DM27: المجموع | DO27: =SUM(DO23:DO26) -> 816 | DQ27: أدوية منصرفة | DR27: 1 | DS27: 2 | DT27: 3 | DU27: 4 | DV27: 5 | DW27: 6 | DY27: المجموع | EA27: =SUM(EA23:EA26) -> 0 | EC27: أدوية منصرفة | ED27: 1 | EE27: 2 | EF27: 3 | EG27: 4 | EH27: 5 | EI27: 6 | EK27: المجموع | EM27: =SUM(EM23:EM26) -> 0 | EP27: أدوية منصرفة | EQ27: 1 | ER27: 2 | ES27: 3 | ET27: 4 | EU27: 5 | EV27: 6 | EX27: المجموع | EZ27: =SUM(EZ23:EZ26) -> 13785
B28: ='أسنان '!B339 -> 70 | C28: ='أسنان '!C339 -> 101 | D28: ='أسنان '!D339 -> 42 | E28: ='أسنان '!E339 -> 3 | F28: ='أسنان '!F339 -> 0 | G28: ='أسنان '!G339 -> 0 | N28: ='أسنان '!N339 -> 91 | O28: ='أسنان '!O339 -> 89 | P28: ='أسنان '!P339 -> 88 | Q28: ='أسنان '!Q339 -> 0 | R28: ='أسنان '!R339 -> 0 | S28: ='أسنان '!S339 -> 0 | Z28: ='أسنان '!Z339 -> #VALUE! | AA28: ='أسنان '!AA339 -> #VALUE! | AB28: ='أسنان '!AB339 -> #VALUE! | AC28: ='أسنان '!AC339 -> 0 | AD28: ='أسنان '!AD339 -> 0 | AE28: ='أسنان '!AE339 -> 0 | AL28: ='أسنان '!AL339 -> 135 | AM28: ='أسنان '!AM339 -> 201 | AN28: ='أسنان '!AN339 -> 95 | AO28: ='أسنان '!AO339 -> 0 | AP28: ='أسنان '!AP339 -> 0 | AQ28: ='أسنان '!AQ339 -> 0 | AX28: ='أسنان '!AX339 -> 170 | AY28: ='أسنان '!AY339 -> 177 | AZ28: ='أسنان '!AZ339 -> 72 | BA28: ='أسنان '!BA339 -> 0 | BB28: ='أسنان '!BB339 -> 0 | BC28: ='أسنان '!BC339 -> 0 | BJ28: ='أسنان '!BJ339 -> 107 | BK28: ='أسنان '!BK339 -> 94 | BL28: ='أسنان '!BL339 -> 47 | BM28: ='أسنان '!BM339 -> 0 | BN28: ='أسنان '!BN339 -> 0 | BO28: ='أسنان '!BO339 -> 0 | BV28: ='أسنان '!BV339 -> 102 | BW28: ='أسنان '!BW339 -> 147 | BX28: ='أسنان '!BX339 -> 62 | BY28: ='أسنان '!BY339 -> 0 | BZ28: ='أسنان '!BZ339 -> 0 | CA28: ='أسنان '!CA339 -> 0 | CH28: ='أسنان '!CH339 -> 23 | CI28: ='أسنان '!CI339 -> 29 | CJ28: ='أسنان '!CJ339 -> 18 | CK28: ='أسنان '!CK339 -> 0 | CL28: ='أسنان '!CL339 -> 0 | CM28: ='أسنان '!CM339 -> 0 | CT28: ='أسنان '!CT339 -> 0 | CU28: ='أسنان '!CU339 -> 0 | CV28: ='أسنان '!CV339 -> 0 | CW28: ='أسنان '!CW339 -> 0 | CX28: ='أسنان '!CX339 -> 0 | CY28: ='أسنان '!CY339 -> 0 | DF28: ='أسنان '!DF339 -> 75 | DG28: ='أسنان '!DG339 -> 127 | DH28: ='أسنان '!DH339 -> 72 | DI28: ='أسنان '!DI339 -> 0 | DJ28: ='أسنان '!DJ339 -> 0 | DK28: ='أسنان '!DK339 -> 0 | DR28: ='أسنان '!DR339 -> 0 | DS28: ='أسنان '!DS339 -> 0 | DT28: ='أسنان '!DT339 -> 0 | DU28: ='أسنان '!DU339 -> 0 | DV28: ='أسنان '!DV339 -> 0 | DW28: ='أسنان '!DW339 -> 0 | ED28: ='أسنان '!ED339 -> 0 | EE28: ='أسنان '!EE339 -> 0 | EF28: ='أسنان '!EF339 -> 0 | EG28: ='أسنان '!EG339 -> 0 | EH28: ='أسنان '!EH339 -> 0 | EI28: ='أسنان '!EI339 -> 0 | EQ28: =SUM(B28+N28+Z28+AL28+AX28+BJ28+BV28+CH28+CT28+DF28+DR28+ED28) -> #VALUE! | ER28: =SUM(C28+O28+AA28+AM28+AY28+BK28+BW28+CI28+CU28+DG28+DS28+EE28) -> #VALUE! | ES28: =SUM(D28+P28+AB28+AN28+AZ28+BL28+BX28+CJ28+CV28+DH28+DT28+EF28) -> #VALUE! | ET28: =SUM(E28+Q28+AC28+AO28+BA28+BM28+BY28+CK28+CW28+DI28+DU28+EG28) -> 3 | EU28: =SUM(F28+R28+AD28+AP28+BB28+BN28+BZ28+CL28+CX28+DJ28+DV28+EH28) -> 0 | EV28: =SUM(G28+S28+AE28+AQ28+BC28+BO28+CA28+CM28+CY28+DK28+DW28+EI28) -> 0
