Workbook

Sheet الفحوصات المخبرية
A1: مراكز شرق جدة | B1: 12 نشاط المختبر ( عدد المفحوصين ) | J1: شهر | K1: 1 | L1: عام | M1: 1447 | O1: هـ | S1: مراكز شرق جدة | T1: 12 نشاط المختبر ( عدد المفحوصين ) | AB1: شهر | AC1: 2 | AD1: عام | AE1: 1447 | AG1: هـ | AK1: مراكز شرق جدة | AL1: 12 نشاط المختبر ( عدد المفحوصين ) | AT1: شهر | AU1: 3 | AV1: عام | AW1: 1447 | AY1: هـ | BC1: مراكز شرق جدة | BD1: 12 نشاط المختبر ( عدد المفحوصين ) | BL1: شهر | BM1: 4 | BN1: عام | BO1: 1447 | BQ1: هـ | BU1: مراكز شرق جدة | BV1: 12 نشاط المختبر ( عدد المفحوصين ) | CD1: شهر | CE1: 5 | CF1: عام | CG1: 1447 | CI1: هـ | CM1: مراكز شرق جدة | CN1: 12 نشاط المختبر ( عدد المفحوصين ) | CV1: شهر | CW1: 6 | CX1: عام | CY1: 1447 | DA1: هـ | DE1: مراكز شرق جدة | DF1: 12 نشاط المختبر ( عدد المفحوصين ) | DN1: شهر | DO1: 7 | DP1: عام | DQ1: 1447 | DS1: هـ | DW1: مراكز شرق جدة | DX1: 12 نشاط المختبر ( عدد المفحوصين ) | EF1: شهر | EG1: 8 | EH1: عام | EI1: 1447 | EK1: هـ | EO1: مراكز شرق جدة | EP1: 12 نشاط المختبر ( عدد المفحوصين ) | EX1: شهر | EY1: 9 | EZ1: عام | FA1: 1447 | FC1: هـ | FG1: مراكز شرق جدة | FH1: 12 نشاط المختبر ( عدد المفحوصين ) | FP1: شهر | FQ1: 10 | FR1: عام | FS1: 1447 | FU1: هـ | FY1: مراكز شرق جدة | FZ1: 12 نشاط المختبر ( عدد المفحوصين ) | GH1: شهر | GI1: 11 | GJ1: عام | GK1: 1447 | GM1: هـ | GQ1: مراكز شرق جدة | GR1: 12 نشاط المختبر ( عدد المفحوصين ) | GZ1: شهر | HA1: 12 | HB1: عام | HC1: 1447 | HE1: هـ | HJ1: 12 نشاط المختبر ( عدد المفحوصين ) | HT1: عام | HU1: =SUM(HC1) -> 1447 | HW1: هـ
A2: المركز الصحي | B2: نوع الفحص | D2: الدم | M2: بول | O2: براز | P2: بصاق | Q2: المجموع | S2: المركز الصحي | T2: نوع الفحص | V2: الدم | AE2: بول | AG2: براز | AH2: بصاق | AI2: المجموع | AK2: المركز الصحي | AL2: نوع الفحص | AN2: الدم | AW2: بول | AY2: براز | AZ2: بصاق | BA2: المجموع | BC2: المركز الصحي | BD2: نوع الفحص | BF2: الدم | BO2: بول | BQ2: براز | BR2: بصاق | BS2: المجموع | BU2: المركز الصحي | BV2: نوع الفحص | BX2: الدم | CG2: بول | CI2: براز | CJ2: بصاق | CK2: المجموع | CM2: المركز الصحي | CN2: نوع الفحص | CP2: الدم | CY2: بول | DA2: براز | DB2: بصاق | DC2: المجموع | DE2: المركز الصحي | DF2: نوع الفحص | DH2: الدم | DQ2: بول | DS2: براز | DT2: بصاق | DU2: المجموع | DW2: المركز الصحي | DX2: نوع الفحص | DZ2: الدم | EI2: بول | EK2: براز | EL2: بصاق | EM2: المجموع | EO2: المركز الصحي | EP2: نوع الفحص | ER2: الدم | FA2: بول | FC2: براز | FD2: بصاق | FE2: المجموع | FG2: المركز الصحي | FH2: نوع الفحص | FJ2: الدم | FS2: بول | FU2: براز | FV2: بصاق | FW2: المجموع | FY2: المركز الصحي | FZ2: نوع الفحص | GB2: الدم | GK2: بول | GM2: براز | GN2: بصاق | GO2: المجموع | GQ2: المركز الصحي | GR2: نوع الفحص | GT2: الدم | HC2: بول | HE2: براز | HF2: بصاق | HG2: المجموع | HI2: المركز الصحي | HJ2: نوع الفحص | HL2: الدم | HU2: بول | HW2: براز | HX2: بصاق | HY2: المجموع
D3: شكلي | F3: مصلي | K3: كيماوي | V3: شكلي | X3: مصلي | AC3: كيماوي | AN3: شكلي | AP3: مصلي | AU3: كيماوي | BF3: شكلي | BH3: مصلي | BM3: كيماوي | BX3: شكلي | BZ3: مصلي | CE3: كيماوي | CP3: شكلي | CR3: مصلي | CW3: كيماوي | DH3: شكلي | DJ3: مصلي | DO3: كيماوي | DZ3: شكلي | EB3: مصلي | EG3: كيماوي | ER3: شكلي | ET3: مصلي | EY3: كيماوي | FJ3: شكلي | FL3: مصلي | FQ3: كيماوي | GB3: شكلي | GD3: مصلي | GI3: كيماوي | GT3: شكلي | GV3: مصلي | HA3: كيماوي | HL3: شكلي | HN3: مصلي | HS3: كيماوي
D4: صور الدم CBC | E4: سرعة الترسيب E.S.R | F4: فحص الإيــدز HIV | G4: فصائل الدم B.GROUP | H4: إلتهاب كبدي HEP | I4: فحص الحمل في الدم | J4: أخرى | K4: نسبة السكر الدم | L4: أخرى | M4: روتين | N4: حمل | V4: صور الدم CBC | W4: سرعة الترسيب E.S.R | X4: فحص الإيــدز HIV | Y4: فصائل الدم B.GROUP | Z4: إلتهاب كبدي HEP | AA4: فحص الحمل في الدم | AB4: أخرى | AC4: نسبة السكر الدم | AD4: أخرى | AE4: روتين | AF4: حمل | AN4: صور الدم CBC | AO4: سرعة الترسيب E.S.R | AP4: فحص الإيــدز HIV | AQ4: فصائل الدم B.GROUP | AR4: إلتهاب كبدي HEP | AS4: فحص الحمل في الدم | AT4: أخرى | AU4: نسبة السكر الدم | AV4: أخرى | AW4: روتين | AX4: حمل | BF4: صور الدم CBC | BG4: سرعة الترسيب E.S.R | BH4: فحص الإيــدز HIV | BI4: فصائل الدم B.GROUP | BJ4: إلتهاب كبدي HEP | BK4: فحص الحمل في الدم | BL4: أخرى | BM4: نسبة السكر الدم | BN4: أخرى | BO4: روتين | BP4: حمل | BX4: صور الدم CBC | BY4: سرعة الترسيب E.S.R | BZ4: فحص الإيــدز HIV | CA4: فصائل الدم B.GROUP | CB4: إلتهاب كبدي HEP | CC4: فحص الحمل في الدم | CD4: أخرى | CE4: نسبة السكر الدم | CF4: أخرى | CG4: روتين | CH4: حمل | CP4: صور الدم CBC | CQ4: سرعة الترسيب E.S.R | CR4: فحص الإيــدز HIV | CS4: فصائل الدم B.GROUP | CT4: إلتهاب كبدي HEP | CU4: فحص الحمل في الدم | CV4: أخرى | CW4: نسبة السكر الدم | CX4: أخرى | CY4: روتين | CZ4: حمل | DH4: صور الدم CBC | DI4: سرعة الترسيب E.S.R | DJ4: فحص الإيــدز HIV | DK4: فصائل الدم B.GROUP | DL4: إلتهاب كبدي HEP | DM4: فحص الحمل في الدم | DN4: أخرى | DO4: نسبة السكر الدم | DP4: أخرى | DQ4: روتين | DR4: حمل | DZ4: صور الدم CBC | EA4: سرعة الترسيب E.S.R | EB4: فحص الإيــدز HIV | EC4: فصائل الدم B.GROUP | ED4: إلتهاب كبدي HEP | EE4: فحص الحمل في الدم | EF4: أخرى | EG4: نسبة السكر الدم | EH4: أخرى | EI4: روتين | EJ4: حمل | ER4: صور الدم CBC | ES4: سرعة الترسيب E.S.R | ET4: فحص الإيــدز HIV | EU4: فصائل الدم B.GROUP | EV4: إلتهاب كبدي HEP | EW4: فحص الحمل في الدم | EX4: أخرى | EY4: نسبة السكر الدم | EZ4: أخرى | FA4: روتين | FB4: حمل | FJ4: صور الدم CBC | FK4: سرعة الترسيب E.S.R | FL4: فحص الإيــدز HIV | FM4: فصائل الدم B.GROUP | FN4: إلتهاب كبدي HEP | FO4: فحص الحمل في الدم | FP4: أخرى | FQ4: نسبة السكر الدم | FR4: أخرى | FS4: روتين | FT4: حمل | GB4: صور الدم CBC | GC4: سرعة الترسيب E.S.R | GD4: فحص الإيــدز HIV | GE4: فصائل الدم B.GROUP | GF4: إلتهاب كبدي HEP | GG4: فحص الحمل في الدم | GH4: أخرى | GI4: نسبة السكر الدم | GJ4: أخرى | GK4: روتين | GL4: حمل | GT4: صور الدم CBC | GU4: سرعة الترسيب E.S.R | GV4: فحص الإيــدز HIV | GW4: فصائل الدم B.GROUP | GX4: إلتهاب كبدي HEP | GY4: فحص الحمل في الدم | GZ4: أخرى | HA4: نسبة السكر الدم | HB4: أخرى | HC4: روتين | HD4: حمل | HL4: صور الدم CBC | HM4: سرعة الترسيب E.S.R | HN4: فحص الإيــدز HIV | HO4: فصائل الدم B.GROUP | HP4: إلتهاب كبدي HEP | HQ4: فحص الحمل في الدم | HR4: أخرى | HS4: نسبة السكر الدم | HT4: أخرى | HU4: روتين | HV4: حمل
B5: الجنسية | C5: الجنس | T5: الجنسية | U5: الجنس | AL5: الجنسية | AM5: الجنس | BD5: الجنسية | BE5: الجنس | BV5: الجنسية | BW5: الجنس | CN5: الجنسية | CO5: الجنس | DF5: الجنسية | DG5: الجنس | DX5: الجنسية | DY5: الجنس | EP5: الجنسية | EQ5: الجنس | FH5: الجنسية | FI5: الجنس | FZ5: الجنسية | GA5: الجنس | GR5: الجنسية | GS5: الجنس | HJ5: الجنسية | HK5: الجنس
A6: الربيع والتوفيق | B6: سعودي | C6: ذكر | D6: 132 | E6: 0 | F6: 15 | G6: 125 | H6: 15 | I6: 0 | J6: 0 | K6: 257 | L6: 0 | M6: 37 | N6: 0 | O6: 16 | P6: 0 | Q6: =SUM(D6:P6) -> 597 | S6: الربيع والتوفيق | T6: سعودي | U6: ذكر | V6: 101 | W6: 0 | X6: 11 | Y6: 23 | Z6: 60 | AA6: 0 | AB6: 110 | AC6: 82 | AD6: 70 | AE6: 0 | AF6: 0 | AG6: 25 | AH6: 0 | AI6: =SUM(V6:AH6) -> 482 | AK6: الربيع والتوفيق | AL6: سعودي | AM6: ذكر | AN6: 103 | AO6: 0 | AP6: 8 | AQ6: 9 | AR6: 23 | AS6: 0 | AT6: 133 | AU6: 105 | AV6: 256 | AW6: 72 | AX6: 0 | AY6: 16 | AZ6: 0 | BA6: =SUM(AN6:AZ6) -> 725 | BC6: الربيع والتوفيق | BD6: سعودي | BE6: ذكر | BF6: 93 | BG6: 1 | BH6: 9 | BI6: 12 | BJ6: 25 | BK6: 0 | BL6: 150 | BM6: 100 | BN6: 250 | BO6: 68 | BP6: 0 | BQ6: 0 | BR6: 0 | BS6: =SUM(BF6:BR6) -> 708 | BU6: الربيع والتوفيق | BV6: سعودي | BW6: ذكر | BX6: 254 | BY6: 0 | BZ6: 51 | CA6: 55 | CB6: 65 | CC6: 0 | CD6: 312 | CE6: 621 | CF6: 125 | CG6: 201 | CH6: 0 | CI6: 0 | CJ6: 0 | CK6: =SUM(BX6:CJ6) -> 1684 | CM6: الربيع والتوفيق | CN6: سعودي | CO6: ذكر | CP6: 93 | CQ6: 1 | CR6: 9 | CS6: 12 | CT6: 25 | CU6: 0 | CV6: 150 | CW6: 100 | CX6: 250 | CY6: 68 | CZ6: 0 | DA6: 36 | DB6: 0 | DC6: =SUM(CP6:DB6) -> 744 | DE6: الربيع والتوفيق | DF6: سعودي | DG6: ذكر | DH6: 95 | DI6: 0 | DJ6: 10 | DK6: 20 | DL6: 60 | DM6: 0 | DN6: 101 | DO6: 80 | DP6: 70 | DQ6: 0 | DR6: 0 | DS6: 20 | DT6: 0 | DU6: 597 | DW6: الربيع والتوفيق | DX6: سعودي | DY6: ذكر | DZ6: 93 | EA6: 1 | EB6: 9 | EC6: 12 | ED6: 25 | EE6: 0 | EF6: 150 | EG6: 100 | EH6: 250 | EI6: 68 | EJ6: 0 | EK6: 36 | EL6: 0 | EM6: =SUM(DZ6:EL6) -> 744 | EO6: الربيع والتوفيق | EP6: سعودي | EQ6: ذكر | ER6: 95 | ES6: 0 | ET6: 10 | EU6: 20 | EV6: 60 | EW6: 0 | EX6: 101 | EY6: 80 | EZ6: 70 | FA6: 0 | FB6: 0 | FC6: 20 | FD6: 0 | FE6: =SUM(ER6:FD6) -> 456 | FG6: الربيع والتوفيق | FH6: سعودي | FI6: ذكر | FJ6: 122 | FK6: 0 | FL6: 15 | FM6: 125 | FN6: 15 | FO6: 0 | FP6: 0 | FQ6: 257 | FR6: 0 | FS6: 37 | FT6: 0 | FU6: 15 | FV6: 0 | FW6: 586 | FY6: الربيع والتوفيق | FZ6: سعودي | GA6: ذكر | GB6: 0 | GC6: 0 | GD6: 0 | GE6: 0 | GF6: 0 | GG6: 0 | GH6: 0 | GI6: 0 | GJ6: 0 | GK6: 0 | GL6: 0 | GM6: 0 | GN6: 0 | GO6: =SUM(GB6:GN6) -> 0 | GQ6: الربيع والتوفيق | GR6: سعودي | GS6: ذكر | GT6: 0 | GU6: 0 | GV6: 0 | GW6: 0 | GX6: 0 | GY6: 0 | GZ6: 0 | HA6: 0 | HB6: 0 | HC6: 0 | HD6: 0 | HE6: 0 | HF6: 0 | HG6: =SUM(GT6:HF6) -> 0 | HI6: =GQ6 -> الربيع والتوفيق | HJ6: سعودي | HK6: ذكر | HL6: =SUM(D6+V6+AN6+BF6+BX6+CP6+DH6+DZ6+ER6+FJ6+GB6+GT6) -> 1181 | HM6: =SUM(E6+W6+AO6+BG6+BY6+CQ6+DI6+EA6+ES6+FK6+GC6+GU6) -> 3 | HN6: =SUM(F6+X6+AP6+BH6+BZ6+CR6+DJ6+EB6+ET6+FL6+GD6+GV6) -> 147 | HO6: =SUM(G6+Y6+AQ6+BI6+CA6+CS6+DK6+EC6+EU6+FM6+GE6+GW6) -> 413 | HP6: =SUM(H6+Z6+AR6+BJ6+CB6+CT6+DL6+ED6+EV6+FN6+GF6+GX6) -> 373 | HQ6: =SUM(I6+AA6+AS6+BK6+CC6+CU6+DM6+EE6+EW6+FO6+GG6+GY6) -> 0 | HR6: =SUM(J6+AB6+AT6+BL6+CD6+CV6+DN6+EF6+EX6+FP6+GH6+GZ6) -> 1207 | HS6: =SUM(K6+AC6+AU6+BM6+CE6+CW6+DO6+EG6+EY6+FQ6+GI6+HA6) -> 1782 | ... HX6: =SUM(P6+AH6+AZ6+BR6+CJ6+DB6+DT6+EL6+FD6+FV6+GN6+HF6) -> 0 | HY6: =SUM(HL6:HX6) -> 7182
C7: أنثى | D7: 144 | E7: 0 | F7: 27 | G7: 156 | H7: 27 | I7: 0 | J7: 0 | K7: 261 | L7: 0 | M7: 71 | N7: 56 | O7: 8 | P7: 0 | Q7: =SUM(D7:P7) -> 750 | U7: أنثى | V7: 85 | W7: 0 | X7: 26 | Y7: 48 | Z7: 82 | AA7: 0 | AB7: 122 | AC7: 90 | AD7: 99 | AE7: 0 | AF7: 80 | AG7: 39 | AH7: 0 | AI7: =SUM(V7:AH7) -> 671 | AM7: أنثى | AN7: 116 | AO7: 0 | AP7: 48 | AQ7: 16 | AR7: 58 | AS7: 0 | AT7: 128 | AU7: 126 | AV7: 313 | AW7: 123 | AX7: 66 | AY7: 54 | AZ7: 0 | BA7: =SUM(AN7:AZ7) -> 1048 | BE7: أنثى | BF7: 112 | BG7: 3 | BH7: 64 | BI7: 21 | BJ7: 66 | BK7: 0 | BL7: 120 | BM7: 135 | BN7: 300 | BO7: 119 | BP7: 0 | BQ7: 83 | BR7: 0 | BS7: =SUM(BF7:BR7) -> 1023 | BW7: أنثى | BX7: 371 | BY7: 0 | BZ7: 201 | CA7: 101 | CB7: 122 | CC7: 0 | CD7: 451 | CE7: 701 | CF7: 202 | CG7: 335 | CH7: 98 | CI7: 0 | CJ7: 0 | CK7: =SUM(BX7:CJ7) -> 2582 | CO7: أنثى | CP7: 112 | CQ7: 3 | CR7: 64 | CS7: 21 | CT7: 66 | CU7: 0 | CV7: 120 | CW7: 135 | CX7: 300 | CY7: 119 | CZ7: 83 | DA7: 57 | DB7: 0 | DC7: =SUM(CP7:DB7) -> 1080 | DG7: أنثى | DH7: 80 | DI7: 0 | DJ7: 23 | DK7: 44 | DL7: 82 | DM7: 0 | DN7: 121 | DO7: 86 | DP7: 99 | DQ7: 0 | DR7: 70 | DS7: 35 | DT7: 0 | DU7: 750 | DY7: أنثى | DZ7: 112 | EA7: 3 | EB7: 64 | EC7: 21 | ED7: 66 | EE7: 0 | EF7: 120 | EG7: 135 | EH7: 300 | EI7: 119 | EJ7: 83 | EK7: 57 | EL7: 0 | EM7: =SUM(DZ7:EL7) -> 1080 | EQ7: أنثى | ER7: 80 | ES7: 0 | ET7: 23 | EU7: 44 | EV7: 82 | EW7: 0 | EX7: 121 | EY7: 86 | EZ7: 99 | FA7: 0 | FB7: 70 | FC7: 35 | FD7: 0 | FE7: =SUM(ER7:FD7) -> 640 | FI7: أنثى | FJ7: 142 | FK7: 0 | FL7: 27 | FM7: 156 | FN7: 27 | FO7: 0 | FP7: 0 | FQ7: 261 | FR7: 0 | FS7: 71 | FT7: 56 | FU7: 7 | FV7: 0 | FW7: 747 | GA7: أنثى | GB7: 0 | GC7: 0 | GD7: 0 | GE7: 0 | GF7: 0 | GG7: 0 | GH7: 0 | GI7: 0 | GJ7: 0 | GK7: 0 | GL7: 0 | GM7: 0 | GN7: 0 | GO7: =SUM(GB7:GN7) -> 0 | GS7: أنثى | GT7: 0 | GU7: 0 | GV7: 0 | GW7: 0 | GX7: 0 | GY7: 0 | GZ7: 0 | HA7: 0 | HB7: 0 | HC7: 0 | HD7: 0 | HE7: 0 | HF7: 0 | HG7: =SUM(GT7:HF7) -> 0 | HK7: أنثى | HL7: =SUM(D7+V7+AN7+BF7+BX7+CP7+DH7+DZ7+ER7+FJ7+GB7+GT7) -> 1354 | HM7: =SUM(E7+W7+AO7+BG7+BY7+CQ7+DI7+EA7+ES7+FK7+GC7+GU7) -> 9 | HN7: =SUM(F7+X7+AP7+BH7+BZ7+CR7+DJ7+EB7+ET7+FL7+GD7+GV7) -> 567 | HO7: =SUM(G7+Y7+AQ7+BI7+CA7+CS7+DK7+EC7+EU7+FM7+GE7+GW7) -> 628 | HP7: =SUM(H7+Z7+AR7+BJ7+CB7+CT7+DL7+ED7+EV7+FN7+GF7+GX7) -> 678 | HQ7: =SUM(I7+AA7+AS7+BK7+CC7+CU7+DM7+EE7+EW7+FO7+GG7+GY7) -> 0 | HR7: =SUM(J7+AB7+AT7+BL7+CD7+CV7+DN7+EF7+EX7+FP7+GH7+GZ7) -> 1303 | HS7: =SUM(K7+AC7+AU7+BM7+CE7+CW7+DO7+EG7+EY7+FQ7+GI7+HA7) -> 2016 | ... HX7: =SUM(P7+AH7+AZ7+BR7+CJ7+DB7+DT7+EL7+FD7+FV7+GN7+HF7) -> 0 | HY7: =SUM(HL7:HX7) -> 10261
B8: مجموع السعوديين | D8: 276 | F8: 365 | K8: 518 | M8: 164 | O8: 24 | P8: 0 | Q8: =SUM(Q6:Q7) -> 1347 | T8: مجموع السعوديين | V8: 186 | X8: 482 | AC8: 341 | AE8: 80 | AG8: 64 | AH8: 0 | AI8: =SUM(AI6:AI7) -> 1153 | AL8: مجموع السعوديين | AN8: 219 | AP8: 423 | AU8: 800 | AW8: 261 | AY8: 70 | AZ8: 0 | BA8: =SUM(BA6:BA7) -> 1773 | BD8: مجموع السعوديين | BF8: 209 | BH8: 467 | BM8: 785 | BO8: 187 | BQ8: 83 | BR8: =SUM(BR6:BR7) -> 0 | BS8: =SUM(BS6:BS7) -> 1731 | BV8: مجموع السعوديين | BX8: 625 | BZ8: 1358 | CE8: 1649 | CG8: 634 | CI8: 0 | CJ8: 0 | CK8: =SUM(CK6:CK7) -> 4266 | CN8: مجموع السعوديين | CP8: 209 | CR8: 467 | CW8: 785 | CY8: 270 | DA8: 93 | DB8: 0 | DC8: =SUM(DC6:DC7) -> 1824 | DF8: مجموع السعوديين | DH8: 175 | DJ8: 461 | DO8: 335 | DQ8: 70 | DS8: 55 | DT8: 0 | DU8: 1347 | DX8: مجموع السعوديين | DZ8: =SUM(DZ6:EA7) -> 209 | EB8: =SUM(EB6:EF7) -> 467 | EG8: =SUM(EG6:EH7) -> 785 | EI8: =SUM(EI6:EJ7) -> 270 | EK8: =SUM(EK6:EK7) -> 93 | EL8: =SUM(EL6:EL7) -> 0 | EM8: =SUM(EM6:EM7) -> 1824 | EP8: مجموع السعوديين | ER8: =SUM(ER6:ES7) -> 175 | ET8: =SUM(ET6:EX7) -> 461 | EY8: =SUM(EY6:EZ7) -> 335 | FA8: =SUM(FA6:FB7) -> 70 | FC8: =SUM(FC6:FC7) -> 55 | FD8: =SUM(FD6:FD7) -> 0 | FE8: =SUM(FE6:FE7) -> 1096 | FH8: مجموع السعوديين | FJ8: 264 | FL8: 365 | FQ8: 518 | FS8: 164 | FU8: 22 | FV8: 0 | FW8: 1333 | FZ8: مجموع السعوديين | GB8: =SUM(GB6:GC7) -> 0 | GD8: =SUM(GD6:GH7) -> 0 | GI8: =SUM(GI6:GJ7) -> 0 | GK8: =SUM(GK6:GL7) -> 0 | GM8: =SUM(GM6:GM7) -> 0 | GN8: =SUM(GN6:GN7) -> 0 | GO8: =SUM(GO6:GO7) -> 0 | GR8: مجموع السعوديين | GT8: =SUM(GT6:GU7) -> 0 | GV8: =SUM(GV6:GZ7) -> 0 | HA8: =SUM(HA6:HB7) -> 0 | HC8: =SUM(HC6:HD7) -> 0 | HE8: =SUM(HE6:HE7) -> 0 | HF8: =SUM(HF6:HF7) -> 0 | HG8: =SUM(HG6:HG7) -> 0 | HJ8: مجموع السعوديين | HL8: =SUM(HL6:HM7) -> 2547 | HN8: =SUM(HN6:HR7) -> 5316 | HS8: =SUM(HS6:HT7) -> 6851 | HU8: =SUM(HU6:HV7) -> 2170 | HW8: =SUM(HW6:HW7) -> 559 | HX8: =SUM(HX6:HX7) -> 0 | HY8: =SUM(HY6:HY7) -> 17443
B9: غير سعودي | C9: ذكر | D9: 1 | E9: 0 | F9: 0 | G9: 0 | H9: 2 | I9: 0 | J9: 0 | K9: 0 | L9: 0 | M9: 0 | N9: 0 | O9: 5 | P9: 0 | Q9: =SUM(D9:P9) -> 8 | T9: غير سعودي | U9: ذكر | V9: 20 | W9: 0 | X9: 2 | Y9: 7 | Z9: 10 | AA9: 0 | AB9: 22 | AC9: 30 | AD9: 20 | AE9: 0 | AF9: 0 | AG9: 6 | AH9: 0 | AI9: =SUM(V9:AH9) -> 117 | AL9: غير سعودي | AM9: ذكر | AN9: 58 | AO9: 0 | AP9: 4 | AQ9: 1 | AR9: 3 | AS9: 0 | AT9: 108 | AU9: 116 | AV9: 88 | AW9: 36 | AX9: 0 | AY9: 22 | AZ9: 0 | BA9: =SUM(AN9:AZ9) -> 436 | BD9: غير سعودي | BE9: ذكر | BF9: 52 | BG9: 1 | BH9: 6 | BI9: 3 | BJ9: 7 | BK9: 0 | BL9: 102 | BM9: 95 | BN9: 65 | BO9: 35 | BP9: 0 | BQ9: 0 | BR9: 0 | BS9: =SUM(BF9:BR9) -> 366 | BV9: غير سعودي | BW9: ذكر | BX9: 90 | BY9: 0 | BZ9: 51 | CA9: 41 | CB9: 121 | CC9: 0 | CD9: 88 | CE9: 102 | CF9: 128 | CG9: 95 | CH9: 0 | CI9: 0 | CJ9: 0 | CK9: =SUM(BX9:CJ9) -> 716 | CN9: غير سعودي | CO9: ذكر | CP9: 52 | CQ9: 1 | CR9: 73 | CS9: 3 | CT9: 7 | CU9: 0 | CV9: 102 | CW9: 95 | CX9: 65 | CY9: 35 | CZ9: 0 | DA9: 20 | DB9: 0 | DC9: =SUM(CP9:DB9) -> 453 | DF9: غير سعودي | DG9: ذكر | DH9: 20 | DI9: 0 | DJ9: 2 | DK9: 7 | DL9: 10 | DM9: 0 | DN9: 22 | DO9: 30 | DP9: 20 | DQ9: 0 | DR9: 0 | DS9: 6 | DT9: 0 | DU9: 117 | DX9: غير سعودي | DY9: ذكر | DZ9: 52 | EA9: 1 | EB9: 73 | EC9: 3 | ED9: 7 | EE9: 0 | EF9: 102 | EG9: 95 | EH9: 65 | EI9: 35 | EJ9: 0 | EK9: 20 | EL9: 0 | EM9: =SUM(DZ9:EL9) -> 453 | EP9: غير سعودي | EQ9: ذكر | ER9: 20 | ES9: 0 | ET9: 2 | EU9: 7 | EV9: 10 | EW9: 0 | EX9: 22 | EY9: 30 | EZ9: 20 | FA9: 0 | FB9: 0 | FC9: 6 | FD9: 0 | FE9: =SUM(ER9:FD9) -> 117 | FH9: غير سعودي | FI9: ذكر | FJ9: 18 | FK9: 0 | FL9: 5 | FM9: 51 | FN9: 3 | FO9: 0 | FP9: 0 | FQ9: 78 | FR9: 0 | FS9: 10 | FT9: 0 | FU9: 8 | FV9: 0 | FW9: 173 | FZ9: غير سعودي | GA9: ذكر | GB9: 0 | GC9: 0 | GD9: 0 | GE9: 0 | GF9: 0 | GG9: 0 | GH9: 0 | GI9: 0 | GJ9: 0 | GK9: 0 | GL9: 0 | GM9: 0 | GN9: 0 | GO9: =SUM(GB9:GN9) -> 0 | GR9: غير سعودي | GS9: ذكر | GT9: 0 | GU9: 0 | GV9: 0 | GW9: 0 | GX9: 0 | GY9: 0 | GZ9: 0 | HA9: 0 | HB9: 0 | HC9: 0 | HD9: 0 | HE9: 0 | HF9: 0 | HG9: =SUM(GT9:HF9) -> 0 | HJ9: غير سعودي | HK9: ذكر | HL9: =SUM(D9+V9+AN9+BF9+BX9+CP9+DH9+DZ9+ER9+FJ9+GB9+GT9) -> 383 | HM9: =SUM(E9+W9+AO9+BG9+BY9+CQ9+DI9+EA9+ES9+FK9+GC9+GU9) -> 3 | HN9: =SUM(F9+X9+AP9+BH9+BZ9+CR9+DJ9+EB9+ET9+FL9+GD9+GV9) -> 218 | HO9: =SUM(G9+Y9+AQ9+BI9+CA9+CS9+DK9+EC9+EU9+FM9+GE9+GW9) -> 123 | HP9: =SUM(H9+Z9+AR9+BJ9+CB9+CT9+DL9+ED9+EV9+FN9+GF9+GX9) -> 180 | HQ9: =SUM(I9+AA9+AS9+BK9+CC9+CU9+DM9+EE9+EW9+FO9+GG9+GY9) -> 0 | HR9: =SUM(J9+AB9+AT9+BL9+CD9+CV9+DN9+EF9+EX9+FP9+GH9+GZ9) -> 568 | HS9: =SUM(K9+AC9+AU9+BM9+CE9+CW9+DO9+EG9+EY9+FQ9+GI9+HA9) -> 671 | ... HX9: =SUM(P9+AH9+AZ9+BR9+CJ9+DB9+DT9+EL9+FD9+FV9+GN9+HF9) -> 0 | HY9: =SUM(HL9:HX9) -> 2956
C10: أنثى | D10: 1 | E10: 0 | F10: 0 | G10: 0 | H10: 2 | I10: 0 | J10: 0 | K10: 0 | L10: 0 | M10: 0 | N10: 0 | O10: 5 | P10: 0 | Q10: =SUM(D10:P10) -> 8 | U10: أنثى | V10: 22 | W10: 0 | X10: 4 | Y10: 9 | Z10: 15 | AA10: 0 | AB10: 18 | AC10: 35 | AD10: 32 | AE10: 0 | AF10: 0 | AG10: 8 | AH10: 0 | AI10: =SUM(V10:AH10) -> 143 | AM10: أنثى | AN10: 79 | AO10: 0 | AP10: 66 | AQ10: 13 | AR10: 83 | AS10: 0 | AT10: 122 | AU10: 98 | AV10: 108 | AW10: 82 | AX10: 4 | AY10: 28 | AZ10: 0 | BA10: =SUM(AN10:AZ10) -> 683 | BE10: أنثى | BF10: 76 | BG10: 2 | BH10: 58 | BI10: 18 | BJ10: 53 | BK10: 0 | BL10: 116 | BM10: 115 | BN10: 74 | BO10: 84 | BP10: 0 | BQ10: 49 | BR10: 0 | BS10: =SUM(BF10:BR10) -> 645 | BW10: أنثى | BX10: 102 | BY10: 0 | BZ10: 80 | CA10: 60 | CB10: 135 | CC10: 0 | CD10: 95 | CE10: 225 | CF10: 152 | CG10: 0 | CH10: 42 | CI10: 0 | CJ10: 0 | CK10: =SUM(BX10:CJ10) -> 891 | CO10: أنثى | CP10: 76 | CQ10: 2 | CR10: 6 | CS10: 18 | CT10: 53 | CU10: 0 | CV10: 116 | CW10: 115 | CX10: 74 | CY10: 84 | CZ10: 49 | DA10: 32 | DB10: 0 | DC10: =SUM(CP10:DB10) -> 625 | DG10: أنثى | DH10: 22 | DI10: 0 | DJ10: 4 | DK10: 9 | DL10: 15 | DM10: 0 | DN10: 18 | DO10: 35 | DP10: 32 | DQ10: 0 | DR10: 0 | DS10: 8 | DT10: 0 | DU10: 143 | DY10: أنثى | DZ10: 76 | EA10: 2 | EB10: 6 | EC10: 18 | ED10: 53 | EE10: 0 | EF10: 116 | EG10: 115 | EH10: 74 | EI10: 84 | EJ10: 49 | EK10: 32 | EL10: 0 | EM10: =SUM(DZ10:EL10) -> 625 | EQ10: أنثى | ER10: 22 | ES10: 0 | ET10: 4 | EU10: 6 | EV10: 15 | EW10: 0 | EX10: 18 | EY10: 35 | EZ10: 32 | FA10: 0 | FB10: 0 | FC10: 8 | FD10: 0 | FE10: =SUM(ER10:FD10) -> 140 | FI10: أنثى | FJ10: 57 | FK10: 0 | FL10: 12 | FM10: 62 | FN10: 12 | FO10: 0 | FP10: 0 | FQ10: 93 | FR10: 0 | FS10: 35 | FT10: 11 | FU10: 12 | FV10: 0 | FW10: 294 | GA10: أنثى | GB10: 0 | GC10: 0 | GD10: 0 | GE10: 0 | GF10: 0 | GG10: 0 | GH10: 0 | GI10: 0 | GJ10: 0 | GK10: 0 | GL10: 0 | GM10: 0 | GN10: 0 | GO10: =SUM(GB10:GN10) -> 0 | GS10: أنثى | GT10: 0 | GU10: 0 | GV10: 0 | GW10: 0 | GX10: 0 | GY10: 0 | GZ10: 0 | HA10: 0 | HB10: 0 | HC10: 0 | HD10: 0 | HE10: 0 | HF10: 0 | HG10: =SUM(GT10:HF10) -> 0 | HK10: أنثى | HL10: =SUM(D10+V10+AN10+BF10+BX10+CP10+DH10+DZ10+ER10+FJ10+GB10+GT10) -> 533 | HM10: =SUM(E10+W10+AO10+BG10+BY10+CQ10+DI10+EA10+ES10+FK10+GC10+GU10) -> 6 | HN10: =SUM(F10+X10+AP10+BH10+BZ10+CR10+DJ10+EB10+ET10+FL10+GD10+GV10) -> 240 | HO10: =SUM(G10+Y10+AQ10+BI10+CA10+CS10+DK10+EC10+EU10+FM10+GE10+GW10) -> 213 | HP10: =SUM(H10+Z10+AR10+BJ10+CB10+CT10+DL10+ED10+EV10+FN10+GF10+GX10) -> 436 | HQ10: =SUM(I10+AA10+AS10+BK10+CC10+CU10+DM10+EE10+EW10+FO10+GG10+GY10) -> 0 | HR10: =SUM(J10+AB10+AT10+BL10+CD10+CV10+DN10+EF10+EX10+FP10+GH10+GZ10) -> 619 | HS10: =SUM(K10+AC10+AU10+BM10+CE10+CW10+DO10+EG10+EY10+FQ10+GI10+HA10) -> 866 | ... HX10: =SUM(P10+AH10+AZ10+BR10+CJ10+DB10+DT10+EL10+FD10+FV10+GN10+HF10) -> 0 | HY10: =SUM(HL10:HX10) -> 4197
B11: مجموع الغير سعوديين | D11: =SUM(D9:E10) -> 2 | F11: =SUM(F9:J10) -> 4 | K11: =SUM(K9:L10) -> 0 | M11: =SUM(M9:N10) -> 0 | O11: =SUM(O9:O10) -> 10 | P11: =SUM(P9:P10) -> 0 | Q11: =SUM(Q9:Q10) -> 16 | T11: مجموع الغير سعوديين | V11: =SUM(V9:W10) -> 42 | X11: =SUM(X9:AB10) -> 87 | AC11: =SUM(AC9:AD10) -> 117 | AE11: =SUM(AE9:AF10) -> 0 | AG11: =SUM(AG9:AG10) -> 14 | AH11: =SUM(AH9:AH10) -> 0 | AI11: =SUM(AI9:AI10) -> 260 | AL11: مجموع الغير سعوديين | AN11: =SUM(AN9:AO10) -> 137 | AP11: =SUM(AP9:AT10) -> 400 | AU11: =SUM(AU9:AV10) -> 410 | AW11: =SUM(AW9:AX10) -> 122 | AY11: =SUM(AY9:AY10) -> 50 | AZ11: =SUM(AZ9:AZ10) -> 0 | BA11: =SUM(BA9:BA10) -> 1119 | BD11: مجموع الغير سعوديين | BF11: 131 | BH11: 363 | BM11: 349 | BO11: 119 | BQ11: 49 | BR11: =SUM(BR9:BR10) -> 0 | BS11: =SUM(BS9:BS10) -> 1011 | BV11: مجموع الغير سعوديين | BX11: =SUM(BX9:BY10) -> 192 | BZ11: =SUM(BZ9:CD10) -> 671 | CE11: =SUM(CE9:CF10) -> 607 | CG11: =SUM(CG9:CH10) -> 137 | CI11: =SUM(CI9:CI10) -> 0 | CJ11: =SUM(CJ9:CJ10) -> 0 | CK11: =SUM(CK9:CK10) -> 1607 | CN11: مجموع الغير سعوديين | CP11: 131 | CR11: 378 | CW11: 349 | CY11: 168 | DA11: 52 | DB11: 0 | DC11: =SUM(DC9:DC10) -> 1078 | DF11: مجموع الغير سعوديين | DH11: 42 | DJ11: 87 | DO11: 117 | DQ11: 0 | DS11: 14 | DT11: 0 | DU11: 260 | DX11: مجموع الغير سعوديين | DZ11: =SUM(DZ9:EA10) -> 131 | EB11: =SUM(EB9:EF10) -> 378 | EG11: =SUM(EG9:EH10) -> 349 | EI11: =SUM(EI9:EJ10) -> 168 | EK11: =SUM(EK9:EK10) -> 52 | EL11: =SUM(EL9:EL10) -> 0 | EM11: =SUM(EM9:EM10) -> 1078 | EP11: مجموع الغير سعوديين | ER11: =SUM(ER9:ES10) -> 42 | ET11: =SUM(ET9:EX10) -> 84 | EY11: =SUM(EY9:EZ10) -> 117 | FA11: =SUM(FA9:FB10) -> 0 | FC11: =SUM(FC9:FC10) -> 14 | FD11: =SUM(FD9:FD10) -> 0 | FE11: =SUM(FE9:FE10) -> 257 | FH11: مجموع الغير سعوديين | FJ11: 75 | FL11: 145 | FQ11: 171 | FS11: 56 | FU11: 20 | FV11: 0 | FW11: 467 | FZ11: مجموع الغير سعوديين | GB11: =SUM(GB9:GC10) -> 0 | GD11: =SUM(GD9:GH10) -> 0 | GI11: =SUM(GI9:GJ10) -> 0 | GK11: =SUM(GK9:GL10) -> 0 | GM11: =SUM(GM9:GM10) -> 0 | GN11: =SUM(GN9:GN10) -> 0 | GO11: =SUM(GO9:GO10) -> 0 | GR11: مجموع الغير سعوديين | GT11: =SUM(GT9:GU10) -> 0 | GV11: =SUM(GV9:GZ10) -> 0 | HA11: =SUM(HA9:HB10) -> 0 | HC11: =SUM(HC9:HD10) -> 0 | HE11: =SUM(HE9:HE10) -> 0 | HF11: =SUM(HF9:HF10) -> 0 | HG11: =SUM(HG9:HG10) -> 0 | HJ11: مجمع الغير سعوديين | HL11: =SUM(HL9:HM10) -> 925 | HN11: =SUM(HN9:HR10) -> 2597 | HS11: =SUM(HS9:HT10) -> 2586 | HU11: =SUM(HU9:HV10) -> 770 | HW11: =SUM(HW9:HW10) -> 275 | HX11: =SUM(HX9:HX10) -> 0 | HY11: =SUM(HY9:HY10) -> 7153
B12: المجموع الكلي | D12: =SUM(D8+D11) -> 278 | F12: =SUM(F8+F11) -> 369 | K12: =SUM(K8+K11) -> 518 | M12: =SUM(M8+M11) -> 164 | O12: =SUM(O8+O11) -> 34 | P12: =SUM(P8+P11) -> 0 | Q12: =SUM(Q8+Q11) -> 1363 | T12: المجموع الكلي | V12: =SUM(V8+V11) -> 228 | X12: =SUM(X8+X11) -> 569 | AC12: =SUM(AC8+AC11) -> 458 | AE12: =SUM(AE8+AE11) -> 80 | AG12: =SUM(AG8+AG11) -> 78 | AH12: =SUM(AH8+AH11) -> 0 | AI12: =SUM(AI8+AI11) -> 1413 | AL12: المجموع الكلي | AN12: =SUM(AN8+AN11) -> 356 | AP12: =SUM(AP8+AP11) -> 823 | AU12: =SUM(AU8+AU11) -> 1210 | AW12: =SUM(AW8+AW11) -> 383 | AY12: =SUM(AY8+AY11) -> 120 | AZ12: =SUM(AZ8+AZ11) -> 0 | BA12: =SUM(BA8+BA11) -> 2892 | BD12: المجموع الكلي | BF12: 340 | BH12: 830 | BM12: 1134 | BO12: 306 | BQ12: 132 | BR12: =SUM(BR8+BR11) -> 0 | BS12: =SUM(BS8+BS11) -> 2742 | BV12: المجموع الكلي | BX12: =SUM(BX8+BX11) -> 817 | BZ12: =SUM(BZ8+BZ11) -> 2029 | CE12: =SUM(CE8+CE11) -> 2256 | CG12: =SUM(CG8+CG11) -> 771 | CI12: =SUM(CI8+CI11) -> 0 | CJ12: =SUM(CJ8+CJ11) -> 0 | CK12: =SUM(CK8+CK11) -> 5873 | CN12: المجموع الكلي | CP12: 340 | CR12: 845 | CW12: 1134 | CY12: 438 | DA12: 145 | DB12: 0 | DC12: =SUM(DC8+DC11) -> 2902 | DF12: المجموع الكلي | DH12: 217 | DJ12: 548 | DO12: 452 | DQ12: 70 | DS12: 69 | DT12: 0 | DU12: 1607 | DX12: المجموع الكلي | DZ12: =SUM(DZ8+DZ11) -> 340 | EB12: =SUM(EB8+EB11) -> 845 | EG12: =SUM(EG8+EG11) -> 1134 | EI12: =SUM(EI8+EI11) -> 438 | EK12: =SUM(EK8+EK11) -> 145 | EL12: =SUM(EL8+EL11) -> 0 | EM12: =SUM(EM8+EM11) -> 2902 | EP12: المجموع الكلي | ER12: =SUM(ER8+ER11) -> 217 | ET12: =SUM(ET8+ET11) -> 545 | EY12: =SUM(EY8+EY11) -> 452 | FA12: =SUM(FA8+FA11) -> 70 | FC12: =SUM(FC8+FC11) -> 69 | FD12: =SUM(FD8+FD11) -> 0 | FE12: =SUM(FE8+FE11) -> 1353 | FH12: المجموع الكلي | FJ12: 339 | FL12: 510 | FQ12: 689 | FS12: 220 | FU12: 42 | FV12: 0 | FW12: 1800 | FZ12: المجموع الكلي | GB12: =SUM(GB8+GB11) -> 0 | GD12: =SUM(GD8+GD11) -> 0 | GI12: =SUM(GI8+GI11) -> 0 | GK12: =SUM(GK8+GK11) -> 0 | GM12: =SUM(GM8+GM11) -> 0 | GN12: =SUM(GN8+GN11) -> 0 | GO12: =SUM(GO8+GO11) -> 0 | GR12: المجموع الكلي | GT12: =SUM(GT8+GT11) -> 0 | GV12: =SUM(GV8+GV11) -> 0 | HA12: =SUM(HA8+HA11) -> 0 | HC12: =SUM(HC8+HC11) -> 0 | HE12: =SUM(HE8+HE11) -> 0 | HF12: =SUM(HF8+HF11) -> 0 | HG12: =SUM(HG8+HG11) -> 0 | HJ12: المجموع الكلي | HL12: =SUM(HL8+HL11) -> 3472 | HN12: =SUM(HN8+HN11) -> 7913 | HS12: =SUM(HS8+HS11) -> 9437 | HU12: =SUM(HU8+HU11) -> 2940 | HW12: =SUM(HW8+HW11) -> 834 | HX12: =SUM(HX8+HX11) -> 0 | HY12: =SUM(HY8+HY11) -> 24596
A13: الجامعة | B13: سعودي | C13: ذكر | D13: 92 | E13: 0 | F13: 0 | G13: 0 | H13: 0 | I13: 0 | J13: 0 | K13: 129 | L13: 0 | M13: 37 | N13: 0 | O13: 2 | P13: 0 | Q13: =SUM(D13:P13) -> 260 | S13: الجامعة | T13: سعودي | U13: ذكر | V13: 105 | W13: 0 | X13: 0 | Y13: 0 | Z13: 0 | AA13: 0 | AB13: 0 | AC13: 136 | AD13: 0 | AE13: 42 | AF13: 0 | AG13: 7 | AH13: 0 | AI13: =SUM(V13:AH13) -> 290 | AK13: الجامعة | AL13: سعودي | AM13: ذكر | AN13: 110 | AO13: 0 | AP13: 0 | AQ13: 22 | AR13: 12 | AS13: 0 | AT13: 145 | AU13: 201 | AV13: 246 | AW13: 52 | AX13: 0 | AY13: 0 | AZ13: 2 | BA13: =SUM(AN13:AZ13) -> 790 | BC13: الجامعة | BD13: سعودي | BE13: ذكر | BF13: 150 | BG13: 0 | BH13: 8 | BI13: 0 | BJ13: 8 | BK13: 0 | BL13: 0 | BM13: 211 | BN13: 0 | BO13: 55 | BP13: 0 | BQ13: 25 | BR13: 0 | BS13: =SUM(BF13:BR13) -> 457 | BU13: الجامعة | BV13: سعودي | BW13: ذكر | BX13: 95 | BY13: 0 | BZ13: 0 | CA13: 0 | CB13: 0 | CC13: 0 | CD13: 0 | CE13: 118 | CF13: 0 | CG13: 33 | CH13: 0 | CI13: 2 | CJ13: 0 | CK13: =SUM(BX13:CJ13) -> 248 | CM13: الجامعة | CN13: سعودي | CO13: ذكر | CP13: 1336 | CQ13: 0 | CR13: 30 | CS13: 133 | CT13: 41 | CU13: 0 | CV13: 347 | CW13: 1820 | CX13: 502 | CY13: 492 | CZ13: 0 | DA13: 160 | DB13: 2 | DC13: =SUM(CP13:DB13) -> 4863 | DE13: الجامعة | DF13: سعودي | DG13: ذكر | DH13: 119 | DI13: 0 | DJ13: 0 | DK13: 0 | DL13: 0 | DM13: 0 | DN13: 0 | DO13: 153 | DP13: 0 | DQ13: 43 | DR13: 0 | DS13: 6 | DT13: 0 | DU13: 321 | DW13: الجامعة | DX13: سعودي | DY13: ذكر | DZ13: 1336 | EA13: 0 | EB13: 30 | EC13: 133 | ED13: 41 | EE13: 0 | EF13: 347 | EG13: 1820 | EH13: 502 | EI13: 492 | EJ13: 0 | EK13: 160 | EL13: 2 | EM13: =SUM(DZ13:EL13) -> 4863 | EO13: الجامعة | EP13: سعودي | EQ13: ذكر | ER13: 101 | ES13: 1 | ET13: 0 | EU13: 0 | EV13: 0 | EW13: 0 | EX13: 0 | EY13: 147 | EZ13: 0 | FA13: 16 | FB13: 0 | FC13: 0 | FD13: 0 | FE13: =SUM(ER13:FD13) -> 265 | FG13: الجامعة | FH13: سعودي | FI13: ذكر | FJ13: 0 | FK13: 0 | FL13: 0 | FM13: 0 | FN13: 0 | FO13: 0 | FP13: 0 | FQ13: 0 | FR13: 0 | FS13: 0 | FT13: 0 | FU13: 0 | FV13: 0 | FW13: =SUM(FJ13:FV13) -> 0 | FY13: الجامعة | FZ13: سعودي | GA13: ذكر | GB13: 0 | GC13: 0 | GD13: 0 | GE13: 0 | GF13: 0 | GG13: 0 | GH13: 0 | GI13: 0 | GJ13: 0 | GK13: 0 | GL13: 0 | GM13: 0 | GN13: 0 | GO13: =SUM(GB13:GN13) -> 0 | GQ13: الجامعة | GR13: سعودي | GS13: ذكر | GT13: 0 | GU13: 0 | GV13: 0 | GW13: 0 | GX13: 0 | GY13: 0 | GZ13: 0 | HA13: 0 | HB13: 0 | HC13: 0 | HD13: 0 | HE13: 0 | HF13: 0 | HG13: =SUM(GT13:HF13) -> 0 | HI13: =GQ13 -> الجامعة | HJ13: سعودي | HK13: ذكر | HL13: =SUM(D13+V13+AN13+BF13+BX13+CP13+DH13+DZ13+ER13+FJ13+GB13+GT13) -> 3444 | HM13: =SUM(E13+W13+AO13+BG13+BY13+CQ13+DI13+EA13+ES13+FK13+GC13+GU13) -> 1 | HN13: =SUM(F13+X13+AP13+BH13+BZ13+CR13+DJ13+EB13+ET13+FL13+GD13+GV13) -> 68 | HO13: =SUM(G13+Y13+AQ13+BI13+CA13+CS13+DK13+EC13+EU13+FM13+GE13+GW13) -> 288 | HP13: =SUM(H13+Z13+AR13+BJ13+CB13+CT13+DL13+ED13+EV13+FN13+GF13+GX13) -> 102 | HQ13: =SUM(I13+AA13+AS13+BK13+CC13+CU13+DM13+EE13+EW13+FO13+GG13+GY13) -> 0 | HR13: =SUM(J13+AB13+AT13+BL13+CD13+CV13+DN13+EF13+EX13+FP13+GH13+GZ13) -> 839 | HS13: =SUM(K13+AC13+AU13+BM13+CE13+CW13+DO13+EG13+EY13+FQ13+GI13+HA13) -> 4735 | ... HX13: =SUM(P13+AH13+AZ13+BR13+CJ13+DB13+DT13+EL13+FD13+FV13+GN13+HF13) -> 6 | HY13: =SUM(HL13:HX13) -> 12357
C14: أنثى | D14: 105 | E14: 0 | F14: 0 | G14: 12 | H14: 0 | I14: 0 | J14: 0 | K14: 177 | L14: 0 | M14: 52 | N14: 0 | O14: 7 | P14: 0 | Q14: =SUM(D14:P14) -> 353 | U14: أنثى | V14: 99 | W14: 0 | X14: 3 | Y14: 2 | Z14: 0 | AA14: 0 | AB14: 0 | AC14: 188 | AD14: 0 | AE14: 58 | AF14: 18 | AG14: 4 | AH14: 0 | AI14: =SUM(V14:AH14) -> 372 | AM14: أنثى | AN14: 112 | AO14: 0 | AP14: 0 | AQ14: 18 | AR14: 54 | AS14: 0 | AT14: 124 | AU14: 210 | AV14: 302 | AW14: 121 | AX14: 24 | AY14: 0 | AZ14: 5 | BA14: =SUM(AN14:AZ14) -> 970 | BE14: أنثى | BF14: 266 | BG14: 2 | BH14: 10 | BI14: 3 | BJ14: 10 | BK14: 2 | BL14: 0 | BM14: 188 | BN14: 0 | BO14: 33 | BP14: 18 | BQ14: 12 | BR14: 0 | BS14: =SUM(BF14:BR14) -> 544 | BW14: أنثى | BX14: 100 | BY14: 0 | BZ14: 0 | CA14: 11 | CB14: 0 | CC14: 0 | CD14: 0 | CE14: 173 | CF14: 0 | CG14: 51 | CH14: 0 | CI14: 1 | CJ14: 0 | CK14: =SUM(BX14:CJ14) -> 336 | CO14: أنثى | CP14: 1911 | CQ14: 9 | CR14: 59 | CS14: 199 | CT14: 148 | CU14: 65 | CV14: 375 | CW14: 1995 | CX14: 707 | CY14: 612 | CZ14: 204 | DA14: 85 | DB14: 5 | DC14: =SUM(CP14:DB14) -> 6374 | DG14: أنثى | DH14: 124 | DI14: 0 | DJ14: 0 | DK14: 9 | DL14: 0 | DM14: 0 | DN14: 0 | DO14: 183 | DP14: 0 | DQ14: 62 | DR14: 0 | DS14: 8 | DT14: 0 | DU14: 386 | DY14: أنثى | DZ14: 1911 | EA14: 9 | EB14: 59 | EC14: 199 | ED14: 148 | EE14: 65 | EF14: 375 | EG14: 1995 | EH14: 707 | EI14: 612 | EJ14: 204 | EK14: 85 | EL14: 5 | EM14: =SUM(DZ14:EL14) -> 6374 | EQ14: أنثى | ER14: 138 | ES14: 1 | ET14: 0 | EU14: 0 | EV14: 0 | EW14: 0 | EX14: 0 | EY14: 195 | EZ14: 0 | FA14: 22 | FB14: 2 | FC14: 2 | FD14: 0 | FE14: =SUM(ER14:FD14) -> 360 | FI14: أنثى | FJ14: 0 | FK14: 0 | FL14: 0 | FM14: 0 | FN14: 0 | FO14: 0 | FP14: 0 | FQ14: 0 | FR14: 0 | FS14: 0 | FT14: 0 | FU14: 0 | FV14: 0 | FW14: =SUM(FJ14:FV14) -> 0 | GA14: أنثى | GB14: 0 | GC14: 0 | GD14: 0 | GE14: 0 | GF14: 0 | GG14: 0 | GH14: 0 | GI14: 0 | GJ14: 0 | GK14: 0 | GL14: 0 | GM14: 0 | GN14: 0 | GO14: =SUM(GB14:GN14) -> 0 | GS14: أنثى | GT14: 0 | GU14: 0 | GV14: 0 | GW14: 0 | GX14: 0 | GY14: 0 | GZ14: 0 | HA14: 0 | HB14: 0 | HC14: 0 | HD14: 0 | HE14: 0 | HF14: 0 | HG14: =SUM(GT14:HF14) -> 0 | HK14: أنثى | HL14: =SUM(D14+V14+AN14+BF14+BX14+CP14+DH14+DZ14+ER14+FJ14+GB14+GT14) -> 4766 | HM14: =SUM(E14+W14+AO14+BG14+BY14+CQ14+DI14+EA14+ES14+FK14+GC14+GU14) -> 21 | HN14: =SUM(F14+X14+AP14+BH14+BZ14+CR14+DJ14+EB14+ET14+FL14+GD14+GV14) -> 131 | HO14: =SUM(G14+Y14+AQ14+BI14+CA14+CS14+DK14+EC14+EU14+FM14+GE14+GW14) -> 453 | HP14: =SUM(H14+Z14+AR14+BJ14+CB14+CT14+DL14+ED14+EV14+FN14+GF14+GX14) -> 360 | HQ14: =SUM(I14+AA14+AS14+BK14+CC14+CU14+DM14+EE14+EW14+FO14+GG14+GY14) -> 132 | HR14: =SUM(J14+AB14+AT14+BL14+CD14+CV14+DN14+EF14+EX14+FP14+GH14+GZ14) -> 874 | HS14: =SUM(K14+AC14+AU14+BM14+CE14+CW14+DO14+EG14+EY14+FQ14+GI14+HA14) -> 5304 | ... HX14: =SUM(P14+AH14+AZ14+BR14+CJ14+DB14+DT14+EL14+FD14+FV14+GN14+HF14) -> 15 | HY14: =SUM(HL14:HX14) -> 16069
B15: مجموع السعوديين | D15: 197 | F15: 12 | K15: 306 | M15: 89 | O15: 9 | P15: 0 | Q15: =SUM(Q13:Q14) -> 613 | T15: مجموع السعوديين | V15: 204 | X15: 5 | AC15: 324 | AE15: 118 | AG15: 11 | AH15: 0 | AI15: =SUM(AI13:AI14) -> 662 | AL15: مجموع السعوديين | AN15: 222 | AP15: 375 | AU15: 959 | AW15: 197 | AY15: 0 | AZ15: 7 | BA15: =SUM(BA13:BA14) -> 1760 | BD15: مجموع السعوديين | BF15: 418 | BH15: 41 | BM15: 399 | BO15: 106 | BQ15: 37 | BR15: =SUM(BR13:BR14) -> 0 | BS15: =SUM(BS13:BS14) -> 1001 | BV15: مجموع السعوديين | BX15: 195 | BZ15: 11 | CE15: 291 | CG15: 84 | CI15: 3 | CJ15: 0 | CK15: =SUM(CK13:CK14) -> 584 | CN15: مجموع السعوديين | CP15: 3256 | CR15: 1397 | CW15: 5024 | CY15: 1308 | DA15: 245 | DB15: 7 | DC15: =SUM(DC13:DC14) -> 11237 | DF15: مجموع السعوديين | DH15: 243 | DJ15: 9 | DO15: 336 | DQ15: 105 | DS15: 14 | DT15: 0 | DU15: 707 | DX15: مجموع السعوديين | DZ15: =SUM(DZ13:EA14) -> 3256 | EB15: =SUM(EB13:EF14) -> 1397 | EG15: =SUM(EG13:EH14) -> 5024 | EI15: =SUM(EI13:EJ14) -> 1308 | EK15: =SUM(EK13:EK14) -> 245 | EL15: =SUM(EL13:EL14) -> 7 | EM15: =SUM(EM13:EM14) -> 11237 | EP15: مجموع السعوديين | ER15: =SUM(ER13:ES14) -> 241 | ET15: =SUM(ET13:EX14) -> 0 | EY15: =SUM(EY13:EZ14) -> 342 | FA15: =SUM(FA13:FB14) -> 40 | FC15: =SUM(FC13:FC14) -> 2 | FD15: =SUM(FD13:FD14) -> 0 | FE15: =SUM(FE13:FE14) -> 625 | FH15: مجموع السعوديين | FJ15: =SUM(FJ13:FK14) -> 0 | FL15: =SUM(FL13:FP14) -> 0 | FQ15: =SUM(FQ13:FR14) -> 0 | FS15: =SUM(FS13:FT14) -> 0 | FU15: =SUM(FU13:FU14) -> 0 | FV15: =SUM(FV13:FV14) -> 0 | FW15: =SUM(FW13:FW14) -> 0 | FZ15: مجموع السعوديين | GB15: =SUM(GB13:GC14) -> 0 | GD15: =SUM(GD13:GH14) -> 0 | GI15: =SUM(GI13:GJ14) -> 0 | GK15: =SUM(GK13:GL14) -> 0 | GM15: =SUM(GM13:GM14) -> 0 | GN15: =SUM(GN13:GN14) -> 0 | GO15: =SUM(GO13:GO14) -> 0 | GR15: مجموع السعوديين | GT15: =SUM(GT13:GU14) -> 0 | GV15: =SUM(GV13:GZ14) -> 0 | HA15: =SUM(HA13:HB14) -> 0 | HC15: =SUM(HC13:HD14) -> 0 | HE15: =SUM(HE13:HE14) -> 0 | HF15: =SUM(HF13:HF14) -> 0 | HG15: =SUM(HG13:HG14) -> 0 | HJ15: مجموع السعوديين | HL15: =SUM(HL13:HM14) -> 8232 | HN15: =SUM(HN13:HR14) -> 3247 | HS15: =SUM(HS13:HT14) -> 13005 | HU15: =SUM(HU13:HV14) -> 3355 | HW15: =SUM(HW13:HW14) -> 566 | HX15: =SUM(HX13:HX14) -> 21 | HY15: =SUM(HY13:HY14) -> 28426
B16: غير سعودي | C16: ذكر | D16: 52 | E16: 0 | F16: 0 | G16: 0 | H16: 0 | I16: 0 | J16: 0 | K16: 27 | L16: 0 | M16: 14 | N16: 0 | O16: 1 | P16: 0 | Q16: =SUM(D16:P16) -> 94 | T16: غير سعودي | U16: ذكر | V16: 66 | W16: 0 | X16: 0 | Y16: 1 | Z16: 0 | AA16: 0 | AB16: 0 | AC16: 34 | AD16: 0 | AE16: 19 | AF16: 0 | AG16: 0 | AH16: 0 | AI16: =SUM(V16:AH16) -> 120 | AL16: غير سعودي | AM16: ذكر | AN16: 95 | AO16: 0 | AP16: 0 | AQ16: 5 | AR16: 1 | AS16: 0 | AT16: 123 | AU16: 102 | AV16: 185 | AW16: 12 | AX16: 0 | AY16: 0 | AZ16: 0 | BA16: =SUM(AN16:AZ16) -> 523 | BD16: غير سعودي | BE16: ذكر | BF16: 140 | BG16: 0 | BH16: 0 | BI16: 0 | BJ16: 0 | BK16: 0 | BL16: 0 | BM16: 70 | BN16: 0 | BO16: 19 | BP16: 0 | BQ16: 7 | BR16: 0 | BS16: =SUM(BF16:BR16) -> 236 | BV16: غير سعودي | BW16: ذكر | BX16: 49 | BY16: 0 | BZ16: 0 | CA16: 0 | CB16: 0 | CC16: 0 | CD16: 0 | CE16: 23 | CF16: 0 | CG16: 12 | CH16: 0 | CI16: 0 | CJ16: 0 | CK16: =SUM(BX16:CJ16) -> 84 | CN16: غير سعودي | CO16: ذكر | CP16: 0 | CQ16: 0 | CR16: 0 | CS16: 0 | CT16: 0 | CU16: 0 | CV16: 0 | CW16: 0 | CX16: 0 | CY16: 0 | CZ16: 0 | DA16: 0 | DB16: 0 | DC16: =SUM(CP16:DB16) -> 0 | DF16: غير سعودي | DG16: ذكر | DH16: 66 | DI16: 0 | DJ16: 0 | DK16: 0 | DL16: 0 | DM16: 0 | DN16: 0 | DO16: 92 | DP16: 0 | DQ16: 29 | DR16: 0 | DS16: 0 | DT16: 0 | DU16: 187 | DX16: غير سعودي | DY16: ذكر | DZ16: 0 | EA16: 0 | EB16: 0 | EC16: 0 | ED16: 0 | EE16: 0 | EF16: 0 | EG16: 0 | EH16: 0 | EI16: 0 | EJ16: 0 | EK16: 0 | EL16: 0 | EM16: =SUM(DZ16:EL16) -> 0 | EP16: غير سعودي | EQ16: ذكر | ER16: 32 | ES16: 0 | ET16: 0 | EU16: 0 | EV16: 0 | EW16: 0 | EX16: 0 | EY16: 49 | EZ16: 0 | FA16: 8 | FB16: 0 | FC16: 0 | FD16: 0 | FE16: =SUM(ER16:FD16) -> 89 | FH16: غير سعودي | FI16: ذكر | FJ16: 0 | FK16: 0 | FL16: 0 | FM16: 0 | FN16: 0 | FO16: 0 | FP16: 0 | FQ16: 0 | FR16: 0 | FS16: 0 | FT16: 0 | FU16: 0 | FV16: 0 | FW16: =SUM(FJ16:FV16) -> 0 | FZ16: غير سعودي | GA16: ذكر | GB16: 0 | GC16: 0 | GD16: 0 | GE16: 0 | GF16: 0 | GG16: 0 | GH16: 0 | GI16: 0 | GJ16: 0 | GK16: 0 | GL16: 0 | GM16: 0 | GN16: 0 | GO16: =SUM(GB16:GN16) -> 0 | GR16: غير سعودي | GS16: ذكر | GT16: 0 | GU16: 0 | GV16: 0 | GW16: 0 | GX16: 0 | GY16: 0 | GZ16: 0 | HA16: 0 | HB16: 0 | HC16: 0 | HD16: 0 | HE16: 0 | HF16: 0 | HG16: =SUM(GT16:HF16) -> 0 | HJ16: غير سعودي | HK16: ذكر | HL16: =SUM(D16+V16+AN16+BF16+BX16+CP16+DH16+DZ16+ER16+FJ16+GB16+GT16) -> 500 | HM16: =SUM(E16+W16+AO16+BG16+BY16+CQ16+DI16+EA16+ES16+FK16+GC16+GU16) -> 0 | HN16: =SUM(F16+X16+AP16+BH16+BZ16+CR16+DJ16+EB16+ET16+FL16+GD16+GV16) -> 0 | HO16: =SUM(G16+Y16+AQ16+BI16+CA16+CS16+DK16+EC16+EU16+FM16+GE16+GW16) -> 6 | HP16: =SUM(H16+Z16+AR16+BJ16+CB16+CT16+DL16+ED16+EV16+FN16+GF16+GX16) -> 1 | HQ16: =SUM(I16+AA16+AS16+BK16+CC16+CU16+DM16+EE16+EW16+FO16+GG16+GY16) -> 0 | HR16: =SUM(J16+AB16+AT16+BL16+CD16+CV16+DN16+EF16+EX16+FP16+GH16+GZ16) -> 123 | HS16: =SUM(K16+AC16+AU16+BM16+CE16+CW16+DO16+EG16+EY16+FQ16+GI16+HA16) -> 397 | ... HX16: =SUM(P16+AH16+AZ16+BR16+CJ16+DB16+DT16+EL16+FD16+FV16+GN16+HF16) -> 0 | HY16: =SUM(HL16:HX16) -> 1333
C17: أنثى | D17: 31 | E17: 0 | F17: 0 | G17: 1 | H17: 0 | I17: 0 | J17: 0 | K17: 18 | L17: 0 | M17: 9 | N17: 0 | O17: 1 | P17: 0 | Q17: =SUM(D17:P17) -> 60 | U17: أنثى | V17: 38 | W17: 0 | X17: 0 | Y17: 1 | Z17: 0 | AA17: 0 | AB17: 0 | AC17: 28 | AD17: 0 | AE17: 13 | AF17: 0 | AG17: 2 | AH17: 0 | AI17: =SUM(V17:AH17) -> 82 | AM17: أنثى | AN17: 87 | AO17: 0 | AP17: 0 | AQ17: 9 | AR17: 8 | AS17: 0 | AT17: 121 | AU17: 195 | AV17: 102 | AW17: 18 | AX17: 5 | AY17: 0 | AZ17: 1 | BA17: =SUM(AN17:AZ17) -> 546 | BE17: أنثى | BF17: 99 | BG17: 0 | BH17: 6 | BI17: 5 | BJ17: 6 | BK17: 0 | BL17: 0 | BM17: 44 | BN17: 0 | BO17: 9 | BP17: 6 | BQ17: 11 | BR17: 0 | BS17: =SUM(BF17:BR17) -> 186 | BW17: أنثى | BX17: 33 | BY17: 0 | BZ17: 0 | CA17: 2 | CB17: 0 | CC17: 0 | CD17: 0 | CE17: 14 | CF17: 0 | CG17: 9 | CH17: 0 | CI17: 1 | CJ17: 0 | CK17: =SUM(BX17:CJ17) -> 59 | CO17: أنثى | CP17: 0 | CQ17: 0 | CR17: 0 | CS17: 0 | CT17: 0 | CU17: 0 | CV17: 0 | CW17: 0 | CX17: 0 | CY17: 0 | CZ17: 0 | DA17: 0 | DB17: 0 | DC17: =SUM(CP17:DB17) -> 0 | DG17: أنثى | DH17: 80 | DI17: 0 | DJ17: 0 | DK17: 4 | DL17: 0 | DM17: 0 | DN17: 0 | DO17: 32 | DP17: 0 | DQ17: 24 | DR17: 0 | DS17: 0 | DT17: 0 | DU17: 140 | DY17: أنثى | DZ17: 0 | EA17: 0 | EB17: 0 | EC17: 0 | ED17: 0 | EE17: 0 | EF17: 0 | EG17: 0 | EH17: 0 | EI17: 0 | EJ17: 0 | EK17: 0 | EL17: 0 | EM17: =SUM(DZ17:EL17) -> 0 | EQ17: أنثى | ER17: 21 | ES17: 0 | ET17: 0 | EU17: 0 | EV17: 0 | EW17: 0 | EX17: 0 | EY17: 38 | EZ17: 0 | FA17: 3 | FB17: 0 | FC17: 2 | FD17: 0 | FE17: =SUM(ER17:FD17) -> 64 | FI17: أنثى | FJ17: 0 | FK17: 0 | FL17: 0 | FM17: 0 | FN17: 0 | FO17: 0 | FP17: 0 | FQ17: 0 | FR17: 0 | FS17: 0 | FT17: 0 | FU17: 0 | FV17: 0 | FW17: =SUM(FJ17:FV17) -> 0 | GA17: أنثى | GB17: 0 | GC17: 0 | GD17: 0 | GE17: 0 | GF17: 0 | GG17: 0 | GH17: 0 | GI17: 0 | GJ17: 0 | GK17: 0 | GL17: 0 | GM17: 0 | GN17: 0 | GO17: =SUM(GB17:GN17) -> 0 | GS17: أنثى | GT17: 0 | GU17: 0 | GV17: 0 | GW17: 0 | GX17: 0 | GY17: 0 | GZ17: 0 | HA17: 0 | HB17: 0 | HC17: 0 | HD17: 0 | HE17: 0 | HF17: 0 | HG17: =SUM(GT17:HF17) -> 0 | HK17: أنثى | HL17: =SUM(D17+V17+AN17+BF17+BX17+CP17+DH17+DZ17+ER17+FJ17+GB17+GT17) -> 389 | HM17: =SUM(E17+W17+AO17+BG17+BY17+CQ17+DI17+EA17+ES17+FK17+GC17+GU17) -> 0 | HN17: =SUM(F17+X17+AP17+BH17+BZ17+CR17+DJ17+EB17+ET17+FL17+GD17+GV17) -> 6 | HO17: =SUM(G17+Y17+AQ17+BI17+CA17+CS17+DK17+EC17+EU17+FM17+GE17+GW17) -> 22 | HP17: =SUM(H17+Z17+AR17+BJ17+CB17+CT17+DL17+ED17+EV17+FN17+GF17+GX17) -> 14 | HQ17: =SUM(I17+AA17+AS17+BK17+CC17+CU17+DM17+EE17+EW17+FO17+GG17+GY17) -> 0 | HR17: =SUM(J17+AB17+AT17+BL17+CD17+CV17+DN17+EF17+EX17+FP17+GH17+GZ17) -> 121 | HS17: =SUM(K17+AC17+AU17+BM17+CE17+CW17+DO17+EG17+EY17+FQ17+GI17+HA17) -> 369 | ... HX17: =SUM(P17+AH17+AZ17+BR17+CJ17+DB17+DT17+EL17+FD17+FV17+GN17+HF17) -> 1 | HY17: =SUM(HL17:HX17) -> 1137
B18: مجموع الغير سعوديين | D18: =SUM(D16:E17) -> 83 | F18: =SUM(F16:J17) -> 1 | K18: =SUM(K16:L17) -> 45 | M18: =SUM(M16:N17) -> 23 | O18: =SUM(O16:O17) -> 2 | P18: =SUM(P16:P17) -> 0 | Q18: =SUM(Q16:Q17) -> 154 | T18: مجموع الغير سعوديين | V18: =SUM(V16:W17) -> 104 | X18: =SUM(X16:AB17) -> 2 | AC18: =SUM(AC16:AD17) -> 62 | AE18: =SUM(AE16:AF17) -> 32 | AG18: =SUM(AG16:AG17) -> 2 | AH18: =SUM(AH16:AH17) -> 0 | AI18: =SUM(AI16:AI17) -> 202 | AL18: مجموع الغير سعوديين | AN18: =SUM(AN16:AO17) -> 182 | AP18: =SUM(AP16:AT17) -> 267 | AU18: =SUM(AU16:AV17) -> 584 | AW18: =SUM(AW16:AX17) -> 35 | AY18: =SUM(AY16:AY17) -> 0 | AZ18: =SUM(AZ16:AZ17) -> 1 | BA18: =SUM(BA16:BA17) -> 1069 | BD18: مجموع الغير سعوديين | BF18: 239 | BH18: 17 | BM18: 114 | BO18: 34 | BQ18: 18 | BR18: =SUM(BR16:BR17) -> 0 | BS18: =SUM(BS16:BS17) -> 422 | BV18: مجموع الغير سعوديين | BX18: =SUM(BX16:BY17) -> 82 | BZ18: =SUM(BZ16:CD17) -> 2 | CE18: =SUM(CE16:CF17) -> 37 | CG18: =SUM(CG16:CH17) -> 21 | CI18: =SUM(CI16:CI17) -> 1 | CJ18: =SUM(CJ16:CJ17) -> 0 | CK18: =SUM(CK16:CK17) -> 143 | CN18: مجموع الغير سعوديين | CP18: 0 | CR18: 0 | CW18: 0 | CY18: 0 | DA18: 0 | DB18: 0 | DC18: =SUM(DC16:DC17) -> 0 | DF18: مجموع الغير سعوديين | DH18: 146 | DJ18: 4 | DO18: 124 | DQ18: 53 | DS18: 0 | DT18: 0 | DU18: 327 | DX18: مجموع الغير سعوديين | DZ18: =SUM(DZ16:EA17) -> 0 | EB18: =SUM(EB16:EF17) -> 0 | EG18: =SUM(EG16:EH17) -> 0 | EI18: =SUM(EI16:EJ17) -> 0 | EK18: =SUM(EK16:EK17) -> 0 | EL18: =SUM(EL16:EL17) -> 0 | EM18: =SUM(EM16:EM17) -> 0 | EP18: مجموع الغير سعوديين | ER18: =SUM(ER16:ES17) -> 53 | ET18: =SUM(ET16:EX17) -> 0 | EY18: =SUM(EY16:EZ17) -> 87 | FA18: =SUM(FA16:FB17) -> 11 | FC18: =SUM(FC16:FC17) -> 2 | FD18: =SUM(FD16:FD17) -> 0 | FE18: =SUM(FE16:FE17) -> 153 | FH18: مجموع الغير سعوديين | FJ18: =SUM(FJ16:FK17) -> 0 | FL18: =SUM(FL16:FP17) -> 0 | FQ18: =SUM(FQ16:FR17) -> 0 | FS18: =SUM(FS16:FT17) -> 0 | FU18: =SUM(FU16:FU17) -> 0 | FV18: =SUM(FV16:FV17) -> 0 | FW18: =SUM(FW16:FW17) -> 0 | FZ18: مجموع الغير سعوديين | GB18: =SUM(GB16:GC17) -> 0 | GD18: =SUM(GD16:GH17) -> 0 | GI18: =SUM(GI16:GJ17) -> 0 | GK18: =SUM(GK16:GL17) -> 0 | GM18: =SUM(GM16:GM17) -> 0 | GN18: =SUM(GN16:GN17) -> 0 | GO18: =SUM(GO16:GO17) -> 0 | GR18: مجموع الغير سعوديين | GT18: =SUM(GT16:GU17) -> 0 | GV18: =SUM(GV16:GZ17) -> 0 | HA18: =SUM(HA16:HB17) -> 0 | HC18: =SUM(HC16:HD17) -> 0 | HE18: =SUM(HE16:HE17) -> 0 | HF18: =SUM(HF16:HF17) -> 0 | HG18: =SUM(HG16:HG17) -> 0 | HJ18: مجمع الغير سعوديين | HL18: =SUM(HL16:HM17) -> 889 | HN18: =SUM(HN16:HR17) -> 293 | HS18: =SUM(HS16:HT17) -> 1053 | HU18: =SUM(HU16:HV17) -> 209 | HW18: =SUM(HW16:HW17) -> 25 | HX18: =SUM(HX16:HX17) -> 1 | HY18: =SUM(HY16:HY17) -> 2470
B19: المجموع الكلي | D19: =SUM(D15+D18) -> 280 | F19: =SUM(F15+F18) -> 13 | K19: =SUM(K15+K18) -> 351 | M19: =SUM(M15+M18) -> 112 | O19: =SUM(O15+O18) -> 11 | P19: =SUM(P15+P18) -> 0 | Q19: =SUM(Q15+Q18) -> 767 | T19: المجموع الكلي | V19: =SUM(V15+V18) -> 308 | X19: =SUM(X15+X18) -> 7 | AC19: =SUM(AC15+AC18) -> 386 | AE19: =SUM(AE15+AE18) -> 150 | AG19: =SUM(AG15+AG18) -> 13 | AH19: =SUM(AH15+AH18) -> 0 | AI19: =SUM(AI15+AI18) -> 864 | AL19: المجموع الكلي | AN19: =SUM(AN15+AN18) -> 404 | AP19: =SUM(AP15+AP18) -> 642 | AU19: =SUM(AU15+AU18) -> 1543 | AW19: =SUM(AW15+AW18) -> 232 | AY19: =SUM(AY15+AY18) -> 0 | AZ19: =SUM(AZ15+AZ18) -> 8 | BA19: =SUM(BA15+BA18) -> 2829 | BD19: المجموع الكلي | BF19: =SUM(BF15+BF18) -> 657 | BH19: =SUM(BH15+BH18) -> 58 | BM19: =SUM(BM15+BM18) -> 513 | BO19: =SUM(BO15+BO18) -> 140 | BQ19: =SUM(BQ15+BQ18) -> 55 | BR19: =SUM(BR15+BR18) -> 0 | BS19: =SUM(BS15+BS18) -> 1423 | BV19: المجموع الكلي | BX19: =SUM(BX15+BX18) -> 277 | BZ19: =SUM(BZ15+BZ18) -> 13 | CE19: =SUM(CE15+CE18) -> 328 | CG19: =SUM(CG15+CG18) -> 105 | CI19: =SUM(CI15+CI18) -> 4 | CJ19: =SUM(CJ15+CJ18) -> 0 | CK19: =SUM(CK15+CK18) -> 727 | CN19: المجموع الكلي | CP19: 3256 | CR19: 1397 | CW19: 5024 | CY19: 1308 | DA19: 245 | DB19: 7 | DC19: =SUM(DC15+DC18) -> 11237 | DF19: المجموع الكلي | DH19: 389 | DJ19: 13 | DO19: 460 | DQ19: 158 | DS19: 14 | DT19: 0 | DU19: 1034 | DX19: المجموع الكلي | DZ19: =SUM(DZ15+DZ18) -> 3256 | EB19: =SUM(EB15+EB18) -> 1397 | EG19: =SUM(EG15+EG18) -> 5024 | EI19: =SUM(EI15+EI18) -> 1308 | EK19: =SUM(EK15+EK18) -> 245 | EL19: =SUM(EL15+EL18) -> 7 | EM19: =SUM(EM15+EM18) -> 11237 | EP19: المجموع الكلي | ER19: =SUM(ER15+ER18) -> 294 | ET19: =SUM(ET15+ET18) -> 0 | EY19: =SUM(EY15+EY18) -> 429 | FA19: =SUM(FA15+FA18) -> 51 | FC19: =SUM(FC15+FC18) -> 4 | FD19: =SUM(FD15+FD18) -> 0 | FE19: =SUM(FE15+FE18) -> 778 | FH19: المجموع الكلي | FJ19: =SUM(FJ15+FJ18) -> 0 | FL19: =SUM(FL15+FL18) -> 0 | FQ19: =SUM(FQ15+FQ18) -> 0 | FS19: =SUM(FS15+FS18) -> 0 | FU19: =SUM(FU15+FU18) -> 0 | FV19: =SUM(FV15+FV18) -> 0 | FW19: =SUM(FW15+FW18) -> 0 | FZ19: المجموع الكلي | GB19: =SUM(GB15+GB18) -> 0 | GD19: =SUM(GD15+GD18) -> 0 | GI19: =SUM(GI15+GI18) -> 0 | GK19: =SUM(GK15+GK18) -> 0 | GM19: =SUM(GM15+GM18) -> 0 | GN19: =SUM(GN15+GN18) -> 0 | GO19: =SUM(GO15+GO18) -> 0 | GR19: المجموع الكلي | GT19: =SUM(GT15+GT18) -> 0 | GV19: =SUM(GV15+GV18) -> 0 | HA19: =SUM(HA15+HA18) -> 0 | HC19: =SUM(HC15+HC18) -> 0 | HE19: =SUM(HE15+HE18) -> 0 | HF19: =SUM(HF15+HF18) -> 0 | HG19: =SUM(HG15+HG18) -> 0 | HJ19: المجموع الكلي | HL19: =SUM(HL15+HL18) -> 9121 | HN19: =SUM(HN15+HN18) -> 3540 | HS19: =SUM(HS15+HS18) -> 14058 | HU19: =SUM(HU15+HU18) -> 3564 | HW19: =SUM(HW15+HW18) -> 591 | HX19: =SUM(HX15+HX18) -> 22 | HY19: =SUM(HY15+HY18) -> 30896
A20: السليمانية | B20: سعودي | C20: ذكر | D20: 484 | E20: 2 | F20: 10 | G20: 1 | H20: 29 | I20: 0 | J20: 700 | K20: 31 | L20: 300 | M20: 162 | N20: 0 | O20: 9 | P20: 0 | Q20: =SUM(D20:P20) -> 1728 | S20: السليمانية | T20: سعودي | U20: ذكر | V20: 399 | W20: 2 | X20: 0 | Y20: 1 | Z20: 28 | AA20: 0 | AB20: 868 | AC20: 138 | AD20: 685 | AE20: 204 | AF20: 0 | AG20: 6 | AH20: 0 | AI20: =SUM(V20:AH20) -> 2331 | AK20: السليمانية | AL20: سعودي | AM20: ذكر | AN20: 100 | AO20: 0 | AP20: 60 | AQ20: 0 | AR20: 20 | AS20: 0 | AT20: 140 | AU20: 250 | AV20: 500 | AW20: 100 | AX20: 0 | AY20: 8 | AZ20: 0 | BA20: =SUM(AN20:AZ20) -> 1178 | BC20: السليمانية | BD20: سعودي | BE20: ذكر | BF20: 0 | BG20: 0 | BH20: 0 | BI20: 0 | BJ20: 0 | BK20: 0 | BL20: 0 | BM20: 0 | BN20: 0 | BO20: 0 | BP20: 0 | BQ20: 0 | BR20: 0 | BS20: =SUM(BF20:BR20) -> 0 | BU20: السليمانية | BV20: سعودي | BW20: ذكر | BX20: 368 | BY20: 0 | BZ20: 43 | CA20: 48 | CB20: 48 | CC20: 0 | CD20: 523 | CE20: 711 | CF20: 190 | CG20: 140 | CH20: 0 | CI20: 0 | CJ20: 0 | CK20: =SUM(BX20:CJ20) -> 2071 | CM20: السليمانية | CN20: سعودي | CO20: ذكر | CP20: 20 | CQ20: 0 | CR20: 30 | CS20: 0 | CT20: 20 | CU20: 0 | CV20: 1500 | CW20: 20 | CX20: 0 | CY20: 30 | CZ20: 0 | DA20: 10 | DB20: 0 | DC20: =SUM(CP20:DB20) -> 1630 | DE20: السليمانية | DF20: سعودي | DG20: ذكر | DH20: 407 | DI20: 1 | DJ20: 0 | DK20: 1 | DL20: 30 | DM20: 0 | DN20: 964 | DO20: 138 | DP20: 790 | DQ20: 204 | DR20: 0 | DS20: 6 | DT20: 0 | DU20: 2541 | DW20: السليمانية | DX20: سعودي | DY20: ذكر | DZ20: 20 | EA20: 0 | EB20: 30 | EC20: 0 | ED20: 20 | EE20: 0 | EF20: 1500 | EG20: 20 | EH20: 0 | EI20: 30 | EJ20: 0 | EK20: 10 | EL20: 0 | EM20: =SUM(DZ20:EL20) -> 1630 | EO20: السليمانية | EP20: سعودي | EQ20: ذكر | ER20: 201 | ES20: 0 | ET20: 0 | EU20: 8 | EV20: 0 | EW20: 0 | EX20: 0 | EY20: 211 | EZ20: 17 | FA20: 18 | FB20: 0 | FC20: 0 | FD20: 0 | FE20: =SUM(ER20:FD20) -> 455 | FG20: السليمانية | FH20: سعودي | FI20: ذكر | FJ20: 394 | FK20: 10 | FL20: 20 | FM20: 5 | FN20: 20 | FO20: 0 | FP20: 0 | FQ20: 26 | FR20: 0 | FS20: 168 | FT20: 0 | FU20: 13 | FV20: 0 | FW20: 656 | FY20: السليمانية | FZ20: سعودي | GA20: ذكر | GB20: 0 | GC20: 0 | GD20: 0 | GE20: 0 | GF20: 0 | GG20: 0 | GH20: 0 | GI20: 0 | GJ20: 0 | GK20: 0 | GL20: 0 | GM20: 0 | GN20: 0 | GO20: =SUM(GB20:GN20) -> 0 | GQ20: السليمانية | GR20: سعودي | GS20: ذكر | GT20: 0 | GU20: 0 | GV20: 0 | GW20: 0 | GX20: 0 | GY20: 0 | GZ20: 0 | HA20: 0 | HB20: 0 | HC20: 0 | HD20: 0 | HE20: 0 | HF20: 0 | HG20: =SUM(GT20:HF20) -> 0 | HI20: =GQ20 -> السليمانية | HJ20: سعودي | HK20: ذكر | HL20: =SUM(D20+V20+AN20+BF20+BX20+CP20+DH20+DZ20+ER20+FJ20+GB20+GT20) -> 2393 | HM20: =SUM(E20+W20+AO20+BG20+BY20+CQ20+DI20+EA20+ES20+FK20+GC20+GU20) -> 15 | HN20: =SUM(F20+X20+AP20+BH20+BZ20+CR20+DJ20+EB20+ET20+FL20+GD20+GV20) -> 193 | HO20: =SUM(G20+Y20+AQ20+BI20+CA20+CS20+DK20+EC20+EU20+FM20+GE20+GW20) -> 64 | HP20: =SUM(H20+Z20+AR20+BJ20+CB20+CT20+DL20+ED20+EV20+FN20+GF20+GX20) -> 215 | HQ20: =SUM(I20+AA20+AS20+BK20+CC20+CU20+DM20+EE20+EW20+FO20+GG20+GY20) -> 0 | HR20: =SUM(J20+AB20+AT20+BL20+CD20+CV20+DN20+EF20+EX20+FP20+GH20+GZ20) -> 6195 | HS20: =SUM(K20+AC20+AU20+BM20+CE20+CW20+DO20+EG20+EY20+FQ20+GI20+HA20) -> 1545 | ... HX20: =SUM(P20+AH20+AZ20+BR20+CJ20+DB20+DT20+EL20+FD20+FV20+GN20+HF20) -> 0 | HY20: =SUM(HL20:HX20) -> 14220
C21: أنثى | D21: 455 | E21: 4 | F21: 105 | G21: 3 | H21: 100 | I21: 0 | J21: 814 | K21: 24 | L21: 667 | M21: 225 | N21: 20 | O21: 10 | P21: 0 | Q21: =SUM(D21:P21) -> 2427 | U21: أنثى | V21: 582 | W21: 4 | X21: 0 | Y21: 5 | Z21: 225 | AA21: 0 | AB21: 0 | AC21: 137 | AD21: 1536 | AE21: 203 | AF21: 21 | AG21: 13 | AH21: 0 | AI21: =SUM(V21:AH21) -> 2726 | AM21: أنثى | AN21: 340 | AO21: 0 | AP21: 160 | AQ21: 10 | AR21: 70 | AS21: 8 | AT21: 400 | AU21: 400 | AV21: 100 | AW21: 240 | AX21: 20 | AY21: 18 | AZ21: 0 | BA21: =SUM(AN21:AZ21) -> 1766 | BE21: أنثى | BF21: 0 | BG21: 0 | BH21: 0 | BI21: 0 | BJ21: 0 | BK21: 0 | BL21: 0 | BM21: 0 | BN21: 0 | BO21: 0 | BP21: 0 | BQ21: 0 | BR21: 0 | BS21: =SUM(BF21:BR21) -> 0 | BW21: أنثى | BX21: 295 | BY21: 0 | BZ21: 50 | CA21: 101 | CB21: 53 | CC21: 0 | CD21: 496 | CE21: 645 | CF21: 207 | CG21: 308 | CH21: 78 | CI21: 0 | CJ21: 0 | CK21: =SUM(BX21:CJ21) -> 2233 | CO21: أنثى | CP21: 50 | CQ21: 0 | CR21: 60 | CS21: 0 | CT21: 40 | CU21: 5 | CV21: 2800 | CW21: 10 | CX21: 0 | CY21: 50 | CZ21: 20 | DA21: 5 | DB21: 0 | DC21: =SUM(CP21:DB21) -> 3040 | DG21: أنثى | DH21: 619 | DI21: 5 | DJ21: 0 | DK21: 5 | DL21: 227 | DM21: 0 | DN21: 0 | DO21: 137 | DP21: 1536 | DQ21: 203 | DR21: 21 | DS21: 13 | DT21: 0 | DU21: 2766 | DY21: أنثى | DZ21: 50 | EA21: 0 | EB21: 60 | EC21: 0 | ED21: 40 | EE21: 5 | EF21: 2800 | EG21: 10 | EH21: 0 | EI21: 50 | EJ21: 20 | EK21: 5 | EL21: 0 | EM21: =SUM(DZ21:EL21) -> 3040 | EQ21: أنثى | ER21: 154 | ES21: 0 | ET21: 0 | EU21: 11 | EV21: 0 | EW21: 0 | EX21: 0 | EY21: 204 | EZ21: 14 | FA21: 20 | FB21: 15 | FC21: 0 | FD21: 0 | FE21: =SUM(ER21:FD21) -> 418 | FI21: أنثى | FJ21: 546 | FK21: 20 | FL21: 25 | FM21: 10 | FN21: 25 | FO21: 0 | FP21: 0 | FQ21: 47 | FR21: 0 | FS21: 196 | FT21: 42 | FU21: 13 | FV21: 0 | FW21: 924 | GA21: أنثى | GB21: 0 | GC21: 0 | GD21: 0 | GE21: 0 | GF21: 0 | GG21: 0 | GH21: 0 | GI21: 0 | GJ21: 0 | GK21: 0 | GL21: 0 | GM21: 0 | GN21: 0 | GO21: =SUM(GB21:GN21) -> 0 | GS21: أنثى | GT21: 0 | GU21: 0 | GV21: 0 | GW21: 0 | GX21: 0 | GY21: 0 | GZ21: 0 | HA21: 0 | HB21: 0 | HC21: 0 | HD21: 0 | HE21: 0 | HF21: 0 | HG21: =SUM(GT21:HF21) -> 0 | HK21: أنثى | HL21: =SUM(D21+V21+AN21+BF21+BX21+CP21+DH21+DZ21+ER21+FJ21+GB21+GT21) -> 3091 | HM21: =SUM(E21+W21+AO21+BG21+BY21+CQ21+DI21+EA21+ES21+FK21+GC21+GU21) -> 33 | HN21: =SUM(F21+X21+AP21+BH21+BZ21+CR21+DJ21+EB21+ET21+FL21+GD21+GV21) -> 460 | HO21: =SUM(G21+Y21+AQ21+BI21+CA21+CS21+DK21+EC21+EU21+FM21+GE21+GW21) -> 145 | HP21: =SUM(H21+Z21+AR21+BJ21+CB21+CT21+DL21+ED21+EV21+FN21+GF21+GX21) -> 780 | HQ21: =SUM(I21+AA21+AS21+BK21+CC21+CU21+DM21+EE21+EW21+FO21+GG21+GY21) -> 18 | HR21: =SUM(J21+AB21+AT21+BL21+CD21+CV21+DN21+EF21+EX21+FP21+GH21+GZ21) -> 7310 | HS21: =SUM(K21+AC21+AU21+BM21+CE21+CW21+DO21+EG21+EY21+FQ21+GI21+HA21) -> 1614 | ... HX21: =SUM(P21+AH21+AZ21+BR21+CJ21+DB21+DT21+EL21+FD21+FV21+GN21+HF21) -> 0 | HY21: =SUM(HL21:HX21) -> 19340
B22: مجموع السعوديين | D22: 945 | F22: 1762 | K22: 1022 | M22: 407 | O22: 19 | P22: 0 | Q22: =SUM(Q20:Q21) -> 4155 | T22: مجموع السعوديين | V22: 987 | X22: 1127 | AC22: 2496 | AE22: 428 | AG22: 19 | AH22: 0 | AI22: =SUM(AI20:AI21) -> 5057 | AL22: مجموع السعوديين | AN22: 440 | AP22: 868 | AU22: 1250 | AW22: 360 | AY22: 26 | AZ22: 0 | BA22: =SUM(BA20:BA21) -> 2944 | BD22: مجموع السعوديين | BF22: =SUM(BF20:BG21) -> 0 | BH22: =SUM(BH20:BL21) -> 0 | BM22: =SUM(BM20:BN21) -> 0 | BO22: =SUM(BO20:BP21) -> 0 | BQ22: =SUM(BQ20:BQ21) -> 0 | BR22: =SUM(BR20:BR21) -> 0 | BS22: =SUM(BS20:BS21) -> 0 | BV22: مجموع السعوديين | BX22: 663 | BZ22: 1362 | CE22: 1753 | CG22: 526 | CI22: 0 | CJ22: 0 | CK22: =SUM(CK20:CK21) -> 4304 | CN22: مجموع السعوديين | CP22: 70 | CR22: 4455 | CW22: 30 | CY22: 100 | DA22: 15 | DB22: 0 | DC22: =SUM(DC20:DC21) -> 4670 | DF22: مجموع السعوديين | DH22: 1032 | DJ22: 1227 | DO22: 2601 | DQ22: 428 | DS22: 19 | DT22: 0 | DU22: 5307 | DX22: مجموع السعوديين | DZ22: =SUM(DZ20:EA21) -> 70 | EB22: =SUM(EB20:EF21) -> 4455 | EG22: =SUM(EG20:EH21) -> 30 | EI22: =SUM(EI20:EJ21) -> 100 | EK22: =SUM(EK20:EK21) -> 15 | EL22: =SUM(EL20:EL21) -> 0 | EM22: =SUM(EM20:EM21) -> 4670 | EP22: مجموع السعوديين | ER22: =SUM(ER20:ES21) -> 355 | ET22: =SUM(ET20:EX21) -> 19 | EY22: =SUM(EY20:EZ21) -> 446 | FA22: =SUM(FA20:FB21) -> 53 | FC22: =SUM(FC20:FC21) -> 0 | FD22: =SUM(FD20:FD21) -> 0 | FE22: =SUM(FE20:FE21) -> 873 | FH22: مجموع السعوديين | FJ22: 970 | FL22: 105 | FQ22: 73 | FS22: 406 | FU22: 26 | FV22: 0 | FW22: 1580 | FZ22: مجموع السعوديين | GB22: =SUM(GB20:GC21) -> 0 | GD22: =SUM(GD20:GH21) -> 0 | GI22: =SUM(GI20:GJ21) -> 0 | GK22: =SUM(GK20:GL21) -> 0 | GM22: =SUM(GM20:GM21) -> 0 | GN22: =SUM(GN20:GN21) -> 0 | GO22: =SUM(GO20:GO21) -> 0 | GR22: مجموع السعوديين | GT22: =SUM(GT20:GU21) -> 0 | GV22: =SUM(GV20:GZ21) -> 0 | HA22: =SUM(HA20:HB21) -> 0 | HC22: =SUM(HC20:HD21) -> 0 | HE22: =SUM(HE20:HE21) -> 0 | HF22: =SUM(HF20:HF21) -> 0 | HG22: =SUM(HG20:HG21) -> 0 | HJ22: مجموع السعوديين | HL22: =SUM(HL20:HM21) -> 5532 | HN22: =SUM(HN20:HR21) -> 15380 | HS22: =SUM(HS20:HT21) -> 9701 | HU22: =SUM(HU20:HV21) -> 2808 | HW22: =SUM(HW20:HW21) -> 139 | HX22: =SUM(HX20:HX21) -> 0 | HY22: =SUM(HY20:HY21) -> 33560
B23: غير سعودي | C23: ذكر | D23: 10 | E23: 1 | F23: 2 | G23: 1 | H23: 4 | I23: 0 | J23: 30 | K23: 13 | L23: 25 | M23: 20 | N23: 0 | O23: 1 | P23: 0 | Q23: =SUM(D23:P23) -> 107 | T23: غير سعودي | U23: ذكر | V23: 27 | W23: 0 | X23: 0 | Y23: 0 | Z23: 5 | AA23: 0 | AB23: 87 | AC23: 20 | AD23: 51 | AE23: 51 | AF23: 0 | AG23: 6 | AH23: 0 | AI23: =SUM(V23:AH23) -> 247 | AL23: غير سعودي | AM23: ذكر | AN23: 90 | AO23: 0 | AP23: 20 | AQ23: 0 | AR23: 20 | AS23: 0 | AT23: 110 | AU23: 20 | AV23: 0 | AW23: 10 | AX23: 0 | AY23: 4 | AZ23: 0 | BA23: =SUM(AN23:AZ23) -> 274 | BD23: غير سعودي | BE23: ذكر | BF23: 0 | BG23: 0 | BH23: 0 | BI23: 0 | BJ23: 0 | BK23: 0 | BL23: 0 | BM23: 0 | BN23: 0 | BO23: 0 | BP23: 0 | BQ23: 0 | BR23: 0 | BS23: =SUM(BF23:BR23) -> 0 | BV23: غير سعودي | BW23: ذكر | BX23: 109 | BY23: 0 | BZ23: 0 | CA23: 22 | CB23: 59 | CC23: 0 | CD23: 73 | CE23: 148 | CF23: 144 | CG23: 82 | CH23: 0 | CI23: 0 | CJ23: 0 | CK23: =SUM(BX23:CJ23) -> 637 | CN23: غير سعودي | CO23: ذكر | CP23: 10 | CQ23: 0 | CR23: 5 | CS23: 0 | CT23: 3 | CU23: 0 | CV23: 100 | CW23: 2 | CX23: 0 | CY23: 5 | CZ23: 0 | DA23: 0 | DB23: 0 | DC23: =SUM(CP23:DB23) -> 125 | DF23: غير سعودي | DG23: ذكر | DH23: 27 | DI23: 0 | DJ23: 0 | DK23: 0 | DL23: 5 | DM23: 0 | DN23: 87 | DO23: 20 | DP23: 51 | DQ23: 51 | DR23: 0 | DS23: 6 | DT23: 0 | DU23: 247 | DX23: غير سعودي | DY23: ذكر | DZ23: 10 | EA23: 0 | EB23: 5 | EC23: 0 | ED23: 3 | EE23: 0 | EF23: 100 | EG23: 2 | EH23: 0 | EI23: 5 | EJ23: 0 | EK23: 0 | EL23: 0 | EM23: =SUM(DZ23:EL23) -> 125 | EP23: غير سعودي | EQ23: ذكر | ER23: 8 | ES23: 0 | ET23: 0 | EU23: 1 | EV23: 0 | EW23: 0 | EX23: 0 | EY23: 5 | EZ23: 4 | FA23: 2 | FB23: 0 | FC23: 0 | FD23: 0 | FE23: =SUM(ER23:FD23) -> 20 | FH23: غير سعودي | FI23: ذكر | FJ23: 30 | FK23: 10 | FL23: 5 | FM23: 5 | FN23: 10 | FO23: 0 | FP23: 0 | FQ23: 20 | FR23: 0 | FS23: 10 | FT23: 0 | FU23: 2 | FV23: 0 | FW23: 92 | FZ23: غير سعودي | GA23: ذكر | GB23: 0 | GC23: 0 | GD23: 0 | GE23: 0 | GF23: 0 | GG23: 0 | GH23: 0 | GI23: 0 | GJ23: 0 | GK23: 0 | GL23: 0 | GM23: 0 | GN23: 0 | GO23: =SUM(GB23:GN23) -> 0 | GR23: غير سعودي | GS23: ذكر | GT23: 0 | GU23: 0 | GV23: 0 | GW23: 0 | GX23: 0 | GY23: 0 | GZ23: 0 | HA23: 0 | HB23: 0 | HC23: 0 | HD23: 0 | HE23: 0 | HF23: 0 | HG23: =SUM(GT23:HF23) -> 0 | HJ23: غير سعودي | HK23: ذكر | HL23: =SUM(D23+V23+AN23+BF23+BX23+CP23+DH23+DZ23+ER23+FJ23+GB23+GT23) -> 321 | HM23: =SUM(E23+W23+AO23+BG23+BY23+CQ23+DI23+EA23+ES23+FK23+GC23+GU23) -> 11 | HN23: =SUM(F23+X23+AP23+BH23+BZ23+CR23+DJ23+EB23+ET23+FL23+GD23+GV23) -> 37 | HO23: =SUM(G23+Y23+AQ23+BI23+CA23+CS23+DK23+EC23+EU23+FM23+GE23+GW23) -> 29 | HP23: =SUM(H23+Z23+AR23+BJ23+CB23+CT23+DL23+ED23+EV23+FN23+GF23+GX23) -> 109 | HQ23: =SUM(I23+AA23+AS23+BK23+CC23+CU23+DM23+EE23+EW23+FO23+GG23+GY23) -> 0 | HR23: =SUM(J23+AB23+AT23+BL23+CD23+CV23+DN23+EF23+EX23+FP23+GH23+GZ23) -> 587 | HS23: =SUM(K23+AC23+AU23+BM23+CE23+CW23+DO23+EG23+EY23+FQ23+GI23+HA23) -> 250 | ... HX23: =SUM(P23+AH23+AZ23+BR23+CJ23+DB23+DT23+EL23+FD23+FV23+GN23+HF23) -> 0 | HY23: =SUM(HL23:HX23) -> 1874
C24: أنثى | D24: 20 | E24: 1 | F24: 4 | G24: 1 | H24: 10 | I24: 0 | J24: 55 | K24: 20 | L24: 20 | M24: 15 | N24: 0 | O24: 4 | P24: 0 | Q24: =SUM(D24:P24) -> 150 | U24: أنثى | V24: 35 | W24: 0 | X24: 0 | Y24: 0 | Z24: 10 | AA24: 0 | AB24: 67 | AC24: 30 | AD24: 85 | AE24: 43 | AF24: 13 | AG24: 9 | AH24: 0 | AI24: =SUM(V24:AH24) -> 292 | AM24: أنثى | AN24: 80 | AO24: 0 | AP24: 40 | AQ24: 5 | AR24: 15 | AS24: 0 | AT24: 100 | AU24: 31 | AV24: 0 | AW24: 15 | AX24: 5 | AY24: 4 | AZ24: 0 | BA24: =SUM(AN24:AZ24) -> 295 | BE24: أنثى | BF24: 0 | BG24: 0 | BH24: 0 | BI24: 0 | BJ24: 0 | BK24: 0 | BL24: 0 | BM24: 0 | BN24: 0 | BO24: 0 | BP24: 0 | BQ24: 0 | BR24: 0 | BS24: =SUM(BF24:BR24) -> 0 | BW24: أنثى | BX24: 47 | BY24: 0 | BZ24: 0 | CA24: 0 | CB24: 6 | CC24: 0 | CD24: 85 | CE24: 211 | CF24: 118 | CG24: 2 | CH24: 15 | CI24: 0 | CJ24: 0 | CK24: =SUM(BX24:CJ24) -> 484 | CO24: أنثى | CP24: 15 | CQ24: 0 | CR24: 10 | CS24: 0 | CT24: 5 | CU24: 0 | CV24: 180 | CW24: 5 | CX24: 0 | CY24: 5 | CZ24: 0 | DA24: 0 | DB24: 0 | DC24: =SUM(CP24:DB24) -> 220 | DG24: أنثى | DH24: 35 | DI24: 0 | DJ24: 0 | DK24: 0 | DL24: 10 | DM24: 0 | DN24: 67 | DO24: 30 | DP24: 85 | DQ24: 43 | DR24: 13 | DS24: 9 | DT24: 0 | DU24: 292 | DY24: أنثى | DZ24: 15 | EA24: 0 | EB24: 10 | EC24: 0 | ED24: 5 | EE24: 0 | EF24: 180 | EG24: 5 | EH24: 0 | EI24: 5 | EJ24: 0 | EK24: 0 | EL24: 0 | EM24: =SUM(DZ24:EL24) -> 220 | EQ24: أنثى | ER24: 9 | ES24: 0 | ET24: 0 | EU24: 3 | EV24: 0 | EW24: 0 | EX24: 0 | EY24: 8 | EZ24: 7 | FA24: 1 | FB24: 1 | FC24: 0 | FD24: 0 | FE24: =SUM(ER24:FD24) -> 29 | FI24: أنثى | FJ24: 20 | FK24: 20 | FL24: 5 | FM24: 5 | FN24: 10 | FO24: 0 | FP24: 0 | FQ24: 30 | FR24: 0 | FS24: 20 | FT24: 10 | FU24: 3 | FV24: 0 | FW24: 123 | GA24: أنثى | GB24: 0 | GC24: 0 | GD24: 0 | GE24: 0 | GF24: 0 | GG24: 0 | GH24: 0 | GI24: 0 | GJ24: 0 | GK24: 0 | GL24: 0 | GM24: 0 | GN24: 0 | GO24: =SUM(GB24:GN24) -> 0 | GS24: أنثى | GT24: 0 | GU24: 0 | GV24: 0 | GW24: 0 | GX24: 0 | GY24: 0 | GZ24: 0 | HA24: 0 | HB24: 0 | HC24: 0 | HD24: 0 | HE24: 0 | HF24: 0 | HG24: =SUM(GT24:HF24) -> 0 | HK24: أنثى | HL24: =SUM(D24+V24+AN24+BF24+BX24+CP24+DH24+DZ24+ER24+FJ24+GB24+GT24) -> 276 | HM24: =SUM(E24+W24+AO24+BG24+BY24+CQ24+DI24+EA24+ES24+FK24+GC24+GU24) -> 21 | HN24: =SUM(F24+X24+AP24+BH24+BZ24+CR24+DJ24+EB24+ET24+FL24+GD24+GV24) -> 69 | HO24: =SUM(G24+Y24+AQ24+BI24+CA24+CS24+DK24+EC24+EU24+FM24+GE24+GW24) -> 14 | HP24: =SUM(H24+Z24+AR24+BJ24+CB24+CT24+DL24+ED24+EV24+FN24+GF24+GX24) -> 71 | HQ24: =SUM(I24+AA24+AS24+BK24+CC24+CU24+DM24+EE24+EW24+FO24+GG24+GY24) -> 0 | HR24: =SUM(J24+AB24+AT24+BL24+CD24+CV24+DN24+EF24+EX24+FP24+GH24+GZ24) -> 734 | HS24: =SUM(K24+AC24+AU24+BM24+CE24+CW24+DO24+EG24+EY24+FQ24+GI24+HA24) -> 370 | ... HX24: =SUM(P24+AH24+AZ24+BR24+CJ24+DB24+DT24+EL24+FD24+FV24+GN24+HF24) -> 0 | HY24: =SUM(HL24:HX24) -> 2105
