Workbook

Sheet رعاية أمومة
B1: رعاية الأمومة | G1: شهر | H1: 1 | I1: 1447 | J1: هـ | L1: رعاية الأمومة | Q1: شهر | R1: 2 | S1: 1447 | T1: هـ | V1: رعاية الأمومة | AA1: شهر | AB1: 3 | AC1: 1447 | AD1: هـ | AF1: رعاية الأمومة | AK1: شهر | AL1: 4 | AM1: 1447 | AN1: هـ | AP1: رعاية الأمومة | AU1: شهر | AV1: 5 | AW1: 1447 | AX1: هـ | AZ1: رعاية الأمومة | BE1: شهر | BF1: 6 | BG1: 1447 | BH1: هـ | BJ1: رعاية الأمومة | BO1: شهر | BP1: 7 | BQ1: 1447 | BR1: هـ | BT1: رعاية الأمومة | BY1: شهر | BZ1: 8 | CA1: 1447 | CB1: هـ | CD1: رعاية الأمومة | CI1: شهر | CJ1: 9 | CK1: 1447 | CL1: هـ | CN1: رعاية الأمومة | CS1: شهر | CT1: 10 | CU1: 1447 | CV1: هـ | CX1: رعاية الأمومة | DC1: شهر | DD1: 11 | DE1: 1447 | DF1: هـ | DH1: رعاية الأمومة | DM1: شهر | DN1: 12 | DO1: 1447 | DP1: هـ | DR1: رعاية الأمومة | DX1: عام | DY1: =SUM(DO1) -> 1447
B2: العدد | C2: إجمالي الحوامل المسجلات | D2: الحوامل الجدد | E2: المعرضات للخطر | F2: زيارات الحوامل خلال الشهر | G2: عدد النساء في سن الإنجاب | L2: العدد | M2: إجمالي الحوامل المسجلات | N2: الحوامل الجدد | O2: المعرضات للخطر | P2: زيارات الحوامل خلال الشهر | Q2: عدد النساء في سن الإنجاب | V2: العدد | W2: إجمالي الحوامل المسجلات | X2: الحوامل الجدد | Y2: المعرضات للخطر | Z2: زيارات الحوامل خلال الشهر | AA2: عدد النساء في سن الإنجاب | AF2: العدد | AG2: إجمالي الحوامل المسجلات | AH2: الحوامل الجدد | AI2: المعرضات للخطر | AJ2: زيارات الحوامل خلال الشهر | AK2: عدد النساء في سن الإنجاب | AP2: العدد | AQ2: إجمالي الحوامل المسجلات | AR2: الحوامل الجدد | AS2: المعرضات للخطر | AT2: زيارات الحوامل خلال الشهر | AU2: عدد النساء في سن الإنجاب | AZ2: العدد | BA2: إجمالي الحوامل المسجلات | BB2: الحوامل الجدد | BC2: المعرضات للخطر | BD2: زيارات الحوامل خلال الشهر | BE2: عدد النساء في سن الإنجاب | BJ2: العدد | BK2: إجمالي الحوامل المسجلات | BL2: الحوامل الجدد | BM2: المعرضات للخطر | BN2: زيارات الحوامل خلال الشهر | BO2: عدد النساء في سن الإنجاب | BT2: العدد | BU2: إجمالي الحوامل المسجلات | BV2: الحوامل الجدد | BW2: المعرضات للخطر | BX2: زيارات الحوامل خلال الشهر | BY2: عدد النساء في سن الإنجاب | CD2: العدد | CE2: إجمالي الحوامل المسجلات | CF2: الحوامل الجدد | CG2: المعرضات للخطر | CH2: زيارات الحوامل خلال الشهر | CI2: عدد النساء في سن الإنجاب | CN2: العدد | CO2: إجمالي الحوامل المسجلات | CP2: الحوامل الجدد | CQ2: المعرضات للخطر | CR2: زيارات الحوامل خلال الشهر | CS2: عدد النساء في سن الإنجاب | CX2: العدد | CY2: إجمالي الحوامل المسجلات | CZ2: الحوامل الجدد | DA2: المعرضات للخطر | DB2: زيارات الحوامل خلال الشهر | DC2: عدد النساء في سن الإنجاب | DH2: العدد | DI2: إجمالي الحوامل المسجلات | DJ2: الحوامل الجدد | DK2: المعرضات للخطر | DL2: زيارات الحوامل خلال الشهر | DM2: عدد النساء في سن الإنجاب | DR2: العدد | DS2: إجمالي الحوامل المسجلات | DT2: الحوامل الجدد | DU2: المعرضات للخطر | DV2: زيارات الحوامل خلال العام | DW2: عدد النساء في سن الإنجاب
B3: الجنسية | L3: الجنسية | V3: الجنسية | AF3: الجنسية | AP3: الجنسية | AZ3: الجنسية | BJ3: الجنسية | BT3: الجنسية | CD3: الجنسية | CN3: الجنسية | CX3: الجنسية | DH3: الجنسية | DR3: الجنسية
B4: الربيع والتوفيق | L4: الربيع والتوفيق | V4: الربيع والتوفيق | AF4: الربيع والتوفيق | AP4: الربيع والتوفيق | AZ4: الربيع والتوفيق | BJ4: الربيع والتوفيق | BT4: الربيع والتوفيق | CD4: الربيع والتوفيق | CN4: الربيع والتوفيق | CX4: الربيع والتوفيق | DH4: الربيع والتوفيق | DR4: =(DH4) -> الربيع والتوفيق
B5: سعودي | C5: 16 | D5: 2 | E5: 0 | F5: 5 | G5: عدد النساء في سن الإنجاب | H5: 8976 | I5: المتزوجات | J5: =H5*38/100 -> 3410.88 | L5: سعودي | M5: 13 | N5: 5 | O5: 3 | P5: 5 | Q5: عدد النساء في سن الإنجاب | R5: 7899 | S5: المتزوجات | T5: =R5*38/100 -> 3001.62 | V5: سعودي | W5: 24 | X5: 1 | Y5: 9 | Z5: 2 | AA5: عدد النساء في سن الإنجاب | AB5: 8976 | AC5: المتزوجات | AD5: =AB5*38/100 -> 3410.88 | AF5: سعودي | AG5: 24 | AH5: 5 | AI5: 10 | AJ5: 24 | AK5: عدد النساء في سن الإنجاب | AL5: 8976 | AM5: المتزوجات | AN5: =AL5*38/100 -> 3410.88 | AP5: سعودي | AQ5: 24 | AR5: 3 | AS5: 2 | AT5: 3 | AU5: عدد النساء في سن الإنجاب | AV5: 8976 | AW5: المتزوجات | AX5: =AV5*38/100 -> 3410.88 | AZ5: سعودي | BA5: 24 | BB5: 0 | BC5: 4 | BD5: 1 | BE5: عدد النساء في سن الإنجاب | BF5: 8976 | BG5: المتزوجات | BH5: =BF5*38/100 -> 3410.88 | BJ5: سعودي | BK5: 24 | BL5: 0 | BM5: 0 | BN5: 0 | BO5: عدد النساء في سن الإنجاب | BP5: 8976 | BQ5: المتزوجات | BR5: =BP5*38/100 -> 3410.88 | BT5: سعودي | BU5: 24 | BV5: 0 | BW5: 0 | BX5: 1 | BY5: عدد النساء في سن الإنجاب | BZ5: 8976 | CA5: المتزوجات | CB5: =BZ5*38/100 -> 3410.88 | CD5: سعودي | CE5: 24 | CF5: 0 | CG5: 0 | CH5: 19 | CI5: عدد النساء في سن الإنجاب | CJ5: 8976 | CK5: المتزوجات | CL5: =CJ5*38/100 -> 3410.88 | CN5: سعودي | CO5: 23 | CP5: 0 | CQ5: 0 | CR5: 2 | CS5: عدد النساء في سن الإنجاب | CT5: 8976 | CU5: المتزوجات | CV5: =CT5*38/100 -> 3410.88 | CX5: سعودي | CY5: 0 | CZ5: 0 | DA5: 0 | DB5: 0 | DC5: عدد النساء في سن الإنجاب | DD5: 0 | DE5: المتزوجات | DF5: =DD5*38/100 -> 0 | DH5: سعودي | DI5: 0 | DJ5: 0 | DK5: 0 | DL5: 0 | DM5: عدد النساء في سن الإنجاب | DN5: 0 | DO5: المتزوجات | DP5: =DN5*38/100 -> 0 | DR5: سعودي | DS5: =C5+DT5-D5 -> 30 | DT5: =D5+N5+X5+AH5+AR5+BB5+BL5+BV5+CF5+CP5+CZ5+DJ5 -> 16 | DU5: =(E5+O5+Y5+AI5+AS5+BC5+BM5+BW5+CG5+CQ5+DA5+DK5)/12 -> 2.3333333 | DV5: =F5+P5+Z5+AJ5+AT5+BD5+BN5+BX5+CH5+CR5+DB5+DL5 -> 62 | DW5: عدد النساء في سن الإنجاب | DX5: =DN5 -> 0 | DY5: المتزوجات | DZ5: =DX5*38/100 -> 0
B6: غ.سعودي | C6: 9 | D6: 0 | E6: 0 | F6: 0 | L6: غ.سعودي | M6: 4 | N6: 1 | O6: 0 | P6: 1 | V6: غ.سعودي | W6: 4 | X6: 0 | Y6: 2 | Z6: 0 | AF6: غ.سعودي | AG6: 4 | AH6: 0 | AI6: 2 | AJ6: 2 | AP6: غ.سعودي | AQ6: 4 | AR6: 0 | AS6: 0 | AT6: 0 | AZ6: غ.سعودي | BA6: 4 | BB6: 1 | BC6: 2 | BD6: 1 | BJ6: غ.سعودي | BK6: 4 | BL6: 0 | BM6: 0 | BN6: 0 | BT6: غ.سعودي | BU6: 4 | BV6: 0 | BW6: 0 | BX6: 1 | CD6: غ.سعودي | CE6: 2 | CF6: 0 | CG6: 0 | CH6: 2 | CN6: غ.سعودي | CO6: 2 | CP6: 0 | CQ6: 0 | CR6: 1 | CX6: غ.سعودي | CY6: 0 | CZ6: 0 | DA6: 0 | DB6: 0 | DH6: غ.سعودي | DI6: 0 | DJ6: 0 | DK6: 0 | DL6: 0 | DR6: غ.سعودي | DS6: =C6+DT6-D6 -> 11 | DT6: =D6+N6+X6+AH6+AR6+BB6+BL6+BV6+CF6+CP6+CZ6+DJ6 -> 2 | DU6: =(E6+O6+Y6+AI6+AS6+BC6+BM6+BW6+CG6+CQ6+DA6+DK6)/12 -> 0.5 | DV6: =F6+P6+Z6+AJ6+AT6+BD6+BN6+BX6+CH6+CR6+DB6+DL6 -> 8
B7: المجموع | C7: =SUM(C5:C6) -> 25 | D7: =SUM(D5:D6) -> 2 | E7: =SUM(E5:E6) -> 0 | F7: =SUM(F5:F6) -> 5 | L7: المجموع | M7: =SUM(M5:M6) -> 17 | N7: 6 | O7: 3 | P7: 6 | V7: المجموع | W7: =SUM(W5:W6) -> 28 | X7: =SUM(X5:X6) -> 1 | Y7: =SUM(Y5:Y6) -> 11 | Z7: =SUM(Z5:Z6) -> 2 | AF7: المجموع | AG7: =SUM(AG5:AG6) -> 28 | AH7: =SUM(AH5:AH6) -> 5 | AI7: =SUM(AI5:AI6) -> 12 | AJ7: =SUM(AJ5:AJ6) -> 26 | AP7: المجموع | AQ7: =SUM(AQ5:AQ6) -> 28 | AR7: =SUM(AR5:AR6) -> 3 | AS7: =SUM(AS5:AS6) -> 2 | AT7: =SUM(AT5:AT6) -> 3 | AZ7: المجموع | BA7: =SUM(BA5:BA6) -> 28 | BB7: =SUM(BB5:BB6) -> 1 | BC7: =SUM(BC5:BC6) -> 6 | BD7: =SUM(BD5:BD6) -> 2 | BJ7: المجموع | BK7: =SUM(BK5:BK6) -> 28 | BL7: =SUM(BL5:BL6) -> 0 | BM7: =SUM(BM5:BM6) -> 0 | BN7: =SUM(BN5:BN6) -> 0 | BT7: المجموع | BU7: =SUM(BU5:BU6) -> 28 | BV7: =SUM(BV5:BV6) -> 0 | BW7: =SUM(BW5:BW6) -> 0 | BX7: =SUM(BX5:BX6) -> 2 | CD7: المجموع | CE7: =SUM(CE5:CE6) -> 26 | CF7: =SUM(CF5:CF6) -> 0 | CG7: =SUM(CG5:CG6) -> 0 | CH7: =SUM(CH5:CH6) -> 21 | CN7: المجموع | CO7: =SUM(CO5:CO6) -> 25 | CP7: =SUM(CP5:CP6) -> 0 | CQ7: =SUM(CQ5:CQ6) -> 0 | CR7: =SUM(CR5:CR6) -> 3 | CX7: المجموع | CY7: =SUM(CY5:CY6) -> 0 | CZ7: =SUM(CZ5:CZ6) -> 0 | DA7: =SUM(DA5:DA6) -> 0 | DB7: =SUM(DB5:DB6) -> 0 | DH7: المجموع | DI7: =SUM(DI5:DI6) -> 0 | DJ7: =SUM(DJ5:DJ6) -> 0 | DK7: =SUM(DK5:DK6) -> 0 | DL7: =SUM(DL5:DL6) -> 0 | DR7: المجموع | DS7: =SUM(DS5:DS6) -> 41 | DT7: =SUM(DT5:DT6) -> 18 | DU7: =SUM(DU5:DU6) -> 2.8333333 | DV7: =SUM(DV5:DV6) -> 70
B8: الجامعة | L8: الجامعة | V8: الجامعة | AF8: الجامعة | AP8: الجامعة | AZ8: الجامعة | BJ8: الجامعة | BT8: الجامعة | CD8: الجامعة | CN8: الجامعة | CX8: الجامعة | DH8: الجامعة | DR8: =(DH8) -> الجامعة
B9: سعودي | C9: 13 | D9: 2 | E9: 2 | F9: 25 | G9: عدد النساء في سن الإنجاب | H9: 12800 | I9: المتزوجات | J9: =H9*38/100 -> 4864 | L9: سعودي | M9: 15 | N9: 3 | O9: 7 | P9: 20 | Q9: عدد النساء في سن الإنجاب | R9: 12800 | S9: المتزوجات | T9: =R9*38/100 -> 4864 | V9: سعودي | W9: 19 | X9: 4 | Y9: 2 | Z9: 19 | AA9: عدد النساء في سن الإنجاب | AB9: 12800 | AC9: المتزوجات | AD9: =AB9*38/100 -> 4864 | AF9: سعودي | AG9: 22 | AH9: 16 | AI9: 1 | AJ9: 22 | AK9: عدد النساء في سن الإنجاب | AL9: 12800 | AM9: المتزوجات | AN9: =AL9*38/100 -> 4864 | AP9: سعودي | AQ9: 22 | AR9: 0 | AS9: 0 | AT9: 18 | AU9: عدد النساء في سن الإنجاب | AV9: 12800 | AW9: المتزوجات | AX9: =AV9*38/100 -> 4864 | AZ9: سعودي | BA9: 22 | BB9: 4 | BC9: 3 | BD9: 33 | BE9: عدد النساء في سن الإنجاب | BF9: 12800 | BG9: المتزوجات | BH9: =BF9*38/100 -> 4864 | BJ9: سعودي | BK9: 22 | BL9: 0 | BM9: 0 | BN9: 18 | BO9: عدد النساء في سن الإنجاب | BP9: 12800 | BQ9: المتزوجات | BR9: =BP9*38/100 -> 4864 | BT9: سعودي | BU9: 22 | BV9: 0 | BW9: 0 | BX9: 33 | BY9: عدد النساء في سن الإنجاب | BZ9: 12800 | CA9: المتزوجات | CB9: =BZ9*38/100 -> 4864 | CD9: سعودي | CE9: 22 | CF9: 0 | CG9: 0 | CH9: 18 | CI9: عدد النساء في سن الإنجاب | CJ9: 12800 | CK9: المتزوجات | CL9: =CJ9*38/100 -> 4864 | CN9: سعودي | CO9: 0 | CP9: 0 | CQ9: 0 | CR9: 0 | CS9: عدد النساء في سن الإنجاب | CT9: 0 | CU9: المتزوجات | CV9: =CT9*38/100 -> 0 | CX9: سعودي | CY9: 0 | CZ9: 0 | DA9: 0 | DB9: 0 | DC9: عدد النساء في سن الإنجاب | DD9: 0 | DE9: المتزوجات | DF9: =DD9*38/100 -> 0 | DH9: سعودي | DI9: 0 | DJ9: 0 | DK9: 0 | DL9: 0 | DM9: عدد النساء في سن الإنجاب | DN9: 0 | DO9: المتزوجات | DP9: =DN9*38/100 -> 0 | DR9: سعودي | DS9: =C9+DT9-D9 -> 40 | DT9: =D9+N9+X9+AH9+AR9+BB9+BL9+BV9+CF9+CP9+CZ9+DJ9 -> 29 | DU9: =(E9+O9+Y9+AI9+AS9+BC9+BM9+BW9+CG9+CQ9+DA9+DK9)/12 -> 1.25 | DV9: =F9+P9+Z9+AJ9+AT9+BD9+BN9+BX9+CH9+CR9+DB9+DL9 -> 206 | DW9: عدد النساء في سن الإنجاب | DX9: =DN9 -> 0 | DY9: المتزوجات | DZ9: =DX9*38/100 -> 0
B10: غ.سعودي | C10: 3 | D10: 0 | E10: 0 | F10: 5 | L10: غ.سعودي | M10: 6 | N10: 0 | O10: 4 | P10: 5 | V10: غ.سعودي | W10: 5 | X10: 0 | Y10: 0 | Z10: 5 | AF10: غ.سعودي | AG10: 12 | AH10: 10 | AI10: 1 | AJ10: 12 | AP10: غ.سعودي | AQ10: 12 | AR10: 0 | AS10: 0 | AT10: 4 | AZ10: غ.سعودي | BA10: 12 | BB10: 0 | BC10: 0 | BD10: 13 | BJ10: غ.سعودي | BK10: 12 | BL10: 0 | BM10: 0 | BN10: 4 | BT10: غ.سعودي | BU10: 12 | BV10: 0 | BW10: 0 | BX10: 13 | CD10: غ.سعودي | CE10: 12 | CF10: 0 | CG10: 0 | CH10: 4 | CN10: غ.سعودي | CO10: 0 | CP10: 0 | CQ10: 0 | CR10: 0 | CX10: غ.سعودي | CY10: 0 | CZ10: 0 | DA10: 0 | DB10: 0 | DH10: غ.سعودي | DI10: 0 | DJ10: 0 | DK10: 0 | DL10: 0 | DR10: غ.سعودي | DS10: =C10+DT10-D10 -> 13 | DT10: =D10+N10+X10+AH10+AR10+BB10+BL10+BV10+CF10+CP10+CZ10+DJ10 -> 10 | DU10: =(E10+O10+Y10+AI10+AS10+BC10+BM10+BW10+CG10+CQ10+DA10+DK10)/12 -> 0.41666667 | DV10: =F10+P10+Z10+AJ10+AT10+BD10+BN10+BX10+CH10+CR10+DB10+DL10 -> 65
B11: المجموع | C11: =SUM(C9:C10) -> 16 | D11: =SUM(D9:D10) -> 2 | E11: =SUM(E9:E10) -> 2 | F11: =SUM(F9:F10) -> 30 | L11: المجموع | M11: =SUM(M9:M10) -> 21 | N11: =SUM(N9:N10) -> 3 | O11: =SUM(O9:O10) -> 11 | P11: =SUM(P9:P10) -> 25 | V11: المجموع | W11: =SUM(W9:W10) -> 24 | X11: =SUM(X9:X10) -> 4 | Y11: =SUM(Y9:Y10) -> 2 | Z11: =SUM(Z9:Z10) -> 24 | AF11: المجموع | AG11: =SUM(AG9:AG10) -> 34 | AH11: =SUM(AH9:AH10) -> 26 | AI11: =SUM(AI9:AI10) -> 2 | AJ11: =SUM(AJ9:AJ10) -> 34 | AP11: المجموع | AQ11: =SUM(AQ9:AQ10) -> 34 | AR11: =SUM(AR9:AR10) -> 0 | AS11: =SUM(AS9:AS10) -> 0 | AT11: =SUM(AT9:AT10) -> 22 | AZ11: المجموع | BA11: =SUM(BA9:BA10) -> 34 | BB11: =SUM(BB9:BB10) -> 4 | BC11: =SUM(BC9:BC10) -> 3 | BD11: =SUM(BD9:BD10) -> 46 | BJ11: المجموع | BK11: =SUM(BK9:BK10) -> 34 | BL11: =SUM(BL9:BL10) -> 0 | BM11: =SUM(BM9:BM10) -> 0 | BN11: =SUM(BN9:BN10) -> 22 | BT11: المجموع | BU11: =SUM(BU9:BU10) -> 34 | BV11: =SUM(BV9:BV10) -> 0 | BW11: =SUM(BW9:BW10) -> 0 | BX11: =SUM(BX9:BX10) -> 46 | CD11: المجموع | CE11: =SUM(CE9:CE10) -> 34 | CF11: =SUM(CF9:CF10) -> 0 | CG11: =SUM(CG9:CG10) -> 0 | CH11: =SUM(CH9:CH10) -> 22 | CN11: المجموع | CO11: =SUM(CO9:CO10) -> 0 | CP11: =SUM(CP9:CP10) -> 0 | CQ11: =SUM(CQ9:CQ10) -> 0 | CR11: =SUM(CR9:CR10) -> 0 | CX11: المجموع | CY11: =SUM(CY9:CY10) -> 0 | CZ11: =SUM(CZ9:CZ10) -> 0 | DA11: =SUM(DA9:DA10) -> 0 | DB11: =SUM(DB9:DB10) -> 0 | DH11: المجموع | DI11: =SUM(DI9:DI10) -> 0 | DJ11: =SUM(DJ9:DJ10) -> 0 | DK11: =SUM(DK9:DK10) -> 0 | DL11: =SUM(DL9:DL10) -> 0 | DR11: المجموع | DS11: =SUM(DS9:DS10) -> 53 | DT11: =SUM(DT9:DT10) -> 39 | DU11: =SUM(DU9:DU10) -> 1.6666667 | DV11: =SUM(DV9:DV10) -> 271
B12: السليمانية | L12: السليمانية | V12: السليمانية | AF12: السليمانية | AP12: السليمانية | AZ12: السليمانية | BJ12: السليمانية | BT12: السليمانية | CD12: السليمانية | CN12: السليمانية | CX12: السليمانية | DH12: السليمانية | DR12: =(DH12) -> السليمانية
B13: سعودي | C13: 25 | D13: 2 | E13: 3 | F13: 7 | G13: عدد النساء في سن الإنجاب | H13: 9766 | I13: المتزوجات | J13: =H13*38/100 -> 3711.08 | L13: سعودي | M13: 36 | N13: 5 | O13: 0 | P13: 20 | Q13: عدد النساء في سن الإنجاب | R13: 8544 | S13: المتزوجات | T13: =R13*38/100 -> 3246.72 | V13: سعودي | W13: 0 | X13: 0 | Y13: 0 | Z13: 0 | AA13: عدد النساء في سن الإنجاب | AB13: 0 | AC13: المتزوجات | AD13: =AB13*38/100 -> 0 | AF13: سعودي | AG13: 0 | AH13: 0 | AI13: 0 | AJ13: 16 | AK13: عدد النساء في سن الإنجاب | AL13: 8544 | AM13: المتزوجات | AN13: =AL13*38/100 -> 3246.72 | AP13: سعودي | AQ13: 0 | AR13: 0 | AS13: 0 | AT13: 1 | AU13: عدد النساء في سن الإنجاب | AV13: 8544 | AW13: المتزوجات | AX13: =AV13*38/100 -> 3246.72 | AZ13: سعودي | BA13: 73 | BB13: 0 | BC13: 3 | BD13: 0 | BE13: عدد النساء في سن الإنجاب | BF13: 8544 | BG13: المتزوجات | BH13: =BF13*38/100 -> 3246.72 | BJ13: سعودي | BK13: 74 | BL13: 0 | BM13: 0 | BN13: 22 | BO13: عدد النساء في سن الإنجاب | BP13: 8544 | BQ13: المتزوجات | BR13: =BP13*38/100 -> 3246.72 | BT13: سعودي | BU13: 74 | BV13: 0 | BW13: 0 | BX13: 0 | BY13: عدد النساء في سن الإنجاب | BZ13: 8544 | CA13: المتزوجات | CB13: =BZ13*38/100 -> 3246.72 | CD13: سعودي | CE13: 74 | CF13: 0 | CG13: 0 | CH13: 35 | CI13: عدد النساء في سن الإنجاب | CJ13: 8544 | CK13: المتزوجات | CL13: =CJ13*38/100 -> 3246.72 | CN13: سعودي | CO13: 0 | CP13: 0 | CQ13: 0 | CR13: 25 | CS13: عدد النساء في سن الإنجاب | CT13: 8544 | CU13: المتزوجات | CV13: =CT13*38/100 -> 3246.72 | CX13: سعودي | CY13: 0 | CZ13: 0 | DA13: 0 | DB13: 0 | DC13: عدد النساء في سن الإنجاب | DD13: 0 | DE13: المتزوجات | DF13: =DD13*38/100 -> 0 | DH13: سعودي | DI13: 0 | DJ13: 0 | DK13: 0 | DL13: 0 | DM13: عدد النساء في سن الإنجاب | DN13: 0 | DO13: المتزوجات | DP13: =DN13*38/100 -> 0 | DR13: سعودي | DS13: =C13+DT13-D13 -> 30 | DT13: =D13+N13+X13+AH13+AR13+BB13+BL13+BV13+CF13+CP13+CZ13+DJ13 -> 7 | DU13: =(E13+O13+Y13+AI13+AS13+BC13+BM13+BW13+CG13+CQ13+DA13+DK13)/12 -> 0.5 | DV13: =F13+P13+Z13+AJ13+AT13+BD13+BN13+BX13+CH13+CR13+DB13+DL13 -> 126 | DW13: عدد النساء في سن الإنجاب | DX13: =DN13 -> 0 | DY13: المتزوجات | DZ13: =DX13*38/100 -> 0
B14: غ.سعودي | C14: 0 | D14: 0 | E14: 0 | F14: 0 | L14: غ.سعودي | M14: 0 | N14: 0 | O14: 0 | P14: 0 | V14: غ.سعودي | W14: 0 | X14: 0 | Y14: 0 | Z14: 0 | AF14: غ.سعودي | AG14: 0 | AH14: 0 | AI14: 0 | AJ14: 1 | AP14: غ.سعودي | AQ14: 0 | AR14: 0 | AS14: 0 | AT14: 0 | AZ14: غ.سعودي | BA14: 21 | BB14: 0 | BC14: 4 | BD14: 0 | BJ14: غ.سعودي | BK14: 22 | BL14: 0 | BM14: 0 | BN14: 0 | BT14: غ.سعودي | BU14: 22 | BV14: 0 | BW14: 0 | BX14: 0 | CD14: غ.سعودي | CE14: 22 | CF14: 0 | CG14: 0 | CH14: 5 | CN14: غ.سعودي | CO14: 0 | CP14: 0 | CQ14: 0 | CR14: 0 | CX14: غ.سعودي | CY14: 0 | CZ14: 0 | DA14: 0 | DB14: 0 | DH14: غ.سعودي | DI14: 0 | DJ14: 0 | DK14: 0 | DL14: 0 | DR14: غ.سعودي | DS14: =C14+DT14-D14 -> 0 | DT14: =D14+N14+X14+AH14+AR14+BB14+BL14+BV14+CF14+CP14+CZ14+DJ14 -> 0 | DU14: =(E14+O14+Y14+AI14+AS14+BC14+BM14+BW14+CG14+CQ14+DA14+DK14)/12 -> 0.33333333 | DV14: =F14+P14+Z14+AJ14+AT14+BD14+BN14+BX14+CH14+CR14+DB14+DL14 -> 6
B15: المجموع | C15: =SUM(C13:C14) -> 25 | D15: =SUM(D13:D14) -> 2 | E15: =SUM(E13:E14) -> 3 | F15: =SUM(F13:F14) -> 7 | L15: المجموع | M15: =SUM(M13:M14) -> 36 | N15: =SUM(N13:N14) -> 5 | O15: =SUM(O13:O14) -> 0 | P15: =SUM(P13:P14) -> 20 | V15: المجموع | W15: =SUM(W13:W14) -> 0 | X15: =SUM(X13:X14) -> 0 | Y15: =SUM(Y13:Y14) -> 0 | Z15: =SUM(Z13:Z14) -> 0 | AF15: المجموع | AG15: =SUM(AG13:AG14) -> 0 | AH15: =SUM(AH13:AH14) -> 0 | AI15: =SUM(AI13:AI14) -> 0 | AJ15: =SUM(AJ13:AJ14) -> 17 | AP15: المجموع | AQ15: =SUM(AQ13:AQ14) -> 0 | AR15: =SUM(AR13:AR14) -> 0 | AS15: =SUM(AS13:AS14) -> 0 | AT15: =SUM(AT13:AT14) -> 1 | AZ15: المجموع | BA15: =SUM(BA13:BA14) -> 94 | BB15: =SUM(BB13:BB14) -> 0 | BC15: =SUM(BC13:BC14) -> 7 | BD15: =SUM(BD13:BD14) -> 0 | BJ15: المجموع | BK15: =SUM(BK13:BK14) -> 96 | BL15: =SUM(BL13:BL14) -> 0 | BM15: =SUM(BM13:BM14) -> 0 | BN15: =SUM(BN13:BN14) -> 22 | BT15: المجموع | BU15: =SUM(BU13:BU14) -> 96 | BV15: =SUM(BV13:BV14) -> 0 | BW15: =SUM(BW13:BW14) -> 0 | BX15: =SUM(BX13:BX14) -> 0 | CD15: المجموع | CE15: =SUM(CE13:CE14) -> 96 | CF15: =SUM(CF13:CF14) -> 0 | CG15: =SUM(CG13:CG14) -> 0 | CH15: =SUM(CH13:CH14) -> 40 | CN15: المجموع | CO15: =SUM(CO13:CO14) -> 0 | CP15: =SUM(CP13:CP14) -> 0 | CQ15: =SUM(CQ13:CQ14) -> 0 | CR15: =SUM(CR13:CR14) -> 25 | CX15: المجموع | CY15: =SUM(CY13:CY14) -> 0 | CZ15: =SUM(CZ13:CZ14) -> 0 | DA15: =SUM(DA13:DA14) -> 0 | DB15: =SUM(DB13:DB14) -> 0 | DH15: المجموع | DI15: =SUM(DI13:DI14) -> 0 | DJ15: =SUM(DJ13:DJ14) -> 0 | DK15: =SUM(DK13:DK14) -> 0 | DL15: =SUM(DL13:DL14) -> 0 | DR15: المجموع | DS15: =SUM(DS13:DS14) -> 30 | DT15: =SUM(DT13:DT14) -> 7 | DU15: =SUM(DU13:DU14) -> 0.83333333 | DV15: =SUM(DV13:DV14) -> 132
B16: المطار القديم | L16: المطار القديم | V16: المطار القديم | AF16: المطار القديم | AP16: المطار القديم | AZ16: المطار القديم | BJ16: المطار القديم | BT16: المطار القديم | CD16: المطار القديم | CN16: المطار القديم | CX16: المطار القديم | DH16: المطار القديم | DR16: =(DH16) -> المطار القديم
B17: سعودي | C17: 13 | D17: 1 | E17: 0 | F17: 3 | G17: عدد النساء في سن الإنجاب | H17: 7977 | I17: المتزوجات | J17: =H17*38/100 -> 3031.26 | L17: سعودي | M17: 13 | N17: 1 | O17: 0 | P17: 3 | Q17: عدد النساء في سن الإنجاب | R17: 7977 | S17: المتزوجات | T17: =R17*38/100 -> 3031.26 | V17: سعودي | W17: 19 | X17: 10 | Y17: 0 | Z17: 28 | AA17: عدد النساء في سن الإنجاب | AB17: 7977 | AC17: المتزوجات | AD17: =AB17*38/100 -> 3031.26 | AF17: سعودي | AG17: 19 | AH17: 0 | AI17: 0 | AJ17: 19 | AK17: عدد النساء في سن الإنجاب | AL17: 7977 | AM17: المتزوجات | AN17: =AL17*38/100 -> 3031.26 | AP17: سعودي | AQ17: 19 | AR17: 0 | AS17: 0 | AT17: 7 | AU17: عدد النساء في سن الإنجاب | AV17: 7977 | AW17: المتزوجات | AX17: =AV17*38/100 -> 3031.26 | AZ17: سعودي | BA17: 0 | BB17: 0 | BC17: 0 | BD17: 0 | BE17: عدد النساء في سن الإنجاب | BF17: 7977 | BG17: المتزوجات | BH17: =BF17*38/100 -> 3031.26 | BJ17: سعودي | BK17: 0 | BL17: 0 | BM17: 0 | BN17: 5 | BO17: عدد النساء في سن الإنجاب | BP17: 7977 | BQ17: المتزوجات | BR17: =BP17*38/100 -> 3031.26 | BT17: سعودي | BU17: 0 | BV17: 0 | BW17: 0 | BX17: 0 | BY17: عدد النساء في سن الإنجاب | BZ17: 7977 | CA17: المتزوجات | CB17: =BZ17*38/100 -> 3031.26 | CD17: سعودي | CE17: 0 | CF17: 0 | CG17: 0 | CH17: 8 | CI17: عدد النساء في سن الإنجاب | CJ17: 7977 | CK17: المتزوجات | CL17: =CJ17*38/100 -> 3031.26 | CN17: سعودي | CO17: 0 | CP17: 0 | CQ17: 0 | CR17: 5 | CS17: عدد النساء في سن الإنجاب | CT17: 7977 | CU17: المتزوجات | CV17: =CT17*38/100 -> 3031.26 | CX17: سعودي | CY17: 0 | CZ17: 0 | DA17: 0 | DB17: 0 | DC17: عدد النساء في سن الإنجاب | DD17: 0 | DE17: المتزوجات | DF17: =DD17*38/100 -> 0 | DH17: سعودي | DI17: 0 | DJ17: 0 | DK17: 0 | DL17: 0 | DM17: عدد النساء في سن الإنجاب | DN17: 0 | DO17: المتزوجات | DP17: =DN17*38/100 -> 0 | DR17: سعودي | DS17: =C17+DT17-D17 -> 24 | DT17: =D17+N17+X17+AH17+AR17+BB17+BL17+BV17+CF17+CP17+CZ17+DJ17 -> 12 | DU17: =(E17+O17+Y17+AI17+AS17+BC17+BM17+BW17+CG17+CQ17+DA17+DK17)/12 -> 0 | DV17: =F17+P17+Z17+AJ17+AT17+BD17+BN17+BX17+CH17+CR17+DB17+DL17 -> 78 | DW17: عدد النساء في سن الإنجاب | DX17: =DN17 -> 0 | DY17: المتزوجات | DZ17: =DX17*38/100 -> 0
B18: غ.سعودي | C18: 8 | D18: 0 | E18: 0 | F18: 0 | L18: غ.سعودي | M18: 8 | N18: 0 | O18: 0 | P18: 0 | V18: غ.سعودي | W18: 5 | X18: 0 | Y18: 0 | Z18: 0 | AF18: غ.سعودي | AG18: 5 | AH18: 0 | AI18: 0 | AJ18: 0 | AP18: غ.سعودي | AQ18: 5 | AR18: 0 | AS18: 0 | AT18: 0 | AZ18: غ.سعودي | BA18: 0 | BB18: 0 | BC18: 0 | BD18: 0 | BJ18: غ.سعودي | BK18: 0 | BL18: 0 | BM18: 0 | BN18: 0 | BT18: غ.سعودي | BU18: 0 | BV18: 0 | BW18: 0 | BX18: 0 | CD18: غ.سعودي | CE18: 0 | CF18: 0 | CG18: 0 | CH18: 1 | CN18: غ.سعودي | CO18: 0 | CP18: 0 | CQ18: 0 | CR18: 0 | CX18: غ.سعودي | CY18: 0 | CZ18: 0 | DA18: 0 | DB18: 0 | DH18: غ.سعودي | DI18: 0 | DJ18: 0 | DK18: 0 | DL18: 0 | DR18: غ.سعودي | DS18: =C18+DT18-D18 -> 8 | DT18: =D18+N18+X18+AH18+AR18+BB18+BL18+BV18+CF18+CP18+CZ18+DJ18 -> 0 | DU18: =(E18+O18+Y18+AI18+AS18+BC18+BM18+BW18+CG18+CQ18+DA18+DK18)/12 -> 0 | DV18: =F18+P18+Z18+AJ18+AT18+BD18+BN18+BX18+CH18+CR18+DB18+DL18 -> 1
B19: المجموع | C19: =SUM(C17:C18) -> 21 | D19: =SUM(D17:D18) -> 1 | E19: =SUM(E17:E18) -> 0 | F19: =SUM(F17:F18) -> 3 | L19: المجموع | M19: =SUM(M17:M18) -> 21 | N19: =SUM(N17:N18) -> 1 | O19: =SUM(O17:O18) -> 0 | P19: =SUM(P17:P18) -> 3 | V19: المجموع | W19: =SUM(W17:W18) -> 24 | X19: =SUM(X17:X18) -> 10 | Y19: =SUM(Y17:Y18) -> 0 | Z19: =SUM(Z17:Z18) -> 28 | AF19: المجموع | AG19: =SUM(AG17:AG18) -> 24 | AH19: =SUM(AH17:AH18) -> 0 | AI19: =SUM(AI17:AI18) -> 0 | AJ19: =SUM(AJ17:AJ18) -> 19 | AP19: المجموع | AQ19: =SUM(AQ17:AQ18) -> 24 | AR19: =SUM(AR17:AR18) -> 0 | AS19: =SUM(AS17:AS18) -> 0 | AT19: =SUM(AT17:AT18) -> 7 | AZ19: المجموع | BA19: =SUM(BA17:BA18) -> 0 | BB19: =SUM(BB17:BB18) -> 0 | BC19: =SUM(BC17:BC18) -> 0 | BD19: =SUM(BD17:BD18) -> 0 | BJ19: المجموع | BK19: =SUM(BK17:BK18) -> 0 | BL19: =SUM(BL17:BL18) -> 0 | BM19: =SUM(BM17:BM18) -> 0 | BN19: =SUM(BN17:BN18) -> 5 | BT19: المجموع | BU19: =SUM(BU17:BU18) -> 0 | BV19: =SUM(BV17:BV18) -> 0 | BW19: =SUM(BW17:BW18) -> 0 | BX19: =SUM(BX17:BX18) -> 0 | CD19: المجموع | CE19: =SUM(CE17:CE18) -> 0 | CF19: =SUM(CF17:CF18) -> 0 | CG19: =SUM(CG17:CG18) -> 0 | CH19: =SUM(CH17:CH18) -> 9 | CN19: المجموع | CO19: =SUM(CO17:CO18) -> 0 | CP19: =SUM(CP17:CP18) -> 0 | CQ19: =SUM(CQ17:CQ18) -> 0 | CR19: =SUM(CR17:CR18) -> 5 | CX19: المجموع | CY19: =SUM(CY17:CY18) -> 0 | CZ19: =SUM(CZ17:CZ18) -> 0 | DA19: =SUM(DA17:DA18) -> 0 | DB19: =SUM(DB17:DB18) -> 0 | DH19: المجموع | DI19: =SUM(DI17:DI18) -> 0 | DJ19: =SUM(DJ17:DJ18) -> 0 | DK19: =SUM(DK17:DK18) -> 0 | DL19: =SUM(DL17:DL18) -> 0 | DR19: المجموع | DS19: =SUM(DS17:DS18) -> 32 | DT19: =SUM(DT17:DT18) -> 12 | DU19: =SUM(DU17:DU18) -> 0 | DV19: =SUM(DV17:DV18) -> 79
B20: الروابي | L20: الروابي | V20: الروابي | AF20: الروابي | AP20: الروابي | AZ20: الروابي | BJ20: الروابي | BT20: الروابي | CD20: الروابي | CN20: الروابي | CX20: الروابي | DH20: الروابي | DR20: =(DH20) -> الروابي
B21: سعودي | C21: 0 | D21: 0 | E21: 0 | F21: 0 | G21: عدد النساء في سن الإنجاب | H21: 0 | I21: المتزوجات | J21: =H21*38/100 -> 0 | L21: سعودي | M21: 0 | N21: 0 | O21: 0 | P21: 0 | Q21: عدد النساء في سن الإنجاب | R21: 0 | S21: المتزوجات | T21: =R21*38/100 -> 0 | V21: سعودي | W21: 0 | X21: 0 | Y21: 0 | Z21: 0 | AA21: عدد النساء في سن الإنجاب | AB21: 0 | AC21: المتزوجات | AD21: =AB21*38/100 -> 0 | AF21: سعودي | AG21: 0 | AH21: 0 | AI21: 0 | AJ21: 0 | AK21: عدد النساء في سن الإنجاب | AL21: 0 | AM21: المتزوجات | AN21: =AL21*38/100 -> 0 | AP21: سعودي | AQ21: 0 | AR21: 0 | AS21: 0 | AT21: 0 | AU21: عدد النساء في سن الإنجاب | AV21: 0 | AW21: المتزوجات | AX21: =AV21*38/100 -> 0 | AZ21: سعودي | BA21: 0 | BB21: 0 | BC21: 0 | BD21: 0 | BE21: عدد النساء في سن الإنجاب | BF21: 0 | BG21: المتزوجات | BH21: =BF21*38/100 -> 0 | BJ21: سعودي | BK21: 0 | BL21: 0 | BM21: 0 | BN21: 0 | BO21: عدد النساء في سن الإنجاب | BP21: 0 | BQ21: المتزوجات | BR21: =BP21*38/100 -> 0 | BT21: سعودي | BU21: 0 | BV21: 0 | BW21: 0 | BX21: 0 | BY21: عدد النساء في سن الإنجاب | BZ21: 0 | CA21: المتزوجات | CB21: =BZ21*38/100 -> 0 | CD21: سعودي | CE21: 0 | CF21: 0 | CG21: 0 | CH21: 0 | CI21: عدد النساء في سن الإنجاب | CJ21: 0 | CK21: المتزوجات | CL21: =CJ21*38/100 -> 0 | CN21: سعودي | CO21: 0 | CP21: 0 | CQ21: 0 | CR21: 0 | CS21: عدد النساء في سن الإنجاب | CT21: 0 | CU21: المتزوجات | CV21: =CT21*38/100 -> 0 | CX21: سعودي | CY21: 0 | CZ21: 0 | DA21: 0 | DB21: 0 | DC21: عدد النساء في سن الإنجاب | DD21: 0 | DE21: المتزوجات | DF21: =DD21*38/100 -> 0 | DH21: سعودي | DI21: 0 | DJ21: 0 | DK21: 0 | DL21: 0 | DM21: عدد النساء في سن الإنجاب | DN21: 0 | DO21: المتزوجات | DP21: =DN21*38/100 -> 0 | DR21: سعودي | DS21: =C21+DT21-D21 -> 0 | DT21: =D21+N21+X21+AH21+AR21+BB21+BL21+BV21+CF21+CP21+CZ21+DJ21 -> 0 | DU21: =(E21+O21+Y21+AI21+AS21+BC21+BM21+BW21+CG21+CQ21+DA21+DK21)/12 -> 0 | DV21: =F21+P21+Z21+AJ21+AT21+BD21+BN21+BX21+CH21+CR21+DB21+DL21 -> 0 | DW21: عدد النساء في سن الإنجاب | DX21: =DN21 -> 0 | DY21: المتزوجات | DZ21: =DX21*38/100 -> 0
B22: غ.سعودي | C22: 0 | D22: 0 | E22: 0 | F22: 0 | L22: غ.سعودي | M22: 0 | N22: 0 | O22: 0 | P22: 0 | V22: غ.سعودي | W22: 0 | X22: 0 | Y22: 0 | Z22: 0 | AF22: غ.سعودي | AG22: 0 | AH22: 0 | AI22: 0 | AJ22: 0 | AP22: غ.سعودي | AQ22: 0 | AR22: 0 | AS22: 0 | AT22: 0 | AZ22: غ.سعودي | BA22: 0 | BB22: 0 | BC22: 0 | BD22: 0 | BJ22: غ.سعودي | BK22: 0 | BL22: 0 | BM22: 0 | BN22: 0 | BT22: غ.سعودي | BU22: 0 | BV22: 0 | BW22: 0 | BX22: 0 | CD22: غ.سعودي | CE22: 0 | CF22: 0 | CG22: 0 | CH22: 0 | CN22: غ.سعودي | CO22: 0 | CP22: 0 | CQ22: 0 | CR22: 0 | CX22: غ.سعودي | CY22: 0 | CZ22: 0 | DA22: 0 | DB22: 0 | DH22: غ.سعودي | DI22: 0 | DJ22: 0 | DK22: 0 | DL22: 0 | DR22: غ.سعودي | DS22: =C22+DT22-D22 -> 0 | DT22: =D22+N22+X22+AH22+AR22+BB22+BL22+BV22+CF22+CP22+CZ22+DJ22 -> 0 | DU22: =(E22+O22+Y22+AI22+AS22+BC22+BM22+BW22+CG22+CQ22+DA22+DK22)/12 -> 0 | DV22: =F22+P22+Z22+AJ22+AT22+BD22+BN22+BX22+CH22+CR22+DB22+DL22 -> 0
B23: المجموع | C23: =SUM(C21:C22) -> 0 | D23: =SUM(D21:D22) -> 0 | E23: =SUM(E21:E22) -> 0 | F23: =SUM(F21:F22) -> 0 | L23: المجموع | M23: =SUM(M21:M22) -> 0 | N23: =SUM(N21:N22) -> 0 | O23: =SUM(O21:O22) -> 0 | P23: =SUM(P21:P22) -> 0 | V23: المجموع | W23: =SUM(W21:W22) -> 0 | X23: =SUM(X21:X22) -> 0 | Y23: =SUM(Y21:Y22) -> 0 | Z23: =SUM(Z21:Z22) -> 0 | AF23: المجموع | AG23: =SUM(AG21:AG22) -> 0 | AH23: =SUM(AH21:AH22) -> 0 | AI23: =SUM(AI21:AI22) -> 0 | AJ23: =SUM(AJ21:AJ22) -> 0 | AP23: المجموع | AQ23: =SUM(AQ21:AQ22) -> 0 | AR23: =SUM(AR21:AR22) -> 0 | AS23: =SUM(AS21:AS22) -> 0 | AT23: =SUM(AT21:AT22) -> 0 | AZ23: المجموع | BA23: =SUM(BA21:BA22) -> 0 | BB23: =SUM(BB21:BB22) -> 0 | BC23: =SUM(BC21:BC22) -> 0 | BD23: =SUM(BD21:BD22) -> 0 | BJ23: المجموع | BK23: =SUM(BK21:BK22) -> 0 | BL23: =SUM(BL21:BL22) -> 0 | BM23: =SUM(BM21:BM22) -> 0 | BN23: =SUM(BN21:BN22) -> 0 | BT23: المجموع | BU23: =SUM(BU21:BU22) -> 0 | BV23: =SUM(BV21:BV22) -> 0 | BW23: =SUM(BW21:BW22) -> 0 | BX23: =SUM(BX21:BX22) -> 0 | CD23: المجموع | CE23: =SUM(CE21:CE22) -> 0 | CF23: =SUM(CF21:CF22) -> 0 | CG23: =SUM(CG21:CG22) -> 0 | CH23: =SUM(CH21:CH22) -> 0 | CN23: المجموع | CO23: =SUM(CO21:CO22) -> 0 | CP23: =SUM(CP21:CP22) -> 0 | CQ23: =SUM(CQ21:CQ22) -> 0 | CR23: =SUM(CR21:CR22) -> 0 | CX23: المجموع | CY23: =SUM(CY21:CY22) -> 0 | CZ23: =SUM(CZ21:CZ22) -> 0 | DA23: =SUM(DA21:DA22) -> 0 | DB23: =SUM(DB21:DB22) -> 0 | DH23: المجموع | DI23: =SUM(DI21:DI22) -> 0 | DJ23: =SUM(DJ21:DJ22) -> 0 | DK23: =SUM(DK21:DK22) -> 0 | DL23: =SUM(DL21:DL22) -> 0 | DR23: المجموع | DS23: =SUM(DS21:DS22) -> 0 | DT23: =SUM(DT21:DT22) -> 0 | DU23: =SUM(DU21:DU22) -> 0 | DV23: =SUM(DV21:DV22) -> 0
B24: قويزة | L24: قويزة | V24: قويزة | AF24: قويزة | AP24: قويزة | AZ24: قويزة | BJ24: قويزة | BT24: قويزة | CD24: قويزة | CN24: قويزة | CX24: قويزة | DH24: قويزة | DR24: =(DH24) -> قويزة
B25: سعودي | C25: 32 | D25: 1 | E25: 0 | F25: 16 | G25: عدد النساء في سن الإنجاب | H25: 6901 | I25: المتزوجات | J25: =H25*38/100 -> 2622.38 | L25: سعودي | M25: 35 | N25: 1 | O25: 0 | P25: 19 | Q25: عدد النساء في سن الإنجاب | R25: 6901 | S25: المتزوجات | T25: =R25*38/100 -> 2622.38 | V25: سعودي | W25: 37 | X25: 1 | Y25: 0 | Z25: 19 | AA25: عدد النساء في سن الإنجاب | AB25: 6901 | AC25: المتزوجات | AD25: =AB25*38/100 -> 2622.38 | AF25: سعودي | AG25: 36 | AH25: 1 | AI25: 0 | AJ25: 30 | AK25: عدد النساء في سن الإنجاب | AL25: 6901 | AM25: المتزوجات | AN25: =AL25*38/100 -> 2622.38 | AP25: سعودي | AQ25: 37 | AR25: 1 | AS25: 0 | AT25: 18 | AU25: عدد النساء في سن الإنجاب | AV25: 6901 | AW25: المتزوجات | AX25: =AV25*38/100 -> 2622.38 | AZ25: سعودي | BA25: 38 | BB25: 1 | BC25: 0 | BD25: 15 | BE25: عدد النساء في سن الإنجاب | BF25: 6901 | BG25: المتزوجات | BH25: =BF25*38/100 -> 2622.38 | BJ25: سعودي | BK25: 39 | BL25: 0 | BM25: 0 | BN25: 13 | BO25: عدد النساء في سن الإنجاب | BP25: 6901 | BQ25: المتزوجات | BR25: =BP25*38/100 -> 2622.38 | BT25: سعودي | BU25: 39 | BV25: 0 | BW25: 0 | BX25: 15 | BY25: عدد النساء في سن الإنجاب | BZ25: 6901 | CA25: المتزوجات | CB25: =BZ25*38/100 -> 2622.38 | CD25: سعودي | CE25: 39 | CF25: 0 | CG25: 0 | CH25: 23 | CI25: عدد النساء في سن الإنجاب | CJ25: 6901 | CK25: المتزوجات | CL25: =CJ25*38/100 -> 2622.38 | CN25: سعودي | CO25: 39 | CP25: 0 | CQ25: 0 | CR25: 16 | CS25: عدد النساء في سن الإنجاب | CT25: 6901 | CU25: المتزوجات | CV25: =CT25*38/100 -> 2622.38 | CX25: سعودي | CY25: 0 | CZ25: 0 | DA25: 0 | DB25: 0 | DC25: عدد النساء في سن الإنجاب | DD25: 0 | DE25: المتزوجات | DF25: =DD25*38/100 -> 0 | DH25: سعودي | DI25: 0 | DJ25: 0 | DK25: 0 | DL25: 0 | DM25: عدد النساء في سن الإنجاب | DN25: 0 | DO25: المتزوجات | DP25: =DN25*38/100 -> 0 | DR25: سعودي | DS25: =C25+DT25-D25 -> 37 | DT25: =D25+N25+X25+AH25+AR25+BB25+BL25+BV25+CF25+CP25+CZ25+DJ25 -> 6 | DU25: =(E25+O25+Y25+AI25+AS25+BC25+BM25+BW25+CG25+CQ25+DA25+DK25)/12 -> 0 | DV25: =F25+P25+Z25+AJ25+AT25+BD25+BN25+BX25+CH25+CR25+DB25+DL25 -> 184 | DW25: عدد النساء في سن الإنجاب | DX25: =DN25 -> 0 | DY25: المتزوجات | DZ25: =DX25*38/100 -> 0
B26: غ.سعودي | C26: 0 | D26: 0 | E26: 0 | F26: 0 | L26: غ.سعودي | M26: 0 | N26: 0 | O26: 0 | P26: 0 | V26: غ.سعودي | W26: 0 | X26: 0 | Y26: 0 | Z26: 0 | AF26: غ.سعودي | AG26: 0 | AH26: 0 | AI26: 0 | AJ26: 0 | AP26: غ.سعودي | AQ26: 0 | AR26: 0 | AS26: 0 | AT26: 0 | AZ26: غ.سعودي | BA26: 0 | BB26: 0 | BC26: 0 | BD26: 0 | BJ26: غ.سعودي | BK26: 0 | BL26: 0 | BM26: 0 | BN26: 0 | BT26: غ.سعودي | BU26: 0 | BV26: 0 | BW26: 0 | BX26: 0 | CD26: غ.سعودي | CE26: 0 | CF26: 0 | CG26: 0 | CH26: 0 | CN26: غ.سعودي | CO26: 1 | CP26: 0 | CQ26: 0 | CR26: 0 | CX26: غ.سعودي | CY26: 0 | CZ26: 0 | DA26: 0 | DB26: 0 | DH26: غ.سعودي | DI26: 0 | DJ26: 0 | DK26: 0 | DL26: 0 | DR26: غ.سعودي | DS26: =C26+DT26-D26 -> 0 | DT26: =D26+N26+X26+AH26+AR26+BB26+BL26+BV26+CF26+CP26+CZ26+DJ26 -> 0 | DU26: =(E26+O26+Y26+AI26+AS26+BC26+BM26+BW26+CG26+CQ26+DA26+DK26)/12 -> 0 | DV26: =F26+P26+Z26+AJ26+AT26+BD26+BN26+BX26+CH26+CR26+DB26+DL26 -> 0
B27: المجموع | C27: =SUM(C25:C26) -> 32 | D27: =SUM(D25:D26) -> 1 | E27: =SUM(E25:E26) -> 0 | F27: =SUM(F25:F26) -> 16 | L27: المجموع | M27: =SUM(M25:M26) -> 35 | N27: =SUM(N25:N26) -> 1 | O27: =SUM(O25:O26) -> 0 | P27: =SUM(P25:P26) -> 19 | V27: المجموع | W27: =SUM(W25:W26) -> 37 | X27: =SUM(X25:X26) -> 1 | Y27: =SUM(Y25:Y26) -> 0 | Z27: =SUM(Z25:Z26) -> 19 | AF27: المجموع | AG27: =SUM(AG25:AG26) -> 36 | AH27: =SUM(AH25:AH26) -> 1 | AI27: =SUM(AI25:AI26) -> 0 | AJ27: =SUM(AJ25:AJ26) -> 30 | AP27: المجموع | AQ27: =SUM(AQ25:AQ26) -> 37 | AR27: =SUM(AR25:AR26) -> 1 | AS27: =SUM(AS25:AS26) -> 0 | AT27: =SUM(AT25:AT26) -> 18 | AZ27: المجموع | BA27: =SUM(BA25:BA26) -> 38 | BB27: =SUM(BB25:BB26) -> 1 | BC27: =SUM(BC25:BC26) -> 0 | BD27: =SUM(BD25:BD26) -> 15 | BJ27: المجموع | BK27: =SUM(BK25:BK26) -> 39 | BL27: =SUM(BL25:BL26) -> 0 | BM27: =SUM(BM25:BM26) -> 0 | BN27: =SUM(BN25:BN26) -> 13 | BT27: المجموع | BU27: =SUM(BU25:BU26) -> 39 | BV27: =SUM(BV25:BV26) -> 0 | BW27: =SUM(BW25:BW26) -> 0 | BX27: =SUM(BX25:BX26) -> 15 | CD27: المجموع | CE27: =SUM(CE25:CE26) -> 39 | CF27: =SUM(CF25:CF26) -> 0 | CG27: =SUM(CG25:CG26) -> 0 | CH27: =SUM(CH25:CH26) -> 23 | CN27: المجموع | CO27: =SUM(CO25:CO26) -> 40 | CP27: =SUM(CP25:CP26) -> 0 | CQ27: =SUM(CQ25:CQ26) -> 0 | CR27: =SUM(CR25:CR26) -> 16 | CX27: المجموع | CY27: =SUM(CY25:CY26) -> 0 | CZ27: =SUM(CZ25:CZ26) -> 0 | DA27: =SUM(DA25:DA26) -> 0 | DB27: =SUM(DB25:DB26) -> 0 | DH27: المجموع | DI27: =SUM(DI25:DI26) -> 0 | DJ27: =SUM(DJ25:DJ26) -> 0 | DK27: =SUM(DK25:DK26) -> 0 | DL27: =SUM(DL25:DL26) -> 0 | DR27: المجموع | DS27: =SUM(DS25:DS26) -> 37 | DT27: =SUM(DT25:DT26) -> 6 | DU27: =SUM(DU25:DU26) -> 0 | DV27: =SUM(DV25:DV26) -> 184
B28: الرغامة | L28: الرغامة | V28: الرغامة | AF28: الرغامة | AP28: الرغامة | AZ28: الرغامة | BJ28: الرغامة | BT28: الرغامة | CD28: الرغامة | CN28: الرغامة | CX28: الرغامة | DH28: الرغامة | DR28: =(DH28) -> الرغامة
B29: سعودي | C29: 11 | D29: 0 | E29: 0 | F29: 9 | G29: عدد النساء في سن الإنجاب | H29: 6901 | I29: المتزوجات | J29: =H29*38/100 -> 2622.38 | L29: سعودي | M29: 61 | N29: 14 | O29: 0 | P29: 14 | Q29: عدد النساء في سن الإنجاب | R29: 6901 | S29: المتزوجات | T29: =R29*38/100 -> 2622.38 | V29: سعودي | W29: 70 | X29: 0 | Y29: 19 | Z29: 11 | AA29: عدد النساء في سن الإنجاب | AB29: 6901 | AC29: المتزوجات | AD29: =AB29*38/100 -> 2622.38 | AF29: سعودي | AG29: 77 | AH29: 0 | AI29: 19 | AJ29: 17 | AK29: عدد النساء في سن الإنجاب | AL29: 6901 | AM29: المتزوجات | AN29: =AL29*38/100 -> 2622.38 | AP29: سعودي | AQ29: 77 | AR29: 0 | AS29: 0 | AT29: 7 | AU29: عدد النساء في سن الإنجاب | AV29: 6901 | AW29: المتزوجات | AX29: =AV29*38/100 -> 2622.38 | AZ29: سعودي | BA29: 77 | BB29: 0 | BC29: 17 | BD29: 22 | BE29: عدد النساء في سن الإنجاب | BF29: 6901 | BG29: المتزوجات | BH29: =BF29*38/100 -> 2622.38 | BJ29: سعودي | BK29: 77 | BL29: 0 | BM29: 2 | BN29: 22 | BO29: عدد النساء في سن الإنجاب | BP29: 6901 | BQ29: المتزوجات | BR29: =BP29*38/100 -> 2622.38 | BT29: سعودي | BU29: 77 | BV29: 0 | BW29: 0 | BX29: 22 | BY29: عدد النساء في سن الإنجاب | BZ29: 6901 | CA29: المتزوجات | CB29: =BZ29*38/100 -> 2622.38 | CD29: سعودي | CE29: 71 | CF29: 0 | CG29: 0 | CH29: 9 | CI29: عدد النساء في سن الإنجاب | CJ29: 6901 | CK29: المتزوجات | CL29: =CJ29*38/100 -> 2622.38 | CN29: سعودي | CO29: 71 | CP29: 0 | CQ29: 0 | CR29: 9 | CS29: عدد النساء في سن الإنجاب | CT29: 6901 | CU29: المتزوجات | CV29: =CT29*38/100 -> 2622.38 | CX29: سعودي | CY29: 0 | CZ29: 0 | DA29: 0 | DB29: 0 | DC29: عدد النساء في سن الإنجاب | DD29: 0 | DE29: المتزوجات | DF29: =DD29*38/100 -> 0 | DH29: سعودي | DI29: 0 | DJ29: 0 | DK29: 0 | DL29: 0 | DM29: عدد النساء في سن الإنجاب | DN29: 0 | DO29: المتزوجات | DP29: =DN29*38/100 -> 0 | DR29: سعودي | DS29: =C29+DT29-D29 -> 25 | DT29: =D29+N29+X29+AH29+AR29+BB29+BL29+BV29+CF29+CP29+CZ29+DJ29 -> 14 | DU29: =(E29+O29+Y29+AI29+AS29+BC29+BM29+BW29+CG29+CQ29+DA29+DK29)/12 -> 4.75 | DV29: =F29+P29+Z29+AJ29+AT29+BD29+BN29+BX29+CH29+CR29+DB29+DL29 -> 142 | DW29: عدد النساء في سن الإنجاب | DX29: =DN29 -> 0 | DY29: المتزوجات | DZ29: =DX29*38/100 -> 0
B30: غ.سعودي | C30: 0 | D30: 0 | E30: 0 | F30: 0 | L30: غ.سعودي | M30: 0 | N30: 0 | O30: 0 | P30: 0 | V30: غ.سعودي | W30: 7 | X30: 0 | Y30: 1 | Z30: 0 | AF30: غ.سعودي | AG30: 9 | AH30: 0 | AI30: 1 | AJ30: 9 | AP30: غ.سعودي | AQ30: 9 | AR30: 0 | AS30: 0 | AT30: 0 | AZ30: غ.سعودي | BA30: 5 | BB30: 0 | BC30: 1 | BD30: 0 | BJ30: غ.سعودي | BK30: 5 | BL30: 0 | BM30: 0 | BN30: 0 | BT30: غ.سعودي | BU30: 5 | BV30: 0 | BW30: 0 | BX30: 0 | CD30: غ.سعودي | CE30: 5 | CF30: 0 | CG30: 0 | CH30: 1 | CN30: غ.سعودي | CO30: 5 | CP30: 0 | CQ30: 0 | CR30: 0 | CX30: غ.سعودي | CY30: 0 | CZ30: 0 | DA30: 0 | DB30: 0 | DH30: غ.سعودي | DI30: 0 | DJ30: 0 | DK30: 0 | DL30: 0 | DR30: غ.سعودي | DS30: =C30+DT30-D30 -> 0 | DT30: =D30+N30+X30+AH30+AR30+BB30+BL30+BV30+CF30+CP30+CZ30+DJ30 -> 0 | DU30: =(E30+O30+Y30+AI30+AS30+BC30+BM30+BW30+CG30+CQ30+DA30+DK30)/12 -> 0.25 | DV30: =F30+P30+Z30+AJ30+AT30+BD30+BN30+BX30+CH30+CR30+DB30+DL30 -> 10
B31: المجموع | C31: =SUM(C29:C30) -> 11 | D31: =SUM(D29:D30) -> 0 | E31: =SUM(E29:E30) -> 0 | F31: =SUM(F29:F30) -> 9 | L31: المجموع | M31: =SUM(M29:M30) -> 61 | N31: =SUM(N29:N30) -> 14 | O31: =SUM(O29:O30) -> 0 | P31: =SUM(P29:P30) -> 14 | V31: المجموع | W31: =SUM(W29:W30) -> 77 | X31: =SUM(X29:X30) -> 0 | Y31: =SUM(Y29:Y30) -> 20 | Z31: =SUM(Z29:Z30) -> 11 | AF31: المجموع | AG31: =SUM(AG29:AG30) -> 86 | AH31: =SUM(AH29:AH30) -> 0 | AI31: =SUM(AI29:AI30) -> 20 | AJ31: =SUM(AJ29:AJ30) -> 26 | AP31: المجموع | AQ31: =SUM(AQ29:AQ30) -> 86 | AR31: =SUM(AR29:AR30) -> 0 | AS31: =SUM(AS29:AS30) -> 0 | AT31: =SUM(AT29:AT30) -> 7 | AZ31: المجموع | BA31: =SUM(BA29:BA30) -> 82 | BB31: =SUM(BB29:BB30) -> 0 | BC31: =SUM(BC29:BC30) -> 18 | BD31: =SUM(BD29:BD30) -> 22 | BJ31: المجموع | BK31: =SUM(BK29:BK30) -> 82 | BL31: =SUM(BL29:BL30) -> 0 | BM31: =SUM(BM29:BM30) -> 2 | BN31: =SUM(BN29:BN30) -> 22 | BT31: المجموع | BU31: =SUM(BU29:BU30) -> 82 | BV31: =SUM(BV29:BV30) -> 0 | BW31: =SUM(BW29:BW30) -> 0 | BX31: =SUM(BX29:BX30) -> 22 | CD31: المجموع | CE31: =SUM(CE29:CE30) -> 76 | CF31: =SUM(CF29:CF30) -> 0 | CG31: =SUM(CG29:CG30) -> 0 | CH31: =SUM(CH29:CH30) -> 10 | CN31: المجموع | CO31: =SUM(CO29:CO30) -> 76 | CP31: =SUM(CP29:CP30) -> 0 | CQ31: =SUM(CQ29:CQ30) -> 0 | CR31: =SUM(CR29:CR30) -> 9 | CX31: المجموع | CY31: =SUM(CY29:CY30) -> 0 | CZ31: =SUM(CZ29:CZ30) -> 0 | DA31: =SUM(DA29:DA30) -> 0 | DB31: =SUM(DB29:DB30) -> 0 | DH31: المجموع | DI31: =SUM(DI29:DI30) -> 0 | DJ31: =SUM(DJ29:DJ30) -> 0 | DK31: =SUM(DK29:DK30) -> 0 | DL31: =SUM(DL29:DL30) -> 0 | DR31: المجموع | DS31: =SUM(DS29:DS30) -> 25 | DT31: =SUM(DT29:DT30) -> 14 | DU31: =SUM(DU29:DU30) -> 5 | DV31: =SUM(DV29:DV30) -> 152
B32: الواحة | L32: الواحة | V32: الواحة | AF32: الواحة | AP32: الواحة | AZ32: الواحة | BJ32: الواحة | BT32: الواحة | CD32: الواحة | CN32: الواحة | CX32: الواحة | DH32: الواحة | DR32: =(DH32) -> الواحة
B33: سعودي | C33: 39 | D33: 24 | E33: 0 | F33: 43 | G33: عدد النساء في سن الإنجاب | H33: 18482 | I33: المتزوجات | J33: =H33*38/100 -> 7023.16 | L33: سعودي | M33: 54 | N33: 36 | O33: 10 | P33: 54 | Q33: عدد النساء في سن الإنجاب | R33: 18482 | S33: المتزوجات | T33: =R33*38/100 -> 7023.16 | V33: سعودي | W33: 40 | X33: 23 | Y33: 0 | Z33: 40 | AA33: عدد النساء في سن الإنجاب | AB33: 18482 | AC33: المتزوجات | AD33: =AB33*38/100 -> 7023.16 | AF33: سعودي | AG33: 40 | AH33: 0 | AI33: 0 | AJ33: 13 | AK33: عدد النساء في سن الإنجاب | AL33: 18482 | AM33: المتزوجات | AN33: =AL33*38/100 -> 7023.16 | AP33: سعودي | AQ33: 41 | AR33: 1 | AS33: 19 | AT33: 91 | AU33: عدد النساء في سن الإنجاب | AV33: 18482 | AW33: المتزوجات | AX33: =AV33*38/100 -> 7023.16 | AZ33: سعودي | BA33: 41 | BB33: 0 | BC33: 0 | BD33: 25 | BE33: عدد النساء في سن الإنجاب | BF33: 18482 | BG33: المتزوجات | BH33: =BF33*38/100 -> 7023.16 | BJ33: سعودي | BK33: 41 | BL33: 0 | BM33: 0 | BN33: 30 | BO33: عدد النساء في سن الإنجاب | BP33: 18482 | BQ33: المتزوجات | BR33: =BP33*38/100 -> 7023.16 | BT33: سعودي | BU33: 41 | BV33: 0 | BW33: 0 | BX33: 25 | BY33: عدد النساء في سن الإنجاب | BZ33: 18482 | CA33: المتزوجات | CB33: =BZ33*38/100 -> 7023.16 | CD33: سعودي | CE33: 41 | CF33: 0 | CG33: 0 | CH33: 3 | CI33: عدد النساء في سن الإنجاب | CJ33: 18482 | CK33: المتزوجات | CL33: =CJ33*38/100 -> 7023.16 | CN33: سعودي | CO33: 41 | CP33: 0 | CQ33: 0 | CR33: 13 | CS33: عدد النساء في سن الإنجاب | CT33: 18482 | CU33: المتزوجات | CV33: =CT33*38/100 -> 7023.16 | CX33: سعودي | CY33: 0 | CZ33: 0 | DA33: 0 | DB33: 0 | DC33: عدد النساء في سن الإنجاب | DD33: 0 | DE33: المتزوجات | DF33: =DD33*38/100 -> 0 | DH33: سعودي | DI33: 0 | DJ33: 0 | DK33: 0 | DL33: 0 | DM33: عدد النساء في سن الإنجاب | DN33: 0 | DO33: المتزوجات | DP33: =DN33*38/100 -> 0 | DR33: سعودي | DS33: =C33+DT33-D33 -> 99 | DT33: =D33+N33+X33+AH33+AR33+BB33+BL33+BV33+CF33+CP33+CZ33+DJ33 -> 84 | DU33: =(E33+O33+Y33+AI33+AS33+BC33+BM33+BW33+CG33+CQ33+DA33+DK33)/12 -> 2.4166667 | DV33: =F33+P33+Z33+AJ33+AT33+BD33+BN33+BX33+CH33+CR33+DB33+DL33 -> 337 | DW33: عدد النساء في سن الإنجاب | DX33: =DN33 -> 0 | DY33: المتزوجات | DZ33: =DX33*38/100 -> 0
B34: غ.سعودي | C34: 0 | D34: 0 | E34: 0 | F34: 6 | L34: غ.سعودي | M34: 3 | N34: 2 | O34: 2 | P34: 3 | V34: غ.سعودي | W34: 0 | X34: 0 | Y34: 0 | Z34: 0 | AF34: غ.سعودي | AG34: 0 | AH34: 0 | AI34: 0 | AJ34: 2 | AP34: غ.سعودي | AQ34: 0 | AR34: 0 | AS34: 0 | AT34: 9 | AZ34: غ.سعودي | BA34: 1 | BB34: 0 | BC34: 0 | BD34: 1 | BJ34: غ.سعودي | BK34: 1 | BL34: 0 | BM34: 0 | BN34: 0 | BT34: غ.سعودي | BU34: 1 | BV34: 0 | BW34: 0 | BX34: 1 | CD34: غ.سعودي | CE34: 1 | CF34: 0 | CG34: 0 | CH34: 0 | CN34: غ.سعودي | CO34: 1 | CP34: 0 | CQ34: 0 | CR34: 6 | CX34: غ.سعودي | CY34: 0 | CZ34: 0 | DA34: 0 | DB34: 0 | DH34: غ.سعودي | DI34: 0 | DJ34: 0 | DK34: 0 | DL34: 0 | DR34: غ.سعودي | DS34: =C34+DT34-D34 -> 2 | DT34: =D34+N34+X34+AH34+AR34+BB34+BL34+BV34+CF34+CP34+CZ34+DJ34 -> 2 | DU34: =(E34+O34+Y34+AI34+AS34+BC34+BM34+BW34+CG34+CQ34+DA34+DK34)/12 -> 0.16666667 | DV34: =F34+P34+Z34+AJ34+AT34+BD34+BN34+BX34+CH34+CR34+DB34+DL34 -> 28
B35: المجموع | C35: =SUM(C33:C34) -> 39 | D35: =SUM(D33:D34) -> 24 | E35: =SUM(E33:E34) -> 0 | F35: =SUM(F33:F34) -> 49 | L35: المجموع | M35: =SUM(M33:M34) -> 57 | N35: =SUM(N33:N34) -> 38 | O35: =SUM(O33:O34) -> 12 | P35: =SUM(P33:P34) -> 57 | V35: المجموع | W35: =SUM(W33:W34) -> 40 | X35: =SUM(X33:X34) -> 23 | Y35: =SUM(Y33:Y34) -> 0 | Z35: =SUM(Z33:Z34) -> 40 | AF35: المجموع | AG35: =SUM(AG33:AG34) -> 40 | AH35: =SUM(AH33:AH34) -> 0 | AI35: =SUM(AI33:AI34) -> 0 | AJ35: =SUM(AJ33:AJ34) -> 15 | AP35: المجموع | AQ35: =SUM(AQ33:AQ34) -> 41 | AR35: =SUM(AR33:AR34) -> 1 | AS35: =SUM(AS33:AS34) -> 19 | AT35: =SUM(AT33:AT34) -> 100 | AZ35: المجموع | BA35: =SUM(BA33:BA34) -> 42 | BB35: =SUM(BB33:BB34) -> 0 | BC35: =SUM(BC33:BC34) -> 0 | BD35: =SUM(BD33:BD34) -> 26 | BJ35: المجموع | BK35: =SUM(BK33:BK34) -> 42 | BL35: =SUM(BL33:BL34) -> 0 | BM35: =SUM(BM33:BM34) -> 0 | BN35: =SUM(BN33:BN34) -> 30 | BT35: المجموع | BU35: =SUM(BU33:BU34) -> 42 | BV35: =SUM(BV33:BV34) -> 0 | BW35: =SUM(BW33:BW34) -> 0 | BX35: =SUM(BX33:BX34) -> 26 | CD35: المجموع | CE35: =SUM(CE33:CE34) -> 42 | CF35: =SUM(CF33:CF34) -> 0 | CG35: =SUM(CG33:CG34) -> 0 | CH35: =SUM(CH33:CH34) -> 3 | CN35: المجموع | CO35: =SUM(CO33:CO34) -> 42 | CP35: =SUM(CP33:CP34) -> 0 | CQ35: =SUM(CQ33:CQ34) -> 0 | CR35: =SUM(CR33:CR34) -> 19 | CX35: المجموع | CY35: =SUM(CY33:CY34) -> 0 | CZ35: =SUM(CZ33:CZ34) -> 0 | DA35: =SUM(DA33:DA34) -> 0 | DB35: =SUM(DB33:DB34) -> 0 | DH35: المجموع | DI35: =SUM(DI33:DI34) -> 0 | DJ35: =SUM(DJ33:DJ34) -> 0 | DK35: =SUM(DK33:DK34) -> 0 | DL35: =SUM(DL33:DL34) -> 0 | DR35: المجموع | DS35: =SUM(DS33:DS34) -> 101 | DT35: =SUM(DT33:DT34) -> 86 | DU35: =SUM(DU33:DU34) -> 2.5833333 | DV35: =SUM(DV33:DV34) -> 365
B36: 0 | L36: 0 | V36: 0 | AF36: 0 | AP36: 0 | AZ36: 0 | BJ36: 0 | BT36: 0 | CD36: 0 | CN36: 0 | CX36: 0 | DH36: 0 | DR36: =(DH36) -> 0
B37: سعودي | C37: 0 | D37: 0 | E37: 0 | F37: 0 | G37: عدد النساء في سن الإنجاب | H37: 0 | I37: المتزوجات | J37: =H37*38/100 -> 0 | L37: سعودي | M37: 0 | N37: 0 | O37: 0 | P37: 0 | Q37: عدد النساء في سن الإنجاب | R37: 0 | S37: المتزوجات | T37: =R37*38/100 -> 0 | V37: سعودي | W37: 0 | X37: 0 | Y37: 0 | Z37: 0 | AA37: عدد النساء في سن الإنجاب | AB37: 0 | AC37: المتزوجات | AD37: =AB37*38/100 -> 0 | AF37: سعودي | AG37: 0 | AH37: 0 | AI37: 0 | AJ37: 0 | AK37: عدد النساء في سن الإنجاب | AL37: 0 | AM37: المتزوجات | AN37: =AL37*38/100 -> 0 | AP37: سعودي | AQ37: 0 | AR37: 0 | AS37: 0 | AT37: 0 | AU37: عدد النساء في سن الإنجاب | AV37: 0 | AW37: المتزوجات | AX37: =AV37*38/100 -> 0 | AZ37: سعودي | BA37: 0 | BB37: 0 | BC37: 0 | BD37: 0 | BE37: عدد النساء في سن الإنجاب | BF37: 0 | BG37: المتزوجات | BH37: =BF37*38/100 -> 0 | BJ37: سعودي | BK37: 0 | BL37: 0 | BM37: 0 | BN37: 0 | BO37: عدد النساء في سن الإنجاب | BP37: 0 | BQ37: المتزوجات | BR37: =BP37*38/100 -> 0 | BT37: سعودي | BU37: 0 | BV37: 0 | BW37: 0 | BX37: 0 | BY37: عدد النساء في سن الإنجاب | BZ37: 0 | CA37: المتزوجات | CB37: =BZ37*38/100 -> 0 | CD37: سعودي | CE37: 0 | CF37: 0 | CG37: 0 | CH37: 0 | CI37: عدد النساء في سن الإنجاب | CJ37: 0 | CK37: المتزوجات | CL37: =CJ37*38/100 -> 0 | CN37: سعودي | CO37: 0 | CP37: 0 | CQ37: 0 | CR37: 0 | CS37: عدد النساء في سن الإنجاب | CT37: 0 | CU37: المتزوجات | CV37: =CT37*38/100 -> 0 | CX37: سعودي | CY37: 0 | CZ37: 0 | DA37: 0 | DB37: 0 | DC37: عدد النساء في سن الإنجاب | DD37: 0 | DE37: المتزوجات | DF37: =DD37*38/100 -> 0 | DH37: سعودي | DI37: 0 | DJ37: 0 | DK37: 0 | DL37: 0 | DM37: عدد النساء في سن الإنجاب | DN37: 0 | DO37: المتزوجات | DP37: =DN37*38/100 -> 0 | DR37: سعودي | DS37: =C37+DT37-D37 -> 0 | DT37: =D37+N37+X37+AH37+AR37+BB37+BL37+BV37+CF37+CP37+CZ37+DJ37 -> 0 | DU37: =(E37+O37+Y37+AI37+AS37+BC37+BM37+BW37+CG37+CQ37+DA37+DK37)/12 -> 0 | DV37: =F37+P37+Z37+AJ37+AT37+BD37+BN37+BX37+CH37+CR37+DB37+DL37 -> 0 | DW37: عدد النساء في سن الإنجاب | DX37: =DN37 -> 0 | DY37: المتزوجات | DZ37: =DX37*38/100 -> 0
B38: غ.سعودي | C38: 0 | D38: 0 | E38: 0 | F38: 0 | L38: غ.سعودي | M38: 0 | N38: 0 | O38: 0 | P38: 0 | V38: غ.سعودي | W38: 0 | X38: 0 | Y38: 0 | Z38: 0 | AF38: غ.سعودي | AG38: 0 | AH38: 0 | AI38: 0 | AJ38: 0 | AP38: غ.سعودي | AQ38: 0 | AR38: 0 | AS38: 0 | AT38: 0 | AZ38: غ.سعودي | BA38: 0 | BB38: 0 | BC38: 0 | BD38: 0 | BJ38: غ.سعودي | BK38: 0 | BL38: 0 | BM38: 0 | BN38: 0 | BT38: غ.سعودي | BU38: 0 | BV38: 0 | BW38: 0 | BX38: 0 | CD38: غ.سعودي | CE38: 0 | CF38: 0 | CG38: 0 | CH38: 0 | CN38: غ.سعودي | CO38: 0 | CP38: 0 | CQ38: 0 | CR38: 0 | CX38: غ.سعودي | CY38: 0 | CZ38: 0 | DA38: 0 | DB38: 0 | DH38: غ.سعودي | DI38: 0 | DJ38: 0 | DK38: 0 | DL38: 0 | DR38: غ.سعودي | DS38: =C38+DT38-D38 -> 0 | DT38: =D38+N38+X38+AH38+AR38+BB38+BL38+BV38+CF38+CP38+CZ38+DJ38 -> 0 | DU38: =(E38+O38+Y38+AI38+AS38+BC38+BM38+BW38+CG38+CQ38+DA38+DK38)/12 -> 0 | DV38: =F38+P38+Z38+AJ38+AT38+BD38+BN38+BX38+CH38+CR38+DB38+DL38 -> 0
B39: المجموع | C39: =SUM(C37:C38) -> 0 | D39: =SUM(D37:D38) -> 0 | E39: =SUM(E37:E38) -> 0 | F39: =SUM(F37:F38) -> 0 | L39: المجموع | M39: =SUM(M37:M38) -> 0 | N39: =SUM(N37:N38) -> 0 | O39: =SUM(O37:O38) -> 0 | P39: =SUM(P37:P38) -> 0 | V39: المجموع | W39: =SUM(W37:W38) -> 0 | X39: =SUM(X37:X38) -> 0 | Y39: =SUM(Y37:Y38) -> 0 | Z39: =SUM(Z37:Z38) -> 0 | AF39: المجموع | AG39: =SUM(AG37:AG38) -> 0 | AH39: =SUM(AH37:AH38) -> 0 | AI39: =SUM(AI37:AI38) -> 0 | AJ39: =SUM(AJ37:AJ38) -> 0 | AP39: المجموع | AQ39: =SUM(AQ37:AQ38) -> 0 | AR39: =SUM(AR37:AR38) -> 0 | AS39: =SUM(AS37:AS38) -> 0 | AT39: =SUM(AT37:AT38) -> 0 | AZ39: المجموع | BA39: =SUM(BA37:BA38) -> 0 | BB39: =SUM(BB37:BB38) -> 0 | BC39: =SUM(BC37:BC38) -> 0 | BD39: =SUM(BD37:BD38) -> 0 | BJ39: المجموع | BK39: =SUM(BK37:BK38) -> 0 | BL39: =SUM(BL37:BL38) -> 0 | BM39: =SUM(BM37:BM38) -> 0 | BN39: =SUM(BN37:BN38) -> 0 | BT39: المجموع | BU39: =SUM(BU37:BU38) -> 0 | BV39: =SUM(BV37:BV38) -> 0 | BW39: =SUM(BW37:BW38) -> 0 | BX39: =SUM(BX37:BX38) -> 0 | CD39: المجموع | CE39: =SUM(CE37:CE38) -> 0 | CF39: =SUM(CF37:CF38) -> 0 | CG39: =SUM(CG37:CG38) -> 0 | CH39: =SUM(CH37:CH38) -> 0 | CN39: المجموع | CO39: =SUM(CO37:CO38) -> 0 | CP39: =SUM(CP37:CP38) -> 0 | CQ39: =SUM(CQ37:CQ38) -> 0 | CR39: =SUM(CR37:CR38) -> 0 | CX39: المجموع | CY39: =SUM(CY37:CY38) -> 0 | CZ39: =SUM(CZ37:CZ38) -> 0 | DA39: =SUM(DA37:DA38) -> 0 | DB39: =SUM(DB37:DB38) -> 0 | DH39: المجموع | DI39: =SUM(DI37:DI38) -> 0 | DJ39: =SUM(DJ37:DJ38) -> 0 | DK39: =SUM(DK37:DK38) -> 0 | DL39: =SUM(DL37:DL38) -> 0 | DR39: المجموع | DS39: =SUM(DS37:DS38) -> 0 | DT39: =SUM(DT37:DT38) -> 0 | DU39: =SUM(DU37:DU38) -> 0 | DV39: =SUM(DV37:DV38) -> 0
B40: 0 | L40: 0 | V40: 0 | AF40: 0 | AP40: 0 | AZ40: 0 | BJ40: 0 | BT40: 0 | CD40: 0 | CN40: 0 | CX40: 0 | DH40: 0 | DR40: =(DH40) -> 0
...

Sheet إجمالية
A1: خدمات رعاية الأمومة | K1: خدمات رعاية الأمومة | U1: خدمات رعاية الأمومة | AE1: خدمات رعاية الأمومة | AO1: خدمات رعاية الأمومة | AY1: خدمات رعاية الأمومة | BI1: خدمات رعاية الأمومة | BS1: خدمات رعاية الأمومة | CC1: خدمات رعاية الأمومة | CM1: خدمات رعاية الأمومة | CW1: خدمات رعاية الأمومة | DG1: خدمات رعاية الأمومة | DQ1: خدمات رعاية الأمومة
A2: إجمالي مراكز شرق جدة لشهر | C2: =SUM('رعاية أمومة'!E53) -> 1 | D2: =SUM('رعاية أمومة'!I1) -> 1447 | E2: عدد النساء في سن الإنجاب | G2: ='رعاية أمومة'!H56 -> 71803 | H2: المتزوجات | I2: =G2*38/100 -> 27285.14 | K2: إجمالي مراكز شرق جدة لشهر | M2: =SUM('رعاية أمومة'!O53) -> 2 | N2: =SUM('رعاية أمومة'!S1) -> 1447 | O2: عدد النساء في سن الإنجاب | Q2: ='رعاية أمومة'!R56 -> 69504 | R2: المتزوجات | S2: =Q2*38/100 -> 26411.52 | U2: إجمالي مراكز شرق جدة لشهر | W2: =SUM('رعاية أمومة'!Y53) -> 3 | X2: =SUM('رعاية أمومة'!AC1) -> 1447 | Y2: عدد النساء في سن الإنجاب | AA2: ='رعاية أمومة'!AB56 -> 62037 | AB2: المتزوجات | AC2: =AA2*38/100 -> 23574.06 | AE2: إجمالي مراكز شرق جدة لشهر | AG2: =SUM('رعاية أمومة'!AI53) -> 4 | AH2: =SUM('رعاية أمومة'!AM1) -> 1447 | AI2: عدد النساء في سن الإنجاب | AK2: ='رعاية أمومة'!AL56 -> 70581 | AL2: المتزوجات | AM2: =AK2*38/100 -> 26820.78 | AO2: إجمالي مراكز شرق جدة لشهر | AQ2: =SUM('رعاية أمومة'!AS53) -> 5 | AR2: =SUM('رعاية أمومة'!AW1) -> 1447 | AS2: عدد النساء في سن الإنجاب | AU2: ='رعاية أمومة'!AV56 -> 70581 | AV2: المتزوجات | AW2: =AU2*38/100 -> 26820.78 | AY2: إجمالي مراكز شرق جدة لشهر | BA2: =SUM('رعاية أمومة'!BC53) -> 6 | BB2: =SUM('رعاية أمومة'!BG1) -> 1447 | BC2: عدد النساء في سن الإنجاب | BE2: ='رعاية أمومة'!BF56 -> 70581 | BF2: المتزوجات | BG2: =BE2*38/100 -> 26820.78 | BI2: إجمالي مراكز شرق جدة لشهر | BK2: =SUM('رعاية أمومة'!BM53) -> 7 | BL2: =SUM('رعاية أمومة'!BQ1) -> 1447 | BM2: عدد النساء في سن الإنجاب | BO2: ='رعاية أمومة'!BP56 -> 70581 | BP2: المتزوجات | BQ2: =BO2*38/100 -> 26820.78 | BS2: إجمالي مراكز شرق جدة لشهر | BU2: =SUM('رعاية أمومة'!BW53) -> 8 | BV2: =SUM('رعاية أمومة'!CA1) -> 1447 | BW2: عدد النساء في سن الإنجاب | BY2: ='رعاية أمومة'!BZ56 -> 70581 | BZ2: المتزوجات | CA2: =BY2*38/100 -> 26820.78 | CC2: إجمالي مراكز شرق جدة لشهر | CE2: =SUM('رعاية أمومة'!CG53) -> 9 | CF2: =SUM('رعاية أمومة'!CK1) -> 1447 | CG2: عدد النساء في سن الإنجاب | CI2: ='رعاية أمومة'!CJ56 -> 70581 | CJ2: المتزوجات | CK2: =CI2*38/100 -> 26820.78 | CM2: إجمالي مراكز شرق جدة لشهر | CO2: =SUM('رعاية أمومة'!CQ53) -> 10 | CP2: =SUM('رعاية أمومة'!CU1) -> 1447 | CQ2: عدد النساء في سن الإنجاب | CS2: ='رعاية أمومة'!CT56 -> 57781 | CT2: المتزوجات | CU2: =CS2*38/100 -> 21956.78 | CW2: إجمالي مراكز شرق جدة لشهر | CY2: =SUM('رعاية أمومة'!DA53) -> 11 | CZ2: =SUM('رعاية أمومة'!DE1) -> 1447 | DA2: عدد النساء في سن الإنجاب | DC2: ='رعاية أمومة'!DD56 -> 0 | DD2: المتزوجات | DE2: =DC2*38/100 -> 0 | DG2: إجمالي مراكز شرق جدة لشهر | DI2: =SUM('رعاية أمومة'!DK53) -> 12 | DJ2: =SUM('رعاية أمومة'!DO1) -> 1447 | DK2: عدد النساء في سن الإنجاب | DM2: ='رعاية أمومة'!DN56 -> 0 | DN2: المتزوجات | DO2: =DM2*38/100 -> 0 | DQ2: إجمالي مراكز شرق جدة | DS2: عام | DT2: =SUM('رعاية أمومة'!DY1) -> 1447 | DU2: عدد النساء في سن الإنجاب | DW2: ='رعاية أمومة'!DX56 -> 0 | DX2: المتزوجات | DY2: =DW2*38/100 -> 0
A3: العدد | B3: إجمالي الحوامل المسجلات | C3: الحوامل الجدد | D3: المعرضات للخطر | E3: زيارات الحوامل خلال الشهر | F3: وفيات الأمهات خلال الشهر | K3: العدد | L3: إجمالي الحوامل المسجلات | M3: الحوامل الجدد | N3: المعرضات للخطر | O3: زيارات الحوامل خلال الشهر | P3: وفيات الأمهات خلال الشهر | U3: العدد | V3: إجمالي الحوامل المسجلات | W3: الحوامل الجدد | X3: المعرضات للخطر | Y3: زيارات الحوامل خلال الشهر | Z3: وفيات الأمهات خلال الشهر | AE3: العدد | AF3: إجمالي الحوامل المسجلات | AG3: الحوامل الجدد | AH3: المعرضات للخطر | AI3: زيارات الحوامل خلال الشهر | AJ3: وفيات الأمهات خلال الشهر | AO3: العدد | AP3: إجمالي الحوامل المسجلات | AQ3: الحوامل الجدد | AR3: المعرضات للخطر | AS3: زيارات الحوامل خلال الشهر | AT3: وفيات الأمهات خلال الشهر | AY3: العدد | AZ3: إجمالي الحوامل المسجلات | BA3: الحوامل الجدد | BB3: المعرضات للخطر | BC3: زيارات الحوامل خلال الشهر | BD3: وفيات الأمهات خلال الشهر | BI3: العدد | BJ3: إجمالي الحوامل المسجلات | BK3: الحوامل الجدد | BL3: المعرضات للخطر | BM3: زيارات الحوامل خلال الشهر | BN3: وفيات الأمهات خلال الشهر | BS3: العدد | BT3: إجمالي الحوامل المسجلات | BU3: الحوامل الجدد | BV3: المعرضات للخطر | BW3: زيارات الحوامل خلال الشهر | BX3: وفيات الأمهات خلال الشهر | CC3: العدد | CD3: إجمالي الحوامل المسجلات | CE3: الحوامل الجدد | CF3: المعرضات للخطر | CG3: زيارات الحوامل خلال الشهر | CH3: وفيات الأمهات خلال الشهر | CM3: العدد | CN3: إجمالي الحوامل المسجلات | CO3: الحوامل الجدد | CP3: المعرضات للخطر | CQ3: زيارات الحوامل خلال الشهر | CR3: وفيات الأمهات خلال الشهر | CW3: العدد | CX3: إجمالي الحوامل المسجلات | CY3: الحوامل الجدد | CZ3: المعرضات للخطر | DA3: زيارات الحوامل خلال الشهر | DB3: وفيات الأمهات خلال الشهر | DG3: العدد | DH3: إجمالي الحوامل المسجلات | DI3: الحوامل الجدد | DJ3: المعرضات للخطر | DK3: زيارات الحوامل خلال الشهر | DL3: وفيات الأمهات خلال الشهر | DQ3: العدد | DR3: إجمالي الحوامل المسجلات | DS3: الحوامل الجدد | DT3: المعرضات للخطر | DU3: زيارات الحوامل خلال الشهر | DV3: وفيات الأمهات خلال الشهر
A4: الجنسية | F4: الإســم | G4: الجنسية | H4: العمر | I4: سبب الوفاة | K4: الجنسية | P4: الإســم | Q4: الجنسية | R4: العمر | S4: سبب الوفاة | U4: الجنسية | Z4: الإســم | AA4: الجنسية | AB4: العمر | AC4: سبب الوفاة | AE4: الجنسية | AJ4: الإســم | AK4: الجنسية | AL4: العمر | AM4: سبب الوفاة | AO4: الجنسية | AT4: الإســم | AU4: الجنسية | AV4: العمر | AW4: سبب الوفاة | AY4: الجنسية | BD4: الإســم | BE4: الجنسية | BF4: العمر | BG4: سبب الوفاة | BI4: الجنسية | BN4: الإســم | BO4: الجنسية | BP4: العمر | BQ4: سبب الوفاة | BS4: الجنسية | BX4: الإســم | BY4: الجنسية | BZ4: العمر | CA4: سبب الوفاة | CC4: الجنسية | CH4: الإســم | CI4: الجنسية | CJ4: العمر | CK4: سبب الوفاة | CM4: الجنسية | CR4: الإســم | CS4: الجنسية | CT4: العمر | CU4: سبب الوفاة | CW4: الجنسية | DB4: الإســم | DC4: الجنسية | DD4: العمر | DE4: سبب الوفاة | DG4: الجنسية | DL4: الإســم | DM4: الجنسية | DN4: العمر | DO4: سبب الوفاة | DQ4: الجنسية | DV4: الإســم | DW4: الجنسية | DX4: العمر | DY4: سبب الوفاة
A5: سعودي | B5: =SUM('رعاية أمومة'!C56) -> 149 | C5: =SUM('رعاية أمومة'!D56) -> 32 | D5: =SUM('رعاية أمومة'!E56) -> 5 | E5: =SUM('رعاية أمومة'!F56) -> 108 | K5: سعودي | L5: =SUM('رعاية أمومة'!M56) -> 227 | M5: =SUM('رعاية أمومة'!N56) -> 65 | N5: =SUM('رعاية أمومة'!O56) -> 20 | O5: =SUM('رعاية أمومة'!P56) -> 135 | U5: سعودي | V5: =SUM('رعاية أمومة'!W56) -> 209 | W5: =SUM('رعاية أمومة'!X56) -> 39 | X5: =SUM('رعاية أمومة'!Y56) -> 30 | Y5: =SUM('رعاية أمومة'!Z56) -> 119 | AE5: سعودي | AF5: =SUM('رعاية أمومة'!AG56) -> 218 | AG5: =SUM('رعاية أمومة'!AH56) -> 22 | AH5: =SUM('رعاية أمومة'!AI56) -> 30 | AI5: =SUM('رعاية أمومة'!AJ56) -> 141 | AO5: سعودي | AP5: =SUM('رعاية أمومة'!AQ56) -> 220 | AQ5: =SUM('رعاية أمومة'!AR56) -> 5 | AR5: =SUM('رعاية أمومة'!AS56) -> 21 | AS5: =SUM('رعاية أمومة'!AT56) -> 145 | AY5: سعودي | AZ5: =SUM('رعاية أمومة'!BA56) -> 275 | BA5: =SUM('رعاية أمومة'!BB56) -> 5 | BB5: =SUM('رعاية أمومة'!BC56) -> 27 | BC5: =SUM('رعاية أمومة'!BD56) -> 96 | BI5: سعودي | BJ5: =SUM('رعاية أمومة'!BK56) -> 277 | BK5: =SUM('رعاية أمومة'!BL56) -> 0 | BL5: =SUM('رعاية أمومة'!BM56) -> 2 | BM5: =SUM('رعاية أمومة'!BN56) -> 110 | BS5: سعودي | BT5: =SUM('رعاية أمومة'!BU56) -> 277 | BU5: =SUM('رعاية أمومة'!BV56) -> 0 | BV5: =SUM('رعاية أمومة'!BW56) -> 0 | BW5: =SUM('رعاية أمومة'!BX56) -> 96 | CC5: سعودي | CD5: =SUM('رعاية أمومة'!CE56) -> 271 | CE5: =SUM('رعاية أمومة'!CF56) -> 0 | CF5: =SUM('رعاية أمومة'!CG56) -> 0 | CG5: =SUM('رعاية أمومة'!CH56) -> 115 | CM5: سعودي | CN5: =SUM('رعاية أمومة'!CO56) -> 174 | CO5: =SUM('رعاية أمومة'!CP56) -> 0 | CP5: =SUM('رعاية أمومة'!CQ56) -> 0 | CQ5: =SUM('رعاية أمومة'!CR56) -> 70 | CW5: سعودي | CX5: =SUM('رعاية أمومة'!CY56) -> 0 | CY5: =SUM('رعاية أمومة'!CZ56) -> 0 | CZ5: =SUM('رعاية أمومة'!DA56) -> 0 | DA5: =SUM('رعاية أمومة'!DB56) -> 0 | DG5: سعودي | DH5: =SUM('رعاية أمومة'!DI56) -> 0 | DI5: =SUM('رعاية أمومة'!DJ56) -> 0 | DJ5: =SUM('رعاية أمومة'!DK56) -> 0 | DK5: =SUM('رعاية أمومة'!DL56) -> 0 | DQ5: سعودي | DR5: =SUM('رعاية أمومة'!DS56) -> 285 | DS5: =SUM('رعاية أمومة'!DT56) -> 168 | DT5: =SUM('رعاية أمومة'!DU56) -> 11.25 | DU5: =SUM('رعاية أمومة'!DV56) -> 1135
A6: غ.سعودي | B6: =SUM('رعاية أمومة'!C57) -> 20 | C6: =SUM('رعاية أمومة'!D57) -> 0 | D6: =SUM('رعاية أمومة'!E57) -> 0 | E6: =SUM('رعاية أمومة'!F57) -> 11 | K6: غ.سعودي | L6: =SUM('رعاية أمومة'!M57) -> 21 | M6: =SUM('رعاية أمومة'!N57) -> 3 | N6: =SUM('رعاية أمومة'!O57) -> 6 | O6: =SUM('رعاية أمومة'!P57) -> 9 | U6: غ.سعودي | V6: =SUM('رعاية أمومة'!W57) -> 21 | W6: =SUM('رعاية أمومة'!X57) -> 0 | X6: =SUM('رعاية أمومة'!Y57) -> 3 | Y6: =SUM('رعاية أمومة'!Z57) -> 5 | AE6: غ.سعودي | AF6: =SUM('رعاية أمومة'!AG57) -> 30 | AG6: =SUM('رعاية أمومة'!AH57) -> 10 | AH6: =SUM('رعاية أمومة'!AI57) -> 4 | AI6: =SUM('رعاية أمومة'!AJ57) -> 26 | AO6: غ.سعودي | AP6: =SUM('رعاية أمومة'!AQ57) -> 30 | AQ6: =SUM('رعاية أمومة'!AR57) -> 0 | AR6: =SUM('رعاية أمومة'!AS57) -> 0 | AS6: =SUM('رعاية أمومة'!AT57) -> 13 | AY6: غ.سعودي | AZ6: =SUM('رعاية أمومة'!BA57) -> 43 | BA6: =SUM('رعاية أمومة'!BB57) -> 1 | BB6: =SUM('رعاية أمومة'!BC57) -> 7 | BC6: =SUM('رعاية أمومة'!BD57) -> 15 | BI6: غ.سعودي | BJ6: =SUM('رعاية أمومة'!BK57) -> 44 | BK6: =SUM('رعاية أمومة'!BL57) -> 0 | BL6: =SUM('رعاية أمومة'!BM57) -> 0 | BM6: =SUM('رعاية أمومة'!BN57) -> 4 | BS6: غ.سعودي | BT6: =SUM('رعاية أمومة'!BU57) -> 44 | BU6: =SUM('رعاية أمومة'!BV57) -> 0 | BV6: =SUM('رعاية أمومة'!BW57) -> 0 | BW6: =SUM('رعاية أمومة'!BX57) -> 15 | CC6: غ.سعودي | CD6: =SUM('رعاية أمومة'!CE57) -> 42 | CE6: =SUM('رعاية أمومة'!CF57) -> 0 | CF6: =SUM('رعاية أمومة'!CG57) -> 0 | CG6: =SUM('رعاية أمومة'!CH57) -> 13 | CM6: غ.سعودي | CN6: =SUM('رعاية أمومة'!CO57) -> 9 | CO6: =SUM('رعاية أمومة'!CP57) -> 0 | CP6: =SUM('رعاية أمومة'!CQ57) -> 0 | CQ6: =SUM('رعاية أمومة'!CR57) -> 7 | CW6: غ.سعودي | CX6: =SUM('رعاية أمومة'!CY57) -> 0 | CY6: =SUM('رعاية أمومة'!CZ57) -> 0 | CZ6: =SUM('رعاية أمومة'!DA57) -> 0 | DA6: =SUM('رعاية أمومة'!DB57) -> 0 | DG6: غ.سعودي | DH6: =SUM('رعاية أمومة'!DI57) -> 0 | DI6: =SUM('رعاية أمومة'!DJ57) -> 0 | DJ6: =SUM('رعاية أمومة'!DK57) -> 0 | DK6: =SUM('رعاية أمومة'!DL57) -> 0 | DQ6: غ.سعودي | DR6: =SUM('رعاية أمومة'!DS57) -> 34 | DS6: =SUM('رعاية أمومة'!DT57) -> 14 | DT6: =SUM('رعاية أمومة'!DU57) -> 1.6666667 | DU6: =SUM('رعاية أمومة'!DV57) -> 118
A7: المجموع | B7: =SUM(B5:B6) -> 169 | C7: =SUM(C5:C6) -> 32 | D7: =SUM(D5:D6) -> 5 | E7: =SUM(E5:E6) -> 119 | K7: المجموع | L7: =SUM(L5:L6) -> 248 | M7: =SUM(M5:M6) -> 68 | N7: =SUM(N5:N6) -> 26 | O7: =SUM(O5:O6) -> 144 | U7: المجموع | V7: =SUM(V5:V6) -> 230 | W7: =SUM(W5:W6) -> 39 | X7: =SUM(X5:X6) -> 33 | Y7: =SUM(Y5:Y6) -> 124 | AE7: المجموع | AF7: =SUM(AF5:AF6) -> 248 | AG7: =SUM(AG5:AG6) -> 32 | AH7: =SUM(AH5:AH6) -> 34 | AI7: =SUM(AI5:AI6) -> 167 | AO7: المجموع | AP7: =SUM(AP5:AP6) -> 250 | AQ7: =SUM(AQ5:AQ6) -> 5 | AR7: =SUM(AR5:AR6) -> 21 | AS7: =SUM(AS5:AS6) -> 158 | AY7: المجموع | AZ7: =SUM(AZ5:AZ6) -> 318 | BA7: =SUM(BA5:BA6) -> 6 | BB7: =SUM(BB5:BB6) -> 34 | BC7: =SUM(BC5:BC6) -> 111 | BI7: المجموع | BJ7: =SUM(BJ5:BJ6) -> 321 | BK7: =SUM(BK5:BK6) -> 0 | BL7: =SUM(BL5:BL6) -> 2 | BM7: =SUM(BM5:BM6) -> 114 | BS7: المجموع | BT7: =SUM(BT5:BT6) -> 321 | BU7: =SUM(BU5:BU6) -> 0 | BV7: =SUM(BV5:BV6) -> 0 | BW7: =SUM(BW5:BW6) -> 111 | CC7: المجموع | CD7: =SUM(CD5:CD6) -> 313 | CE7: =SUM(CE5:CE6) -> 0 | CF7: =SUM(CF5:CF6) -> 0 | CG7: =SUM(CG5:CG6) -> 128 | CM7: المجموع | CN7: =SUM(CN5:CN6) -> 183 | CO7: =SUM(CO5:CO6) -> 0 | CP7: =SUM(CP5:CP6) -> 0 | CQ7: =SUM(CQ5:CQ6) -> 77 | CW7: المجموع | CX7: =SUM(CX5:CX6) -> 0 | CY7: =SUM(CY5:CY6) -> 0 | CZ7: =SUM(CZ5:CZ6) -> 0 | DA7: =SUM(DA5:DA6) -> 0 | DG7: المجموع | DH7: =SUM(DH5:DH6) -> 0 | DI7: =SUM(DI5:DI6) -> 0 | DJ7: =SUM(DJ5:DJ6) -> 0 | DK7: =SUM(DK5:DK6) -> 0 | DQ7: المجموع | DR7: =SUM(DR5:DR6) -> 319 | DS7: =SUM(DS5:DS6) -> 182 | DT7: =SUM(DT5:DT6) -> 12.916667 | DU7: =SUM(DU5:DU6) -> 1253
A11: محمد الزهراني | I11: ادارة الاحصاء | K11: محمد الزهراني | S11: ادارة الاحصاء | U11: محمد الزهراني | AC11: ادارة الاحصاء | AE11: محمد الزهراني | AM11: ادارة الاحصاء | AO11: محمد الزهراني | AW11: ادارة الاحصاء | AY11: محمد الزهراني | BG11: ادارة الاحصاء | BI11: محمد الزهراني | BQ11: ادارة الاحصاء | BS11: محمد الزهراني | CA11: ادارة الاحصاء | CC11: محمد الزهراني | CK11: ادارة الاحصاء | CM11: محمد الزهراني | CU11: ادارة الاحصاء | CW11: محمد الزهراني | DE11: ادارة الاحصاء | DG11: محمد الزهراني | DO11: ادارة الاحصاء | DQ11: محمد الزهراني | DY11: ادارة الاحصاء
