Workbook

Sheet ضماد
A2: 14ـ الجراحات الصغرى والغيارات والحقن | I2: 14ـ الجراحات الصغرى والغيارات والحقن | Q2: 14ـ الجراحات الصغرى والغيارات والحقن | Y2: 14ـ الجراحات الصغرى والغيارات والحقن | AG2: 14ـ الجراحات الصغرى والغيارات والحقن | AO2: 14ـ الجراحات الصغرى والغيارات والحقن | AW2: 14ـ الجراحات الصغرى والغيارات والحقن | BE2: 14ـ الجراحات الصغرى والغيارات والحقن | BM2: 14ـ الجراحات الصغرى والغيارات والحقن | BU2: 14ـ الجراحات الصغرى والغيارات والحقن | CC2: 14ـ الجراحات الصغرى والغيارات والحقن | CK2: 14ـ الجراحات الصغرى والغيارات والحقن | CS2: 14ـ الجراحات الصغرى والغيارات والحقن
C3: شهر | D3: 1 | E3: عام | F3: 1447 | G3: هـ | K3: شهر | L3: 2 | M3: عام | N3: 1447 | O3: هـ | S3: شهر | T3: 3 | U3: عام | V3: 1447 | W3: هـ | AA3: شهر | AB3: 4 | AC3: عام | AD3: 1447 | AE3: هـ | AI3: شهر | AJ3: 5 | AK3: عام | AL3: 1447 | AM3: هـ | AQ3: شهر | AR3: 6 | AS3: عام | AT3: 1447 | AU3: هـ | AY3: شهر | AZ3: 7 | BA3: عام | BB3: 1447 | BC3: هـ | BG3: شهر | BH3: 8 | BI3: عام | BJ3: 1447 | BK3: هـ | BO3: شهر | BP3: 9 | BQ3: عام | BR3: 1447 | BS3: هـ | BW3: شهر | BX3: 10 | BY3: عام | BZ3: 1447 | CA3: هـ | CE3: شهر | CF3: 11 | CG3: عام | CH3: 1447 | CI3: هـ | CM3: شهر | CN3: 12 | CO3: عام | CP3: 1447 | CQ3: هـ | CW3: عام | CX3: =SUM(CP3) -> 1447 | CY3: هـ
A4: المركز الصحي | B4: الخدمة | D4: جراحات صغرى | E4: غيارات | F4: حقن | G4: أكسجين | I4: المركز الصحي | J4: الخدمة | L4: جراحات صغرى | M4: غيارات | N4: حقن | O4: أكسجين | Q4: المركز الصحي | R4: الخدمة | T4: جراحات صغرى | U4: غيارات | V4: حقن | W4: أكسجين | Y4: المركز الصحي | Z4: الخدمة | AB4: جراحات صغرى | AC4: غيارات | AD4: حقن | AE4: أكسجين | AG4: المركز الصحي | AH4: الخدمة | AJ4: جراحات صغرى | AK4: غيارات | AL4: حقن | AM4: أكسجين | AO4: المركز الصحي | AP4: الخدمة | AR4: جراحات صغرى | AS4: غيارات | AT4: حقن | AU4: أكسجين | AW4: المركز الصحي | AX4: الخدمة | AZ4: جراحات صغرى | BA4: غيارات | BB4: حقن | BC4: أكسجين | BE4: المركز الصحي | BF4: الخدمة | BH4: جراحات صغرى | BI4: غيارات | BJ4: حقن | BK4: أكسجين | BM4: المركز الصحي | BN4: الخدمة | BP4: جراحات صغرى | BQ4: غيارات | BR4: حقن | BS4: أكسجين | BU4: المركز الصحي | BV4: الخدمة | BX4: جراحات صغرى | BY4: غيارات | BZ4: حقن | CA4: أكسجين | CC4: المركز الصحي | CD4: الخدمة | CF4: جراحات صغرى | CG4: غيارات | CH4: حقن | CI4: أكسجين | CK4: المركز الصحي | CL4: الخدمة | CN4: جراحات صغرى | CO4: غيارات | CP4: حقن | CQ4: أكسجين | CS4: المركز الصحي | CT4: الخدمة | CV4: جراحات صغرى | CW4: غيارات | CX4: حقن | CY4: أكسجين
B5: الجنس والجنسية | J5: الجنس والجنسية | R5: الجنس والجنسية | Z5: الجنس والجنسية | AH5: الجنس والجنسية | AP5: الجنس والجنسية | AX5: الجنس والجنسية | BF5: الجنس والجنسية | BN5: الجنس والجنسية | BV5: الجنس والجنسية | CD5: الجنس والجنسية | CL5: الجنس والجنسية | CT5: الجنس والجنسية
A6: الربيع والتوفيق | B6: سعودي | C6: ذكر | D6: 0 | E6: 45 | F6: 25 | G6: 16 | I6: الربيع والتوفيق | J6: سعودي | K6: ذكر | L6: 0 | M6: 30 | N6: 28 | O6: 36 | Q6: الربيع والتوفيق | R6: سعودي | S6: ذكر | T6: 12 | U6: 31 | V6: 19 | W6: 51 | Y6: الربيع والتوفيق | Z6: سعودي | AA6: ذكر | AB6: 2 | AC6: 35 | AD6: 44 | AE6: 34 | AG6: الربيع والتوفيق | AH6: سعودي | AI6: ذكر | AJ6: 4 | AK6: 60 | AL6: 28 | AM6: 99 | AO6: الربيع والتوفيق | AP6: سعودي | AQ6: ذكر | AR6: 0 | AS6: 28 | AT6: 14 | AU6: 6 | AW6: الربيع والتوفيق | AX6: سعودي | AY6: ذكر | AZ6: 0 | BA6: 22 | BB6: 20 | BC6: 36 | BE6: الربيع والتوفيق | BF6: سعودي | BG6: ذكر | BH6: 0 | BI6: 28 | BJ6: 14 | BK6: 6 | BM6: الربيع والتوفيق | BN6: سعودي | BO6: ذكر | BP6: 25 | BQ6: 20 | BR6: 9 | BS6: 14 | BU6: الربيع والتوفيق | BV6: سعودي | BW6: ذكر | BX6: 0 | BY6: 44 | BZ6: 24 | CA6: 17 | CC6: الربيع والتوفيق | CD6: سعودي | CE6: ذكر | CF6: 0 | CG6: 0 | CH6: 0 | CI6: 0 | CK6: الربيع والتوفيق | CL6: سعودي | CM6: ذكر | CN6: 0 | CO6: 0 | CP6: 0 | CQ6: 0 | CS6: =(CK6) -> الربيع والتوفيق | CT6: سعودي | CU6: ذكر | CV6: =SUM(D6+L6+T6+AB6+AJ6+AR6+AZ6+BH6+BP6+BX6+CF6+CN6) -> 43 | CW6: =SUM(E6+M6+U6+AC6+AK6+AS6+BA6+BI6+BQ6+BY6+CG6+CO6) -> 343 | CX6: =SUM(F6+N6+V6+AD6+AL6+AT6+BB6+BJ6+BR6+BZ6+CH6+CP6) -> 225 | CY6: =SUM(G6+O6+W6+AE6+AM6+AU6+BC6+BK6+BS6+CA6+CI6+CQ6) -> 315
C7: أنثى | D7: 0 | E7: 20 | F7: 40 | G7: 25 | K7: أنثى | L7: 0 | M7: 12 | N7: 32 | O7: 58 | S7: أنثى | T7: 13 | U7: 22 | V7: 31 | W7: 52 | AA7: أنثى | AB7: 1 | AC7: 8 | AD7: 11 | AE7: 21 | AI7: أنثى | AJ7: 2 | AK7: 24 | AL7: 34 | AM7: 106 | AQ7: أنثى | AR7: 0 | AS7: 8 | AT7: 17 | AU7: 7 | AY7: أنثى | AZ7: 0 | BA7: 10 | BB7: 25 | BC7: 58 | BG7: أنثى | BH7: 0 | BI7: 8 | BJ7: 17 | BK7: 7 | BO7: أنثى | BP7: 35 | BQ7: 18 | BR7: 8 | BS7: 10 | BW7: أنثى | BX7: 4 | BY7: 19 | BZ7: 34 | CA7: 24 | CE7: أنثى | CF7: 0 | CG7: 0 | CH7: 0 | CI7: 0 | CM7: أنثى | CN7: 0 | CO7: 0 | CP7: 0 | CQ7: 0 | CU7: أنثى | CV7: =SUM(D7+L7+T7+AB7+AJ7+AR7+AZ7+BH7+BP7+BX7+CF7+CN7) -> 55 | CW7: =SUM(E7+M7+U7+AC7+AK7+AS7+BA7+BI7+BQ7+BY7+CG7+CO7) -> 149 | CX7: =SUM(F7+N7+V7+AD7+AL7+AT7+BB7+BJ7+BR7+BZ7+CH7+CP7) -> 249 | CY7: =SUM(G7+O7+W7+AE7+AM7+AU7+BC7+BK7+BS7+CA7+CI7+CQ7) -> 368
B8: مجموع السعوديين | D8: 0 | E8: 65 | F8: 65 | G8: 41 | J8: مجموع السعوديين | L8: 0 | M8: 42 | N8: 60 | O8: 94 | R8: مجموع السعوديين | T8: 25 | U8: 53 | V8: 50 | W8: 103 | Z8: مجموع السعوديين | AB8: 3 | AC8: 43 | AD8: 55 | AE8: 55 | AH8: مجموع السعوديين | AJ8: 6 | AK8: 84 | AL8: 62 | AM8: 205 | AP8: مجموع السعوديين | AR8: 0 | AS8: 36 | AT8: 31 | AU8: 13 | AX8: مجموع السعوديين | AZ8: 0 | BA8: 32 | BB8: 45 | BC8: 94 | BF8: مجموع السعوديين | BH8: =SUM(BH6:BH7) -> 0 | BI8: =SUM(BI6:BI7) -> 36 | BJ8: 31 | BK8: =SUM(BK6:BK7) -> 13 | BN8: مجموع السعوديين | BP8: =SUM(BP6:BP7) -> 60 | BQ8: =SUM(BQ6:BQ7) -> 38 | BR8: =SUM(BR6:BR7) -> 17 | BS8: =SUM(BS6:BS7) -> 24 | BV8: مجموع السعوديين | BX8: 4 | BY8: 63 | BZ8: 58 | CA8: 41 | CD8: مجموع السعوديين | CF8: =SUM(CF6:CF7) -> 0 | CG8: =SUM(CG6:CG7) -> 0 | CH8: =SUM(CH6:CH7) -> 0 | CI8: =SUM(CI6:CI7) -> 0 | CL8: مجموع السعوديين | CN8: =SUM(CN6:CN7) -> 0 | CO8: =SUM(CO6:CO7) -> 0 | CP8: =SUM(CP6:CP7) -> 0 | CQ8: =SUM(CQ6:CQ7) -> 0 | CT8: مجموع السعوديين | CV8: =SUM(CV6:CV7) -> 98 | CW8: =SUM(CW6:CW7) -> 492 | CX8: =SUM(CX6:CX7) -> 474 | CY8: =SUM(CY6:CY7) -> 683
B9: غير سعودي | C9: ذكر | D9: 0 | E9: 1 | F9: 0 | G9: 0 | J9: غير سعودي | K9: ذكر | L9: 0 | M9: 7 | N9: 6 | O9: 16 | R9: غير سعودي | S9: ذكر | T9: 0 | U9: 3 | V9: 3 | W9: 5 | Z9: غير سعودي | AA9: ذكر | AB9: 0 | AC9: 11 | AD9: 1 | AE9: 0 | AH9: غير سعودي | AI9: ذكر | AJ9: 0 | AK9: 5 | AL9: 2 | AM9: 0 | AP9: غير سعودي | AQ9: ذكر | AR9: 0 | AS9: 4 | AT9: 5 | AU9: 0 | AX9: غير سعودي | AY9: ذكر | AZ9: 0 | BA9: 5 | BB9: 5 | BC9: 15 | BF9: غير سعودي | BG9: ذكر | BH9: 0 | BI9: 4 | BJ9: 5 | BK9: 0 | BN9: غير سعودي | BO9: ذكر | BP9: 0 | BQ9: 6 | BR9: 0 | BS9: 2 | BV9: غير سعودي | BW9: ذكر | BX9: 1 | BY9: 7 | BZ9: 7 | CA9: 3 | CD9: غير سعودي | CE9: ذكر | CF9: 0 | CG9: 0 | CH9: 0 | CI9: 0 | CL9: غير سعودي | CM9: ذكر | CN9: 0 | CO9: 0 | CP9: 0 | CQ9: 0 | CT9: غير سعودي | CU9: ذكر | CV9: =SUM(D9+L9+T9+AB9+AJ9+AR9+AZ9+BH9+BP9+BX9+CF9+CN9) -> 1 | CW9: =SUM(E9+M9+U9+AC9+AK9+AS9+BA9+BI9+BQ9+BY9+CG9+CO9) -> 53 | CX9: =SUM(F9+N9+V9+AD9+AL9+AT9+BB9+BJ9+BR9+BZ9+CH9+CP9) -> 34 | CY9: =SUM(G9+O9+W9+AE9+AM9+AU9+BC9+BK9+BS9+CA9+CI9+CQ9) -> 41
C10: أنثى | D10: 0 | E10: 1 | F10: 0 | G10: 0 | K10: أنثى | L10: 0 | M10: 3 | N10: 3 | O10: 1 | S10: أنثى | T10: 0 | U10: 0 | V10: 4 | W10: 0 | AA10: أنثى | AB10: 0 | AC10: 1 | AD10: 0 | AE10: 3 | AI10: أنثى | AJ10: 0 | AK10: 0 | AL10: 2 | AM10: 2 | AQ10: أنثى | AR10: 0 | AS10: 0 | AT10: 2 | AU10: 1 | AY10: أنثى | AZ10: 0 | BA10: 2 | BB10: 1 | BC10: 1 | BG10: أنثى | BH10: 0 | BI10: 0 | BJ10: 2 | BK10: 1 | BO10: أنثى | BP10: 0 | BQ10: 2 | BR10: 0 | BS10: 2 | BW10: أنثى | BX10: 0 | BY10: 1 | BZ10: 8 | CA10: 1 | CE10: أنثى | CF10: 0 | CG10: 0 | CH10: 0 | CI10: 0 | CM10: أنثى | CN10: 0 | CO10: 0 | CP10: 0 | CQ10: 0 | CU10: أنثى | CV10: =SUM(D10+L10+T10+AB10+AJ10+AR10+AZ10+BH10+BP10+BX10+CF10+CN10) -> 0 | CW10: =SUM(E10+M10+U10+AC10+AK10+AS10+BA10+BI10+BQ10+BY10+CG10+CO10) -> 10 | CX10: =SUM(F10+N10+V10+AD10+AL10+AT10+BB10+BJ10+BR10+BZ10+CH10+CP10) -> 22 | CY10: =SUM(G10+O10+W10+AE10+AM10+AU10+BC10+BK10+BS10+CA10+CI10+CQ10) -> 12
B11: مجمع الغير سعوديين | D11: =SUM(D9:D10) -> 0 | E11: =SUM(E9:E10) -> 2 | F11: =SUM(F9:F10) -> 0 | G11: =SUM(G9:G10) -> 0 | J11: مجمع الغير سعوديين | L11: =SUM(L9:L10) -> 0 | M11: =SUM(M9:M10) -> 10 | N11: =SUM(N9:N10) -> 9 | O11: =SUM(O9:O10) -> 17 | R11: مجمع الغير سعوديين | T11: 0 | U11: 3 | V11: 7 | W11: 5 | Z11: مجمع الغير سعوديين | AB11: 0 | AC11: 12 | AD11: 1 | AE11: 3 | AH11: مجمع الغير سعوديين | AJ11: =SUM(AJ9:AJ10) -> 0 | AK11: =SUM(AK9:AK10) -> 5 | AL11: =SUM(AL9:AL10) -> 4 | AM11: =SUM(AM9:AM10) -> 2 | AP11: مجمع الغير سعوديين | AR11: 0 | AS11: 4 | AT11: 7 | AU11: 1 | AX11: مجمع الغير سعوديين | AZ11: 0 | BA11: 7 | BB11: 6 | BC11: 16 | BF11: مجمع الغير سعوديين | BH11: =SUM(BH9:BH10) -> 0 | BI11: =SUM(BI9:BI10) -> 4 | BJ11: =SUM(BJ9:BJ10) -> 7 | BK11: =SUM(BK9:BK10) -> 1 | BN11: مجمع الغير سعوديين | BP11: =SUM(BP9:BP10) -> 0 | BQ11: =SUM(BQ9:BQ10) -> 8 | BR11: =SUM(BR9:BR10) -> 0 | BS11: =SUM(BS9:BS10) -> 4 | BV11: مجمع الغير سعوديين | BX11: 1 | BY11: 8 | BZ11: 15 | CA11: 4 | CD11: مجمع الغير سعوديين | CF11: =SUM(CF9:CF10) -> 0 | CG11: =SUM(CG9:CG10) -> 0 | CH11: =SUM(CH9:CH10) -> 0 | CI11: =SUM(CI9:CI10) -> 0 | CL11: مجمع الغير سعوديين | CN11: =SUM(CN9:CN10) -> 0 | CO11: =SUM(CO9:CO10) -> 0 | CP11: =SUM(CP9:CP10) -> 0 | CQ11: =SUM(CQ9:CQ10) -> 0 | CT11: مجمع الغير سعوديين | CV11: =SUM(CV9:CV10) -> 1 | CW11: =SUM(CW9:CW10) -> 63 | CX11: =SUM(CX9:CX10) -> 56 | CY11: =SUM(CY9:CY10) -> 53
B12: المجموع الكلي | D12: =SUM(D8+D11) -> 0 | E12: =SUM(E8+E11) -> 67 | F12: =SUM(F8+F11) -> 65 | G12: =SUM(G8+G11) -> 41 | J12: المجموع الكلي | L12: =SUM(L8+L11) -> 0 | M12: =SUM(M8+M11) -> 52 | N12: =SUM(N8+N11) -> 69 | O12: =SUM(O8+O11) -> 111 | R12: المجموع الكلي | T12: 25 | U12: 56 | V12: 57 | W12: 108 | Z12: المجموع الكلي | AB12: 3 | AC12: 55 | AD12: 56 | AE12: 58 | AH12: المجموع الكلي | AJ12: =SUM(AJ8+AJ11) -> 6 | AK12: =SUM(AK8+AK11) -> 89 | AL12: =SUM(AL8+AL11) -> 66 | AM12: =SUM(AM8+AM11) -> 207 | AP12: المجموع الكلي | AR12: 0 | AS12: 40 | AT12: 38 | AU12: 14 | AX12: المجموع الكلي | AZ12: 0 | BA12: 39 | BB12: 51 | BC12: 110 | BF12: المجموع الكلي | BH12: =SUM(BH8+BH11) -> 0 | BI12: =SUM(BI8+BI11) -> 40 | BJ12: =SUM(BJ8+BJ11) -> 38 | BK12: =SUM(BK8+BK11) -> 14 | BN12: المجموع الكلي | BP12: =SUM(BP8+BP11) -> 60 | BQ12: =SUM(BQ8+BQ11) -> 46 | BR12: =SUM(BR8+BR11) -> 17 | BS12: =SUM(BS8+BS11) -> 28 | BV12: المجموع الكلي | BX12: =SUM(BX8+BX11) -> 5 | BY12: =SUM(BY8+BY11) -> 71 | BZ12: =SUM(BZ8+BZ11) -> 73 | CA12: =SUM(CA8+CA11) -> 45 | CD12: المجموع الكلي | CF12: =SUM(CF8+CF11) -> 0 | CG12: =SUM(CG8+CG11) -> 0 | CH12: =SUM(CH8+CH11) -> 0 | CI12: =SUM(CI8+CI11) -> 0 | CL12: المجموع الكلي | CN12: =SUM(CN8+CN11) -> 0 | CO12: =SUM(CO8+CO11) -> 0 | CP12: =SUM(CP8+CP11) -> 0 | CQ12: =SUM(CQ8+CQ11) -> 0 | CT12: المجموع الكلي | CV12: =SUM(CV8+CV11) -> 99 | CW12: =SUM(CW8+CW11) -> 555 | CX12: =SUM(CX8+CX11) -> 530 | CY12: =SUM(CY8+CY11) -> 736
A13: الجامعة | B13: سعودي | C13: ذكر | D13: 0 | E13: 9 | F13: 10 | G13: 12 | I13: الجامعة | J13: سعودي | K13: ذكر | L13: 0 | M13: 5 | N13: 6 | O13: 2 | Q13: الجامعة | R13: سعودي | S13: ذكر | T13: 0 | U13: 30 | V13: 10 | W13: 20 | Y13: الجامعة | Z13: سعودي | AA13: ذكر | AB13: 0 | AC13: 32 | AD13: 61 | AE13: 9 | AG13: الجامعة | AH13: سعودي | AI13: ذكر | AJ13: 0 | AK13: 0 | AL13: 0 | AM13: 0 | AO13: الجامعة | AP13: سعودي | AQ13: ذكر | AR13: 0 | AS13: 159 | AT13: 358 | AU13: 373 | AW13: الجامعة | AX13: سعودي | AY13: ذكر | AZ13: 0 | BA13: 12 | BB13: 6 | BC13: 10 | BE13: الجامعة | BF13: سعودي | BG13: ذكر | BH13: 0 | BI13: 159 | BJ13: 358 | BK13: 373 | BM13: الجامعة | BN13: سعودي | BO13: ذكر | BP13: 0 | BQ13: 3 | BR13: 6 | BS13: 3 | BU13: الجامعة | BV13: سعودي | BW13: ذكر | BX13: 0 | BY13: 0 | BZ13: 0 | CA13: 0 | CC13: الجامعة | CD13: سعودي | CE13: ذكر | CF13: 0 | CG13: 0 | CH13: 0 | CI13: 0 | CK13: الجامعة | CL13: سعودي | CM13: ذكر | CN13: 0 | CO13: 0 | CP13: 0 | CQ13: 0 | CS13: =(CK13) -> الجامعة | CT13: سعودي | CU13: ذكر | CV13: =SUM(D13+L13+T13+AB13+AJ13+AR13+AZ13+BH13+BP13+BX13+CF13+CN13) -> 0 | CW13: =SUM(E13+M13+U13+AC13+AK13+AS13+BA13+BI13+BQ13+BY13+CG13+CO13) -> 409 | CX13: =SUM(F13+N13+V13+AD13+AL13+AT13+BB13+BJ13+BR13+BZ13+CH13+CP13) -> 815 | CY13: =SUM(G13+O13+W13+AE13+AM13+AU13+BC13+BK13+BS13+CA13+CI13+CQ13) -> 802
C14: أنثى | D14: 0 | E14: 0 | F14: 0 | G14: 0 | K14: أنثى | L14: 0 | M14: 0 | N14: 4 | O14: 5 | S14: أنثى | T14: 0 | U14: 5 | V14: 6 | W14: 0 | AA14: أنثى | AB14: 0 | AC14: 2 | AD14: 22 | AE14: 5 | AI14: أنثى | AJ14: 0 | AK14: 0 | AL14: 0 | AM14: 0 | AQ14: أنثى | AR14: 0 | AS14: 173 | AT14: 327 | AU14: 376 | AY14: أنثى | AZ14: 0 | BA14: 0 | BB14: 2 | BC14: 3 | BG14: أنثى | BH14: 0 | BI14: 173 | BJ14: 327 | BK14: 376 | BO14: أنثى | BP14: 0 | BQ14: 4 | BR14: 4 | BS14: 7 | BW14: أنثى | BX14: 0 | BY14: 0 | BZ14: 0 | CA14: 0 | CE14: أنثى | CF14: 0 | CG14: 0 | CH14: 0 | CI14: 0 | CM14: أنثى | CN14: 0 | CO14: 0 | CP14: 0 | CQ14: 0 | CU14: أنثى | CV14: =SUM(D14+L14+T14+AB14+AJ14+AR14+AZ14+BH14+BP14+BX14+CF14+CN14) -> 0 | CW14: =SUM(E14+M14+U14+AC14+AK14+AS14+BA14+BI14+BQ14+BY14+CG14+CO14) -> 357 | CX14: =SUM(F14+N14+V14+AD14+AL14+AT14+BB14+BJ14+BR14+BZ14+CH14+CP14) -> 692 | CY14: =SUM(G14+O14+W14+AE14+AM14+AU14+BC14+BK14+BS14+CA14+CI14+CQ14) -> 772
B15: مجموع السعوديين | D15: 0 | E15: 9 | F15: 10 | G15: 12 | J15: مجموع السعوديين | L15: 0 | M15: 5 | N15: 10 | O15: 7 | R15: مجموع السعوديين | T15: 0 | U15: 35 | V15: 16 | W15: 20 | Z15: مجموع السعوديين | AB15: 0 | AC15: 34 | AD15: 83 | AE15: 14 | AH15: مجموع السعوديين | AJ15: =SUM(AJ13:AJ14) -> 0 | AK15: =SUM(AK13:AK14) -> 0 | AL15: =SUM(AL13:AL14) -> 0 | AM15: =SUM(AM13:AM14) -> 0 | AP15: مجموع السعوديين | AR15: 0 | AS15: 332 | AT15: 685 | AU15: 749 | AX15: مجموع السعوديين | AZ15: 0 | BA15: 12 | BB15: 8 | BC15: 13 | BF15: مجموع السعوديين | BH15: =SUM(BH13:BH14) -> 0 | BI15: =SUM(BI13:BI14) -> 332 | BJ15: =SUM(BJ13:BJ14) -> 685 | BK15: =SUM(BK13:BK14) -> 749 | BN15: مجموع السعوديين | BP15: =SUM(BP13:BP14) -> 0 | BQ15: =SUM(BQ13:BQ14) -> 7 | BR15: =SUM(BR13:BR14) -> 10 | BS15: =SUM(BS13:BS14) -> 10 | BV15: مجموع السعوديين | BX15: =SUM(BX13:BX14) -> 0 | BY15: =SUM(BY13:BY14) -> 0 | BZ15: =SUM(BZ13:BZ14) -> 0 | CA15: =SUM(CA13:CA14) -> 0 | CD15: مجموع السعوديين | CF15: =SUM(CF13:CF14) -> 0 | CG15: =SUM(CG13:CG14) -> 0 | CH15: =SUM(CH13:CH14) -> 0 | CI15: =SUM(CI13:CI14) -> 0 | CL15: مجموع السعوديين | CN15: =SUM(CN13:CN14) -> 0 | CO15: =SUM(CO13:CO14) -> 0 | CP15: =SUM(CP13:CP14) -> 0 | CQ15: =SUM(CQ13:CQ14) -> 0 | CT15: مجموع السعوديين | CV15: =SUM(CV13:CV14) -> 0 | CW15: =SUM(CW13:CW14) -> 766 | CX15: =SUM(CX13:CX14) -> 1507 | CY15: =SUM(CY13:CY14) -> 1574
B16: غير سعودي | C16: ذكر | D16: 0 | E16: 0 | F16: 0 | G16: 0 | J16: غير سعودي | K16: ذكر | L16: 0 | M16: 0 | N16: 0 | O16: 3 | R16: غير سعودي | S16: ذكر | T16: 0 | U16: 10 | V16: 5 | W16: 0 | Z16: غير سعودي | AA16: ذكر | AB16: 0 | AC16: 1 | AD16: 0 | AE16: 2 | AH16: غير سعودي | AI16: ذكر | AJ16: 0 | AK16: 0 | AL16: 0 | AM16: 0 | AP16: غير سعودي | AQ16: ذكر | AR16: 0 | AS16: 114 | AT16: 129 | AU16: 94 | AX16: غير سعودي | AY16: ذكر | AZ16: 0 | BA16: 0 | BB16: 0 | BC16: 0 | BF16: غير سعودي | BG16: ذكر | BH16: 0 | BI16: 114 | BJ16: 129 | BK16: 94 | BN16: غير سعودي | BO16: ذكر | BP16: 0 | BQ16: 2 | BR16: 3 | BS16: 0 | BV16: غير سعودي | BW16: ذكر | BX16: 0 | BY16: 0 | BZ16: 0 | CA16: 0 | CD16: غير سعودي | CE16: ذكر | CF16: 0 | CG16: 0 | CH16: 0 | CI16: 0 | CL16: غير سعودي | CM16: ذكر | CN16: 0 | CO16: 0 | CP16: 0 | CQ16: 0 | CT16: غير سعودي | CU16: ذكر | CV16: =SUM(D16+L16+T16+AB16+AJ16+AR16+AZ16+BH16+BP16+BX16+CF16+CN16) -> 0 | CW16: =SUM(E16+M16+U16+AC16+AK16+AS16+BA16+BI16+BQ16+BY16+CG16+CO16) -> 241 | CX16: =SUM(F16+N16+V16+AD16+AL16+AT16+BB16+BJ16+BR16+BZ16+CH16+CP16) -> 266 | CY16: =SUM(G16+O16+W16+AE16+AM16+AU16+BC16+BK16+BS16+CA16+CI16+CQ16) -> 193
C17: أنثى | D17: 0 | E17: 0 | F17: 3 | G17: 0 | K17: أنثى | L17: 0 | M17: 0 | N17: 4 | O17: 0 | S17: أنثى | T17: 0 | U17: 5 | V17: 5 | W17: 5 | AA17: أنثى | AB17: 0 | AC17: 5 | AD17: 0 | AE17: 1 | AI17: أنثى | AJ17: 0 | AK17: 0 | AL17: 0 | AM17: 0 | AQ17: أنثى | AR17: 0 | AS17: 81 | AT17: 80 | AU17: 98 | AY17: أنثى | AZ17: 0 | BA17: 0 | BB17: 0 | BC17: 0 | BG17: أنثى | BH17: 0 | BI17: 81 | BJ17: 80 | BK17: 98 | BO17: أنثى | BP17: 0 | BQ17: 0 | BR17: 0 | BS17: 0 | BW17: أنثى | BX17: 0 | BY17: 0 | BZ17: 0 | CA17: 0 | CE17: أنثى | CF17: 0 | CG17: 0 | CH17: 0 | CI17: 0 | CM17: أنثى | CN17: 0 | CO17: 0 | CP17: 0 | CQ17: 0 | CU17: أنثى | CV17: =SUM(D17+L17+T17+AB17+AJ17+AR17+AZ17+BH17+BP17+BX17+CF17+CN17) -> 0 | CW17: =SUM(E17+M17+U17+AC17+AK17+AS17+BA17+BI17+BQ17+BY17+CG17+CO17) -> 172 | CX17: =SUM(F17+N17+V17+AD17+AL17+AT17+BB17+BJ17+BR17+BZ17+CH17+CP17) -> 172 | CY17: =SUM(G17+O17+W17+AE17+AM17+AU17+BC17+BK17+BS17+CA17+CI17+CQ17) -> 202
B18: مجمع الغير سعوديين | D18: =SUM(D16:D17) -> 0 | E18: =SUM(E16:E17) -> 0 | F18: =SUM(F16:F17) -> 3 | G18: =SUM(G16:G17) -> 0 | J18: مجمع الغير سعوديين | L18: =SUM(L16:L17) -> 0 | M18: =SUM(M16:M17) -> 0 | N18: =SUM(N16:N17) -> 4 | O18: =SUM(O16:O17) -> 3 | R18: مجمع الغير سعوديين | T18: 0 | U18: 15 | V18: 10 | W18: 5 | Z18: مجمع الغير سعوديين | AB18: 0 | AC18: 6 | AD18: 0 | AE18: 3 | AH18: مجمع الغير سعوديين | AJ18: =SUM(AJ16:AJ17) -> 0 | AK18: =SUM(AK16:AK17) -> 0 | AL18: =SUM(AL16:AL17) -> 0 | AM18: =SUM(AM16:AM17) -> 0 | AP18: مجمع الغير سعوديين | AR18: 0 | AS18: 195 | AT18: 209 | AU18: 192 | AX18: مجمع الغير سعوديين | AZ18: 0 | BA18: 0 | BB18: 0 | BC18: 0 | BF18: مجمع الغير سعوديين | BH18: =SUM(BH16:BH17) -> 0 | BI18: =SUM(BI16:BI17) -> 195 | BJ18: =SUM(BJ16:BJ17) -> 209 | BK18: =SUM(BK16:BK17) -> 192 | BN18: مجمع الغير سعوديين | BP18: =SUM(BP16:BP17) -> 0 | BQ18: =SUM(BQ16:BQ17) -> 2 | BR18: =SUM(BR16:BR17) -> 3 | BS18: =SUM(BS16:BS17) -> 0 | BV18: مجمع الغير سعوديين | BX18: =SUM(BX16:BX17) -> 0 | BY18: =SUM(BY16:BY17) -> 0 | BZ18: =SUM(BZ16:BZ17) -> 0 | CA18: =SUM(CA16:CA17) -> 0 | CD18: مجمع الغير سعوديين | CF18: =SUM(CF16:CF17) -> 0 | CG18: =SUM(CG16:CG17) -> 0 | CH18: =SUM(CH16:CH17) -> 0 | CI18: =SUM(CI16:CI17) -> 0 | CL18: مجمع الغير سعوديين | CN18: =SUM(CN16:CN17) -> 0 | CO18: =SUM(CO16:CO17) -> 0 | CP18: =SUM(CP16:CP17) -> 0 | CQ18: =SUM(CQ16:CQ17) -> 0 | CT18: مجمع الغير سعوديين | CV18: =SUM(CV16:CV17) -> 0 | CW18: =SUM(CW16:CW17) -> 413 | CX18: =SUM(CX16:CX17) -> 438 | CY18: =SUM(CY16:CY17) -> 395
B19: المجموع الكلي | D19: =SUM(D15+D18) -> 0 | E19: =SUM(E15+E18) -> 9 | F19: =SUM(F15+F18) -> 13 | G19: =SUM(G15+G18) -> 12 | J19: المجموع الكلي | L19: =SUM(L15+L18) -> 0 | M19: =SUM(M15+M18) -> 5 | N19: =SUM(N15+N18) -> 14 | O19: =SUM(O15+O18) -> 10 | R19: المجموع الكلي | T19: 0 | U19: 50 | V19: 26 | W19: 25 | Z19: المجموع الكلي | AB19: 0 | AC19: 40 | AD19: 83 | AE19: 17 | AH19: المجموع الكلي | AJ19: =SUM(AJ15+AJ18) -> 0 | AK19: =SUM(AK15+AK18) -> 0 | AL19: =SUM(AL15+AL18) -> 0 | AM19: =SUM(AM15+AM18) -> 0 | AP19: المجموع الكلي | AR19: 0 | AS19: 527 | AT19: 894 | AU19: 941 | AX19: المجموع الكلي | AZ19: 0 | BA19: 12 | BB19: 8 | BC19: 13 | BF19: المجموع الكلي | BH19: =SUM(BH15+BH18) -> 0 | BI19: =SUM(BI15+BI18) -> 527 | BJ19: =SUM(BJ15+BJ18) -> 894 | BK19: =SUM(BK15+BK18) -> 941 | BN19: المجموع الكلي | BP19: =SUM(BP15+BP18) -> 0 | BQ19: =SUM(BQ15+BQ18) -> 9 | BR19: =SUM(BR15+BR18) -> 13 | BS19: =SUM(BS15+BS18) -> 10 | BV19: المجموع الكلي | BX19: =SUM(BX15+BX18) -> 0 | BY19: =SUM(BY15+BY18) -> 0 | BZ19: =SUM(BZ15+BZ18) -> 0 | CA19: =SUM(CA15+CA18) -> 0 | CD19: المجموع الكلي | CF19: =SUM(CF15+CF18) -> 0 | CG19: =SUM(CG15+CG18) -> 0 | CH19: =SUM(CH15+CH18) -> 0 | CI19: =SUM(CI15+CI18) -> 0 | CL19: المجموع الكلي | CN19: =SUM(CN15+CN18) -> 0 | CO19: =SUM(CO15+CO18) -> 0 | CP19: =SUM(CP15+CP18) -> 0 | CQ19: =SUM(CQ15+CQ18) -> 0 | CT19: المجموع الكلي | CV19: =SUM(CV15+CV18) -> 0 | CW19: =SUM(CW15+CW18) -> 1179 | CX19: =SUM(CX15+CX18) -> 1945 | CY19: =SUM(CY15+CY18) -> 1969
A20: السليمانية | B20: سعودي | C20: ذكر | D20: 0 | E20: 98 | F20: 301 | G20: 211 | I20: السليمانية | J20: سعودي | K20: ذكر | L20: 0 | M20: 178 | N20: 154 | O20: 158 | Q20: السليمانية | R20: سعودي | S20: ذكر | T20: 2 | U20: 35 | V20: 44 | W20: 34 | Y20: السليمانية | Z20: سعودي | AA20: ذكر | AB20: 0 | AC20: 0 | AD20: 0 | AE20: 0 | AG20: السليمانية | AH20: سعودي | AI20: ذكر | AJ20: 2 | AK20: 62 | AL20: 29 | AM20: 64 | AO20: السليمانية | AP20: سعودي | AQ20: ذكر | AR20: 0 | AS20: 78 | AT20: 298 | AU20: 302 | AW20: السليمانية | AX20: سعودي | AY20: ذكر | AZ20: 0 | BA20: 78 | BB20: 298 | BC20: 302 | BE20: السليمانية | BF20: سعودي | BG20: ذكر | BH20: 0 | BI20: 78 | BJ20: 298 | BK20: 302 | BM20: السليمانية | BN20: سعودي | BO20: ذكر | BQ20: 21 | BR20: 45 | BS20: 66 | BU20: السليمانية | BV20: سعودي | BW20: ذكر | BX20: 0 | BY20: 98 | BZ20: 301 | CA20: 211 | CC20: السليمانية | CD20: سعودي | CE20: ذكر | CF20: 0 | CG20: 0 | CH20: 0 | CI20: 0 | CK20: السليمانية | CL20: سعودي | CM20: ذكر | CN20: 0 | CO20: 0 | CP20: 0 | CQ20: 0 | CS20: =(CK20) -> السليمانية | CT20: سعودي | CU20: ذكر | CV20: =SUM(D20+L20+T20+AB20+AJ20+AR20+AZ20+BH20+BP20+BX20+CF20+CN20) -> 4 | CW20: =SUM(E20+M20+U20+AC20+AK20+AS20+BA20+BI20+BQ20+BY20+CG20+CO20) -> 726 | CX20: =SUM(F20+N20+V20+AD20+AL20+AT20+BB20+BJ20+BR20+BZ20+CH20+CP20) -> 1768 | CY20: =SUM(G20+O20+W20+AE20+AM20+AU20+BC20+BK20+BS20+CA20+CI20+CQ20) -> 1650
C21: أنثى | D21: 0 | E21: 65 | F21: 280 | G21: 190 | K21: أنثى | L21: 0 | M21: 165 | N21: 124 | O21: 187 | S21: أنثى | T21: 1 | U21: 8 | V21: 11 | W21: 21 | AA21: أنثى | AB21: 0 | AC21: 0 | AD21: 0 | AE21: 0 | AI21: أنثى | AJ21: 1 | AK21: 19 | AL21: 40 | AM21: 51 | AQ21: أنثى | AR21: 0 | AS21: 98 | AT21: 201 | AU21: 206 | AY21: أنثى | AZ21: 0 | BA21: 98 | BB21: 201 | BC21: 206 | BG21: أنثى | BH21: 0 | BI21: 98 | BJ21: 201 | BK21: 206 | BO21: أنثى | BP21: 0 | BQ21: 25 | BR21: 50 | BS21: 71 | BW21: أنثى | BX21: 0 | BY21: 65 | BZ21: 280 | CA21: 190 | CE21: أنثى | CF21: 0 | CG21: 0 | CH21: 0 | CI21: 0 | CM21: أنثى | CN21: 0 | CO21: 0 | CP21: 0 | CQ21: 0 | CU21: أنثى | CV21: =SUM(D21+L21+T21+AB21+AJ21+AR21+AZ21+BH21+BP21+BX21+CF21+CN21) -> 2 | CW21: =SUM(E21+M21+U21+AC21+AK21+AS21+BA21+BI21+BQ21+BY21+CG21+CO21) -> 641 | CX21: =SUM(F21+N21+V21+AD21+AL21+AT21+BB21+BJ21+BR21+BZ21+CH21+CP21) -> 1388 | CY21: =SUM(G21+O21+W21+AE21+AM21+AU21+BC21+BK21+BS21+CA21+CI21+CQ21) -> 1328
B22: مجموع السعوديين | D22: 0 | E22: 163 | F22: 581 | G22: 401 | J22: مجموع السعوديين | L22: 0 | M22: 343 | N22: 278 | O22: 345 | R22: مجموع السعوديين | T22: 3 | U22: 43 | V22: 55 | W22: 55 | Z22: مجموع السعوديين | AB22: 0 | AC22: 0 | AD22: 0 | AE22: 0 | AH22: مجموع السعوديين | AJ22: 3 | AK22: 81 | AL22: 69 | AM22: 115 | AP22: مجموع السعوديين | AR22: 0 | AS22: 176 | AT22: 499 | AU22: 508 | AX22: مجموع السعوديين | AZ22: 0 | BA22: 176 | BB22: 499 | BC22: 508 | BF22: مجموع السعوديين | BH22: =SUM(BH20:BH21) -> 0 | BI22: =SUM(BI20:BI21) -> 176 | BJ22: =SUM(BJ20:BJ21) -> 499 | BK22: =SUM(BK20:BK21) -> 508 | BN22: مجموع السعوديين | BP22: =SUM(BP20:BP21) -> 0 | BQ22: =SUM(BQ20:BQ21) -> 46 | BR22: =SUM(BR20:BR21) -> 95 | BS22: =SUM(BS20:BS21) -> 137 | BV22: مجموع السعوديين | BX22: 0 | BY22: 163 | BZ22: 581 | CA22: 401 | CD22: مجموع السعوديين | CF22: =SUM(CF20:CF21) -> 0 | CG22: =SUM(CG20:CG21) -> 0 | CH22: =SUM(CH20:CH21) -> 0 | CI22: =SUM(CI20:CI21) -> 0 | CL22: مجموع السعوديين | CN22: =SUM(CN20:CN21) -> 0 | CO22: =SUM(CO20:CO21) -> 0 | CP22: =SUM(CP20:CP21) -> 0 | CQ22: =SUM(CQ20:CQ21) -> 0 | CT22: مجموع السعوديين | CV22: =SUM(CV20:CV21) -> 6 | CW22: =SUM(CW20:CW21) -> 1367 | CX22: =SUM(CX20:CX21) -> 3156 | CY22: =SUM(CY20:CY21) -> 2978
B23: غير سعودي | C23: ذكر | D23: 0 | E23: 32 | F23: 144 | G23: 111 | J23: غير سعودي | K23: ذكر | L23: 0 | M23: 112 | N23: 141 | O23: 96 | R23: غير سعودي | S23: ذكر | T23: 0 | U23: 16 | V23: 35 | W23: 28 | Z23: غير سعودي | AA23: ذكر | AB23: 0 | AC23: 0 | AD23: 0 | AE23: 0 | AH23: غير سعودي | AI23: ذكر | AJ23: 0 | AK23: 14 | AL23: 16 | AM23: 3 | AP23: غير سعودي | AQ23: ذكر | AR23: 0 | AS23: 95 | AT23: 102 | AU23: 82 | AX23: غير سعودي | AY23: ذكر | AZ23: 0 | BA23: 54 | BB23: 147 | BC23: 120 | BF23: غير سعودي | BG23: ذكر | BH23: 0 | BI23: 95 | BJ23: 102 | BK23: 82 | BN23: غير سعودي | BO23: ذكر | BP23: 0 | BQ23: 5 | BR23: 7 | BS23: 8 | BV23: غير سعودي | BW23: ذكر | BX23: 0 | BY23: 32 | BZ23: 144 | CA23: 111 | CD23: غير سعودي | CE23: ذكر | CF23: 0 | CG23: 0 | CH23: 0 | CI23: 0 | CL23: غير سعودي | CM23: ذكر | CN23: 0 | CO23: 0 | CP23: 0 | CQ23: 0 | CT23: غير سعودي | CU23: ذكر | CV23: =SUM(D23+L23+T23+AB23+AJ23+AR23+AZ23+BH23+BP23+BX23+CF23+CN23) -> 0 | CW23: =SUM(E23+M23+U23+AC23+AK23+AS23+BA23+BI23+BQ23+BY23+CG23+CO23) -> 455 | CX23: =SUM(F23+N23+V23+AD23+AL23+AT23+BB23+BJ23+BR23+BZ23+CH23+CP23) -> 838 | CY23: =SUM(G23+O23+W23+AE23+AM23+AU23+BC23+BK23+BS23+CA23+CI23+CQ23) -> 641
C24: أنثى | D24: 0 | E24: 22 | F24: 80 | G24: 89 | K24: أنثى | L24: 0 | M24: 69 | N24: 87 | O24: 78 | S24: أنثى | T24: 0 | U24: 2 | V24: 15 | W24: 5 | AA24: أنثى | AB24: 0 | AC24: 0 | AD24: 0 | AE24: 0 | AI24: أنثى | AJ24: 0 | AK24: 2 | AL24: 4 | AM24: 1 | AQ24: أنثى | AR24: 0 | AS24: 63 | AT24: 52 | AU24: 79 | AY24: أنثى | AZ24: 0 | BA24: 25 | BB24: 66 | BC24: 101 | BG24: أنثى | BH24: 0 | BI24: 63 | BJ24: 52 | BK24: 79 | BO24: أنثى | BP24: 0 | BQ24: 6 | BR24: 5 | BS24: 0 | BW24: أنثى | BX24: 0 | BY24: 22 | BZ24: 80 | CA24: 89 | CE24: أنثى | CF24: 0 | CG24: 0 | CH24: 0 | CI24: 0 | CM24: أنثى | CN24: 0 | CO24: 0 | CP24: 0 | CQ24: 0 | CU24: أنثى | CV24: =SUM(D24+L24+T24+AB24+AJ24+AR24+AZ24+BH24+BP24+BX24+CF24+CN24) -> 0 | CW24: =SUM(E24+M24+U24+AC24+AK24+AS24+BA24+BI24+BQ24+BY24+CG24+CO24) -> 274 | CX24: =SUM(F24+N24+V24+AD24+AL24+AT24+BB24+BJ24+BR24+BZ24+CH24+CP24) -> 441 | CY24: =SUM(G24+O24+W24+AE24+AM24+AU24+BC24+BK24+BS24+CA24+CI24+CQ24) -> 521
B25: مجمع الغير سعوديين | D25: =SUM(D23:D24) -> 0 | E25: =SUM(E23:E24) -> 54 | F25: =SUM(F23:F24) -> 224 | G25: =SUM(G23:G24) -> 200 | J25: مجمع الغير سعوديين | L25: =SUM(L23:L24) -> 0 | M25: =SUM(M23:M24) -> 181 | N25: =SUM(N23:N24) -> 228 | O25: =SUM(O23:O24) -> 174 | R25: مجمع الغير سعوديين | T25: 0 | U25: 18 | V25: 50 | W25: 33 | Z25: مجمع الغير سعوديين | AB25: 0 | AC25: 0 | AD25: 0 | AE25: 0 | AH25: مجمع الغير سعوديين | AJ25: =SUM(AJ23:AJ24) -> 0 | AK25: =SUM(AK23:AK24) -> 16 | AL25: =SUM(AL23:AL24) -> 20 | AM25: =SUM(AM23:AM24) -> 4 | AP25: مجمع الغير سعوديين | AR25: 0 | AS25: 158 | AT25: 154 | AU25: 161 | AX25: مجمع الغير سعوديين | AZ25: 0 | BA25: 79 | BB25: 213 | BC25: 221 | BF25: مجمع الغير سعوديين | BH25: =SUM(BH23:BH24) -> 0 | BI25: =SUM(BI23:BI24) -> 158 | BJ25: =SUM(BJ23:BJ24) -> 154 | BK25: =SUM(BK23:BK24) -> 161 | BN25: مجمع الغير سعوديين | BP25: =SUM(BP23:BP24) -> 0 | BQ25: =SUM(BQ23:BQ24) -> 11 | BR25: =SUM(BR23:BR24) -> 12 | BS25: =SUM(BS23:BS24) -> 8 | BV25: مجمع الغير سعوديين | BX25: 0 | BY25: 54 | BZ25: 224 | CA25: 200 | CD25: مجمع الغير سعوديين | CF25: =SUM(CF23:CF24) -> 0 | CG25: =SUM(CG23:CG24) -> 0 | CH25: =SUM(CH23:CH24) -> 0 | CI25: =SUM(CI23:CI24) -> 0 | CL25: مجمع الغير سعوديين | CN25: =SUM(CN23:CN24) -> 0 | CO25: =SUM(CO23:CO24) -> 0 | CP25: =SUM(CP23:CP24) -> 0 | CQ25: =SUM(CQ23:CQ24) -> 0 | CT25: مجمع الغير سعوديين | CV25: =SUM(CV23:CV24) -> 0 | CW25: =SUM(CW23:CW24) -> 729 | CX25: =SUM(CX23:CX24) -> 1279 | CY25: =SUM(CY23:CY24) -> 1162
B26: المجموع الكلي | D26: =SUM(D22+D25) -> 0 | E26: =SUM(E22+E25) -> 217 | F26: =SUM(F22+F25) -> 805 | G26: =SUM(G22+G25) -> 601 | J26: المجموع الكلي | L26: =SUM(L22+L25) -> 0 | M26: =SUM(M22+M25) -> 524 | N26: =SUM(N22+N25) -> 506 | O26: =SUM(O22+O25) -> 519 | R26: المجموع الكلي | T26: 3 | U26: 61 | V26: 105 | W26: 88 | Z26: المجموع الكلي | AB26: 0 | AC26: 0 | AD26: 0 | AE26: 0 | AH26: المجموع الكلي | AJ26: =SUM(AJ22+AJ25) -> 3 | AK26: =SUM(AK22+AK25) -> 97 | AL26: =SUM(AL22+AL25) -> 89 | AM26: =SUM(AM22+AM25) -> 119 | AP26: المجموع الكلي | AR26: 0 | AS26: 334 | AT26: 653 | AU26: 669 | AX26: المجموع الكلي | AZ26: 0 | BA26: 255 | BB26: 712 | BC26: 729 | BF26: المجموع الكلي | BH26: =SUM(BH22+BH25) -> 0 | BI26: =SUM(BI22+BI25) -> 334 | BJ26: =SUM(BJ22+BJ25) -> 653 | BK26: =SUM(BK22+BK25) -> 669 | BN26: المجموع الكلي | BP26: =SUM(BP22+BP25) -> 0 | BQ26: =SUM(BQ22+BQ25) -> 57 | BR26: =SUM(BR22+BR25) -> 107 | BS26: =SUM(BS22+BS25) -> 145 | BV26: المجموع الكلي | BX26: 0 | BY26: 217 | BZ26: 805 | CA26: 601 | CD26: المجموع الكلي | CF26: =SUM(CF22+CF25) -> 0 | CG26: =SUM(CG22+CG25) -> 0 | CH26: =SUM(CH22+CH25) -> 0 | CI26: =SUM(CI22+CI25) -> 0 | CL26: المجموع الكلي | CN26: =SUM(CN22+CN25) -> 0 | CO26: =SUM(CO22+CO25) -> 0 | CP26: =SUM(CP22+CP25) -> 0 | CQ26: =SUM(CQ22+CQ25) -> 0 | CT26: المجموع الكلي | CV26: =SUM(CV22+CV25) -> 6 | CW26: =SUM(CW22+CW25) -> 2096 | CX26: =SUM(CX22+CX25) -> 4435 | CY26: =SUM(CY22+CY25) -> 4140
A27: المطار القديم | B27: سعودي | C27: ذكر | D27: 0 | E27: 81 | F27: 99 | G27: 120 | I27: المطار القديم | J27: سعودي | K27: ذكر | L27: 0 | M27: 0 | N27: 0 | O27: 0 | Q27: المطار القديم | R27: سعودي | S27: ذكر | T27: 0 | U27: 56 | V27: 36 | W27: 33 | Y27: المطار القديم | Z27: سعودي | AA27: ذكر | AB27: 0 | AC27: 0 | AD27: 0 | AE27: 0 | AG27: المطار القديم | AH27: سعودي | AI27: ذكر | AJ27: 0 | AK27: 21 | AL27: 20 | AM27: 26 | AO27: المطار القديم | AP27: سعودي | AQ27: ذكر | AR27: 0 | AS27: 18 | AT27: 19 | AU27: 23 | AW27: المطار القديم | AX27: سعودي | AY27: ذكر | AZ27: 0 | BA27: 89 | BB27: 110 | BC27: 102 | BE27: المطار القديم | BF27: سعودي | BG27: ذكر | BH27: 0 | BI27: 18 | BJ27: 1 | BK27: 31 | BM27: المطار القديم | BN27: سعودي | BO27: ذكر | BP27: 2 | BQ27: 35 | BR27: 22 | BS27: 58 | BU27: المطار القديم | BV27: سعودي | BW27: ذكر | BX27: 0 | BY27: 81 | BZ27: 99 | CA27: 120 | CC27: المطار القديم | CD27: سعودي | CE27: ذكر | CF27: 0 | CG27: 0 | CH27: 0 | CI27: 0 | CK27: المطار القديم | CL27: سعودي | CM27: ذكر | CN27: 0 | CO27: 0 | CP27: 0 | CQ27: 0 | CS27: =(CK27) -> المطار القديم | CT27: سعودي | CU27: ذكر | CV27: =SUM(D27+L27+T27+AB27+AJ27+AR27+AZ27+BH27+BP27+BX27+CF27+CN27) -> 2 | CW27: =SUM(E27+M27+U27+AC27+AK27+AS27+BA27+BI27+BQ27+BY27+CG27+CO27) -> 399 | CX27: =SUM(F27+N27+V27+AD27+AL27+AT27+BB27+BJ27+BR27+BZ27+CH27+CP27) -> 406 | CY27: =SUM(G27+O27+W27+AE27+AM27+AU27+BC27+BK27+BS27+CA27+CI27+CQ27) -> 513
C28: أنثى | D28: 0 | E28: 25 | F28: 40 | G28: 35 | K28: أنثى | L28: 0 | M28: 0 | N28: 0 | O28: 0 | S28: أنثى | T28: 0 | U28: 33 | V28: 6 | W28: 11 | AA28: أنثى | AB28: 0 | AC28: 0 | AD28: 0 | AE28: 0 | AI28: أنثى | AJ28: 0 | AK28: 5 | AL28: 9 | AM28: 10 | AQ28: أنثى | AR28: 0 | AS28: 8 | AT28: 21 | AU28: 27 | AY28: أنثى | AZ28: 0 | BA28: 49 | BB28: 87 | BC28: 76 | BG28: أنثى | BH28: 0 | BI28: 3 | BJ28: 0 | BK28: 9 | BO28: أنثى | BP28: 0 | BQ28: 8 | BR28: 10 | BS28: 9 | BW28: أنثى | BX28: 0 | BY28: 25 | BZ28: 40 | CA28: 35 | CE28: أنثى | CF28: 0 | CG28: 0 | CH28: 0 | CI28: 0 | CM28: أنثى | CN28: 0 | CO28: 0 | CP28: 0 | CQ28: 0 | CU28: أنثى | CV28: =SUM(D28+L28+T28+AB28+AJ28+AR28+AZ28+BH28+BP28+BX28+CF28+CN28) -> 0 | CW28: =SUM(E28+M28+U28+AC28+AK28+AS28+BA28+BI28+BQ28+BY28+CG28+CO28) -> 156 | CX28: =SUM(F28+N28+V28+AD28+AL28+AT28+BB28+BJ28+BR28+BZ28+CH28+CP28) -> 213 | CY28: =SUM(G28+O28+W28+AE28+AM28+AU28+BC28+BK28+BS28+CA28+CI28+CQ28) -> 212
B29: مجموع السعوديين | D29: 0 | E29: 106 | F29: 139 | G29: 155 | J29: مجموع السعوديين | L29: =SUM(L27:L28) -> 0 | M29: =SUM(M27:M28) -> 0 | N29: =SUM(N27:N28) -> 0 | O29: =SUM(O27:O28) -> 0 | R29: مجموع السعوديين | T29: 0 | U29: 89 | V29: 42 | W29: 44 | Z29: مجموع السعوديين | AB29: 0 | AC29: 0 | AD29: 0 | AE29: 0 | AH29: مجموع السعوديين | AJ29: 0 | AK29: 26 | AL29: 29 | AM29: 36 | AP29: مجموع السعوديين | AR29: 0 | AS29: 26 | AT29: 40 | AU29: 50 | AX29: مجموع السعوديين | AZ29: 0 | BA29: 138 | BB29: 197 | BC29: 178 | BF29: مجموع السعوديين | BH29: =SUM(BH27:BH28) -> 0 | BI29: =SUM(BI27:BI28) -> 21 | BJ29: =SUM(BJ27:BJ28) -> 1 | BK29: =SUM(BK27:BK28) -> 40 | BN29: مجموع السعوديين | BP29: =SUM(BP27:BP28) -> 2 | BQ29: =SUM(BQ27:BQ28) -> 43 | BR29: =SUM(BR27:BR28) -> 32 | BS29: =SUM(BS27:BS28) -> 67 | BV29: مجموع السعوديين | BX29: 0 | BY29: 106 | BZ29: 139 | CA29: 155 | CD29: مجموع السعوديين | CF29: =SUM(CF27:CF28) -> 0 | CG29: =SUM(CG27:CG28) -> 0 | CH29: =SUM(CH27:CH28) -> 0 | CI29: =SUM(CI27:CI28) -> 0 | CL29: مجموع السعوديين | CN29: =SUM(CN27:CN28) -> 0 | CO29: =SUM(CO27:CO28) -> 0 | CP29: =SUM(CP27:CP28) -> 0 | CQ29: =SUM(CQ27:CQ28) -> 0 | CT29: مجموع السعوديين | CV29: =SUM(CV27:CV28) -> 2 | CW29: =SUM(CW27:CW28) -> 555 | CX29: =SUM(CX27:CX28) -> 619 | CY29: =SUM(CY27:CY28) -> 725
B30: غير سعودي | C30: ذكر | D30: 0 | E30: 10 | F30: 11 | G30: 1 | J30: غير سعودي | K30: ذكر | L30: 0 | M30: 0 | N30: 0 | O30: 0 | R30: غير سعودي | S30: ذكر | T30: 0 | U30: 2 | V30: 5 | W30: 0 | Z30: غير سعودي | AA30: ذكر | AB30: 0 | AC30: 0 | AD30: 0 | AE30: 0 | AH30: غير سعودي | AI30: ذكر | AJ30: 0 | AK30: 2 | AL30: 3 | AM30: 0 | AP30: غير سعودي | AQ30: ذكر | AR30: 0 | AS30: 4 | AT30: 6 | AU30: 0 | AX30: غير سعودي | AY30: ذكر | AZ30: 0 | BA30: 16 | BB30: 6 | BC30: 5 | BF30: غير سعودي | BG30: ذكر | BH30: 0 | BI30: 2 | BJ30: 0 | BK30: 2 | BN30: غير سعودي | BO30: ذكر | BP30: 0 | BQ30: 0 | BR30: 0 | BS30: 0 | BV30: غير سعودي | BW30: ذكر | BX30: 0 | BY30: 10 | BZ30: 11 | CA30: 1 | CD30: غير سعودي | CE30: ذكر | CF30: 0 | CG30: 0 | CH30: 0 | CI30: 0 | CL30: غير سعودي | CM30: ذكر | CN30: 0 | CO30: 0 | CP30: 0 | CQ30: 0 | CT30: غير سعودي | CU30: ذكر | CV30: =SUM(D30+L30+T30+AB30+AJ30+AR30+AZ30+BH30+BP30+BX30+CF30+CN30) -> 0 | CW30: =SUM(E30+M30+U30+AC30+AK30+AS30+BA30+BI30+BQ30+BY30+CG30+CO30) -> 46 | CX30: =SUM(F30+N30+V30+AD30+AL30+AT30+BB30+BJ30+BR30+BZ30+CH30+CP30) -> 42 | CY30: =SUM(G30+O30+W30+AE30+AM30+AU30+BC30+BK30+BS30+CA30+CI30+CQ30) -> 9
C31: أنثى | D31: 0 | E31: 2 | F31: 5 | G31: 5 | K31: أنثى | L31: 0 | M31: 0 | N31: 0 | O31: 0 | S31: أنثى | T31: 0 | U31: 3 | V31: 1 | W31: 0 | AA31: أنثى | AB31: 0 | AC31: 0 | AD31: 0 | AE31: 0 | AI31: أنثى | AJ31: 0 | AK31: 0 | AL31: 0 | AM31: 0 | AQ31: أنثى | AR31: 0 | AS31: 0 | AT31: 0 | AU31: 0 | AY31: أنثى | AZ31: 0 | BA31: 6 | BB31: 10 | BC31: 11 | BG31: أنثى | BH31: 0 | BI31: 0 | BJ31: 0 | BK31: 0 | BO31: أنثى | BP31: 0 | BQ31: 0 | BR31: 0 | BS31: 0 | BW31: أنثى | BX31: 0 | BY31: 2 | BZ31: 5 | CA31: 5 | CE31: أنثى | CF31: 0 | CG31: 0 | CH31: 0 | CI31: 0 | CM31: أنثى | CN31: 0 | CO31: 0 | CP31: 0 | CQ31: 0 | CU31: أنثى | CV31: =SUM(D31+L31+T31+AB31+AJ31+AR31+AZ31+BH31+BP31+BX31+CF31+CN31) -> 0 | CW31: =SUM(E31+M31+U31+AC31+AK31+AS31+BA31+BI31+BQ31+BY31+CG31+CO31) -> 13 | CX31: =SUM(F31+N31+V31+AD31+AL31+AT31+BB31+BJ31+BR31+BZ31+CH31+CP31) -> 21 | CY31: =SUM(G31+O31+W31+AE31+AM31+AU31+BC31+BK31+BS31+CA31+CI31+CQ31) -> 21
B32: مجمع الغير سعوديين | D32: =SUM(D30:D31) -> 0 | E32: =SUM(E30:E31) -> 12 | F32: =SUM(F30:F31) -> 16 | G32: =SUM(G30:G31) -> 6 | J32: مجمع الغير سعوديين | L32: =SUM(L30:L31) -> 0 | M32: =SUM(M30:M31) -> 0 | N32: =SUM(N30:N31) -> 0 | O32: =SUM(O30:O31) -> 0 | R32: مجمع الغير سعوديين | T32: 0 | U32: 0 | V32: 0 | W32: 0 | Z32: مجمع الغير سعوديين | AB32: 0 | AC32: 0 | AD32: 0 | AE32: 0 | AH32: مجمع الغير سعوديين | AJ32: =SUM(AJ30:AJ31) -> 0 | AK32: =SUM(AK30:AK31) -> 2 | AL32: =SUM(AL30:AL31) -> 3 | AM32: =SUM(AM30:AM31) -> 0 | AP32: مجمع الغير سعوديين | AR32: 0 | AS32: 4 | AT32: 6 | AU32: 0 | AX32: مجمع الغير سعوديين | AZ32: 0 | BA32: 22 | BB32: 16 | BC32: 16 | BF32: مجمع الغير سعوديين | BH32: =SUM(BH30:BH31) -> 0 | BI32: =SUM(BI30:BI31) -> 2 | BJ32: =SUM(BJ30:BJ31) -> 0 | BK32: =SUM(BK30:BK31) -> 2 | BN32: مجمع الغير سعوديين | BP32: =SUM(BP30:BP31) -> 0 | BQ32: =SUM(BQ30:BQ31) -> 0 | BR32: =SUM(BR30:BR31) -> 0 | BS32: =SUM(BS30:BS31) -> 0 | BV32: مجمع الغير سعوديين | BX32: 0 | BY32: 12 | BZ32: 16 | CA32: 6 | CD32: مجمع الغير سعوديين | CF32: =SUM(CF30:CF31) -> 0 | CG32: =SUM(CG30:CG31) -> 0 | CH32: =SUM(CH30:CH31) -> 0 | CI32: =SUM(CI30:CI31) -> 0 | CL32: مجمع الغير سعوديين | CN32: =SUM(CN30:CN31) -> 0 | CO32: =SUM(CO30:CO31) -> 0 | CP32: =SUM(CP30:CP31) -> 0 | CQ32: =SUM(CQ30:CQ31) -> 0 | CT32: مجمع الغير سعوديين | CV32: =SUM(CV30:CV31) -> 0 | CW32: =SUM(CW30:CW31) -> 59 | CX32: =SUM(CX30:CX31) -> 63 | CY32: =SUM(CY30:CY31) -> 30
B33: المجموع الكلي | D33: =SUM(D29+D32) -> 0 | E33: =SUM(E29+E32) -> 118 | F33: =SUM(F29+F32) -> 155 | G33: =SUM(G29+G32) -> 161 | J33: المجموع الكلي | L33: =SUM(L29+L32) -> 0 | M33: =SUM(M29+M32) -> 0 | N33: =SUM(N29+N32) -> 0 | O33: =SUM(O29+O32) -> 0 | R33: المجموع الكلي | T33: 0 | U33: 0 | V33: 0 | W33: 0 | Z33: المجموع الكلي | AB33: 0 | AC33: 0 | AD33: 0 | AE33: 0 | AH33: المجموع الكلي | AJ33: =SUM(AJ29+AJ32) -> 0 | AK33: =SUM(AK29+AK32) -> 28 | AL33: =SUM(AL29+AL32) -> 32 | AM33: =SUM(AM29+AM32) -> 36 | AP33: المجموع الكلي | AR33: 0 | AS33: 0 | AT33: 0 | AU33: 0 | AX33: المجموع الكلي | AZ33: 0 | BA33: 160 | BB33: 213 | BC33: 194 | BF33: المجموع الكلي | BH33: =SUM(BH29+BH32) -> 0 | BI33: =SUM(BI29+BI32) -> 23 | BJ33: =SUM(BJ29+BJ32) -> 1 | BK33: =SUM(BK29+BK32) -> 42 | BN33: المجموع الكلي | BP33: =SUM(BP29+BP32) -> 2 | BQ33: =SUM(BQ29+BQ32) -> 43 | BR33: =SUM(BR29+BR32) -> 32 | BS33: =SUM(BS29+BS32) -> 67 | BV33: المجموع الكلي | BX33: 0 | BY33: 118 | BZ33: 155 | CA33: 161 | CD33: المجموع الكلي | CF33: =SUM(CF29+CF32) -> 0 | CG33: =SUM(CG29+CG32) -> 0 | CH33: =SUM(CH29+CH32) -> 0 | CI33: =SUM(CI29+CI32) -> 0 | CL33: المجموع الكلي | CN33: =SUM(CN29+CN32) -> 0 | CO33: =SUM(CO29+CO32) -> 0 | CP33: =SUM(CP29+CP32) -> 0 | CQ33: =SUM(CQ29+CQ32) -> 0 | CT33: المجموع الكلي | CV33: =SUM(CV29+CV32) -> 2 | CW33: =SUM(CW29+CW32) -> 614 | CX33: =SUM(CX29+CX32) -> 682 | CY33: =SUM(CY29+CY32) -> 755
A34: الروابي | B34: سعودي | C34: ذكر | D34: 0 | E34: 0 | F34: 0 | G34: 0 | I34: الروابي | J34: سعودي | K34: ذكر | L34: 0 | M34: 0 | N34: 0 | O34: 0 | Q34: الروابي | R34: سعودي | S34: ذكر | T34: 0 | U34: 0 | V34: 0 | W34: 0 | Y34: الروابي | Z34: سعودي | AA34: ذكر | AB34: 0 | AC34: 0 | AD34: 0 | AE34: 0 | AG34: الروابي | AH34: سعودي | AI34: ذكر | AJ34: 0 | AK34: 0 | AL34: 0 | AM34: 0 | AO34: الروابي | AP34: سعودي | AQ34: ذكر | AR34: 0 | AS34: 0 | AT34: 0 | AU34: 0 | AW34: الروابي | AX34: سعودي | AY34: ذكر | AZ34: 0 | BA34: 0 | BB34: 0 | BC34: 0 | BE34: الروابي | BF34: سعودي | BG34: ذكر | BH34: 0 | BI34: 0 | BJ34: 0 | BK34: 0 | BM34: الروابي | BN34: سعودي | BO34: ذكر | BP34: 0 | BQ34: 0 | BR34: 0 | BS34: 0 | BU34: الروابي | BV34: سعودي | BW34: ذكر | BX34: 0 | BY34: 9 | BZ34: 10 | CA34: 12 | CC34: الروابي | CD34: سعودي | CE34: ذكر | CF34: 0 | CG34: 0 | CH34: 0 | CI34: 0 | CK34: الروابي | CL34: سعودي | CM34: ذكر | CN34: 0 | CO34: 0 | CP34: 0 | CQ34: 0 | CS34: =(CK34) -> الروابي | CT34: سعودي | CU34: ذكر | CV34: =SUM(D34+L34+T34+AB34+AJ34+AR34+AZ34+BH34+BP34+BX34+CF34+CN34) -> 0 | CW34: =SUM(E34+M34+U34+AC34+AK34+AS34+BA34+BI34+BQ34+BY34+CG34+CO34) -> 9 | CX34: =SUM(F34+N34+V34+AD34+AL34+AT34+BB34+BJ34+BR34+BZ34+CH34+CP34) -> 10 | CY34: =SUM(G34+O34+W34+AE34+AM34+AU34+BC34+BK34+BS34+CA34+CI34+CQ34) -> 12
C35: أنثى | D35: 0 | E35: 0 | F35: 0 | G35: 0 | K35: أنثى | L35: 0 | M35: 0 | N35: 0 | O35: 0 | S35: أنثى | T35: 0 | U35: 0 | V35: 0 | W35: 0 | AA35: أنثى | AB35: 0 | AC35: 0 | AD35: 0 | AE35: 0 | AI35: أنثى | AJ35: 0 | AK35: 0 | AL35: 0 | AM35: 0 | AQ35: أنثى | AR35: 0 | AS35: 0 | AT35: 0 | AU35: 0 | AY35: أنثى | AZ35: 0 | BA35: 0 | BB35: 0 | BC35: 0 | BG35: أنثى | BH35: 0 | BI35: 0 | BJ35: 0 | BK35: 0 | BO35: أنثى | BP35: 0 | BQ35: 0 | BR35: 0 | BS35: 0 | BW35: أنثى | BX35: 0 | BY35: 0 | BZ35: 0 | CA35: 0 | CE35: أنثى | CF35: 0 | CG35: 0 | CH35: 0 | CI35: 0 | CM35: أنثى | CN35: 0 | CO35: 0 | CP35: 0 | CQ35: 0 | CU35: أنثى | CV35: =SUM(D35+L35+T35+AB35+AJ35+AR35+AZ35+BH35+BP35+BX35+CF35+CN35) -> 0 | CW35: =SUM(E35+M35+U35+AC35+AK35+AS35+BA35+BI35+BQ35+BY35+CG35+CO35) -> 0 | CX35: =SUM(F35+N35+V35+AD35+AL35+AT35+BB35+BJ35+BR35+BZ35+CH35+CP35) -> 0 | CY35: =SUM(G35+O35+W35+AE35+AM35+AU35+BC35+BK35+BS35+CA35+CI35+CQ35) -> 0
B36: مجموع السعوديين | D36: =SUM(D34:D35) -> 0 | E36: =SUM(E34:E35) -> 0 | F36: =SUM(F34:F35) -> 0 | G36: =SUM(G34:G35) -> 0 | J36: مجموع السعوديين | L36: =SUM(L34:L35) -> 0 | M36: =SUM(M34:M35) -> 0 | N36: =SUM(N34:N35) -> 0 | O36: =SUM(O34:O35) -> 0 | R36: مجموع السعوديين | T36: 0 | U36: 0 | V36: 0 | W36: 0 | Z36: مجموع السعوديين | AB36: 0 | AC36: 0 | AD36: 0 | AE36: 0 | AH36: مجموع السعوديين | AJ36: =SUM(AJ34:AJ35) -> 0 | AK36: =SUM(AK34:AK35) -> 0 | AL36: =SUM(AL34:AL35) -> 0 | AM36: =SUM(AM34:AM35) -> 0 | AP36: مجموع السعوديين | AR36: 0 | AS36: 0 | AT36: 0 | AU36: 0 | AX36: مجموع السعوديين | AZ36: 0 | BA36: 0 | BB36: 0 | BC36: 0 | BF36: مجموع السعوديين | BH36: =SUM(BH34:BH35) -> 0 | BI36: =SUM(BI34:BI35) -> 0 | BJ36: =SUM(BJ34:BJ35) -> 0 | BK36: =SUM(BK34:BK35) -> 0 | BN36: مجموع السعوديين | BP36: =SUM(BP34:BP35) -> 0 | BQ36: =SUM(BQ34:BQ35) -> 0 | BR36: =SUM(BR34:BR35) -> 0 | BS36: =SUM(BS34:BS35) -> 0 | BV36: مجموع السعوديين | BX36: 0 | BY36: 9 | BZ36: 10 | CA36: 12 | CD36: مجموع السعوديين | CF36: =SUM(CF34:CF35) -> 0 | CG36: =SUM(CG34:CG35) -> 0 | CH36: =SUM(CH34:CH35) -> 0 | CI36: =SUM(CI34:CI35) -> 0 | CL36: مجموع السعوديين | CN36: =SUM(CN34:CN35) -> 0 | CO36: =SUM(CO34:CO35) -> 0 | CP36: =SUM(CP34:CP35) -> 0 | CQ36: =SUM(CQ34:CQ35) -> 0 | CT36: مجموع السعوديين | CV36: =SUM(CV34:CV35) -> 0 | CW36: =SUM(CW34:CW35) -> 9 | CX36: =SUM(CX34:CX35) -> 10 | CY36: =SUM(CY34:CY35) -> 12
B37: غير سعودي | C37: ذكر | D37: 0 | E37: 0 | F37: 0 | G37: 0 | J37: غير سعودي | K37: ذكر | L37: 0 | M37: 0 | N37: 0 | O37: 0 | R37: غير سعودي | S37: ذكر | T37: 0 | U37: 0 | V37: 0 | W37: 0 | Z37: غير سعودي | AA37: ذكر | AB37: 0 | AC37: 0 | AD37: 0 | AE37: 0 | AH37: غير سعودي | AI37: ذكر | AJ37: 0 | AK37: 0 | AL37: 0 | AM37: 0 | AP37: غير سعودي | AQ37: ذكر | AR37: 0 | AS37: 0 | AT37: 0 | AU37: 0 | AX37: غير سعودي | AY37: ذكر | AZ37: 0 | BA37: 0 | BB37: 0 | BC37: 0 | BF37: غير سعودي | BG37: ذكر | BH37: 0 | BI37: 0 | BJ37: 0 | BK37: 0 | BN37: غير سعودي | BO37: ذكر | BP37: 0 | BQ37: 0 | BR37: 0 | BS37: 0 | BV37: غير سعودي | BW37: ذكر | BX37: 0 | BY37: 0 | BZ37: 0 | CA37: 0 | CD37: غير سعودي | CE37: ذكر | CF37: 0 | CG37: 0 | CH37: 0 | CI37: 0 | CL37: غير سعودي | CM37: ذكر | CN37: 0 | CO37: 0 | CP37: 0 | CQ37: 0 | CT37: غير سعودي | CU37: ذكر | CV37: =SUM(D37+L37+T37+AB37+AJ37+AR37+AZ37+BH37+BP37+BX37+CF37+CN37) -> 0 | CW37: =SUM(E37+M37+U37+AC37+AK37+AS37+BA37+BI37+BQ37+BY37+CG37+CO37) -> 0 | CX37: =SUM(F37+N37+V37+AD37+AL37+AT37+BB37+BJ37+BR37+BZ37+CH37+CP37) -> 0 | CY37: =SUM(G37+O37+W37+AE37+AM37+AU37+BC37+BK37+BS37+CA37+CI37+CQ37) -> 0
C38: أنثى | D38: 0 | E38: 0 | F38: 0 | G38: 0 | K38: أنثى | L38: 0 | M38: 0 | N38: 0 | O38: 0 | S38: أنثى | T38: 0 | U38: 0 | V38: 0 | W38: 0 | AA38: أنثى | AB38: 0 | AC38: 0 | AD38: 0 | AE38: 0 | AI38: أنثى | AJ38: 0 | AK38: 0 | AL38: 0 | AM38: 0 | AQ38: أنثى | AR38: 0 | AS38: 0 | AT38: 0 | AU38: 0 | AY38: أنثى | AZ38: 0 | BA38: 0 | BB38: 0 | BC38: 0 | BG38: أنثى | BH38: 0 | BI38: 0 | BJ38: 0 | BK38: 0 | BO38: أنثى | BP38: 0 | BQ38: 0 | BR38: 0 | BS38: 0 | BW38: أنثى | BX38: 0 | BY38: 0 | BZ38: 3 | CA38: 0 | CE38: أنثى | CF38: 0 | CG38: 0 | CH38: 0 | CI38: 0 | CM38: أنثى | CN38: 0 | CO38: 0 | CP38: 0 | CQ38: 0 | CU38: أنثى | CV38: =SUM(D38+L38+T38+AB38+AJ38+AR38+AZ38+BH38+BP38+BX38+CF38+CN38) -> 0 | CW38: =SUM(E38+M38+U38+AC38+AK38+AS38+BA38+BI38+BQ38+BY38+CG38+CO38) -> 0 | CX38: =SUM(F38+N38+V38+AD38+AL38+AT38+BB38+BJ38+BR38+BZ38+CH38+CP38) -> 3 | CY38: =SUM(G38+O38+W38+AE38+AM38+AU38+BC38+BK38+BS38+CA38+CI38+CQ38) -> 0
B39: مجمع الغير سعوديين | D39: =SUM(D37:D38) -> 0 | E39: =SUM(E37:E38) -> 0 | F39: =SUM(F37:F38) -> 0 | G39: =SUM(G37:G38) -> 0 | J39: مجمع الغير سعوديين | L39: =SUM(L37:L38) -> 0 | M39: =SUM(M37:M38) -> 0 | N39: =SUM(N37:N38) -> 0 | O39: =SUM(O37:O38) -> 0 | R39: مجمع الغير سعوديين | T39: 0 | U39: 0 | V39: 0 | W39: 0 | Z39: مجمع الغير سعوديين | AB39: 0 | AC39: 0 | AD39: 0 | AE39: 0 | AH39: مجمع الغير سعوديين | AJ39: =SUM(AJ37:AJ38) -> 0 | AK39: =SUM(AK37:AK38) -> 0 | AL39: =SUM(AL37:AL38) -> 0 | AM39: =SUM(AM37:AM38) -> 0 | AP39: مجمع الغير سعوديين | AR39: 0 | AS39: 0 | AT39: 0 | AU39: 0 | AX39: مجمع الغير سعوديين | AZ39: 0 | BA39: 0 | BB39: 0 | BC39: 0 | BF39: مجمع الغير سعوديين | BH39: =SUM(BH37:BH38) -> 0 | BI39: =SUM(BI37:BI38) -> 0 | BJ39: =SUM(BJ37:BJ38) -> 0 | BK39: =SUM(BK37:BK38) -> 0 | BN39: مجمع الغير سعوديين | BP39: =SUM(BP37:BP38) -> 0 | BQ39: =SUM(BQ37:BQ38) -> 0 | BR39: =SUM(BR37:BR38) -> 0 | BS39: =SUM(BS37:BS38) -> 0 | BV39: مجمع الغير سعوديين | BX39: 0 | BY39: 0 | BZ39: 3 | CA39: 0 | CD39: مجمع الغير سعوديين | CF39: =SUM(CF37:CF38) -> 0 | CG39: =SUM(CG37:CG38) -> 0 | CH39: =SUM(CH37:CH38) -> 0 | CI39: =SUM(CI37:CI38) -> 0 | CL39: مجمع الغير سعوديين | CN39: =SUM(CN37:CN38) -> 0 | CO39: =SUM(CO37:CO38) -> 0 | CP39: =SUM(CP37:CP38) -> 0 | CQ39: =SUM(CQ37:CQ38) -> 0 | CT39: مجمع الغير سعوديين | CV39: =SUM(CV37:CV38) -> 0 | CW39: =SUM(CW37:CW38) -> 0 | CX39: =SUM(CX37:CX38) -> 3 | CY39: =SUM(CY37:CY38) -> 0
B40: المجموع الكلي | D40: =SUM(D36+D39) -> 0 | E40: =SUM(E36+E39) -> 0 | F40: =SUM(F36+F39) -> 0 | G40: =SUM(G36+G39) -> 0 | J40: المجموع الكلي | L40: =SUM(L36+L39) -> 0 | M40: =SUM(M36+M39) -> 0 | N40: =SUM(N36+N39) -> 0 | O40: =SUM(O36+O39) -> 0 | R40: المجموع الكلي | T40: 0 | U40: 0 | V40: 0 | W40: 0 | Z40: المجموع الكلي | AB40: 0 | AC40: 0 | AD40: 0 | AE40: 0 | AH40: المجموع الكلي | AJ40: =SUM(AJ36+AJ39) -> 0 | AK40: =SUM(AK36+AK39) -> 0 | AL40: =SUM(AL36+AL39) -> 0 | AM40: =SUM(AM36+AM39) -> 0 | AP40: المجموع الكلي | AR40: 0 | AS40: 0 | AT40: 0 | AU40: 0 | AX40: المجموع الكلي | AZ40: 0 | BA40: 0 | BB40: 0 | BC40: 0 | BF40: المجموع الكلي | BH40: =SUM(BH36+BH39) -> 0 | BI40: =SUM(BI36+BI39) -> 0 | BJ40: =SUM(BJ36+BJ39) -> 0 | BK40: =SUM(BK36+BK39) -> 0 | BN40: المجموع الكلي | BP40: =SUM(BP36+BP39) -> 0 | BQ40: =SUM(BQ36+BQ39) -> 0 | BR40: =SUM(BR36+BR39) -> 0 | BS40: =SUM(BS36+BS39) -> 0 | BV40: المجموع الكلي | BX40: =SUM(BX36+BX39) -> 0 | BY40: =SUM(BY36+BY39) -> 9 | BZ40: =SUM(BZ36+BZ39) -> 13 | CA40: =SUM(CA36+CA39) -> 12 | CD40: المجموع الكلي | CF40: =SUM(CF36+CF39) -> 0 | CG40: =SUM(CG36+CG39) -> 0 | CH40: =SUM(CH36+CH39) -> 0 | CI40: =SUM(CI36+CI39) -> 0 | CL40: المجموع الكلي | CN40: =SUM(CN36+CN39) -> 0 | CO40: =SUM(CO36+CO39) -> 0 | CP40: =SUM(CP36+CP39) -> 0 | CQ40: =SUM(CQ36+CQ39) -> 0 | CT40: المجموع الكلي | CV40: =SUM(CV36+CV39) -> 0 | CW40: =SUM(CW36+CW39) -> 9 | CX40: =SUM(CX36+CX39) -> 13 | CY40: =SUM(CY36+CY39) -> 12
A41: قويزة | B41: سعودي | C41: ذكر | D41: 0 | E41: 17 | F41: 9 | G41: 10 | I41: قويزة | J41: سعودي | K41: ذكر | L41: 0 | M41: 49 | N41: 29 | O41: 13 | Q41: قويزة | R41: سعودي | S41: ذكر | T41: 0 | U41: 70 | V41: 62 | W41: 28 | Y41: قويزة | Z41: سعودي | AA41: ذكر | AB41: 0 | AC41: 61 | AD41: 49 | AE41: 40 | AG41: قويزة | AH41: سعودي | AI41: ذكر | AJ41: 0 | AK41: 35 | AL41: 40 | AM41: 35 | AO41: قويزة | AP41: سعودي | AQ41: ذكر | AR41: 0 | AS41: 45 | AT41: 25 | AU41: 16 | AW41: قويزة | AX41: سعودي | AY41: ذكر | AZ41: 0 | BA41: 18 | BB41: 10 | BC41: 12 | BE41: قويزة | BF41: سعودي | BG41: ذكر | BH41: 0 | BI41: 45 | BJ41: 25 | BK41: 16 | BM41: قويزة | BN41: سعودي | BO41: ذكر | BP41: 0 | BQ41: 25 | BR41: 20 | BS41: 22 | BU41: قويزة | BV41: سعودي | BW41: ذكر | BX41: 0 | BY41: 17 | BZ41: 9 | CA41: 10 | CC41: قويزة | CD41: سعودي | CE41: ذكر | CF41: 0 | CG41: 0 | CH41: 0 | CI41: 0 | CK41: قويزة | CL41: سعودي | CM41: ذكر | CN41: 0 | CO41: 0 | CP41: 0 | CQ41: 0 | CS41: =(CK41) -> قويزة | CT41: سعودي | CU41: ذكر | CV41: =SUM(D41+L41+T41+AB41+AJ41+AR41+AZ41+BH41+BP41+BX41+CF41+CN41) -> 0 | CW41: =SUM(E41+M41+U41+AC41+AK41+AS41+BA41+BI41+BQ41+BY41+CG41+CO41) -> 382 | CX41: =SUM(F41+N41+V41+AD41+AL41+AT41+BB41+BJ41+BR41+BZ41+CH41+CP41) -> 278 | CY41: =SUM(G41+O41+W41+AE41+AM41+AU41+BC41+BK41+BS41+CA41+CI41+CQ41) -> 202
...

Sheet إجمالي
A2: 14ـ الجراحات الصغرى والغيارات والحقن | I2: 14ـ الجراحات الصغرى والغيارات والحقن | Q2: 14ـ الجراحات الصغرى والغيارات والحقن | Y2: 14ـ الجراحات الصغرى والغيارات والحقن | AG2: 14ـ الجراحات الصغرى والغيارات والحقن | AO2: 14ـ الجراحات الصغرى والغيارات والحقن | AW2: 14ـ الجراحات الصغرى والغيارات والحقن | BE2: 14ـ الجراحات الصغرى والغيارات والحقن | BM2: 14ـ الجراحات الصغرى والغيارات والحقن | BU2: 14ـ الجراحات الصغرى والغيارات والحقن | CC2: 14ـ الجراحات الصغرى والغيارات والحقن | CK2: 14ـ الجراحات الصغرى والغيارات والحقن | CS2: 14ـ الجراحات الصغرى والغيارات والحقن
C3: شهر | D3: 1 | E3: عام | F3: =SUM(ضماد!F3) -> 1447 | G3: هـ | K3: شهر | L3: 2 | M3: عام | N3: =SUM(ضماد!N3) -> 1447 | O3: هـ | S3: شهر | T3: 3 | U3: عام | V3: =SUM(ضماد!V3) -> 1447 | W3: هـ | AA3: شهر | AB3: 4 | AC3: عام | AD3: =SUM(ضماد!AD3) -> 1447 | AE3: هـ | AI3: شهر | AJ3: 5 | AK3: عام | AL3: =SUM(ضماد!AL3) -> 1447 | AM3: هـ | AQ3: شهر | AR3: 6 | AS3: عام | AT3: =SUM(ضماد!AT3) -> 1447 | AU3: هـ | AY3: شهر | AZ3: 7 | BA3: عام | BB3: =SUM(ضماد!BB3) -> 1447 | BC3: هـ | BG3: شهر | BH3: 8 | BI3: عام | BJ3: =SUM(ضماد!BJ3) -> 1447 | BK3: هـ | BO3: شهر | BP3: 9 | BQ3: عام | BR3: =SUM(ضماد!BR3) -> 1447 | BS3: هـ | BW3: شهر | BX3: 10 | BY3: عام | BZ3: =SUM(ضماد!BZ3) -> 1447 | CA3: هـ | CE3: شهر | CF3: 11 | CG3: عام | CH3: =SUM(ضماد!CH3) -> 1447 | CI3: هـ | CM3: شهر | CN3: 12 | CO3: عام | CP3: =SUM(ضماد!CP3) -> 1447 | CQ3: هـ | CW3: عام | CX3: =SUM(CP3) -> 1447 | CY3: هـ
A4: المركز الصحي | B4: الخدمة | D4: جراحات صغرى | E4: غيارات | F4: حقن | G4: أكسجين | I4: المركز الصحي | J4: الخدمة | L4: جراحات صغرى | M4: غيارات | N4: حقن | O4: أكسجين | Q4: المركز الصحي | R4: الخدمة | T4: جراحات صغرى | U4: غيارات | V4: حقن | W4: أكسجين | Y4: المركز الصحي | Z4: الخدمة | AB4: جراحات صغرى | AC4: غيارات | AD4: حقن | AE4: أكسجين | AG4: المركز الصحي | AH4: الخدمة | AJ4: جراحات صغرى | AK4: غيارات | AL4: حقن | AM4: أكسجين | AO4: المركز الصحي | AP4: الخدمة | AR4: جراحات صغرى | AS4: غيارات | AT4: حقن | AU4: أكسجين | AW4: المركز الصحي | AX4: الخدمة | AZ4: جراحات صغرى | BA4: غيارات | BB4: حقن | BC4: أكسجين | BE4: المركز الصحي | BF4: الخدمة | BH4: جراحات صغرى | BI4: غيارات | BJ4: حقن | BK4: أكسجين | BM4: المركز الصحي | BN4: الخدمة | BP4: جراحات صغرى | BQ4: غيارات | BR4: حقن | BS4: أكسجين | BU4: المركز الصحي | BV4: الخدمة | BX4: جراحات صغرى | BY4: غيارات | BZ4: حقن | CA4: أكسجين | CC4: المركز الصحي | CD4: الخدمة | CF4: جراحات صغرى | CG4: غيارات | CH4: حقن | CI4: أكسجين | CK4: المركز الصحي | CL4: الخدمة | CN4: جراحات صغرى | CO4: غيارات | CP4: حقن | CQ4: أكسجين | CS4: المركز الصحي | CT4: الخدمة | CV4: جراحات صغرى | CW4: غيارات | CX4: حقن | CY4: أكسجين
B5: الجنس والجنسية | J5: الجنس والجنسية | R5: الجنس والجنسية | Z5: الجنس والجنسية | AH5: الجنس والجنسية | AP5: الجنس والجنسية | AX5: الجنس والجنسية | BF5: الجنس والجنسية | BN5: الجنس والجنسية | BV5: الجنس والجنسية | CD5: الجنس والجنسية | CL5: الجنس والجنسية | CT5: الجنس والجنسية
A6: إجمالي مراكز مستشفى شرق جدة | B6: سعودي | C6: ذكر | D6: =SUM(ضماد!D95) -> 0 | E6: =SUM(ضماد!E95) -> 525 | F6: =SUM(ضماد!F95) -> 724 | G6: =SUM(ضماد!G95) -> 676 | I6: إجمالي مراكز مستشفى شرق جدة | J6: سعودي | K6: ذكر | L6: =SUM(ضماد!L95) -> 0 | M6: =SUM(ضماد!M95) -> 569 | N6: =SUM(ضماد!N95) -> 540 | O6: =SUM(ضماد!O95) -> 587 | Q6: إجمالي مراكز مستشفى شرق جدة | R6: سعودي | S6: ذكر | T6: =SUM(ضماد!T95) -> 14 | U6: =SUM(ضماد!U95) -> 533 | V6: =SUM(ضماد!V95) -> 666 | W6: =SUM(ضماد!W95) -> 597 | Y6: إجمالي مراكز مستشفى شرق جدة | Z6: سعودي | AA6: ذكر | AB6: =SUM(ضماد!AB95) -> 3 | AC6: =SUM(ضماد!AC95) -> 303 | AD6: =SUM(ضماد!AD95) -> 509 | AE6: =SUM(ضماد!AE95) -> 385 | AG6: إجمالي مراكز مستشفى شرق جدة | AH6: سعودي | AI6: ذكر | AJ6: =SUM(ضماد!AJ95) -> 6 | AK6: =SUM(ضماد!AK95) -> 466 | AL6: =SUM(ضماد!AL95) -> 616 | AM6: =SUM(ضماد!AM95) -> 686 | AO6: إجمالي مراكز مستشفى شرق جدة | AP6: سعودي | AQ6: ذكر | AR6: =SUM(ضماد!AR95) -> 2 | AS6: =SUM(ضماد!AS95) -> 523 | AT6: =SUM(ضماد!AT95) -> 805 | AU6: =SUM(ضماد!AU95) -> 847 | AW6: إجمالي مراكز مستشفى شرق جدة | AX6: سعودي | AY6: ذكر | AZ6: =SUM(ضماد!AZ95) -> 194 | BA6: =SUM(ضماد!BA95) -> 473 | BB6: =SUM(ضماد!BB95) -> 760 | BC6: =SUM(ضماد!BC95) -> 903 | BE6: إجمالي مراكز مستشفى شرق جدة | BF6: سعودي | BG6: ذكر | BH6: =SUM(ضماد!BH95) -> 2 | BI6: =SUM(ضماد!BI95) -> 523 | BJ6: =SUM(ضماد!BJ95) -> 787 | BK6: =SUM(ضماد!BK95) -> 855 | BM6: إجمالي مراكز مستشفى شرق جدة | BN6: سعودي | BO6: ذكر | BP6: =SUM(ضماد!BP95) -> 27 | BQ6: =SUM(ضماد!BQ95) -> 346 | BR6: =SUM(ضماد!BR95) -> 321 | BS6: =SUM(ضماد!BS95) -> 465 | BU6: إجمالي مراكز مستشفى شرق جدة | BV6: سعودي | BW6: ذكر | BX6: =SUM(ضماد!BX95) -> 0 | BY6: =SUM(ضماد!BY95) -> 524 | BZ6: =SUM(ضماد!BZ95) -> 723 | CA6: =SUM(ضماد!CA95) -> 677 | CC6: إجمالي مراكز مستشفى شرق جدة | CD6: سعودي | CE6: ذكر | CF6: =SUM(ضماد!CF95) -> 0 | CG6: =SUM(ضماد!CG95) -> 0 | CH6: =SUM(ضماد!CH95) -> 0 | CI6: =SUM(ضماد!CI95) -> 0 | CK6: إجمالي مراكز مستشفى شرق جدة | CL6: سعودي | CM6: ذكر | CN6: =SUM(ضماد!CN95) -> 0 | CO6: =SUM(ضماد!CO95) -> 0 | CP6: =SUM(ضماد!CP95) -> 0 | CQ6: =SUM(ضماد!CQ95) -> 0 | CS6: إجمالي مراكز مستشفى شرق جدة | CT6: سعودي | CU6: ذكر | CV6: =SUM(ضماد!CV95) -> 248 | CW6: =SUM(ضماد!CW95) -> 4785 | CX6: =SUM(ضماد!CX95) -> 6451 | CY6: =SUM(ضماد!CY95) -> 6678
C7: أنثى | D7: =SUM(ضماد!D96) -> 0 | E7: =SUM(ضماد!E96) -> 394 | F7: =SUM(ضماد!F96) -> 662 | G7: =SUM(ضماد!G96) -> 589 | K7: أنثى | L7: =SUM(ضماد!L96) -> 0 | M7: =SUM(ضماد!M96) -> 508 | N7: =SUM(ضماد!N96) -> 519 | O7: =SUM(ضماد!O96) -> 683 | S7: أنثى | T7: =SUM(ضماد!T96) -> 14 | U7: =SUM(ضماد!U96) -> 429 | V7: =SUM(ضماد!V96) -> 641 | W7: =SUM(ضماد!W96) -> 407 | AA7: أنثى | AB7: =SUM(ضماد!AB96) -> 2 | AC7: =SUM(ضماد!AC96) -> 272 | AD7: =SUM(ضماد!AD96) -> 457 | AE7: =SUM(ضماد!AE96) -> 389 | AI7: أنثى | AJ7: =SUM(ضماد!AJ96) -> 3 | AK7: =SUM(ضماد!AK96) -> 402 | AL7: =SUM(ضماد!AL96) -> 605 | AM7: =SUM(ضماد!AM96) -> 669 | AQ7: أنثى | AR7: =SUM(ضماد!AR96) -> 1 | AS7: =SUM(ضماد!AS96) -> 497 | AT7: =SUM(ضماد!AT96) -> 726 | AU7: =SUM(ضماد!AU96) -> 765 | AY7: أنثى | AZ7: =SUM(ضماد!AZ96) -> 49 | BA7: =SUM(ضماد!BA96) -> 381 | BB7: =SUM(ضماد!BB96) -> 630 | BC7: =SUM(ضماد!BC96) -> 816 | BG7: أنثى | BH7: =SUM(ضماد!BH96) -> 1 | BI7: =SUM(ضماد!BI96) -> 492 | BJ7: =SUM(ضماد!BJ96) -> 705 | BK7: =SUM(ضماد!BK96) -> 747 | BO7: أنثى | BP7: =SUM(ضماد!BP96) -> 35 | BQ7: =SUM(ضماد!BQ96) -> 306 | BR7: =SUM(ضماد!BR96) -> 275 | BS7: =SUM(ضماد!BS96) -> 403 | BW7: أنثى | BX7: =SUM(ضماد!BX96) -> 4 | BY7: =SUM(ضماد!BY96) -> 393 | BZ7: =SUM(ضماد!BZ96) -> 656 | CA7: =SUM(ضماد!CA96) -> 588 | CE7: أنثى | CF7: =SUM(ضماد!CF96) -> 0 | CG7: =SUM(ضماد!CG96) -> 0 | CH7: =SUM(ضماد!CH96) -> 0 | CI7: =SUM(ضماد!CI96) -> 0 | CM7: أنثى | CN7: =SUM(ضماد!CN96) -> 0 | CO7: =SUM(ضماد!CO96) -> 0 | CP7: =SUM(ضماد!CP96) -> 0 | CQ7: =SUM(ضماد!CQ96) -> 0 | CU7: أنثى | CV7: =SUM(ضماد!CV96) -> 109 | CW7: =SUM(ضماد!CW96) -> 4074 | CX7: =SUM(ضماد!CX96) -> 5876 | CY7: =SUM(ضماد!CY96) -> 6056
B8: مجموع السعوديين | D8: =SUM(D6:D7) -> 0 | E8: =SUM(E6:E7) -> 919 | F8: =SUM(F6:F7) -> 1386 | G8: =SUM(G6:G7) -> 1265 | J8: مجموع السعوديين | L8: =SUM(L6:L7) -> 0 | M8: =SUM(M6:M7) -> 1077 | N8: =SUM(N6:N7) -> 1059 | O8: =SUM(O6:O7) -> 1270 | R8: مجموع السعوديين | T8: =SUM(T6:T7) -> 28 | U8: =SUM(U6:U7) -> 962 | V8: =SUM(V6:V7) -> 1307 | W8: =SUM(W6:W7) -> 1004 | Z8: مجموع السعوديين | AB8: =SUM(AB6:AB7) -> 5 | AC8: =SUM(AC6:AC7) -> 575 | AD8: =SUM(AD6:AD7) -> 966 | AE8: =SUM(AE6:AE7) -> 774 | AH8: مجموع السعوديين | AJ8: =SUM(AJ6:AJ7) -> 9 | AK8: =SUM(AK6:AK7) -> 868 | AL8: =SUM(AL6:AL7) -> 1221 | AM8: =SUM(AM6:AM7) -> 1355 | AP8: مجموع السعوديين | AR8: =SUM(AR6:AR7) -> 3 | AS8: =SUM(AS6:AS7) -> 1020 | AT8: =SUM(AT6:AT7) -> 1531 | AU8: =SUM(AU6:AU7) -> 1612 | AX8: مجموع السعوديين | AZ8: =SUM(AZ6:AZ7) -> 243 | BA8: =SUM(BA6:BA7) -> 854 | BB8: =SUM(BB6:BB7) -> 1390 | BC8: =SUM(BC6:BC7) -> 1719 | BF8: مجموع السعوديين | BH8: =SUM(BH6:BH7) -> 3 | BI8: =SUM(BI6:BI7) -> 1015 | BJ8: =SUM(BJ6:BJ7) -> 1492 | BK8: =SUM(BK6:BK7) -> 1602 | BN8: مجموع السعوديين | BP8: =SUM(BP6:BP7) -> 62 | BQ8: =SUM(BQ6:BQ7) -> 652 | BR8: =SUM(BR6:BR7) -> 596 | BS8: =SUM(BS6:BS7) -> 868 | BV8: مجموع السعوديين | BX8: =SUM(BX6:BX7) -> 4 | BY8: =SUM(BY6:BY7) -> 917 | BZ8: =SUM(BZ6:BZ7) -> 1379 | CA8: =SUM(CA6:CA7) -> 1265 | CD8: مجموع السعوديين | CF8: =SUM(CF6:CF7) -> 0 | CG8: =SUM(CG6:CG7) -> 0 | CH8: =SUM(CH6:CH7) -> 0 | CI8: =SUM(CI6:CI7) -> 0 | CL8: مجموع السعوديين | CN8: =SUM(CN6:CN7) -> 0 | CO8: =SUM(CO6:CO7) -> 0 | CP8: =SUM(CP6:CP7) -> 0 | CQ8: =SUM(CQ6:CQ7) -> 0 | CT8: مجموع السعوديين | CV8: =SUM(CV6:CV7) -> 357 | CW8: =SUM(CW6:CW7) -> 8859 | CX8: =SUM(CX6:CX7) -> 12327 | CY8: =SUM(CY6:CY7) -> 12734
B9: غير سعودي | C9: ذكر | D9: =SUM(ضماد!D98) -> 0 | E9: =SUM(ضماد!E98) -> 104 | F9: =SUM(ضماد!F98) -> 187 | G9: =SUM(ضماد!G98) -> 153 | J9: غير سعودي | K9: ذكر | L9: =SUM(ضماد!L98) -> 0 | M9: =SUM(ضماد!M98) -> 153 | N9: =SUM(ضماد!N98) -> 178 | O9: =SUM(ضماد!O98) -> 144 | R9: غير سعودي | S9: ذكر | T9: =SUM(ضماد!T98) -> 0 | U9: =SUM(ضماد!U98) -> 59 | V9: =SUM(ضماد!V98) -> 109 | W9: =SUM(ضماد!W98) -> 54 | Z9: غير سعودي | AA9: ذكر | AB9: =SUM(ضماد!AB98) -> 0 | AC9: =SUM(ضماد!AC98) -> 53 | AD9: =SUM(ضماد!AD98) -> 68 | AE9: =SUM(ضماد!AE98) -> 79 | AH9: غير سعودي | AI9: ذكر | AJ9: =SUM(ضماد!AJ98) -> 0 | AK9: =SUM(ضماد!AK98) -> 90 | AL9: =SUM(ضماد!AL98) -> 56 | AM9: =SUM(ضماد!AM98) -> 45 | AP9: غير سعودي | AQ9: ذكر | AR9: =SUM(ضماد!AR98) -> 0 | AS9: =SUM(ضماد!AS98) -> 244 | AT9: =SUM(ضماد!AT98) -> 267 | AU9: =SUM(ضماد!AU98) -> 193 | AX9: غير سعودي | AY9: ذكر | AZ9: =SUM(ضماد!AZ98) -> 16 | BA9: =SUM(ضماد!BA98) -> 98 | BB9: =SUM(ضماد!BB98) -> 173 | BC9: =SUM(ضماد!BC98) -> 188 | BF9: غير سعودي | BG9: ذكر | BH9: =SUM(ضماد!BH98) -> 0 | BI9: =SUM(ضماد!BI98) -> 242 | BJ9: =SUM(ضماد!BJ98) -> 261 | BK9: =SUM(ضماد!BK98) -> 195 | BN9: غير سعودي | BO9: ذكر | BP9: =SUM(ضماد!BP98) -> 0 | BQ9: =SUM(ضماد!BQ98) -> 126 | BR9: =SUM(ضماد!BR98) -> 97 | BS9: =SUM(ضماد!BS98) -> 66 | BV9: غير سعودي | BW9: ذكر | BX9: =SUM(ضماد!BX98) -> 1 | BY9: =SUM(ضماد!BY98) -> 110 | BZ9: =SUM(ضماد!BZ98) -> 194 | CA9: =SUM(ضماد!CA98) -> 156 | CD9: غير سعودي | CE9: ذكر | CF9: =SUM(ضماد!CF98) -> 0 | CG9: =SUM(ضماد!CG98) -> 0 | CH9: =SUM(ضماد!CH98) -> 0 | CI9: =SUM(ضماد!CI98) -> 0 | CL9: غير سعودي | CM9: ذكر | CN9: =SUM(ضماد!CN98) -> 0 | CO9: =SUM(ضماد!CO98) -> 0 | CP9: =SUM(ضماد!CP98) -> 0 | CQ9: =SUM(ضماد!CQ98) -> 0 | CT9: غير سعودي | CU9: ذكر | CV9: =SUM(ضماد!CV98) -> 17 | CW9: =SUM(ضماد!CW98) -> 1279 | CX9: =SUM(ضماد!CX98) -> 1590 | CY9: =SUM(ضماد!CY98) -> 1273
C10: أنثى | D10: =SUM(ضماد!D99) -> 0 | E10: =SUM(ضماد!E99) -> 93 | F10: =SUM(ضماد!F99) -> 121 | G10: =SUM(ضماد!G99) -> 137 | K10: أنثى | L10: =SUM(ضماد!L99) -> 0 | M10: =SUM(ضماد!M99) -> 115 | N10: =SUM(ضماد!N99) -> 126 | O10: =SUM(ضماد!O99) -> 115 | S10: أنثى | T10: =SUM(ضماد!T99) -> 0 | U10: =SUM(ضماد!U99) -> 35 | V10: =SUM(ضماد!V99) -> 82 | W10: =SUM(ضماد!W99) -> 36 | AA10: أنثى | AB10: =SUM(ضماد!AB99) -> 0 | AC10: =SUM(ضماد!AC99) -> 58 | AD10: =SUM(ضماد!AD99) -> 75 | AE10: =SUM(ضماد!AE99) -> 69 | AI10: أنثى | AJ10: =SUM(ضماد!AJ99) -> 0 | AK10: =SUM(ضماد!AK99) -> 74 | AL10: =SUM(ضماد!AL99) -> 57 | AM10: =SUM(ضماد!AM99) -> 45 | AQ10: أنثى | AR10: =SUM(ضماد!AR99) -> 0 | AS10: =SUM(ضماد!AS99) -> 175 | AT10: =SUM(ضماد!AT99) -> 165 | AU10: =SUM(ضماد!AU99) -> 199 | AY10: أنثى | AZ10: =SUM(ضماد!AZ99) -> 6 | BA10: =SUM(ضماد!BA99) -> 50 | BB10: =SUM(ضماد!BB99) -> 100 | BC10: =SUM(ضماد!BC99) -> 159 | BG10: أنثى | BH10: =SUM(ضماد!BH99) -> 0 | BI10: =SUM(ضماد!BI99) -> 175 | BJ10: =SUM(ضماد!BJ99) -> 165 | BK10: =SUM(ضماد!BK99) -> 199 | BO10: أنثى | BP10: =SUM(ضماد!BP99) -> 0 | BQ10: =SUM(ضماد!BQ99) -> 120 | BR10: =SUM(ضماد!BR99) -> 89 | BS10: =SUM(ضماد!BS99) -> 112 | BW10: أنثى | BX10: =SUM(ضماد!BX99) -> 0 | BY10: =SUM(ضماد!BY99) -> 93 | BZ10: =SUM(ضماد!BZ99) -> 129 | CA10: =SUM(ضماد!CA99) -> 138 | CE10: أنثى | CF10: =SUM(ضماد!CF99) -> 0 | CG10: =SUM(ضماد!CG99) -> 0 | CH10: =SUM(ضماد!CH99) -> 0 | CI10: =SUM(ضماد!CI99) -> 0 | CM10: أنثى | CN10: =SUM(ضماد!CN99) -> 0 | CO10: =SUM(ضماد!CO99) -> 0 | CP10: =SUM(ضماد!CP99) -> 0 | CQ10: =SUM(ضماد!CQ99) -> 0 | CU10: أنثى | CV10: =SUM(ضماد!CV99) -> 6 | CW10: =SUM(ضماد!CW99) -> 988 | CX10: =SUM(ضماد!CX99) -> 1109 | CY10: =SUM(ضماد!CY99) -> 1209
