Workbook

Sheet سكان وأسر
A2: مراكز شرق جدة | D2: شهر | E2: 1 | F2: 1447 | G2: بيان عدد السكان والأسر المشمولين بالخدمة من واقع الملفات الصحية | M2: مراكز شرق جدة | P2: شهر | Q2: 2 | R2: 1447 | S2: بيان عدد السكان والأسر المشمولين بالخدمة من واقع الملفات الصحية | Y2: مراكز شرق جدة | AB2: شهر | AC2: 3 | AD2: 1447 | AE2: بيان عدد السكان والأسر المشمولين بالخدمة من واقع الملفات الصحية | AK2: مراكز شرق جدة | AN2: شهر | AO2: 4 | AP2: 1447 | AQ2: بيان عدد السكان والأسر المشمولين بالخدمة من واقع الملفات الصحية | AW2: مراكز شرق جدة | AZ2: شهر | BA2: 5 | BB2: 1447 | BC2: بيان عدد السكان والأسر المشمولين بالخدمة من واقع الملفات الصحية | BI2: مراكز شرق جدة | BL2: شهر | BM2: 6 | BN2: 1447 | BO2: بيان عدد السكان والأسر المشمولين بالخدمة من واقع الملفات الصحية | BU2: مراكز شرق جدة | BX2: شهر | BY2: 7 | BZ2: 1447 | CA2: بيان عدد السكان والأسر المشمولين بالخدمة من واقع الملفات الصحية | CG2: مراكز شرق جدة | CJ2: شهر | CK2: 8 | CL2: 1447 | CM2: بيان عدد السكان والأسر المشمولين بالخدمة من واقع الملفات الصحية | CS2: مراكز شرق جدة | CV2: شهر | CW2: 9 | CX2: 1447 | CY2: بيان عدد السكان والأسر المشمولين بالخدمة من واقع الملفات الصحية | DE2: مراكز شرق جدة | DH2: شهر | DI2: 10 | DJ2: 1447 | DK2: بيان عدد السكان والأسر المشمولين بالخدمة من واقع الملفات الصحية | DQ2: مراكز شرق جدة | DT2: شهر | DU2: 11 | DV2: 1447 | DW2: بيان عدد السكان والأسر المشمولين بالخدمة من واقع الملفات الصحية | EC2: مراكز شرق جدة | EF2: شهر | EG2: 12 | EH2: 1447 | EI2: بيان عدد السكان والأسر المشمولين بالخدمة من واقع الملفات الصحية | EO2: مراكز شرق جدة | ES2: عام | ET2: =SUM(EH2) -> 1447 | EY2: بيان عدد السكان والأسر المشمولين بالخدمة من واقع الملفات الصحية
A3: مراكز | D3: الفئات العمرية | J3: الإجمالي | K3: عدد الأسر | M3: مراكز | P3: الفئات العمرية | V3: الإجمالي | W3: عدد الأسر | Y3: مراكز | AB3: الفئات العمرية | AH3: الإجمالي | AI3: عدد الأسر | AK3: مراكز | AN3: الفئات العمرية | AT3: الإجمالي | AU3: عدد الأسر | AW3: مراكز | AZ3: الفئات العمرية | BF3: الإجمالي | BG3: عدد الأسر | BI3: مراكز | BL3: الفئات العمرية | BR3: الإجمالي | BS3: عدد الأسر | BU3: مراكز | BX3: الفئات العمرية | CD3: الإجمالي | CE3: عدد الأسر | CG3: مراكز | CJ3: الفئات العمرية | CP3: الإجمالي | CQ3: عدد الأسر | CS3: مراكز | CV3: الفئات العمرية | DB3: الإجمالي | DC3: عدد الأسر | DE3: مراكز | DH3: الفئات العمرية | DN3: الإجمالي | DO3: عدد الأسر | DQ3: مراكز | DT3: الفئات العمرية | DZ3: الإجمالي | EA3: عدد الأسر | EC3: مراكز | EF3: الفئات العمرية | EL3: الإجمالي | EM3: عدد الأسر | EO3: مراكز | ER3: الفئات العمرية | EX3: الإجمالي | EY3: عدد الأسر
D4: أقل من سنة | E4: من 4:1 | F4: من14:5 | G4: من44:15 | H4: من60:45 | I4: أكثر من 60 | P4: أقل من سنة | Q4: من 4:1 | R4: من14:5 | S4: من44:15 | T4: من60:45 | U4: أكثر من 60 | AB4: أقل من سنة | AC4: من 4:1 | AD4: من14:5 | AE4: من44:15 | AF4: من60:45 | AG4: أكثر من 60 | AN4: أقل من سنة | AO4: من 4:1 | AP4: من14:5 | AQ4: من44:15 | AR4: من60:45 | AS4: أكثر من 60 | AZ4: أقل من سنة | BA4: من 4:1 | BB4: من14:5 | BC4: من44:15 | BD4: من60:45 | BE4: أكثر من 60 | BL4: أقل من سنة | BM4: من 4:1 | BN4: من14:5 | BO4: من44:15 | BP4: من60:45 | BQ4: أكثر من 60 | BX4: أقل من سنة | BY4: من 4:1 | BZ4: من14:5 | CA4: من44:15 | CB4: من60:45 | CC4: أكثر من 60 | CJ4: أقل من سنة | CK4: من 4:1 | CL4: من14:5 | CM4: من44:15 | CN4: من60:45 | CO4: أكثر من 60 | CV4: أقل من سنة | CW4: من 4:1 | CX4: من14:5 | CY4: من44:15 | CZ4: من60:45 | DA4: أكثر من 60 | DH4: أقل من سنة | DI4: من 4:1 | DJ4: من14:5 | DK4: من44:15 | DL4: من60:45 | DM4: أكثر من 60 | DT4: أقل من سنة | DU4: من 4:1 | DV4: من14:5 | DW4: من44:15 | DX4: من60:45 | DY4: أكثر من 60 | EF4: أقل من سنة | EG4: من 4:1 | EH4: من14:5 | EI4: من44:15 | EJ4: من60:45 | EK4: أكثر من 60 | ER4: أقل من سنة | ES4: من 5:1 | ET4: من14:5 | EU4: من44:15 | EV4: من60:45 | EW4: أكثر من 60
A5: الربيع والتوفيق | B5: سعودي | C5: ذكر | D5: 1422 | E5: 1866 | F5: 3398 | G5: 8608 | H5: 1709 | I5: 698 | J5: =SUM(D5:I5) -> 17701 | K5: 5381 | M5: الربيع والتوفيق | N5: سعودي | O5: ذكر | P5: 1422 | Q5: 1866 | R5: 3398 | S5: 8608 | T5: 1709 | U5: 698 | V5: =SUM(P5:U5) -> 17701 | W5: 5381 | Y5: الربيع والتوفيق | Z5: سعودي | AA5: ذكر | AB5: 1422 | AC5: 1866 | AD5: 3398 | AE5: 8608 | AF5: 1709 | AG5: 698 | AH5: =SUM(AB5:AG5) -> 17701 | AI5: 5381 | AK5: الربيع والتوفيق | AL5: سعودي | AM5: ذكر | AN5: 1422 | AO5: 1866 | AP5: 3398 | AQ5: 8608 | AR5: 1709 | AS5: 698 | AT5: =SUM(AN5:AS5) -> 17701 | AU5: 5381 | AW5: الربيع والتوفيق | AX5: سعودي | AY5: ذكر | AZ5: 1422 | BA5: 1866 | BB5: 3398 | BC5: 8608 | BD5: 1709 | BE5: 698 | BF5: =SUM(AZ5:BE5) -> 17701 | BG5: 5381 | BI5: الربيع والتوفيق | BJ5: سعودي | BK5: ذكر | BL5: 1422 | BM5: 1866 | BN5: 3398 | BO5: 8608 | BP5: 1709 | BQ5: 698 | BR5: =SUM(BL5:BQ5) -> 17701 | BS5: 5381 | BU5: الربيع والتوفيق | BV5: سعودي | BW5: ذكر | BX5: 1422 | BY5: 1866 | BZ5: 3398 | CA5: 8608 | CB5: 1709 | CC5: 698 | CD5: =SUM(BX5:CC5) -> 17701 | CE5: 5381 | CG5: الربيع والتوفيق | CH5: سعودي | CI5: ذكر | CJ5: 1422 | CK5: 1866 | CL5: 3398 | CM5: 8608 | CN5: 1709 | CO5: 698 | CP5: =SUM(CJ5:CO5) -> 17701 | CQ5: 5381 | CS5: الربيع والتوفيق | CT5: سعودي | CU5: ذكر | CV5: 1422 | CW5: 1866 | CX5: 3398 | CY5: 8608 | CZ5: 1709 | DA5: 698 | DB5: =SUM(CV5:DA5) -> 17701 | DC5: 5381 | DE5: الربيع والتوفيق | DF5: سعودي | DG5: ذكر | DH5: 0 | DI5: 0 | DJ5: 0 | DK5: 0 | DL5: 0 | DM5: 0 | DN5: =SUM(DH5:DM5) -> 0 | DO5: 0 | DQ5: الربيع والتوفيق | DR5: سعودي | DS5: ذكر | DT5: 0 | DU5: 0 | DV5: 0 | DW5: 0 | DX5: 0 | DY5: 0 | DZ5: =SUM(DT5:DY5) -> 0 | EA5: 0 | EC5: الربيع والتوفيق | ED5: سعودي | EE5: ذكر | EF5: 0 | EG5: 0 | EH5: 0 | EI5: 0 | EJ5: 0 | EK5: 0 | EL5: =SUM(EF5:EK5) -> 0 | EM5: 0 | EO5: =EC5 -> الربيع والتوفيق | EP5: سعودي | EQ5: ذكر | ER5: =SUM(EF5) -> 0 | ES5: =SUM(EG5) -> 0 | ET5: =SUM(EH5) -> 0 | EU5: =SUM(EI5) -> 0 | EV5: =SUM(EJ5) -> 0 | EW5: =SUM(EK5) -> 0 | EX5: =SUM(ER5:EW5) -> 0 | EY5: =SUM(EM5) -> 0
C6: أنثى | D6: 988 | E6: 11765 | F6: 3466 | G6: 8790 | H6: 1278 | I6: 576 | J6: =SUM(D6:I6) -> 26863 | O6: أنثى | P6: 988 | Q6: 11765 | R6: 3466 | S6: 8790 | T6: 1278 | U6: 576 | V6: =SUM(P6:U6) -> 26863 | AA6: أنثى | AB6: 988 | AC6: 11765 | AD6: 3466 | AE6: 8790 | AF6: 1278 | AG6: 576 | AH6: =SUM(AB6:AG6) -> 26863 | AM6: أنثى | AN6: 988 | AO6: 11765 | AP6: 3466 | AQ6: 8790 | AR6: 1278 | AS6: 576 | AT6: =SUM(AN6:AS6) -> 26863 | AY6: أنثى | AZ6: 988 | BA6: 11765 | BB6: 3466 | BC6: 8790 | BD6: 1278 | BE6: 576 | BF6: =SUM(AZ6:BE6) -> 26863 | BK6: أنثى | BL6: 988 | BM6: 11765 | BN6: 3466 | BO6: 8790 | BP6: 1278 | BQ6: 576 | BR6: =SUM(BL6:BQ6) -> 26863 | BW6: أنثى | BX6: 988 | BY6: 11765 | BZ6: 3466 | CA6: 8790 | CB6: 1278 | CC6: 576 | CD6: =SUM(BX6:CC6) -> 26863 | CI6: أنثى | CJ6: 988 | CK6: 11765 | CL6: 3466 | CM6: 8790 | CN6: 1278 | CO6: 576 | CP6: =SUM(CJ6:CO6) -> 26863 | CU6: أنثى | CV6: 988 | CW6: 11765 | CX6: 3466 | CY6: 8790 | CZ6: 1278 | DA6: 576 | DB6: =SUM(CV6:DA6) -> 26863 | DG6: أنثى | DH6: 0 | DI6: 0 | DJ6: 0 | DK6: 0 | DL6: 0 | DM6: 0 | DN6: =SUM(DH6:DM6) -> 0 | DS6: أنثى | DT6: 0 | DU6: 0 | DV6: 0 | DW6: 0 | DX6: 0 | DY6: 0 | DZ6: =SUM(DT6:DY6) -> 0 | EE6: أنثى | EF6: 0 | EG6: 0 | EH6: 0 | EI6: 0 | EJ6: 0 | EK6: 0 | EL6: =SUM(EF6:EK6) -> 0 | EQ6: أنثى | ER6: =SUM(EF6) -> 0 | ES6: =SUM(EG6) -> 0 | ET6: =SUM(EH6) -> 0 | EU6: =SUM(EI6) -> 0 | EV6: =SUM(EJ6) -> 0 | EW6: =SUM(EK6) -> 0 | EX6: =SUM(ER6:EW6) -> 0
B7: غير | C7: ذكر | D7: 0 | E7: 357 | F7: 456 | G7: 90 | H7: 88 | I7: 16 | J7: =SUM(D7:I7) -> 1007 | K7: 50 | N7: غير | O7: ذكر | P7: 0 | Q7: 357 | R7: 456 | S7: 90 | T7: 88 | U7: 16 | V7: =SUM(P7:U7) -> 1007 | W7: 50 | Z7: غير | AA7: ذكر | AB7: 0 | AC7: 357 | AD7: 456 | AE7: 90 | AF7: 88 | AG7: 16 | AH7: =SUM(AB7:AG7) -> 1007 | AI7: 50 | AL7: غير | AM7: ذكر | AN7: 0 | AO7: 357 | AP7: 456 | AQ7: 90 | AR7: 88 | AS7: 16 | AT7: =SUM(AN7:AS7) -> 1007 | AU7: 50 | AX7: غير | AY7: ذكر | AZ7: 0 | BA7: 357 | BB7: 456 | BC7: 90 | BD7: 88 | BE7: 16 | BF7: =SUM(AZ7:BE7) -> 1007 | BG7: 50 | BJ7: غير | BK7: ذكر | BL7: 0 | BM7: 357 | BN7: 456 | BO7: 90 | BP7: 88 | BQ7: 16 | BR7: =SUM(BL7:BQ7) -> 1007 | BS7: 50 | BV7: غير | BW7: ذكر | BX7: 0 | BY7: 357 | BZ7: 456 | CA7: 90 | CB7: 88 | CC7: 16 | CD7: =SUM(BX7:CC7) -> 1007 | CE7: 50 | CH7: غير | CI7: ذكر | CJ7: 0 | CK7: 357 | CL7: 456 | CM7: 90 | CN7: 88 | CO7: 16 | CP7: =SUM(CJ7:CO7) -> 1007 | CQ7: 50 | CT7: غير | CU7: ذكر | CV7: 0 | CW7: 357 | CX7: 456 | CY7: 90 | CZ7: 88 | DA7: 16 | DB7: =SUM(CV7:DA7) -> 1007 | DC7: 50 | DF7: غير | DG7: ذكر | DH7: 0 | DI7: 0 | DJ7: 0 | DK7: 0 | DL7: 0 | DM7: 0 | DN7: =SUM(DH7:DM7) -> 0 | DO7: 0 | DR7: غير | DS7: ذكر | DT7: 0 | DU7: 0 | DV7: 0 | DW7: 0 | DX7: 0 | DY7: 0 | DZ7: =SUM(DT7:DY7) -> 0 | EA7: 0 | ED7: غير | EE7: ذكر | EF7: 0 | EG7: 0 | EH7: 0 | EI7: 0 | EJ7: 0 | EK7: 0 | EL7: =SUM(EF7:EK7) -> 0 | EM7: 0 | EP7: غير | EQ7: ذكر | ER7: =SUM(EF7) -> 0 | ES7: =SUM(EG7) -> 0 | ET7: =SUM(EH7) -> 0 | EU7: =SUM(EI7) -> 0 | EV7: =SUM(EJ7) -> 0 | EW7: =SUM(EK7) -> 0 | EX7: =SUM(ER7:EW7) -> 0 | EY7: =SUM(EM7) -> 0
B8: سعودي | C8: أنثى | D8: 0 | E8: 324 | F8: 567 | G8: 130 | H8: 69 | I8: 12 | J8: =SUM(D8:I8) -> 1102 | N8: سعودي | O8: أنثى | P8: 0 | Q8: 324 | R8: 567 | S8: 130 | T8: 69 | U8: 12 | V8: =SUM(P8:U8) -> 1102 | Z8: سعودي | AA8: أنثى | AB8: 0 | AC8: 324 | AD8: 567 | AE8: 130 | AF8: 69 | AG8: 12 | AH8: =SUM(AB8:AG8) -> 1102 | AL8: سعودي | AM8: أنثى | AN8: 0 | AO8: 324 | AP8: 567 | AQ8: 130 | AR8: 69 | AS8: 12 | AT8: =SUM(AN8:AS8) -> 1102 | AX8: سعودي | AY8: أنثى | AZ8: 0 | BA8: 324 | BB8: 567 | BC8: 130 | BD8: 69 | BE8: 12 | BF8: =SUM(AZ8:BE8) -> 1102 | BJ8: سعودي | BK8: أنثى | BL8: 0 | BM8: 324 | BN8: 567 | BO8: 130 | BP8: 69 | BQ8: 12 | BR8: =SUM(BL8:BQ8) -> 1102 | BV8: سعودي | BW8: أنثى | BX8: 0 | BY8: 324 | BZ8: 567 | CA8: 130 | CB8: 69 | CC8: 12 | CD8: =SUM(BX8:CC8) -> 1102 | CH8: سعودي | CI8: أنثى | CJ8: 0 | CK8: 324 | CL8: 567 | CM8: 130 | CN8: 69 | CO8: 12 | CP8: =SUM(CJ8:CO8) -> 1102 | CT8: سعودي | CU8: أنثى | CV8: 0 | CW8: 324 | CX8: 567 | CY8: 130 | CZ8: 69 | DA8: 12 | DB8: =SUM(CV8:DA8) -> 1102 | DF8: سعودي | DG8: أنثى | DH8: 0 | DI8: 0 | DJ8: 0 | DK8: 0 | DL8: 0 | DM8: 0 | DN8: =SUM(DH8:DM8) -> 0 | DR8: سعودي | DS8: أنثى | DT8: 0 | DU8: 0 | DV8: 0 | DW8: 0 | DX8: 0 | DY8: 0 | DZ8: =SUM(DT8:DY8) -> 0 | ED8: سعودي | EE8: أنثى | EF8: 0 | EG8: 0 | EH8: 0 | EI8: 0 | EJ8: 0 | EK8: 0 | EL8: =SUM(EF8:EK8) -> 0 | EP8: سعودي | EQ8: أنثى | ER8: =SUM(EF8) -> 0 | ES8: =SUM(EG8) -> 0 | ET8: =SUM(EH8) -> 0 | EU8: =SUM(EI8) -> 0 | EV8: =SUM(EJ8) -> 0 | EW8: =SUM(EK8) -> 0 | EX8: =SUM(ER8:EW8) -> 0
B9: المجموع | D9: =SUM(D5:D8) -> 2410 | E9: =SUM(E5:E8) -> 14312 | F9: =SUM(F5:F8) -> 7887 | G9: =SUM(G5:G8) -> 17618 | H9: =SUM(H5:H8) -> 3144 | I9: =SUM(I5:I8) -> 1302 | J9: =SUM(J5:J8) -> 46673 | K9: =SUM(K5:K8) -> 5431 | N9: المجموع | P9: =SUM(P5:P8) -> 2410 | Q9: =SUM(Q5:Q8) -> 14312 | R9: =SUM(R5:R8) -> 7887 | S9: =SUM(S5:S8) -> 17618 | T9: =SUM(T5:T8) -> 3144 | U9: =SUM(U5:U8) -> 1302 | V9: =SUM(V5:V8) -> 46673 | W9: =SUM(W5:W8) -> 5431 | Z9: المجموع | AB9: =SUM(AB5:AB8) -> 2410 | AC9: =SUM(AC5:AC8) -> 14312 | AD9: =SUM(AD5:AD8) -> 7887 | AE9: =SUM(AE5:AE8) -> 17618 | AF9: =SUM(AF5:AF8) -> 3144 | AG9: =SUM(AG5:AG8) -> 1302 | AH9: =SUM(AH5:AH8) -> 46673 | AI9: =SUM(AI5:AI8) -> 5431 | AL9: المجموع | AN9: =SUM(AN5:AN8) -> 2410 | AO9: =SUM(AO5:AO8) -> 14312 | AP9: =SUM(AP5:AP8) -> 7887 | AQ9: =SUM(AQ5:AQ8) -> 17618 | AR9: =SUM(AR5:AR8) -> 3144 | AS9: =SUM(AS5:AS8) -> 1302 | AT9: =SUM(AT5:AT8) -> 46673 | AU9: =SUM(AU5:AU8) -> 5431 | AX9: المجموع | AZ9: =SUM(AZ5:AZ8) -> 2410 | BA9: =SUM(BA5:BA8) -> 14312 | BB9: =SUM(BB5:BB8) -> 7887 | BC9: =SUM(BC5:BC8) -> 17618 | BD9: =SUM(BD5:BD8) -> 3144 | BE9: =SUM(BE5:BE8) -> 1302 | BF9: =SUM(BF5:BF8) -> 46673 | BG9: =SUM(BG5:BG8) -> 5431 | BJ9: المجموع | BL9: =SUM(BL5:BL8) -> 2410 | BM9: =SUM(BM5:BM8) -> 14312 | BN9: =SUM(BN5:BN8) -> 7887 | BO9: =SUM(BO5:BO8) -> 17618 | BP9: =SUM(BP5:BP8) -> 3144 | BQ9: =SUM(BQ5:BQ8) -> 1302 | BR9: =SUM(BR5:BR8) -> 46673 | BS9: =SUM(BS5:BS8) -> 5431 | BV9: المجموع | BX9: =SUM(BX5:BX8) -> 2410 | BY9: =SUM(BY5:BY8) -> 14312 | BZ9: =SUM(BZ5:BZ8) -> 7887 | CA9: =SUM(CA5:CA8) -> 17618 | CB9: =SUM(CB5:CB8) -> 3144 | CC9: =SUM(CC5:CC8) -> 1302 | CD9: =SUM(CD5:CD8) -> 46673 | CE9: =SUM(CE5:CE8) -> 5431 | CH9: المجموع | CJ9: =SUM(CJ5:CJ8) -> 2410 | CK9: =SUM(CK5:CK8) -> 14312 | CL9: =SUM(CL5:CL8) -> 7887 | CM9: =SUM(CM5:CM8) -> 17618 | CN9: =SUM(CN5:CN8) -> 3144 | CO9: =SUM(CO5:CO8) -> 1302 | CP9: =SUM(CP5:CP8) -> 46673 | CQ9: =SUM(CQ5:CQ8) -> 5431 | CT9: المجموع | CV9: =SUM(CV5:CV8) -> 2410 | CW9: =SUM(CW5:CW8) -> 14312 | CX9: =SUM(CX5:CX8) -> 7887 | CY9: =SUM(CY5:CY8) -> 17618 | CZ9: =SUM(CZ5:CZ8) -> 3144 | DA9: =SUM(DA5:DA8) -> 1302 | DB9: =SUM(DB5:DB8) -> 46673 | DC9: =SUM(DC5:DC8) -> 5431 | DF9: المجموع | DH9: =SUM(DH5:DH8) -> 0 | DI9: =SUM(DI5:DI8) -> 0 | DJ9: =SUM(DJ5:DJ8) -> 0 | DK9: =SUM(DK5:DK8) -> 0 | DL9: =SUM(DL5:DL8) -> 0 | DM9: =SUM(DM5:DM8) -> 0 | DN9: =SUM(DN5:DN8) -> 0 | DO9: =SUM(DO5:DO8) -> 0 | DR9: المجموع | DT9: =SUM(DT5:DT8) -> 0 | DU9: =SUM(DU5:DU8) -> 0 | DV9: =SUM(DV5:DV8) -> 0 | DW9: =SUM(DW5:DW8) -> 0 | DX9: =SUM(DX5:DX8) -> 0 | DY9: =SUM(DY5:DY8) -> 0 | DZ9: =SUM(DZ5:DZ8) -> 0 | EA9: =SUM(EA5:EA8) -> 0 | ED9: المجموع | EF9: =SUM(EF5:EF8) -> 0 | EG9: =SUM(EG5:EG8) -> 0 | EH9: =SUM(EH5:EH8) -> 0 | EI9: =SUM(EI5:EI8) -> 0 | EJ9: =SUM(EJ5:EJ8) -> 0 | EK9: =SUM(EK5:EK8) -> 0 | EL9: =SUM(EL5:EL8) -> 0 | EM9: =SUM(EM5:EM8) -> 0 | EP9: المجموع | ER9: =SUM(ER5:ER8) -> 0 | ES9: =SUM(ES5:ES8) -> 0 | ET9: =SUM(ET5:ET8) -> 0 | EU9: =SUM(EU5:EU8) -> 0 | EV9: =SUM(EV5:EV8) -> 0 | EW9: =SUM(EW5:EW8) -> 0 | EX9: =SUM(EX5:EX8) -> 0 | EY9: =SUM(EY5:EY8) -> 0
A10: الجامعة | B10: سعودي | C10: ذكر | D10: 57 | E10: 756 | F10: 3886 | G10: 10832 | H10: 1884 | I10: 1267 | J10: =SUM(D10:I10) -> 18682 | K10: 4366 | M10: الجامعة | N10: سعودي | O10: ذكر | P10: 57 | Q10: 756 | R10: 3886 | S10: 10832 | T10: 1884 | U10: 1267 | V10: =SUM(P10:U10) -> 18682 | W10: 4366 | Y10: الجامعة | Z10: سعودي | AA10: ذكر | AB10: 57 | AC10: 756 | AD10: 3886 | AE10: 10832 | AF10: 1884 | AG10: 1267 | AH10: =SUM(AB10:AG10) -> 18682 | AI10: 4366 | AK10: الجامعة | AL10: سعودي | AM10: ذكر | AN10: 57 | AO10: 756 | AP10: 3886 | AQ10: 10832 | AR10: 1884 | AS10: 1267 | AT10: =SUM(AN10:AS10) -> 18682 | AU10: 4366 | AW10: الجامعة | AX10: سعودي | AY10: ذكر | AZ10: 57 | BA10: 756 | BB10: 3886 | BC10: 10832 | BD10: 1884 | BE10: 1267 | BF10: =SUM(AZ10:BE10) -> 18682 | BG10: 4366 | BI10: الجامعة | BJ10: سعودي | BK10: ذكر | BL10: 57 | BM10: 756 | BN10: 3886 | BO10: 10832 | BP10: 1884 | BQ10: 1267 | BR10: =SUM(BL10:BQ10) -> 18682 | BS10: 4366 | BU10: الجامعة | BV10: سعودي | BW10: ذكر | BX10: 57 | BY10: 756 | BZ10: 3886 | CA10: 10832 | CB10: 1884 | CC10: 1267 | CD10: =SUM(BX10:CC10) -> 18682 | CE10: 4366 | CG10: الجامعة | CH10: سعودي | CI10: ذكر | CJ10: 57 | CK10: 756 | CL10: 3886 | CM10: 10832 | CN10: 1884 | CO10: 1267 | CP10: =SUM(CJ10:CO10) -> 18682 | CQ10: 4366 | CS10: الجامعة | CT10: سعودي | CU10: ذكر | CV10: 57 | CW10: 756 | CX10: 3886 | CY10: 10832 | CZ10: 1884 | DA10: 1267 | DB10: =SUM(CV10:DA10) -> 18682 | DC10: 4366 | DE10: الجامعة | DF10: سعودي | DG10: ذكر | DH10: 0 | DI10: 0 | DJ10: 0 | DK10: 0 | DL10: 0 | DM10: 0 | DN10: =SUM(DH10:DM10) -> 0 | DO10: 0 | DQ10: الجامعة | DR10: سعودي | DS10: ذكر | DT10: 0 | DU10: 0 | DV10: 0 | DW10: 0 | DX10: 0 | DY10: 0 | DZ10: =SUM(DT10:DY10) -> 0 | EA10: 0 | EC10: الجامعة | ED10: سعودي | EE10: ذكر | EF10: 0 | EG10: 0 | EH10: 0 | EI10: 0 | EJ10: 0 | EK10: 0 | EL10: =SUM(EF10:EK10) -> 0 | EM10: 0 | EO10: =EC10 -> الجامعة | EP10: سعودي | EQ10: ذكر | ER10: =SUM(EF10) -> 0 | ES10: =SUM(EG10) -> 0 | ET10: =SUM(EH10) -> 0 | EU10: =SUM(EI10) -> 0 | EV10: =SUM(EJ10) -> 0 | EW10: =SUM(EK10) -> 0 | EX10: =SUM(ER10:EW10) -> 0 | EY10: =SUM(EM10) -> 0
C11: أنثى | D11: 54 | E11: 598 | F11: 3948 | G11: 12090 | H11: 2299 | I11: 989 | J11: =SUM(D11:I11) -> 19978 | O11: أنثى | P11: 54 | Q11: 598 | R11: 3948 | S11: 12090 | T11: 2299 | U11: 989 | V11: =SUM(P11:U11) -> 19978 | AA11: أنثى | AB11: 54 | AC11: 598 | AD11: 3948 | AE11: 12090 | AF11: 2299 | AG11: 989 | AH11: =SUM(AB11:AG11) -> 19978 | AM11: أنثى | AN11: 54 | AO11: 598 | AP11: 3948 | AQ11: 12090 | AR11: 2299 | AS11: 989 | AT11: =SUM(AN11:AS11) -> 19978 | AY11: أنثى | AZ11: 54 | BA11: 598 | BB11: 3948 | BC11: 12090 | BD11: 2299 | BE11: 989 | BF11: =SUM(AZ11:BE11) -> 19978 | BK11: أنثى | BL11: 54 | BM11: 598 | BN11: 3948 | BO11: 12090 | BP11: 2299 | BQ11: 989 | BR11: =SUM(BL11:BQ11) -> 19978 | BW11: أنثى | BX11: 54 | BY11: 598 | BZ11: 3948 | CA11: 12090 | CB11: 2299 | CC11: 989 | CD11: =SUM(BX11:CC11) -> 19978 | CI11: أنثى | CJ11: 54 | CK11: 598 | CL11: 3948 | CM11: 12090 | CN11: 2299 | CO11: 989 | CP11: =SUM(CJ11:CO11) -> 19978 | CU11: أنثى | CV11: 54 | CW11: 598 | CX11: 3948 | CY11: 12090 | CZ11: 2299 | DA11: 989 | DB11: =SUM(CV11:DA11) -> 19978 | DG11: أنثى | DH11: 0 | DI11: 0 | DJ11: 0 | DK11: 0 | DL11: 0 | DM11: 0 | DN11: =SUM(DH11:DM11) -> 0 | DS11: أنثى | DT11: 0 | DU11: 0 | DV11: 0 | DW11: 0 | DX11: 0 | DY11: 0 | DZ11: =SUM(DT11:DY11) -> 0 | EE11: أنثى | EF11: 0 | EG11: 0 | EH11: 0 | EI11: 0 | EJ11: 0 | EK11: 0 | EL11: =SUM(EF11:EK11) -> 0 | EQ11: أنثى | ER11: =SUM(EF11) -> 0 | ES11: =SUM(EG11) -> 0 | ET11: =SUM(EH11) -> 0 | EU11: =SUM(EI11) -> 0 | EV11: =SUM(EJ11) -> 0 | EW11: =SUM(EK11) -> 0 | EX11: =SUM(ER11:EW11) -> 0
B12: غير | C12: ذكر | D12: 24 | E12: 40 | F12: 180 | G12: 511 | H12: 242 | I12: 59 | J12: =SUM(D12:I12) -> 1056 | K12: 2031 | N12: غير | O12: ذكر | P12: 24 | Q12: 40 | R12: 180 | S12: 511 | T12: 242 | U12: 59 | V12: =SUM(P12:U12) -> 1056 | W12: 2031 | Z12: غير | AA12: ذكر | AB12: 24 | AC12: 40 | AD12: 180 | AE12: 511 | AF12: 242 | AG12: 59 | AH12: =SUM(AB12:AG12) -> 1056 | AI12: 2031 | AL12: غير | AM12: ذكر | AN12: 24 | AO12: 40 | AP12: 180 | AQ12: 511 | AR12: 242 | AS12: 59 | AT12: =SUM(AN12:AS12) -> 1056 | AU12: 2031 | AX12: غير | AY12: ذكر | AZ12: 24 | BA12: 40 | BB12: 180 | BC12: 511 | BD12: 242 | BE12: 59 | BF12: =SUM(AZ12:BE12) -> 1056 | BG12: 2031 | BJ12: غير | BK12: ذكر | BL12: 24 | BM12: 40 | BN12: 180 | BO12: 511 | BP12: 242 | BQ12: 59 | BR12: =SUM(BL12:BQ12) -> 1056 | BS12: 2031 | BV12: غير | BW12: ذكر | BX12: 24 | BY12: 40 | BZ12: 180 | CA12: 511 | CB12: 242 | CC12: 59 | CD12: =SUM(BX12:CC12) -> 1056 | CE12: 2031 | CH12: غير | CI12: ذكر | CJ12: 24 | CK12: 40 | CL12: 180 | CM12: 511 | CN12: 242 | CO12: 59 | CP12: =SUM(CJ12:CO12) -> 1056 | CQ12: 2031 | CT12: غير | CU12: ذكر | CV12: 24 | CW12: 40 | CX12: 180 | CY12: 511 | CZ12: 242 | DA12: 59 | DB12: =SUM(CV12:DA12) -> 1056 | DC12: 2031 | DF12: غير | DG12: ذكر | DH12: 0 | DI12: 0 | DJ12: 0 | DK12: 0 | DL12: 0 | DM12: 0 | DN12: =SUM(DH12:DM12) -> 0 | DO12: 0 | DR12: غير | DS12: ذكر | DT12: 0 | DU12: 0 | DV12: 0 | DW12: 0 | DX12: 0 | DY12: 0 | DZ12: =SUM(DT12:DY12) -> 0 | EA12: 0 | ED12: غير | EE12: ذكر | EF12: 0 | EG12: 0 | EH12: 0 | EI12: 0 | EJ12: 0 | EK12: 0 | EL12: =SUM(EF12:EK12) -> 0 | EM12: 0 | EP12: غير | EQ12: ذكر | ER12: =SUM(EF12) -> 0 | ES12: =SUM(EG12) -> 0 | ET12: =SUM(EH12) -> 0 | EU12: =SUM(EI12) -> 0 | EV12: =SUM(EJ12) -> 0 | EW12: =SUM(EK12) -> 0 | EX12: =SUM(ER12:EW12) -> 0 | EY12: =SUM(EM12) -> 0
B13: سعودي | C13: أنثى | D13: 44 | E13: 64 | F13: 188 | G13: 710 | H13: 280 | I13: 50 | J13: =SUM(D13:I13) -> 1336 | N13: سعودي | O13: أنثى | P13: 44 | Q13: 64 | R13: 188 | S13: 710 | T13: 280 | U13: 50 | V13: =SUM(P13:U13) -> 1336 | Z13: سعودي | AA13: أنثى | AB13: 44 | AC13: 64 | AD13: 188 | AE13: 710 | AF13: 280 | AG13: 50 | AH13: =SUM(AB13:AG13) -> 1336 | AL13: سعودي | AM13: أنثى | AN13: 44 | AO13: 64 | AP13: 188 | AQ13: 710 | AR13: 280 | AS13: 50 | AT13: =SUM(AN13:AS13) -> 1336 | AX13: سعودي | AY13: أنثى | AZ13: 44 | BA13: 64 | BB13: 188 | BC13: 710 | BD13: 280 | BE13: 50 | BF13: =SUM(AZ13:BE13) -> 1336 | BJ13: سعودي | BK13: أنثى | BL13: 44 | BM13: 64 | BN13: 188 | BO13: 710 | BP13: 280 | BQ13: 50 | BR13: =SUM(BL13:BQ13) -> 1336 | BV13: سعودي | BW13: أنثى | BX13: 44 | BY13: 64 | BZ13: 188 | CA13: 710 | CB13: 280 | CC13: 50 | CD13: =SUM(BX13:CC13) -> 1336 | CH13: سعودي | CI13: أنثى | CJ13: 44 | CK13: 64 | CL13: 188 | CM13: 710 | CN13: 280 | CO13: 50 | CP13: =SUM(CJ13:CO13) -> 1336 | CT13: سعودي | CU13: أنثى | CV13: 44 | CW13: 64 | CX13: 188 | CY13: 710 | CZ13: 280 | DA13: 50 | DB13: =SUM(CV13:DA13) -> 1336 | DF13: سعودي | DG13: أنثى | DH13: 0 | DI13: 0 | DJ13: 0 | DK13: 0 | DL13: 0 | DM13: 0 | DN13: =SUM(DH13:DM13) -> 0 | DR13: سعودي | DS13: أنثى | DT13: 0 | DU13: 0 | DV13: 0 | DW13: 0 | DX13: 0 | DY13: 0 | DZ13: =SUM(DT13:DY13) -> 0 | ED13: سعودي | EE13: أنثى | EF13: 0 | EG13: 0 | EH13: 0 | EI13: 0 | EJ13: 0 | EK13: 0 | EL13: =SUM(EF13:EK13) -> 0 | EP13: سعودي | EQ13: أنثى | ER13: =SUM(EF13) -> 0 | ES13: =SUM(EG13) -> 0 | ET13: =SUM(EH13) -> 0 | EU13: =SUM(EI13) -> 0 | EV13: =SUM(EJ13) -> 0 | EW13: =SUM(EK13) -> 0 | EX13: =SUM(ER13:EW13) -> 0
B14: المجموع | D14: =SUM(D10:D13) -> 179 | E14: =SUM(E10:E13) -> 1458 | F14: =SUM(F10:F13) -> 8202 | G14: =SUM(G10:G13) -> 24143 | H14: =SUM(H10:H13) -> 4705 | I14: =SUM(I10:I13) -> 2365 | J14: =SUM(J10:J13) -> 41052 | K14: =SUM(K10:K13) -> 6397 | N14: المجموع | P14: =SUM(P10:P13) -> 179 | Q14: =SUM(Q10:Q13) -> 1458 | R14: =SUM(R10:R13) -> 8202 | S14: =SUM(S10:S13) -> 24143 | T14: =SUM(T10:T13) -> 4705 | U14: =SUM(U10:U13) -> 2365 | V14: =SUM(V10:V13) -> 41052 | W14: =SUM(W10:W13) -> 6397 | Z14: المجموع | AB14: =SUM(AB10:AB13) -> 179 | AC14: =SUM(AC10:AC13) -> 1458 | AD14: =SUM(AD10:AD13) -> 8202 | AE14: =SUM(AE10:AE13) -> 24143 | AF14: =SUM(AF10:AF13) -> 4705 | AG14: =SUM(AG10:AG13) -> 2365 | AH14: =SUM(AH10:AH13) -> 41052 | AI14: =SUM(AI10:AI13) -> 6397 | AL14: المجموع | AN14: =SUM(AN10:AN13) -> 179 | AO14: =SUM(AO10:AO13) -> 1458 | AP14: =SUM(AP10:AP13) -> 8202 | AQ14: =SUM(AQ10:AQ13) -> 24143 | AR14: =SUM(AR10:AR13) -> 4705 | AS14: =SUM(AS10:AS13) -> 2365 | AT14: =SUM(AT10:AT13) -> 41052 | AU14: =SUM(AU10:AU13) -> 6397 | AX14: المجموع | AZ14: =SUM(AZ10:AZ13) -> 179 | BA14: =SUM(BA10:BA13) -> 1458 | BB14: =SUM(BB10:BB13) -> 8202 | BC14: =SUM(BC10:BC13) -> 24143 | BD14: =SUM(BD10:BD13) -> 4705 | BE14: =SUM(BE10:BE13) -> 2365 | BF14: =SUM(BF10:BF13) -> 41052 | BG14: =SUM(BG10:BG13) -> 6397 | BJ14: المجموع | BL14: =SUM(BL10:BL13) -> 179 | BM14: =SUM(BM10:BM13) -> 1458 | BN14: =SUM(BN10:BN13) -> 8202 | BO14: =SUM(BO10:BO13) -> 24143 | BP14: =SUM(BP10:BP13) -> 4705 | BQ14: =SUM(BQ10:BQ13) -> 2365 | BR14: =SUM(BR10:BR13) -> 41052 | BS14: =SUM(BS10:BS13) -> 6397 | BV14: المجموع | BX14: =SUM(BX10:BX13) -> 179 | BY14: =SUM(BY10:BY13) -> 1458 | BZ14: =SUM(BZ10:BZ13) -> 8202 | CA14: =SUM(CA10:CA13) -> 24143 | CB14: =SUM(CB10:CB13) -> 4705 | CC14: =SUM(CC10:CC13) -> 2365 | CD14: =SUM(CD10:CD13) -> 41052 | CE14: =SUM(CE10:CE13) -> 6397 | CH14: المجموع | CJ14: =SUM(CJ10:CJ13) -> 179 | CK14: =SUM(CK10:CK13) -> 1458 | CL14: =SUM(CL10:CL13) -> 8202 | CM14: =SUM(CM10:CM13) -> 24143 | CN14: =SUM(CN10:CN13) -> 4705 | CO14: =SUM(CO10:CO13) -> 2365 | CP14: =SUM(CP10:CP13) -> 41052 | CQ14: =SUM(CQ10:CQ13) -> 6397 | CT14: المجموع | CV14: =SUM(CV10:CV13) -> 179 | CW14: =SUM(CW10:CW13) -> 1458 | CX14: =SUM(CX10:CX13) -> 8202 | CY14: =SUM(CY10:CY13) -> 24143 | CZ14: =SUM(CZ10:CZ13) -> 4705 | DA14: =SUM(DA10:DA13) -> 2365 | DB14: =SUM(DB10:DB13) -> 41052 | DC14: =SUM(DC10:DC13) -> 6397 | DF14: المجموع | DH14: =SUM(DH10:DH13) -> 0 | DI14: =SUM(DI10:DI13) -> 0 | DJ14: =SUM(DJ10:DJ13) -> 0 | DK14: =SUM(DK10:DK13) -> 0 | DL14: =SUM(DL10:DL13) -> 0 | DM14: =SUM(DM10:DM13) -> 0 | DN14: =SUM(DN10:DN13) -> 0 | DO14: =SUM(DO10:DO13) -> 0 | DR14: المجموع | DT14: =SUM(DT10:DT13) -> 0 | DU14: =SUM(DU10:DU13) -> 0 | DV14: =SUM(DV10:DV13) -> 0 | DW14: =SUM(DW10:DW13) -> 0 | DX14: =SUM(DX10:DX13) -> 0 | DY14: =SUM(DY10:DY13) -> 0 | DZ14: =SUM(DZ10:DZ13) -> 0 | EA14: =SUM(EA10:EA13) -> 0 | ED14: المجموع | EF14: =SUM(EF10:EF13) -> 0 | EG14: =SUM(EG10:EG13) -> 0 | EH14: =SUM(EH10:EH13) -> 0 | EI14: =SUM(EI10:EI13) -> 0 | EJ14: =SUM(EJ10:EJ13) -> 0 | EK14: =SUM(EK10:EK13) -> 0 | EL14: =SUM(EL10:EL13) -> 0 | EM14: =SUM(EM10:EM13) -> 0 | EP14: المجموع | ER14: =SUM(ER10:ER13) -> 0 | ES14: =SUM(ES10:ES13) -> 0 | ET14: =SUM(ET10:ET13) -> 0 | EU14: =SUM(EU10:EU13) -> 0 | EV14: =SUM(EV10:EV13) -> 0 | EW14: =SUM(EW10:EW13) -> 0 | EX14: =SUM(EX10:EX13) -> 0 | EY14: =SUM(EY10:EY13) -> 0
A15: السليمانية | B15: سعودي | C15: ذكر | D15: 2100 | E15: 285 | F15: 3445 | G15: 3175 | H15: 2572 | I15: 522 | J15: =SUM(D15:I15) -> 12099 | K15: 7560 | M15: السليمانية | N15: سعودي | O15: ذكر | P15: 2100+P15:U43 | Q15: 285 | R15: 3445 | S15: 3175 | T15: 2572 | U15: 522 | V15: =SUM(P15:U15) -> 9999 | W15: 7560 | Y15: السليمانية | Z15: سعودي | AA15: ذكر | AB15: 2100+P15:U43 | AC15: 285 | AD15: 3445 | AE15: 3175 | AF15: 2572 | AG15: 522 | AH15: =SUM(AB15:AG15) -> 9999 | AI15: 7560 | AK15: السليمانية | AL15: سعودي | AM15: ذكر | AN15: 2100+P15:U43 | AO15: 285 | AP15: 3445 | AQ15: 3175 | AR15: 2572 | AS15: 522 | AT15: =SUM(AN15:AS15) -> 9999 | AU15: 7560 | AW15: السليمانية | AX15: سعودي | AY15: ذكر | AZ15: 2100+P15:U43 | BA15: 285 | BB15: 3445 | BC15: 3175 | BD15: 2572 | BE15: 522 | BF15: =SUM(AZ15:BE15) -> 9999 | BG15: 7560 | BI15: السليمانية | BJ15: سعودي | BK15: ذكر | BL15: 2100+P15:U43 | BM15: 285 | BN15: 3445 | BO15: 3175 | BP15: 2572 | BQ15: 522 | BR15: =SUM(BL15:BQ15) -> 9999 | BS15: 7560 | BU15: السليمانية | BV15: سعودي | BW15: ذكر | BX15: 2100+P15:U43 | BY15: 285 | BZ15: 3445 | CA15: 3175 | CB15: 2572 | CC15: 522 | CD15: =SUM(BX15:CC15) -> 9999 | CE15: 7560 | CG15: السليمانية | CH15: سعودي | CI15: ذكر | CJ15: 2100+P15:U43 | CK15: 285 | CL15: 3445 | CM15: 3175 | CN15: 2572 | CO15: 522 | CP15: =SUM(CJ15:CO15) -> 9999 | CQ15: 7560 | CS15: السليمانية | CT15: سعودي | CU15: ذكر | CV15: 2100+P15:U43 | CW15: 285 | CX15: 3445 | CY15: 3175 | CZ15: 2572 | DA15: 522 | DB15: =SUM(CV15:DA15) -> 9999 | DC15: 7560 | DE15: السليمانية | DF15: سعودي | DG15: ذكر | DH15: 0 | DI15: 0 | DJ15: 0 | DK15: 0 | DL15: 0 | DM15: 0 | DN15: =SUM(DH15:DM15) -> 0 | DO15: 0 | DQ15: السليمانية | DR15: سعودي | DS15: ذكر | DT15: 0 | DU15: 0 | DV15: 0 | DW15: 0 | DX15: 0 | DY15: 0 | DZ15: =SUM(DT15:DY15) -> 0 | EA15: 0 | EC15: السليمانية | ED15: سعودي | EE15: ذكر | EF15: 0 | EG15: 0 | EH15: 0 | EI15: 0 | EJ15: 0 | EK15: 0 | EL15: =SUM(EF15:EK15) -> 0 | EM15: 0 | EO15: =EC15 -> السليمانية | EP15: سعودي | EQ15: ذكر | ER15: =SUM(EF15) -> 0 | ES15: =SUM(EG15) -> 0 | ET15: =SUM(EH15) -> 0 | EU15: =SUM(EI15) -> 0 | EV15: =SUM(EJ15) -> 0 | EW15: =SUM(EK15) -> 0 | EX15: =SUM(ER15:EW15) -> 0 | EY15: =SUM(EM15) -> 0
C16: أنثى | D16: 2251 | E16: 255 | F16: 3325 | G16: 3663 | H16: 211 | I16: 402 | J16: =SUM(D16:I16) -> 10107 | O16: أنثى | P16: 2251 | Q16: 255 | R16: 3325 | S16: 3663 | T16: 211 | U16: 402 | V16: =SUM(P16:U16) -> 10107 | AA16: أنثى | AB16: 2251 | AC16: 255 | AD16: 3325 | AE16: 3663 | AF16: 211 | AG16: 402 | AH16: =SUM(AB16:AG16) -> 10107 | AM16: أنثى | AN16: 2251 | AO16: 255 | AP16: 3325 | AQ16: 3663 | AR16: 211 | AS16: 402 | AT16: =SUM(AN16:AS16) -> 10107 | AY16: أنثى | AZ16: 2251 | BA16: 255 | BB16: 3325 | BC16: 3663 | BD16: 211 | BE16: 402 | BF16: =SUM(AZ16:BE16) -> 10107 | BK16: أنثى | BL16: 2251 | BM16: 255 | BN16: 3325 | BO16: 3663 | BP16: 211 | BQ16: 402 | BR16: =SUM(BL16:BQ16) -> 10107 | BW16: أنثى | BX16: 2251 | BY16: 255 | BZ16: 3325 | CA16: 3663 | CB16: 211 | CC16: 402 | CD16: =SUM(BX16:CC16) -> 10107 | CI16: أنثى | CJ16: 2251 | CK16: 255 | CL16: 3325 | CM16: 3663 | CN16: 211 | CO16: 402 | CP16: =SUM(CJ16:CO16) -> 10107 | CU16: أنثى | CV16: 2251 | CW16: 255 | CX16: 3325 | CY16: 3663 | CZ16: 211 | DA16: 402 | DB16: =SUM(CV16:DA16) -> 10107 | DG16: أنثى | DH16: 0 | DI16: 0 | DJ16: 0 | DK16: 0 | DL16: 0 | DM16: 0 | DN16: =SUM(DH16:DM16) -> 0 | DS16: أنثى | DT16: 0 | DU16: 0 | DV16: 0 | DW16: 0 | DX16: 0 | DY16: 0 | DZ16: =SUM(DT16:DY16) -> 0 | EE16: أنثى | EF16: 0 | EG16: 0 | EH16: 0 | EI16: 0 | EJ16: 0 | EK16: 0 | EL16: =SUM(EF16:EK16) -> 0 | EQ16: أنثى | ER16: =SUM(EF16) -> 0 | ES16: =SUM(EG16) -> 0 | ET16: =SUM(EH16) -> 0 | EU16: =SUM(EI16) -> 0 | EV16: =SUM(EJ16) -> 0 | EW16: =SUM(EK16) -> 0 | EX16: =SUM(ER16:EW16) -> 0
B17: غير | C17: ذكر | D17: 1247 | E17: 580 | F17: 241 | G17: 248 | H17: 411 | I17: 59 | J17: =SUM(D17:I17) -> 2786 | K17: 2980 | N17: غير | O17: ذكر | P17: 1247 | Q17: 580 | R17: 241 | S17: 248 | T17: 411 | U17: 59 | V17: =SUM(P17:U17) -> 2786 | W17: 2980 | Z17: غير | AA17: ذكر | AB17: 1247 | AC17: 580 | AD17: 241 | AE17: 248 | AF17: 411 | AG17: 59 | AH17: =SUM(AB17:AG17) -> 2786 | AI17: 2980 | AL17: غير | AM17: ذكر | AN17: 1247 | AO17: 580 | AP17: 241 | AQ17: 248 | AR17: 411 | AS17: 59 | AT17: =SUM(AN17:AS17) -> 2786 | AU17: 2980 | AX17: غير | AY17: ذكر | AZ17: 1247 | BA17: 580 | BB17: 241 | BC17: 248 | BD17: 411 | BE17: 59 | BF17: =SUM(AZ17:BE17) -> 2786 | BG17: 2980 | BJ17: غير | BK17: ذكر | BL17: 1247 | BM17: 580 | BN17: 241 | BO17: 248 | BP17: 411 | BQ17: 59 | BR17: =SUM(BL17:BQ17) -> 2786 | BS17: 2980 | BV17: غير | BW17: ذكر | BX17: 1247 | BY17: 580 | BZ17: 241 | CA17: 248 | CB17: 411 | CC17: 59 | CD17: =SUM(BX17:CC17) -> 2786 | CE17: 2980 | CH17: غير | CI17: ذكر | CJ17: 1247 | CK17: 580 | CL17: 241 | CM17: 248 | CN17: 411 | CO17: 59 | CP17: =SUM(CJ17:CO17) -> 2786 | CQ17: 2980 | CT17: غير | CU17: ذكر | CV17: 1247 | CW17: 580 | CX17: 241 | CY17: 248 | CZ17: 411 | DA17: 59 | DB17: =SUM(CV17:DA17) -> 2786 | DC17: 2980 | DF17: غير | DG17: ذكر | DH17: 0 | DI17: 0 | DJ17: 0 | DK17: 0 | DL17: 0 | DM17: 0 | DN17: =SUM(DH17:DM17) -> 0 | DO17: 0 | DR17: غير | DS17: ذكر | DT17: 0 | DU17: 0 | DV17: 0 | DW17: 0 | DX17: 0 | DY17: 0 | DZ17: =SUM(DT17:DY17) -> 0 | EA17: 0 | ED17: غير | EE17: ذكر | EF17: 0 | EG17: 0 | EH17: 0 | EI17: 0 | EJ17: 0 | EK17: 0 | EL17: =SUM(EF17:EK17) -> 0 | EM17: 0 | EP17: غير | EQ17: ذكر | ER17: =SUM(EF17) -> 0 | ES17: =SUM(EG17) -> 0 | ET17: =SUM(EH17) -> 0 | EU17: =SUM(EI17) -> 0 | EV17: =SUM(EJ17) -> 0 | EW17: =SUM(EK17) -> 0 | EX17: =SUM(ER17:EW17) -> 0 | EY17: =SUM(EM17) -> 0
B18: سعودي | C18: أنثى | D18: 975 | E18: 457 | F18: 288 | G18: 254 | H18: 254 | I18: 50 | J18: =SUM(D18:I18) -> 2278 | N18: سعودي | O18: أنثى | P18: 975 | Q18: 457 | R18: 288 | S18: 254 | T18: 254 | U18: 50 | V18: =SUM(P18:U18) -> 2278 | Z18: سعودي | AA18: أنثى | AB18: 975 | AC18: 457 | AD18: 288 | AE18: 254 | AF18: 254 | AG18: 50 | AH18: =SUM(AB18:AG18) -> 2278 | AL18: سعودي | AM18: أنثى | AN18: 975 | AO18: 457 | AP18: 288 | AQ18: 254 | AR18: 254 | AS18: 50 | AT18: =SUM(AN18:AS18) -> 2278 | AX18: سعودي | AY18: أنثى | AZ18: 975 | BA18: 457 | BB18: 288 | BC18: 254 | BD18: 254 | BE18: 50 | BF18: =SUM(AZ18:BE18) -> 2278 | BJ18: سعودي | BK18: أنثى | BL18: 975 | BM18: 457 | BN18: 288 | BO18: 254 | BP18: 254 | BQ18: 50 | BR18: =SUM(BL18:BQ18) -> 2278 | BV18: سعودي | BW18: أنثى | BX18: 975 | BY18: 457 | BZ18: 288 | CA18: 254 | CB18: 254 | CC18: 50 | CD18: =SUM(BX18:CC18) -> 2278 | CH18: سعودي | CI18: أنثى | CJ18: 975 | CK18: 457 | CL18: 288 | CM18: 254 | CN18: 254 | CO18: 50 | CP18: =SUM(CJ18:CO18) -> 2278 | CT18: سعودي | CU18: أنثى | CV18: 975 | CW18: 457 | CX18: 288 | CY18: 254 | CZ18: 254 | DA18: 50 | DB18: =SUM(CV18:DA18) -> 2278 | DF18: سعودي | DG18: أنثى | DH18: 0 | DI18: 0 | DJ18: 0 | DK18: 0 | DL18: 0 | DM18: 0 | DN18: =SUM(DH18:DM18) -> 0 | DR18: سعودي | DS18: أنثى | DT18: 0 | DU18: 0 | DV18: 0 | DW18: 0 | DX18: 0 | DY18: 0 | DZ18: =SUM(DT18:DY18) -> 0 | ED18: سعودي | EE18: أنثى | EF18: 0 | EG18: 0 | EH18: 0 | EI18: 0 | EJ18: 0 | EK18: 0 | EL18: =SUM(EF18:EK18) -> 0 | EP18: سعودي | EQ18: أنثى | ER18: =SUM(EF18) -> 0 | ES18: =SUM(EG18) -> 0 | ET18: =SUM(EH18) -> 0 | EU18: =SUM(EI18) -> 0 | EV18: =SUM(EJ18) -> 0 | EW18: =SUM(EK18) -> 0 | EX18: =SUM(ER18:EW18) -> 0
B19: المجموع | D19: =SUM(D15:D18) -> 6573 | E19: =SUM(E15:E18) -> 1577 | F19: =SUM(F15:F18) -> 7299 | G19: =SUM(G15:G18) -> 7340 | H19: =SUM(H15:H18) -> 3448 | I19: =SUM(I15:I18) -> 1033 | J19: =SUM(J15:J18) -> 27270 | K19: =SUM(K15:K18) -> 10540 | N19: المجموع | P19: =SUM(P15:P18) -> 4473 | Q19: =SUM(Q15:Q18) -> 1577 | R19: =SUM(R15:R18) -> 7299 | S19: =SUM(S15:S18) -> 7340 | T19: =SUM(T15:T18) -> 3448 | U19: =SUM(U15:U18) -> 1033 | V19: =SUM(V15:V18) -> 25170 | W19: =SUM(W15:W18) -> 10540 | Z19: المجموع | AB19: =SUM(AB15:AB18) -> 4473 | AC19: =SUM(AC15:AC18) -> 1577 | AD19: =SUM(AD15:AD18) -> 7299 | AE19: =SUM(AE15:AE18) -> 7340 | AF19: =SUM(AF15:AF18) -> 3448 | AG19: =SUM(AG15:AG18) -> 1033 | AH19: =SUM(AH15:AH18) -> 25170 | AI19: =SUM(AI15:AI18) -> 10540 | AL19: المجموع | AN19: =SUM(AN15:AN18) -> 4473 | AO19: =SUM(AO15:AO18) -> 1577 | AP19: =SUM(AP15:AP18) -> 7299 | AQ19: =SUM(AQ15:AQ18) -> 7340 | AR19: =SUM(AR15:AR18) -> 3448 | AS19: =SUM(AS15:AS18) -> 1033 | AT19: =SUM(AT15:AT18) -> 25170 | AU19: =SUM(AU15:AU18) -> 10540 | AX19: المجموع | AZ19: =SUM(AZ15:AZ18) -> 4473 | BA19: =SUM(BA15:BA18) -> 1577 | BB19: =SUM(BB15:BB18) -> 7299 | BC19: =SUM(BC15:BC18) -> 7340 | BD19: =SUM(BD15:BD18) -> 3448 | BE19: =SUM(BE15:BE18) -> 1033 | BF19: =SUM(BF15:BF18) -> 25170 | BG19: =SUM(BG15:BG18) -> 10540 | BJ19: المجموع | BL19: =SUM(BL15:BL18) -> 4473 | BM19: =SUM(BM15:BM18) -> 1577 | BN19: =SUM(BN15:BN18) -> 7299 | BO19: =SUM(BO15:BO18) -> 7340 | BP19: =SUM(BP15:BP18) -> 3448 | BQ19: =SUM(BQ15:BQ18) -> 1033 | BR19: =SUM(BR15:BR18) -> 25170 | BS19: =SUM(BS15:BS18) -> 10540 | BV19: المجموع | BX19: =SUM(BX15:BX18) -> 4473 | BY19: =SUM(BY15:BY18) -> 1577 | BZ19: =SUM(BZ15:BZ18) -> 7299 | CA19: =SUM(CA15:CA18) -> 7340 | CB19: =SUM(CB15:CB18) -> 3448 | CC19: =SUM(CC15:CC18) -> 1033 | CD19: =SUM(CD15:CD18) -> 25170 | CE19: =SUM(CE15:CE18) -> 10540 | CH19: المجموع | CJ19: =SUM(CJ15:CJ18) -> 4473 | CK19: =SUM(CK15:CK18) -> 1577 | CL19: =SUM(CL15:CL18) -> 7299 | CM19: =SUM(CM15:CM18) -> 7340 | CN19: =SUM(CN15:CN18) -> 3448 | CO19: =SUM(CO15:CO18) -> 1033 | CP19: =SUM(CP15:CP18) -> 25170 | CQ19: =SUM(CQ15:CQ18) -> 10540 | CT19: المجموع | CV19: =SUM(CV15:CV18) -> 4473 | CW19: =SUM(CW15:CW18) -> 1577 | CX19: =SUM(CX15:CX18) -> 7299 | CY19: =SUM(CY15:CY18) -> 7340 | CZ19: =SUM(CZ15:CZ18) -> 3448 | DA19: =SUM(DA15:DA18) -> 1033 | DB19: =SUM(DB15:DB18) -> 25170 | DC19: =SUM(DC15:DC18) -> 10540 | DF19: المجموع | DH19: =SUM(DH15:DH18) -> 0 | DI19: =SUM(DI15:DI18) -> 0 | DJ19: =SUM(DJ15:DJ18) -> 0 | DK19: =SUM(DK15:DK18) -> 0 | DL19: =SUM(DL15:DL18) -> 0 | DM19: =SUM(DM15:DM18) -> 0 | DN19: =SUM(DN15:DN18) -> 0 | DO19: =SUM(DO15:DO18) -> 0 | DR19: المجموع | DT19: =SUM(DT15:DT18) -> 0 | DU19: =SUM(DU15:DU18) -> 0 | DV19: =SUM(DV15:DV18) -> 0 | DW19: =SUM(DW15:DW18) -> 0 | DX19: =SUM(DX15:DX18) -> 0 | DY19: =SUM(DY15:DY18) -> 0 | DZ19: =SUM(DZ15:DZ18) -> 0 | EA19: =SUM(EA15:EA18) -> 0 | ED19: المجموع | EF19: =SUM(EF15:EF18) -> 0 | EG19: =SUM(EG15:EG18) -> 0 | EH19: =SUM(EH15:EH18) -> 0 | EI19: =SUM(EI15:EI18) -> 0 | EJ19: =SUM(EJ15:EJ18) -> 0 | EK19: =SUM(EK15:EK18) -> 0 | EL19: =SUM(EL15:EL18) -> 0 | EM19: =SUM(EM15:EM18) -> 0 | EP19: المجموع | ER19: =SUM(ER15:ER18) -> 0 | ES19: =SUM(ES15:ES18) -> 0 | ET19: =SUM(ET15:ET18) -> 0 | EU19: =SUM(EU15:EU18) -> 0 | EV19: =SUM(EV15:EV18) -> 0 | EW19: =SUM(EW15:EW18) -> 0 | EX19: =SUM(EX15:EX18) -> 0 | EY19: =SUM(EY15:EY18) -> 0
A20: المطار القديم | B20: سعودي | C20: ذكر | D20: 1977 | E20: 5121 | F20: 6530 | G20: 1970 | H20: 1876 | I20: 1100 | J20: =SUM(D20:I20) -> 18574 | K20: 12066 | M20: المطار القديم | N20: سعودي | O20: ذكر | P20: 1977 | Q20: 5121 | R20: 6530 | S20: 1970 | T20: 1876 | U20: 1100 | V20: =SUM(P20:U20) -> 18574 | W20: 12066 | Y20: المطار القديم | Z20: سعودي | AA20: ذكر | AB20: 1977 | AC20: 5121 | AD20: 6530 | AE20: 1970 | AF20: 1876 | AG20: 1100 | AH20: =SUM(AB20:AG20) -> 18574 | AI20: 12066 | AK20: المطار القديم | AL20: سعودي | AM20: ذكر | AN20: 1977 | AO20: 5121 | AP20: 6530 | AQ20: 1970 | AR20: 1876 | AS20: 1100 | AT20: =SUM(AN20:AS20) -> 18574 | AU20: 12066 | AW20: المطار القديم | AX20: سعودي | AY20: ذكر | AZ20: 1977 | BA20: 5121 | BB20: 6530 | BC20: 1970 | BD20: 1876 | BE20: 1100 | BF20: =SUM(AZ20:BE20) -> 18574 | BG20: 12066 | BI20: المطار القديم | BJ20: سعودي | BK20: ذكر | BL20: 1977 | BM20: 5121 | BN20: 6530 | BO20: 1970 | BP20: 1876 | BQ20: 1100 | BR20: =SUM(BL20:BQ20) -> 18574 | BS20: 12066 | BU20: المطار القديم | BV20: سعودي | BW20: ذكر | BX20: 1977 | BY20: 5121 | BZ20: 6530 | CA20: 1970 | CB20: 1876 | CC20: 1100 | CD20: =SUM(BX20:CC20) -> 18574 | CE20: 12066 | CG20: المطار القديم | CH20: سعودي | CI20: ذكر | CJ20: 1977 | CK20: 5121 | CL20: 6530 | CM20: 1970 | CN20: 1876 | CO20: 1100 | CP20: =SUM(CJ20:CO20) -> 18574 | CQ20: 12066 | CS20: المطار القديم | CT20: سعودي | CU20: ذكر | CV20: 1977 | CW20: 5121 | CX20: 6530 | CY20: 1970 | CZ20: 1876 | DA20: 1100 | DB20: =SUM(CV20:DA20) -> 18574 | DC20: 12066 | DE20: المطار القديم | DF20: سعودي | DG20: ذكر | DH20: 0 | DI20: 0 | DJ20: 0 | DK20: 0 | DL20: 0 | DM20: 0 | DN20: =SUM(DH20:DM20) -> 0 | DO20: 0 | DQ20: المطار القديم | DR20: سعودي | DS20: ذكر | DT20: 0 | DU20: 0 | DV20: 0 | DW20: 0 | DX20: 0 | DY20: 0 | DZ20: =SUM(DT20:DY20) -> 0 | EA20: 0 | EC20: المطار القديم | ED20: سعودي | EE20: ذكر | EF20: 0 | EG20: 0 | EH20: 0 | EI20: 0 | EJ20: 0 | EK20: 0 | EL20: =SUM(EF20:EK20) -> 0 | EM20: 0 | EO20: =EC20 -> المطار القديم | EP20: سعودي | EQ20: ذكر | ER20: =SUM(EF20) -> 0 | ES20: =SUM(EG20) -> 0 | ET20: =SUM(EH20) -> 0 | EU20: =SUM(EI20) -> 0 | EV20: =SUM(EJ20) -> 0 | EW20: =SUM(EK20) -> 0 | EX20: =SUM(ER20:EW20) -> 0 | EY20: =SUM(EM20) -> 0
C21: أنثى | D21: 876 | E21: 8976 | F21: 6500 | G21: 1100 | H21: 1400 | I21: 877 | J21: =SUM(D21:I21) -> 19729 | O21: أنثى | P21: 876 | Q21: 8976 | R21: 6500 | S21: 1100 | T21: 1400 | U21: 877 | V21: =SUM(P21:U21) -> 19729 | AA21: أنثى | AB21: 876 | AC21: 8976 | AD21: 6500 | AE21: 1100 | AF21: 1400 | AG21: 877 | AH21: =SUM(AB21:AG21) -> 19729 | AM21: أنثى | AN21: 876 | AO21: 8976 | AP21: 6500 | AQ21: 1100 | AR21: 1400 | AS21: 877 | AT21: =SUM(AN21:AS21) -> 19729 | AY21: أنثى | AZ21: 876 | BA21: 8976 | BB21: 6500 | BC21: 1100 | BD21: 1400 | BE21: 877 | BF21: =SUM(AZ21:BE21) -> 19729 | BK21: أنثى | BL21: 876 | BM21: 8976 | BN21: 6500 | BO21: 1100 | BP21: 1400 | BQ21: 877 | BR21: =SUM(BL21:BQ21) -> 19729 | BW21: أنثى | BX21: 876 | BY21: 8976 | BZ21: 6500 | CA21: 1100 | CB21: 1400 | CC21: 877 | CD21: =SUM(BX21:CC21) -> 19729 | CI21: أنثى | CJ21: 876 | CK21: 8976 | CL21: 6500 | CM21: 1100 | CN21: 1400 | CO21: 877 | CP21: =SUM(CJ21:CO21) -> 19729 | CU21: أنثى | CV21: 876 | CW21: 8976 | CX21: 6500 | CY21: 1100 | CZ21: 1400 | DA21: 877 | DB21: =SUM(CV21:DA21) -> 19729 | DG21: أنثى | DH21: 0 | DI21: 0 | DJ21: 0 | DK21: 0 | DL21: 0 | DM21: 0 | DN21: =SUM(DH21:DM21) -> 0 | DS21: أنثى | DT21: 0 | DU21: 0 | DV21: 0 | DW21: 0 | DX21: 0 | DY21: 0 | DZ21: =SUM(DT21:DY21) -> 0 | EE21: أنثى | EF21: 0 | EG21: 0 | EH21: 0 | EI21: 0 | EJ21: 0 | EK21: 0 | EL21: =SUM(EF21:EK21) -> 0 | EQ21: أنثى | ER21: =SUM(EF21) -> 0 | ES21: =SUM(EG21) -> 0 | ET21: =SUM(EH21) -> 0 | EU21: =SUM(EI21) -> 0 | EV21: =SUM(EJ21) -> 0 | EW21: =SUM(EK21) -> 0 | EX21: =SUM(ER21:EW21) -> 0
B22: غير | C22: ذكر | D22: 76 | E22: 89 | F22: 878 | G22: 1200 | H22: 387 | I22: 20 | J22: =SUM(D22:I22) -> 2650 | K22: 160 | N22: غير | O22: ذكر | P22: 76 | Q22: 89 | R22: 878 | S22: 1200 | T22: 387 | U22: 20 | V22: =SUM(P22:U22) -> 2650 | W22: 160 | Z22: غير | AA22: ذكر | AB22: 76 | AC22: 89 | AD22: 878 | AE22: 1200 | AF22: 387 | AG22: 20 | AH22: =SUM(AB22:AG22) -> 2650 | AI22: 160 | AL22: غير | AM22: ذكر | AN22: 76 | AO22: 89 | AP22: 878 | AQ22: 1200 | AR22: 387 | AS22: 20 | AT22: =SUM(AN22:AS22) -> 2650 | AU22: 160 | AX22: غير | AY22: ذكر | AZ22: 76 | BA22: 89 | BB22: 878 | BC22: 1200 | BD22: 387 | BE22: 20 | BF22: =SUM(AZ22:BE22) -> 2650 | BG22: 160 | BJ22: غير | BK22: ذكر | BL22: 76 | BM22: 89 | BN22: 878 | BO22: 1200 | BP22: 387 | BQ22: 20 | BR22: =SUM(BL22:BQ22) -> 2650 | BS22: 160 | BV22: غير | BW22: ذكر | BX22: 76 | BY22: 89 | BZ22: 878 | CA22: 1200 | CB22: 387 | CC22: 20 | CD22: =SUM(BX22:CC22) -> 2650 | CE22: 160 | CH22: غير | CI22: ذكر | CJ22: 76 | CK22: 89 | CL22: 878 | CM22: 1200 | CN22: 387 | CO22: 20 | CP22: =SUM(CJ22:CO22) -> 2650 | CQ22: 160 | CT22: غير | CU22: ذكر | CV22: 76 | CW22: 89 | CX22: 878 | CY22: 1200 | CZ22: 387 | DA22: 20 | DB22: =SUM(CV22:DA22) -> 2650 | DC22: 160 | DF22: غير | DG22: ذكر | DH22: 0 | DI22: 0 | DJ22: 0 | DK22: 0 | DL22: 0 | DM22: 0 | DN22: =SUM(DH22:DM22) -> 0 | DO22: 0 | DR22: غير | DS22: ذكر | DT22: 0 | DU22: 0 | DV22: 0 | DW22: 0 | DX22: 0 | DY22: 0 | DZ22: =SUM(DT22:DY22) -> 0 | EA22: 0 | ED22: غير | EE22: ذكر | EF22: 0 | EG22: 0 | EH22: 0 | EI22: 0 | EJ22: 0 | EK22: 0 | EL22: =SUM(EF22:EK22) -> 0 | EM22: 0 | EP22: غير | EQ22: ذكر | ER22: =SUM(EF22) -> 0 | ES22: =SUM(EG22) -> 0 | ET22: =SUM(EH22) -> 0 | EU22: =SUM(EI22) -> 0 | EV22: =SUM(EJ22) -> 0 | EW22: =SUM(EK22) -> 0 | EX22: =SUM(ER22:EW22) -> 0 | EY22: =SUM(EM22) -> 0
B23: سعودي | C23: أنثى | D23: 54 | E23: 189 | F23: 879 | G23: 1066 | H23: 106 | I23: 12 | J23: =SUM(D23:I23) -> 2306 | N23: سعودي | O23: أنثى | P23: 54 | Q23: 189 | R23: 879 | S23: 1066 | T23: 106 | U23: 12 | V23: =SUM(P23:U23) -> 2306 | Z23: سعودي | AA23: أنثى | AB23: 54 | AC23: 189 | AD23: 879 | AE23: 1066 | AF23: 106 | AG23: 12 | AH23: =SUM(AB23:AG23) -> 2306 | AL23: سعودي | AM23: أنثى | AN23: 54 | AO23: 189 | AP23: 879 | AQ23: 1066 | AR23: 106 | AS23: 12 | AT23: =SUM(AN23:AS23) -> 2306 | AX23: سعودي | AY23: أنثى | AZ23: 54 | BA23: 189 | BB23: 879 | BC23: 1066 | BD23: 106 | BE23: 12 | BF23: =SUM(AZ23:BE23) -> 2306 | BJ23: سعودي | BK23: أنثى | BL23: 54 | BM23: 189 | BN23: 879 | BO23: 1066 | BP23: 106 | BQ23: 12 | BR23: =SUM(BL23:BQ23) -> 2306 | BV23: سعودي | BW23: أنثى | BX23: 54 | BY23: 189 | BZ23: 879 | CA23: 1066 | CB23: 106 | CC23: 12 | CD23: =SUM(BX23:CC23) -> 2306 | CH23: سعودي | CI23: أنثى | CJ23: 54 | CK23: 189 | CL23: 879 | CM23: 1066 | CN23: 106 | CO23: 12 | CP23: =SUM(CJ23:CO23) -> 2306 | CT23: سعودي | CU23: أنثى | CV23: 54 | CW23: 189 | CX23: 879 | CY23: 1066 | CZ23: 106 | DA23: 12 | DB23: =SUM(CV23:DA23) -> 2306 | DF23: سعودي | DG23: أنثى | DH23: 0 | DI23: 0 | DJ23: 0 | DK23: 0 | DL23: 0 | DM23: 0 | DN23: =SUM(DH23:DM23) -> 0 | DR23: سعودي | DS23: أنثى | DT23: 0 | DU23: 0 | DV23: 0 | DW23: 0 | DX23: 0 | DY23: 0 | DZ23: =SUM(DT23:DY23) -> 0 | ED23: سعودي | EE23: أنثى | EF23: 0 | EG23: 0 | EH23: 0 | EI23: 0 | EJ23: 0 | EK23: 0 | EL23: =SUM(EF23:EK23) -> 0 | EP23: سعودي | EQ23: أنثى | ER23: =SUM(EF23) -> 0 | ES23: =SUM(EG23) -> 0 | ET23: =SUM(EH23) -> 0 | EU23: =SUM(EI23) -> 0 | EV23: =SUM(EJ23) -> 0 | EW23: =SUM(EK23) -> 0 | EX23: =SUM(ER23:EW23) -> 0
B24: المجموع | D24: =SUM(D20:D23) -> 2983 | E24: =SUM(E20:E23) -> 14375 | F24: =SUM(F20:F23) -> 14787 | G24: =SUM(G20:G23) -> 5336 | H24: =SUM(H20:H23) -> 3769 | I24: =SUM(I20:I23) -> 2009 | J24: =SUM(J20:J23) -> 43259 | K24: =SUM(K20:K23) -> 12226 | N24: المجموع | P24: =SUM(P20:P23) -> 2983 | Q24: =SUM(Q20:Q23) -> 14375 | R24: =SUM(R20:R23) -> 14787 | S24: =SUM(S20:S23) -> 5336 | T24: =SUM(T20:T23) -> 3769 | U24: =SUM(U20:U23) -> 2009 | V24: =SUM(V20:V23) -> 43259 | W24: =SUM(W20:W23) -> 12226 | Z24: المجموع | AB24: =SUM(AB20:AB23) -> 2983 | AC24: =SUM(AC20:AC23) -> 14375 | AD24: =SUM(AD20:AD23) -> 14787 | AE24: =SUM(AE20:AE23) -> 5336 | AF24: =SUM(AF20:AF23) -> 3769 | AG24: =SUM(AG20:AG23) -> 2009 | AH24: =SUM(AH20:AH23) -> 43259 | AI24: =SUM(AI20:AI23) -> 12226 | AL24: المجموع | AN24: =SUM(AN20:AN23) -> 2983 | AO24: =SUM(AO20:AO23) -> 14375 | AP24: =SUM(AP20:AP23) -> 14787 | AQ24: =SUM(AQ20:AQ23) -> 5336 | AR24: =SUM(AR20:AR23) -> 3769 | AS24: =SUM(AS20:AS23) -> 2009 | AT24: =SUM(AT20:AT23) -> 43259 | AU24: =SUM(AU20:AU23) -> 12226 | AX24: المجموع | AZ24: =SUM(AZ20:AZ23) -> 2983 | BA24: =SUM(BA20:BA23) -> 14375 | BB24: =SUM(BB20:BB23) -> 14787 | BC24: =SUM(BC20:BC23) -> 5336 | BD24: =SUM(BD20:BD23) -> 3769 | BE24: =SUM(BE20:BE23) -> 2009 | BF24: =SUM(BF20:BF23) -> 43259 | BG24: =SUM(BG20:BG23) -> 12226 | BJ24: المجموع | BL24: =SUM(BL20:BL23) -> 2983 | BM24: =SUM(BM20:BM23) -> 14375 | BN24: =SUM(BN20:BN23) -> 14787 | BO24: =SUM(BO20:BO23) -> 5336 | BP24: =SUM(BP20:BP23) -> 3769 | BQ24: =SUM(BQ20:BQ23) -> 2009 | BR24: =SUM(BR20:BR23) -> 43259 | BS24: =SUM(BS20:BS23) -> 12226 | BV24: المجموع | BX24: =SUM(BX20:BX23) -> 2983 | BY24: =SUM(BY20:BY23) -> 14375 | BZ24: =SUM(BZ20:BZ23) -> 14787 | CA24: =SUM(CA20:CA23) -> 5336 | CB24: =SUM(CB20:CB23) -> 3769 | CC24: =SUM(CC20:CC23) -> 2009 | CD24: =SUM(CD20:CD23) -> 43259 | CE24: =SUM(CE20:CE23) -> 12226 | CH24: المجموع | CJ24: =SUM(CJ20:CJ23) -> 2983 | CK24: =SUM(CK20:CK23) -> 14375 | CL24: =SUM(CL20:CL23) -> 14787 | CM24: =SUM(CM20:CM23) -> 5336 | CN24: =SUM(CN20:CN23) -> 3769 | CO24: =SUM(CO20:CO23) -> 2009 | CP24: =SUM(CP20:CP23) -> 43259 | CQ24: =SUM(CQ20:CQ23) -> 12226 | CT24: المجموع | CV24: =SUM(CV20:CV23) -> 2983 | CW24: =SUM(CW20:CW23) -> 14375 | CX24: =SUM(CX20:CX23) -> 14787 | CY24: =SUM(CY20:CY23) -> 5336 | CZ24: =SUM(CZ20:CZ23) -> 3769 | DA24: =SUM(DA20:DA23) -> 2009 | DB24: =SUM(DB20:DB23) -> 43259 | DC24: =SUM(DC20:DC23) -> 12226 | DF24: المجموع | DH24: =SUM(DH20:DH23) -> 0 | DI24: =SUM(DI20:DI23) -> 0 | DJ24: =SUM(DJ20:DJ23) -> 0 | DK24: =SUM(DK20:DK23) -> 0 | DL24: =SUM(DL20:DL23) -> 0 | DM24: =SUM(DM20:DM23) -> 0 | DN24: =SUM(DN20:DN23) -> 0 | DO24: =SUM(DO20:DO23) -> 0 | DR24: المجموع | DT24: =SUM(DT20:DT23) -> 0 | DU24: =SUM(DU20:DU23) -> 0 | DV24: =SUM(DV20:DV23) -> 0 | DW24: =SUM(DW20:DW23) -> 0 | DX24: =SUM(DX20:DX23) -> 0 | DY24: =SUM(DY20:DY23) -> 0 | DZ24: =SUM(DZ20:DZ23) -> 0 | EA24: =SUM(EA20:EA23) -> 0 | ED24: المجموع | EF24: =SUM(EF20:EF23) -> 0 | EG24: =SUM(EG20:EG23) -> 0 | EH24: =SUM(EH20:EH23) -> 0 | EI24: =SUM(EI20:EI23) -> 0 | EJ24: =SUM(EJ20:EJ23) -> 0 | EK24: =SUM(EK20:EK23) -> 0 | EL24: =SUM(EL20:EL23) -> 0 | EM24: =SUM(EM20:EM23) -> 0 | EP24: المجموع | ER24: =SUM(ER20:ER23) -> 0 | ES24: =SUM(ES20:ES23) -> 0 | ET24: =SUM(ET20:ET23) -> 0 | EU24: =SUM(EU20:EU23) -> 0 | EV24: =SUM(EV20:EV23) -> 0 | EW24: =SUM(EW20:EW23) -> 0 | EX24: =SUM(EX20:EX23) -> 0 | EY24: =SUM(EY20:EY23) -> 0
A25: الروابي | B25: سعودي | C25: ذكر | D25: 0 | E25: 0 | F25: 0 | G25: 0 | H25: 0 | I25: 0 | J25: =SUM(D25:I25) -> 0 | K25: 0 | M25: الروابي | N25: سعودي | O25: ذكر | P25: 0 | Q25: 0 | R25: 0 | S25: 0 | T25: 0 | U25: 0 | V25: =SUM(P25:U25) -> 0 | W25: 0 | Y25: الروابي | Z25: سعودي | AA25: ذكر | AB25: 0 | AC25: 0 | AD25: 0 | AE25: 0 | AF25: 0 | AG25: 0 | AH25: =SUM(AB25:AG25) -> 0 | AI25: 0 | AK25: الروابي | AL25: سعودي | AM25: ذكر | AN25: 0 | AO25: 0 | AP25: 0 | AQ25: 0 | AR25: 0 | AS25: 0 | AT25: =SUM(AN25:AS25) -> 0 | AU25: 0 | AW25: الروابي | AX25: سعودي | AY25: ذكر | AZ25: 0 | BA25: 0 | BB25: 0 | BC25: 0 | BD25: 0 | BE25: 0 | BF25: =SUM(AZ25:BE25) -> 0 | BG25: 0 | BI25: الروابي | BJ25: سعودي | BK25: ذكر | BL25: 0 | BM25: 0 | BN25: 0 | BO25: 0 | BP25: 0 | BQ25: 0 | BR25: =SUM(BL25:BQ25) -> 0 | BS25: 0 | BU25: الروابي | BV25: سعودي | BW25: ذكر | BX25: 0 | BY25: 0 | BZ25: 0 | CA25: 0 | CB25: 0 | CC25: 0 | CD25: =SUM(BX25:CC25) -> 0 | CE25: 0 | CG25: الروابي | CH25: سعودي | CI25: ذكر | CJ25: 0 | CK25: 0 | CL25: 0 | CM25: 0 | CN25: 0 | CO25: 0 | CP25: =SUM(CJ25:CO25) -> 0 | CQ25: 0 | CS25: الروابي | CT25: سعودي | CU25: ذكر | CV25: 0 | CW25: 0 | CX25: 0 | CY25: 0 | CZ25: 0 | DA25: 0 | DB25: =SUM(CV25:DA25) -> 0 | DC25: 0 | DE25: الروابي | DF25: سعودي | DG25: ذكر | DH25: 0 | DI25: 0 | DJ25: 0 | DK25: 0 | DL25: 0 | DM25: 0 | DN25: =SUM(DH25:DM25) -> 0 | DO25: 0 | DQ25: الروابي | DR25: سعودي | DS25: ذكر | DT25: 0 | DU25: 0 | DV25: 0 | DW25: 0 | DX25: 0 | DY25: 0 | DZ25: =SUM(DT25:DY25) -> 0 | EA25: 0 | EC25: الروابي | ED25: سعودي | EE25: ذكر | EF25: 0 | EG25: 0 | EH25: 0 | EI25: 0 | EJ25: 0 | EK25: 0 | EL25: =SUM(EF25:EK25) -> 0 | EM25: 0 | EO25: =EC25 -> الروابي | EP25: سعودي | EQ25: ذكر | ER25: =SUM(EF25) -> 0 | ES25: =SUM(EG25) -> 0 | ET25: =SUM(EH25) -> 0 | EU25: =SUM(EI25) -> 0 | EV25: =SUM(EJ25) -> 0 | EW25: =SUM(EK25) -> 0 | EX25: =SUM(ER25:EW25) -> 0 | EY25: =SUM(EM25) -> 0
C26: أنثى | D26: 0 | E26: 0 | F26: 0 | G26: 0 | H26: 0 | I26: 0 | J26: =SUM(D26:I26) -> 0 | O26: أنثى | P26: 0 | Q26: 0 | R26: 0 | S26: 0 | T26: 0 | U26: 0 | V26: =SUM(P26:U26) -> 0 | AA26: أنثى | AB26: 0 | AC26: 0 | AD26: 0 | AE26: 0 | AF26: 0 | AG26: 0 | AH26: =SUM(AB26:AG26) -> 0 | AM26: أنثى | AN26: 0 | AO26: 0 | AP26: 0 | AQ26: 0 | AR26: 0 | AS26: 0 | AT26: =SUM(AN26:AS26) -> 0 | AY26: أنثى | AZ26: 0 | BA26: 0 | BB26: 0 | BC26: 0 | BD26: 0 | BE26: 0 | BF26: =SUM(AZ26:BE26) -> 0 | BK26: أنثى | BL26: 0 | BM26: 0 | BN26: 0 | BO26: 0 | BP26: 0 | BQ26: 0 | BR26: =SUM(BL26:BQ26) -> 0 | BW26: أنثى | BX26: 0 | BY26: 0 | BZ26: 0 | CA26: 0 | CB26: 0 | CC26: 0 | CD26: =SUM(BX26:CC26) -> 0 | CI26: أنثى | CJ26: 0 | CK26: 0 | CL26: 0 | CM26: 0 | CN26: 0 | CO26: 0 | CP26: =SUM(CJ26:CO26) -> 0 | CU26: أنثى | CV26: 0 | CW26: 0 | CX26: 0 | CY26: 0 | CZ26: 0 | DA26: 0 | DB26: =SUM(CV26:DA26) -> 0 | DG26: أنثى | DH26: 0 | DI26: 0 | DJ26: 0 | DK26: 0 | DL26: 0 | DM26: 0 | DN26: =SUM(DH26:DM26) -> 0 | DS26: أنثى | DT26: 0 | DU26: 0 | DV26: 0 | DW26: 0 | DX26: 0 | DY26: 0 | DZ26: =SUM(DT26:DY26) -> 0 | EE26: أنثى | EF26: 0 | EG26: 0 | EH26: 0 | EI26: 0 | EJ26: 0 | EK26: 0 | EL26: =SUM(EF26:EK26) -> 0 | EQ26: أنثى | ER26: =SUM(EF26) -> 0 | ES26: =SUM(EG26) -> 0 | ET26: =SUM(EH26) -> 0 | EU26: =SUM(EI26) -> 0 | EV26: =SUM(EJ26) -> 0 | EW26: =SUM(EK26) -> 0 | EX26: =SUM(ER26:EW26) -> 0
B27: غير | C27: ذكر | D27: 0 | E27: 0 | F27: 0 | G27: 0 | H27: 0 | I27: 0 | J27: =SUM(D27:I27) -> 0 | K27: 0 | N27: غير | O27: ذكر | P27: 0 | Q27: 0 | R27: 0 | S27: 0 | T27: 0 | U27: 0 | V27: =SUM(P27:U27) -> 0 | W27: 0 | Z27: غير | AA27: ذكر | AB27: 0 | AC27: 0 | AD27: 0 | AE27: 0 | AF27: 0 | AG27: 0 | AH27: =SUM(AB27:AG27) -> 0 | AI27: 0 | AL27: غير | AM27: ذكر | AN27: 0 | AO27: 0 | AP27: 0 | AQ27: 0 | AR27: 0 | AS27: 0 | AT27: =SUM(AN27:AS27) -> 0 | AU27: 0 | AX27: غير | AY27: ذكر | AZ27: 0 | BA27: 0 | BB27: 0 | BC27: 0 | BD27: 0 | BE27: 0 | BF27: =SUM(AZ27:BE27) -> 0 | BG27: 0 | BJ27: غير | BK27: ذكر | BL27: 0 | BM27: 0 | BN27: 0 | BO27: 0 | BP27: 0 | BQ27: 0 | BR27: =SUM(BL27:BQ27) -> 0 | BS27: 0 | BV27: غير | BW27: ذكر | BX27: 0 | BY27: 0 | BZ27: 0 | CA27: 0 | CB27: 0 | CC27: 0 | CD27: =SUM(BX27:CC27) -> 0 | CE27: 0 | CH27: غير | CI27: ذكر | CJ27: 0 | CK27: 0 | CL27: 0 | CM27: 0 | CN27: 0 | CO27: 0 | CP27: =SUM(CJ27:CO27) -> 0 | CQ27: 0 | CT27: غير | CU27: ذكر | CV27: 0 | CW27: 0 | CX27: 0 | CY27: 0 | CZ27: 0 | DA27: 0 | DB27: =SUM(CV27:DA27) -> 0 | DC27: 0 | DF27: غير | DG27: ذكر | DH27: 0 | DI27: 0 | DJ27: 0 | DK27: 0 | DL27: 0 | DM27: 0 | DN27: =SUM(DH27:DM27) -> 0 | DO27: 0 | DR27: غير | DS27: ذكر | DT27: 0 | DU27: 0 | DV27: 0 | DW27: 0 | DX27: 0 | DY27: 0 | DZ27: =SUM(DT27:DY27) -> 0 | EA27: 0 | ED27: غير | EE27: ذكر | EF27: 0 | EG27: 0 | EH27: 0 | EI27: 0 | EJ27: 0 | EK27: 0 | EL27: =SUM(EF27:EK27) -> 0 | EM27: 0 | EP27: غير | EQ27: ذكر | ER27: =SUM(EF27) -> 0 | ES27: =SUM(EG27) -> 0 | ET27: =SUM(EH27) -> 0 | EU27: =SUM(EI27) -> 0 | EV27: =SUM(EJ27) -> 0 | EW27: =SUM(EK27) -> 0 | EX27: =SUM(ER27:EW27) -> 0 | EY27: =SUM(EM27) -> 0
B28: سعودي | C28: أنثى | D28: 0 | E28: 0 | F28: 0 | G28: 0 | H28: 0 | I28: 0 | J28: =SUM(D28:I28) -> 0 | N28: سعودي | O28: أنثى | P28: 0 | Q28: 0 | R28: 0 | S28: 0 | T28: 0 | U28: 0 | V28: =SUM(P28:U28) -> 0 | Z28: سعودي | AA28: أنثى | AB28: 0 | AC28: 0 | AD28: 0 | AE28: 0 | AF28: 0 | AG28: 0 | AH28: =SUM(AB28:AG28) -> 0 | AL28: سعودي | AM28: أنثى | AN28: 0 | AO28: 0 | AP28: 0 | AQ28: 0 | AR28: 0 | AS28: 0 | AT28: =SUM(AN28:AS28) -> 0 | AX28: سعودي | AY28: أنثى | AZ28: 0 | BA28: 0 | BB28: 0 | BC28: 0 | BD28: 0 | BE28: 0 | BF28: =SUM(AZ28:BE28) -> 0 | BJ28: سعودي | BK28: أنثى | BL28: 0 | BM28: 0 | BN28: 0 | BO28: 0 | BP28: 0 | BQ28: 0 | BR28: =SUM(BL28:BQ28) -> 0 | BV28: سعودي | BW28: أنثى | BX28: 0 | BY28: 0 | BZ28: 0 | CA28: 0 | CB28: 0 | CC28: 0 | CD28: =SUM(BX28:CC28) -> 0 | CH28: سعودي | CI28: أنثى | CJ28: 0 | CK28: 0 | CL28: 0 | CM28: 0 | CN28: 0 | CO28: 0 | CP28: =SUM(CJ28:CO28) -> 0 | CT28: سعودي | CU28: أنثى | CV28: 0 | CW28: 0 | CX28: 0 | CY28: 0 | CZ28: 0 | DA28: 0 | DB28: =SUM(CV28:DA28) -> 0 | DF28: سعودي | DG28: أنثى | DH28: 0 | DI28: 0 | DJ28: 0 | DK28: 0 | DL28: 0 | DM28: 0 | DN28: =SUM(DH28:DM28) -> 0 | DR28: سعودي | DS28: أنثى | DT28: 0 | DU28: 0 | DV28: 0 | DW28: 0 | DX28: 0 | DY28: 0 | DZ28: =SUM(DT28:DY28) -> 0 | ED28: سعودي | EE28: أنثى | EF28: 0 | EG28: 0 | EH28: 0 | EI28: 0 | EJ28: 0 | EK28: 0 | EL28: =SUM(EF28:EK28) -> 0 | EP28: سعودي | EQ28: أنثى | ER28: =SUM(EF28) -> 0 | ES28: =SUM(EG28) -> 0 | ET28: =SUM(EH28) -> 0 | EU28: =SUM(EI28) -> 0 | EV28: =SUM(EJ28) -> 0 | EW28: =SUM(EK28) -> 0 | EX28: =SUM(ER28:EW28) -> 0
B29: المجموع | D29: =SUM(D25:D28) -> 0 | E29: =SUM(E25:E28) -> 0 | F29: =SUM(F25:F28) -> 0 | G29: =SUM(G25:G28) -> 0 | H29: =SUM(H25:H28) -> 0 | I29: =SUM(I25:I28) -> 0 | J29: =SUM(J25:J28) -> 0 | K29: =SUM(K25:K28) -> 0 | N29: المجموع | P29: =SUM(P25:P28) -> 0 | Q29: =SUM(Q25:Q28) -> 0 | R29: =SUM(R25:R28) -> 0 | S29: =SUM(S25:S28) -> 0 | T29: =SUM(T25:T28) -> 0 | U29: =SUM(U25:U28) -> 0 | V29: =SUM(V25:V28) -> 0 | W29: =SUM(W25:W28) -> 0 | Z29: المجموع | AB29: =SUM(AB25:AB28) -> 0 | AC29: =SUM(AC25:AC28) -> 0 | AD29: =SUM(AD25:AD28) -> 0 | AE29: =SUM(AE25:AE28) -> 0 | AF29: =SUM(AF25:AF28) -> 0 | AG29: =SUM(AG25:AG28) -> 0 | AH29: =SUM(AH25:AH28) -> 0 | AI29: =SUM(AI25:AI28) -> 0 | AL29: المجموع | AN29: =SUM(AN25:AN28) -> 0 | AO29: =SUM(AO25:AO28) -> 0 | AP29: =SUM(AP25:AP28) -> 0 | AQ29: =SUM(AQ25:AQ28) -> 0 | AR29: =SUM(AR25:AR28) -> 0 | AS29: =SUM(AS25:AS28) -> 0 | AT29: =SUM(AT25:AT28) -> 0 | AU29: =SUM(AU25:AU28) -> 0 | AX29: المجموع | AZ29: =SUM(AZ25:AZ28) -> 0 | BA29: =SUM(BA25:BA28) -> 0 | BB29: =SUM(BB25:BB28) -> 0 | BC29: =SUM(BC25:BC28) -> 0 | BD29: =SUM(BD25:BD28) -> 0 | BE29: =SUM(BE25:BE28) -> 0 | BF29: =SUM(BF25:BF28) -> 0 | BG29: =SUM(BG25:BG28) -> 0 | BJ29: المجموع | BL29: =SUM(BL25:BL28) -> 0 | BM29: =SUM(BM25:BM28) -> 0 | BN29: =SUM(BN25:BN28) -> 0 | BO29: =SUM(BO25:BO28) -> 0 | BP29: =SUM(BP25:BP28) -> 0 | BQ29: =SUM(BQ25:BQ28) -> 0 | BR29: =SUM(BR25:BR28) -> 0 | BS29: =SUM(BS25:BS28) -> 0 | BV29: المجموع | BX29: =SUM(BX25:BX28) -> 0 | BY29: =SUM(BY25:BY28) -> 0 | BZ29: =SUM(BZ25:BZ28) -> 0 | CA29: =SUM(CA25:CA28) -> 0 | CB29: =SUM(CB25:CB28) -> 0 | CC29: =SUM(CC25:CC28) -> 0 | CD29: =SUM(CD25:CD28) -> 0 | CE29: =SUM(CE25:CE28) -> 0 | CH29: المجموع | CJ29: =SUM(CJ25:CJ28) -> 0 | CK29: =SUM(CK25:CK28) -> 0 | CL29: =SUM(CL25:CL28) -> 0 | CM29: =SUM(CM25:CM28) -> 0 | CN29: =SUM(CN25:CN28) -> 0 | CO29: =SUM(CO25:CO28) -> 0 | CP29: =SUM(CP25:CP28) -> 0 | CQ29: =SUM(CQ25:CQ28) -> 0 | CT29: المجموع | CV29: =SUM(CV25:CV28) -> 0 | CW29: =SUM(CW25:CW28) -> 0 | CX29: =SUM(CX25:CX28) -> 0 | CY29: =SUM(CY25:CY28) -> 0 | CZ29: =SUM(CZ25:CZ28) -> 0 | DA29: =SUM(DA25:DA28) -> 0 | DB29: =SUM(DB25:DB28) -> 0 | DC29: =SUM(DC25:DC28) -> 0 | DF29: المجموع | DH29: =SUM(DH25:DH28) -> 0 | DI29: =SUM(DI25:DI28) -> 0 | DJ29: =SUM(DJ25:DJ28) -> 0 | DK29: =SUM(DK25:DK28) -> 0 | DL29: =SUM(DL25:DL28) -> 0 | DM29: =SUM(DM25:DM28) -> 0 | DN29: =SUM(DN25:DN28) -> 0 | DO29: =SUM(DO25:DO28) -> 0 | DR29: المجموع | DT29: =SUM(DT25:DT28) -> 0 | DU29: =SUM(DU25:DU28) -> 0 | DV29: =SUM(DV25:DV28) -> 0 | DW29: =SUM(DW25:DW28) -> 0 | DX29: =SUM(DX25:DX28) -> 0 | DY29: =SUM(DY25:DY28) -> 0 | DZ29: =SUM(DZ25:DZ28) -> 0 | EA29: =SUM(EA25:EA28) -> 0 | ED29: المجموع | EF29: =SUM(EF25:EF28) -> 0 | EG29: =SUM(EG25:EG28) -> 0 | EH29: =SUM(EH25:EH28) -> 0 | EI29: =SUM(EI25:EI28) -> 0 | EJ29: =SUM(EJ25:EJ28) -> 0 | EK29: =SUM(EK25:EK28) -> 0 | EL29: =SUM(EL25:EL28) -> 0 | EM29: =SUM(EM25:EM28) -> 0 | EP29: المجموع | ER29: =SUM(ER25:ER28) -> 0 | ES29: =SUM(ES25:ES28) -> 0 | ET29: =SUM(ET25:ET28) -> 0 | EU29: =SUM(EU25:EU28) -> 0 | EV29: =SUM(EV25:EV28) -> 0 | EW29: =SUM(EW25:EW28) -> 0 | EX29: =SUM(EX25:EX28) -> 0 | EY29: =SUM(EY25:EY28) -> 0
A30: قويزة | B30: سعودي | C30: ذكر | D30: 755 | E30: 4728 | F30: 7927 | G30: 9930 | H30: 2329 | I30: 889 | J30: =SUM(D30:I30) -> 26558 | K30: 7276 | M30: قويزة | N30: سعودي | O30: ذكر | P30: 755 | Q30: 4728 | R30: 7927 | S30: 9930 | T30: 2329 | U30: 889 | V30: =SUM(P30:U30) -> 26558 | W30: 7276 | Y30: قويزة | Z30: سعودي | AA30: ذكر | AB30: 755 | AC30: 4728 | AD30: 7927 | AE30: 9930 | AF30: 2329 | AG30: 889 | AH30: =SUM(AB30:AG30) -> 26558 | AI30: 7276 | AK30: قويزة | AL30: سعودي | AM30: ذكر | AN30: 755 | AO30: 4728 | AP30: 7927 | AQ30: 9930 | AR30: 2329 | AS30: 889 | AT30: =SUM(AN30:AS30) -> 26558 | AU30: 7276 | AW30: قويزة | AX30: سعودي | AY30: ذكر | AZ30: 755 | BA30: 4728 | BB30: 7927 | BC30: 9930 | BD30: 2329 | BE30: 889 | BF30: =SUM(AZ30:BE30) -> 26558 | BG30: 7276 | BI30: قويزة | BJ30: سعودي | BK30: ذكر | BL30: 755 | BM30: 4728 | BN30: 7927 | BO30: 9930 | BP30: 2329 | BQ30: 889 | BR30: =SUM(BL30:BQ30) -> 26558 | BS30: 7276 | BU30: قويزة | BV30: سعودي | BW30: ذكر | BX30: 755 | BY30: 4728 | BZ30: 7927 | CA30: 9930 | CB30: 2329 | CC30: 889 | CD30: =SUM(BX30:CC30) -> 26558 | CE30: 7276 | CG30: قويزة | CH30: سعودي | CI30: ذكر | CJ30: 755 | CK30: 4728 | CL30: 7927 | CM30: 9930 | CN30: 2329 | CO30: 889 | CP30: =SUM(CJ30:CO30) -> 26558 | CQ30: 7276 | CS30: قويزة | CT30: سعودي | CU30: ذكر | CV30: 755 | CW30: 4728 | CX30: 7927 | CY30: 9930 | CZ30: 2329 | DA30: 889 | DB30: =SUM(CV30:DA30) -> 26558 | DC30: 7276 | DE30: قويزة | DF30: سعودي | DG30: ذكر | DH30: 0 | DI30: 0 | DJ30: 0 | DK30: 0 | DL30: 0 | DM30: 0 | DN30: =SUM(DH30:DM30) -> 0 | DO30: 0 | DQ30: قويزة | DR30: سعودي | DS30: ذكر | DT30: 0 | DU30: 0 | DV30: 0 | DW30: 0 | DX30: 0 | DY30: 0 | DZ30: =SUM(DT30:DY30) -> 0 | EA30: 0 | EC30: قويزة | ED30: سعودي | EE30: ذكر | EF30: 0 | EG30: 0 | EH30: 0 | EI30: 0 | EJ30: 0 | EK30: 0 | EL30: =SUM(EF30:EK30) -> 0 | EM30: 0 | EO30: =EC30 -> قويزة | EP30: سعودي | EQ30: ذكر | ER30: =SUM(EF30) -> 0 | ES30: =SUM(EG30) -> 0 | ET30: =SUM(EH30) -> 0 | EU30: =SUM(EI30) -> 0 | EV30: =SUM(EJ30) -> 0 | EW30: =SUM(EK30) -> 0 | EX30: =SUM(ER30:EW30) -> 0 | EY30: =SUM(EM30) -> 0
C31: أنثى | D31: 613 | E31: 4656 | F31: 6603 | G31: 11493 | H31: 1956 | I31: 566 | J31: =SUM(D31:I31) -> 25887 | O31: أنثى | P31: 613 | Q31: 4656 | R31: 6603 | S31: 11493 | T31: 1956 | U31: 566 | V31: =SUM(P31:U31) -> 25887 | AA31: أنثى | AB31: 613 | AC31: 4656 | AD31: 6603 | AE31: 11493 | AF31: 1956 | AG31: 566 | AH31: =SUM(AB31:AG31) -> 25887 | AM31: أنثى | AN31: 613 | AO31: 4656 | AP31: 6603 | AQ31: 11493 | AR31: 1956 | AS31: 566 | AT31: =SUM(AN31:AS31) -> 25887 | AY31: أنثى | AZ31: 613 | BA31: 4656 | BB31: 6603 | BC31: 11493 | BD31: 1956 | BE31: 566 | BF31: =SUM(AZ31:BE31) -> 25887 | BK31: أنثى | BL31: 613 | BM31: 4656 | BN31: 6603 | BO31: 11493 | BP31: 1956 | BQ31: 566 | BR31: =SUM(BL31:BQ31) -> 25887 | BW31: أنثى | BX31: 613 | BY31: 4656 | BZ31: 6603 | CA31: 11493 | CB31: 1956 | CC31: 566 | CD31: =SUM(BX31:CC31) -> 25887 | CI31: أنثى | CJ31: 613 | CK31: 4656 | CL31: 6603 | CM31: 11493 | CN31: 1956 | CO31: 566 | CP31: =SUM(CJ31:CO31) -> 25887 | CU31: أنثى | CV31: 613 | CW31: 4656 | CX31: 6603 | CY31: 11493 | CZ31: 1956 | DA31: 566 | DB31: =SUM(CV31:DA31) -> 25887 | DG31: أنثى | DH31: 0 | DI31: 0 | DJ31: 0 | DK31: 0 | DL31: 0 | DM31: 0 | DN31: =SUM(DH31:DM31) -> 0 | DS31: أنثى | DT31: 0 | DU31: 0 | DV31: 0 | DW31: 0 | DX31: 0 | DY31: 0 | DZ31: =SUM(DT31:DY31) -> 0 | EE31: أنثى | EF31: 0 | EG31: 0 | EH31: 0 | EI31: 0 | EJ31: 0 | EK31: 0 | EL31: =SUM(EF31:EK31) -> 0 | EQ31: أنثى | ER31: =SUM(EF31) -> 0 | ES31: =SUM(EG31) -> 0 | ET31: =SUM(EH31) -> 0 | EU31: =SUM(EI31) -> 0 | EV31: =SUM(EJ31) -> 0 | EW31: =SUM(EK31) -> 0 | EX31: =SUM(ER31:EW31) -> 0
