Workbook

Sheet نتائج إيجابية
A2: 12 ـ ب :النتائج الإيجابية | F2: شهر | G2: 1 | H2: عام | I2: 1447 | J2: هـ | L2: 12 ـ ب :النتائج الإيجابية | Q2: شهر | R2: 2 | S2: عام | T2: 1447 | U2: هـ | W2: 12 ـ ب :النتائج الإيجابية | AB2: شهر | AC2: 3 | AD2: عام | AE2: 1447 | AF2: هـ | AH2: 12 ـ ب :النتائج الإيجابية | AM2: شهر | AN2: 4 | AO2: عام | AP2: 1447 | AQ2: هـ | AS2: 12 ـ ب :النتائج الإيجابية | AX2: شهر | AY2: 5 | AZ2: عام | BA2: 1447 | BB2: هـ | BD2: 12 ـ ب :النتائج الإيجابية | BI2: شهر | BJ2: 6 | BK2: عام | BL2: 1447 | BM2: هـ | BO2: 12 ـ ب :النتائج الإيجابية | BT2: شهر | BU2: 7 | BV2: عام | BW2: 1447 | BX2: هـ | BZ2: 12 ـ ب :النتائج الإيجابية | CE2: شهر | CF2: 8 | CG2: عام | CH2: 1447 | CI2: هـ | CK2: 12 ـ ب :النتائج الإيجابية | CP2: شهر | CQ2: 9 | CR2: عام | CS2: 1447 | CT2: هـ | CV2: 12 ـ ب :النتائج الإيجابية | DA2: شهر | DB2: 10 | DC2: عام | DD2: 1447 | DE2: هـ | DG2: 12 ـ ب :النتائج الإيجابية | DL2: شهر | DM2: 11 | DN2: عام | DO2: 1447 | DP2: هـ | DR2: 12 ـ ب :النتائج الإيجابية | DW2: شهر | DX2: 12 | DY2: عام | DZ2: 1447 | EA2: هـ | EC2: 12 ـ ب :النتائج الإيجابية | EJ2: عام | EK2: =SUM(DZ2) -> 1447 | EL2: هـ
A4: المركز الصحي | B4: نوع الإصابة ( العددالإيجابي من عدد الفحوصات ) | D4: بلهارسيا بولية | E4: بلهارسيا معوية | F4: دوسنتاريا | G4: ملاريا | H4: حمل | I4: أخرى | J4: المجموع | L4: المركز الصحي | M4: نوع الإصابة ( العددالإيجابي من عدد الفحوصات ) | O4: بلهارسيا بولية | P4: بلهارسيا معوية | Q4: دوسنتاريا | R4: ملاريا | S4: حمل | T4: أخرى | U4: المجموع | W4: المركز الصحي | X4: نوع الإصابة ( العددالإيجابي من عدد الفحوصات ) | Z4: بلهارسيا بولية | AA4: بلهارسيا معوية | AB4: دوسنتاريا | AC4: ملاريا | AD4: حمل | AE4: أخرى | AF4: المجموع | AH4: المركز الصحي | AI4: نوع الإصابة ( العددالإيجابي من عدد الفحوصات ) | AK4: بلهارسيا بولية | AL4: بلهارسيا معوية | AM4: دوسنتاريا | AN4: ملاريا | AO4: حمل | AP4: أخرى | AQ4: المجموع | AS4: المركز الصحي | AT4: نوع الإصابة ( العددالإيجابي من عدد الفحوصات ) | AV4: بلهارسيا بولية | AW4: بلهارسيا معوية | AX4: دوسنتاريا | AY4: ملاريا | AZ4: حمل | BA4: أخرى | BB4: المجموع | BD4: المركز الصحي | BE4: نوع الإصابة ( العددالإيجابي من عدد الفحوصات ) | BG4: بلهارسيا بولية | BH4: بلهارسيا معوية | BI4: دوسنتاريا | BJ4: ملاريا | BK4: حمل | BL4: أخرى | BM4: المجموع | BO4: المركز الصحي | BP4: نوع الإصابة ( العددالإيجابي من عدد الفحوصات ) | BR4: بلهارسيا بولية | BS4: بلهارسيا معوية | BT4: دوسنتاريا | BU4: ملاريا | BV4: حمل | BW4: أخرى | BX4: المجموع | BZ4: المركز الصحي | CA4: نوع الإصابة ( العددالإيجابي من عدد الفحوصات ) | CC4: بلهارسيا بولية | CD4: بلهارسيا معوية | CE4: دوسنتاريا | CF4: ملاريا | CG4: حمل | CH4: أخرى | CI4: المجموع | CK4: المركز الصحي | CL4: نوع الإصابة ( العددالإيجابي من عدد الفحوصات ) | CN4: بلهارسيا بولية | CO4: بلهارسيا معوية | CP4: دوسنتاريا | CQ4: ملاريا | CR4: حمل | CS4: أخرى | CT4: المجموع | CV4: المركز الصحي | CW4: نوع الإصابة ( العددالإيجابي من عدد الفحوصات ) | CY4: بلهارسيا بولية | CZ4: بلهارسيا معوية | DA4: دوسنتاريا | DB4: ملاريا | DC4: حمل | DD4: أخرى | DE4: المجموع | DG4: المركز الصحي | DH4: نوع الإصابة ( العددالإيجابي من عدد الفحوصات ) | DJ4: بلهارسيا بولية | DK4: بلهارسيا معوية | DL4: دوسنتاريا | DM4: ملاريا | DN4: حمل | DO4: أخرى | DP4: المجموع | DR4: المركز الصحي | DS4: نوع الإصابة ( العددالإيجابي من عدد الفحوصات ) | DU4: بلهارسيا بولية | DV4: بلهارسيا معوية | DW4: دوسنتاريا | DX4: ملاريا | DY4: حمل | DZ4: أخرى | EA4: المجموع | EC4: المركز الصحي | ED4: نوع الإصابة ( العددالإيجابي من عدد الفحوصات ) | EF4: بلهارسيا بولية | EG4: بلهارسيا معوية | EH4: دوسنتاريا | EI4: ملاريا | EJ4: حمل | EK4: أخرى | EL4: المجموع
A6: الربيع والتوفيق | B6: سعودي | C6: ذكر | D6: 0 | E6: 0 | F6: 0 | G6: 0 | H6: 0 | I6: 0 | J6: =SUM(D6:I6) -> 0 | L6: الربيع والتوفيق | M6: سعودي | N6: ذكر | O6: 0 | P6: 0 | Q6: 0 | R6: 0 | S6: 0 | T6: 0 | U6: =SUM(O6:T6) -> 0 | W6: الربيع والتوفيق | X6: سعودي | Y6: ذكر | Z6: 0 | AA6: 0 | AB6: 0 | AC6: 0 | AD6: 0 | AE6: 0 | AF6: =SUM(Z6:AE6) -> 0 | AH6: الربيع والتوفيق | AI6: سعودي | AJ6: ذكر | AK6: 0 | AL6: 0 | AM6: 0 | AN6: 0 | AO6: 0 | AP6: 0 | AQ6: =SUM(AK6:AP6) -> 0 | AS6: الربيع والتوفيق | AT6: سعودي | AU6: ذكر | AV6: 0 | AW6: 0 | AX6: 0 | AY6: 0 | AZ6: 0 | BA6: 0 | BB6: =SUM(AV6:BA6) -> 0 | BD6: الربيع والتوفيق | BE6: سعودي | BF6: ذكر | BG6: 0 | BH6: 0 | BI6: 0 | BJ6: 0 | BK6: 0 | BL6: 0 | BM6: =SUM(BG6:BL6) -> 0 | BO6: الربيع والتوفيق | BP6: سعودي | BQ6: ذكر | BR6: 0 | BS6: 0 | BT6: 0 | BU6: 0 | BV6: 0 | BW6: 0 | BX6: =SUM(BR6:BW6) -> 0 | BZ6: الربيع والتوفيق | CA6: سعودي | CB6: ذكر | CC6: 0 | CD6: 0 | CE6: 0 | CF6: 0 | CG6: 0 | CH6: 0 | CI6: =SUM(CC6:CH6) -> 0 | CK6: الربيع والتوفيق | CL6: سعودي | CM6: ذكر | CN6: 0 | CO6: 0 | CP6: 0 | CQ6: 0 | CR6: 0 | CS6: 0 | CT6: =SUM(CN6:CS6) -> 0 | CV6: الربيع والتوفيق | CW6: سعودي | CX6: ذكر | CY6: 0 | CZ6: 0 | DA6: 0 | DB6: 0 | DC6: 0 | DD6: 0 | DE6: =SUM(CY6:DD6) -> 0 | DG6: الربيع والتوفيق | DH6: سعودي | DI6: ذكر | DJ6: 0 | DK6: 0 | DL6: 0 | DM6: 0 | DN6: 0 | DO6: 0 | DP6: =SUM(DJ6:DO6) -> 0 | DR6: الربيع والتوفيق | DS6: سعودي | DT6: ذكر | DU6: 0 | DV6: 0 | DW6: 0 | DX6: 0 | DY6: 0 | DZ6: 0 | EA6: =SUM(DU6:DZ6) -> 0 | EC6: =DR6 -> الربيع والتوفيق | ED6: سعودي | EE6: ذكر | EF6: =SUM(D6+O6+Z6+AK6+AV6+BG6+BR6+CC6+CN6+CY6+DJ6+DU6) -> 0 | EG6: =SUM(E6+P6+AA6+AL6+AW6+BH6+BS6+CD6+CO6+CZ6+DK6+DV6) -> 0 | EH6: =SUM(F6+Q6+AB6+AM6+AX6+BI6+BT6+CE6+CP6+DA6+DL6+DW6) -> 0 | EI6: =SUM(G6+R6+AC6+AN6+AY6+BJ6+BU6+CF6+CQ6+DB6+DM6+DX6) -> 0 | EJ6: 0 | EK6: =SUM(I6+T6+AE6+AP6+BA6+BL6+BW6+CH6+CS6+DD6+DO6+DZ6) -> 0 | EL6: =SUM(EF6:EK6) -> 0
C7: أنثى | D7: 0 | E7: 0 | F7: 0 | G7: 0 | H7: 0 | I7: 0 | J7: =SUM(D7:I7) -> 0 | N7: أنثى | O7: 0 | P7: 0 | Q7: 0 | R7: 0 | S7: 0 | T7: 0 | U7: =SUM(O7:T7) -> 0 | Y7: أنثى | Z7: 0 | AA7: 0 | AB7: 0 | AC7: 0 | AD7: 0 | AE7: 0 | AF7: =SUM(Z7:AE7) -> 0 | AJ7: أنثى | AK7: 0 | AL7: 0 | AM7: 0 | AN7: 0 | AO7: 0 | AP7: 0 | AQ7: =SUM(AK7:AP7) -> 0 | AU7: أنثى | AV7: 0 | AW7: 0 | AX7: 0 | AY7: 0 | AZ7: 0 | BA7: 0 | BB7: =SUM(AV7:BA7) -> 0 | BF7: أنثى | BG7: 0 | BH7: 0 | BI7: 0 | BJ7: 0 | BK7: 0 | BL7: 0 | BM7: =SUM(BG7:BL7) -> 0 | BQ7: أنثى | BR7: 0 | BS7: 0 | BT7: 0 | BU7: 0 | BV7: 0 | BW7: 0 | BX7: =SUM(BR7:BW7) -> 0 | CB7: أنثى | CC7: 0 | CD7: 0 | CE7: 0 | CF7: 0 | CG7: 0 | CH7: 0 | CI7: =SUM(CC7:CH7) -> 0 | CM7: أنثى | CN7: 0 | CO7: 0 | CP7: 0 | CQ7: 0 | CR7: 0 | CS7: 0 | CT7: =SUM(CN7:CS7) -> 0 | CX7: أنثى | CY7: 0 | CZ7: 0 | DA7: 0 | DB7: 0 | DC7: 0 | DD7: 0 | DE7: =SUM(CY7:DD7) -> 0 | DI7: أنثى | DJ7: 0 | DK7: 0 | DL7: 0 | DM7: 0 | DN7: 0 | DO7: 0 | DP7: =SUM(DJ7:DO7) -> 0 | DT7: أنثى | DU7: 0 | DV7: 0 | DW7: 0 | DX7: 0 | DY7: 0 | DZ7: 0 | EA7: =SUM(DU7:DZ7) -> 0 | EE7: أنثى | EF7: =SUM(D7+O7+Z7+AK7+AV7+BG7+BR7+CC7+CN7+CY7+DJ7+DU7) -> 0 | EG7: =SUM(E7+P7+AA7+AL7+AW7+BH7+BS7+CD7+CO7+CZ7+DK7+DV7) -> 0 | EH7: =SUM(F7+Q7+AB7+AM7+AX7+BI7+BT7+CE7+CP7+DA7+DL7+DW7) -> 0 | EI7: =SUM(G7+R7+AC7+AN7+AY7+BJ7+BU7+CF7+CQ7+DB7+DM7+DX7) -> 0 | EJ7: =SUM(H7+S7+AD7+AO7+AZ7+BK7+BV7+CG7+CR7+DC7+DN7+DY7) -> 0 | EK7: =SUM(I7+T7+AE7+AP7+BA7+BL7+BW7+CH7+CS7+DD7+DO7+DZ7) -> 0 | EL7: =SUM(EF7:EK7) -> 0
B8: مجموع السعوديين | D8: =SUM(D6:D7) -> 0 | E8: =SUM(E6:E7) -> 0 | F8: =SUM(F6:F7) -> 0 | G8: =SUM(G6:G7) -> 0 | H8: =SUM(H6:H7) -> 0 | I8: =SUM(I6:I7) -> 0 | J8: =SUM(J6:J7) -> 0 | M8: مجموع السعوديين | O8: =SUM(O6:O7) -> 0 | P8: =SUM(P6:P7) -> 0 | Q8: =SUM(Q6:Q7) -> 0 | R8: =SUM(R6:R7) -> 0 | S8: =SUM(S6:S7) -> 0 | T8: =SUM(T6:T7) -> 0 | U8: =SUM(U6:U7) -> 0 | X8: مجموع السعوديين | Z8: =SUM(Z6:Z7) -> 0 | AA8: =SUM(AA6:AA7) -> 0 | AB8: =SUM(AB6:AB7) -> 0 | AC8: =SUM(AC6:AC7) -> 0 | AD8: =SUM(AD6:AD7) -> 0 | AE8: =SUM(AE6:AE7) -> 0 | AF8: =SUM(AF6:AF7) -> 0 | AI8: مجموع السعوديين | AK8: =SUM(AK6:AK7) -> 0 | AL8: =SUM(AL6:AL7) -> 0 | AM8: =SUM(AM6:AM7) -> 0 | AN8: =SUM(AN6:AN7) -> 0 | AO8: =SUM(AO6:AO7) -> 0 | AP8: =SUM(AP6:AP7) -> 0 | AQ8: =SUM(AQ6:AQ7) -> 0 | AT8: مجموع السعوديين | AV8: =SUM(AV6:AV7) -> 0 | AW8: =SUM(AW6:AW7) -> 0 | AX8: =SUM(AX6:AX7) -> 0 | AY8: =SUM(AY6:AY7) -> 0 | AZ8: =SUM(AZ6:AZ7) -> 0 | BA8: =SUM(BA6:BA7) -> 0 | BB8: =SUM(BB6:BB7) -> 0 | BE8: مجموع السعوديين | BG8: =SUM(BG6:BG7) -> 0 | BH8: =SUM(BH6:BH7) -> 0 | BI8: =SUM(BI6:BI7) -> 0 | BJ8: =SUM(BJ6:BJ7) -> 0 | BK8: =SUM(BK6:BK7) -> 0 | BL8: =SUM(BL6:BL7) -> 0 | BM8: =SUM(BM6:BM7) -> 0 | BP8: مجموع السعوديين | BR8: =SUM(BR6:BR7) -> 0 | BS8: =SUM(BS6:BS7) -> 0 | BT8: =SUM(BT6:BT7) -> 0 | BU8: =SUM(BU6:BU7) -> 0 | BV8: =SUM(BV6:BV7) -> 0 | BW8: =SUM(BW6:BW7) -> 0 | BX8: =SUM(BX6:BX7) -> 0 | CA8: مجموع السعوديين | CC8: =SUM(CC6:CC7) -> 0 | CD8: =SUM(CD6:CD7) -> 0 | CE8: =SUM(CE6:CE7) -> 0 | CF8: =SUM(CF6:CF7) -> 0 | CG8: =SUM(CG6:CG7) -> 0 | CH8: =SUM(CH6:CH7) -> 0 | CI8: =SUM(CI6:CI7) -> 0 | CL8: مجموع السعوديين | CN8: =SUM(CN6:CN7) -> 0 | CO8: =SUM(CO6:CO7) -> 0 | CP8: =SUM(CP6:CP7) -> 0 | CQ8: =SUM(CQ6:CQ7) -> 0 | CR8: =SUM(CR6:CR7) -> 0 | CS8: =SUM(CS6:CS7) -> 0 | CT8: =SUM(CT6:CT7) -> 0 | CW8: مجموع السعوديين | CY8: =SUM(CY6:CY7) -> 0 | CZ8: =SUM(CZ6:CZ7) -> 0 | DA8: =SUM(DA6:DA7) -> 0 | DB8: =SUM(DB6:DB7) -> 0 | DC8: =SUM(DC6:DC7) -> 0 | DD8: =SUM(DD6:DD7) -> 0 | DE8: =SUM(DE6:DE7) -> 0 | DH8: مجموع السعوديين | DJ8: =SUM(DJ6:DJ7) -> 0 | DK8: =SUM(DK6:DK7) -> 0 | DL8: =SUM(DL6:DL7) -> 0 | DM8: =SUM(DM6:DM7) -> 0 | DN8: =SUM(DN6:DN7) -> 0 | DO8: =SUM(DO6:DO7) -> 0 | DP8: =SUM(DP6:DP7) -> 0 | DS8: مجموع السعوديين | DU8: =SUM(DU6:DU7) -> 0 | DV8: =SUM(DV6:DV7) -> 0 | DW8: =SUM(DW6:DW7) -> 0 | DX8: =SUM(DX6:DX7) -> 0 | DY8: =SUM(DY6:DY7) -> 0 | DZ8: =SUM(DZ6:DZ7) -> 0 | EA8: =SUM(EA6:EA7) -> 0 | ED8: مجموع السعوديين | EF8: =SUM(EF6:EF7) -> 0 | EG8: =SUM(EG6:EG7) -> 0 | EH8: =SUM(EH6:EH7) -> 0 | EI8: =SUM(EI6:EI7) -> 0 | EJ8: =SUM(EJ6:EJ7) -> 0 | EK8: =SUM(EK6:EK7) -> 0 | EL8: =SUM(EL6:EL7) -> 0
B9: غير سعودي | C9: ذكر | D9: 0 | E9: 0 | F9: 0 | G9: 0 | H9: 0 | I9: 0 | J9: =SUM(D9:I9) -> 0 | M9: غير سعودي | N9: ذكر | O9: 0 | P9: 0 | Q9: 0 | R9: 0 | S9: 0 | T9: 0 | U9: =SUM(O9:T9) -> 0 | X9: غير سعودي | Y9: ذكر | Z9: 0 | AA9: 0 | AB9: 0 | AC9: 0 | AD9: 0 | AE9: 0 | AF9: =SUM(Z9:AE9) -> 0 | AI9: غير سعودي | AJ9: ذكر | AK9: 0 | AL9: 0 | AM9: 0 | AN9: 0 | AO9: 0 | AP9: 0 | AQ9: =SUM(AK9:AP9) -> 0 | AT9: غير سعودي | AU9: ذكر | AV9: 0 | AW9: 0 | AX9: 0 | AY9: 0 | AZ9: 0 | BA9: 0 | BB9: =SUM(AV9:BA9) -> 0 | BE9: غير سعودي | BF9: ذكر | BG9: 0 | BH9: 0 | BI9: 0 | BJ9: 0 | BK9: 0 | BL9: 0 | BM9: =SUM(BG9:BL9) -> 0 | BP9: غير سعودي | BQ9: ذكر | BR9: 0 | BS9: 0 | BT9: 0 | BU9: 0 | BV9: 0 | BW9: 0 | BX9: =SUM(BR9:BW9) -> 0 | CA9: غير سعودي | CB9: ذكر | CC9: 0 | CD9: 0 | CE9: 0 | CF9: 0 | CG9: 0 | CH9: 0 | CI9: =SUM(CC9:CH9) -> 0 | CL9: غير سعودي | CM9: ذكر | CN9: 0 | CO9: 0 | CP9: 0 | CQ9: 0 | CR9: 0 | CS9: 0 | CT9: =SUM(CN9:CS9) -> 0 | CW9: غير سعودي | CX9: ذكر | CY9: 0 | CZ9: 0 | DA9: 0 | DB9: 0 | DC9: 0 | DD9: 0 | DE9: =SUM(CY9:DD9) -> 0 | DH9: غير سعودي | DI9: ذكر | DJ9: 0 | DK9: 0 | DL9: 0 | DM9: 0 | DN9: 0 | DO9: 0 | DP9: =SUM(DJ9:DO9) -> 0 | DS9: غير سعودي | DT9: ذكر | DU9: 0 | DV9: 0 | DW9: 0 | DX9: 0 | DY9: 0 | DZ9: 0 | EA9: =SUM(DU9:DZ9) -> 0 | ED9: غير سعودي | EE9: ذكر | EF9: =SUM(D9+O9+Z9+AK9+AV9+BG9+BR9+CC9+CN9+CY9+DJ9+DU9) -> 0 | EG9: =SUM(E9+P9+AA9+AL9+AW9+BH9+BS9+CD9+CO9+CZ9+DK9+DV9) -> 0 | EH9: =SUM(F9+Q9+AB9+AM9+AX9+BI9+BT9+CE9+CP9+DA9+DL9+DW9) -> 0 | EI9: =SUM(G9+R9+AC9+AN9+AY9+BJ9+BU9+CF9+CQ9+DB9+DM9+DX9) -> 0 | EJ9: 0 | EK9: =SUM(I9+T9+AE9+AP9+BA9+BL9+BW9+CH9+CS9+DD9+DO9+DZ9) -> 0 | EL9: =SUM(EF9:EK9) -> 0
C10: أنثى | D10: 0 | E10: 0 | F10: 0 | G10: 0 | H10: 0 | I10: 0 | J10: =SUM(D10:I10) -> 0 | N10: أنثى | O10: 0 | P10: 0 | Q10: 0 | R10: 0 | S10: 0 | T10: 0 | U10: =SUM(O10:T10) -> 0 | Y10: أنثى | Z10: 0 | AA10: 0 | AB10: 0 | AC10: 0 | AD10: 0 | AE10: 0 | AF10: =SUM(Z10:AE10) -> 0 | AJ10: أنثى | AK10: 0 | AL10: 0 | AM10: 0 | AN10: 0 | AO10: 0 | AP10: 0 | AQ10: =SUM(AK10:AP10) -> 0 | AU10: أنثى | AV10: 0 | AW10: 0 | AX10: 0 | AY10: 0 | AZ10: 0 | BA10: 0 | BB10: =SUM(AV10:BA10) -> 0 | BF10: أنثى | BG10: 0 | BH10: 0 | BI10: 0 | BJ10: 0 | BK10: 0 | BL10: 0 | BM10: =SUM(BG10:BL10) -> 0 | BQ10: أنثى | BR10: 0 | BS10: 0 | BT10: 0 | BU10: 0 | BV10: 0 | BW10: 0 | BX10: =SUM(BR10:BW10) -> 0 | CB10: أنثى | CC10: 0 | CD10: 0 | CE10: 0 | CF10: 0 | CG10: 0 | CH10: 0 | CI10: =SUM(CC10:CH10) -> 0 | CM10: أنثى | CN10: 0 | CO10: 0 | CP10: 0 | CQ10: 0 | CR10: 0 | CS10: 0 | CT10: =SUM(CN10:CS10) -> 0 | CX10: أنثى | CY10: 0 | CZ10: 0 | DA10: 0 | DB10: 0 | DC10: 0 | DD10: 0 | DE10: =SUM(CY10:DD10) -> 0 | DI10: أنثى | DJ10: 0 | DK10: 0 | DL10: 0 | DM10: 0 | DN10: 0 | DO10: 0 | DP10: =SUM(DJ10:DO10) -> 0 | DT10: أنثى | DU10: 0 | DV10: 0 | DW10: 0 | DX10: 0 | DY10: 0 | DZ10: 0 | EA10: =SUM(DU10:DZ10) -> 0 | EE10: أنثى | EF10: =SUM(D10+O10+Z10+AK10+AV10+BG10+BR10+CC10+CN10+CY10+DJ10+DU10) -> 0 | EG10: =SUM(E10+P10+AA10+AL10+AW10+BH10+BS10+CD10+CO10+CZ10+DK10+DV10) -> 0 | EH10: =SUM(F10+Q10+AB10+AM10+AX10+BI10+BT10+CE10+CP10+DA10+DL10+DW10) -> 0 | EI10: =SUM(G10+R10+AC10+AN10+AY10+BJ10+BU10+CF10+CQ10+DB10+DM10+DX10) -> 0 | EJ10: =SUM(H10+S10+AD10+AO10+AZ10+BK10+BV10+CG10+CR10+DC10+DN10+DY10) -> 0 | EK10: =SUM(I10+T10+AE10+AP10+BA10+BL10+BW10+CH10+CS10+DD10+DO10+DZ10) -> 0 | EL10: =SUM(EF10:EK10) -> 0
B11: مجموع الغير سعوديين | D11: =SUM(D9:D10) -> 0 | E11: =SUM(E9:E10) -> 0 | F11: =SUM(F9:F10) -> 0 | G11: =SUM(G9:G10) -> 0 | H11: =SUM(H9:H10) -> 0 | I11: =SUM(I9:I10) -> 0 | J11: =SUM(J9:J10) -> 0 | M11: مجموع الغير سعوديين | O11: =SUM(O9:O10) -> 0 | P11: =SUM(P9:P10) -> 0 | Q11: =SUM(Q9:Q10) -> 0 | R11: =SUM(R9:R10) -> 0 | S11: =SUM(S9:S10) -> 0 | T11: =SUM(T9:T10) -> 0 | U11: =SUM(U9:U10) -> 0 | X11: مجموع الغير سعوديين | Z11: =SUM(Z9:Z10) -> 0 | AA11: =SUM(AA9:AA10) -> 0 | AB11: =SUM(AB9:AB10) -> 0 | AC11: =SUM(AC9:AC10) -> 0 | AD11: =SUM(AD9:AD10) -> 0 | AE11: =SUM(AE9:AE10) -> 0 | AF11: =SUM(AF9:AF10) -> 0 | AI11: مجموع الغير سعوديين | AK11: =SUM(AK9:AK10) -> 0 | AL11: =SUM(AL9:AL10) -> 0 | AM11: =SUM(AM9:AM10) -> 0 | AN11: =SUM(AN9:AN10) -> 0 | AO11: =SUM(AO9:AO10) -> 0 | AP11: =SUM(AP9:AP10) -> 0 | AQ11: =SUM(AQ9:AQ10) -> 0 | AT11: مجموع الغير سعوديين | AV11: =SUM(AV9:AV10) -> 0 | AW11: =SUM(AW9:AW10) -> 0 | AX11: =SUM(AX9:AX10) -> 0 | AY11: =SUM(AY9:AY10) -> 0 | AZ11: =SUM(AZ9:AZ10) -> 0 | BA11: =SUM(BA9:BA10) -> 0 | BB11: =SUM(BB9:BB10) -> 0 | BE11: مجموع الغير سعوديين | BG11: =SUM(BG9:BG10) -> 0 | BH11: =SUM(BH9:BH10) -> 0 | BI11: =SUM(BI9:BI10) -> 0 | BJ11: =SUM(BJ9:BJ10) -> 0 | BK11: =SUM(BK9:BK10) -> 0 | BL11: =SUM(BL9:BL10) -> 0 | BM11: =SUM(BM9:BM10) -> 0 | BP11: مجموع الغير سعوديين | BR11: =SUM(BR9:BR10) -> 0 | BS11: =SUM(BS9:BS10) -> 0 | BT11: =SUM(BT9:BT10) -> 0 | BU11: =SUM(BU9:BU10) -> 0 | BV11: =SUM(BV9:BV10) -> 0 | BW11: =SUM(BW9:BW10) -> 0 | BX11: =SUM(BX9:BX10) -> 0 | CA11: مجموع الغير سعوديين | CC11: =SUM(CC9:CC10) -> 0 | CD11: =SUM(CD9:CD10) -> 0 | CE11: =SUM(CE9:CE10) -> 0 | CF11: =SUM(CF9:CF10) -> 0 | CG11: =SUM(CG9:CG10) -> 0 | CH11: =SUM(CH9:CH10) -> 0 | CI11: =SUM(CI9:CI10) -> 0 | CL11: مجموع الغير سعوديين | CN11: =SUM(CN9:CN10) -> 0 | CO11: =SUM(CO9:CO10) -> 0 | CP11: =SUM(CP9:CP10) -> 0 | CQ11: =SUM(CQ9:CQ10) -> 0 | CR11: =SUM(CR9:CR10) -> 0 | CS11: =SUM(CS9:CS10) -> 0 | CT11: =SUM(CT9:CT10) -> 0 | CW11: مجموع الغير سعوديين | CY11: =SUM(CY9:CY10) -> 0 | CZ11: =SUM(CZ9:CZ10) -> 0 | DA11: =SUM(DA9:DA10) -> 0 | DB11: =SUM(DB9:DB10) -> 0 | DC11: =SUM(DC9:DC10) -> 0 | DD11: =SUM(DD9:DD10) -> 0 | DE11: =SUM(DE9:DE10) -> 0 | DH11: مجموع الغير سعوديين | DJ11: =SUM(DJ9:DJ10) -> 0 | DK11: =SUM(DK9:DK10) -> 0 | DL11: =SUM(DL9:DL10) -> 0 | DM11: =SUM(DM9:DM10) -> 0 | DN11: =SUM(DN9:DN10) -> 0 | DO11: =SUM(DO9:DO10) -> 0 | DP11: =SUM(DP9:DP10) -> 0 | DS11: مجموع الغير سعوديين | DU11: =SUM(DU9:DU10) -> 0 | DV11: =SUM(DV9:DV10) -> 0 | DW11: =SUM(DW9:DW10) -> 0 | DX11: =SUM(DX9:DX10) -> 0 | DY11: =SUM(DY9:DY10) -> 0 | DZ11: =SUM(DZ9:DZ10) -> 0 | EA11: =SUM(EA9:EA10) -> 0 | ED11: مجموع الغير سعوديين | EF11: =SUM(EF9:EF10) -> 0 | EG11: =SUM(EG9:EG10) -> 0 | EH11: =SUM(EH9:EH10) -> 0 | EI11: =SUM(EI9:EI10) -> 0 | EJ11: =SUM(EJ9:EJ10) -> 0 | EK11: =SUM(EK9:EK10) -> 0 | EL11: =SUM(EL9:EL10) -> 0
B12: المجموع الكلي | D12: =SUM(D8+D11) -> 0 | E12: =SUM(E8+E11) -> 0 | F12: =SUM(F8+F11) -> 0 | G12: =SUM(G8+G11) -> 0 | H12: =SUM(H8+H11) -> 0 | I12: =SUM(I8+I11) -> 0 | J12: =SUM(J8+J11) -> 0 | M12: المجموع الكلي | O12: =SUM(O8+O11) -> 0 | P12: =SUM(P8+P11) -> 0 | Q12: =SUM(Q8+Q11) -> 0 | R12: =SUM(R8+R11) -> 0 | S12: =SUM(S8+S11) -> 0 | T12: =SUM(T8+T11) -> 0 | U12: =SUM(U8+U11) -> 0 | X12: المجموع الكلي | Z12: =SUM(Z8+Z11) -> 0 | AA12: =SUM(AA8+AA11) -> 0 | AB12: =SUM(AB8+AB11) -> 0 | AC12: =SUM(AC8+AC11) -> 0 | AD12: =SUM(AD8+AD11) -> 0 | AE12: =SUM(AE8+AE11) -> 0 | AF12: =SUM(AF8+AF11) -> 0 | AI12: المجموع الكلي | AK12: =SUM(AK8+AK11) -> 0 | AL12: =SUM(AL8+AL11) -> 0 | AM12: =SUM(AM8+AM11) -> 0 | AN12: =SUM(AN8+AN11) -> 0 | AO12: =SUM(AO8+AO11) -> 0 | AP12: =SUM(AP8+AP11) -> 0 | AQ12: =SUM(AQ8+AQ11) -> 0 | AT12: المجموع الكلي | AV12: =SUM(AV8+AV11) -> 0 | AW12: =SUM(AW8+AW11) -> 0 | AX12: =SUM(AX8+AX11) -> 0 | AY12: =SUM(AY8+AY11) -> 0 | AZ12: =SUM(AZ8+AZ11) -> 0 | BA12: =SUM(BA8+BA11) -> 0 | BB12: =SUM(BB8+BB11) -> 0 | BE12: المجموع الكلي | BG12: =SUM(BG8+BG11) -> 0 | BH12: =SUM(BH8+BH11) -> 0 | BI12: =SUM(BI8+BI11) -> 0 | BJ12: =SUM(BJ8+BJ11) -> 0 | BK12: =SUM(BK8+BK11) -> 0 | BL12: =SUM(BL8+BL11) -> 0 | BM12: =SUM(BM8+BM11) -> 0 | BP12: المجموع الكلي | BR12: =SUM(BR8+BR11) -> 0 | BS12: =SUM(BS8+BS11) -> 0 | BT12: =SUM(BT8+BT11) -> 0 | BU12: =SUM(BU8+BU11) -> 0 | BV12: =SUM(BV8+BV11) -> 0 | BW12: =SUM(BW8+BW11) -> 0 | BX12: =SUM(BX8+BX11) -> 0 | CA12: المجموع الكلي | CC12: =SUM(CC8+CC11) -> 0 | CD12: =SUM(CD8+CD11) -> 0 | CE12: =SUM(CE8+CE11) -> 0 | CF12: =SUM(CF8+CF11) -> 0 | CG12: =SUM(CG8+CG11) -> 0 | CH12: =SUM(CH8+CH11) -> 0 | CI12: =SUM(CI8+CI11) -> 0 | CL12: المجموع الكلي | CN12: =SUM(CN8+CN11) -> 0 | CO12: =SUM(CO8+CO11) -> 0 | CP12: =SUM(CP8+CP11) -> 0 | CQ12: =SUM(CQ8+CQ11) -> 0 | CR12: =SUM(CR8+CR11) -> 0 | CS12: =SUM(CS8+CS11) -> 0 | CT12: =SUM(CT8+CT11) -> 0 | CW12: المجموع الكلي | CY12: =SUM(CY8+CY11) -> 0 | CZ12: =SUM(CZ8+CZ11) -> 0 | DA12: =SUM(DA8+DA11) -> 0 | DB12: =SUM(DB8+DB11) -> 0 | DC12: =SUM(DC8+DC11) -> 0 | DD12: =SUM(DD8+DD11) -> 0 | DE12: =SUM(DE8+DE11) -> 0 | DH12: المجموع الكلي | DJ12: =SUM(DJ8+DJ11) -> 0 | DK12: =SUM(DK8+DK11) -> 0 | DL12: =SUM(DL8+DL11) -> 0 | DM12: =SUM(DM8+DM11) -> 0 | DN12: =SUM(DN8+DN11) -> 0 | DO12: =SUM(DO8+DO11) -> 0 | DP12: =SUM(DP8+DP11) -> 0 | DS12: المجموع الكلي | DU12: =SUM(DU8+DU11) -> 0 | DV12: =SUM(DV8+DV11) -> 0 | DW12: =SUM(DW8+DW11) -> 0 | DX12: =SUM(DX8+DX11) -> 0 | DY12: =SUM(DY8+DY11) -> 0 | DZ12: =SUM(DZ8+DZ11) -> 0 | EA12: =SUM(EA8+EA11) -> 0 | ED12: المجموع الكلي | EF12: =SUM(EF8+EF11) -> 0 | EG12: =SUM(EG8+EG11) -> 0 | EH12: =SUM(EH8+EH11) -> 0 | EI12: =SUM(EI8+EI11) -> 0 | EJ12: =SUM(EJ8+EJ11) -> 0 | EK12: =SUM(EK8+EK11) -> 0 | EL12: =SUM(EL8+EL11) -> 0
A13: الجامعة | B13: سعودي | C13: ذكر | D13: 0 | E13: 0 | F13: 0 | G13: 0 | H13: 0 | I13: 0 | J13: =SUM(D13:I13) -> 0 | L13: الجامعة | M13: سعودي | N13: ذكر | O13: 0 | P13: 0 | Q13: 0 | R13: 0 | S13: 0 | T13: 0 | U13: =SUM(O13:T13) -> 0 | W13: الجامعة | X13: سعودي | Y13: ذكر | Z13: 0 | AA13: 0 | AB13: 0 | AC13: 0 | AD13: 0 | AE13: 0 | AF13: =SUM(Z13:AE13) -> 0 | AH13: الجامعة | AI13: سعودي | AJ13: ذكر | AK13: 0 | AL13: 0 | AM13: 0 | AN13: 0 | AO13: 0 | AP13: 66 | AQ13: =SUM(AK13:AP13) -> 66 | AS13: الجامعة | AT13: سعودي | AU13: ذكر | AV13: 0 | AW13: 0 | AX13: 0 | AY13: 0 | AZ13: 0 | BA13: 0 | BB13: =SUM(AV13:BA13) -> 0 | BD13: الجامعة | BE13: سعودي | BF13: ذكر | BG13: 0 | BH13: 0 | BI13: 0 | BJ13: 0 | BK13: 0 | BL13: 0 | BM13: =SUM(BG13:BL13) -> 0 | BO13: الجامعة | BP13: سعودي | BQ13: ذكر | BR13: 0 | BS13: 0 | BT13: 0 | BU13: 0 | BV13: 0 | BW13: 0 | BX13: =SUM(BR13:BW13) -> 0 | BZ13: الجامعة | CA13: سعودي | CB13: ذكر | CC13: 0 | CD13: 0 | CE13: 0 | CF13: 0 | CG13: 0 | CH13: 0 | CI13: =SUM(CC13:CH13) -> 0 | CK13: الجامعة | CL13: سعودي | CM13: ذكر | CN13: 0 | CO13: 0 | CP13: 0 | CQ13: 0 | CR13: 0 | CS13: 0 | CT13: =SUM(CN13:CS13) -> 0 | CV13: الجامعة | CW13: سعودي | CX13: ذكر | CY13: 0 | CZ13: 0 | DA13: 0 | DB13: 0 | DC13: 0 | DD13: 0 | DE13: =SUM(CY13:DD13) -> 0 | DG13: الجامعة | DH13: سعودي | DI13: ذكر | DJ13: 0 | DK13: 0 | DL13: 0 | DM13: 0 | DN13: 0 | DO13: 0 | DP13: =SUM(DJ13:DO13) -> 0 | DR13: الجامعة | DS13: سعودي | DT13: ذكر | DU13: 0 | DV13: 0 | DW13: 0 | DX13: 0 | DY13: 0 | DZ13: 0 | EA13: =SUM(DU13:DZ13) -> 0 | EC13: =DR13 -> الجامعة | ED13: سعودي | EE13: ذكر | EF13: =SUM(D13+O13+Z13+AK13+AV13+BG13+BR13+CC13+CN13+CY13+DJ13+DU13) -> 0 | EG13: =SUM(E13+P13+AA13+AL13+AW13+BH13+BS13+CD13+CO13+CZ13+DK13+DV13) -> 0 | EH13: =SUM(F13+Q13+AB13+AM13+AX13+BI13+BT13+CE13+CP13+DA13+DL13+DW13) -> 0 | EI13: =SUM(G13+R13+AC13+AN13+AY13+BJ13+BU13+CF13+CQ13+DB13+DM13+DX13) -> 0 | EJ13: 0 | EK13: =SUM(I13+T13+AE13+AP13+BA13+BL13+BW13+CH13+CS13+DD13+DO13+DZ13) -> 66 | EL13: =SUM(EF13:EK13) -> 66
C14: أنثى | D14: 0 | E14: 0 | F14: 0 | G14: 0 | H14: 0 | I14: 0 | J14: =SUM(D14:I14) -> 0 | N14: أنثى | O14: 0 | P14: 0 | Q14: 0 | R14: 0 | S14: 0 | T14: 0 | U14: =SUM(O14:T14) -> 0 | Y14: أنثى | Z14: 0 | AA14: 0 | AB14: 0 | AC14: 0 | AD14: 0 | AE14: 0 | AF14: =SUM(Z14:AE14) -> 0 | AJ14: أنثى | AK14: 0 | AL14: 0 | AM14: 0 | AN14: 0 | AO14: 25 | AP14: 2 | AQ14: =SUM(AK14:AP14) -> 27 | AU14: أنثى | AV14: 0 | AW14: 0 | AX14: 0 | AY14: 0 | AZ14: 0 | BA14: 0 | BB14: =SUM(AV14:BA14) -> 0 | BF14: أنثى | BG14: 0 | BH14: 0 | BI14: 0 | BJ14: 0 | BK14: 0 | BL14: 0 | BM14: =SUM(BG14:BL14) -> 0 | BQ14: أنثى | BR14: 0 | BS14: 0 | BT14: 0 | BU14: 0 | BV14: 0 | BW14: 0 | BX14: =SUM(BR14:BW14) -> 0 | CB14: أنثى | CC14: 0 | CD14: 0 | CE14: 0 | CF14: 0 | CG14: 0 | CH14: 0 | CI14: =SUM(CC14:CH14) -> 0 | CM14: أنثى | CN14: 0 | CO14: 0 | CP14: 0 | CQ14: 0 | CR14: 0 | CS14: 0 | CT14: =SUM(CN14:CS14) -> 0 | CX14: أنثى | CY14: 0 | CZ14: 0 | DA14: 0 | DB14: 0 | DC14: 0 | DD14: 0 | DE14: =SUM(CY14:DD14) -> 0 | DI14: أنثى | DJ14: 0 | DK14: 0 | DL14: 0 | DM14: 0 | DN14: 0 | DO14: 0 | DP14: =SUM(DJ14:DO14) -> 0 | DT14: أنثى | DU14: 0 | DV14: 0 | DW14: 0 | DX14: 0 | DY14: 0 | DZ14: 0 | EA14: =SUM(DU14:DZ14) -> 0 | EE14: أنثى | EF14: =SUM(D14+O14+Z14+AK14+AV14+BG14+BR14+CC14+CN14+CY14+DJ14+DU14) -> 0 | EG14: =SUM(E14+P14+AA14+AL14+AW14+BH14+BS14+CD14+CO14+CZ14+DK14+DV14) -> 0 | EH14: =SUM(F14+Q14+AB14+AM14+AX14+BI14+BT14+CE14+CP14+DA14+DL14+DW14) -> 0 | EI14: =SUM(G14+R14+AC14+AN14+AY14+BJ14+BU14+CF14+CQ14+DB14+DM14+DX14) -> 0 | EJ14: =SUM(H14+S14+AD14+AO14+AZ14+BK14+BV14+CG14+CR14+DC14+DN14+DY14) -> 25 | EK14: =SUM(I14+T14+AE14+AP14+BA14+BL14+BW14+CH14+CS14+DD14+DO14+DZ14) -> 2 | EL14: =SUM(EF14:EK14) -> 27
B15: مجموع السعوديين | D15: =SUM(D13:D14) -> 0 | E15: =SUM(E13:E14) -> 0 | F15: =SUM(F13:F14) -> 0 | G15: =SUM(G13:G14) -> 0 | H15: =SUM(H13:H14) -> 0 | I15: =SUM(I13:I14) -> 0 | J15: =SUM(J13:J14) -> 0 | M15: مجموع السعوديين | O15: =SUM(O13:O14) -> 0 | P15: =SUM(P13:P14) -> 0 | Q15: =SUM(Q13:Q14) -> 0 | R15: =SUM(R13:R14) -> 0 | S15: =SUM(S13:S14) -> 0 | T15: =SUM(T13:T14) -> 0 | U15: =SUM(U13:U14) -> 0 | X15: مجموع السعوديين | Z15: =SUM(Z13:Z14) -> 0 | AA15: =SUM(AA13:AA14) -> 0 | AB15: =SUM(AB13:AB14) -> 0 | AC15: =SUM(AC13:AC14) -> 0 | AD15: =SUM(AD13:AD14) -> 0 | AE15: =SUM(AE13:AE14) -> 0 | AF15: =SUM(AF13:AF14) -> 0 | AI15: مجموع السعوديين | AK15: =SUM(AK13:AK14) -> 0 | AL15: =SUM(AL13:AL14) -> 0 | AM15: =SUM(AM13:AM14) -> 0 | AN15: =SUM(AN13:AN14) -> 0 | AO15: =SUM(AO13:AO14) -> 25 | AP15: =SUM(AP13:AP14) -> 68 | AQ15: =SUM(AQ13:AQ14) -> 93 | AT15: مجموع السعوديين | AV15: =SUM(AV13:AV14) -> 0 | AW15: =SUM(AW13:AW14) -> 0 | AX15: =SUM(AX13:AX14) -> 0 | AY15: =SUM(AY13:AY14) -> 0 | AZ15: =SUM(AZ13:AZ14) -> 0 | BA15: =SUM(BA13:BA14) -> 0 | BB15: =SUM(BB13:BB14) -> 0 | BE15: مجموع السعوديين | BG15: =SUM(BG13:BG14) -> 0 | BH15: =SUM(BH13:BH14) -> 0 | BI15: =SUM(BI13:BI14) -> 0 | BJ15: =SUM(BJ13:BJ14) -> 0 | BK15: =SUM(BK13:BK14) -> 0 | BL15: =SUM(BL13:BL14) -> 0 | BM15: =SUM(BM13:BM14) -> 0 | BP15: مجموع السعوديين | BR15: =SUM(BR13:BR14) -> 0 | BS15: =SUM(BS13:BS14) -> 0 | BT15: =SUM(BT13:BT14) -> 0 | BU15: =SUM(BU13:BU14) -> 0 | BV15: =SUM(BV13:BV14) -> 0 | BW15: =SUM(BW13:BW14) -> 0 | BX15: =SUM(BX13:BX14) -> 0 | CA15: مجموع السعوديين | CC15: =SUM(CC13:CC14) -> 0 | CD15: =SUM(CD13:CD14) -> 0 | CE15: =SUM(CE13:CE14) -> 0 | CF15: =SUM(CF13:CF14) -> 0 | CG15: =SUM(CG13:CG14) -> 0 | CH15: =SUM(CH13:CH14) -> 0 | CI15: =SUM(CI13:CI14) -> 0 | CL15: مجموع السعوديين | CN15: =SUM(CN13:CN14) -> 0 | CO15: =SUM(CO13:CO14) -> 0 | CP15: =SUM(CP13:CP14) -> 0 | CQ15: =SUM(CQ13:CQ14) -> 0 | CR15: =SUM(CR13:CR14) -> 0 | CS15: =SUM(CS13:CS14) -> 0 | CT15: =SUM(CT13:CT14) -> 0 | CW15: مجموع السعوديين | CY15: =SUM(CY13:CY14) -> 0 | CZ15: =SUM(CZ13:CZ14) -> 0 | DA15: =SUM(DA13:DA14) -> 0 | DB15: =SUM(DB13:DB14) -> 0 | DC15: =SUM(DC13:DC14) -> 0 | DD15: =SUM(DD13:DD14) -> 0 | DE15: =SUM(DE13:DE14) -> 0 | DH15: مجموع السعوديين | DJ15: =SUM(DJ13:DJ14) -> 0 | DK15: =SUM(DK13:DK14) -> 0 | DL15: =SUM(DL13:DL14) -> 0 | DM15: =SUM(DM13:DM14) -> 0 | DN15: =SUM(DN13:DN14) -> 0 | DO15: =SUM(DO13:DO14) -> 0 | DP15: =SUM(DP13:DP14) -> 0 | DS15: مجموع السعوديين | DU15: =SUM(DU13:DU14) -> 0 | DV15: =SUM(DV13:DV14) -> 0 | DW15: =SUM(DW13:DW14) -> 0 | DX15: =SUM(DX13:DX14) -> 0 | DY15: =SUM(DY13:DY14) -> 0 | DZ15: =SUM(DZ13:DZ14) -> 0 | EA15: =SUM(EA13:EA14) -> 0 | ED15: مجموع السعوديين | EF15: =SUM(EF13:EF14) -> 0 | EG15: =SUM(EG13:EG14) -> 0 | EH15: =SUM(EH13:EH14) -> 0 | EI15: =SUM(EI13:EI14) -> 0 | EJ15: =SUM(EJ13:EJ14) -> 25 | EK15: =SUM(EK13:EK14) -> 68 | EL15: =SUM(EL13:EL14) -> 93
B16: غير سعودي | C16: ذكر | D16: 0 | E16: 0 | F16: 0 | G16: 0 | H16: 0 | I16: 0 | J16: =SUM(D16:I16) -> 0 | M16: غير سعودي | N16: ذكر | O16: 0 | P16: 0 | Q16: 0 | R16: 0 | S16: 0 | T16: 0 | U16: =SUM(O16:T16) -> 0 | X16: غير سعودي | Y16: ذكر | Z16: 0 | AA16: 0 | AB16: 0 | AC16: 0 | AD16: 0 | AE16: 0 | AF16: =SUM(Z16:AE16) -> 0 | AI16: غير سعودي | AJ16: ذكر | AK16: 0 | AL16: 0 | AM16: 0 | AN16: 0 | AO16: 0 | AP16: 5 | AQ16: =SUM(AK16:AP16) -> 5 | AT16: غير سعودي | AU16: ذكر | AV16: 0 | AW16: 0 | AX16: 0 | AY16: 0 | AZ16: 0 | BA16: 0 | BB16: =SUM(AV16:BA16) -> 0 | BE16: غير سعودي | BF16: ذكر | BG16: 0 | BH16: 0 | BI16: 0 | BJ16: 0 | BK16: 0 | BL16: 0 | BM16: =SUM(BG16:BL16) -> 0 | BP16: غير سعودي | BQ16: ذكر | BR16: 0 | BS16: 0 | BT16: 0 | BU16: 0 | BV16: 0 | BW16: 0 | BX16: =SUM(BR16:BW16) -> 0 | CA16: غير سعودي | CB16: ذكر | CC16: 0 | CD16: 0 | CE16: 0 | CF16: 0 | CG16: 0 | CH16: 0 | CI16: =SUM(CC16:CH16) -> 0 | CL16: غير سعودي | CM16: ذكر | CN16: 0 | CO16: 0 | CP16: 0 | CQ16: 0 | CR16: 0 | CS16: 0 | CT16: =SUM(CN16:CS16) -> 0 | CW16: غير سعودي | CX16: ذكر | CY16: 0 | CZ16: 0 | DA16: 0 | DB16: 0 | DC16: 0 | DD16: 0 | DE16: =SUM(CY16:DD16) -> 0 | DH16: غير سعودي | DI16: ذكر | DJ16: 0 | DK16: 0 | DL16: 0 | DM16: 0 | DN16: 0 | DO16: 0 | DP16: =SUM(DJ16:DO16) -> 0 | DS16: غير سعودي | DT16: ذكر | DU16: 0 | DV16: 0 | DW16: 0 | DX16: 0 | DY16: 0 | DZ16: 0 | EA16: =SUM(DU16:DZ16) -> 0 | ED16: غير سعودي | EE16: ذكر | EF16: =SUM(D16+O16+Z16+AK16+AV16+BG16+BR16+CC16+CN16+CY16+DJ16+DU16) -> 0 | EG16: =SUM(E16+P16+AA16+AL16+AW16+BH16+BS16+CD16+CO16+CZ16+DK16+DV16) -> 0 | EH16: =SUM(F16+Q16+AB16+AM16+AX16+BI16+BT16+CE16+CP16+DA16+DL16+DW16) -> 0 | EI16: =SUM(G16+R16+AC16+AN16+AY16+BJ16+BU16+CF16+CQ16+DB16+DM16+DX16) -> 0 | EJ16: 0 | EK16: =SUM(I16+T16+AE16+AP16+BA16+BL16+BW16+CH16+CS16+DD16+DO16+DZ16) -> 5 | EL16: =SUM(EF16:EK16) -> 5
C17: أنثى | D17: 0 | E17: 0 | F17: 0 | G17: 0 | H17: 0 | I17: 0 | J17: =SUM(D17:I17) -> 0 | N17: أنثى | O17: 0 | P17: 0 | Q17: 0 | R17: 0 | S17: 0 | T17: 0 | U17: =SUM(O17:T17) -> 0 | Y17: أنثى | Z17: 0 | AA17: 0 | AB17: 0 | AC17: 0 | AD17: 0 | AE17: 0 | AF17: =SUM(Z17:AE17) -> 0 | AJ17: أنثى | AK17: 0 | AL17: 0 | AM17: 0 | AN17: 0 | AO17: 2 | AP17: 1 | AQ17: =SUM(AK17:AP17) -> 3 | AU17: أنثى | AV17: 0 | AW17: 0 | AX17: 0 | AY17: 0 | AZ17: 0 | BA17: 0 | BB17: =SUM(AV17:BA17) -> 0 | BF17: أنثى | BG17: 0 | BH17: 0 | BI17: 0 | BJ17: 0 | BK17: 0 | BL17: 0 | BM17: =SUM(BG17:BL17) -> 0 | BQ17: أنثى | BR17: 0 | BS17: 0 | BT17: 0 | BU17: 0 | BV17: 0 | BW17: 0 | BX17: =SUM(BR17:BW17) -> 0 | CB17: أنثى | CC17: 0 | CD17: 0 | CE17: 0 | CF17: 0 | CG17: 0 | CH17: 0 | CI17: =SUM(CC17:CH17) -> 0 | CM17: أنثى | CN17: 0 | CO17: 0 | CP17: 0 | CQ17: 0 | CR17: 0 | CS17: 0 | CT17: =SUM(CN17:CS17) -> 0 | CX17: أنثى | CY17: 0 | CZ17: 0 | DA17: 0 | DB17: 0 | DC17: 0 | DD17: 0 | DE17: =SUM(CY17:DD17) -> 0 | DI17: أنثى | DJ17: 0 | DK17: 0 | DL17: 0 | DM17: 0 | DN17: 0 | DO17: 0 | DP17: =SUM(DJ17:DO17) -> 0 | DT17: أنثى | DU17: 0 | DV17: 0 | DW17: 0 | DX17: 0 | DY17: 0 | DZ17: 0 | EA17: =SUM(DU17:DZ17) -> 0 | EE17: أنثى | EF17: =SUM(D17+O17+Z17+AK17+AV17+BG17+BR17+CC17+CN17+CY17+DJ17+DU17) -> 0 | EG17: =SUM(E17+P17+AA17+AL17+AW17+BH17+BS17+CD17+CO17+CZ17+DK17+DV17) -> 0 | EH17: =SUM(F17+Q17+AB17+AM17+AX17+BI17+BT17+CE17+CP17+DA17+DL17+DW17) -> 0 | EI17: =SUM(G17+R17+AC17+AN17+AY17+BJ17+BU17+CF17+CQ17+DB17+DM17+DX17) -> 0 | EJ17: =SUM(H17+S17+AD17+AO17+AZ17+BK17+BV17+CG17+CR17+DC17+DN17+DY17) -> 2 | EK17: =SUM(I17+T17+AE17+AP17+BA17+BL17+BW17+CH17+CS17+DD17+DO17+DZ17) -> 1 | EL17: =SUM(EF17:EK17) -> 3
B18: مجموع الغير سعوديين | D18: =SUM(D16:D17) -> 0 | E18: =SUM(E16:E17) -> 0 | F18: =SUM(F16:F17) -> 0 | G18: =SUM(G16:G17) -> 0 | H18: =SUM(H16:H17) -> 0 | I18: =SUM(I16:I17) -> 0 | J18: =SUM(J16:J17) -> 0 | M18: مجموع الغير سعوديين | O18: =SUM(O16:O17) -> 0 | P18: =SUM(P16:P17) -> 0 | Q18: =SUM(Q16:Q17) -> 0 | R18: =SUM(R16:R17) -> 0 | S18: =SUM(S16:S17) -> 0 | T18: =SUM(T16:T17) -> 0 | U18: =SUM(U16:U17) -> 0 | X18: مجموع الغير سعوديين | Z18: =SUM(Z16:Z17) -> 0 | AA18: =SUM(AA16:AA17) -> 0 | AB18: =SUM(AB16:AB17) -> 0 | AC18: =SUM(AC16:AC17) -> 0 | AD18: =SUM(AD16:AD17) -> 0 | AE18: =SUM(AE16:AE17) -> 0 | AF18: =SUM(AF16:AF17) -> 0 | AI18: مجموع الغير سعوديين | AK18: =SUM(AK16:AK17) -> 0 | AL18: =SUM(AL16:AL17) -> 0 | AM18: =SUM(AM16:AM17) -> 0 | AN18: =SUM(AN16:AN17) -> 0 | AO18: =SUM(AO16:AO17) -> 2 | AP18: =SUM(AP16:AP17) -> 6 | AQ18: =SUM(AQ16:AQ17) -> 8 | AT18: مجموع الغير سعوديين | AV18: =SUM(AV16:AV17) -> 0 | AW18: =SUM(AW16:AW17) -> 0 | AX18: =SUM(AX16:AX17) -> 0 | AY18: =SUM(AY16:AY17) -> 0 | AZ18: =SUM(AZ16:AZ17) -> 0 | BA18: =SUM(BA16:BA17) -> 0 | BB18: =SUM(BB16:BB17) -> 0 | BE18: مجموع الغير سعوديين | BG18: =SUM(BG16:BG17) -> 0 | BH18: =SUM(BH16:BH17) -> 0 | BI18: =SUM(BI16:BI17) -> 0 | BJ18: =SUM(BJ16:BJ17) -> 0 | BK18: =SUM(BK16:BK17) -> 0 | BL18: =SUM(BL16:BL17) -> 0 | BM18: =SUM(BM16:BM17) -> 0 | BP18: مجموع الغير سعوديين | BR18: =SUM(BR16:BR17) -> 0 | BS18: =SUM(BS16:BS17) -> 0 | BT18: =SUM(BT16:BT17) -> 0 | BU18: =SUM(BU16:BU17) -> 0 | BV18: =SUM(BV16:BV17) -> 0 | BW18: =SUM(BW16:BW17) -> 0 | BX18: =SUM(BX16:BX17) -> 0 | CA18: مجموع الغير سعوديين | CC18: =SUM(CC16:CC17) -> 0 | CD18: =SUM(CD16:CD17) -> 0 | CE18: =SUM(CE16:CE17) -> 0 | CF18: =SUM(CF16:CF17) -> 0 | CG18: =SUM(CG16:CG17) -> 0 | CH18: =SUM(CH16:CH17) -> 0 | CI18: =SUM(CI16:CI17) -> 0 | CL18: مجموع الغير سعوديين | CN18: =SUM(CN16:CN17) -> 0 | CO18: =SUM(CO16:CO17) -> 0 | CP18: =SUM(CP16:CP17) -> 0 | CQ18: =SUM(CQ16:CQ17) -> 0 | CR18: =SUM(CR16:CR17) -> 0 | CS18: =SUM(CS16:CS17) -> 0 | CT18: =SUM(CT16:CT17) -> 0 | CW18: مجموع الغير سعوديين | CY18: =SUM(CY16:CY17) -> 0 | CZ18: =SUM(CZ16:CZ17) -> 0 | DA18: =SUM(DA16:DA17) -> 0 | DB18: =SUM(DB16:DB17) -> 0 | DC18: =SUM(DC16:DC17) -> 0 | DD18: =SUM(DD16:DD17) -> 0 | DE18: =SUM(DE16:DE17) -> 0 | DH18: مجموع الغير سعوديين | DJ18: =SUM(DJ16:DJ17) -> 0 | DK18: =SUM(DK16:DK17) -> 0 | DL18: =SUM(DL16:DL17) -> 0 | DM18: =SUM(DM16:DM17) -> 0 | DN18: =SUM(DN16:DN17) -> 0 | DO18: =SUM(DO16:DO17) -> 0 | DP18: =SUM(DP16:DP17) -> 0 | DS18: مجموع الغير سعوديين | DU18: =SUM(DU16:DU17) -> 0 | DV18: =SUM(DV16:DV17) -> 0 | DW18: =SUM(DW16:DW17) -> 0 | DX18: =SUM(DX16:DX17) -> 0 | DY18: =SUM(DY16:DY17) -> 0 | DZ18: =SUM(DZ16:DZ17) -> 0 | EA18: =SUM(EA16:EA17) -> 0 | ED18: مجموع الغير سعوديين | EF18: =SUM(EF16:EF17) -> 0 | EG18: =SUM(EG16:EG17) -> 0 | EH18: =SUM(EH16:EH17) -> 0 | EI18: =SUM(EI16:EI17) -> 0 | EJ18: =SUM(EJ16:EJ17) -> 2 | EK18: =SUM(EK16:EK17) -> 6 | EL18: =SUM(EL16:EL17) -> 8
B19: المجموع الكلي | D19: =SUM(D15+D18) -> 0 | E19: =SUM(E15+E18) -> 0 | F19: =SUM(F15+F18) -> 0 | G19: =SUM(G15+G18) -> 0 | H19: =SUM(H15+H18) -> 0 | I19: =SUM(I15+I18) -> 0 | J19: =SUM(J15+J18) -> 0 | M19: المجموع الكلي | O19: =SUM(O15+O18) -> 0 | P19: =SUM(P15+P18) -> 0 | Q19: =SUM(Q15+Q18) -> 0 | R19: =SUM(R15+R18) -> 0 | S19: =SUM(S15+S18) -> 0 | T19: =SUM(T15+T18) -> 0 | U19: =SUM(U15+U18) -> 0 | X19: المجموع الكلي | Z19: =SUM(Z15+Z18) -> 0 | AA19: =SUM(AA15+AA18) -> 0 | AB19: =SUM(AB15+AB18) -> 0 | AC19: =SUM(AC15+AC18) -> 0 | AD19: =SUM(AD15+AD18) -> 0 | AE19: =SUM(AE15+AE18) -> 0 | AF19: =SUM(AF15+AF18) -> 0 | AI19: المجموع الكلي | AK19: =SUM(AK15+AK18) -> 0 | AL19: =SUM(AL15+AL18) -> 0 | AM19: =SUM(AM15+AM18) -> 0 | AN19: =SUM(AN15+AN18) -> 0 | AO19: =SUM(AO15+AO18) -> 27 | AP19: =SUM(AP15+AP18) -> 74 | AQ19: =SUM(AQ15+AQ18) -> 101 | AT19: المجموع الكلي | AV19: =SUM(AV15+AV18) -> 0 | AW19: =SUM(AW15+AW18) -> 0 | AX19: =SUM(AX15+AX18) -> 0 | AY19: =SUM(AY15+AY18) -> 0 | AZ19: =SUM(AZ15+AZ18) -> 0 | BA19: =SUM(BA15+BA18) -> 0 | BB19: =SUM(BB15+BB18) -> 0 | BE19: المجموع الكلي | BG19: =SUM(BG15+BG18) -> 0 | BH19: =SUM(BH15+BH18) -> 0 | BI19: =SUM(BI15+BI18) -> 0 | BJ19: =SUM(BJ15+BJ18) -> 0 | BK19: =SUM(BK15+BK18) -> 0 | BL19: =SUM(BL15+BL18) -> 0 | BM19: =SUM(BM15+BM18) -> 0 | BP19: المجموع الكلي | BR19: =SUM(BR15+BR18) -> 0 | BS19: =SUM(BS15+BS18) -> 0 | BT19: =SUM(BT15+BT18) -> 0 | BU19: =SUM(BU15+BU18) -> 0 | BV19: =SUM(BV15+BV18) -> 0 | BW19: =SUM(BW15+BW18) -> 0 | BX19: =SUM(BX15+BX18) -> 0 | CA19: المجموع الكلي | CC19: =SUM(CC15+CC18) -> 0 | CD19: =SUM(CD15+CD18) -> 0 | CE19: =SUM(CE15+CE18) -> 0 | CF19: =SUM(CF15+CF18) -> 0 | CG19: =SUM(CG15+CG18) -> 0 | CH19: =SUM(CH15+CH18) -> 0 | CI19: =SUM(CI15+CI18) -> 0 | CL19: المجموع الكلي | CN19: =SUM(CN15+CN18) -> 0 | CO19: =SUM(CO15+CO18) -> 0 | CP19: =SUM(CP15+CP18) -> 0 | CQ19: =SUM(CQ15+CQ18) -> 0 | CR19: =SUM(CR15+CR18) -> 0 | CS19: =SUM(CS15+CS18) -> 0 | CT19: =SUM(CT15+CT18) -> 0 | CW19: المجموع الكلي | CY19: =SUM(CY15+CY18) -> 0 | CZ19: =SUM(CZ15+CZ18) -> 0 | DA19: =SUM(DA15+DA18) -> 0 | DB19: =SUM(DB15+DB18) -> 0 | DC19: =SUM(DC15+DC18) -> 0 | DD19: =SUM(DD15+DD18) -> 0 | DE19: =SUM(DE15+DE18) -> 0 | DH19: المجموع الكلي | DJ19: =SUM(DJ15+DJ18) -> 0 | DK19: =SUM(DK15+DK18) -> 0 | DL19: =SUM(DL15+DL18) -> 0 | DM19: =SUM(DM15+DM18) -> 0 | DN19: =SUM(DN15+DN18) -> 0 | DO19: =SUM(DO15+DO18) -> 0 | DP19: =SUM(DP15+DP18) -> 0 | DS19: المجموع الكلي | DU19: =SUM(DU15+DU18) -> 0 | DV19: =SUM(DV15+DV18) -> 0 | DW19: =SUM(DW15+DW18) -> 0 | DX19: =SUM(DX15+DX18) -> 0 | DY19: =SUM(DY15+DY18) -> 0 | DZ19: =SUM(DZ15+DZ18) -> 0 | EA19: =SUM(EA15+EA18) -> 0 | ED19: المجموع الكلي | EF19: =SUM(EF15+EF18) -> 0 | EG19: =SUM(EG15+EG18) -> 0 | EH19: =SUM(EH15+EH18) -> 0 | EI19: =SUM(EI15+EI18) -> 0 | EJ19: =SUM(EJ15+EJ18) -> 27 | EK19: =SUM(EK15+EK18) -> 74 | EL19: =SUM(EL15+EL18) -> 101
A20: السليمانية | B20: سعودي | C20: ذكر | D20: 0 | E20: 0 | F20: 0 | G20: 0 | H20: 0 | I20: 0 | J20: =SUM(D20:I20) -> 0 | L20: السليمانية | M20: سعودي | N20: ذكر | O20: 0 | P20: 0 | Q20: 0 | R20: 0 | S20: 0 | T20: 0 | U20: =SUM(O20:T20) -> 0 | W20: السليمانية | X20: سعودي | Y20: ذكر | Z20: 0 | AA20: 0 | AB20: 0 | AC20: 0 | AD20: 0 | AE20: 0 | AF20: =SUM(Z20:AE20) -> 0 | AH20: السليمانية | AI20: سعودي | AJ20: ذكر | AK20: 0 | AL20: 0 | AM20: 0 | AN20: 0 | AO20: 0 | AP20: 0 | AQ20: =SUM(AK20:AP20) -> 0 | AS20: السليمانية | AT20: سعودي | AU20: ذكر | AV20: 0 | AW20: 0 | AX20: 0 | AY20: 0 | AZ20: 0 | BA20: 0 | BB20: =SUM(AV20:BA20) -> 0 | BD20: السليمانية | BE20: سعودي | BF20: ذكر | BG20: 0 | BH20: 0 | BI20: 0 | BJ20: 0 | BK20: 0 | BL20: 0 | BM20: =SUM(BG20:BL20) -> 0 | BO20: السليمانية | BP20: سعودي | BQ20: ذكر | BR20: 0 | BS20: 0 | BT20: 0 | BU20: 0 | BV20: 0 | BW20: 0 | BX20: =SUM(BR20:BW20) -> 0 | BZ20: السليمانية | CA20: سعودي | CB20: ذكر | CC20: 0 | CD20: 0 | CE20: 0 | CF20: 0 | CG20: 0 | CH20: 0 | CI20: =SUM(CC20:CH20) -> 0 | CK20: السليمانية | CL20: سعودي | CM20: ذكر | CN20: 0 | CO20: 0 | CP20: 0 | CQ20: 0 | CR20: 0 | CS20: 0 | CT20: =SUM(CN20:CS20) -> 0 | CV20: السليمانية | CW20: سعودي | CX20: ذكر | CY20: 0 | CZ20: 0 | DA20: 0 | DB20: 0 | DC20: 0 | DD20: 0 | DE20: =SUM(CY20:DD20) -> 0 | DG20: السليمانية | DH20: سعودي | DI20: ذكر | DJ20: 0 | DK20: 0 | DL20: 0 | DM20: 0 | DN20: 0 | DO20: 0 | DP20: =SUM(DJ20:DO20) -> 0 | DR20: السليمانية | DS20: سعودي | DT20: ذكر | DU20: 0 | DV20: 0 | DW20: 0 | DX20: 0 | DY20: 0 | DZ20: 0 | EA20: =SUM(DU20:DZ20) -> 0 | EC20: =DR20 -> السليمانية | ED20: سعودي | EE20: ذكر | EF20: =SUM(D20+O20+Z20+AK20+AV20+BG20+BR20+CC20+CN20+CY20+DJ20+DU20) -> 0 | EG20: =SUM(E20+P20+AA20+AL20+AW20+BH20+BS20+CD20+CO20+CZ20+DK20+DV20) -> 0 | EH20: =SUM(F20+Q20+AB20+AM20+AX20+BI20+BT20+CE20+CP20+DA20+DL20+DW20) -> 0 | EI20: =SUM(G20+R20+AC20+AN20+AY20+BJ20+BU20+CF20+CQ20+DB20+DM20+DX20) -> 0 | EJ20: 0 | EK20: =SUM(I20+T20+AE20+AP20+BA20+BL20+BW20+CH20+CS20+DD20+DO20+DZ20) -> 0 | EL20: =SUM(EF20:EK20) -> 0
C21: أنثى | D21: 0 | E21: 0 | F21: 0 | G21: 0 | H21: 0 | I21: 0 | J21: =SUM(D21:I21) -> 0 | N21: أنثى | O21: 0 | P21: 0 | Q21: 0 | R21: 0 | S21: 0 | T21: 0 | U21: =SUM(O21:T21) -> 0 | Y21: أنثى | Z21: 0 | AA21: 0 | AB21: 0 | AC21: 0 | AD21: 0 | AE21: 0 | AF21: =SUM(Z21:AE21) -> 0 | AJ21: أنثى | AK21: 0 | AL21: 0 | AM21: 0 | AN21: 0 | AO21: 10 | AP21: 0 | AQ21: =SUM(AK21:AP21) -> 10 | AU21: أنثى | AV21: 0 | AW21: 0 | AX21: 0 | AY21: 0 | AZ21: 0 | BA21: 0 | BB21: =SUM(AV21:BA21) -> 0 | BF21: أنثى | BG21: 0 | BH21: 0 | BI21: 0 | BJ21: 0 | BK21: 0 | BL21: 0 | BM21: =SUM(BG21:BL21) -> 0 | BQ21: أنثى | BR21: 0 | BS21: 0 | BT21: 0 | BU21: 0 | BV21: 0 | BW21: 0 | BX21: =SUM(BR21:BW21) -> 0 | CB21: أنثى | CC21: 0 | CD21: 0 | CE21: 0 | CF21: 0 | CG21: 0 | CH21: 0 | CI21: =SUM(CC21:CH21) -> 0 | CM21: أنثى | CN21: 0 | CO21: 0 | CP21: 0 | CQ21: 0 | CR21: 0 | CS21: 0 | CT21: =SUM(CN21:CS21) -> 0 | CX21: أنثى | CY21: 0 | CZ21: 0 | DA21: 0 | DB21: 0 | DC21: 0 | DD21: 0 | DE21: =SUM(CY21:DD21) -> 0 | DI21: أنثى | DJ21: 0 | DK21: 0 | DL21: 0 | DM21: 0 | DN21: 0 | DO21: 0 | DP21: =SUM(DJ21:DO21) -> 0 | DT21: أنثى | DU21: 0 | DV21: 0 | DW21: 0 | DX21: 0 | DY21: 0 | DZ21: 0 | EA21: =SUM(DU21:DZ21) -> 0 | EE21: أنثى | EF21: =SUM(D21+O21+Z21+AK21+AV21+BG21+BR21+CC21+CN21+CY21+DJ21+DU21) -> 0 | EG21: =SUM(E21+P21+AA21+AL21+AW21+BH21+BS21+CD21+CO21+CZ21+DK21+DV21) -> 0 | EH21: =SUM(F21+Q21+AB21+AM21+AX21+BI21+BT21+CE21+CP21+DA21+DL21+DW21) -> 0 | EI21: =SUM(G21+R21+AC21+AN21+AY21+BJ21+BU21+CF21+CQ21+DB21+DM21+DX21) -> 0 | EJ21: =SUM(H21+S21+AD21+AO21+AZ21+BK21+BV21+CG21+CR21+DC21+DN21+DY21) -> 10 | EK21: =SUM(I21+T21+AE21+AP21+BA21+BL21+BW21+CH21+CS21+DD21+DO21+DZ21) -> 0 | EL21: =SUM(EF21:EK21) -> 10
B22: مجموع السعوديين | D22: =SUM(D20:D21) -> 0 | E22: =SUM(E20:E21) -> 0 | F22: =SUM(F20:F21) -> 0 | G22: =SUM(G20:G21) -> 0 | H22: =SUM(H20:H21) -> 0 | I22: =SUM(I20:I21) -> 0 | J22: =SUM(J20:J21) -> 0 | M22: مجموع السعوديين | O22: =SUM(O20:O21) -> 0 | P22: =SUM(P20:P21) -> 0 | Q22: =SUM(Q20:Q21) -> 0 | R22: =SUM(R20:R21) -> 0 | S22: =SUM(S20:S21) -> 0 | T22: =SUM(T20:T21) -> 0 | U22: =SUM(U20:U21) -> 0 | X22: مجموع السعوديين | Z22: =SUM(Z20:Z21) -> 0 | AA22: =SUM(AA20:AA21) -> 0 | AB22: =SUM(AB20:AB21) -> 0 | AC22: =SUM(AC20:AC21) -> 0 | AD22: =SUM(AD20:AD21) -> 0 | AE22: =SUM(AE20:AE21) -> 0 | AF22: =SUM(AF20:AF21) -> 0 | AI22: مجموع السعوديين | AK22: 0 | AL22: 0 | AM22: 0 | AN22: 0 | AO22: 10 | AP22: 0 | AQ22: =SUM(AQ20:AQ21) -> 10 | AT22: مجموع السعوديين | AV22: =SUM(AV20:AV21) -> 0 | AW22: =SUM(AW20:AW21) -> 0 | AX22: =SUM(AX20:AX21) -> 0 | AY22: =SUM(AY20:AY21) -> 0 | AZ22: =SUM(AZ20:AZ21) -> 0 | BA22: =SUM(BA20:BA21) -> 0 | BB22: =SUM(BB20:BB21) -> 0 | BE22: مجموع السعوديين | BG22: =SUM(BG20:BG21) -> 0 | BH22: =SUM(BH20:BH21) -> 0 | BI22: =SUM(BI20:BI21) -> 0 | BJ22: =SUM(BJ20:BJ21) -> 0 | BK22: =SUM(BK20:BK21) -> 0 | BL22: =SUM(BL20:BL21) -> 0 | BM22: =SUM(BM20:BM21) -> 0 | BP22: مجموع السعوديين | BR22: =SUM(BR20:BR21) -> 0 | BS22: =SUM(BS20:BS21) -> 0 | BT22: =SUM(BT20:BT21) -> 0 | BU22: =SUM(BU20:BU21) -> 0 | BV22: =SUM(BV20:BV21) -> 0 | BW22: =SUM(BW20:BW21) -> 0 | BX22: =SUM(BX20:BX21) -> 0 | CA22: مجموع السعوديين | CC22: =SUM(CC20:CC21) -> 0 | CD22: =SUM(CD20:CD21) -> 0 | CE22: =SUM(CE20:CE21) -> 0 | CF22: =SUM(CF20:CF21) -> 0 | CG22: =SUM(CG20:CG21) -> 0 | CH22: =SUM(CH20:CH21) -> 0 | CI22: =SUM(CI20:CI21) -> 0 | CL22: مجموع السعوديين | CN22: =SUM(CN20:CN21) -> 0 | CO22: =SUM(CO20:CO21) -> 0 | CP22: =SUM(CP20:CP21) -> 0 | CQ22: =SUM(CQ20:CQ21) -> 0 | CR22: =SUM(CR20:CR21) -> 0 | CS22: =SUM(CS20:CS21) -> 0 | CT22: =SUM(CT20:CT21) -> 0 | CW22: مجموع السعوديين | CY22: =SUM(CY20:CY21) -> 0 | CZ22: =SUM(CZ20:CZ21) -> 0 | DA22: =SUM(DA20:DA21) -> 0 | DB22: =SUM(DB20:DB21) -> 0 | DC22: =SUM(DC20:DC21) -> 0 | DD22: =SUM(DD20:DD21) -> 0 | DE22: =SUM(DE20:DE21) -> 0 | DH22: مجموع السعوديين | DJ22: =SUM(DJ20:DJ21) -> 0 | DK22: =SUM(DK20:DK21) -> 0 | DL22: =SUM(DL20:DL21) -> 0 | DM22: =SUM(DM20:DM21) -> 0 | DN22: =SUM(DN20:DN21) -> 0 | DO22: =SUM(DO20:DO21) -> 0 | DP22: =SUM(DP20:DP21) -> 0 | DS22: مجموع السعوديين | DU22: =SUM(DU20:DU21) -> 0 | DV22: =SUM(DV20:DV21) -> 0 | DW22: =SUM(DW20:DW21) -> 0 | DX22: =SUM(DX20:DX21) -> 0 | DY22: =SUM(DY20:DY21) -> 0 | DZ22: =SUM(DZ20:DZ21) -> 0 | EA22: =SUM(EA20:EA21) -> 0 | ED22: مجموع السعوديين | EF22: =SUM(EF20:EF21) -> 0 | EG22: =SUM(EG20:EG21) -> 0 | EH22: =SUM(EH20:EH21) -> 0 | EI22: =SUM(EI20:EI21) -> 0 | EJ22: =SUM(EJ20:EJ21) -> 10 | EK22: =SUM(EK20:EK21) -> 0 | EL22: =SUM(EL20:EL21) -> 10
B23: غير سعودي | C23: ذكر | D23: 0 | E23: 0 | F23: 0 | G23: 0 | H23: 0 | I23: 0 | J23: =SUM(D23:I23) -> 0 | M23: غير سعودي | N23: ذكر | O23: 0 | P23: 0 | Q23: 0 | R23: 0 | S23: 0 | T23: 0 | U23: =SUM(O23:T23) -> 0 | X23: غير سعودي | Y23: ذكر | Z23: 0 | AA23: 0 | AB23: 0 | AC23: 0 | AD23: 0 | AE23: 0 | AF23: =SUM(Z23:AE23) -> 0 | AI23: غير سعودي | AJ23: ذكر | AK23: 0 | AL23: 0 | AM23: 0 | AN23: 0 | AO23: 0 | AP23: 0 | AQ23: =SUM(AK23:AP23) -> 0 | AT23: غير سعودي | AU23: ذكر | AV23: 0 | AW23: 0 | AX23: 0 | AY23: 0 | AZ23: 0 | BA23: 0 | BB23: =SUM(AV23:BA23) -> 0 | BE23: غير سعودي | BF23: ذكر | BG23: 0 | BH23: 0 | BI23: 0 | BJ23: 0 | BK23: 0 | BL23: 0 | BM23: =SUM(BG23:BL23) -> 0 | BP23: غير سعودي | BQ23: ذكر | BR23: 0 | BS23: 0 | BT23: 0 | BU23: 0 | BV23: 0 | BW23: 0 | BX23: =SUM(BR23:BW23) -> 0 | CA23: غير سعودي | CB23: ذكر | CC23: 0 | CD23: 0 | CE23: 0 | CF23: 0 | CG23: 0 | CH23: 0 | CI23: =SUM(CC23:CH23) -> 0 | CL23: غير سعودي | CM23: ذكر | CN23: 0 | CO23: 0 | CP23: 0 | CQ23: 0 | CR23: 0 | CS23: 0 | CT23: =SUM(CN23:CS23) -> 0 | CW23: غير سعودي | CX23: ذكر | CY23: 0 | CZ23: 0 | DA23: 0 | DB23: 0 | DC23: 0 | DD23: 0 | DE23: =SUM(CY23:DD23) -> 0 | DH23: غير سعودي | DI23: ذكر | DJ23: 0 | DK23: 0 | DL23: 0 | DM23: 0 | DN23: 0 | DO23: 0 | DP23: =SUM(DJ23:DO23) -> 0 | DS23: غير سعودي | DT23: ذكر | DU23: 0 | DV23: 0 | DW23: 0 | DX23: 0 | DY23: 0 | DZ23: 0 | EA23: =SUM(DU23:DZ23) -> 0 | ED23: غير سعودي | EE23: ذكر | EF23: =SUM(D23+O23+Z23+AK23+AV23+BG23+BR23+CC23+CN23+CY23+DJ23+DU23) -> 0 | EG23: =SUM(E23+P23+AA23+AL23+AW23+BH23+BS23+CD23+CO23+CZ23+DK23+DV23) -> 0 | EH23: =SUM(F23+Q23+AB23+AM23+AX23+BI23+BT23+CE23+CP23+DA23+DL23+DW23) -> 0 | EI23: =SUM(G23+R23+AC23+AN23+AY23+BJ23+BU23+CF23+CQ23+DB23+DM23+DX23) -> 0 | EJ23: 0 | EK23: =SUM(I23+T23+AE23+AP23+BA23+BL23+BW23+CH23+CS23+DD23+DO23+DZ23) -> 0 | EL23: =SUM(EF23:EK23) -> 0
C24: أنثى | D24: 0 | E24: 0 | F24: 0 | G24: 0 | H24: 0 | I24: 0 | J24: =SUM(D24:I24) -> 0 | N24: أنثى | O24: 0 | P24: 0 | Q24: 0 | R24: 0 | S24: 0 | T24: 0 | U24: =SUM(O24:T24) -> 0 | Y24: أنثى | Z24: 0 | AA24: 0 | AB24: 0 | AC24: 0 | AD24: 0 | AE24: 0 | AF24: =SUM(Z24:AE24) -> 0 | AJ24: أنثى | AK24: 0 | AL24: 0 | AM24: 0 | AN24: 0 | AO24: 0 | AP24: 5 | AQ24: =SUM(AK24:AP24) -> 5 | AU24: أنثى | AV24: 0 | AW24: 0 | AX24: 0 | AY24: 0 | AZ24: 0 | BA24: 0 | BB24: =SUM(AV24:BA24) -> 0 | BF24: أنثى | BG24: 0 | BH24: 0 | BI24: 0 | BJ24: 0 | BK24: 0 | BL24: 0 | BM24: =SUM(BG24:BL24) -> 0 | BQ24: أنثى | BR24: 0 | BS24: 0 | BT24: 0 | BU24: 0 | BV24: 0 | BW24: 0 | BX24: =SUM(BR24:BW24) -> 0 | CB24: أنثى | CC24: 0 | CD24: 0 | CE24: 0 | CF24: 0 | CG24: 0 | CH24: 0 | CI24: =SUM(CC24:CH24) -> 0 | CM24: أنثى | CN24: 0 | CO24: 0 | CP24: 0 | CQ24: 0 | CR24: 0 | CS24: 0 | CT24: =SUM(CN24:CS24) -> 0 | CX24: أنثى | CY24: 0 | CZ24: 0 | DA24: 0 | DB24: 0 | DC24: 0 | DD24: 0 | DE24: =SUM(CY24:DD24) -> 0 | DI24: أنثى | DJ24: 0 | DK24: 0 | DL24: 0 | DM24: 0 | DN24: 0 | DO24: 0 | DP24: =SUM(DJ24:DO24) -> 0 | DT24: أنثى | DU24: 0 | DV24: 0 | DW24: 0 | DX24: 0 | DY24: 0 | DZ24: 0 | EA24: =SUM(DU24:DZ24) -> 0 | EE24: أنثى | EF24: =SUM(D24+O24+Z24+AK24+AV24+BG24+BR24+CC24+CN24+CY24+DJ24+DU24) -> 0 | EG24: =SUM(E24+P24+AA24+AL24+AW24+BH24+BS24+CD24+CO24+CZ24+DK24+DV24) -> 0 | EH24: =SUM(F24+Q24+AB24+AM24+AX24+BI24+BT24+CE24+CP24+DA24+DL24+DW24) -> 0 | EI24: =SUM(G24+R24+AC24+AN24+AY24+BJ24+BU24+CF24+CQ24+DB24+DM24+DX24) -> 0 | EJ24: =SUM(H24+S24+AD24+AO24+AZ24+BK24+BV24+CG24+CR24+DC24+DN24+DY24) -> 0 | EK24: =SUM(I24+T24+AE24+AP24+BA24+BL24+BW24+CH24+CS24+DD24+DO24+DZ24) -> 5 | EL24: =SUM(EF24:EK24) -> 5
B25: مجموع الغير سعوديين | D25: =SUM(D23:D24) -> 0 | E25: =SUM(E23:E24) -> 0 | F25: =SUM(F23:F24) -> 0 | G25: =SUM(G23:G24) -> 0 | H25: =SUM(H23:H24) -> 0 | I25: =SUM(I23:I24) -> 0 | J25: =SUM(J23:J24) -> 0 | M25: مجموع الغير سعوديين | O25: =SUM(O23:O24) -> 0 | P25: =SUM(P23:P24) -> 0 | Q25: =SUM(Q23:Q24) -> 0 | R25: =SUM(R23:R24) -> 0 | S25: =SUM(S23:S24) -> 0 | T25: =SUM(T23:T24) -> 0 | U25: =SUM(U23:U24) -> 0 | X25: مجموع الغير سعوديين | Z25: =SUM(Z23:Z24) -> 0 | AA25: =SUM(AA23:AA24) -> 0 | AB25: =SUM(AB23:AB24) -> 0 | AC25: =SUM(AC23:AC24) -> 0 | AD25: =SUM(AD23:AD24) -> 0 | AE25: =SUM(AE23:AE24) -> 0 | AF25: =SUM(AF23:AF24) -> 0 | AI25: مجموع الغير سعوديين | AK25: =SUM(AK23:AK24) -> 0 | AL25: =SUM(AL23:AL24) -> 0 | AM25: =SUM(AM23:AM24) -> 0 | AN25: =SUM(AN23:AN24) -> 0 | AO25: =SUM(AO23:AO24) -> 0 | AP25: =SUM(AP23:AP24) -> 5 | AQ25: =SUM(AQ23:AQ24) -> 5 | AT25: مجموع الغير سعوديين | AV25: =SUM(AV23:AV24) -> 0 | AW25: =SUM(AW23:AW24) -> 0 | AX25: =SUM(AX23:AX24) -> 0 | AY25: =SUM(AY23:AY24) -> 0 | AZ25: =SUM(AZ23:AZ24) -> 0 | BA25: =SUM(BA23:BA24) -> 0 | BB25: =SUM(BB23:BB24) -> 0 | BE25: مجموع الغير سعوديين | BG25: =SUM(BG23:BG24) -> 0 | BH25: =SUM(BH23:BH24) -> 0 | BI25: =SUM(BI23:BI24) -> 0 | BJ25: =SUM(BJ23:BJ24) -> 0 | BK25: =SUM(BK23:BK24) -> 0 | BL25: =SUM(BL23:BL24) -> 0 | BM25: =SUM(BM23:BM24) -> 0 | BP25: مجموع الغير سعوديين | BR25: =SUM(BR23:BR24) -> 0 | BS25: =SUM(BS23:BS24) -> 0 | BT25: =SUM(BT23:BT24) -> 0 | BU25: =SUM(BU23:BU24) -> 0 | BV25: =SUM(BV23:BV24) -> 0 | BW25: =SUM(BW23:BW24) -> 0 | BX25: =SUM(BX23:BX24) -> 0 | CA25: مجموع الغير سعوديين | CC25: =SUM(CC23:CC24) -> 0 | CD25: =SUM(CD23:CD24) -> 0 | CE25: =SUM(CE23:CE24) -> 0 | CF25: =SUM(CF23:CF24) -> 0 | CG25: =SUM(CG23:CG24) -> 0 | CH25: =SUM(CH23:CH24) -> 0 | CI25: =SUM(CI23:CI24) -> 0 | CL25: مجموع الغير سعوديين | CN25: =SUM(CN23:CN24) -> 0 | CO25: =SUM(CO23:CO24) -> 0 | CP25: =SUM(CP23:CP24) -> 0 | CQ25: =SUM(CQ23:CQ24) -> 0 | CR25: =SUM(CR23:CR24) -> 0 | CS25: =SUM(CS23:CS24) -> 0 | CT25: =SUM(CT23:CT24) -> 0 | CW25: مجموع الغير سعوديين | CY25: =SUM(CY23:CY24) -> 0 | CZ25: =SUM(CZ23:CZ24) -> 0 | DA25: =SUM(DA23:DA24) -> 0 | DB25: =SUM(DB23:DB24) -> 0 | DC25: =SUM(DC23:DC24) -> 0 | DD25: =SUM(DD23:DD24) -> 0 | DE25: =SUM(DE23:DE24) -> 0 | DH25: مجموع الغير سعوديين | DJ25: =SUM(DJ23:DJ24) -> 0 | DK25: =SUM(DK23:DK24) -> 0 | DL25: =SUM(DL23:DL24) -> 0 | DM25: =SUM(DM23:DM24) -> 0 | DN25: =SUM(DN23:DN24) -> 0 | DO25: =SUM(DO23:DO24) -> 0 | DP25: =SUM(DP23:DP24) -> 0 | DS25: مجموع الغير سعوديين | DU25: =SUM(DU23:DU24) -> 0 | DV25: =SUM(DV23:DV24) -> 0 | DW25: =SUM(DW23:DW24) -> 0 | DX25: =SUM(DX23:DX24) -> 0 | DY25: =SUM(DY23:DY24) -> 0 | DZ25: =SUM(DZ23:DZ24) -> 0 | EA25: =SUM(EA23:EA24) -> 0 | ED25: مجموع الغير سعوديين | EF25: =SUM(EF23:EF24) -> 0 | EG25: =SUM(EG23:EG24) -> 0 | EH25: =SUM(EH23:EH24) -> 0 | EI25: =SUM(EI23:EI24) -> 0 | EJ25: =SUM(EJ23:EJ24) -> 0 | EK25: =SUM(EK23:EK24) -> 5 | EL25: =SUM(EL23:EL24) -> 5
B26: المجموع الكلي | D26: =SUM(D22+D25) -> 0 | E26: =SUM(E22+E25) -> 0 | F26: =SUM(F22+F25) -> 0 | G26: =SUM(G22+G25) -> 0 | H26: =SUM(H22+H25) -> 0 | I26: =SUM(I22+I25) -> 0 | J26: =SUM(J22+J25) -> 0 | M26: المجموع الكلي | O26: =SUM(O22+O25) -> 0 | P26: =SUM(P22+P25) -> 0 | Q26: =SUM(Q22+Q25) -> 0 | R26: =SUM(R22+R25) -> 0 | S26: =SUM(S22+S25) -> 0 | T26: =SUM(T22+T25) -> 0 | U26: =SUM(U22+U25) -> 0 | X26: المجموع الكلي | Z26: =SUM(Z22+Z25) -> 0 | AA26: =SUM(AA22+AA25) -> 0 | AB26: =SUM(AB22+AB25) -> 0 | AC26: =SUM(AC22+AC25) -> 0 | AD26: =SUM(AD22+AD25) -> 0 | AE26: =SUM(AE22+AE25) -> 0 | AF26: =SUM(AF22+AF25) -> 0 | AI26: المجموع الكلي | AK26: =SUM(AK22+AK25) -> 0 | AL26: =SUM(AL22+AL25) -> 0 | AM26: =SUM(AM22+AM25) -> 0 | AN26: =SUM(AN22+AN25) -> 0 | AO26: =SUM(AO22+AO25) -> 10 | AP26: =SUM(AP22+AP25) -> 5 | AQ26: =SUM(AQ22+AQ25) -> 15 | AT26: المجموع الكلي | AV26: =SUM(AV22+AV25) -> 0 | AW26: =SUM(AW22+AW25) -> 0 | AX26: =SUM(AX22+AX25) -> 0 | AY26: =SUM(AY22+AY25) -> 0 | AZ26: =SUM(AZ22+AZ25) -> 0 | BA26: =SUM(BA22+BA25) -> 0 | BB26: =SUM(BB22+BB25) -> 0 | BE26: المجموع الكلي | BG26: =SUM(BG22+BG25) -> 0 | BH26: =SUM(BH22+BH25) -> 0 | BI26: =SUM(BI22+BI25) -> 0 | BJ26: =SUM(BJ22+BJ25) -> 0 | BK26: =SUM(BK22+BK25) -> 0 | BL26: =SUM(BL22+BL25) -> 0 | BM26: =SUM(BM22+BM25) -> 0 | BP26: المجموع الكلي | BR26: =SUM(BR22+BR25) -> 0 | BS26: =SUM(BS22+BS25) -> 0 | BT26: =SUM(BT22+BT25) -> 0 | BU26: =SUM(BU22+BU25) -> 0 | BV26: =SUM(BV22+BV25) -> 0 | BW26: =SUM(BW22+BW25) -> 0 | BX26: =SUM(BX22+BX25) -> 0 | CA26: المجموع الكلي | CC26: =SUM(CC22+CC25) -> 0 | CD26: =SUM(CD22+CD25) -> 0 | CE26: =SUM(CE22+CE25) -> 0 | CF26: =SUM(CF22+CF25) -> 0 | CG26: =SUM(CG22+CG25) -> 0 | CH26: =SUM(CH22+CH25) -> 0 | CI26: =SUM(CI22+CI25) -> 0 | CL26: المجموع الكلي | CN26: =SUM(CN22+CN25) -> 0 | CO26: =SUM(CO22+CO25) -> 0 | CP26: =SUM(CP22+CP25) -> 0 | CQ26: =SUM(CQ22+CQ25) -> 0 | CR26: =SUM(CR22+CR25) -> 0 | CS26: =SUM(CS22+CS25) -> 0 | CT26: =SUM(CT22+CT25) -> 0 | CW26: المجموع الكلي | CY26: =SUM(CY22+CY25) -> 0 | CZ26: =SUM(CZ22+CZ25) -> 0 | DA26: =SUM(DA22+DA25) -> 0 | DB26: =SUM(DB22+DB25) -> 0 | DC26: =SUM(DC22+DC25) -> 0 | DD26: =SUM(DD22+DD25) -> 0 | DE26: =SUM(DE22+DE25) -> 0 | DH26: المجموع الكلي | DJ26: =SUM(DJ22+DJ25) -> 0 | DK26: =SUM(DK22+DK25) -> 0 | DL26: =SUM(DL22+DL25) -> 0 | DM26: =SUM(DM22+DM25) -> 0 | DN26: =SUM(DN22+DN25) -> 0 | DO26: =SUM(DO22+DO25) -> 0 | DP26: =SUM(DP22+DP25) -> 0 | DS26: المجموع الكلي | DU26: =SUM(DU22+DU25) -> 0 | DV26: =SUM(DV22+DV25) -> 0 | DW26: =SUM(DW22+DW25) -> 0 | DX26: =SUM(DX22+DX25) -> 0 | DY26: =SUM(DY22+DY25) -> 0 | DZ26: =SUM(DZ22+DZ25) -> 0 | EA26: =SUM(EA22+EA25) -> 0 | ED26: المجموع الكلي | EF26: =SUM(EF22+EF25) -> 0 | EG26: =SUM(EG22+EG25) -> 0 | EH26: =SUM(EH22+EH25) -> 0 | EI26: =SUM(EI22+EI25) -> 0 | EJ26: =SUM(EJ22+EJ25) -> 10 | EK26: =SUM(EK22+EK25) -> 5 | EL26: =SUM(EL22+EL25) -> 15
A27: المطار القديم | B27: سعودي | C27: ذكر | D27: 0 | E27: 0 | F27: 0 | G27: 0 | H27: 0 | I27: 0 | J27: =SUM(D27:I27) -> 0 | L27: المطار القديم | M27: سعودي | N27: ذكر | O27: 0 | P27: 0 | Q27: 0 | R27: 0 | S27: 0 | T27: 0 | U27: =SUM(O27:T27) -> 0 | W27: المطار القديم | X27: سعودي | Y27: ذكر | Z27: 0 | AA27: 0 | AB27: 0 | AC27: 0 | AD27: 0 | AE27: 0 | AF27: =SUM(Z27:AE27) -> 0 | AH27: المطار القديم | AI27: سعودي | AJ27: ذكر | AK27: 0 | AL27: 0 | AM27: 0 | AN27: 0 | AO27: 0 | AP27: 16 | AQ27: =SUM(AK27:AP27) -> 16 | AS27: المطار القديم | AT27: سعودي | AU27: ذكر | AV27: 0 | AW27: 0 | AX27: 0 | AY27: 0 | AZ27: 0 | BA27: 0 | BB27: =SUM(AV27:BA27) -> 0 | BD27: المطار القديم | BE27: سعودي | BF27: ذكر | BG27: 0 | BH27: 0 | BI27: 0 | BJ27: 0 | BK27: 0 | BL27: 0 | BM27: =SUM(BG27:BL27) -> 0 | BO27: المطار القديم | BP27: سعودي | BQ27: ذكر | BR27: 0 | BS27: 0 | BT27: 0 | BU27: 0 | BV27: 0 | BW27: 0 | BX27: =SUM(BR27:BW27) -> 0 | BZ27: المطار القديم | CA27: سعودي | CB27: ذكر | CC27: 0 | CD27: 0 | CE27: 0 | CF27: 0 | CG27: 0 | CH27: 0 | CI27: =SUM(CC27:CH27) -> 0 | CK27: المطار القديم | CL27: سعودي | CM27: ذكر | CN27: 0 | CO27: 0 | CP27: 0 | CQ27: 0 | CR27: 0 | CS27: 0 | CT27: =SUM(CN27:CS27) -> 0 | CV27: المطار القديم | CW27: سعودي | CX27: ذكر | CY27: 0 | CZ27: 0 | DA27: 0 | DB27: 0 | DC27: 0 | DD27: 0 | DE27: =SUM(CY27:DD27) -> 0 | DG27: المطار القديم | DH27: سعودي | DI27: ذكر | DJ27: 0 | DK27: 0 | DL27: 0 | DM27: 0 | DN27: 0 | DO27: 0 | DP27: =SUM(DJ27:DO27) -> 0 | DR27: المطار القديم | DS27: سعودي | DT27: ذكر | DU27: 0 | DV27: 0 | DW27: 0 | DX27: 0 | DY27: 0 | DZ27: 0 | EA27: =SUM(DU27:DZ27) -> 0 | EC27: =DR27 -> المطار القديم | ED27: سعودي | EE27: ذكر | EF27: =SUM(D27+O27+Z27+AK27+AV27+BG27+BR27+CC27+CN27+CY27+DJ27+DU27) -> 0 | EG27: =SUM(E27+P27+AA27+AL27+AW27+BH27+BS27+CD27+CO27+CZ27+DK27+DV27) -> 0 | EH27: =SUM(F27+Q27+AB27+AM27+AX27+BI27+BT27+CE27+CP27+DA27+DL27+DW27) -> 0 | EI27: =SUM(G27+R27+AC27+AN27+AY27+BJ27+BU27+CF27+CQ27+DB27+DM27+DX27) -> 0 | EJ27: 0 | EK27: =SUM(I27+T27+AE27+AP27+BA27+BL27+BW27+CH27+CS27+DD27+DO27+DZ27) -> 16 | EL27: =SUM(EF27:EK27) -> 16
C28: أنثى | D28: 0 | E28: 0 | F28: 0 | G28: 0 | H28: 0 | I28: 0 | J28: =SUM(D28:I28) -> 0 | N28: أنثى | O28: 0 | P28: 0 | Q28: 0 | R28: 0 | S28: 0 | T28: 0 | U28: =SUM(O28:T28) -> 0 | Y28: أنثى | Z28: 0 | AA28: 0 | AB28: 0 | AC28: 0 | AD28: 0 | AE28: 0 | AF28: =SUM(Z28:AE28) -> 0 | AJ28: أنثى | AK28: 0 | AL28: 0 | AM28: 0 | AN28: 0 | AO28: 11 | AP28: 37 | AQ28: =SUM(AK28:AP28) -> 48 | AU28: أنثى | AV28: 0 | AW28: 0 | AX28: 0 | AY28: 0 | AZ28: 0 | BA28: 0 | BB28: =SUM(AV28:BA28) -> 0 | BF28: أنثى | BG28: 0 | BH28: 0 | BI28: 0 | BJ28: 0 | BK28: 0 | BL28: 0 | BM28: =SUM(BG28:BL28) -> 0 | BQ28: أنثى | BR28: 0 | BS28: 0 | BT28: 0 | BU28: 0 | BV28: 0 | BW28: 0 | BX28: =SUM(BR28:BW28) -> 0 | CB28: أنثى | CC28: 0 | CD28: 0 | CE28: 0 | CF28: 0 | CG28: 0 | CH28: 0 | CI28: =SUM(CC28:CH28) -> 0 | CM28: أنثى | CN28: 0 | CO28: 0 | CP28: 0 | CQ28: 0 | CR28: 0 | CS28: 0 | CT28: =SUM(CN28:CS28) -> 0 | CX28: أنثى | CY28: 0 | CZ28: 0 | DA28: 0 | DB28: 0 | DC28: 0 | DD28: 0 | DE28: =SUM(CY28:DD28) -> 0 | DI28: أنثى | DJ28: 0 | DK28: 0 | DL28: 0 | DM28: 0 | DN28: 0 | DO28: 0 | DP28: =SUM(DJ28:DO28) -> 0 | DT28: أنثى | DU28: 0 | DV28: 0 | DW28: 0 | DX28: 0 | DY28: 0 | DZ28: 0 | EA28: =SUM(DU28:DZ28) -> 0 | EE28: أنثى | EF28: =SUM(D28+O28+Z28+AK28+AV28+BG28+BR28+CC28+CN28+CY28+DJ28+DU28) -> 0 | EG28: =SUM(E28+P28+AA28+AL28+AW28+BH28+BS28+CD28+CO28+CZ28+DK28+DV28) -> 0 | EH28: =SUM(F28+Q28+AB28+AM28+AX28+BI28+BT28+CE28+CP28+DA28+DL28+DW28) -> 0 | EI28: =SUM(G28+R28+AC28+AN28+AY28+BJ28+BU28+CF28+CQ28+DB28+DM28+DX28) -> 0 | EJ28: =SUM(H28+S28+AD28+AO28+AZ28+BK28+BV28+CG28+CR28+DC28+DN28+DY28) -> 11 | EK28: =SUM(I28+T28+AE28+AP28+BA28+BL28+BW28+CH28+CS28+DD28+DO28+DZ28) -> 37 | EL28: =SUM(EF28:EK28) -> 48
B29: مجموع السعوديين | D29: =SUM(D27:D28) -> 0 | E29: =SUM(E27:E28) -> 0 | F29: =SUM(F27:F28) -> 0 | G29: =SUM(G27:G28) -> 0 | H29: =SUM(H27:H28) -> 0 | I29: =SUM(I27:I28) -> 0 | J29: =SUM(J27:J28) -> 0 | M29: مجموع السعوديين | O29: =SUM(O27:O28) -> 0 | P29: =SUM(P27:P28) -> 0 | Q29: =SUM(Q27:Q28) -> 0 | R29: =SUM(R27:R28) -> 0 | S29: =SUM(S27:S28) -> 0 | T29: =SUM(T27:T28) -> 0 | U29: =SUM(U27:U28) -> 0 | X29: مجموع السعوديين | Z29: =SUM(Z27:Z28) -> 0 | AA29: =SUM(AA27:AA28) -> 0 | AB29: =SUM(AB27:AB28) -> 0 | AC29: =SUM(AC27:AC28) -> 0 | AD29: =SUM(AD27:AD28) -> 0 | AE29: =SUM(AE27:AE28) -> 0 | AF29: =SUM(AF27:AF28) -> 0 | AI29: مجموع السعوديين | AK29: =SUM(AK27:AK28) -> 0 | AL29: =SUM(AL27:AL28) -> 0 | AM29: =SUM(AM27:AM28) -> 0 | AN29: =SUM(AN27:AN28) -> 0 | AO29: =SUM(AO27:AO28) -> 11 | AP29: =SUM(AP27:AP28) -> 53 | AQ29: =SUM(AQ27:AQ28) -> 64 | AT29: مجموع السعوديين | AV29: =SUM(AV27:AV28) -> 0 | AW29: =SUM(AW27:AW28) -> 0 | AX29: =SUM(AX27:AX28) -> 0 | AY29: =SUM(AY27:AY28) -> 0 | AZ29: =SUM(AZ27:AZ28) -> 0 | BA29: =SUM(BA27:BA28) -> 0 | BB29: =SUM(BB27:BB28) -> 0 | BE29: مجموع السعوديين | BG29: =SUM(BG27:BG28) -> 0 | BH29: =SUM(BH27:BH28) -> 0 | BI29: =SUM(BI27:BI28) -> 0 | BJ29: =SUM(BJ27:BJ28) -> 0 | BK29: =SUM(BK27:BK28) -> 0 | BL29: =SUM(BL27:BL28) -> 0 | BM29: =SUM(BM27:BM28) -> 0 | BP29: مجموع السعوديين | BR29: =SUM(BR27:BR28) -> 0 | BS29: =SUM(BS27:BS28) -> 0 | BT29: =SUM(BT27:BT28) -> 0 | BU29: =SUM(BU27:BU28) -> 0 | BV29: =SUM(BV27:BV28) -> 0 | BW29: =SUM(BW27:BW28) -> 0 | BX29: =SUM(BX27:BX28) -> 0 | CA29: مجموع السعوديين | CC29: =SUM(CC27:CC28) -> 0 | CD29: =SUM(CD27:CD28) -> 0 | CE29: =SUM(CE27:CE28) -> 0 | CF29: =SUM(CF27:CF28) -> 0 | CG29: =SUM(CG27:CG28) -> 0 | CH29: =SUM(CH27:CH28) -> 0 | CI29: =SUM(CI27:CI28) -> 0 | CL29: مجموع السعوديين | CN29: =SUM(CN27:CN28) -> 0 | CO29: =SUM(CO27:CO28) -> 0 | CP29: =SUM(CP27:CP28) -> 0 | CQ29: =SUM(CQ27:CQ28) -> 0 | CR29: =SUM(CR27:CR28) -> 0 | CS29: =SUM(CS27:CS28) -> 0 | CT29: =SUM(CT27:CT28) -> 0 | CW29: مجموع السعوديين | CY29: =SUM(CY27:CY28) -> 0 | CZ29: =SUM(CZ27:CZ28) -> 0 | DA29: =SUM(DA27:DA28) -> 0 | DB29: =SUM(DB27:DB28) -> 0 | DC29: =SUM(DC27:DC28) -> 0 | DD29: =SUM(DD27:DD28) -> 0 | DE29: =SUM(DE27:DE28) -> 0 | DH29: مجموع السعوديين | DJ29: =SUM(DJ27:DJ28) -> 0 | DK29: =SUM(DK27:DK28) -> 0 | DL29: =SUM(DL27:DL28) -> 0 | DM29: =SUM(DM27:DM28) -> 0 | DN29: =SUM(DN27:DN28) -> 0 | DO29: =SUM(DO27:DO28) -> 0 | DP29: =SUM(DP27:DP28) -> 0 | DS29: مجموع السعوديين | DU29: =SUM(DU27:DU28) -> 0 | DV29: =SUM(DV27:DV28) -> 0 | DW29: =SUM(DW27:DW28) -> 0 | DX29: =SUM(DX27:DX28) -> 0 | DY29: =SUM(DY27:DY28) -> 0 | DZ29: =SUM(DZ27:DZ28) -> 0 | EA29: =SUM(EA27:EA28) -> 0 | ED29: مجموع السعوديين | EF29: =SUM(EF27:EF28) -> 0 | EG29: =SUM(EG27:EG28) -> 0 | EH29: =SUM(EH27:EH28) -> 0 | EI29: =SUM(EI27:EI28) -> 0 | EJ29: =SUM(EJ27:EJ28) -> 11 | EK29: =SUM(EK27:EK28) -> 53 | EL29: =SUM(EL27:EL28) -> 64
B30: غير سعودي | C30: ذكر | D30: 0 | E30: 0 | F30: 0 | G30: 0 | H30: 0 | I30: 0 | J30: =SUM(D30:I30) -> 0 | M30: غير سعودي | N30: ذكر | O30: 0 | P30: 0 | Q30: 0 | R30: 0 | S30: 0 | T30: 0 | U30: =SUM(O30:T30) -> 0 | X30: غير سعودي | Y30: ذكر | Z30: 0 | AA30: 0 | AB30: 0 | AC30: 0 | AD30: 0 | AE30: 0 | AF30: =SUM(Z30:AE30) -> 0 | AI30: غير سعودي | AJ30: ذكر | AK30: 0 | AL30: 0 | AM30: 0 | AN30: 0 | AO30: 0 | AP30: 2 | AQ30: =SUM(AK30:AP30) -> 2 | AT30: غير سعودي | AU30: ذكر | AV30: 0 | AW30: 0 | AX30: 0 | AY30: 0 | AZ30: 0 | BA30: 0 | BB30: =SUM(AV30:BA30) -> 0 | BE30: غير سعودي | BF30: ذكر | BG30: 0 | BH30: 0 | BI30: 0 | BJ30: 0 | BK30: 0 | BL30: 0 | BM30: =SUM(BG30:BL30) -> 0 | BP30: غير سعودي | BQ30: ذكر | BR30: 0 | BS30: 0 | BT30: 0 | BU30: 0 | BV30: 0 | BW30: 0 | BX30: =SUM(BR30:BW30) -> 0 | CA30: غير سعودي | CB30: ذكر | CC30: 0 | CD30: 0 | CE30: 0 | CF30: 0 | CG30: 0 | CH30: 0 | CI30: =SUM(CC30:CH30) -> 0 | CL30: غير سعودي | CM30: ذكر | CN30: 0 | CO30: 0 | CP30: 0 | CQ30: 0 | CR30: 0 | CS30: 0 | CT30: =SUM(CN30:CS30) -> 0 | CW30: غير سعودي | CX30: ذكر | CY30: 0 | CZ30: 0 | DA30: 0 | DB30: 0 | DC30: 0 | DD30: 0 | DE30: =SUM(CY30:DD30) -> 0 | DH30: غير سعودي | DI30: ذكر | DJ30: 0 | DK30: 0 | DL30: 0 | DM30: 0 | DN30: 0 | DO30: 0 | DP30: =SUM(DJ30:DO30) -> 0 | DS30: غير سعودي | DT30: ذكر | DU30: 0 | DV30: 0 | DW30: 0 | DX30: 0 | DY30: 0 | DZ30: 0 | EA30: =SUM(DU30:DZ30) -> 0 | ED30: غير سعودي | EE30: ذكر | EF30: =SUM(D30+O30+Z30+AK30+AV30+BG30+BR30+CC30+CN30+CY30+DJ30+DU30) -> 0 | EG30: =SUM(E30+P30+AA30+AL30+AW30+BH30+BS30+CD30+CO30+CZ30+DK30+DV30) -> 0 | EH30: =SUM(F30+Q30+AB30+AM30+AX30+BI30+BT30+CE30+CP30+DA30+DL30+DW30) -> 0 | EI30: =SUM(G30+R30+AC30+AN30+AY30+BJ30+BU30+CF30+CQ30+DB30+DM30+DX30) -> 0 | EJ30: 0 | EK30: =SUM(I30+T30+AE30+AP30+BA30+BL30+BW30+CH30+CS30+DD30+DO30+DZ30) -> 2 | EL30: =SUM(EF30:EK30) -> 2
