Workbook

Sheet نساء إنتهى حملهن
A1: شرق جدة | B1: ب ـ نساء إنتهى حملهن خلال شهر | G1: 1 | H1: عام | I1: 1447هـ | P1: شرق جدة | Q1: ب ـ نساء إنتهى حملهن خلال شهر | V1: 2 | W1: عام | X1: 1447هـ | AE1: شرق جدة | AF1: ب ـ نساء إنتهى حملهن خلال شهر | AK1: 3 | AL1: عام | AM1: 1447هـ | AT1: شرق جدة | AU1: ب ـ نساء إنتهى حملهن خلال شهر | AZ1: 4 | BA1: عام | BB1: 1447هـ | BI1: شرق جدة | BJ1: ب ـ نساء إنتهى حملهن خلال شهر | BO1: 5 | BP1: عام | BQ1: 1447هـ | BX1: شرق جدة | BY1: ب ـ نساء إنتهى حملهن خلال شهر | CD1: 6 | CE1: عام | CF1: 1447هـ | CM1: شرق جدة | CN1: ب ـ نساء إنتهى حملهن خلال شهر | CS1: 7 | CT1: عام | CU1: 1447هـ | DB1: شرق جدة | DC1: ب ـ نساء إنتهى حملهن خلال شهر | DH1: 8 | DI1: عام | DJ1: 1447هـ | DQ1: شرق جدة | DR1: ب ـ نساء إنتهى حملهن خلال شهر | DW1: 9 | DX1: عام | DY1: 1447هـ | EF1: شرق جدة | EG1: ب ـ نساء إنتهى حملهن خلال شهر | EL1: 10 | EM1: عام | EN1: 1447هـ | EU1: شرق جدة | EV1: ب ـ نساء إنتهى حملهن خلال شهر | FA1: 11 | FB1: عام | FC1: 1447هـ | FJ1: شرق جدة | FK1: ب ـ نساء إنتهى حملهن خلال شهر | FP1: 12 | FQ1: عام | FR1: 1447هـ | FY1: شرق جدة | FZ1: ب ـ نساء إنتهى حملهن خلال | GF1: عام | GG1: 1447هـ
A3: المركز الصحي | B3: عدد النساء اللاتي إنتهى حملهن خلال الشهر | D3: عدد الزيارات أثناء الحمل | H3: عدد زيارات النفاس | K3: إستكمال تحصينات الكزاز * | P3: المركز الصحي | Q3: عدد النساء اللاتي إنتهى حملهن خلال الشهر | S3: عدد الزيارات أثناء الحمل | W3: عدد زيارات النفاس | Z3: إستكمال تحصينات الكزاز * | AE3: المركز الصحي | AF3: عدد النساء اللاتي إنتهى حملهن خلال الشهر | AH3: عدد الزيارات أثناء الحمل | AL3: عدد زيارات النفاس | AO3: إستكمال تحصينات الكزاز * | AT3: المركز الصحي | AU3: عدد النساء اللاتي إنتهى حملهن خلال الشهر | AW3: عدد الزيارات أثناء الحمل | BA3: عدد زيارات النفاس | BD3: إستكمال تحصينات الكزاز * | BI3: المركز الصحي | BJ3: عدد النساء اللاتي إنتهى حملهن خلال الشهر | BL3: عدد الزيارات أثناء الحمل | BP3: عدد زيارات النفاس | BS3: إستكمال تحصينات الكزاز * | BX3: المركز الصحي | BY3: عدد النساء اللاتي إنتهى حملهن خلال الشهر | CA3: عدد الزيارات أثناء الحمل | CE3: عدد زيارات النفاس | CH3: إستكمال تحصينات الكزاز * | CM3: المركز الصحي | CN3: عدد النساء اللاتي إنتهى حملهن خلال الشهر | CP3: عدد الزيارات أثناء الحمل | CT3: عدد زيارات النفاس | CW3: إستكمال تحصينات الكزاز * | DB3: المركز الصحي | DC3: عدد النساء اللاتي إنتهى حملهن خلال الشهر | DE3: عدد الزيارات أثناء الحمل | DI3: عدد زيارات النفاس | DL3: إستكمال تحصينات الكزاز * | DQ3: المركز الصحي | DR3: عدد النساء اللاتي إنتهى حملهن خلال الشهر | DT3: عدد الزيارات أثناء الحمل | DX3: عدد زيارات النفاس | EA3: إستكمال تحصينات الكزاز * | EF3: المركز الصحي | EG3: عدد النساء اللاتي إنتهى حملهن خلال الشهر | EI3: عدد الزيارات أثناء الحمل | EM3: عدد زيارات النفاس | EP3: إستكمال تحصينات الكزاز * | EU3: المركز الصحي | EV3: عدد النساء اللاتي إنتهى حملهن خلال الشهر | EX3: عدد الزيارات أثناء الحمل | FB3: عدد زيارات النفاس | FE3: إستكمال تحصينات الكزاز * | FJ3: المركز الصحي | FK3: عدد النساء اللاتي إنتهى حملهن خلال الشهر | FM3: عدد الزيارات أثناء الحمل | FQ3: عدد زيارات النفاس | FT3: إستكمال تحصينات الكزاز * | FY3: المركز الصحي | FZ3: عدد النساء اللاتي إنتهى حملهن خلال العام | GB3: عدد الزيارات أثناء الحمل | GF3: عدد زيارات النفاس | GI3: إستكمال تحصينات الكزاز *
D4: أقل من4 زيارات | F4: أكثر من 4 زيارات | H4: خلال 10 أيام الأولى | I4: نهاية الفترة | K4: أكملت | M4: لم تستكمل | S4: أقل من4 زيارات | U4: أكثر من 4 زيارات | W4: خلال 10 أيام الأولى | X4: نهاية الفترة | Z4: أكملت | AB4: لم تستكمل | AH4: أقل من4 زيارات | AJ4: أكثر من 4 زيارات | AL4: خلال 10 أيام الأولى | AM4: نهاية الفترة | AO4: أكملت | AQ4: لم تستكمل | AW4: أقل من4 زيارات | AY4: أكثر من 4 زيارات | BA4: خلال 10 أيام الأولى | BB4: نهاية الفترة | BD4: أكملت | BF4: لم تستكمل | BL4: أقل من4 زيارات | BN4: أكثر من 4 زيارات | BP4: خلال 10 أيام الأولى | BQ4: نهاية الفترة | BS4: أكملت | BU4: لم تستكمل | CA4: أقل من4 زيارات | CC4: أكثر من 4 زيارات | CE4: خلال 10 أيام الأولى | CF4: نهاية الفترة | CH4: أكملت | CJ4: لم تستكمل | CP4: أقل من4 زيارات | CR4: أكثر من 4 زيارات | CT4: خلال 10 أيام الأولى | CU4: نهاية الفترة | CW4: أكملت | CY4: لم تستكمل | DE4: أقل من4 زيارات | DG4: أكثر من 4 زيارات | DI4: خلال 10 أيام الأولى | DJ4: نهاية الفترة | DL4: أكملت | DN4: لم تستكمل | DT4: أقل من4 زيارات | DV4: أكثر من 4 زيارات | DX4: خلال 10 أيام الأولى | DY4: نهاية الفترة | EA4: أكملت | EC4: لم تستكمل | EI4: أقل من4 زيارات | EK4: أكثر من 4 زيارات | EM4: خلال 10 أيام الأولى | EN4: نهاية الفترة | EP4: أكملت | ER4: لم تستكمل | EX4: أقل من4 زيارات | EZ4: أكثر من 4 زيارات | FB4: خلال 10 أيام الأولى | FC4: نهاية الفترة | FE4: أكملت | FG4: لم تستكمل | FM4: أقل من4 زيارات | FO4: أكثر من 4 زيارات | FQ4: خلال 10 أيام الأولى | FR4: نهاية الفترة | FT4: أكملت | FV4: لم تستكمل | GB4: أقل من4 زيارات | GD4: أكثر من 4 زيارات | GF4: خلال 10 أيام الأولى | GG4: نهاية الفترة | GI4: أكملت | GK4: لم تستكمل
A5: الربيع والتوفيق | B5: سعوديات | C5: 0 | D5: 0 | F5: 0 | H5: 0 | I5: 0 | K5: 0 | M5: 0 | O5: =SUM(C5) -> 0 | P5: الربيع والتوفيق | Q5: سعوديات | R5: 0 | S5: 0 | U5: 0 | W5: 0 | X5: 0 | Z5: 0 | AB5: 0 | AD5: =SUM(R5) -> 0 | AE5: الربيع والتوفيق | AF5: سعوديات | AG5: 0 | AH5: 0 | AJ5: 0 | AL5: 0 | AM5: 0 | AO5: 0 | AQ5: 0 | AS5: =SUM(AG5) -> 0 | AT5: الربيع والتوفيق | AU5: سعوديات | AV5: 0 | AW5: 0 | AY5: 0 | BA5: 0 | BB5: 0 | BD5: 0 | BF5: 0 | BH5: =SUM(AV5) -> 0 | BI5: الربيع والتوفيق | BJ5: سعوديات | BK5: 0 | BL5: 0 | BN5: 0 | BP5: 0 | BQ5: 0 | BS5: 0 | BU5: 0 | BW5: =SUM(BK5) -> 0 | BX5: الربيع والتوفيق | BY5: سعوديات | BZ5: 0 | CA5: 0 | CC5: 0 | CE5: 0 | CF5: 0 | CH5: 0 | CJ5: 0 | CL5: =SUM(BZ5) -> 0 | CM5: الربيع والتوفيق | CN5: سعوديات | CO5: 0 | CP5: 0 | CR5: 0 | CT5: 0 | CU5: 0 | CW5: 0 | CY5: 0 | DA5: =SUM(CO5) -> 0 | DB5: الربيع والتوفيق | DC5: سعوديات | DD5: 0 | DE5: 0 | DG5: 0 | DI5: 0 | DJ5: 0 | DL5: 0 | DN5: 0 | DP5: =SUM(DD5) -> 0 | DQ5: الربيع والتوفيق | DR5: سعوديات | DS5: 0 | DT5: 0 | DV5: 0 | DX5: 0 | DY5: 0 | EA5: 0 | EC5: 0 | EE5: =SUM(DS5) -> 0 | EF5: الربيع والتوفيق | EG5: سعوديات | EH5: 0 | EI5: 0 | EK5: 0 | EM5: 0 | EN5: 0 | EP5: 0 | ER5: 0 | ET5: =SUM(EH5) -> 0 | EU5: الربيع والتوفيق | EV5: سعوديات | EW5: 0 | EX5: 0 | EZ5: 0 | FB5: 0 | FC5: 0 | FE5: 0 | FG5: 0 | FI5: =SUM(EW5) -> 0 | FJ5: الربيع والتوفيق | FK5: سعوديات | FL5: 0 | FM5: 0 | FO5: 0 | FQ5: 0 | FR5: 0 | FT5: 0 | FV5: 0 | FX5: =SUM(FL5) -> 0 | FY5: =(FJ5) -> الربيع والتوفيق | FZ5: سعوديات | GA5: =SUM(C5+R5+AG5+AV5+BK5+BZ5+CO5+DD5+DS5+EH5+EW5+FL5) -> 0 | GB5: =SUM(D5+S5+AH5+AW5+BL5+CA5+CP5+DE5+DT5+EI5+EX5+FM5) -> 0 | GD5: =SUM(F5+U5+AJ5+AY5+BN5+CC5+CR5+DG5+DV5+EK5+EZ5+FO5) -> 0 | GF5: =SUM(H5+W5+AL5+BA5+BP5+CE5+CT5+DI5+DX5+EM5+FB5+FQ5) -> 0 | GG5: =SUM(I5+X5+AM5+BB5+BQ5+CF5+CU5+DJ5+DY5+EN5+FC5+FR5) -> 0 | GI5: =SUM(K5+Z5+AO5+BD5+BS5+CH5+CW5+DL5+EA5+EP5+FE5+FT5) -> 0 | GK5: =SUM(M5+AB5+AQ5+BF5+BU5+CJ5+CY5+DN5+EC5+ER5+FG5+FV5) -> 0 | GM5: =SUM(GA5) -> 0
B6: غير سعوديات | C6: 0 | D6: 0 | F6: 0 | H6: 0 | I6: 0 | K6: 0 | M6: 0 | O6: =SUM(D5:G5) -> 0 | Q6: غير سعوديات | R6: 0 | S6: 0 | U6: 0 | W6: 0 | X6: 0 | Z6: 0 | AB6: 0 | AD6: =SUM(S5:V5) -> 0 | AF6: غير سعوديات | AG6: 0 | AH6: 0 | AJ6: 0 | AL6: 0 | AM6: 0 | AO6: 0 | AQ6: 0 | AS6: =SUM(AH5:AK5) -> 0 | AU6: غير سعوديات | AV6: 0 | AW6: 0 | AY6: 0 | BA6: 0 | BB6: 0 | BD6: 0 | BF6: 0 | BH6: =SUM(AW5:AZ5) -> 0 | BJ6: غير سعوديات | BK6: 0 | BL6: 0 | BN6: 0 | BP6: 0 | BQ6: 0 | BS6: 0 | BU6: 0 | BW6: =SUM(BL5:BO5) -> 0 | BY6: غير سعوديات | BZ6: 0 | CA6: 0 | CC6: 0 | CE6: 0 | CF6: 0 | CH6: 0 | CJ6: 0 | CL6: =SUM(CA5:CD5) -> 0 | CN6: غير سعوديات | CO6: 0 | CP6: 0 | CR6: 0 | CT6: 0 | CU6: 0 | CW6: 0 | CY6: 0 | DA6: =SUM(CP5:CS5) -> 0 | DC6: غير سعوديات | DD6: 0 | DE6: 0 | DG6: 0 | DI6: 0 | DJ6: 0 | DL6: 0 | DN6: 0 | DP6: =SUM(DE5:DH5) -> 0 | DR6: غير سعوديات | DS6: 0 | DT6: 0 | DV6: 0 | DX6: 0 | DY6: 0 | EA6: 0 | EC6: 0 | EE6: =SUM(DT5:DW5) -> 0 | EG6: غير سعوديات | EH6: 0 | EI6: 0 | EK6: 0 | EM6: 0 | EN6: 0 | EP6: 0 | ER6: 0 | ET6: =SUM(EI5:EL5) -> 0 | EV6: غير سعوديات | EW6: 0 | EX6: 0 | EZ6: 0 | FB6: 0 | FC6: 0 | FE6: 0 | FG6: 0 | FI6: =SUM(EX5:FA5) -> 0 | FK6: غير سعوديات | FL6: 0 | FM6: 0 | FO6: 0 | FQ6: 0 | FR6: 0 | FT6: 0 | FV6: 0 | FX6: =SUM(FM5:FP5) -> 0 | FZ6: غير سعوديات | GA6: =SUM(C6+R6+AG6+AV6+BK6+BZ6+CO6+DD6+DS6+EH6+EW6+FL6) -> 0 | GB6: =SUM(D6+S6+AH6+AW6+BL6+CA6+CP6+DE6+DT6+EI6+EX6+FM6) -> 0 | GD6: =SUM(F6+U6+AJ6+AY6+BN6+CC6+CR6+DG6+DV6+EK6+EZ6+FO6) -> 0 | GF6: =SUM(H6+W6+AL6+BA6+BP6+CE6+CT6+DI6+DX6+EM6+FB6+FQ6) -> 0 | GG6: =SUM(I6+X6+AM6+BB6+BQ6+CF6+CU6+DJ6+DY6+EN6+FC6+FR6) -> 0 | GI6: =SUM(K6+Z6+AO6+BD6+BS6+CH6+CW6+DL6+EA6+EP6+FE6+FT6) -> 0 | GK6: =SUM(M6+AB6+AQ6+BF6+BU6+CJ6+CY6+DN6+EC6+ER6+FG6+FV6) -> 0 | GM6: =SUM(GB5:GE5) -> 0
B7: المجموع | C7: =SUM(C5:C6) -> 0 | D7: =SUM(D5:E6) -> 0 | F7: =SUM(F5:G6) -> 0 | H7: =SUM(H5:H6) -> 0 | I7: =SUM(I5:J6) -> 0 | K7: =SUM(K5:L6) -> 0 | M7: =SUM(M5:N6) -> 0 | O7: =SUM(K5:N5) -> 0 | Q7: المجموع | R7: =SUM(R5:R6) -> 0 | S7: =SUM(S5:T6) -> 0 | U7: =SUM(U5:V6) -> 0 | W7: =SUM(W5:W6) -> 0 | X7: =SUM(X5:Y6) -> 0 | Z7: =SUM(Z5:AA6) -> 0 | AB7: =SUM(AB5:AC6) -> 0 | AD7: =SUM(Z5:AC5) -> 0 | AF7: المجموع | AG7: =SUM(AG5:AG6) -> 0 | AH7: =SUM(AH5:AI6) -> 0 | AJ7: =SUM(AJ5:AK6) -> 0 | AL7: =SUM(AL5:AL6) -> 0 | AM7: =SUM(AM5:AN6) -> 0 | AO7: =SUM(AO5:AP6) -> 0 | AQ7: =SUM(AQ5:AR6) -> 0 | AS7: =SUM(AO5:AR5) -> 0 | AU7: المجموع | AV7: =SUM(AV5:AV6) -> 0 | AW7: =SUM(AW5:AX6) -> 0 | AY7: =SUM(AY5:AZ6) -> 0 | BA7: =SUM(BA5:BA6) -> 0 | BB7: =SUM(BB5:BC6) -> 0 | BD7: =SUM(BD5:BE6) -> 0 | BF7: =SUM(BF5:BG6) -> 0 | BH7: =SUM(BD5:BG5) -> 0 | BJ7: المجموع | BK7: =SUM(BK5:BK6) -> 0 | BL7: =SUM(BL5:BM6) -> 0 | BN7: =SUM(BN5:BO6) -> 0 | BP7: =SUM(BP5:BP6) -> 0 | BQ7: =SUM(BQ5:BR6) -> 0 | BS7: =SUM(BS5:BT6) -> 0 | BU7: =SUM(BU5:BV6) -> 0 | BW7: =SUM(BS5:BV5) -> 0 | BY7: المجموع | BZ7: =SUM(BZ5:BZ6) -> 0 | CA7: =SUM(CA5:CB6) -> 0 | CC7: =SUM(CC5:CD6) -> 0 | CE7: =SUM(CE5:CE6) -> 0 | CF7: =SUM(CF5:CG6) -> 0 | CH7: =SUM(CH5:CI6) -> 0 | CJ7: =SUM(CJ5:CK6) -> 0 | CL7: =SUM(CH5:CK5) -> 0 | CN7: المجموع | CO7: =SUM(CO5:CO6) -> 0 | CP7: =SUM(CP5:CQ6) -> 0 | CR7: =SUM(CR5:CS6) -> 0 | CT7: =SUM(CT5:CT6) -> 0 | CU7: =SUM(CU5:CV6) -> 0 | CW7: =SUM(CW5:CX6) -> 0 | CY7: =SUM(CY5:CZ6) -> 0 | DA7: =SUM(CW5:CZ5) -> 0 | DC7: المجموع | DD7: =SUM(DD5:DD6) -> 0 | DE7: =SUM(DE5:DF6) -> 0 | DG7: =SUM(DG5:DH6) -> 0 | DI7: =SUM(DI5:DI6) -> 0 | DJ7: =SUM(DJ5:DK6) -> 0 | DL7: =SUM(DL5:DM6) -> 0 | DN7: =SUM(DN5:DO6) -> 0 | DP7: =SUM(DL5:DO5) -> 0 | DR7: المجموع | DS7: =SUM(DS5:DS6) -> 0 | DT7: =SUM(DT5:DU6) -> 0 | DV7: =SUM(DV5:DW6) -> 0 | DX7: =SUM(DX5:DX6) -> 0 | DY7: =SUM(DY5:DZ6) -> 0 | EA7: =SUM(EA5:EB6) -> 0 | EC7: =SUM(EC5:ED6) -> 0 | EE7: =SUM(EA5:ED5) -> 0 | EG7: المجموع | EH7: =SUM(EH5:EH6) -> 0 | EI7: =SUM(EI5:EJ6) -> 0 | EK7: =SUM(EK5:EL6) -> 0 | EM7: =SUM(EM5:EM6) -> 0 | EN7: =SUM(EN5:EO6) -> 0 | EP7: =SUM(EP5:EQ6) -> 0 | ER7: =SUM(ER5:ES6) -> 0 | ET7: =SUM(EP5:ES5) -> 0 | EV7: المجموع | EW7: =SUM(EW5:EW6) -> 0 | EX7: =SUM(EX5:EY6) -> 0 | EZ7: =SUM(EZ5:FA6) -> 0 | FB7: =SUM(FB5:FB6) -> 0 | FC7: =SUM(FC5:FD6) -> 0 | FE7: =SUM(FE5:FF6) -> 0 | FG7: =SUM(FG5:FH6) -> 0 | FI7: =SUM(FE5:FH5) -> 0 | FK7: المجموع | FL7: =SUM(FL5:FL6) -> 0 | FM7: =SUM(FM5:FN6) -> 0 | FO7: =SUM(FO5:FP6) -> 0 | FQ7: =SUM(FQ5:FQ6) -> 0 | FR7: =SUM(FR5:FS6) -> 0 | FT7: =SUM(FT5:FU6) -> 0 | FV7: =SUM(FV5:FW6) -> 0 | FX7: =SUM(FT5:FW5) -> 0 | FZ7: المجموع | GA7: =SUM(GA5:GA6) -> 0 | GB7: =SUM(GB5:GC6) -> 0 | GD7: =SUM(GD5:GE6) -> 0 | GF7: =SUM(GF5:GF6) -> 0 | GG7: =SUM(GG5:GH6) -> 0 | GI7: =SUM(GI5:GJ6) -> 0 | GK7: =SUM(GK5:GL6) -> 0 | GM7: =SUM(GI5:GL5) -> 0
D8: مكان الولادة | H8: نتيجة الحمل | O8: =SUM(D11:G11) -> 0 | S8: مكان الولادة | W8: نتيجة الحمل | AD8: =SUM(S11:V11) -> 0 | AH8: مكان الولادة | AL8: نتيجة الحمل | AS8: =SUM(AH11:AK11) -> 0 | AW8: مكان الولادة | BA8: نتيجة الحمل | BH8: =SUM(AW11:AZ11) -> 0 | BL8: مكان الولادة | BP8: نتيجة الحمل | BW8: =SUM(BL11:BO11) -> 0 | CA8: مكان الولادة | CE8: نتيجة الحمل | CL8: =SUM(CA11:CD11) -> 0 | CP8: مكان الولادة | CT8: نتيجة الحمل | DA8: =SUM(CP11:CS11) -> 0 | DE8: مكان الولادة | DI8: نتيجة الحمل | DP8: =SUM(DE11:DH11) -> 0 | DT8: مكان الولادة | DX8: نتيجة الحمل | EE8: =SUM(DT11:DW11) -> 0 | EI8: مكان الولادة | EM8: نتيجة الحمل | ET8: =SUM(EI11:EL11) -> 0 | EX8: مكان الولادة | FB8: نتيجة الحمل | FI8: =SUM(EX11:FA11) -> 0 | FM8: مكان الولادة | FQ8: نتيجة الحمل | FX8: =SUM(FM11:FP11) -> 0 | GB8: مكان الولادة | GF8: نتيجة الحمل | GM8: =SUM(GB11:GE11) -> 0
D9: بالمنزل | F9: بالمركز الصحي | G9: بالمستشفى | H9: مولود حي | M9: إجهاض | N9: مولود ميت | O9: =SUM(H11:N11) -> 0 | S9: بالمنزل | U9: بالمركز الصحي | V9: بالمستشفى | W9: مولود حي | AB9: إجهاض | AC9: مولود ميت | AD9: =SUM(W11:AC11) -> 0 | AH9: بالمنزل | AJ9: بالمركز الصحي | AK9: بالمستشفى | AL9: مولود حي | AQ9: إجهاض | AR9: مولود ميت | AS9: =SUM(AL11:AR11) -> 0 | AW9: بالمنزل | AY9: بالمركز الصحي | AZ9: بالمستشفى | BA9: مولود حي | BF9: إجهاض | BG9: مولود ميت | BH9: =SUM(BA11:BG11) -> 0 | BL9: بالمنزل | BN9: بالمركز الصحي | BO9: بالمستشفى | BP9: مولود حي | BU9: إجهاض | BV9: مولود ميت | BW9: =SUM(BP11:BV11) -> 0 | CA9: بالمنزل | CC9: بالمركز الصحي | CD9: بالمستشفى | CE9: مولود حي | CJ9: إجهاض | CK9: مولود ميت | CL9: =SUM(CE11:CK11) -> 0 | CP9: بالمنزل | CR9: بالمركز الصحي | CS9: بالمستشفى | CT9: مولود حي | CY9: إجهاض | CZ9: مولود ميت | DA9: =SUM(CT11:CZ11) -> 0 | DE9: بالمنزل | DG9: بالمركز الصحي | DH9: بالمستشفى | DI9: مولود حي | DN9: إجهاض | DO9: مولود ميت | DP9: =SUM(DI11:DO11) -> 0 | DT9: بالمنزل | DV9: بالمركز الصحي | DW9: بالمستشفى | DX9: مولود حي | EC9: إجهاض | ED9: مولود ميت | EE9: =SUM(DX11:ED11) -> 0 | EI9: بالمنزل | EK9: بالمركز الصحي | EL9: بالمستشفى | EM9: مولود حي | ER9: إجهاض | ES9: مولود ميت | ET9: =SUM(EM11:ES11) -> 0 | EX9: بالمنزل | EZ9: بالمركز الصحي | FA9: بالمستشفى | FB9: مولود حي | FG9: إجهاض | FH9: مولود ميت | FI9: =SUM(FB11:FH11) -> 0 | FM9: بالمنزل | FO9: بالمركز الصحي | FP9: بالمستشفى | FQ9: مولود حي | FV9: إجهاض | FW9: مولود ميت | FX9: =SUM(FQ11:FW11) -> 0 | GB9: بالمنزل | GD9: بالمركز الصحي | GE9: بالمستشفى | GF9: مولود حي | GK9: إجهاض | GL9: مولود ميت | GM9: =SUM(GF11:GL11) -> 0
D10: بإشراف | E10: بدون | H10: طبيعي | J10: مبتسر | K10: أقل من 2.5 كجم | O10: =SUM(C6) -> 0 | S10: بإشراف | T10: بدون | W10: طبيعي | Y10: مبتسر | Z10: أقل من 2.5 كجم | AD10: =SUM(R6) -> 0 | AH10: بإشراف | AI10: بدون | AL10: طبيعي | AN10: مبتسر | AO10: أقل من 2.5 كجم | AS10: =SUM(AG6) -> 0 | AW10: بإشراف | AX10: بدون | BA10: طبيعي | BC10: مبتسر | BD10: أقل من 2.5 كجم | BH10: =SUM(AV6) -> 0 | BL10: بإشراف | BM10: بدون | BP10: طبيعي | BR10: مبتسر | BS10: أقل من 2.5 كجم | BW10: =SUM(BK6) -> 0 | CA10: بإشراف | CB10: بدون | CE10: طبيعي | CG10: مبتسر | CH10: أقل من 2.5 كجم | CL10: =SUM(BZ6) -> 0 | CP10: بإشراف | CQ10: بدون | CT10: طبيعي | CV10: مبتسر | CW10: أقل من 2.5 كجم | DA10: =SUM(CO6) -> 0 | DE10: بإشراف | DF10: بدون | DI10: طبيعي | DK10: مبتسر | DL10: أقل من 2.5 كجم | DP10: =SUM(DD6) -> 0 | DT10: بإشراف | DU10: بدون | DX10: طبيعي | DZ10: مبتسر | EA10: أقل من 2.5 كجم | EE10: =SUM(DS6) -> 0 | EI10: بإشراف | EJ10: بدون | EM10: طبيعي | EO10: مبتسر | EP10: أقل من 2.5 كجم | ET10: =SUM(EH6) -> 0 | EX10: بإشراف | EY10: بدون | FB10: طبيعي | FD10: مبتسر | FE10: أقل من 2.5 كجم | FI10: =SUM(EW6) -> 0 | FM10: بإشراف | FN10: بدون | FQ10: طبيعي | FS10: مبتسر | FT10: أقل من 2.5 كجم | FX10: =SUM(FL6) -> 0 | GB10: بإشراف | GC10: بدون | GF10: طبيعي | GH10: مبتسر | GI10: أقل من 2.5 كجم | GM10: =SUM(GA6) -> 0
B11: سعوديات | D11: 0 | E11: 0 | F11: 0 | G11: 0 | H11: 0 | J11: 0 | K11: 0 | M11: 0 | N11: 0 | O11: =SUM(K6:N6) -> 0 | Q11: سعوديات | S11: 0 | T11: 0 | U11: 0 | V11: 0 | W11: 0 | Y11: 0 | Z11: 0 | AB11: 0 | AC11: 0 | AD11: =SUM(Z6:AC6) -> 0 | AF11: سعوديات | AH11: 0 | AI11: 0 | AJ11: 0 | AK11: 0 | AL11: 0 | AN11: 0 | AO11: 0 | AQ11: 0 | AR11: 0 | AS11: =SUM(AO6:AR6) -> 0 | AU11: سعوديات | AW11: 0 | AX11: 0 | AY11: 0 | AZ11: 0 | BA11: 0 | BC11: 0 | BD11: 0 | BF11: 0 | BG11: 0 | BH11: =SUM(BD6:BG6) -> 0 | BJ11: سعوديات | BL11: 0 | BM11: 0 | BN11: 0 | BO11: 0 | BP11: 0 | BR11: 0 | BS11: 0 | BU11: 0 | BV11: 0 | BW11: =SUM(BS6:BV6) -> 0 | BY11: سعوديات | CA11: 0 | CB11: 0 | CC11: 0 | CD11: 0 | CE11: 0 | CG11: 0 | CH11: 0 | CJ11: 0 | CK11: 0 | CL11: =SUM(CH6:CK6) -> 0 | CN11: سعوديات | CP11: 0 | CQ11: 0 | CR11: 0 | CS11: 0 | CT11: 0 | CV11: 0 | CW11: 0 | CY11: 0 | CZ11: 0 | DA11: =SUM(CW6:CZ6) -> 0 | DC11: سعوديات | DE11: 0 | DF11: 0 | DG11: 0 | DH11: 0 | DI11: 0 | DK11: 0 | DL11: 0 | DN11: 0 | DO11: 0 | DP11: =SUM(DL6:DO6) -> 0 | DR11: سعوديات | DT11: 0 | DU11: 0 | DV11: 0 | DW11: 0 | DX11: 0 | DZ11: 0 | EA11: 0 | EC11: 0 | ED11: 0 | EE11: =SUM(EA6:ED6) -> 0 | EG11: سعوديات | EI11: 0 | EJ11: 0 | EK11: 0 | EL11: 0 | EM11: 0 | EO11: 0 | EP11: 0 | ER11: 0 | ES11: 0 | ET11: =SUM(EP6:ES6) -> 0 | EV11: سعوديات | EX11: 0 | EY11: 0 | EZ11: 0 | FA11: 0 | FB11: 0 | FD11: 0 | FE11: 0 | FG11: 0 | FH11: 0 | FI11: =SUM(FE6:FH6) -> 0 | FK11: سعوديات | FM11: 0 | FN11: 0 | FO11: 0 | FP11: 0 | FQ11: 0 | FS11: 0 | FT11: 0 | FV11: 0 | FW11: 0 | FX11: =SUM(FT6:FW6) -> 0 | FZ11: سعوديات | GB11: =SUM(D11+S11+AH11+AW11+BL11+CA11+CP11+DE11+DT11+EI11+EX11+FM11) -> 0 | GC11: =SUM(E11+T11+AI11+AX11+BM11+CB11+CQ11+DF11+DU11+EJ11+EY11+FN11) -> 0 | GD11: =SUM(F11+U11+AJ11+AY11+BN11+CC11+CR11+DG11+DV11+EK11+EZ11+FO11) -> 0 | GE11: =SUM(G11+V11+AK11+AZ11+BO11+CD11+CS11+DH11+DW11+EL11+FA11+FP11) -> 0 | GF11: =SUM(H11+W11+AL11+BA11+BP11+CE11+CT11+DI11+DX11+EM11+FB11+FQ11) -> 0 | GH11: =SUM(J11+Y11+AN11+BC11+BR11+CG11+CV11+DK11+DZ11+EO11+FD11+FS11) -> 0 | GI11: =SUM(K11+Z11+AO11+BD11+BS11+CH11+CW11+DL11+EA11+EP11+FE11+FT11) -> 0 | GK11: =SUM(M11+AB11+AQ11+BF11+BU11+CJ11+CY11+DN11+EC11+ER11+FG11+FV11) -> 0 | GL11: =SUM(N11+AC11+AR11+BG11+BV11+CK11+CZ11+DO11+ED11+ES11+FH11+FW11) -> 0 | GM11: =SUM(GI6:GL6) -> 0
B12: غ.سعوديات | D12: 0 | E12: 0 | F12: 0 | G12: 0 | H12: 0 | J12: 0 | K12: 0 | M12: 0 | N12: 0 | O12: =SUM(D12:G12) -> 0 | Q12: غ.سعوديات | S12: 0 | T12: 0 | U12: 0 | V12: 0 | W12: 0 | Y12: 0 | Z12: 0 | AB12: 0 | AC12: 0 | AD12: =SUM(S12:V12) -> 0 | AF12: غ.سعوديات | AH12: 0 | AI12: 0 | AJ12: 0 | AK12: 0 | AL12: 0 | AN12: 0 | AO12: 0 | AQ12: 0 | AR12: 0 | AS12: =SUM(AH12:AK12) -> 0 | AU12: غ.سعوديات | AW12: 0 | AX12: 0 | AY12: 0 | AZ12: 0 | BA12: 0 | BC12: 0 | BD12: 0 | BF12: 0 | BG12: 0 | BH12: =SUM(AW12:AZ12) -> 0 | BJ12: غ.سعوديات | BL12: 0 | BM12: 0 | BN12: 0 | BO12: 0 | BP12: 0 | BR12: 0 | BS12: 0 | BU12: 0 | BV12: 0 | BW12: =SUM(BL12:BO12) -> 0 | BY12: غ.سعوديات | CA12: 0 | CB12: 0 | CC12: 0 | CD12: 0 | CE12: 0 | CG12: 0 | CH12: 0 | CJ12: 0 | CK12: 0 | CL12: =SUM(CA12:CD12) -> 0 | CN12: غ.سعوديات | CP12: 0 | CQ12: 0 | CR12: 0 | CS12: 0 | CT12: 0 | CV12: 0 | CW12: 0 | CY12: 0 | CZ12: 0 | DA12: =SUM(CP12:CS12) -> 0 | DC12: غ.سعوديات | DE12: 0 | DF12: 0 | DG12: 0 | DH12: 0 | DI12: 0 | DK12: 0 | DL12: 0 | DN12: 0 | DO12: 0 | DP12: =SUM(DE12:DH12) -> 0 | DR12: غ.سعوديات | DT12: 0 | DU12: 0 | DV12: 0 | DW12: 0 | DX12: 0 | DZ12: 0 | EA12: 0 | EC12: 0 | ED12: 0 | EE12: =SUM(DT12:DW12) -> 0 | EG12: غ.سعوديات | EI12: 0 | EJ12: 0 | EK12: 0 | EL12: 0 | EM12: 0 | EO12: 0 | EP12: 0 | ER12: 0 | ES12: 0 | ET12: =SUM(EI12:EL12) -> 0 | EV12: غ.سعوديات | EX12: 0 | EY12: 0 | EZ12: 0 | FA12: 0 | FB12: 0 | FD12: 0 | FE12: 0 | FG12: 0 | FH12: 0 | FI12: =SUM(EX12:FA12) -> 0 | FK12: غ.سعوديات | FM12: 0 | FN12: 0 | FO12: 0 | FP12: 0 | FQ12: 0 | FS12: 0 | FT12: 0 | FV12: 0 | FW12: 0 | FX12: =SUM(FM12:FP12) -> 0 | FZ12: غ.سعوديات | GB12: =SUM(D12+S12+AH12+AW12+BL12+CA12+CP12+DE12+DT12+EI12+EX12+FM12) -> 0 | GC12: =SUM(E12+T12+AI12+AX12+BM12+CB12+CQ12+DF12+DU12+EJ12+EY12+FN12) -> 0 | GD12: =SUM(F12+U12+AJ12+AY12+BN12+CC12+CR12+DG12+DV12+EK12+EZ12+FO12) -> 0 | GE12: =SUM(G12+V12+AK12+AZ12+BO12+CD12+CS12+DH12+DW12+EL12+FA12+FP12) -> 0 | GF12: =SUM(H12+W12+AL12+BA12+BP12+CE12+CT12+DI12+DX12+EM12+FB12+FQ12) -> 0 | GH12: =SUM(J12+Y12+AN12+BC12+BR12+CG12+CV12+DK12+DZ12+EO12+FD12+FS12) -> 0 | GI12: =SUM(K12+Z12+AO12+BD12+BS12+CH12+CW12+DL12+EA12+EP12+FE12+FT12) -> 0 | GK12: =SUM(M12+AB12+AQ12+BF12+BU12+CJ12+CY12+DN12+EC12+ER12+FG12+FV12) -> 0 | GL12: =SUM(N12+AC12+AR12+BG12+BV12+CK12+CZ12+DO12+ED12+ES12+FH12+FW12) -> 0 | GM12: =SUM(GB12:GE12) -> 0
B13: المجموع | D13: =SUM(D11:D12) -> 0 | E13: =SUM(E11:E12) -> 0 | F13: =SUM(F11:F12) -> 0 | G13: =SUM(G11:G12) -> 0 | H13: =SUM(H11:I12) -> 0 | J13: =SUM(J11:J12) -> 0 | K13: =SUM(K11:L12) -> 0 | M13: =SUM(M11:M12) -> 0 | N13: =SUM(N11:N12) -> 0 | O13: =SUM(H12:N12) -> 0 | Q13: المجموع | S13: =SUM(S11:S12) -> 0 | T13: =SUM(T11:T12) -> 0 | U13: =SUM(U11:U12) -> 0 | V13: =SUM(V11:V12) -> 0 | W13: =SUM(W11:X12) -> 0 | Y13: =SUM(Y11:Y12) -> 0 | Z13: =SUM(Z11:AA12) -> 0 | AB13: =SUM(AB11:AB12) -> 0 | AC13: =SUM(AC11:AC12) -> 0 | AD13: =SUM(W12:AC12) -> 0 | AF13: المجموع | AH13: =SUM(AH11:AH12) -> 0 | AI13: =SUM(AI11:AI12) -> 0 | AJ13: =SUM(AJ11:AJ12) -> 0 | AK13: =SUM(AK11:AK12) -> 0 | AL13: =SUM(AL11:AM12) -> 0 | AN13: =SUM(AN11:AN12) -> 0 | AO13: =SUM(AO11:AP12) -> 0 | AQ13: =SUM(AQ11:AQ12) -> 0 | AR13: =SUM(AR11:AR12) -> 0 | AS13: =SUM(AL12:AR12) -> 0 | AU13: المجموع | AW13: =SUM(AW11:AW12) -> 0 | AX13: =SUM(AX11:AX12) -> 0 | AY13: =SUM(AY11:AY12) -> 0 | AZ13: =SUM(AZ11:AZ12) -> 0 | BA13: =SUM(BA11:BB12) -> 0 | BC13: =SUM(BC11:BC12) -> 0 | BD13: =SUM(BD11:BE12) -> 0 | BF13: =SUM(BF11:BF12) -> 0 | BG13: =SUM(BG11:BG12) -> 0 | BH13: =SUM(BA12:BG12) -> 0 | BJ13: المجموع | BL13: =SUM(BL11:BL12) -> 0 | BM13: =SUM(BM11:BM12) -> 0 | BN13: =SUM(BN11:BN12) -> 0 | BO13: =SUM(BO11:BO12) -> 0 | BP13: =SUM(BP11:BQ12) -> 0 | BR13: =SUM(BR11:BR12) -> 0 | BS13: =SUM(BS11:BT12) -> 0 | BU13: =SUM(BU11:BU12) -> 0 | BV13: =SUM(BV11:BV12) -> 0 | BW13: =SUM(BP12:BV12) -> 0 | BY13: المجموع | CA13: =SUM(CA11:CA12) -> 0 | CB13: =SUM(CB11:CB12) -> 0 | CC13: =SUM(CC11:CC12) -> 0 | CD13: =SUM(CD11:CD12) -> 0 | CE13: =SUM(CE11:CF12) -> 0 | CG13: =SUM(CG11:CG12) -> 0 | CH13: =SUM(CH11:CI12) -> 0 | CJ13: =SUM(CJ11:CJ12) -> 0 | CK13: =SUM(CK11:CK12) -> 0 | CL13: =SUM(CE12:CK12) -> 0 | CN13: المجموع | CP13: =SUM(CP11:CP12) -> 0 | CQ13: =SUM(CQ11:CQ12) -> 0 | CR13: =SUM(CR11:CR12) -> 0 | CS13: =SUM(CS11:CS12) -> 0 | CT13: =SUM(CT11:CU12) -> 0 | CV13: =SUM(CV11:CV12) -> 0 | CW13: =SUM(CW11:CX12) -> 0 | CY13: =SUM(CY11:CY12) -> 0 | CZ13: =SUM(CZ11:CZ12) -> 0 | DA13: =SUM(CT12:CZ12) -> 0 | DC13: المجموع | DE13: =SUM(DE11:DE12) -> 0 | DF13: =SUM(DF11:DF12) -> 0 | DG13: =SUM(DG11:DG12) -> 0 | DH13: =SUM(DH11:DH12) -> 0 | DI13: =SUM(DI11:DJ12) -> 0 | DK13: =SUM(DK11:DK12) -> 0 | DL13: =SUM(DL11:DM12) -> 0 | DN13: =SUM(DN11:DN12) -> 0 | DO13: =SUM(DO11:DO12) -> 0 | DP13: =SUM(DI12:DO12) -> 0 | DR13: المجموع | DT13: =SUM(DT11:DT12) -> 0 | DU13: =SUM(DU11:DU12) -> 0 | DV13: =SUM(DV11:DV12) -> 0 | DW13: =SUM(DW11:DW12) -> 0 | DX13: =SUM(DX11:DY12) -> 0 | DZ13: =SUM(DZ11:DZ12) -> 0 | EA13: =SUM(EA11:EB12) -> 0 | EC13: =SUM(EC11:EC12) -> 0 | ED13: =SUM(ED11:ED12) -> 0 | EE13: =SUM(DX12:ED12) -> 0 | EG13: المجموع | EI13: =SUM(EI11:EI12) -> 0 | EJ13: =SUM(EJ11:EJ12) -> 0 | EK13: =SUM(EK11:EK12) -> 0 | EL13: =SUM(EL11:EL12) -> 0 | EM13: =SUM(EM11:EN12) -> 0 | EO13: =SUM(EO11:EO12) -> 0 | EP13: =SUM(EP11:EQ12) -> 0 | ER13: =SUM(ER11:ER12) -> 0 | ES13: =SUM(ES11:ES12) -> 0 | ET13: =SUM(EM12:ES12) -> 0 | EV13: المجموع | EX13: =SUM(EX11:EX12) -> 0 | EY13: =SUM(EY11:EY12) -> 0 | EZ13: =SUM(EZ11:EZ12) -> 0 | FA13: =SUM(FA11:FA12) -> 0 | FB13: =SUM(FB11:FC12) -> 0 | FD13: =SUM(FD11:FD12) -> 0 | FE13: =SUM(FE11:FF12) -> 0 | FG13: =SUM(FG11:FG12) -> 0 | FH13: =SUM(FH11:FH12) -> 0 | FI13: =SUM(FB12:FH12) -> 0 | FK13: المجموع | FM13: =SUM(FM11:FM12) -> 0 | FN13: =SUM(FN11:FN12) -> 0 | FO13: =SUM(FO11:FO12) -> 0 | FP13: =SUM(FP11:FP12) -> 0 | FQ13: =SUM(FQ11:FR12) -> 0 | FS13: =SUM(FS11:FS12) -> 0 | FT13: =SUM(FT11:FU12) -> 0 | FV13: =SUM(FV11:FV12) -> 0 | FW13: =SUM(FW11:FW12) -> 0 | FX13: =SUM(FQ12:FW12) -> 0 | FZ13: المجموع | GB13: =SUM(GB11:GB12) -> 0 | GC13: =SUM(GC11:GC12) -> 0 | GD13: =SUM(GD11:GD12) -> 0 | GE13: =SUM(GE11:GE12) -> 0 | GF13: =SUM(GF11:GG12) -> 0 | GH13: =SUM(GH11:GH12) -> 0 | GI13: =SUM(GI11:GJ12) -> 0 | GK13: =SUM(GK11:GK12) -> 0 | GL13: =SUM(GL11:GL12) -> 0 | GM13: =SUM(GF12:GL12) -> 0
A15: الجامعة | B15: سعوديات | C15: 0 | D15: 0 | F15: 0 | H15: 0 | I15: 0 | K15: 0 | M15: 0 | O15: =SUM(C15) -> 0 | P15: الجامعة | Q15: سعوديات | R15: 0 | S15: 0 | U15: 0 | W15: 0 | X15: 0 | Z15: 0 | AB15: 0 | AD15: =SUM(R15) -> 0 | AE15: الجامعة | AF15: سعوديات | AG15: 0 | AH15: 0 | AJ15: 0 | AL15: 0 | AM15: 0 | AO15: 0 | AQ15: 0 | AS15: =SUM(AG15) -> 0 | AT15: الجامعة | AU15: سعوديات | AV15: 0 | AW15: 0 | AY15: 0 | BA15: 0 | BB15: 0 | BD15: 0 | BF15: 0 | BH15: =SUM(AV15) -> 0 | BI15: الجامعة | BJ15: سعوديات | BK15: 0 | BL15: 0 | BN15: 0 | BP15: 0 | BQ15: 0 | BS15: 0 | BU15: 0 | BW15: =SUM(BK15) -> 0 | BX15: الجامعة | BY15: سعوديات | BZ15: 0 | CA15: 0 | CC15: 0 | CE15: 0 | CF15: 0 | CH15: 0 | CJ15: 0 | CL15: =SUM(BZ15) -> 0 | CM15: الجامعة | CN15: سعوديات | CO15: 0 | CP15: 0 | CR15: 0 | CT15: 0 | CU15: 0 | CW15: 0 | CY15: 0 | DA15: =SUM(CO15) -> 0 | DB15: الجامعة | DC15: سعوديات | DD15: 0 | DE15: 0 | DG15: 0 | DI15: 0 | DJ15: 0 | DL15: 0 | DN15: 0 | DP15: =SUM(DD15) -> 0 | DQ15: الجامعة | DR15: سعوديات | DS15: 0 | DT15: 0 | DV15: 0 | DX15: 0 | DY15: 0 | EA15: 0 | EC15: 0 | EE15: =SUM(DS15) -> 0 | EF15: الجامعة | EG15: سعوديات | EH15: 0 | EI15: 0 | EK15: 0 | EM15: 0 | EN15: 0 | EP15: 0 | ER15: 0 | ET15: =SUM(EH15) -> 0 | EU15: الجامعة | EV15: سعوديات | EW15: 0 | EX15: 0 | EZ15: 0 | FB15: 0 | FC15: 0 | FE15: 0 | FG15: 0 | FI15: =SUM(EW15) -> 0 | FJ15: الجامعة | FK15: سعوديات | FL15: 0 | FM15: 0 | FO15: 0 | FQ15: 0 | FR15: 0 | FT15: 0 | FV15: 0 | FX15: =SUM(FL15) -> 0 | FY15: =(FJ15) -> الجامعة | FZ15: سعوديات | GA15: =SUM(C15+R15+AG15+AV15+BK15+BZ15+CO15+DD15+DS15+EH15+EW15+FL15) -> 0 | GB15: =SUM(D15+S15+AH15+AW15+BL15+CA15+CP15+DE15+DT15+EI15+EX15+FM15) -> 0 | GD15: =SUM(F15+U15+AJ15+AY15+BN15+CC15+CR15+DG15+DV15+EK15+EZ15+FO15) -> 0 | GF15: =SUM(H15+W15+AL15+BA15+BP15+CE15+CT15+DI15+DX15+EM15+FB15+FQ15) -> 0 | GG15: =SUM(I15+X15+AM15+BB15+BQ15+CF15+CU15+DJ15+DY15+EN15+FC15+FR15) -> 0 | GI15: =SUM(K15+Z15+AO15+BD15+BS15+CH15+CW15+DL15+EA15+EP15+FE15+FT15) -> 0 | GK15: =SUM(M15+AB15+AQ15+BF15+BU15+CJ15+CY15+DN15+EC15+ER15+FG15+FV15) -> 0 | GM15: =SUM(GA15) -> 0
B16: غير سعوديات | C16: 0 | D16: 0 | F16: 0 | H16: 0 | I16: 0 | K16: 0 | M16: 0 | O16: =SUM(D15:G15) -> 0 | Q16: غير سعوديات | R16: 0 | S16: 0 | U16: 0 | W16: 0 | X16: 0 | Z16: 0 | AB16: 0 | AD16: =SUM(S15:V15) -> 0 | AF16: غير سعوديات | AG16: 0 | AH16: 0 | AJ16: 0 | AL16: 0 | AM16: 0 | AO16: 0 | AQ16: 0 | AS16: =SUM(AH15:AK15) -> 0 | AU16: غير سعوديات | AV16: 0 | AW16: 0 | AY16: 0 | BA16: 0 | BB16: 0 | BD16: 0 | BF16: 0 | BH16: =SUM(AW15:AZ15) -> 0 | BJ16: غير سعوديات | BK16: 0 | BL16: 0 | BN16: 0 | BP16: 0 | BQ16: 0 | BS16: 0 | BU16: 0 | BW16: =SUM(BL15:BO15) -> 0 | BY16: غير سعوديات | BZ16: 0 | CA16: 0 | CC16: 0 | CE16: 0 | CF16: 0 | CH16: 0 | CJ16: 0 | CL16: =SUM(CA15:CD15) -> 0 | CN16: غير سعوديات | CO16: 0 | CP16: 0 | CR16: 0 | CT16: 0 | CU16: 0 | CW16: 0 | CY16: 0 | DA16: =SUM(CP15:CS15) -> 0 | DC16: غير سعوديات | DD16: 0 | DE16: 0 | DG16: 0 | DI16: 0 | DJ16: 0 | DL16: 0 | DN16: 0 | DP16: =SUM(DE15:DH15) -> 0 | DR16: غير سعوديات | DS16: 0 | DT16: 0 | DV16: 0 | DX16: 0 | DY16: 0 | EA16: 0 | EC16: 0 | EE16: =SUM(DT15:DW15) -> 0 | EG16: غير سعوديات | EH16: 0 | EI16: 0 | EK16: 0 | EM16: 0 | EN16: 0 | EP16: 0 | ER16: 0 | ET16: =SUM(EI15:EL15) -> 0 | EV16: غير سعوديات | EW16: 0 | EX16: 0 | EZ16: 0 | FB16: 0 | FC16: 0 | FE16: 0 | FG16: 0 | FI16: =SUM(EX15:FA15) -> 0 | FK16: غير سعوديات | FL16: 0 | FM16: 0 | FO16: 0 | FQ16: 0 | FR16: 0 | FT16: 0 | FV16: 0 | FX16: =SUM(FM15:FP15) -> 0 | FZ16: غير سعوديات | GA16: =SUM(C16+R16+AG16+AV16+BK16+BZ16+CO16+DD16+DS16+EH16+EW16+FL16) -> 0 | GB16: =SUM(D16+S16+AH16+AW16+BL16+CA16+CP16+DE16+DT16+EI16+EX16+FM16) -> 0 | GD16: =SUM(F16+U16+AJ16+AY16+BN16+CC16+CR16+DG16+DV16+EK16+EZ16+FO16) -> 0 | GF16: =SUM(H16+W16+AL16+BA16+BP16+CE16+CT16+DI16+DX16+EM16+FB16+FQ16) -> 0 | GG16: =SUM(I16+X16+AM16+BB16+BQ16+CF16+CU16+DJ16+DY16+EN16+FC16+FR16) -> 0 | GI16: =SUM(K16+Z16+AO16+BD16+BS16+CH16+CW16+DL16+EA16+EP16+FE16+FT16) -> 0 | GK16: =SUM(M16+AB16+AQ16+BF16+BU16+CJ16+CY16+DN16+EC16+ER16+FG16+FV16) -> 0 | GM16: =SUM(GB15:GE15) -> 0
B17: المجموع | C17: =SUM(C15:C16) -> 0 | D17: =SUM(D15:E16) -> 0 | F17: =SUM(F15:G16) -> 0 | H17: =SUM(H15:H16) -> 0 | I17: =SUM(I15:J16) -> 0 | K17: =SUM(K15:L16) -> 0 | M17: =SUM(M15:N16) -> 0 | O17: =SUM(K15:N15) -> 0 | Q17: المجموع | R17: =SUM(R15:R16) -> 0 | S17: =SUM(S15:T16) -> 0 | U17: =SUM(U15:V16) -> 0 | W17: =SUM(W15:W16) -> 0 | X17: =SUM(X15:Y16) -> 0 | Z17: =SUM(Z15:AA16) -> 0 | AB17: =SUM(AB15:AC16) -> 0 | AD17: =SUM(Z15:AC15) -> 0 | AF17: المجموع | AG17: =SUM(AG15:AG16) -> 0 | AH17: =SUM(AH15:AI16) -> 0 | AJ17: =SUM(AJ15:AK16) -> 0 | AL17: =SUM(AL15:AL16) -> 0 | AM17: =SUM(AM15:AN16) -> 0 | AO17: =SUM(AO15:AP16) -> 0 | AQ17: =SUM(AQ15:AR16) -> 0 | AS17: =SUM(AO15:AR15) -> 0 | AU17: المجموع | AV17: =SUM(AV15:AV16) -> 0 | AW17: =SUM(AW15:AX16) -> 0 | AY17: =SUM(AY15:AZ16) -> 0 | BA17: =SUM(BA15:BA16) -> 0 | BB17: =SUM(BB15:BC16) -> 0 | BD17: =SUM(BD15:BE16) -> 0 | BF17: =SUM(BF15:BG16) -> 0 | BH17: =SUM(BD15:BG15) -> 0 | BJ17: المجموع | BK17: =SUM(BK15:BK16) -> 0 | BL17: =SUM(BL15:BM16) -> 0 | BN17: =SUM(BN15:BO16) -> 0 | BP17: =SUM(BP15:BP16) -> 0 | BQ17: =SUM(BQ15:BR16) -> 0 | BS17: =SUM(BS15:BT16) -> 0 | BU17: =SUM(BU15:BV16) -> 0 | BW17: =SUM(BS15:BV15) -> 0 | BY17: المجموع | BZ17: =SUM(BZ15:BZ16) -> 0 | CA17: =SUM(CA15:CB16) -> 0 | CC17: =SUM(CC15:CD16) -> 0 | CE17: =SUM(CE15:CE16) -> 0 | CF17: =SUM(CF15:CG16) -> 0 | CH17: =SUM(CH15:CI16) -> 0 | CJ17: =SUM(CJ15:CK16) -> 0 | CL17: =SUM(CH15:CK15) -> 0 | CN17: المجموع | CO17: =SUM(CO15:CO16) -> 0 | CP17: =SUM(CP15:CQ16) -> 0 | CR17: =SUM(CR15:CS16) -> 0 | CT17: =SUM(CT15:CT16) -> 0 | CU17: =SUM(CU15:CV16) -> 0 | CW17: =SUM(CW15:CX16) -> 0 | CY17: =SUM(CY15:CZ16) -> 0 | DA17: =SUM(CW15:CZ15) -> 0 | DC17: المجموع | DD17: =SUM(DD15:DD16) -> 0 | DE17: =SUM(DE15:DF16) -> 0 | DG17: =SUM(DG15:DH16) -> 0 | DI17: =SUM(DI15:DI16) -> 0 | DJ17: =SUM(DJ15:DK16) -> 0 | DL17: =SUM(DL15:DM16) -> 0 | DN17: =SUM(DN15:DO16) -> 0 | DP17: =SUM(DL15:DO15) -> 0 | DR17: المجموع | DS17: =SUM(DS15:DS16) -> 0 | DT17: =SUM(DT15:DU16) -> 0 | DV17: =SUM(DV15:DW16) -> 0 | DX17: =SUM(DX15:DX16) -> 0 | DY17: =SUM(DY15:DZ16) -> 0 | EA17: =SUM(EA15:EB16) -> 0 | EC17: =SUM(EC15:ED16) -> 0 | EE17: =SUM(EA15:ED15) -> 0 | EG17: المجموع | EH17: =SUM(EH15:EH16) -> 0 | EI17: =SUM(EI15:EJ16) -> 0 | EK17: =SUM(EK15:EL16) -> 0 | EM17: =SUM(EM15:EM16) -> 0 | EN17: =SUM(EN15:EO16) -> 0 | EP17: =SUM(EP15:EQ16) -> 0 | ER17: =SUM(ER15:ES16) -> 0 | ET17: =SUM(EP15:ES15) -> 0 | EV17: المجموع | EW17: =SUM(EW15:EW16) -> 0 | EX17: =SUM(EX15:EY16) -> 0 | EZ17: =SUM(EZ15:FA16) -> 0 | FB17: =SUM(FB15:FB16) -> 0 | FC17: =SUM(FC15:FD16) -> 0 | FE17: =SUM(FE15:FF16) -> 0 | FG17: =SUM(FG15:FH16) -> 0 | FI17: =SUM(FE15:FH15) -> 0 | FK17: المجموع | FL17: =SUM(FL15:FL16) -> 0 | FM17: =SUM(FM15:FN16) -> 0 | FO17: =SUM(FO15:FP16) -> 0 | FQ17: =SUM(FQ15:FQ16) -> 0 | FR17: =SUM(FR15:FS16) -> 0 | FT17: =SUM(FT15:FU16) -> 0 | FV17: =SUM(FV15:FW16) -> 0 | FX17: =SUM(FT15:FW15) -> 0 | FZ17: المجموع | GA17: =SUM(GA15:GA16) -> 0 | GB17: =SUM(GB15:GC16) -> 0 | GD17: =SUM(GD15:GE16) -> 0 | GF17: =SUM(GF15:GF16) -> 0 | GG17: =SUM(GG15:GH16) -> 0 | GI17: =SUM(GI15:GJ16) -> 0 | GK17: =SUM(GK15:GL16) -> 0 | GM17: =SUM(GI15:GL15) -> 0
D18: مكان الولادة | H18: نتيجة الحمل | O18: =SUM(D21:G21) -> 0 | S18: مكان الولادة | W18: نتيجة الحمل | AD18: =SUM(S21:V21) -> 0 | AH18: مكان الولادة | AL18: نتيجة الحمل | AS18: =SUM(AH21:AK21) -> 0 | AW18: مكان الولادة | BA18: نتيجة الحمل | BH18: =SUM(AW21:AZ21) -> 0 | BL18: مكان الولادة | BP18: نتيجة الحمل | BW18: =SUM(BL21:BO21) -> 0 | CA18: مكان الولادة | CE18: نتيجة الحمل | CL18: =SUM(CA21:CD21) -> 0 | CP18: مكان الولادة | CT18: نتيجة الحمل | DA18: =SUM(CP21:CS21) -> 0 | DE18: مكان الولادة | DI18: نتيجة الحمل | DP18: =SUM(DE21:DH21) -> 0 | DT18: مكان الولادة | DX18: نتيجة الحمل | EE18: =SUM(DT21:DW21) -> 0 | EI18: مكان الولادة | EM18: نتيجة الحمل | ET18: =SUM(EI21:EL21) -> 0 | EX18: مكان الولادة | FB18: نتيجة الحمل | FI18: =SUM(EX21:FA21) -> 0 | FM18: مكان الولادة | FQ18: نتيجة الحمل | FX18: =SUM(FM21:FP21) -> 0 | GB18: مكان الولادة | GF18: نتيجة الحمل | GM18: =SUM(GB21:GE21) -> 0
D19: بالمنزل | F19: بالمركز الصحي | G19: بالمستشفى | H19: مولود حي | M19: إجهاض | N19: مولود ميت | O19: =SUM(H21:N21) -> 0 | S19: بالمنزل | U19: بالمركز الصحي | V19: بالمستشفى | W19: مولود حي | AB19: إجهاض | AC19: مولود ميت | AD19: =SUM(W21:AC21) -> 0 | AH19: بالمنزل | AJ19: بالمركز الصحي | AK19: بالمستشفى | AL19: مولود حي | AQ19: إجهاض | AR19: مولود ميت | AS19: =SUM(AL21:AR21) -> 0 | AW19: بالمنزل | AY19: بالمركز الصحي | AZ19: بالمستشفى | BA19: مولود حي | BF19: إجهاض | BG19: مولود ميت | BH19: =SUM(BA21:BG21) -> 0 | BL19: بالمنزل | BN19: بالمركز الصحي | BO19: بالمستشفى | BP19: مولود حي | BU19: إجهاض | BV19: مولود ميت | BW19: =SUM(BP21:BV21) -> 0 | CA19: بالمنزل | CC19: بالمركز الصحي | CD19: بالمستشفى | CE19: مولود حي | CJ19: إجهاض | CK19: مولود ميت | CL19: =SUM(CE21:CK21) -> 0 | CP19: بالمنزل | CR19: بالمركز الصحي | CS19: بالمستشفى | CT19: مولود حي | CY19: إجهاض | CZ19: مولود ميت | DA19: =SUM(CT21:CZ21) -> 0 | DE19: بالمنزل | DG19: بالمركز الصحي | DH19: بالمستشفى | DI19: مولود حي | DN19: إجهاض | DO19: مولود ميت | DP19: =SUM(DI21:DO21) -> 0 | DT19: بالمنزل | DV19: بالمركز الصحي | DW19: بالمستشفى | DX19: مولود حي | EC19: إجهاض | ED19: مولود ميت | EE19: =SUM(DX21:ED21) -> 0 | EI19: بالمنزل | EK19: بالمركز الصحي | EL19: بالمستشفى | EM19: مولود حي | ER19: إجهاض | ES19: مولود ميت | ET19: =SUM(EM21:ES21) -> 0 | EX19: بالمنزل | EZ19: بالمركز الصحي | FA19: بالمستشفى | FB19: مولود حي | FG19: إجهاض | FH19: مولود ميت | FI19: =SUM(FB21:FH21) -> 0 | FM19: بالمنزل | FO19: بالمركز الصحي | FP19: بالمستشفى | FQ19: مولود حي | FV19: إجهاض | FW19: مولود ميت | FX19: =SUM(FQ21:FW21) -> 0 | GB19: بالمنزل | GD19: بالمركز الصحي | GE19: بالمستشفى | GF19: مولود حي | GK19: إجهاض | GL19: مولود ميت | GM19: =SUM(GF21:GL21) -> 0
D20: بإشراف | E20: بدون | H20: طبيعي | J20: مبتسر | K20: أقل من 2.5 كجم | O20: =SUM(C16) -> 0 | S20: بإشراف | T20: بدون | W20: طبيعي | Y20: مبتسر | Z20: أقل من 2.5 كجم | AD20: =SUM(R16) -> 0 | AH20: بإشراف | AI20: بدون | AL20: طبيعي | AN20: مبتسر | AO20: أقل من 2.5 كجم | AS20: =SUM(AG16) -> 0 | AW20: بإشراف | AX20: بدون | BA20: طبيعي | BC20: مبتسر | BD20: أقل من 2.5 كجم | BH20: =SUM(AV16) -> 0 | BL20: بإشراف | BM20: بدون | BP20: طبيعي | BR20: مبتسر | BS20: أقل من 2.5 كجم | BW20: =SUM(BK16) -> 0 | CA20: بإشراف | CB20: بدون | CE20: طبيعي | CG20: مبتسر | CH20: أقل من 2.5 كجم | CL20: =SUM(BZ16) -> 0 | CP20: بإشراف | CQ20: بدون | CT20: طبيعي | CV20: مبتسر | CW20: أقل من 2.5 كجم | DA20: =SUM(CO16) -> 0 | DE20: بإشراف | DF20: بدون | DI20: طبيعي | DK20: مبتسر | DL20: أقل من 2.5 كجم | DP20: =SUM(DD16) -> 0 | DT20: بإشراف | DU20: بدون | DX20: طبيعي | DZ20: مبتسر | EA20: أقل من 2.5 كجم | EE20: =SUM(DS16) -> 0 | EI20: بإشراف | EJ20: بدون | EM20: طبيعي | EO20: مبتسر | EP20: أقل من 2.5 كجم | ET20: =SUM(EH16) -> 0 | EX20: بإشراف | EY20: بدون | FB20: طبيعي | FD20: مبتسر | FE20: أقل من 2.5 كجم | FI20: =SUM(EW16) -> 0 | FM20: بإشراف | FN20: بدون | FQ20: طبيعي | FS20: مبتسر | FT20: أقل من 2.5 كجم | FX20: =SUM(FL16) -> 0 | GB20: بإشراف | GC20: بدون | GF20: طبيعي | GH20: مبتسر | GI20: أقل من 2.5 كجم | GM20: =SUM(GA16) -> 0
B21: سعوديات | D21: 0 | E21: 0 | F21: 0 | G21: 0 | H21: 0 | J21: 0 | K21: 0 | M21: 0 | N21: 0 | O21: =SUM(K16:N16) -> 0 | Q21: سعوديات | S21: 0 | T21: 0 | U21: 0 | V21: 0 | W21: 0 | Y21: 0 | Z21: 0 | AB21: 0 | AC21: 0 | AD21: =SUM(Z16:AC16) -> 0 | AF21: سعوديات | AH21: 0 | AI21: 0 | AJ21: 0 | AK21: 0 | AL21: 0 | AN21: 0 | AO21: 0 | AQ21: 0 | AR21: 0 | AS21: =SUM(AO16:AR16) -> 0 | AU21: سعوديات | AW21: 0 | AX21: 0 | AY21: 0 | AZ21: 0 | BA21: 0 | BC21: 0 | BD21: 0 | BF21: 0 | BG21: 0 | BH21: =SUM(BD16:BG16) -> 0 | BJ21: سعوديات | BL21: 0 | BM21: 0 | BN21: 0 | BO21: 0 | BP21: 0 | BR21: 0 | BS21: 0 | BU21: 0 | BV21: 0 | BW21: =SUM(BS16:BV16) -> 0 | BY21: سعوديات | CA21: 0 | CB21: 0 | CC21: 0 | CD21: 0 | CE21: 0 | CG21: 0 | CH21: 0 | CJ21: 0 | CK21: 0 | CL21: =SUM(CH16:CK16) -> 0 | CN21: سعوديات | CP21: 0 | CQ21: 0 | CR21: 0 | CS21: 0 | CT21: 0 | CV21: 0 | CW21: 0 | CY21: 0 | CZ21: 0 | DA21: =SUM(CW16:CZ16) -> 0 | DC21: سعوديات | DE21: 0 | DF21: 0 | DG21: 0 | DH21: 0 | DI21: 0 | DK21: 0 | DL21: 0 | DN21: 0 | DO21: 0 | DP21: =SUM(DL16:DO16) -> 0 | DR21: سعوديات | DT21: 0 | DU21: 0 | DV21: 0 | DW21: 0 | DX21: 0 | DZ21: 0 | EA21: 0 | EC21: 0 | ED21: 0 | EE21: =SUM(EA16:ED16) -> 0 | EG21: سعوديات | EI21: 0 | EJ21: 0 | EK21: 0 | EL21: 0 | EM21: 0 | EO21: 0 | EP21: 0 | ER21: 0 | ES21: 0 | ET21: =SUM(EP16:ES16) -> 0 | EV21: سعوديات | EX21: 0 | EY21: 0 | EZ21: 0 | FA21: 0 | FB21: 0 | FD21: 0 | FE21: 0 | FG21: 0 | FH21: 0 | FI21: =SUM(FE16:FH16) -> 0 | FK21: سعوديات | FM21: 0 | FN21: 0 | FO21: 0 | FP21: 0 | FQ21: 0 | FS21: 0 | FT21: 0 | FV21: 0 | FW21: 0 | FX21: =SUM(FT16:FW16) -> 0 | FZ21: سعوديات | GB21: =SUM(D21+S21+AH21+AW21+BL21+CA21+CP21+DE21+DT21+EI21+EX21+FM21) -> 0 | GC21: =SUM(E21+T21+AI21+AX21+BM21+CB21+CQ21+DF21+DU21+EJ21+EY21+FN21) -> 0 | GD21: =SUM(F21+U21+AJ21+AY21+BN21+CC21+CR21+DG21+DV21+EK21+EZ21+FO21) -> 0 | GE21: =SUM(G21+V21+AK21+AZ21+BO21+CD21+CS21+DH21+DW21+EL21+FA21+FP21) -> 0 | GF21: =SUM(H21+W21+AL21+BA21+BP21+CE21+CT21+DI21+DX21+EM21+FB21+FQ21) -> 0 | GH21: =SUM(J21+Y21+AN21+BC21+BR21+CG21+CV21+DK21+DZ21+EO21+FD21+FS21) -> 0 | GI21: =SUM(K21+Z21+AO21+BD21+BS21+CH21+CW21+DL21+EA21+EP21+FE21+FT21) -> 0 | GK21: =SUM(M21+AB21+AQ21+BF21+BU21+CJ21+CY21+DN21+EC21+ER21+FG21+FV21) -> 0 | GL21: =SUM(N21+AC21+AR21+BG21+BV21+CK21+CZ21+DO21+ED21+ES21+FH21+FW21) -> 0 | GM21: =SUM(GI16:GL16) -> 0
B22: غ.سعوديات | D22: 0 | E22: 0 | F22: 0 | G22: 0 | H22: 0 | J22: 0 | K22: 0 | M22: 0 | N22: 0 | O22: =SUM(D22:G22) -> 0 | Q22: غ.سعوديات | S22: 0 | T22: 0 | U22: 0 | V22: 0 | W22: 0 | Y22: 0 | Z22: 0 | AB22: 0 | AC22: 0 | AD22: =SUM(S22:V22) -> 0 | AF22: غ.سعوديات | AH22: 0 | AI22: 0 | AJ22: 0 | AK22: 0 | AL22: 0 | AN22: 0 | AO22: 0 | AQ22: 0 | AR22: 0 | AS22: =SUM(AH22:AK22) -> 0 | AU22: غ.سعوديات | AW22: 0 | AX22: 0 | AY22: 0 | AZ22: 0 | BA22: 0 | BC22: 0 | BD22: 0 | BF22: 0 | BG22: 0 | BH22: =SUM(AW22:AZ22) -> 0 | BJ22: غ.سعوديات | BL22: 0 | BM22: 0 | BN22: 0 | BO22: 0 | BP22: 0 | BR22: 0 | BS22: 0 | BU22: 0 | BV22: 0 | BW22: =SUM(BL22:BO22) -> 0 | BY22: غ.سعوديات | CA22: 0 | CB22: 0 | CC22: 0 | CD22: 0 | CE22: 0 | CG22: 0 | CH22: 0 | CJ22: 0 | CK22: 0 | CL22: =SUM(CA22:CD22) -> 0 | CN22: غ.سعوديات | CP22: 0 | CQ22: 0 | CR22: 0 | CS22: 0 | CT22: 0 | CV22: 0 | CW22: 0 | CY22: 0 | CZ22: 0 | DA22: =SUM(CP22:CS22) -> 0 | DC22: غ.سعوديات | DE22: 0 | DF22: 0 | DG22: 0 | DH22: 0 | DI22: 0 | DK22: 0 | DL22: 0 | DN22: 0 | DO22: 0 | DP22: =SUM(DE22:DH22) -> 0 | DR22: غ.سعوديات | DT22: 0 | DU22: 0 | DV22: 0 | DW22: 0 | DX22: 0 | DZ22: 0 | EA22: 0 | EC22: 0 | ED22: 0 | EE22: =SUM(DT22:DW22) -> 0 | EG22: غ.سعوديات | EI22: 0 | EJ22: 0 | EK22: 0 | EL22: 0 | EM22: 0 | EO22: 0 | EP22: 0 | ER22: 0 | ES22: 0 | ET22: =SUM(EI22:EL22) -> 0 | EV22: غ.سعوديات | EX22: 0 | EY22: 0 | EZ22: 0 | FA22: 0 | FB22: 0 | FD22: 0 | FE22: 0 | FG22: 0 | FH22: 0 | FI22: =SUM(EX22:FA22) -> 0 | FK22: غ.سعوديات | FM22: 0 | FN22: 0 | FO22: 0 | FP22: 0 | FQ22: 0 | FS22: 0 | FT22: 0 | FV22: 0 | FW22: 0 | FX22: =SUM(FM22:FP22) -> 0 | FZ22: غ.سعوديات | GB22: =SUM(D22+S22+AH22+AW22+BL22+CA22+CP22+DE22+DT22+EI22+EX22+FM22) -> 0 | GC22: =SUM(E22+T22+AI22+AX22+BM22+CB22+CQ22+DF22+DU22+EJ22+EY22+FN22) -> 0 | GD22: =SUM(F22+U22+AJ22+AY22+BN22+CC22+CR22+DG22+DV22+EK22+EZ22+FO22) -> 0 | GE22: =SUM(G22+V22+AK22+AZ22+BO22+CD22+CS22+DH22+DW22+EL22+FA22+FP22) -> 0 | GF22: =SUM(H22+W22+AL22+BA22+BP22+CE22+CT22+DI22+DX22+EM22+FB22+FQ22) -> 0 | GH22: =SUM(J22+Y22+AN22+BC22+BR22+CG22+CV22+DK22+DZ22+EO22+FD22+FS22) -> 0 | GI22: =SUM(K22+Z22+AO22+BD22+BS22+CH22+CW22+DL22+EA22+EP22+FE22+FT22) -> 0 | GK22: =SUM(M22+AB22+AQ22+BF22+BU22+CJ22+CY22+DN22+EC22+ER22+FG22+FV22) -> 0 | GL22: =SUM(N22+AC22+AR22+BG22+BV22+CK22+CZ22+DO22+ED22+ES22+FH22+FW22) -> 0 | GM22: =SUM(GB22:GE22) -> 0
B23: المجموع | D23: =SUM(D21:D22) -> 0 | E23: =SUM(E21:E22) -> 0 | F23: =SUM(F21:F22) -> 0 | G23: =SUM(G21:G22) -> 0 | H23: =SUM(H21:I22) -> 0 | J23: =SUM(J21:J22) -> 0 | K23: =SUM(K21:L22) -> 0 | M23: =SUM(M21:M22) -> 0 | N23: =SUM(N21:N22) -> 0 | O23: =SUM(H22:N22) -> 0 | Q23: المجموع | S23: =SUM(S21:S22) -> 0 | T23: =SUM(T21:T22) -> 0 | U23: =SUM(U21:U22) -> 0 | V23: =SUM(V21:V22) -> 0 | W23: =SUM(W21:X22) -> 0 | Y23: =SUM(Y21:Y22) -> 0 | Z23: =SUM(Z21:AA22) -> 0 | AB23: =SUM(AB21:AB22) -> 0 | AC23: =SUM(AC21:AC22) -> 0 | AD23: =SUM(W22:AC22) -> 0 | AF23: المجموع | AH23: =SUM(AH21:AH22) -> 0 | AI23: =SUM(AI21:AI22) -> 0 | AJ23: =SUM(AJ21:AJ22) -> 0 | AK23: =SUM(AK21:AK22) -> 0 | AL23: =SUM(AL21:AM22) -> 0 | AN23: =SUM(AN21:AN22) -> 0 | AO23: =SUM(AO21:AP22) -> 0 | AQ23: =SUM(AQ21:AQ22) -> 0 | AR23: =SUM(AR21:AR22) -> 0 | AS23: =SUM(AL22:AR22) -> 0 | AU23: المجموع | AW23: =SUM(AW21:AW22) -> 0 | AX23: =SUM(AX21:AX22) -> 0 | AY23: =SUM(AY21:AY22) -> 0 | AZ23: =SUM(AZ21:AZ22) -> 0 | BA23: =SUM(BA21:BB22) -> 0 | BC23: =SUM(BC21:BC22) -> 0 | BD23: =SUM(BD21:BE22) -> 0 | BF23: =SUM(BF21:BF22) -> 0 | BG23: =SUM(BG21:BG22) -> 0 | BH23: =SUM(BA22:BG22) -> 0 | BJ23: المجموع | BL23: =SUM(BL21:BL22) -> 0 | BM23: =SUM(BM21:BM22) -> 0 | BN23: =SUM(BN21:BN22) -> 0 | BO23: =SUM(BO21:BO22) -> 0 | BP23: =SUM(BP21:BQ22) -> 0 | BR23: =SUM(BR21:BR22) -> 0 | BS23: =SUM(BS21:BT22) -> 0 | BU23: =SUM(BU21:BU22) -> 0 | BV23: =SUM(BV21:BV22) -> 0 | BW23: =SUM(BP22:BV22) -> 0 | BY23: المجموع | CA23: =SUM(CA21:CA22) -> 0 | CB23: =SUM(CB21:CB22) -> 0 | CC23: =SUM(CC21:CC22) -> 0 | CD23: =SUM(CD21:CD22) -> 0 | CE23: =SUM(CE21:CF22) -> 0 | CG23: =SUM(CG21:CG22) -> 0 | CH23: =SUM(CH21:CI22) -> 0 | CJ23: =SUM(CJ21:CJ22) -> 0 | CK23: =SUM(CK21:CK22) -> 0 | CL23: =SUM(CE22:CK22) -> 0 | CN23: المجموع | CP23: =SUM(CP21:CP22) -> 0 | CQ23: =SUM(CQ21:CQ22) -> 0 | CR23: =SUM(CR21:CR22) -> 0 | CS23: =SUM(CS21:CS22) -> 0 | CT23: =SUM(CT21:CU22) -> 0 | CV23: =SUM(CV21:CV22) -> 0 | CW23: =SUM(CW21:CX22) -> 0 | CY23: =SUM(CY21:CY22) -> 0 | CZ23: =SUM(CZ21:CZ22) -> 0 | DA23: =SUM(CT22:CZ22) -> 0 | DC23: المجموع | DE23: =SUM(DE21:DE22) -> 0 | DF23: =SUM(DF21:DF22) -> 0 | DG23: =SUM(DG21:DG22) -> 0 | DH23: =SUM(DH21:DH22) -> 0 | DI23: =SUM(DI21:DJ22) -> 0 | DK23: =SUM(DK21:DK22) -> 0 | DL23: =SUM(DL21:DM22) -> 0 | DN23: =SUM(DN21:DN22) -> 0 | DO23: =SUM(DO21:DO22) -> 0 | DP23: =SUM(DI22:DO22) -> 0 | DR23: المجموع | DT23: =SUM(DT21:DT22) -> 0 | DU23: =SUM(DU21:DU22) -> 0 | DV23: =SUM(DV21:DV22) -> 0 | DW23: =SUM(DW21:DW22) -> 0 | DX23: =SUM(DX21:DY22) -> 0 | DZ23: =SUM(DZ21:DZ22) -> 0 | EA23: =SUM(EA21:EB22) -> 0 | EC23: =SUM(EC21:EC22) -> 0 | ED23: =SUM(ED21:ED22) -> 0 | EE23: =SUM(DX22:ED22) -> 0 | EG23: المجموع | EI23: =SUM(EI21:EI22) -> 0 | EJ23: =SUM(EJ21:EJ22) -> 0 | EK23: =SUM(EK21:EK22) -> 0 | EL23: =SUM(EL21:EL22) -> 0 | EM23: =SUM(EM21:EN22) -> 0 | EO23: =SUM(EO21:EO22) -> 0 | EP23: =SUM(EP21:EQ22) -> 0 | ER23: =SUM(ER21:ER22) -> 0 | ES23: =SUM(ES21:ES22) -> 0 | ET23: =SUM(EM22:ES22) -> 0 | EV23: المجموع | EX23: =SUM(EX21:EX22) -> 0 | EY23: =SUM(EY21:EY22) -> 0 | EZ23: =SUM(EZ21:EZ22) -> 0 | FA23: =SUM(FA21:FA22) -> 0 | FB23: =SUM(FB21:FC22) -> 0 | FD23: =SUM(FD21:FD22) -> 0 | FE23: =SUM(FE21:FF22) -> 0 | FG23: =SUM(FG21:FG22) -> 0 | FH23: =SUM(FH21:FH22) -> 0 | FI23: =SUM(FB22:FH22) -> 0 | FK23: المجموع | FM23: =SUM(FM21:FM22) -> 0 | FN23: =SUM(FN21:FN22) -> 0 | FO23: =SUM(FO21:FO22) -> 0 | FP23: =SUM(FP21:FP22) -> 0 | FQ23: =SUM(FQ21:FR22) -> 0 | FS23: =SUM(FS21:FS22) -> 0 | FT23: =SUM(FT21:FU22) -> 0 | FV23: =SUM(FV21:FV22) -> 0 | FW23: =SUM(FW21:FW22) -> 0 | FX23: =SUM(FQ22:FW22) -> 0 | FZ23: المجموع | GB23: =SUM(GB21:GB22) -> 0 | GC23: =SUM(GC21:GC22) -> 0 | GD23: =SUM(GD21:GD22) -> 0 | GE23: =SUM(GE21:GE22) -> 0 | GF23: =SUM(GF21:GG22) -> 0 | GH23: =SUM(GH21:GH22) -> 0 | GI23: =SUM(GI21:GJ22) -> 0 | GK23: =SUM(GK21:GK22) -> 0 | GL23: =SUM(GL21:GL22) -> 0 | GM23: =SUM(GF22:GL22) -> 0
A25: السليمانية | B25: سعوديات | C25: 0 | D25: 0 | F25: 0 | H25: 0 | I25: 0 | K25: 0 | M25: 0 | O25: =SUM(C25) -> 0 | P25: السليمانية | Q25: سعوديات | R25: 0 | S25: 0 | U25: 0 | W25: 0 | X25: 0 | Z25: 0 | AB25: 0 | AD25: =SUM(R25) -> 0 | AE25: السليمانية | AF25: سعوديات | AG25: 0 | AH25: 0 | AJ25: 0 | AL25: 0 | AM25: 0 | AO25: 0 | AQ25: 0 | AS25: =SUM(AG25) -> 0 | AT25: السليمانية | AU25: سعوديات | AV25: 0 | AW25: 0 | AY25: 0 | BA25: 0 | BB25: 0 | BD25: 0 | BF25: 0 | BH25: =SUM(AV25) -> 0 | BI25: السليمانية | BJ25: سعوديات | BK25: 0 | BL25: 0 | BN25: 0 | BP25: 0 | BQ25: 0 | BS25: 0 | BU25: 0 | BW25: =SUM(BK25) -> 0 | BX25: السليمانية | BY25: سعوديات | BZ25: 0 | CA25: 0 | CC25: 0 | CE25: 0 | CF25: 0 | CH25: 0 | CJ25: 0 | CL25: =SUM(BZ25) -> 0 | CM25: السليمانية | CN25: سعوديات | CO25: 0 | CP25: 0 | CR25: 0 | CT25: 0 | CU25: 0 | CW25: 0 | CY25: 0 | DA25: =SUM(CO25) -> 0 | DB25: السليمانية | DC25: سعوديات | DD25: 0 | DE25: 0 | DG25: 0 | DI25: 0 | DJ25: 0 | DL25: 0 | DN25: 0 | DP25: =SUM(DD25) -> 0 | DQ25: السليمانية | DR25: سعوديات | DS25: 0 | DT25: 0 | DV25: 0 | DX25: 0 | DY25: 0 | EA25: 0 | EC25: 0 | EE25: =SUM(DS25) -> 0 | EF25: السليمانية | EG25: سعوديات | EH25: 0 | EI25: 0 | EK25: 0 | EM25: 0 | EN25: 0 | EP25: 0 | ER25: 0 | ET25: =SUM(EH25) -> 0 | EU25: السليمانية | EV25: سعوديات | EW25: 0 | EX25: 0 | EZ25: 0 | FB25: 0 | FC25: 0 | FE25: 0 | FG25: 0 | FI25: =SUM(EW25) -> 0 | FJ25: السليمانية | FK25: سعوديات | FL25: 0 | FM25: 0 | FO25: 0 | FQ25: 0 | FR25: 0 | FT25: 0 | FV25: 0 | FX25: =SUM(FL25) -> 0 | FY25: =(FJ25) -> السليمانية | FZ25: سعوديات | GA25: =SUM(C25+R25+AG25+AV25+BK25+BZ25+CO25+DD25+DS25+EH25+EW25+FL25) -> 0 | GB25: =SUM(D25+S25+AH25+AW25+BL25+CA25+CP25+DE25+DT25+EI25+EX25+FM25) -> 0 | GD25: =SUM(F25+U25+AJ25+AY25+BN25+CC25+CR25+DG25+DV25+EK25+EZ25+FO25) -> 0 | GF25: =SUM(H25+W25+AL25+BA25+BP25+CE25+CT25+DI25+DX25+EM25+FB25+FQ25) -> 0 | GG25: =SUM(I25+X25+AM25+BB25+BQ25+CF25+CU25+DJ25+DY25+EN25+FC25+FR25) -> 0 | GI25: =SUM(K25+Z25+AO25+BD25+BS25+CH25+CW25+DL25+EA25+EP25+FE25+FT25) -> 0 | GK25: =SUM(M25+AB25+AQ25+BF25+BU25+CJ25+CY25+DN25+EC25+ER25+FG25+FV25) -> 0 | GM25: =SUM(GA25) -> 0
B26: غير سعوديات | C26: 0 | D26: 0 | F26: 0 | H26: 0 | I26: 0 | K26: 0 | M26: 0 | O26: =SUM(D25:G25) -> 0 | Q26: غير سعوديات | R26: 0 | S26: 0 | U26: 0 | W26: 0 | X26: 0 | Z26: 0 | AB26: 0 | AD26: =SUM(S25:V25) -> 0 | AF26: غير سعوديات | AG26: 0 | AH26: 0 | AJ26: 0 | AL26: 0 | AM26: 0 | AO26: 0 | AQ26: 0 | AS26: =SUM(AH25:AK25) -> 0 | AU26: غير سعوديات | AV26: 0 | AW26: 0 | AY26: 0 | BA26: 0 | BB26: 0 | BD26: 0 | BF26: 0 | BH26: =SUM(AW25:AZ25) -> 0 | BJ26: غير سعوديات | BK26: 0 | BL26: 0 | BN26: 0 | BP26: 0 | BQ26: 0 | BS26: 0 | BU26: 0 | BW26: =SUM(BL25:BO25) -> 0 | BY26: غير سعوديات | BZ26: 0 | CA26: 0 | CC26: 0 | CE26: 0 | CF26: 0 | CH26: 0 | CJ26: 0 | CL26: =SUM(CA25:CD25) -> 0 | CN26: غير سعوديات | CO26: 0 | CP26: 0 | CR26: 0 | CT26: 0 | CU26: 0 | CW26: 0 | CY26: 0 | DA26: =SUM(CP25:CS25) -> 0 | DC26: غير سعوديات | DD26: 0 | DE26: 0 | DG26: 0 | DI26: 0 | DJ26: 0 | DL26: 0 | DN26: 0 | DP26: =SUM(DE25:DH25) -> 0 | DR26: غير سعوديات | DS26: 0 | DT26: 0 | DV26: 0 | DX26: 0 | DY26: 0 | EA26: 0 | EC26: 0 | EE26: =SUM(DT25:DW25) -> 0 | EG26: غير سعوديات | EH26: 0 | EI26: 0 | EK26: 0 | EM26: 0 | EN26: 0 | EP26: 0 | ER26: 0 | ET26: =SUM(EI25:EL25) -> 0 | EV26: غير سعوديات | EW26: 0 | EX26: 0 | EZ26: 0 | FB26: 0 | FC26: 0 | FE26: 0 | FG26: 0 | FI26: =SUM(EX25:FA25) -> 0 | FK26: غير سعوديات | FL26: 0 | FM26: 0 | FO26: 0 | FQ26: 0 | FR26: 0 | FT26: 0 | FV26: 0 | FX26: =SUM(FM25:FP25) -> 0 | FZ26: غير سعوديات | GA26: =SUM(C26+R26+AG26+AV26+BK26+BZ26+CO26+DD26+DS26+EH26+EW26+FL26) -> 0 | GB26: =SUM(D26+S26+AH26+AW26+BL26+CA26+CP26+DE26+DT26+EI26+EX26+FM26) -> 0 | GD26: =SUM(F26+U26+AJ26+AY26+BN26+CC26+CR26+DG26+DV26+EK26+EZ26+FO26) -> 0 | GF26: =SUM(H26+W26+AL26+BA26+BP26+CE26+CT26+DI26+DX26+EM26+FB26+FQ26) -> 0 | GG26: =SUM(I26+X26+AM26+BB26+BQ26+CF26+CU26+DJ26+DY26+EN26+FC26+FR26) -> 0 | GI26: =SUM(K26+Z26+AO26+BD26+BS26+CH26+CW26+DL26+EA26+EP26+FE26+FT26) -> 0 | GK26: =SUM(M26+AB26+AQ26+BF26+BU26+CJ26+CY26+DN26+EC26+ER26+FG26+FV26) -> 0 | GM26: =SUM(GB25:GE25) -> 0
B27: المجموع | C27: =SUM(C25:C26) -> 0 | D27: =SUM(D25:E26) -> 0 | F27: =SUM(F25:G26) -> 0 | H27: =SUM(H25:H26) -> 0 | I27: =SUM(I25:J26) -> 0 | K27: =SUM(K25:L26) -> 0 | M27: =SUM(M25:N26) -> 0 | O27: =SUM(K25:N25) -> 0 | Q27: المجموع | R27: =SUM(R25:R26) -> 0 | S27: =SUM(S25:T26) -> 0 | U27: =SUM(U25:V26) -> 0 | W27: =SUM(W25:W26) -> 0 | X27: =SUM(X25:Y26) -> 0 | Z27: =SUM(Z25:AA26) -> 0 | AB27: =SUM(AB25:AC26) -> 0 | AD27: =SUM(Z25:AC25) -> 0 | AF27: المجموع | AG27: =SUM(AG25:AG26) -> 0 | AH27: =SUM(AH25:AI26) -> 0 | AJ27: =SUM(AJ25:AK26) -> 0 | AL27: =SUM(AL25:AL26) -> 0 | AM27: =SUM(AM25:AN26) -> 0 | AO27: =SUM(AO25:AP26) -> 0 | AQ27: =SUM(AQ25:AR26) -> 0 | AS27: =SUM(AO25:AR25) -> 0 | AU27: المجموع | AV27: =SUM(AV25:AV26) -> 0 | AW27: =SUM(AW25:AX26) -> 0 | AY27: =SUM(AY25:AZ26) -> 0 | BA27: =SUM(BA25:BA26) -> 0 | BB27: =SUM(BB25:BC26) -> 0 | BD27: =SUM(BD25:BE26) -> 0 | BF27: =SUM(BF25:BG26) -> 0 | BH27: =SUM(BD25:BG25) -> 0 | BJ27: المجموع | BK27: =SUM(BK25:BK26) -> 0 | BL27: =SUM(BL25:BM26) -> 0 | BN27: =SUM(BN25:BO26) -> 0 | BP27: =SUM(BP25:BP26) -> 0 | BQ27: =SUM(BQ25:BR26) -> 0 | BS27: =SUM(BS25:BT26) -> 0 | BU27: =SUM(BU25:BV26) -> 0 | BW27: =SUM(BS25:BV25) -> 0 | BY27: المجموع | BZ27: =SUM(BZ25:BZ26) -> 0 | CA27: =SUM(CA25:CB26) -> 0 | CC27: =SUM(CC25:CD26) -> 0 | CE27: =SUM(CE25:CE26) -> 0 | CF27: =SUM(CF25:CG26) -> 0 | CH27: =SUM(CH25:CI26) -> 0 | CJ27: =SUM(CJ25:CK26) -> 0 | CL27: =SUM(CH25:CK25) -> 0 | CN27: المجموع | CO27: =SUM(CO25:CO26) -> 0 | CP27: =SUM(CP25:CQ26) -> 0 | CR27: =SUM(CR25:CS26) -> 0 | CT27: =SUM(CT25:CT26) -> 0 | CU27: =SUM(CU25:CV26) -> 0 | CW27: =SUM(CW25:CX26) -> 0 | CY27: =SUM(CY25:CZ26) -> 0 | DA27: =SUM(CW25:CZ25) -> 0 | DC27: المجموع | DD27: =SUM(DD25:DD26) -> 0 | DE27: =SUM(DE25:DF26) -> 0 | DG27: =SUM(DG25:DH26) -> 0 | DI27: =SUM(DI25:DI26) -> 0 | DJ27: =SUM(DJ25:DK26) -> 0 | DL27: =SUM(DL25:DM26) -> 0 | DN27: =SUM(DN25:DO26) -> 0 | DP27: =SUM(DL25:DO25) -> 0 | DR27: المجموع | DS27: =SUM(DS25:DS26) -> 0 | DT27: =SUM(DT25:DU26) -> 0 | DV27: =SUM(DV25:DW26) -> 0 | DX27: =SUM(DX25:DX26) -> 0 | DY27: =SUM(DY25:DZ26) -> 0 | EA27: =SUM(EA25:EB26) -> 0 | EC27: =SUM(EC25:ED26) -> 0 | EE27: =SUM(EA25:ED25) -> 0 | EG27: المجموع | EH27: =SUM(EH25:EH26) -> 0 | EI27: =SUM(EI25:EJ26) -> 0 | EK27: =SUM(EK25:EL26) -> 0 | EM27: =SUM(EM25:EM26) -> 0 | EN27: =SUM(EN25:EO26) -> 0 | EP27: =SUM(EP25:EQ26) -> 0 | ER27: =SUM(ER25:ES26) -> 0 | ET27: =SUM(EP25:ES25) -> 0 | EV27: المجموع | EW27: =SUM(EW25:EW26) -> 0 | EX27: =SUM(EX25:EY26) -> 0 | EZ27: =SUM(EZ25:FA26) -> 0 | FB27: =SUM(FB25:FB26) -> 0 | FC27: =SUM(FC25:FD26) -> 0 | FE27: =SUM(FE25:FF26) -> 0 | FG27: =SUM(FG25:FH26) -> 0 | FI27: =SUM(FE25:FH25) -> 0 | FK27: المجموع | FL27: =SUM(FL25:FL26) -> 0 | FM27: =SUM(FM25:FN26) -> 0 | FO27: =SUM(FO25:FP26) -> 0 | FQ27: =SUM(FQ25:FQ26) -> 0 | FR27: =SUM(FR25:FS26) -> 0 | FT27: =SUM(FT25:FU26) -> 0 | FV27: =SUM(FV25:FW26) -> 0 | FX27: =SUM(FT25:FW25) -> 0 | FZ27: المجموع | GA27: =SUM(GA25:GA26) -> 0 | GB27: =SUM(GB25:GC26) -> 0 | GD27: =SUM(GD25:GE26) -> 0 | GF27: =SUM(GF25:GF26) -> 0 | GG27: =SUM(GG25:GH26) -> 0 | GI27: =SUM(GI25:GJ26) -> 0 | GK27: =SUM(GK25:GL26) -> 0 | GM27: =SUM(GI25:GL25) -> 0
D28: مكان الولادة | H28: نتيجة الحمل | O28: =SUM(D31:G31) -> 0 | S28: مكان الولادة | W28: نتيجة الحمل | AD28: =SUM(S31:V31) -> 0 | AH28: مكان الولادة | AL28: نتيجة الحمل | AS28: =SUM(AH31:AK31) -> 0 | AW28: مكان الولادة | BA28: نتيجة الحمل | BH28: =SUM(AW31:AZ31) -> 0 | BL28: مكان الولادة | BP28: نتيجة الحمل | BW28: =SUM(BL31:BO31) -> 0 | CA28: مكان الولادة | CE28: نتيجة الحمل | CL28: =SUM(CA31:CD31) -> 0 | CP28: مكان الولادة | CT28: نتيجة الحمل | DA28: =SUM(CP31:CS31) -> 0 | DE28: مكان الولادة | DI28: نتيجة الحمل | DP28: =SUM(DE31:DH31) -> 0 | DT28: مكان الولادة | DX28: نتيجة الحمل | EE28: =SUM(DT31:DW31) -> 0 | EI28: مكان الولادة | EM28: نتيجة الحمل | ET28: =SUM(EI31:EL31) -> 0 | EX28: مكان الولادة | FB28: نتيجة الحمل | FI28: =SUM(EX31:FA31) -> 0 | FM28: مكان الولادة | FQ28: نتيجة الحمل | FX28: =SUM(FM31:FP31) -> 0 | GB28: مكان الولادة | GF28: نتيجة الحمل | GM28: =SUM(GB31:GE31) -> 0
D29: بالمنزل | F29: بالمركز الصحي | G29: بالمستشفى | H29: مولود حي | M29: إجهاض | N29: مولود ميت | O29: =SUM(H31:N31) -> 0 | S29: بالمنزل | U29: بالمركز الصحي | V29: بالمستشفى | W29: مولود حي | AB29: إجهاض | AC29: مولود ميت | AD29: =SUM(W31:AC31) -> 0 | AH29: بالمنزل | AJ29: بالمركز الصحي | AK29: بالمستشفى | AL29: مولود حي | AQ29: إجهاض | AR29: مولود ميت | AS29: =SUM(AL31:AR31) -> 0 | AW29: بالمنزل | AY29: بالمركز الصحي | AZ29: بالمستشفى | BA29: مولود حي | BF29: إجهاض | BG29: مولود ميت | BH29: =SUM(BA31:BG31) -> 0 | BL29: بالمنزل | BN29: بالمركز الصحي | BO29: بالمستشفى | BP29: مولود حي | BU29: إجهاض | BV29: مولود ميت | BW29: =SUM(BP31:BV31) -> 0 | CA29: بالمنزل | CC29: بالمركز الصحي | CD29: بالمستشفى | CE29: مولود حي | CJ29: إجهاض | CK29: مولود ميت | CL29: =SUM(CE31:CK31) -> 0 | CP29: بالمنزل | CR29: بالمركز الصحي | CS29: بالمستشفى | CT29: مولود حي | CY29: إجهاض | CZ29: مولود ميت | DA29: =SUM(CT31:CZ31) -> 0 | DE29: بالمنزل | DG29: بالمركز الصحي | DH29: بالمستشفى | DI29: مولود حي | DN29: إجهاض | DO29: مولود ميت | DP29: =SUM(DI31:DO31) -> 0 | DT29: بالمنزل | DV29: بالمركز الصحي | DW29: بالمستشفى | DX29: مولود حي | EC29: إجهاض | ED29: مولود ميت | EE29: =SUM(DX31:ED31) -> 0 | EI29: بالمنزل | EK29: بالمركز الصحي | EL29: بالمستشفى | EM29: مولود حي | ER29: إجهاض | ES29: مولود ميت | ET29: =SUM(EM31:ES31) -> 0 | EX29: بالمنزل | EZ29: بالمركز الصحي | FA29: بالمستشفى | FB29: مولود حي | FG29: إجهاض | FH29: مولود ميت | FI29: =SUM(FB31:FH31) -> 0 | FM29: بالمنزل | FO29: بالمركز الصحي | FP29: بالمستشفى | FQ29: مولود حي | FV29: إجهاض | FW29: مولود ميت | FX29: =SUM(FQ31:FW31) -> 0 | GB29: بالمنزل | GD29: بالمركز الصحي | GE29: بالمستشفى | GF29: مولود حي | GK29: إجهاض | GL29: مولود ميت | GM29: =SUM(GF31:GL31) -> 0
D30: بإشراف | E30: بدون | H30: طبيعي | J30: مبتسر | K30: أقل من 2.5 كجم | O30: =SUM(C26) -> 0 | S30: بإشراف | T30: بدون | W30: طبيعي | Y30: مبتسر | Z30: أقل من 2.5 كجم | AD30: =SUM(R26) -> 0 | AH30: بإشراف | AI30: بدون | AL30: طبيعي | AN30: مبتسر | AO30: أقل من 2.5 كجم | AS30: =SUM(AG26) -> 0 | AW30: بإشراف | AX30: بدون | BA30: طبيعي | BC30: مبتسر | BD30: أقل من 2.5 كجم | BH30: =SUM(AV26) -> 0 | BL30: بإشراف | BM30: بدون | BP30: طبيعي | BR30: مبتسر | BS30: أقل من 2.5 كجم | BW30: =SUM(BK26) -> 0 | CA30: بإشراف | CB30: بدون | CE30: طبيعي | CG30: مبتسر | CH30: أقل من 2.5 كجم | CL30: =SUM(BZ26) -> 0 | CP30: بإشراف | CQ30: بدون | CT30: طبيعي | CV30: مبتسر | CW30: أقل من 2.5 كجم | DA30: =SUM(CO26) -> 0 | DE30: بإشراف | DF30: بدون | DI30: طبيعي | DK30: مبتسر | DL30: أقل من 2.5 كجم | DP30: =SUM(DD26) -> 0 | DT30: بإشراف | DU30: بدون | DX30: طبيعي | DZ30: مبتسر | EA30: أقل من 2.5 كجم | EE30: =SUM(DS26) -> 0 | EI30: بإشراف | EJ30: بدون | EM30: طبيعي | EO30: مبتسر | EP30: أقل من 2.5 كجم | ET30: =SUM(EH26) -> 0 | EX30: بإشراف | EY30: بدون | FB30: طبيعي | FD30: مبتسر | FE30: أقل من 2.5 كجم | FI30: =SUM(EW26) -> 0 | FM30: بإشراف | FN30: بدون | FQ30: طبيعي | FS30: مبتسر | FT30: أقل من 2.5 كجم | FX30: =SUM(FL26) -> 0 | GB30: بإشراف | GC30: بدون | GF30: طبيعي | GH30: مبتسر | GI30: أقل من 2.5 كجم | GM30: =SUM(GA26) -> 0
B31: سعوديات | D31: 0 | E31: 0 | F31: 0 | G31: 0 | H31: 0 | J31: 0 | K31: 0 | M31: 0 | N31: 0 | O31: =SUM(K26:N26) -> 0 | Q31: سعوديات | S31: 0 | T31: 0 | U31: 0 | V31: 0 | W31: 0 | Y31: 0 | Z31: 0 | AB31: 0 | AC31: 0 | AD31: =SUM(Z26:AC26) -> 0 | AF31: سعوديات | AH31: 0 | AI31: 0 | AJ31: 0 | AK31: 0 | AL31: 0 | AN31: 0 | AO31: 0 | AQ31: 0 | AR31: 0 | AS31: =SUM(AO26:AR26) -> 0 | AU31: سعوديات | AW31: 0 | AX31: 0 | AY31: 0 | AZ31: 0 | BA31: 0 | BC31: 0 | BD31: 0 | BF31: 0 | BG31: 0 | BH31: =SUM(BD26:BG26) -> 0 | BJ31: سعوديات | BL31: 0 | BM31: 0 | BN31: 0 | BO31: 0 | BP31: 0 | BR31: 0 | BS31: 0 | BU31: 0 | BV31: 0 | BW31: =SUM(BS26:BV26) -> 0 | BY31: سعوديات | CA31: 0 | CB31: 0 | CC31: 0 | CD31: 0 | CE31: 0 | CG31: 0 | CH31: 0 | CJ31: 0 | CK31: 0 | CL31: =SUM(CH26:CK26) -> 0 | CN31: سعوديات | CP31: 0 | CQ31: 0 | CR31: 0 | CS31: 0 | CT31: 0 | CV31: 0 | CW31: 0 | CY31: 0 | CZ31: 0 | DA31: =SUM(CW26:CZ26) -> 0 | DC31: سعوديات | DE31: 0 | DF31: 0 | DG31: 0 | DH31: 0 | DI31: 0 | DK31: 0 | DL31: 0 | DN31: 0 | DO31: 0 | DP31: =SUM(DL26:DO26) -> 0 | DR31: سعوديات | DT31: 0 | DU31: 0 | DV31: 0 | DW31: 0 | DX31: 0 | DZ31: 0 | EA31: 0 | EC31: 0 | ED31: 0 | EE31: =SUM(EA26:ED26) -> 0 | EG31: سعوديات | EI31: 0 | EJ31: 0 | EK31: 0 | EL31: 0 | EM31: 0 | EO31: 0 | EP31: 0 | ER31: 0 | ES31: 0 | ET31: =SUM(EP26:ES26) -> 0 | EV31: سعوديات | EX31: 0 | EY31: 0 | EZ31: 0 | FA31: 0 | FB31: 0 | FD31: 0 | FE31: 0 | FG31: 0 | FH31: 0 | FI31: =SUM(FE26:FH26) -> 0 | FK31: سعوديات | FM31: 0 | FN31: 0 | FO31: 0 | FP31: 0 | FQ31: 0 | FS31: 0 | FT31: 0 | FV31: 0 | FW31: 0 | FX31: =SUM(FT26:FW26) -> 0 | FZ31: سعوديات | GB31: =SUM(D31+S31+AH31+AW31+BL31+CA31+CP31+DE31+DT31+EI31+EX31+FM31) -> 0 | GC31: =SUM(E31+T31+AI31+AX31+BM31+CB31+CQ31+DF31+DU31+EJ31+EY31+FN31) -> 0 | GD31: =SUM(F31+U31+AJ31+AY31+BN31+CC31+CR31+DG31+DV31+EK31+EZ31+FO31) -> 0 | GE31: =SUM(G31+V31+AK31+AZ31+BO31+CD31+CS31+DH31+DW31+EL31+FA31+FP31) -> 0 | GF31: =SUM(H31+W31+AL31+BA31+BP31+CE31+CT31+DI31+DX31+EM31+FB31+FQ31) -> 0 | GH31: =SUM(J31+Y31+AN31+BC31+BR31+CG31+CV31+DK31+DZ31+EO31+FD31+FS31) -> 0 | GI31: =SUM(K31+Z31+AO31+BD31+BS31+CH31+CW31+DL31+EA31+EP31+FE31+FT31) -> 0 | GK31: =SUM(M31+AB31+AQ31+BF31+BU31+CJ31+CY31+DN31+EC31+ER31+FG31+FV31) -> 0 | GL31: =SUM(N31+AC31+AR31+BG31+BV31+CK31+CZ31+DO31+ED31+ES31+FH31+FW31) -> 0 | GM31: =SUM(GI26:GL26) -> 0
B32: غ.سعوديات | D32: 0 | E32: 0 | F32: 0 | G32: 0 | H32: 0 | J32: 0 | K32: 0 | M32: 0 | N32: 0 | O32: =SUM(D32:G32) -> 0 | Q32: غ.سعوديات | S32: 0 | T32: 0 | U32: 0 | V32: 0 | W32: 0 | Y32: 0 | Z32: 0 | AB32: 0 | AC32: 0 | AD32: =SUM(S32:V32) -> 0 | AF32: غ.سعوديات | AH32: 0 | AI32: 0 | AJ32: 0 | AK32: 0 | AL32: 0 | AN32: 0 | AO32: 0 | AQ32: 0 | AR32: 0 | AS32: =SUM(AH32:AK32) -> 0 | AU32: غ.سعوديات | AW32: 0 | AX32: 0 | AY32: 0 | AZ32: 0 | BA32: 0 | BC32: 0 | BD32: 0 | BF32: 0 | BG32: 0 | BH32: =SUM(AW32:AZ32) -> 0 | BJ32: غ.سعوديات | BL32: 0 | BM32: 0 | BN32: 0 | BO32: 0 | BP32: 0 | BR32: 0 | BS32: 0 | BU32: 0 | BV32: 0 | BW32: =SUM(BL32:BO32) -> 0 | BY32: غ.سعوديات | CA32: 0 | CB32: 0 | CC32: 0 | CD32: 0 | CE32: 0 | CG32: 0 | CH32: 0 | CJ32: 0 | CK32: 0 | CL32: =SUM(CA32:CD32) -> 0 | CN32: غ.سعوديات | CP32: 0 | CQ32: 0 | CR32: 0 | CS32: 0 | CT32: 0 | CV32: 0 | CW32: 0 | CY32: 0 | CZ32: 0 | DA32: =SUM(CP32:CS32) -> 0 | DC32: غ.سعوديات | DE32: 0 | DF32: 0 | DG32: 0 | DH32: 0 | DI32: 0 | DK32: 0 | DL32: 0 | DN32: 0 | DO32: 0 | DP32: =SUM(DE32:DH32) -> 0 | DR32: غ.سعوديات | DT32: 0 | DU32: 0 | DV32: 0 | DW32: 0 | DX32: 0 | DZ32: 0 | EA32: 0 | EC32: 0 | ED32: 0 | EE32: =SUM(DT32:DW32) -> 0 | EG32: غ.سعوديات | EI32: 0 | EJ32: 0 | EK32: 0 | EL32: 0 | EM32: 0 | EO32: 0 | EP32: 0 | ER32: 0 | ES32: 0 | ET32: =SUM(EI32:EL32) -> 0 | EV32: غ.سعوديات | EX32: 0 | EY32: 0 | EZ32: 0 | FA32: 0 | FB32: 0 | FD32: 0 | FE32: 0 | FG32: 0 | FH32: 0 | FI32: =SUM(EX32:FA32) -> 0 | FK32: غ.سعوديات | FM32: 0 | FN32: 0 | FO32: 0 | FP32: 0 | FQ32: 0 | FS32: 0 | FT32: 0 | FV32: 0 | FW32: 0 | FX32: =SUM(FM32:FP32) -> 0 | FZ32: غ.سعوديات | GB32: =SUM(D32+S32+AH32+AW32+BL32+CA32+CP32+DE32+DT32+EI32+EX32+FM32) -> 0 | GC32: =SUM(E32+T32+AI32+AX32+BM32+CB32+CQ32+DF32+DU32+EJ32+EY32+FN32) -> 0 | GD32: =SUM(F32+U32+AJ32+AY32+BN32+CC32+CR32+DG32+DV32+EK32+EZ32+FO32) -> 0 | GE32: =SUM(G32+V32+AK32+AZ32+BO32+CD32+CS32+DH32+DW32+EL32+FA32+FP32) -> 0 | GF32: =SUM(H32+W32+AL32+BA32+BP32+CE32+CT32+DI32+DX32+EM32+FB32+FQ32) -> 0 | GH32: =SUM(J32+Y32+AN32+BC32+BR32+CG32+CV32+DK32+DZ32+EO32+FD32+FS32) -> 0 | GI32: =SUM(K32+Z32+AO32+BD32+BS32+CH32+CW32+DL32+EA32+EP32+FE32+FT32) -> 0 | GK32: =SUM(M32+AB32+AQ32+BF32+BU32+CJ32+CY32+DN32+EC32+ER32+FG32+FV32) -> 0 | GL32: =SUM(N32+AC32+AR32+BG32+BV32+CK32+CZ32+DO32+ED32+ES32+FH32+FW32) -> 0 | GM32: =SUM(GB32:GE32) -> 0
