Workbook

Sheet الإحالات
A2: مراكز شرق جدة | D2: شهر | E2: 1 | F2: 1447 | G2: هـ | J2: مراكز شرق جدة | M2: شهر | N2: 2 | O2: 1447 | P2: هـ | S2: مراكز شرق جدة | V2: شهر | W2: 3 | X2: 1447 | Y2: هـ | AB2: مراكز شرق جدة | AE2: شهر | AF2: 4 | AG2: 1447 | AH2: هـ | AK2: مراكز شرق جدة | AN2: شهر | AO2: 5 | AP2: 1447 | AQ2: هـ | AT2: مراكز شرق جدة | AW2: شهر | AX2: 6 | AY2: 1447 | AZ2: هـ | BC2: مراكز شرق جدة | BF2: شهر | BG2: 7 | BH2: 1447 | BI2: هـ | BL2: مراكز شرق جدة | BO2: شهر | BP2: 8 | BQ2: 1447 | BR2: هـ | BU2: مراكز شرق جدة | BX2: شهر | BY2: 9 | BZ2: 1447 | CA2: هـ | CD2: مراكز شرق جدة | CG2: شهر | CH2: 10 | CI2: 1447 | CJ2: هـ | CM2: مراكز شرق جدة | CP2: شهر | CQ2: 11 | CR2: 1447 | CS2: هـ | CV2: مراكز شرق جدة | CY2: شهر | CZ2: 12 | DA2: 1447 | DB2: هـ | DE2: الإحالات والردود الراجعة | DI2: عام | DJ2: =SUM(DA2) -> 1447 | DK2: هـ
A3: مراكز | D3: نوع الإحالات | G3: المجموع | H3: الردود | J3: مراكز | M3: نوع الإحالات | P3: المجموع | Q3: الردود | S3: مراكز | V3: نوع الإحالات | Y3: المجموع | Z3: الردود | AB3: مراكز | AE3: نوع الإحالات | AH3: المجموع | AI3: الردود | AK3: مراكز | AN3: نوع الإحالات | AQ3: المجموع | AR3: الردود | AT3: مراكز | AW3: نوع الإحالات | AZ3: المجموع | BA3: الردود | BC3: مراكز | BF3: نوع الإحالات | BI3: المجموع | BJ3: الردود | BL3: مراكز | BO3: نوع الإحالات | BR3: المجموع | BS3: الردود | BU3: مراكز | BX3: نوع الإحالات | CA3: المجموع | CB3: الردود | CD3: مراكز | CG3: نوع الإحالات | CJ3: المجموع | CK3: الردود | CM3: مراكز | CP3: نوع الإحالات | CS3: المجموع | CT3: الردود | CV3: مراكز | CY3: نوع الإحالات | DB3: المجموع | DC3: الردود | DE3: مراكز | DF3: الجنسية | DG3: الجنس | DH3: نوع الإحالات | DK3: المجموع | DL3: الردود
D4: إسعافات أولية | E4: طارئة | F4: عادية | H4: الراجعة | M4: إسعافات أولية | N4: طارئة | O4: عادية | Q4: الراجعة | V4: إسعافات أولية | W4: طارئة | X4: عادية | Z4: الراجعة | AE4: إسعافات أولية | AF4: طارئة | AG4: عادية | AI4: الراجعة | AN4: إسعافات أولية | AO4: طارئة | AP4: عادية | AR4: الراجعة | AW4: إسعافات أولية | AX4: طارئة | AY4: عادية | BA4: الراجعة | BF4: إسعافات أولية | BG4: طارئة | BH4: عادية | BJ4: الراجعة | BO4: إسعافات أولية | BP4: طارئة | BQ4: عادية | BS4: الراجعة | BX4: إسعافات أولية | BY4: طارئة | BZ4: عادية | CB4: الراجعة | CG4: إسعافات أولية | CH4: طارئة | CI4: عادية | CK4: الراجعة | CP4: إسعافات أولية | CQ4: طارئة | CR4: عادية | CT4: الراجعة | CY4: إسعافات أولية | CZ4: طارئة | DA4: عادية | DC4: الراجعة | DH4: إسعافات أولية | DI4: طارئة | DJ4: عادية | DL4: الراجعة
A5: الربيع والتوفيق | B5: سعودي | C5: ذكر | D5: 0 | E5: 3 | F5: 280 | G5: =SUM(D5:F5) -> 283 | H5: 0 | J5: الربيع والتوفيق | K5: سعودي | L5: ذكر | M5: 0 | N5: 9 | O5: 301 | P5: 310 | Q5: 0 | S5: الربيع والتوفيق | T5: سعودي | U5: ذكر | V5: 0 | W5: 105 | X5: 225 | Y5: =SUM(V5:X5) -> 330 | Z5: 0 | AB5: الربيع والتوفيق | AC5: سعودي | AD5: ذكر | AE5: 0 | AF5: 38 | AG5: 258 | AH5: =SUM(AE5:AG5) -> 296 | AI5: 0 | AK5: الربيع والتوفيق | AL5: سعودي | AM5: ذكر | AN5: 0 | AO5: 33 | AP5: 325 | AQ5: =SUM(AN5:AP5) -> 358 | AR5: 0 | AT5: الربيع والتوفيق | AU5: سعودي | AV5: ذكر | AW5: 0 | AX5: 29 | AY5: 415 | AZ5: =SUM(AW5:AY5) -> 444 | BA5: 0 | BC5: الربيع والتوفيق | BD5: سعودي | BE5: ذكر | BF5: 0 | BG5: 11 | BH5: 315 | BI5: 326 | BJ5: 0 | BL5: الربيع والتوفيق | BM5: سعودي | BN5: ذكر | BO5: 0 | BP5: 52 | BQ5: 185 | BR5: =SUM(BO5:BQ5) -> 237 | BS5: 0 | BU5: الربيع والتوفيق | BV5: سعودي | BW5: ذكر | BX5: 0 | BY5: 17 | BZ5: 322 | CA5: =SUM(BX5:BZ5) -> 339 | CB5: 0 | CD5: الربيع والتوفيق | CE5: سعودي | CF5: ذكر | CG5: 0 | CH5: 7 | CI5: 425 | CJ5: =SUM(CG5:CI5) -> 432 | CK5: 0 | CM5: الربيع والتوفيق | CN5: سعودي | CO5: ذكر | CP5: 0 | CQ5: 0 | CR5: 0 | CS5: =SUM(CP5:CR5) -> 0 | CT5: 0 | CV5: الربيع والتوفيق | CW5: سعودي | CX5: ذكر | CY5: 0 | CZ5: 0 | DA5: 0 | DB5: =SUM(CY5:DA5) -> 0 | DC5: 0 | DE5: =CV5 -> الربيع والتوفيق | DG5: ذكر | DH5: =D5+M5+V5+AE5+AN5+AW5+BF5+BO5+BX5+CG5+CP5+CY5 -> 0 | DI5: =E5+N5+W5+AF5+AO5+AX5+BG5+BP5+BY5+CH5+CQ5+CZ5 -> 304 | DJ5: =F5+O5+X5+AG5+AP5+AY5+BH5+BQ5+BZ5+CI5+CR5+DA5 -> 3051 | DK5: =SUM(DH5:DJ5) -> 3355 | DL5: =H5+Q5+Z5+AI5+AR5+BA5+BJ5+BS5+CB5+CK5+CT5+DC5 -> 0
C6: أنثى | D6: 0 | E6: 10 | F6: 390 | G6: =SUM(D6:F6) -> 400 | H6: 0 | L6: أنثى | M6: 0 | N6: 11 | O6: 398 | P6: 409 | Q6: 0 | U6: أنثى | V6: 0 | W6: 125 | X6: 242 | Y6: =SUM(V6:X6) -> 367 | Z6: 0 | AD6: أنثى | AE6: 0 | AF6: 77 | AG6: 238 | AH6: =SUM(AE6:AG6) -> 315 | AI6: 0 | AM6: أنثى | AN6: 0 | AO6: 51 | AP6: 230 | AQ6: =SUM(AN6:AP6) -> 281 | AR6: 0 | AV6: أنثى | AW6: 0 | AX6: 44 | AY6: 310 | AZ6: =SUM(AW6:AY6) -> 354 | BA6: 0 | BE6: أنثى | BF6: 0 | BG6: 15 | BH6: 410 | BI6: 425 | BJ6: 0 | BN6: أنثى | BO6: 0 | BP6: 62 | BQ6: 143 | BR6: =SUM(BO6:BQ6) -> 205 | BS6: 0 | BW6: أنثى | BX6: 0 | BY6: 5 | BZ6: 240 | CA6: =SUM(BX6:BZ6) -> 245 | CB6: 0 | CF6: أنثى | CG6: 0 | CH6: 6 | CI6: 255 | CJ6: =SUM(CG6:CI6) -> 261 | CK6: 0 | CO6: أنثى | CP6: 0 | CQ6: 0 | CR6: 0 | CS6: =SUM(CP6:CR6) -> 0 | CT6: 0 | CX6: أنثى | CY6: 0 | CZ6: 0 | DA6: 0 | DB6: =SUM(CY6:DA6) -> 0 | DC6: 0 | DF6: سعودي | DG6: أنثى | DH6: =D6+M6+V6+AE6+AN6+AW6+BF6+BO6+BX6+CG6+CP6+CY6 -> 0 | DI6: =E6+N6+W6+AF6+AO6+AX6+BG6+BP6+BY6+CH6+CQ6+CZ6 -> 406 | DJ6: =F6+O6+X6+AG6+AP6+AY6+BH6+BQ6+BZ6+CI6+CR6+DA6 -> 2856 | DK6: =SUM(DH6:DJ6) -> 3262 | DL6: =H6+Q6+Z6+AI6+AR6+BA6+BJ6+BS6+CB6+CK6+CT6+DC6 -> 0
B7: غير | C7: ذكر | G7: =SUM(D7:F7) -> 0 | H7: 0 | K7: غير | L7: ذكر | Q7: 0 | T7: غير | U7: ذكر | Y7: =SUM(V7:X7) -> 0 | Z7: 0 | AC7: غير | AD7: ذكر | AH7: =SUM(AE7:AG7) -> 0 | AI7: 0 | AL7: غير | AM7: ذكر | AN7: 0 | AO7: 40 | AP7: 88 | AQ7: =SUM(AN7:AP7) -> 128 | AR7: 0 | AU7: غير | AV7: ذكر | AW7: 0 | AX7: 11 | AY7: 90 | AZ7: =SUM(AW7:AY7) -> 101 | BA7: 0 | BD7: غير | BE7: ذكر | BJ7: 0 | BM7: غير | BN7: ذكر | BO7: 0 | BP7: 19 | BQ7: 42 | BR7: =SUM(BO7:BQ7) -> 61 | BS7: 0 | BV7: غير | BW7: ذكر | BX7: 0 | BY7: 0 | BZ7: 0 | CA7: =SUM(BX7:BZ7) -> 0 | CB7: 0 | CE7: غير | CF7: ذكر | CG7: 0 | CH7: 0 | CI7: 8 | CJ7: =SUM(CG7:CI7) -> 8 | CK7: 0 | CN7: غير | CO7: ذكر | CP7: 0 | CQ7: 0 | CR7: 0 | CS7: =SUM(CP7:CR7) -> 0 | CT7: 0 | CW7: غير | CX7: ذكر | CY7: 0 | CZ7: 0 | DA7: 0 | DB7: =SUM(CY7:DA7) -> 0 | DC7: 0 | DF7: غير | DG7: ذكر | DH7: =D7+M7+V7+AE7+AN7+AW7+BF7+BO7+BX7+CG7+CP7+CY7 -> 0 | DI7: =E7+N7+W7+AF7+AO7+AX7+BG7+BP7+BY7+CH7+CQ7+CZ7 -> 70 | DJ7: =F7+O7+X7+AG7+AP7+AY7+BH7+BQ7+BZ7+CI7+CR7+DA7 -> 228 | DK7: =SUM(DH7:DJ7) -> 298 | DL7: =H7+Q7+Z7+AI7+AR7+BA7+BJ7+BS7+CB7+CK7+CT7+DC7 -> 0
B8: سعودي | C8: أنثى | D8: 0 | E8: 1 | F8: 20 | G8: =SUM(D8:F8) -> 21 | H8: 0 | K8: سعودي | L8: أنثى | M8: 0 | N8: 0 | O8: 0 | P8: 0 | Q8: 0 | T8: سعودي | U8: أنثى | V8: 0 | W8: 32 | X8: 43 | Y8: =SUM(V8:X8) -> 75 | Z8: 0 | AC8: سعودي | AD8: أنثى | AE8: 0 | AF8: 43 | AG8: 81 | AH8: =SUM(AE8:AG8) -> 124 | AI8: 0 | AL8: سعودي | AM8: أنثى | AN8: 0 | AO8: 20 | AP8: 50 | AQ8: =SUM(AN8:AP8) -> 70 | AR8: 0 | AU8: سعودي | AV8: أنثى | AW8: 0 | AX8: 6 | AY8: 46 | AZ8: =SUM(AW8:AY8) -> 52 | BA8: 0 | BD8: سعودي | BE8: أنثى | BF8: 0 | BG8: 0 | BH8: 0 | BI8: 0 | BJ8: 0 | BM8: سعودي | BN8: أنثى | BO8: 0 | BP8: 15 | BQ8: 61 | BR8: =SUM(BO8:BQ8) -> 76 | BS8: 0 | BV8: سعودي | BW8: أنثى | BX8: 0 | BY8: 0 | BZ8: 0 | CA8: =SUM(BX8:BZ8) -> 0 | CB8: 0 | CE8: سعودي | CF8: أنثى | CG8: 0 | CH8: 0 | CI8: 2 | CJ8: =SUM(CG8:CI8) -> 2 | CK8: 0 | CN8: سعودي | CO8: أنثى | CP8: 0 | CQ8: 0 | CR8: 0 | CS8: =SUM(CP8:CR8) -> 0 | CT8: 0 | CW8: سعودي | CX8: أنثى | CY8: 0 | CZ8: 0 | DA8: 0 | DB8: =SUM(CY8:DA8) -> 0 | DC8: 0 | DF8: سعودي | DG8: أنثى | DH8: =D8+M8+V8+AE8+AN8+AW8+BF8+BO8+BX8+CG8+CP8+CY8 -> 0 | DI8: =E8+N8+W8+AF8+AO8+AX8+BG8+BP8+BY8+CH8+CQ8+CZ8 -> 117 | DJ8: =F8+O8+X8+AG8+AP8+AY8+BH8+BQ8+BZ8+CI8+CR8+DA8 -> 303 | DK8: =SUM(DH8:DJ8) -> 420 | DL8: =H8+Q8+Z8+AI8+AR8+BA8+BJ8+BS8+CB8+CK8+CT8+DC8 -> 0
B9: المجموع | D9: 0 | E9: 0 | F9: 33 | G9: =SUM(G5:G8) -> 704 | H9: =SUM(H5:H8) -> 0 | K9: المجموع | M9: 0 | N9: 0 | O9: 0 | P9: 0 | Q9: =SUM(Q5:Q8) -> 0 | T9: المجموع | V9: 0 | W9: 28 | X9: 30 | Y9: =SUM(Y5:Y8) -> 772 | Z9: =SUM(Z5:Z8) -> 0 | AC9: المجموع | AE9: 0 | AF9: 35 | AG9: 89 | AH9: =SUM(AH5:AH8) -> 735 | AI9: =SUM(AI5:AI8) -> 0 | AL9: المجموع | AN9: =SUM(AN5:AN8) -> 0 | AO9: =SUM(AO5:AO8) -> 144 | AP9: =SUM(AP5:AP8) -> 693 | AQ9: =SUM(AQ5:AQ8) -> 837 | AR9: =SUM(AR5:AR8) -> 0 | AU9: المجموع | AW9: =SUM(AW5:AW8) -> 0 | AX9: =SUM(AX5:AX8) -> 90 | AY9: =SUM(AY5:AY8) -> 861 | AZ9: =SUM(AZ5:AZ8) -> 951 | BA9: =SUM(BA5:BA8) -> 0 | BD9: المجموع | BF9: 0 | BG9: 0 | BH9: 0 | BI9: 0 | BJ9: =SUM(BJ5:BJ8) -> 0 | BM9: المجموع | BO9: =SUM(BO5:BO8) -> 0 | BP9: =SUM(BP5:BP8) -> 148 | BQ9: =SUM(BQ5:BQ8) -> 431 | BR9: =SUM(BR5:BR8) -> 579 | BS9: =SUM(BS5:BS8) -> 0 | BV9: المجموع | BX9: =SUM(BX5:BX8) -> 0 | BY9: =SUM(BY5:BY8) -> 22 | BZ9: =SUM(BZ5:BZ8) -> 562 | CA9: =SUM(CA5:CA8) -> 584 | CB9: =SUM(CB5:CB8) -> 0 | CE9: المجموع | CG9: =SUM(CG5:CG8) -> 0 | CH9: =SUM(CH5:CH8) -> 13 | CI9: =SUM(CI5:CI8) -> 690 | CJ9: =SUM(CJ5:CJ8) -> 703 | CK9: =SUM(CK5:CK8) -> 0 | CN9: المجموع | CP9: =SUM(CP5:CP8) -> 0 | CQ9: =SUM(CQ5:CQ8) -> 0 | CR9: =SUM(CR5:CR8) -> 0 | CS9: =SUM(CS5:CS8) -> 0 | CT9: =SUM(CT5:CT8) -> 0 | CW9: المجموع | CY9: =SUM(CY5:CY8) -> 0 | CZ9: =SUM(CZ5:CZ8) -> 0 | DA9: =SUM(DA5:DA8) -> 0 | DB9: =SUM(DB5:DB8) -> 0 | DC9: =SUM(DC5:DC8) -> 0 | DF9: المجموع | DH9: =SUM(DH5:DH8) -> 0 | DI9: =SUM(DI5:DI8) -> 897 | DJ9: =SUM(DJ5:DJ8) -> 6438 | DK9: =SUM(DK5:DK8) -> 7335 | DL9: =SUM(DL5:DL8) -> 0
A10: الجامعة | B10: سعودي | C10: ذكر | D10: 0 | E10: 2 | F10: 128 | G10: =SUM(D10:F10) -> 130 | H10: 0 | J10: الجامعة | K10: سعودي | L10: ذكر | M10: 0 | N10: 8 | O10: 104 | P10: 112 | Q10: 0 | S10: الجامعة | T10: سعودي | U10: ذكر | V10: 0 | W10: 290 | X10: 540 | Y10: =SUM(V10:X10) -> 830 | Z10: 0 | AB10: الجامعة | AC10: سعودي | AD10: ذكر | AE10: 0 | AF10: 193 | AG10: 666 | AH10: =SUM(AE10:AG10) -> 859 | AI10: 0 | AK10: الجامعة | AL10: سعودي | AM10: ذكر | AN10: 0 | AO10: 11 | AP10: 266 | AQ10: =SUM(AN10:AP10) -> 277 | AR10: 0 | AT10: الجامعة | AU10: سعودي | AV10: ذكر | AW10: 0 | AX10: 8 | AY10: 399 | AZ10: =SUM(AW10:AY10) -> 407 | BA10: 0 | BC10: الجامعة | BD10: سعودي | BE10: ذكر | BF10: 0 | BG10: 26 | BH10: 725 | BI10: 751 | BJ10: 0 | BL10: الجامعة | BM10: سعودي | BN10: ذكر | BO10: 2 | BP10: 55 | BQ10: 325 | BR10: 382 | BS10: 0 | BU10: الجامعة | BV10: سعودي | BW10: ذكر | BX10: 0 | BY10: 19 | BZ10: 146 | CA10: =SUM(BX10:BZ10) -> 165 | CB10: 0 | CD10: الجامعة | CE10: سعودي | CF10: ذكر | CG10: 0 | CH10: 0 | CI10: 0 | CJ10: 0 | CK10: 0 | CM10: الجامعة | CN10: سعودي | CO10: ذكر | CP10: 0 | CQ10: 0 | CR10: 0 | CS10: =SUM(CP10:CR10) -> 0 | CT10: 0 | CV10: الجامعة | CW10: سعودي | CX10: ذكر | CY10: 0 | CZ10: 0 | DA10: 0 | DB10: =SUM(CY10:DA10) -> 0 | DC10: 0 | DE10: =CV10 -> الجامعة | DG10: ذكر | DH10: =D10+M10+V10+AE10+AN10+AW10+BF10+BO10+BX10+CG10+CP10+CY10 -> 2 | DI10: =E10+N10+W10+AF10+AO10+AX10+BG10+BP10+BY10+CH10+CQ10+CZ10 -> 612 | DJ10: =F10+O10+X10+AG10+AP10+AY10+BH10+BQ10+BZ10+CI10+CR10+DA10 -> 3299 | DK10: =SUM(DH10:DJ10) -> 3913 | DL10: =H10+Q10+Z10+AI10+AR10+BA10+BJ10+BS10+CB10+CK10+CT10+DC10 -> 0
C11: أنثى | D11: 0 | E11: 5 | F11: 201 | G11: =SUM(D11:F11) -> 206 | H11: 0 | L11: أنثى | M11: 0 | N11: 16 | O11: 225 | P11: 241 | Q11: 0 | U11: أنثى | V11: 1 | W11: 35 | X11: 332 | Y11: =SUM(V11:X11) -> 368 | Z11: 0 | AD11: أنثى | AE11: 0 | AF11: 2 | AG11: 263 | AH11: =SUM(AE11:AG11) -> 265 | AI11: 0 | AM11: أنثى | AN11: 0 | AO11: 4 | AP11: 185 | AQ11: =SUM(AN11:AP11) -> 189 | AR11: 0 | AV11: أنثى | AW11: 0 | AX11: 0 | AY11: 212 | AZ11: =SUM(AW11:AY11) -> 212 | BA11: 0 | BE11: أنثى | BF11: 0 | BG11: 10 | BH11: 232 | BI11: 242 | BJ11: 0 | BN11: أنثى | BO11: 3 | BP11: 20 | BQ11: 359 | BR11: 382 | BS11: 0 | BW11: أنثى | BX11: 0 | BY11: 21 | BZ11: 112 | CA11: =SUM(BX11:BZ11) -> 133 | CB11: 0 | CF11: أنثى | CG11: 0 | CH11: 0 | CI11: 0 | CJ11: 0 | CK11: 0 | CO11: أنثى | CP11: 0 | CQ11: 0 | CR11: 0 | CS11: =SUM(CP11:CR11) -> 0 | CT11: 0 | CX11: أنثى | CY11: 0 | CZ11: 0 | DA11: 0 | DB11: =SUM(CY11:DA11) -> 0 | DC11: 0 | DF11: سعودي | DG11: أنثى | DH11: =D11+M11+V11+AE11+AN11+AW11+BF11+BO11+BX11+CG11+CP11+CY11 -> 4 | DI11: =E11+N11+W11+AF11+AO11+AX11+BG11+BP11+BY11+CH11+CQ11+CZ11 -> 113 | DJ11: =F11+O11+X11+AG11+AP11+AY11+BH11+BQ11+BZ11+CI11+CR11+DA11 -> 2121 | DK11: =SUM(DH11:DJ11) -> 2238 | DL11: =H11+Q11+Z11+AI11+AR11+BA11+BJ11+BS11+CB11+CK11+CT11+DC11 -> 0
B12: غير | C12: ذكر | D12: 0 | E12: 0 | F12: 14 | G12: =SUM(D12:F12) -> 14 | H12: 0 | K12: غير | L12: ذكر | M12: 0 | N12: 2 | O12: 3 | P12: 5 | Q12: 0 | T12: غير | U12: ذكر | V12: 1 | W12: 42 | X12: 421 | Y12: =SUM(V12:X12) -> 464 | Z12: 0 | AC12: غير | AD12: ذكر | AE12: 0 | AF12: 9 | AG12: 192 | AH12: =SUM(AE12:AG12) -> 201 | AI12: 0 | AL12: غير | AM12: ذكر | AN12: 0 | AO12: 0 | AP12: 90 | AQ12: =SUM(AN12:AP12) -> 90 | AR12: 0 | AU12: غير | AV12: ذكر | AW12: 0 | AX12: 0 | AY12: 80 | AZ12: =SUM(AW12:AY12) -> 80 | BA12: 0 | BD12: غير | BE12: ذكر | BF12: 0 | BG12: 9 | BH12: 305 | BI12: 314 | BJ12: 0 | BM12: غير | BN12: ذكر | BO12: 0 | BP12: 0 | BQ12: 125 | BR12: 125 | BS12: 0 | BV12: غير | BW12: ذكر | BX12: 0 | BY12: 4 | BZ12: 13 | CA12: =SUM(BX12:BZ12) -> 17 | CB12: 0 | CE12: غير | CF12: ذكر | CG12: 0 | CH12: 0 | CI12: 0 | CJ12: 0 | CK12: 0 | CN12: غير | CO12: ذكر | CP12: 0 | CQ12: 0 | CR12: 0 | CS12: =SUM(CP12:CR12) -> 0 | CT12: 0 | CW12: غير | CX12: ذكر | CY12: 0 | CZ12: 0 | DA12: 0 | DB12: =SUM(CY12:DA12) -> 0 | DC12: 0 | DF12: غير | DG12: ذكر | DH12: =D12+M12+V12+AE12+AN12+AW12+BF12+BO12+BX12+CG12+CP12+CY12 -> 1 | DI12: =E12+N12+W12+AF12+AO12+AX12+BG12+BP12+BY12+CH12+CQ12+CZ12 -> 66 | DJ12: =F12+O12+X12+AG12+AP12+AY12+BH12+BQ12+BZ12+CI12+CR12+DA12 -> 1243 | DK12: =SUM(DH12:DJ12) -> 1310 | DL12: =H12+Q12+Z12+AI12+AR12+BA12+BJ12+BS12+CB12+CK12+CT12+DC12 -> 0
B13: سعودي | C13: أنثى | D13: 0 | E13: 1 | F13: 5 | G13: =SUM(D13:F13) -> 6 | H13: 0 | K13: سعودي | L13: أنثى | M13: 0 | N13: 0 | O13: 7 | P13: 7 | Q13: 0 | T13: سعودي | U13: أنثى | V13: 0 | W13: 5 | X13: 21 | Y13: =SUM(V13:X13) -> 26 | Z13: 0 | AC13: سعودي | AD13: أنثى | AE13: 0 | AF13: 0 | AG13: 5 | AH13: =SUM(AE13:AG13) -> 5 | AI13: 0 | AL13: سعودي | AM13: أنثى | AN13: 0 | AO13: 0 | AP13: 56 | AQ13: =SUM(AN13:AP13) -> 56 | AR13: 0 | AU13: سعودي | AV13: أنثى | AW13: 0 | AX13: 0 | AY13: 44 | AZ13: =SUM(AW13:AY13) -> 44 | BA13: 0 | BD13: سعودي | BE13: أنثى | BF13: 0 | BG13: 0 | BH13: 5 | BI13: 5 | BJ13: 0 | BM13: سعودي | BN13: أنثى | BO13: 0 | BP13: 0 | BQ13: 235 | BR13: 235 | BS13: 0 | BV13: سعودي | BW13: أنثى | BX13: 0 | BY13: 3 | BZ13: 9 | CA13: =SUM(BX13:BZ13) -> 12 | CB13: 0 | CE13: سعودي | CF13: أنثى | CG13: 0 | CH13: 0 | CI13: 0 | CJ13: 0 | CK13: 0 | CN13: سعودي | CO13: أنثى | CP13: 0 | CQ13: 0 | CR13: 0 | CS13: =SUM(CP13:CR13) -> 0 | CT13: 0 | CW13: سعودي | CX13: أنثى | CY13: 0 | CZ13: 0 | DA13: 0 | DB13: =SUM(CY13:DA13) -> 0 | DC13: 0 | DF13: سعودي | DG13: أنثى | DH13: =D13+M13+V13+AE13+AN13+AW13+BF13+BO13+BX13+CG13+CP13+CY13 -> 0 | DI13: =E13+N13+W13+AF13+AO13+AX13+BG13+BP13+BY13+CH13+CQ13+CZ13 -> 9 | DJ13: =F13+O13+X13+AG13+AP13+AY13+BH13+BQ13+BZ13+CI13+CR13+DA13 -> 387 | DK13: =SUM(DH13:DJ13) -> 396 | DL13: =H13+Q13+Z13+AI13+AR13+BA13+BJ13+BS13+CB13+CK13+CT13+DC13 -> 0
B14: المجموع | D14: =SUM(D10:D13) -> 0 | E14: =SUM(E10:E13) -> 8 | F14: =SUM(F10:F13) -> 348 | G14: =SUM(G10:G13) -> 356 | H14: =SUM(H10:H13) -> 0 | K14: المجموع | M14: =SUM(M10:M13) -> 0 | N14: =SUM(N10:N13) -> 26 | O14: =SUM(O10:O13) -> 339 | P14: =SUM(P10:P13) -> 365 | Q14: =SUM(Q10:Q13) -> 0 | T14: المجموع | V14: 0 | W14: 1 | X14: 22 | Y14: =SUM(Y10:Y13) -> 1688 | Z14: =SUM(Z10:Z13) -> 0 | AC14: المجموع | AE14: 0 | AF14: 0 | AG14: 9 | AH14: =SUM(AH10:AH13) -> 1330 | AI14: =SUM(AI10:AI13) -> 0 | AL14: المجموع | AN14: =SUM(AN10:AN13) -> 0 | AO14: =SUM(AO10:AO13) -> 15 | AP14: =SUM(AP10:AP13) -> 597 | AQ14: =SUM(AQ10:AQ13) -> 612 | AR14: =SUM(AR10:AR13) -> 0 | AU14: المجموع | AW14: =SUM(AW10:AW13) -> 0 | AX14: =SUM(AX10:AX13) -> 8 | AY14: =SUM(AY10:AY13) -> 735 | AZ14: =SUM(AZ10:AZ13) -> 743 | BA14: =SUM(BA10:BA13) -> 0 | BD14: المجموع | BF14: 0 | BG14: 0 | BH14: 7 | BI14: 7 | BJ14: =SUM(BJ10:BJ13) -> 0 | BM14: المجموع | BO14: =SUM(BO10:BO13) -> 5 | BP14: =SUM(BP10:BP13) -> 75 | BQ14: =SUM(BQ10:BQ13) -> 1044 | BR14: =SUM(BR10:BR13) -> 1124 | BS14: =SUM(BS10:BS13) -> 0 | BV14: المجموع | BX14: =SUM(BX10:BX13) -> 0 | BY14: =SUM(BY10:BY13) -> 47 | BZ14: =SUM(BZ10:BZ13) -> 280 | CA14: =SUM(CA10:CA13) -> 327 | CB14: =SUM(CB10:CB13) -> 0 | CE14: المجموع | CN14: المجموع | CP14: =SUM(CP10:CP13) -> 0 | CQ14: =SUM(CQ10:CQ13) -> 0 | CR14: =SUM(CR10:CR13) -> 0 | CS14: =SUM(CS10:CS13) -> 0 | CT14: =SUM(CT10:CT13) -> 0 | CW14: المجموع | CY14: =SUM(CY10:CY13) -> 0 | CZ14: =SUM(CZ10:CZ13) -> 0 | DA14: =SUM(DA10:DA13) -> 0 | DB14: =SUM(DB10:DB13) -> 0 | DC14: =SUM(DC10:DC13) -> 0 | DF14: المجموع | DH14: =SUM(DH10:DH13) -> 7 | DI14: =SUM(DI10:DI13) -> 800 | DJ14: =SUM(DJ10:DJ13) -> 7050 | DK14: =SUM(DK10:DK13) -> 7857 | DL14: =SUM(DL10:DL13) -> 0
A15: السليمانية | B15: سعودي | C15: ذكر | D15: 0 | E15: 166 | F15: 211 | G15: =SUM(D15:F15) -> 377 | H15: 0 | J15: السليمانية | K15: سعودي | L15: ذكر | M15: 0 | N15: 210 | O15: 376 | P15: =SUM(M15:O15) -> 586 | Q15: 0 | S15: السليمانية | T15: سعودي | U15: ذكر | V15: 2 | W15: 83 | X15: 796 | Y15: =SUM(V15:X15) -> 881 | Z15: 0 | AB15: السليمانية | AC15: سعودي | AD15: ذكر | AE15: 0 | AF15: 11 | AG15: 469 | AH15: =SUM(AE15:AG15) -> 480 | AI15: 0 | AK15: السليمانية | AL15: سعودي | AM15: ذكر | AN15: 0 | AO15: 33 | AP15: 433 | AQ15: =SUM(AN15:AP15) -> 466 | AR15: 0 | AT15: السليمانية | AU15: سعودي | AV15: ذكر | AW15: 0 | AX15: 40 | AY15: 495 | AZ15: =SUM(AW15:AY15) -> 535 | BA15: 0 | BC15: السليمانية | BD15: سعودي | BE15: ذكر | BF15: 0 | BG15: 19 | BH15: 549 | BI15: 568 | BJ15: 0 | BL15: السليمانية | BM15: سعودي | BN15: ذكر | BO15: 0 | BP15: 26 | BQ15: 179 | BR15: =SUM(BO15:BQ15) -> 205 | BS15: 0 | BU15: السليمانية | BV15: سعودي | BW15: ذكر | BX15: 0 | BY15: 7 | BZ15: 456 | CA15: =SUM(BX15:BZ15) -> 463 | CB15: 0 | CD15: السليمانية | CE15: سعودي | CF15: ذكر | CG15: 0 | CH15: 15 | CI15: 560 | CJ15: =SUM(CG15:CI15) -> 575 | CK15: 0 | CM15: السليمانية | CN15: سعودي | CO15: ذكر | CP15: 0 | CQ15: 0 | CR15: 0 | CS15: =SUM(CP15:CR15) -> 0 | CT15: 0 | CV15: السليمانية | CW15: سعودي | CX15: ذكر | CY15: 0 | CZ15: 0 | DA15: 0 | DB15: =SUM(CY15:DA15) -> 0 | DC15: 0 | DE15: =CV15 -> السليمانية | DG15: ذكر | DH15: =D15+M15+V15+AE15+AN15+AW15+BF15+BO15+BX15+CG15+CP15+CY15 -> 2 | DI15: =E15+N15+W15+AF15+AO15+AX15+BG15+BP15+BY15+CH15+CQ15+CZ15 -> 610 | DJ15: =F15+O15+X15+AG15+AP15+AY15+BH15+BQ15+BZ15+CI15+CR15+DA15 -> 4524 | DK15: =SUM(DH15:DJ15) -> 5136 | DL15: =H15+Q15+Z15+AI15+AR15+BA15+BJ15+BS15+CB15+CK15+CT15+DC15 -> 0
C16: أنثى | D16: 0 | E16: 101 | F16: 241 | G16: =SUM(D16:F16) -> 342 | H16: 0 | L16: أنثى | M16: 0 | N16: 190 | O16: 410 | P16: =SUM(M16:O16) -> 600 | Q16: 0 | U16: أنثى | V16: 0 | W16: 99 | X16: 158 | Y16: =SUM(V16:X16) -> 257 | Z16: 0 | AD16: أنثى | AE16: 0 | AF16: 26 | AG16: 189 | AH16: =SUM(AE16:AG16) -> 215 | AI16: 0 | AM16: أنثى | AN16: 0 | AO16: 25 | AP16: 325 | AQ16: =SUM(AN16:AP16) -> 350 | AR16: 0 | AV16: أنثى | AW16: 0 | AX16: 22 | AY16: 322 | AZ16: =SUM(AW16:AY16) -> 344 | BA16: 0 | BE16: أنثى | BF16: 0 | BG16: 198 | BH16: 231 | BI16: 429 | BJ16: 0 | BN16: أنثى | BO16: 0 | BP16: 44 | BQ16: 155 | BR16: =SUM(BO16:BQ16) -> 199 | BS16: 0 | BW16: أنثى | BX16: 0 | BY16: 2 | BZ16: 341 | CA16: =SUM(BX16:BZ16) -> 343 | CB16: 0 | CF16: أنثى | CG16: 0 | CH16: 4 | CI16: 419 | CJ16: =SUM(CG16:CI16) -> 423 | CK16: 0 | CO16: أنثى | CP16: 0 | CQ16: 0 | CR16: 0 | CS16: =SUM(CP16:CR16) -> 0 | CT16: 0 | CX16: أنثى | CY16: 0 | CZ16: 0 | DA16: 0 | DB16: =SUM(CY16:DA16) -> 0 | DC16: 0 | DF16: سعودي | DG16: أنثى | DH16: =D16+M16+V16+AE16+AN16+AW16+BF16+BO16+BX16+CG16+CP16+CY16 -> 0 | DI16: =E16+N16+W16+AF16+AO16+AX16+BG16+BP16+BY16+CH16+CQ16+CZ16 -> 711 | DJ16: =F16+O16+X16+AG16+AP16+AY16+BH16+BQ16+BZ16+CI16+CR16+DA16 -> 2791 | DK16: =SUM(DH16:DJ16) -> 3502 | DL16: =H16+Q16+Z16+AI16+AR16+BA16+BJ16+BS16+CB16+CK16+CT16+DC16 -> 0
B17: غير | C17: ذكر | D17: 0 | E17: 75 | F17: 155 | G17: =SUM(D17:F17) -> 230 | H17: 0 | K17: غير | L17: ذكر | M17: 0 | N17: 52 | O17: 58 | P17: =SUM(M17:O17) -> 110 | Q17: 0 | T17: غير | U17: ذكر | V17: 0 | W17: 158 | X17: 202 | Y17: =SUM(V17:X17) -> 360 | Z17: 0 | AC17: غير | AD17: ذكر | AE17: 0 | AF17: 27 | AG17: 200 | AH17: =SUM(AE17:AG17) -> 227 | AI17: 0 | AL17: غير | AM17: ذكر | AN17: 0 | AO17: 0 | AP17: 106 | AQ17: =SUM(AN17:AP17) -> 106 | AR17: 0 | AU17: غير | AV17: ذكر | AW17: 0 | AX17: 0 | AY17: 110 | AZ17: =SUM(AW17:AY17) -> 110 | BA17: 0 | BD17: غير | BE17: ذكر | BF17: 0 | BG17: 140 | BH17: 150 | BI17: 290 | BJ17: 0 | BM17: غير | BN17: ذكر | BO17: 0 | BP17: 9 | BQ17: 25 | BR17: =SUM(BO17:BQ17) -> 34 | BS17: 0 | BV17: غير | BW17: ذكر | BX17: 0 | BY17: 2 | BZ17: 55 | CA17: =SUM(BX17:BZ17) -> 57 | CB17: 0 | CE17: غير | CF17: ذكر | CG17: 0 | CH17: 0 | CI17: 60 | CJ17: =SUM(CG17:CI17) -> 60 | CK17: 0 | CN17: غير | CO17: ذكر | CP17: 0 | CQ17: 0 | CR17: 0 | CS17: =SUM(CP17:CR17) -> 0 | CT17: 0 | CW17: غير | CX17: ذكر | CY17: 0 | CZ17: 0 | DA17: 0 | DB17: =SUM(CY17:DA17) -> 0 | DC17: 0 | DF17: غير | DG17: ذكر | DH17: =D17+M17+V17+AE17+AN17+AW17+BF17+BO17+BX17+CG17+CP17+CY17 -> 0 | DI17: =E17+N17+W17+AF17+AO17+AX17+BG17+BP17+BY17+CH17+CQ17+CZ17 -> 463 | DJ17: =F17+O17+X17+AG17+AP17+AY17+BH17+BQ17+BZ17+CI17+CR17+DA17 -> 1121 | DK17: =SUM(DH17:DJ17) -> 1584 | DL17: =H17+Q17+Z17+AI17+AR17+BA17+BJ17+BS17+CB17+CK17+CT17+DC17 -> 0
B18: سعودي | C18: أنثى | D18: 0 | E18: 61 | F18: 108 | G18: =SUM(D18:F18) -> 169 | H18: 0 | K18: سعودي | L18: أنثى | M18: 0 | N18: 16 | O18: 64 | P18: =SUM(M18:O18) -> 80 | Q18: 0 | T18: سعودي | U18: أنثى | V18: 0 | W18: 6 | X18: 33 | Y18: =SUM(V18:X18) -> 39 | Z18: 0 | AC18: سعودي | AD18: أنثى | AH18: =SUM(AE18:AG18) -> 0 | AI18: 0 | AL18: سعودي | AM18: أنثى | AN18: 0 | AO18: 0 | AP18: 45 | AQ18: =SUM(AN18:AP18) -> 45 | AR18: 0 | AU18: سعودي | AV18: أنثى | AW18: 0 | AX18: 0 | AY18: 37 | AZ18: =SUM(AW18:AY18) -> 37 | BA18: 0 | BD18: سعودي | BE18: أنثى | BF18: 0 | BG18: 105 | BH18: 104 | BI18: 209 | BJ18: 0 | BM18: سعودي | BN18: أنثى | BO18: 0 | BP18: 10 | BQ18: 43 | BR18: =SUM(BO18:BQ18) -> 53 | BS18: 0 | BV18: سعودي | BW18: أنثى | BX18: 0 | BY18: 0 | BZ18: 48 | CA18: =SUM(BX18:BZ18) -> 48 | CB18: 0 | CE18: سعودي | CF18: أنثى | CG18: 0 | CH18: 0 | CI18: 22 | CJ18: =SUM(CG18:CI18) -> 22 | CK18: 0 | CN18: سعودي | CO18: أنثى | CP18: 0 | CQ18: 0 | CR18: 0 | CS18: =SUM(CP18:CR18) -> 0 | CT18: 0 | CW18: سعودي | CX18: أنثى | CY18: 0 | CZ18: 0 | DA18: 0 | DB18: =SUM(CY18:DA18) -> 0 | DC18: 0 | DF18: سعودي | DG18: أنثى | DH18: =D18+M18+V18+AE18+AN18+AW18+BF18+BO18+BX18+CG18+CP18+CY18 -> 0 | DI18: =E18+N18+W18+AF18+AO18+AX18+BG18+BP18+BY18+CH18+CQ18+CZ18 -> 198 | DJ18: =F18+O18+X18+AG18+AP18+AY18+BH18+BQ18+BZ18+CI18+CR18+DA18 -> 504 | DK18: =SUM(DH18:DJ18) -> 702 | DL18: =H18+Q18+Z18+AI18+AR18+BA18+BJ18+BS18+CB18+CK18+CT18+DC18 -> 0
B19: المجموع | D19: =SUM(D15:D18) -> 0 | E19: =SUM(E15:E18) -> 403 | F19: =SUM(F15:F18) -> 715 | G19: =SUM(G15:G18) -> 1118 | H19: =SUM(H15:H18) -> 0 | K19: المجموع | M19: =SUM(M15:M18) -> 0 | N19: =SUM(N15:N18) -> 468 | O19: =SUM(O15:O18) -> 908 | P19: =SUM(P15:P18) -> 1376 | Q19: =SUM(Q15:Q18) -> 0 | T19: المجموع | V19: 0 | W19: 5 | X19: 25 | Y19: =SUM(Y15:Y18) -> 1537 | Z19: =SUM(Z15:Z18) -> 0 | AC19: المجموع | AE19: 0 | AF19: 5 | AG19: 45 | AH19: =SUM(AH15:AH18) -> 922 | AI19: =SUM(AI15:AI18) -> 0 | AL19: المجموع | AN19: =SUM(AN15:AN18) -> 0 | AO19: =SUM(AO15:AO18) -> 58 | AP19: =SUM(AP15:AP18) -> 909 | AQ19: =SUM(AQ15:AQ18) -> 967 | AR19: =SUM(AR15:AR18) -> 0 | AU19: المجموع | AW19: =SUM(AW15:AW18) -> 0 | AX19: =SUM(AX15:AX18) -> 62 | AY19: =SUM(AY15:AY18) -> 964 | AZ19: =SUM(AZ15:AZ18) -> 1026 | BA19: =SUM(BA15:BA18) -> 0 | BD19: المجموع | BF19: 0 | BG19: 289 | BH19: 102 | BI19: 391 | BJ19: =SUM(BJ15:BJ18) -> 0 | BM19: المجموع | BO19: =SUM(BO15:BO18) -> 0 | BP19: =SUM(BP15:BP18) -> 89 | BQ19: =SUM(BQ15:BQ18) -> 402 | BR19: =SUM(BR15:BR18) -> 491 | BS19: =SUM(BS15:BS18) -> 0 | BV19: المجموع | BX19: =SUM(BX15:BX18) -> 0 | BY19: =SUM(BY15:BY18) -> 11 | BZ19: =SUM(BZ15:BZ18) -> 900 | CA19: 959 | CB19: =SUM(CB15:CB18) -> 0 | CE19: المجموع | CG19: =SUM(CG15:CG18) -> 0 | CH19: =SUM(CH15:CH18) -> 19 | CI19: =SUM(CI15:CI18) -> 1061 | CJ19: 959 | CK19: =SUM(CK15:CK18) -> 0 | CN19: المجموع | CP19: =SUM(CP15:CP18) -> 0 | CQ19: =SUM(CQ15:CQ18) -> 0 | CR19: =SUM(CR15:CR18) -> 0 | CS19: =SUM(CS15:CS18) -> 0 | CT19: =SUM(CT15:CT18) -> 0 | CW19: المجموع | CY19: =SUM(CY15:CY18) -> 0 | CZ19: =SUM(CZ15:CZ18) -> 0 | DA19: =SUM(DA15:DA18) -> 0 | DB19: =SUM(DB15:DB18) -> 0 | DC19: =SUM(DC15:DC18) -> 0 | DF19: المجموع | DH19: =SUM(DH15:DH18) -> 2 | DI19: =SUM(DI15:DI18) -> 1982 | DJ19: =SUM(DJ15:DJ18) -> 8940 | DK19: =SUM(DK15:DK18) -> 10924 | DL19: =SUM(DL15:DL18) -> 0
A20: المطار القديم | B20: سعودي | C20: ذكر | D20: 0 | E20: 9 | F20: 240 | G20: =SUM(D20:F20) -> 249 | H20: 0 | J20: المطار القديم | K20: سعودي | L20: ذكر | M20: 0 | N20: 6 | O20: 272 | P20: =SUM(M20:O20) -> 278 | Q20: 0 | S20: المطار القديم | T20: سعودي | U20: ذكر | V20: 0 | W20: 268 | X20: 418 | Y20: =SUM(V20:X20) -> 686 | Z20: 0 | AB20: المطار القديم | AC20: سعودي | AD20: ذكر | AE20: 0 | AF20: 6 | AG20: 50 | AH20: =SUM(AE20:AG20) -> 56 | AI20: 0 | AK20: المطار القديم | AL20: سعودي | AM20: ذكر | AN20: 0 | AO20: 0 | AP20: 221 | AQ20: =SUM(AN20:AP20) -> 221 | AR20: 0 | AT20: المطار القديم | AU20: سعودي | AV20: ذكر | AW20: 0 | AX20: 0 | AY20: 322 | AZ20: =SUM(AW20:AY20) -> 322 | BA20: 0 | BC20: المطار القديم | BD20: سعودي | BE20: ذكر | BF20: 0 | BG20: 732 | BH20: 587 | BI20: 1319 | BJ20: 0 | BL20: المطار القديم | BM20: سعودي | BN20: ذكر | BO20: 0 | BP20: 29 | BQ20: 190 | BR20: 219 | BS20: 0 | BU20: المطار القديم | BV20: سعودي | BW20: ذكر | BX20: 0 | BY20: 33 | BZ20: 210 | CA20: =SUM(BX20:BZ20) -> 243 | CB20: 0 | CD20: المطار القديم | CE20: سعودي | CF20: ذكر | CG20: 0 | CH20: 0 | CI20: 320 | CJ20: =SUM(CG20:CI20) -> 320 | CK20: 0 | CM20: المطار القديم | CN20: سعودي | CO20: ذكر | CP20: 0 | CQ20: 0 | CR20: 0 | CS20: =SUM(CP20:CR20) -> 0 | CT20: 0 | CV20: المطار القديم | CW20: سعودي | CX20: ذكر | CY20: 0 | CZ20: 0 | DA20: 0 | DB20: =SUM(CY20:DA20) -> 0 | DC20: 0 | DE20: =CV20 -> المطار القديم | DG20: ذكر | DH20: =D20+M20+V20+AE20+AN20+AW20+BF20+BO20+BX20+CG20+CP20+CY20 -> 0 | DI20: =E20+N20+W20+AF20+AO20+AX20+BG20+BP20+BY20+CH20+CQ20+CZ20 -> 1083 | DJ20: =F20+O20+X20+AG20+AP20+AY20+BH20+BQ20+BZ20+CI20+CR20+DA20 -> 2830 | DK20: =SUM(DH20:DJ20) -> 3913 | DL20: =H20+Q20+Z20+AI20+AR20+BA20+BJ20+BS20+CB20+CK20+CT20+DC20 -> 0
C21: أنثى | D21: 0 | E21: 7 | F21: 219 | G21: =SUM(D21:F21) -> 226 | H21: 0 | L21: أنثى | M21: 0 | N21: 4 | O21: 300 | P21: =SUM(M21:O21) -> 304 | Q21: 0 | U21: أنثى | V21: 0 | W21: 8 | X21: 321 | Y21: =SUM(V21:X21) -> 329 | Z21: 0 | AD21: أنثى | AE21: 0 | AF21: 0 | AG21: 0 | AH21: =SUM(AE21:AG21) -> 0 | AI21: 0 | AM21: أنثى | AN21: 0 | AO21: 0 | AP21: 79 | AQ21: =SUM(AN21:AP21) -> 79 | AR21: 0 | AV21: أنثى | AW21: 0 | AX21: 0 | AY21: 95 | AZ21: =SUM(AW21:AY21) -> 95 | BA21: 0 | BE21: أنثى | BF21: 0 | BG21: 12 | BH21: 222 | BI21: 234 | BJ21: 0 | BN21: أنثى | BO21: 0 | BP21: 16 | BQ21: 197 | BR21: 213 | BS21: 0 | BW21: أنثى | BX21: 0 | BY21: 22 | BZ21: 169 | CA21: =SUM(BX21:BZ21) -> 191 | CB21: 0 | CF21: أنثى | CG21: 0 | CH21: 0 | CI21: 155 | CJ21: =SUM(CG21:CI21) -> 155 | CK21: 0 | CO21: أنثى | CP21: 0 | CQ21: 0 | CR21: 0 | CS21: =SUM(CP21:CR21) -> 0 | CT21: 0 | CX21: أنثى | CY21: 0 | CZ21: 0 | DA21: 0 | DB21: =SUM(CY21:DA21) -> 0 | DC21: 0 | DF21: سعودي | DG21: أنثى | DH21: =D21+M21+V21+AE21+AN21+AW21+BF21+BO21+BX21+CG21+CP21+CY21 -> 0 | DI21: =E21+N21+W21+AF21+AO21+AX21+BG21+BP21+BY21+CH21+CQ21+CZ21 -> 69 | DJ21: =F21+O21+X21+AG21+AP21+AY21+BH21+BQ21+BZ21+CI21+CR21+DA21 -> 1757 | DK21: =SUM(DH21:DJ21) -> 1826 | DL21: =H21+Q21+Z21+AI21+AR21+BA21+BJ21+BS21+CB21+CK21+CT21+DC21 -> 0
B22: غير | C22: ذكر | D22: 0 | E22: 2 | F22: 19 | G22: =SUM(D22:F22) -> 21 | H22: 0 | K22: غير | L22: ذكر | M22: 0 | N22: 0 | O22: 22 | P22: =SUM(M22:O22) -> 22 | Q22: 0 | T22: غير | U22: ذكر | V22: 0 | W22: 4 | X22: 110 | Y22: =SUM(V22:X22) -> 114 | Z22: 0 | AC22: غير | AD22: ذكر | AE22: 0 | AF22: 0 | AG22: 0 | AH22: =SUM(AE22:AG22) -> 0 | AI22: 0 | AL22: غير | AM22: ذكر | AN22: 0 | AO22: 0 | AP22: 36 | AQ22: =SUM(AN22:AP22) -> 36 | AR22: 0 | AU22: غير | AV22: ذكر | AW22: 0 | AX22: 0 | AY22: 40 | AZ22: =SUM(AW22:AY22) -> 40 | BA22: 0 | BD22: غير | BE22: ذكر | BF22: 0 | BG22: 6 | BH22: 219 | BI22: 225 | BJ22: 0 | BM22: غير | BN22: ذكر | BO22: 0 | BP22: 5 | BQ22: 0 | BR22: 5 | BS22: 0 | BV22: غير | BW22: ذكر | BX22: 0 | BY22: 2 | BZ22: 33 | CA22: =SUM(BX22:BZ22) -> 35 | CB22: 0 | CE22: غير | CF22: ذكر | CG22: 0 | CH22: 0 | CI22: 22 | CJ22: =SUM(CG22:CI22) -> 22 | CK22: 0 | CN22: غير | CO22: ذكر | CP22: 0 | CQ22: 0 | CR22: 0 | CS22: =SUM(CP22:CR22) -> 0 | CT22: 0 | CW22: غير | CX22: ذكر | CY22: 0 | CZ22: 0 | DA22: 0 | DB22: =SUM(CY22:DA22) -> 0 | DC22: 0 | DF22: غير | DG22: ذكر | DH22: =D22+M22+V22+AE22+AN22+AW22+BF22+BO22+BX22+CG22+CP22+CY22 -> 0 | DI22: =E22+N22+W22+AF22+AO22+AX22+BG22+BP22+BY22+CH22+CQ22+CZ22 -> 19 | DJ22: =F22+O22+X22+AG22+AP22+AY22+BH22+BQ22+BZ22+CI22+CR22+DA22 -> 501 | DK22: =SUM(DH22:DJ22) -> 520 | DL22: =H22+Q22+Z22+AI22+AR22+BA22+BJ22+BS22+CB22+CK22+CT22+DC22 -> 0
B23: سعودي | C23: أنثى | D23: 0 | E23: 0 | F23: 6 | G23: =SUM(D23:F23) -> 6 | H23: 0 | K23: سعودي | L23: أنثى | M23: 0 | N23: 1 | O23: 4 | P23: =SUM(M23:O23) -> 5 | Q23: 0 | T23: سعودي | U23: أنثى | V23: 0 | W23: 0 | X23: 0 | Y23: =SUM(V23:X23) -> 0 | Z23: 0 | AC23: سعودي | AD23: أنثى | AE23: 0 | AF23: 0 | AG23: 0 | AH23: =SUM(AE23:AG23) -> 0 | AI23: 0 | AL23: سعودي | AM23: أنثى | AN23: 0 | AO23: 0 | AP23: 41 | AQ23: =SUM(AN23:AP23) -> 41 | AR23: 0 | AU23: سعودي | AV23: أنثى | AW23: 0 | AX23: 0 | AY23: 14 | AZ23: =SUM(AW23:AY23) -> 14 | BA23: 0 | BD23: سعودي | BE23: أنثى | BF23: 0 | BG23: 2 | BH23: 19 | BI23: 21 | BJ23: 0 | BM23: سعودي | BN23: أنثى | BO23: 0 | BP23: 0 | BQ23: 0 | BR23: 0 | BS23: 0 | BV23: سعودي | BW23: أنثى | BX23: 0 | BY23: 1 | BZ23: 26 | CA23: =SUM(BX23:BZ23) -> 27 | CB23: 0 | CE23: سعودي | CF23: أنثى | CG23: 0 | CH23: 0 | CI23: 10 | CJ23: =SUM(CG23:CI23) -> 10 | CK23: 0 | CN23: سعودي | CO23: أنثى | CP23: 0 | CQ23: 0 | CR23: 0 | CS23: =SUM(CP23:CR23) -> 0 | CT23: 0 | CW23: سعودي | CX23: أنثى | CY23: 0 | CZ23: 0 | DA23: 0 | DB23: =SUM(CY23:DA23) -> 0 | DC23: 0 | DF23: سعودي | DG23: أنثى | DH23: =D23+M23+V23+AE23+AN23+AW23+BF23+BO23+BX23+CG23+CP23+CY23 -> 0 | DI23: =E23+N23+W23+AF23+AO23+AX23+BG23+BP23+BY23+CH23+CQ23+CZ23 -> 4 | DJ23: =F23+O23+X23+AG23+AP23+AY23+BH23+BQ23+BZ23+CI23+CR23+DA23 -> 120 | DK23: =SUM(DH23:DJ23) -> 124 | DL23: =H23+Q23+Z23+AI23+AR23+BA23+BJ23+BS23+CB23+CK23+CT23+DC23 -> 0
B24: المجموع | D24: =SUM(D20:D23) -> 0 | E24: =SUM(E20:E23) -> 18 | F24: =SUM(F20:F23) -> 484 | G24: =SUM(G20:G23) -> 502 | H24: =SUM(H20:H23) -> 0 | K24: المجموع | M24: =SUM(M20:M23) -> 0 | N24: =SUM(N20:N23) -> 11 | O24: =SUM(O20:O23) -> 598 | P24: =SUM(P20:P23) -> 609 | Q24: =SUM(Q20:Q23) -> 0 | T24: المجموع | V24: 0 | W24: 0 | X24: 0 | Y24: =SUM(Y20:Y23) -> 1129 | Z24: =SUM(Z20:Z23) -> 0 | AC24: المجموع | AE24: 0 | AF24: 0 | AG24: 0 | AH24: =SUM(AH20:AH23) -> 56 | AI24: =SUM(AI20:AI23) -> 0 | AL24: المجموع | AN24: =SUM(AN20:AN23) -> 0 | AO24: =SUM(AO20:AO23) -> 0 | AP24: =SUM(AP20:AP23) -> 377 | AQ24: =SUM(AQ20:AQ23) -> 377 | AR24: =SUM(AR20:AR23) -> 0 | AU24: المجموع | AW24: =SUM(AW20:AW23) -> 0 | AX24: =SUM(AX20:AX23) -> 0 | AY24: =SUM(AY20:AY23) -> 471 | AZ24: =SUM(AZ20:AZ23) -> 471 | BA24: =SUM(BA20:BA23) -> 0 | BD24: المجموع | BF24: 0 | BG24: 0 | BH24: 6 | BI24: 6 | BJ24: =SUM(BJ20:BJ23) -> 0 | BM24: المجموع | BO24: =SUM(BO20:BO23) -> 0 | BP24: =SUM(BP20:BP23) -> 50 | BQ24: =SUM(BQ20:BQ23) -> 387 | BR24: =SUM(BR20:BR23) -> 437 | BS24: =SUM(BS20:BS23) -> 0 | BV24: المجموع | BX24: =SUM(BX20:BX23) -> 0 | BY24: =SUM(BY20:BY23) -> 58 | BZ24: =SUM(BZ20:BZ23) -> 438 | CA24: =SUM(CA20:CA23) -> 496 | CB24: =SUM(CB20:CB23) -> 0 | CE24: المجموع | CG24: =SUM(CG20:CG23) -> 0 | CH24: =SUM(CH20:CH23) -> 0 | CI24: =SUM(CI20:CI23) -> 507 | CJ24: =SUM(CJ20:CJ23) -> 507 | CK24: =SUM(CK20:CK23) -> 0 | CN24: المجموع | CP24: =SUM(CP20:CP23) -> 0 | CQ24: =SUM(CQ20:CQ23) -> 0 | CR24: =SUM(CR20:CR23) -> 0 | CS24: =SUM(CS20:CS23) -> 0 | CT24: =SUM(CT20:CT23) -> 0 | CW24: المجموع | CY24: =SUM(CY20:CY23) -> 0 | CZ24: =SUM(CZ20:CZ23) -> 0 | DA24: =SUM(DA20:DA23) -> 0 | DB24: =SUM(DB20:DB23) -> 0 | DC24: =SUM(DC20:DC23) -> 0 | DF24: المجموع | DH24: =SUM(DH20:DH23) -> 0 | DI24: =SUM(DI20:DI23) -> 1175 | DJ24: =SUM(DJ20:DJ23) -> 5208 | DK24: =SUM(DK20:DK23) -> 6383 | DL24: =SUM(DL20:DL23) -> 0
A25: الروابي | B25: سعودي | C25: ذكر | D25: 0 | E25: 0 | F25: 0 | G25: =SUM(D25:F25) -> 0 | H25: 0 | J25: الروابي | K25: سعودي | L25: ذكر | M25: 0 | N25: 0 | O25: 0 | P25: =SUM(M25:O25) -> 0 | Q25: 0 | S25: الروابي | T25: سعودي | U25: ذكر | V25: 0 | W25: 0 | X25: 0 | Y25: =SUM(V25:X25) -> 0 | Z25: 0 | AB25: الروابي | AC25: سعودي | AD25: ذكر | AE25: 0 | AF25: 0 | AG25: 0 | AH25: =SUM(AE25:AG25) -> 0 | AI25: 0 | AK25: الروابي | AL25: سعودي | AM25: ذكر | AN25: 0 | AO25: 0 | AP25: 0 | AQ25: =SUM(AN25:AP25) -> 0 | AR25: 0 | AT25: الروابي | AU25: سعودي | AV25: ذكر | AW25: 0 | AX25: 0 | AY25: 0 | AZ25: =SUM(AW25:AY25) -> 0 | BA25: 0 | BC25: الروابي | BD25: سعودي | BE25: ذكر | BF25: 0 | BG25: 20 | BH25: 466 | BI25: 486 | BJ25: 0 | BL25: الروابي | BM25: سعودي | BN25: ذكر | BO25: 0 | BP25: 0 | BQ25: 0 | BR25: =SUM(BO25:BQ25) -> 0 | BS25: 0 | BU25: الروابي | BV25: سعودي | BW25: ذكر | BX25: 0 | BY25: 0 | BZ25: 0 | CA25: =SUM(BX25:BZ25) -> 0 | CB25: 0 | CD25: الروابي | CE25: سعودي | CF25: ذكر | CG25: 0 | CH25: 0 | CI25: 192 | CJ25: =SUM(CG25:CI25) -> 192 | CK25: 0 | CM25: الروابي | CN25: سعودي | CO25: ذكر | CP25: 0 | CQ25: 0 | CR25: 0 | CS25: =SUM(CP25:CR25) -> 0 | CT25: 0 | CV25: الروابي | CW25: سعودي | CX25: ذكر | CY25: 0 | CZ25: 0 | DA25: 0 | DB25: =SUM(CY25:DA25) -> 0 | DC25: 0 | DE25: =CV25 -> الروابي | DG25: ذكر | DH25: =D25+M25+V25+AE25+AN25+AW25+BF25+BO25+BX25+CG25+CP25+CY25 -> 0 | DI25: =E25+N25+W25+AF25+AO25+AX25+BG25+BP25+BY25+CH25+CQ25+CZ25 -> 20 | DJ25: =F25+O25+X25+AG25+AP25+AY25+BH25+BQ25+BZ25+CI25+CR25+DA25 -> 658 | DK25: =SUM(DH25:DJ25) -> 678 | DL25: =H25+Q25+Z25+AI25+AR25+BA25+BJ25+BS25+CB25+CK25+CT25+DC25 -> 0
C26: أنثى | D26: 0 | E26: 0 | F26: 0 | G26: =SUM(D26:F26) -> 0 | H26: 0 | L26: أنثى | M26: 0 | N26: 0 | O26: 0 | P26: =SUM(M26:O26) -> 0 | Q26: 0 | U26: أنثى | V26: 0 | W26: 0 | X26: 0 | Y26: =SUM(V26:X26) -> 0 | Z26: 0 | AD26: أنثى | AE26: 0 | AF26: 0 | AG26: 0 | AH26: =SUM(AE26:AG26) -> 0 | AI26: 0 | AM26: أنثى | AN26: 0 | AO26: 0 | AP26: 0 | AQ26: =SUM(AN26:AP26) -> 0 | AR26: 0 | AV26: أنثى | AW26: 0 | AX26: 0 | AY26: 0 | AZ26: =SUM(AW26:AY26) -> 0 | BA26: 0 | BE26: أنثى | BF26: 0 | BG26: 0 | BH26: 0 | BI26: 0 | BJ26: 0 | BN26: أنثى | BO26: 0 | BP26: 0 | BQ26: 0 | BR26: =SUM(BO26:BQ26) -> 0 | BS26: 0 | BW26: أنثى | BX26: 0 | BY26: 0 | BZ26: 0 | CA26: =SUM(BX26:BZ26) -> 0 | CB26: 0 | CF26: أنثى | CG26: 0 | CH26: 0 | CI26: 100 | CJ26: =SUM(CG26:CI26) -> 100 | CK26: 0 | CO26: أنثى | CP26: 0 | CQ26: 0 | CR26: 0 | CS26: =SUM(CP26:CR26) -> 0 | CT26: 0 | CX26: أنثى | CY26: 0 | CZ26: 0 | DA26: 0 | DB26: =SUM(CY26:DA26) -> 0 | DC26: 0 | DF26: سعودي | DG26: أنثى | DH26: =D26+M26+V26+AE26+AN26+AW26+BF26+BO26+BX26+CG26+CP26+CY26 -> 0 | DI26: =E26+N26+W26+AF26+AO26+AX26+BG26+BP26+BY26+CH26+CQ26+CZ26 -> 0 | DJ26: =F26+O26+X26+AG26+AP26+AY26+BH26+BQ26+BZ26+CI26+CR26+DA26 -> 100 | DK26: =SUM(DH26:DJ26) -> 100 | DL26: =H26+Q26+Z26+AI26+AR26+BA26+BJ26+BS26+CB26+CK26+CT26+DC26 -> 0
B27: غير | C27: ذكر | D27: 0 | E27: 0 | F27: 0 | G27: =SUM(D27:F27) -> 0 | H27: 0 | K27: غير | L27: ذكر | M27: 0 | N27: 0 | O27: 0 | P27: =SUM(M27:O27) -> 0 | Q27: 0 | T27: غير | U27: ذكر | V27: 0 | W27: 0 | X27: 0 | Y27: =SUM(V27:X27) -> 0 | Z27: 0 | AC27: غير | AD27: ذكر | AE27: 0 | AF27: 0 | AG27: 0 | AH27: =SUM(AE27:AG27) -> 0 | AI27: 0 | AL27: غير | AM27: ذكر | AN27: 0 | AO27: 0 | AP27: 0 | AQ27: =SUM(AN27:AP27) -> 0 | AR27: 0 | AU27: غير | AV27: ذكر | AW27: 0 | AX27: 0 | AY27: 0 | AZ27: =SUM(AW27:AY27) -> 0 | BA27: 0 | BD27: غير | BE27: ذكر | BF27: 0 | BG27: 0 | BH27: 0 | BI27: 0 | BJ27: 0 | BM27: غير | BN27: ذكر | BO27: 0 | BP27: 0 | BQ27: 0 | BR27: =SUM(BO27:BQ27) -> 0 | BS27: 0 | BV27: غير | BW27: ذكر | BX27: 0 | BY27: 0 | BZ27: 0 | CA27: =SUM(BX27:BZ27) -> 0 | CB27: 0 | CE27: غير | CF27: ذكر | CG27: 0 | CH27: 0 | CI27: 8 | CJ27: =SUM(CG27:CI27) -> 8 | CK27: 0 | CN27: غير | CO27: ذكر | CP27: 0 | CQ27: 0 | CR27: 0 | CS27: =SUM(CP27:CR27) -> 0 | CT27: 0 | CW27: غير | CX27: ذكر | CY27: 0 | CZ27: 0 | DA27: 0 | DB27: =SUM(CY27:DA27) -> 0 | DC27: 0 | DF27: غير | DG27: ذكر | DH27: =D27+M27+V27+AE27+AN27+AW27+BF27+BO27+BX27+CG27+CP27+CY27 -> 0 | DI27: =E27+N27+W27+AF27+AO27+AX27+BG27+BP27+BY27+CH27+CQ27+CZ27 -> 0 | DJ27: =F27+O27+X27+AG27+AP27+AY27+BH27+BQ27+BZ27+CI27+CR27+DA27 -> 8 | DK27: =SUM(DH27:DJ27) -> 8 | DL27: =H27+Q27+Z27+AI27+AR27+BA27+BJ27+BS27+CB27+CK27+CT27+DC27 -> 0
B28: سعودي | C28: أنثى | D28: 0 | E28: 0 | F28: 0 | G28: =SUM(D28:F28) -> 0 | H28: 0 | K28: سعودي | L28: أنثى | M28: 0 | N28: 0 | O28: 0 | P28: =SUM(M28:O28) -> 0 | Q28: 0 | T28: سعودي | U28: أنثى | V28: 0 | W28: 0 | X28: 0 | Y28: =SUM(V28:X28) -> 0 | Z28: 0 | AC28: سعودي | AD28: أنثى | AE28: 0 | AF28: 0 | AG28: 0 | AH28: =SUM(AE28:AG28) -> 0 | AI28: 0 | AL28: سعودي | AM28: أنثى | AN28: 0 | AO28: 0 | AP28: 0 | AQ28: =SUM(AN28:AP28) -> 0 | AR28: 0 | AU28: سعودي | AV28: أنثى | AW28: 0 | AX28: 0 | AY28: 0 | AZ28: =SUM(AW28:AY28) -> 0 | BA28: 0 | BD28: سعودي | BE28: أنثى | BF28: 0 | BG28: 0 | BH28: 0 | BI28: 0 | BJ28: 0 | BM28: سعودي | BN28: أنثى | BO28: 0 | BP28: 0 | BQ28: 0 | BR28: =SUM(BO28:BQ28) -> 0 | BS28: 0 | BV28: سعودي | BW28: أنثى | BX28: 0 | BY28: 0 | BZ28: 0 | CA28: =SUM(BX28:BZ28) -> 0 | CB28: 0 | CE28: سعودي | CF28: أنثى | CG28: 0 | CH28: 0 | CI28: 2 | CJ28: =SUM(CG28:CI28) -> 2 | CK28: 0 | CN28: سعودي | CO28: أنثى | CP28: 0 | CQ28: 0 | CR28: 0 | CS28: =SUM(CP28:CR28) -> 0 | CT28: 0 | CW28: سعودي | CX28: أنثى | CY28: 0 | CZ28: 0 | DA28: 0 | DB28: =SUM(CY28:DA28) -> 0 | DC28: 0 | DF28: سعودي | DG28: أنثى | DH28: =D28+M28+V28+AE28+AN28+AW28+BF28+BO28+BX28+CG28+CP28+CY28 -> 0 | DI28: =E28+N28+W28+AF28+AO28+AX28+BG28+BP28+BY28+CH28+CQ28+CZ28 -> 0 | DJ28: =F28+O28+X28+AG28+AP28+AY28+BH28+BQ28+BZ28+CI28+CR28+DA28 -> 2 | DK28: =SUM(DH28:DJ28) -> 2 | DL28: =H28+Q28+Z28+AI28+AR28+BA28+BJ28+BS28+CB28+CK28+CT28+DC28 -> 0
B29: المجموع | D29: =SUM(D25:D28) -> 0 | E29: =SUM(E25:E28) -> 0 | F29: =SUM(F25:F28) -> 0 | G29: =SUM(G25:G28) -> 0 | H29: =SUM(H25:H28) -> 0 | K29: المجموع | M29: =SUM(M25:M28) -> 0 | N29: =SUM(N25:N28) -> 0 | O29: =SUM(O25:O28) -> 0 | P29: =SUM(P25:P28) -> 0 | Q29: =SUM(Q25:Q28) -> 0 | T29: المجموع | V29: 0 | W29: 0 | X29: 0 | Y29: =SUM(Y25:Y28) -> 0 | Z29: =SUM(Z25:Z28) -> 0 | AC29: المجموع | AE29: 0 | AF29: 0 | AG29: 0 | AH29: =SUM(AH25:AH28) -> 0 | AI29: =SUM(AI25:AI28) -> 0 | AL29: المجموع | AN29: =SUM(AN25:AN28) -> 0 | AO29: =SUM(AO25:AO28) -> 0 | AP29: =SUM(AP25:AP28) -> 0 | AQ29: =SUM(AQ25:AQ28) -> 0 | AR29: =SUM(AR25:AR28) -> 0 | AU29: المجموع | AW29: =SUM(AW25:AW28) -> 0 | AX29: =SUM(AX25:AX28) -> 0 | AY29: =SUM(AY25:AY28) -> 0 | AZ29: =SUM(AZ25:AZ28) -> 0 | BA29: =SUM(BA25:BA28) -> 0 | BD29: المجموع | BF29: 0 | BG29: 0 | BH29: 0 | BI29: 0 | BJ29: =SUM(BJ25:BJ28) -> 0 | BM29: المجموع | BO29: =SUM(BO25:BO28) -> 0 | BP29: =SUM(BP25:BP28) -> 0 | BQ29: =SUM(BQ25:BQ28) -> 0 | BR29: =SUM(BR25:BR28) -> 0 | BS29: =SUM(BS25:BS28) -> 0 | BV29: المجموع | BX29: =SUM(BX25:BX28) -> 0 | BY29: =SUM(BY25:BY28) -> 0 | BZ29: =SUM(BZ25:BZ28) -> 0 | CA29: =SUM(CA25:CA28) -> 0 | CB29: =SUM(CB25:CB28) -> 0 | CE29: المجموع | CG29: =SUM(CG25:CG28) -> 0 | CH29: =SUM(CH25:CH28) -> 0 | CI29: =SUM(CI25:CI28) -> 302 | CJ29: =SUM(CJ25:CJ28) -> 302 | CK29: =SUM(CK25:CK28) -> 0 | CN29: المجموع | CP29: =SUM(CP25:CP28) -> 0 | CQ29: =SUM(CQ25:CQ28) -> 0 | CR29: =SUM(CR25:CR28) -> 0 | CS29: =SUM(CS25:CS28) -> 0 | CT29: =SUM(CT25:CT28) -> 0 | CW29: المجموع | CY29: =SUM(CY25:CY28) -> 0 | CZ29: =SUM(CZ25:CZ28) -> 0 | DA29: =SUM(DA25:DA28) -> 0 | DB29: =SUM(DB25:DB28) -> 0 | DC29: =SUM(DC25:DC28) -> 0 | DF29: المجموع | DH29: =SUM(DH25:DH28) -> 0 | DI29: =SUM(DI25:DI28) -> 20 | DJ29: =SUM(DJ25:DJ28) -> 768 | DK29: =SUM(DK25:DK28) -> 788 | DL29: =SUM(DL25:DL28) -> 0
A30: قويزة | B30: سعودي | C30: ذكر | D30: 0 | E30: 10 | F30: 368 | G30: =SUM(D30:F30) -> 378 | H30: 0 | J30: قويزة | K30: سعودي | L30: ذكر | M30: 0 | N30: 24 | O30: 358 | P30: =SUM(M30:O30) -> 382 | Q30: 0 | S30: قويزة | T30: سعودي | U30: ذكر | V30: 0 | W30: 0 | X30: 0 | Y30: =SUM(V30:X30) -> 0 | Z30: 0 | AB30: قويزة | AC30: سعودي | AD30: ذكر | AE30: 0 | AF30: 0 | AG30: 0 | AH30: =SUM(AE30:AG30) -> 0 | AI30: 0 | AK30: قويزة | AL30: سعودي | AM30: ذكر | AN30: 0 | AO30: 9 | AP30: 261 | AQ30: =SUM(AN30:AP30) -> 270 | AR30: 0 | AT30: قويزة | AU30: سعودي | AV30: ذكر | AW30: 0 | AX30: 0 | AY30: 320 | AZ30: =SUM(AW30:AY30) -> 320 | BA30: 0 | BC30: قويزة | BD30: سعودي | BE30: ذكر | BF30: 0 | BG30: 0 | BH30: 0 | BI30: 0 | BJ30: 0 | BL30: قويزة | BM30: سعودي | BN30: ذكر | BO30: 0 | BP30: 8 | BQ30: 232 | BR30: =SUM(BO30:BQ30) -> 240 | BS30: 0 | BU30: قويزة | BV30: سعودي | BW30: ذكر | BX30: 0 | BY30: 9 | BZ30: 145 | CA30: =SUM(BX30:BZ30) -> 154 | CB30: 0 | CD30: قويزة | CE30: سعودي | CF30: ذكر | CG30: 0 | CH30: 6 | CI30: 156 | CJ30: =SUM(CG30:CI30) -> 162 | CK30: 0 | CM30: قويزة | CN30: سعودي | CO30: ذكر | CP30: 0 | CQ30: 0 | CR30: 0 | CS30: =SUM(CP30:CR30) -> 0 | CT30: 0 | CV30: قويزة | CW30: سعودي | CX30: ذكر | CY30: 0 | CZ30: 0 | DA30: 0 | DB30: =SUM(CY30:DA30) -> 0 | DC30: 0 | DE30: =CV30 -> قويزة | DG30: ذكر | DH30: =D30+M30+V30+AE30+AN30+AW30+BF30+BO30+BX30+CG30+CP30+CY30 -> 0 | DI30: =E30+N30+W30+AF30+AO30+AX30+BG30+BP30+BY30+CH30+CQ30+CZ30 -> 66 | DJ30: =F30+O30+X30+AG30+AP30+AY30+BH30+BQ30+BZ30+CI30+CR30+DA30 -> 1840 | DK30: =SUM(DH30:DJ30) -> 1906 | DL30: =H30+Q30+Z30+AI30+AR30+BA30+BJ30+BS30+CB30+CK30+CT30+DC30 -> 0
C31: أنثى | D31: 0 | E31: 6 | F31: 362 | G31: =SUM(D31:F31) -> 368 | H31: 0 | L31: أنثى | M31: 0 | N31: 20 | O31: 352 | P31: =SUM(M31:O31) -> 372 | Q31: 0 | U31: أنثى | V31: 0 | W31: 15 | X31: 245 | Y31: =SUM(V31:X31) -> 260 | Z31: 0 | AD31: أنثى | AE31: 0 | AF31: 32 | AG31: 379 | AH31: =SUM(AE31:AG31) -> 411 | AI31: 0 | AM31: أنثى | AN31: 0 | AO31: 0 | AP31: 330 | AQ31: =SUM(AN31:AP31) -> 330 | AR31: 0 | AV31: أنثى | AW31: 0 | AX31: 0 | AY31: 295 | AZ31: =SUM(AW31:AY31) -> 295 | BA31: 0 | BE31: أنثى | BF31: 0 | BG31: 30 | BH31: 369 | BI31: 399 | BJ31: 0 | BN31: أنثى | BO31: 0 | BP31: 9 | BQ31: 199 | BR31: =SUM(BO31:BQ31) -> 208 | BS31: 0 | BW31: أنثى | BX31: 0 | BY31: 8 | BZ31: 162 | CA31: =SUM(BX31:BZ31) -> 170 | CB31: 0 | CF31: أنثى | CG31: 0 | CH31: 4 | CI31: 170 | CJ31: =SUM(CG31:CI31) -> 174 | CK31: 0 | CO31: أنثى | CP31: 0 | CQ31: 0 | CR31: 0 | CS31: =SUM(CP31:CR31) -> 0 | CT31: 0 | CX31: أنثى | CY31: 0 | CZ31: 0 | DA31: 0 | DB31: =SUM(CY31:DA31) -> 0 | DC31: 0 | DF31: سعودي | DG31: أنثى | DH31: =D31+M31+V31+AE31+AN31+AW31+BF31+BO31+BX31+CG31+CP31+CY31 -> 0 | DI31: =E31+N31+W31+AF31+AO31+AX31+BG31+BP31+BY31+CH31+CQ31+CZ31 -> 124 | DJ31: =F31+O31+X31+AG31+AP31+AY31+BH31+BQ31+BZ31+CI31+CR31+DA31 -> 2863 | DK31: =SUM(DH31:DJ31) -> 2987 | DL31: =H31+Q31+Z31+AI31+AR31+BA31+BJ31+BS31+CB31+CK31+CT31+DC31 -> 0
B32: غير | C32: ذكر | D32: 0 | E32: 0 | F32: 0 | G32: =SUM(D32:F32) -> 0 | H32: 0 | K32: غير | L32: ذكر | M32: 0 | N32: 0 | O32: 0 | P32: =SUM(M32:O32) -> 0 | Q32: 0 | T32: غير | U32: ذكر | V32: 0 | W32: 13 | X32: 212 | Y32: =SUM(V32:X32) -> 225 | Z32: 0 | AC32: غير | AD32: ذكر | AE32: 0 | AF32: 35 | AG32: 365 | AH32: =SUM(AE32:AG32) -> 400 | AI32: 0 | AL32: غير | AM32: ذكر | AN32: 0 | AO32: 0 | AP32: 91 | AQ32: =SUM(AN32:AP32) -> 91 | AR32: 0 | AU32: غير | AV32: ذكر | AW32: 0 | AX32: 0 | AY32: 85 | AZ32: =SUM(AW32:AY32) -> 85 | BA32: 0 | BD32: غير | BE32: ذكر | BF32: 0 | BG32: 39 | BH32: 358 | BI32: 397 | BJ32: 0 | BM32: غير | BN32: ذكر | BO32: 0 | BP32: 0 | BQ32: 0 | BR32: =SUM(BO32:BQ32) -> 0 | BS32: 0 | BV32: غير | BW32: ذكر | BX32: 0 | BY32: 0 | BZ32: 5 | CA32: =SUM(BX32:BZ32) -> 5 | CB32: 0 | CE32: غير | CF32: ذكر | CG32: 0 | CH32: 0 | CI32: 2 | CJ32: =SUM(CG32:CI32) -> 2 | CK32: 0 | CN32: غير | CO32: ذكر | CP32: 0 | CQ32: 0 | CR32: 0 | CS32: =SUM(CP32:CR32) -> 0 | CT32: 0 | CW32: غير | CX32: ذكر | CY32: 0 | CZ32: 0 | DA32: 0 | DB32: =SUM(CY32:DA32) -> 0 | DC32: 0 | DF32: غير | DG32: ذكر | DH32: =D32+M32+V32+AE32+AN32+AW32+BF32+BO32+BX32+CG32+CP32+CY32 -> 0 | DI32: =E32+N32+W32+AF32+AO32+AX32+BG32+BP32+BY32+CH32+CQ32+CZ32 -> 87 | DJ32: =F32+O32+X32+AG32+AP32+AY32+BH32+BQ32+BZ32+CI32+CR32+DA32 -> 1118 | DK32: =SUM(DH32:DJ32) -> 1205 | DL32: =H32+Q32+Z32+AI32+AR32+BA32+BJ32+BS32+CB32+CK32+CT32+DC32 -> 0
B33: سعودي | C33: أنثى | D33: 0 | E33: 0 | F33: 0 | G33: =SUM(D33:F33) -> 0 | H33: 0 | K33: سعودي | L33: أنثى | M33: 0 | N33: 0 | O33: 0 | P33: =SUM(M33:O33) -> 0 | Q33: 0 | T33: سعودي | U33: أنثى | V33: 0 | W33: 0 | X33: 0 | Y33: =SUM(V33:X33) -> 0 | Z33: 0 | AC33: سعودي | AD33: أنثى | AE33: 0 | AF33: 0 | AG33: 0 | AH33: =SUM(AE33:AG33) -> 0 | AI33: 0 | AL33: سعودي | AM33: أنثى | AN33: 0 | AO33: 0 | AP33: 80 | AQ33: =SUM(AN33:AP33) -> 80 | AR33: 0 | AU33: سعودي | AV33: أنثى | AW33: 0 | AX33: 0 | AY33: 66 | AZ33: =SUM(AW33:AY33) -> 66 | BA33: 0 | BD33: سعودي | BE33: أنثى | BF33: 0 | BG33: 0 | BH33: 0 | BI33: 0 | BJ33: 0 | BM33: سعودي | BN33: أنثى | BO33: 0 | BP33: 0 | BQ33: 0 | BR33: =SUM(BO33:BQ33) -> 0 | BS33: 0 | BV33: سعودي | BW33: أنثى | BX33: 0 | BY33: 0 | BZ33: 4 | CA33: =SUM(BX33:BZ33) -> 4 | CB33: 0 | CE33: سعودي | CF33: أنثى | CG33: 0 | CH33: 0 | CI33: 1 | CJ33: =SUM(CG33:CI33) -> 1 | CK33: 0 | CN33: سعودي | CO33: أنثى | CP33: 0 | CQ33: 0 | CR33: 0 | CS33: =SUM(CP33:CR33) -> 0 | CT33: 0 | CW33: سعودي | CX33: أنثى | CY33: 0 | CZ33: 0 | DA33: 0 | DB33: =SUM(CY33:DA33) -> 0 | DC33: 0 | DF33: سعودي | DG33: أنثى | DH33: =D33+M33+V33+AE33+AN33+AW33+BF33+BO33+BX33+CG33+CP33+CY33 -> 0 | DI33: =E33+N33+W33+AF33+AO33+AX33+BG33+BP33+BY33+CH33+CQ33+CZ33 -> 0 | DJ33: =F33+O33+X33+AG33+AP33+AY33+BH33+BQ33+BZ33+CI33+CR33+DA33 -> 151 | DK33: =SUM(DH33:DJ33) -> 151 | DL33: =H33+Q33+Z33+AI33+AR33+BA33+BJ33+BS33+CB33+CK33+CT33+DC33 -> 0
B34: المجموع | D34: =SUM(D30:D33) -> 0 | E34: =SUM(E30:E33) -> 16 | F34: =SUM(F30:F33) -> 730 | G34: =SUM(G30:G33) -> 746 | H34: =SUM(H30:H33) -> 0 | K34: المجموع | M34: =SUM(M30:M33) -> 0 | N34: =SUM(N30:N33) -> 44 | O34: =SUM(O30:O33) -> 710 | P34: =SUM(P30:P33) -> 754 | Q34: =SUM(Q30:Q33) -> 0 | T34: المجموع | V34: 0 | W34: 0 | X34: 0 | Y34: =SUM(Y30:Y33) -> 485 | Z34: =SUM(Z30:Z33) -> 0 | AC34: المجموع | AE34: 0 | AF34: 0 | AG34: 0 | AH34: =SUM(AH30:AH33) -> 811 | AI34: =SUM(AI30:AI33) -> 0 | AL34: المجموع | AN34: =SUM(AN30:AN33) -> 0 | AO34: =SUM(AO30:AO33) -> 9 | AP34: =SUM(AP30:AP33) -> 762 | AQ34: =SUM(AQ30:AQ33) -> 771 | AR34: =SUM(AR30:AR33) -> 0 | AU34: المجموع | AW34: =SUM(AW30:AW33) -> 0 | AX34: =SUM(AX30:AX33) -> 0 | AY34: =SUM(AY30:AY33) -> 766 | AZ34: =SUM(AZ30:AZ33) -> 766 | BA34: =SUM(BA30:BA33) -> 0 | BD34: المجموع | BF34: 0 | BG34: 0 | BH34: 0 | BI34: 0 | BJ34: =SUM(BJ30:BJ33) -> 0 | BM34: المجموع | BO34: =SUM(BO30:BO33) -> 0 | BP34: =SUM(BP30:BP33) -> 17 | BQ34: =SUM(BQ30:BQ33) -> 431 | BR34: =SUM(BR30:BR33) -> 448 | BS34: =SUM(BS30:BS33) -> 0 | BV34: المجموع | BX34: =SUM(BX30:BX33) -> 0 | BY34: =SUM(BY30:BY33) -> 17 | BZ34: =SUM(BZ30:BZ33) -> 316 | CA34: =SUM(CA30:CA33) -> 333 | CB34: =SUM(CB30:CB33) -> 0 | CE34: المجموع | CG34: =SUM(CG30:CG33) -> 0 | CH34: =SUM(CH30:CH33) -> 10 | CI34: =SUM(CI30:CI33) -> 329 | CJ34: =SUM(CJ30:CJ33) -> 339 | CK34: =SUM(CK30:CK33) -> 0 | CN34: المجموع | CP34: =SUM(CP30:CP33) -> 0 | CQ34: =SUM(CQ30:CQ33) -> 0 | CR34: =SUM(CR30:CR33) -> 0 | CS34: =SUM(CS30:CS33) -> 0 | CT34: =SUM(CT30:CT33) -> 0 | CW34: المجموع | CY34: =SUM(CY30:CY33) -> 0 | CZ34: =SUM(CZ30:CZ33) -> 0 | DA34: =SUM(DA30:DA33) -> 0 | DB34: =SUM(DB30:DB33) -> 0 | DC34: =SUM(DC30:DC33) -> 0 | DF34: المجموع | DH34: =SUM(DH30:DH33) -> 0 | DI34: =SUM(DI30:DI33) -> 277 | DJ34: =SUM(DJ30:DJ33) -> 5972 | DK34: =SUM(DK30:DK33) -> 6249 | DL34: =SUM(DL30:DL33) -> 0
A35: الرغامة | B35: سعودي | C35: ذكر | D35: 0 | E35: 16 | F35: 396 | G35: =SUM(D35:F35) -> 412 | H35: 0 | J35: الرغامة | K35: سعودي | L35: ذكر | M35: 0 | N35: 145 | O35: 365 | P35: 510 | Q35: 0 | S35: الرغامة | T35: سعودي | U35: ذكر | V35: 0 | W35: 28 | X35: 457 | Y35: =SUM(V35:X35) -> 485 | Z35: 0 | AB35: الرغامة | AC35: سعودي | AD35: ذكر | AE35: 0 | AF35: 67 | AG35: 744 | AH35: =SUM(AE35:AG35) -> 811 | AI35: 0 | AK35: الرغامة | AL35: سعودي | AM35: ذكر | AN35: 0 | AO35: 14 | AP35: 252 | AQ35: =SUM(AN35:AP35) -> 266 | AR35: 0 | AT35: الرغامة | AU35: سعودي | AV35: ذكر | AW35: 0 | AX35: 11 | AY35: 336 | AZ35: =SUM(AW35:AY35) -> 347 | BA35: 0 | BC35: الرغامة | BD35: سعودي | BE35: ذكر | BF35: 0 | BG35: 69 | BH35: 727 | BI35: 796 | BJ35: 0 | BL35: الرغامة | BM35: سعودي | BN35: ذكر | BO35: 0 | BP35: 0 | BQ35: 202 | BR35: =SUM(BO35:BQ35) -> 202 | BS35: 0 | BU35: الرغامة | BV35: سعودي | BW35: ذكر | BX35: 0 | BY35: 0 | BZ35: 210 | CA35: =SUM(BX35:BZ35) -> 210 | CB35: 0 | CD35: الرغامة | CE35: سعودي | CF35: ذكر | CG35: 0 | CH35: 0 | CI35: 219 | CJ35: =SUM(CG35:CI35) -> 219 | CK35: 0 | CM35: الرغامة | CN35: سعودي | CO35: ذكر | CP35: 0 | CQ35: 0 | CR35: 0 | CS35: =SUM(CP35:CR35) -> 0 | CT35: 0 | CV35: الرغامة | CW35: سعودي | CX35: ذكر | CY35: 0 | CZ35: 0 | DA35: 0 | DB35: =SUM(CY35:DA35) -> 0 | DC35: 0 | DE35: =CV35 -> الرغامة | DG35: ذكر | DH35: =D35+M35+V35+AE35+AN35+AW35+BF35+BO35+BX35+CG35+CP35+CY35 -> 0 | DI35: =E35+N35+W35+AF35+AO35+AX35+BG35+BP35+BY35+CH35+CQ35+CZ35 -> 350 | DJ35: =F35+O35+X35+AG35+AP35+AY35+BH35+BQ35+BZ35+CI35+CR35+DA35 -> 3908 | DK35: =SUM(DH35:DJ35) -> 4258 | DL35: =H35+Q35+Z35+AI35+AR35+BA35+BJ35+BS35+CB35+CK35+CT35+DC35 -> 0
C36: أنثى | D36: 0 | E36: 33 | F36: 412 | G36: =SUM(D36:F36) -> 445 | H36: 0 | L36: أنثى | M36: 0 | N36: 163 | O36: 496 | P36: 659 | Q36: 0 | U36: أنثى | V36: 0 | W36: 342 | X36: 567 | Y36: =SUM(V36:X36) -> 909 | Z36: 0 | AD36: أنثى | AE36: 0 | AF36: 1 | AG36: 475 | AH36: =SUM(AE36:AG36) -> 476 | AI36: 0 | AM36: أنثى | AN36: 0 | AO36: 10 | AP36: 221 | AQ36: =SUM(AN36:AP36) -> 231 | AR36: 0 | AV36: أنثى | AW36: 0 | AX36: 6 | AY36: 302 | AZ36: =SUM(AW36:AY36) -> 308 | BA36: 0 | BE36: أنثى | BF36: 0 | BG36: 0 | BH36: 658 | BI36: 658 | BJ36: 0 | BN36: أنثى | BO36: 0 | BP36: 0 | BQ36: 221 | BR36: =SUM(BO36:BQ36) -> 221 | BS36: 0 | BW36: أنثى | BX36: 0 | BY36: 0 | BZ36: 224 | CA36: =SUM(BX36:BZ36) -> 224 | CB36: 0 | CF36: أنثى | CG36: 0 | CH36: 0 | CI36: 200 | CJ36: =SUM(CG36:CI36) -> 200 | CK36: 0 | CO36: أنثى | CP36: 0 | CQ36: 0 | CR36: 0 | CS36: =SUM(CP36:CR36) -> 0 | CT36: 0 | CX36: أنثى | CY36: 0 | CZ36: 0 | DA36: 0 | DB36: =SUM(CY36:DA36) -> 0 | DC36: 0 | DF36: سعودي | DG36: أنثى | DH36: =D36+M36+V36+AE36+AN36+AW36+BF36+BO36+BX36+CG36+CP36+CY36 -> 0 | DI36: =E36+N36+W36+AF36+AO36+AX36+BG36+BP36+BY36+CH36+CQ36+CZ36 -> 555 | DJ36: =F36+O36+X36+AG36+AP36+AY36+BH36+BQ36+BZ36+CI36+CR36+DA36 -> 3776 | DK36: =SUM(DH36:DJ36) -> 4331 | DL36: =H36+Q36+Z36+AI36+AR36+BA36+BJ36+BS36+CB36+CK36+CT36+DC36 -> 0
B37: غير | C37: ذكر | D37: 0 | E37: 0 | F37: 0 | G37: =SUM(D37:F37) -> 0 | H37: 0 | K37: غير | L37: ذكر | M37: 0 | N37: 2 | O37: 15 | P37: 17 | Q37: 0 | T37: غير | U37: ذكر | V37: 0 | W37: 654 | X37: 698 | Y37: =SUM(V37:X37) -> 1352 | Z37: 0 | AC37: غير | AD37: ذكر | AE37: 0 | AF37: 0 | AG37: 574 | AH37: =SUM(AE37:AG37) -> 574 | AI37: 0 | AL37: غير | AM37: ذكر | AN37: 0 | AO37: 0 | AP37: 69 | AQ37: =SUM(AN37:AP37) -> 69 | AR37: 0 | AU37: غير | AV37: ذكر | AW37: 0 | AX37: 0 | AY37: 81 | AZ37: =SUM(AW37:AY37) -> 81 | BA37: 0 | BD37: غير | BE37: ذكر | BF37: 0 | BG37: 0 | BH37: 748 | BI37: 748 | BJ37: 0 | BM37: غير | BN37: ذكر | BO37: 0 | BP37: 0 | BQ37: 4 | BR37: =SUM(BO37:BQ37) -> 4 | BS37: 0 | BV37: غير | BW37: ذكر | BX37: 0 | BY37: 0 | BZ37: 11 | CA37: =SUM(BX37:BZ37) -> 11 | CB37: 0 | CE37: غير | CF37: ذكر | CG37: 0 | CH37: 0 | CI37: 9 | CJ37: =SUM(CG37:CI37) -> 9 | CK37: 0 | CN37: غير | CO37: ذكر | CP37: 0 | CQ37: 0 | CR37: 0 | CS37: =SUM(CP37:CR37) -> 0 | CT37: 0 | CW37: غير | CX37: ذكر | CY37: 0 | CZ37: 0 | DA37: 0 | DB37: =SUM(CY37:DA37) -> 0 | DC37: 0 | DF37: غير | DG37: ذكر | DH37: =D37+M37+V37+AE37+AN37+AW37+BF37+BO37+BX37+CG37+CP37+CY37 -> 0 | DI37: =E37+N37+W37+AF37+AO37+AX37+BG37+BP37+BY37+CH37+CQ37+CZ37 -> 656 | DJ37: =F37+O37+X37+AG37+AP37+AY37+BH37+BQ37+BZ37+CI37+CR37+DA37 -> 2209 | DK37: =SUM(DH37:DJ37) -> 2865 | DL37: =H37+Q37+Z37+AI37+AR37+BA37+BJ37+BS37+CB37+CK37+CT37+DC37 -> 0
B38: سعودي | C38: أنثى | D38: 0 | E38: 0 | F38: 0 | G38: =SUM(D38:F38) -> 0 | H38: 0 | K38: سعودي | L38: أنثى | M38: 0 | N38: 3 | O38: 26 | P38: 29 | Q38: 0 | T38: سعودي | U38: أنثى | V38: 0 | W38: 15 | X38: 28 | Y38: =SUM(V38:X38) -> 43 | Z38: 0 | AC38: سعودي | AD38: أنثى | AE38: 0 | AF38: 0 | AG38: 23 | AH38: =SUM(AE38:AG38) -> 23 | AI38: 0 | AL38: سعودي | AM38: أنثى | AN38: 0 | AO38: 0 | AP38: 70 | AQ38: =SUM(AN38:AP38) -> 70 | AR38: 0 | AU38: سعودي | AV38: أنثى | AW38: 0 | AX38: 0 | AY38: 65 | AZ38: =SUM(AW38:AY38) -> 65 | BA38: 0 | BD38: سعودي | BE38: أنثى | BF38: 0 | BG38: 0 | BH38: 31 | BI38: 31 | BJ38: 0 | BM38: سعودي | BN38: أنثى | BO38: 0 | BP38: 0 | BQ38: 9 | BR38: =SUM(BO38:BQ38) -> 9 | BS38: 0 | BV38: سعودي | BW38: أنثى | BX38: 0 | BY38: 0 | BZ38: 12 | CA38: =SUM(BX38:BZ38) -> 12 | CB38: 0 | CE38: سعودي | CF38: أنثى | CG38: 0 | CH38: 0 | CI38: 10 | CJ38: =SUM(CG38:CI38) -> 10 | CK38: 0 | CN38: سعودي | CO38: أنثى | CP38: 0 | CQ38: 0 | CR38: 0 | CS38: =SUM(CP38:CR38) -> 0 | CT38: 0 | CW38: سعودي | CX38: أنثى | CY38: 0 | CZ38: 0 | DA38: 0 | DB38: =SUM(CY38:DA38) -> 0 | DC38: 0 | DF38: سعودي | DG38: أنثى | DH38: =D38+M38+V38+AE38+AN38+AW38+BF38+BO38+BX38+CG38+CP38+CY38 -> 0 | DI38: =E38+N38+W38+AF38+AO38+AX38+BG38+BP38+BY38+CH38+CQ38+CZ38 -> 18 | DJ38: =F38+O38+X38+AG38+AP38+AY38+BH38+BQ38+BZ38+CI38+CR38+DA38 -> 274 | DK38: =SUM(DH38:DJ38) -> 292 | DL38: =H38+Q38+Z38+AI38+AR38+BA38+BJ38+BS38+CB38+CK38+CT38+DC38 -> 0
B39: المجموع | D39: =SUM(D35:D38) -> 0 | E39: =SUM(E35:E38) -> 49 | F39: =SUM(F35:F38) -> 808 | G39: =SUM(G35:G38) -> 857 | H39: =SUM(H35:H38) -> 0 | K39: المجموع | M39: =SUM(M35:M38) -> 0 | N39: =SUM(N35:N38) -> 313 | O39: =SUM(O35:O38) -> 902 | P39: =SUM(P35:P38) -> 1215 | Q39: =SUM(Q35:Q38) -> 0 | T39: المجموع | V39: 0 | W39: 19 | X39: 33 | Y39: =SUM(Y35:Y38) -> 2789 | Z39: =SUM(Z35:Z38) -> 0 | AC39: المجموع | AE39: 0 | AF39: 0 | AG39: 36 | AH39: =SUM(AH35:AH38) -> 1884 | AI39: =SUM(AI35:AI38) -> 0 | AL39: المجموع | AN39: =SUM(AN35:AN38) -> 0 | AO39: =SUM(AO35:AO38) -> 24 | AP39: =SUM(AP35:AP38) -> 612 | AQ39: =SUM(AQ35:AQ38) -> 636 | AR39: =SUM(AR35:AR38) -> 0 | AU39: المجموع | AW39: =SUM(AW35:AW38) -> 0 | AX39: =SUM(AX35:AX38) -> 17 | AY39: =SUM(AY35:AY38) -> 784 | AZ39: =SUM(AZ35:AZ38) -> 801 | BA39: =SUM(BA35:BA38) -> 0 | BD39: المجموع | BF39: 0 | BG39: 0 | BH39: 23 | BI39: 23 | BJ39: =SUM(BJ35:BJ38) -> 0 | BM39: المجموع | BO39: =SUM(BO35:BO38) -> 0 | BP39: =SUM(BP35:BP38) -> 0 | BQ39: =SUM(BQ35:BQ38) -> 436 | BR39: =SUM(BR35:BR38) -> 436 | BS39: =SUM(BS35:BS38) -> 0 | BV39: المجموع | BX39: =SUM(BX35:BX38) -> 0 | BY39: =SUM(BY35:BY38) -> 0 | BZ39: =SUM(BZ35:BZ38) -> 457 | CA39: =SUM(CA35:CA38) -> 457 | CB39: =SUM(CB35:CB38) -> 0 | CE39: المجموع | CG39: =SUM(CG35:CG38) -> 0 | CH39: =SUM(CH35:CH38) -> 0 | CI39: =SUM(CI35:CI38) -> 438 | CJ39: =SUM(CJ35:CJ38) -> 438 | CK39: =SUM(CK35:CK38) -> 0 | CN39: المجموع | CP39: =SUM(CP35:CP38) -> 0 | CQ39: =SUM(CQ35:CQ38) -> 0 | CR39: =SUM(CR35:CR38) -> 0 | CS39: =SUM(CS35:CS38) -> 0 | CT39: =SUM(CT35:CT38) -> 0 | CW39: المجموع | CY39: =SUM(CY35:CY38) -> 0 | CZ39: =SUM(CZ35:CZ38) -> 0 | DA39: =SUM(DA35:DA38) -> 0 | DB39: =SUM(DB35:DB38) -> 0 | DC39: =SUM(DC35:DC38) -> 0 | DF39: المجموع | DH39: =SUM(DH35:DH38) -> 0 | DI39: =SUM(DI35:DI38) -> 1579 | DJ39: =SUM(DJ35:DJ38) -> 10167 | DK39: =SUM(DK35:DK38) -> 11746 | DL39: =SUM(DL35:DL38) -> 0
A40: الواحة | B40: سعودي | C40: ذكر | D40: 1 | E40: 22 | F40: 310 | G40: =SUM(D40:F40) -> 333 | H40: 0 | J40: الواحة | K40: سعودي | L40: ذكر | M40: 0 | N40: 7 | O40: 252 | P40: =SUM(M40:O40) -> 259 | Q40: 0 | S40: الواحة | T40: سعودي | U40: ذكر | V40: 0 | W40: 10 | X40: 362 | Y40: =SUM(V40:X40) -> 372 | Z40: 0 | AB40: الواحة | AC40: سعودي | AD40: ذكر | AE40: 0 | AF40: 1 | AG40: 1108 | AH40: =SUM(AE40:AG40) -> 1109 | AI40: 0 | AK40: الواحة | AL40: سعودي | AM40: ذكر | AN40: 0 | AO40: 22 | AP40: 441 | AQ40: =SUM(AN40:AP40) -> 463 | AR40: 0 | AT40: الواحة | AU40: سعودي | AV40: ذكر | AW40: 0 | AX40: 19 | AY40: 425 | AZ40: =SUM(AW40:AY40) -> 444 | BA40: 0 | BC40: الواحة | BD40: سعودي | BE40: ذكر | BF40: 0 | BG40: 0 | BH40: 1460 | BI40: 1460 | BJ40: 0 | BL40: الواحة | BM40: سعودي | BN40: ذكر | BO40: 0 | BP40: 5 | BQ40: 475 | BR40: =SUM(BO40:BQ40) -> 480 | BS40: 0 | BU40: الواحة | BV40: سعودي | BW40: ذكر | BX40: 0 | BY40: 36 | BZ40: 126 | CA40: =SUM(BX40:BZ40) -> 162 | CB40: 0 | CD40: الواحة | CE40: سعودي | CF40: ذكر | CG40: 0 | CH40: 36 | CI40: 155 | CJ40: =SUM(CG40:CI40) -> 191 | CK40: 0 | CM40: الواحة | CN40: سعودي | CO40: ذكر | CP40: 0 | CQ40: 0 | CR40: 0 | CS40: =SUM(CP40:CR40) -> 0 | CT40: 0 | CV40: الواحة | CW40: سعودي | CX40: ذكر | CY40: 0 | CZ40: 0 | DA40: 0 | DB40: =SUM(CY40:DA40) -> 0 | DC40: 0 | DE40: =CV40 -> الواحة | DG40: ذكر | DH40: =D40+M40+V40+AE40+AN40+AW40+BF40+BO40+BX40+CG40+CP40+CY40 -> 1 | DI40: =E40+N40+W40+AF40+AO40+AX40+BG40+BP40+BY40+CH40+CQ40+CZ40 -> 158 | DJ40: =F40+O40+X40+AG40+AP40+AY40+BH40+BQ40+BZ40+CI40+CR40+DA40 -> 5114 | DK40: =SUM(DH40:DJ40) -> 5273 | DL40: =H40+Q40+Z40+AI40+AR40+BA40+BJ40+BS40+CB40+CK40+CT40+DC40 -> 0
C41: أنثى | D41: 0 | E41: 0 | F41: 412 | G41: =SUM(D41:F41) -> 412 | H41: 0 | L41: أنثى | M41: 0 | N41: 5 | O41: 320 | P41: =SUM(M41:O41) -> 325 | Q41: 0 | U41: أنثى | V41: 0 | W41: 2 | X41: 395 | Y41: =SUM(V41:X41) -> 397 | Z41: 0 | AD41: أنثى | AE41: 0 | AF41: 0 | AG41: 0 | AH41: =SUM(AE41:AG41) -> 0 | AI41: 0 | AM41: أنثى | AN41: 0 | AO41: 10 | AP41: 220 | AQ41: =SUM(AN41:AP41) -> 230 | AR41: 0 | AV41: أنثى | AW41: 0 | AX41: 4 | AY41: 285 | AZ41: =SUM(AW41:AY41) -> 289 | BA41: 0 | BE41: أنثى | BF41: 0 | BG41: 7 | BH41: 252 | BI41: 259 | BJ41: 0 | BN41: أنثى | BO41: 0 | BP41: 1 | BQ41: 486 | BR41: =SUM(BO41:BQ41) -> 487 | BS41: 0 | BW41: أنثى | BX41: 0 | BY41: 64 | BZ41: 130 | CA41: =SUM(BX41:BZ41) -> 194 | CB41: 0 | CF41: أنثى | CG41: 0 | CH41: 64 | CI41: 124 | CJ41: =SUM(CG41:CI41) -> 188 | CK41: 0 | CO41: أنثى | CP41: 0 | CQ41: 0 | CR41: 0 | CS41: =SUM(CP41:CR41) -> 0 | CT41: 0 | CX41: أنثى | CY41: 0 | CZ41: 0 | DA41: 0 | DB41: =SUM(CY41:DA41) -> 0 | DC41: 0 | DF41: سعودي | DG41: أنثى | DH41: =D41+M41+V41+AE41+AN41+AW41+BF41+BO41+BX41+CG41+CP41+CY41 -> 0 | DI41: =E41+N41+W41+AF41+AO41+AX41+BG41+BP41+BY41+CH41+CQ41+CZ41 -> 157 | DJ41: =F41+O41+X41+AG41+AP41+AY41+BH41+BQ41+BZ41+CI41+CR41+DA41 -> 2624 | DK41: =SUM(DH41:DJ41) -> 2781 | DL41: =H41+Q41+Z41+AI41+AR41+BA41+BJ41+BS41+CB41+CK41+CT41+DC41 -> 0
...

Sheet إجمالية
A2: مراكز شرق جدة | D2: شهر | E2: 1 | F2: =SUM(الإحالات!F2) -> 1447 | G2: الإحالات والردود الراجعة | J2: مراكز شرق جدة | M2: شهر | N2: 2 | O2: =SUM(الإحالات!O2) -> 1447 | P2: الإحالات والردود الراجعة | S2: مراكز شرق جدة | V2: شهر | W2: 3 | X2: =SUM(الإحالات!X2) -> 1447 | Y2: الإحالات والردود الراجعة | AB2: مراكز شرق جدة | AE2: شهر | AF2: 4 | AG2: =SUM(الإحالات!AG2) -> 1447 | AH2: الإحالات والردود الراجعة | AK2: مراكز شرق جدة | AN2: شهر | AO2: 5 | AP2: =SUM(الإحالات!AP2) -> 1447 | AQ2: الإحالات والردود الراجعة | AT2: مراكز شرق جدة | AW2: شهر | AX2: 6 | AY2: =SUM(الإحالات!AY2) -> 1447 | AZ2: الإحالات والردود الراجعة | BC2: مراكز شرق جدة | BF2: شهر | BG2: 7 | BH2: =SUM(الإحالات!BH2) -> 1447 | BI2: الإحالات والردود الراجعة | BL2: مراكز شرق جدة | BO2: شهر | BP2: 8 | BQ2: =SUM(الإحالات!BQ2) -> 1447 | BR2: الإحالات والردود الراجعة | BU2: مراكز شرق جدة | BX2: شهر | BY2: 9 | BZ2: =SUM(الإحالات!BZ2) -> 1447 | CA2: الإحالات والردود الراجعة | CD2: مراكز شرق جدة | CG2: شهر | CH2: 10 | CI2: =SUM(الإحالات!CI2) -> 1447 | CJ2: الإحالات والردود الراجعة | CM2: مراكز شرق جدة | CP2: شهر | CQ2: 11 | CR2: =SUM(الإحالات!CR2) -> 1447 | CS2: الإحالات والردود الراجعة | CV2: مراكز شرق جدة | CY2: شهر | CZ2: 12 | DA2: =SUM(الإحالات!DA2) -> 1447 | DB2: الإحالات والردود الراجعة | DE2: مراكز شرق جدة | DJ2: =SUM(الإحالات!DJ2) -> 1447 | DK2: الإحالات والردود الراجعة
