Workbook

Sheet مراجعي العيادات
H1: شهر | I1: 1 | J1: عام | K1: 1447 | L1: هـ | V1: شهر | W1: 2 | X1: عام | Y1: 1447 | Z1: هـ | AJ1: شهر | AK1: 3 | AL1: عام | AM1: 1447 | AN1: هـ | AX1: شهر | AY1: 4 | AZ1: عام | BA1: 1447 | BB1: هـ | BL1: شهر | BM1: 5 | BN1: عام | BO1: 1447 | BP1: هـ | BZ1: شهر | CA1: 6 | CB1: عام | CC1: 1447 | CD1: هـ | CN1: شهر | CO1: 7 | CP1: عام | CQ1: 1447 | CR1: هـ | DB1: شهر | DC1: 8 | DD1: عام | DE1: 1447 | DF1: هـ | DP1: شهر | DQ1: 9 | DR1: عام | DS1: 1447 | DT1: هـ | ED1: شهر | EE1: 10 | EF1: عام | EG1: 1447 | EH1: هـ | ER1: شهر | ES1: 11 | ET1: عام | EU1: 1447 | EV1: هـ | FF1: شهر | FG1: 12 | FH1: عام | FI1: 1447 | FJ1: هـ | FV1: عام | FW1: =SUM(FI1) -> 1447 | FX1: هـ
A2: 3ـ | B2: إجمالي المراجعين للمركز خلال الشهر : | O2: 3ـ | P2: إجمالي المراجعين للمركز خلال الشهر : | AC2: 3ـ | AD2: إجمالي المراجعين للمركز خلال الشهر : | AQ2: 3ـ | AR2: إجمالي المراجعين للمركز خلال الشهر : | BE2: 3ـ | BF2: إجمالي المراجعين للمركز خلال الشهر : | BS2: 3ـ | BT2: إجمالي المراجعين للمركز خلال الشهر : | CG2: 3ـ | CH2: إجمالي المراجعين للمركز خلال الشهر : | CU2: 3ـ | CV2: إجمالي المراجعين للمركز خلال الشهر : | DI2: 3ـ | DJ2: إجمالي المراجعين للمركز خلال الشهر : | DW2: 3ـ | DX2: إجمالي المراجعين للمركز خلال الشهر : | EK2: 3ـ | EL2: إجمالي المراجعين للمركز خلال الشهر : | EY2: 3ـ | EZ2: إجمالي المراجعين للمركز خلال الشهر : | FM2: 3ـ | FN2: إجمالي المراجعين للمركز خلال العام :
A4: المركز الصحي | B4: الجنسية | C4: الجنس | D4: عدد مراجعي العيادات العامة | E4: مراجعي الأمراض المزمنة | F4: عدد مراجعي عيادة الأسنان | G4: عدد زيارات الحوامل | H4: الطفل السليم والتطعيمات | I4: مجموع مراجعي العيادات | J4: الضماد والحقن والطواريء | K4: المختبر | L4: الأشعة | M4: مجموع الخدمات والمساندة | O4: المركز الصحي | P4: الجنسية | Q4: الجنس | R4: عدد مراجعي العيادات العامة | S4: مراجعي الأمراض المزمنة | T4: عدد مراجعي عيادة الأسنان | U4: عدد زيارات الحوامل | V4: الطفل السليم والتطعيمات | W4: مجموع مراجعي العيادات | X4: الضماد والحقن والطواريء | Y4: المختبر | Z4: الأشعة | AA4: مجموع الخدمات والمساندة | AC4: المركز الصحي | AD4: الجنسية | AE4: الجنس | AF4: عدد مراجعي العيادات العامة | AG4: مراجعي الأمراض المزمنة | AH4: عدد مراجعي عيادة الأسنان | AI4: عدد زيارات الحوامل | AJ4: الطفل السليم والتطعيمات | AK4: مجموع مراجعي العيادات | AL4: الضماد والحقن والطواريء | AM4: المختبر | AN4: الأشعة | AO4: مجموع الخدمات والمساندة | AQ4: المركز الصحي | AR4: الجنسية | AS4: الجنس | AT4: عدد مراجعي العيادات العامة | AU4: مراجعي الأمراض المزمنة | AV4: عدد مراجعي عيادة الأسنان | AW4: عدد زيارات الحوامل | AX4: الطفل السليم والتطعيمات | AY4: مجموع مراجعي العيادات | AZ4: الضماد والحقن والطواريء | BA4: المختبر | BB4: الأشعة | BC4: مجموع الخدمات والمساندة | BE4: المركز الصحي | BF4: الجنسية | BG4: الجنس | BH4: عدد مراجعي العيادات العامة | BI4: مراجعي الأمراض المزمنة | BJ4: عدد مراجعي عيادة الأسنان | BK4: عدد زيارات الحوامل | BL4: الطفل السليم والتطعيمات | BM4: مجموع مراجعي العيادات | BN4: الضماد والحقن والطواريء | BO4: المختبر | BP4: الأشعة | BQ4: مجموع الخدمات والمساندة | BS4: المركز الصحي | BT4: الجنسية | BU4: الجنس | BV4: عدد مراجعي العيادات العامة | BW4: مراجعي الأمراض المزمنة | BX4: عدد مراجعي عيادة الأسنان | BY4: عدد زيارات الحوامل | BZ4: الطفل السليم والتطعيمات | CA4: مجموع مراجعي العيادات | CB4: الضماد والحقن والطواريء | CC4: المختبر | CD4: الأشعة | CE4: مجموع الخدمات والمساندة | CG4: المركز الصحي | CH4: الجنسية | CI4: الجنس | CJ4: عدد مراجعي العيادات العامة | CK4: مراجعي الأمراض المزمنة | CL4: عدد مراجعي عيادة الأسنان | CM4: عدد زيارات الحوامل | CN4: الطفل السليم والتطعيمات | CO4: مجموع مراجعي العيادات | CP4: الضماد والحقن والطواريء | CQ4: المختبر | CR4: الأشعة | CS4: مجموع الخدمات والمساندة | CU4: المركز الصحي | CV4: الجنسية | CW4: الجنس | CX4: عدد مراجعي العيادات العامة | CY4: مراجعي الأمراض المزمنة | CZ4: عدد مراجعي عيادة الأسنان | DA4: عدد زيارات الحوامل | DB4: الطفل السليم والتطعيمات | DC4: مجموع مراجعي العيادات | DD4: الضماد والحقن والطواريء | DE4: المختبر | DF4: الأشعة | DG4: مجموع الخدمات والمساندة | DI4: المركز الصحي | DJ4: الجنسية | DK4: الجنس | DL4: عدد مراجعي العيادات العامة | DM4: مراجعي الأمراض المزمنة | DN4: عدد مراجعي عيادة الأسنان | DO4: عدد زيارات الحوامل | DP4: الطفل السليم والتطعيمات | DQ4: مجموع مراجعي العيادات | DR4: الضماد والحقن والطواريء | DS4: المختبر | DT4: الأشعة | DU4: مجموع الخدمات والمساندة | DW4: المركز الصحي | DX4: الجنسية | DY4: الجنس | DZ4: عدد مراجعي العيادات العامة | EA4: مراجعي الأمراض المزمنة | EB4: عدد مراجعي عيادة الأسنان | EC4: عدد زيارات الحوامل | ED4: الطفل السليم والتطعيمات | EE4: مجموع مراجعي العيادات | EF4: الضماد والحقن والطواريء | EG4: المختبر | EH4: الأشعة | EI4: مجموع الخدمات والمساندة | EK4: المركز الصحي | EL4: الجنسية | EM4: الجنس | EN4: عدد مراجعي العيادات العامة | EO4: مراجعي الأمراض المزمنة | EP4: عدد مراجعي عيادة الأسنان | EQ4: عدد زيارات الحوامل | ER4: الطفل السليم والتطعيمات | ES4: مجموع مراجعي العيادات | ET4: الضماد والحقن والطواريء | EU4: المختبر | EV4: الأشعة | EW4: مجموع الخدمات والمساندة | EY4: المركز الصحي | EZ4: الجنسية | FA4: الجنس | FB4: عدد مراجعي العيادات العامة | FC4: مراجعي الأمراض المزمنة | FD4: عدد مراجعي عيادة الأسنان | FE4: عدد زيارات الحوامل | FF4: الطفل السليم والتطعيمات | FG4: مجموع مراجعي العيادات | FH4: الضماد والحقن والطواريء | FI4: المختبر | FJ4: الأشعة | FK4: مجموع الخدمات والمساندة | FM4: المركز الصحي | FN4: الجنسية | FO4: الجنس | FP4: عدد مراجعي العيادات العامة | FQ4: مراجعي الأمراض المزمنة | FR4: عدد مراجعي عيادة الأسنان | FS4: عدد زيارات الحوامل | FT4: الطفل السليم والتطعيمات | FU4: مجموع مراجعي العيادات | FV4: الضماد والحقن والطواريء | FW4: المختبر | FX4: الأشعة | FY4: مجموع الخدمات والمساندة
D5: 1 | E5: 2 | F5: 3 | G5: 4 | H5: 5 | I5: 6=1+2+3+4+5 | J5: 7 | K5: 8 | L5: 9 | M5: 10=7+8+9 | R5: 1 | S5: 2 | T5: 3 | U5: 4 | V5: 5 | W5: 6=1+2+3+4+5 | X5: 7 | Y5: 8 | Z5: 9 | AA5: 10=7+8+9 | AF5: 1 | AG5: 2 | AH5: 3 | AI5: 4 | AJ5: 5 | AK5: 6=1+2+3+4+5 | AL5: 7 | AM5: 8 | AN5: 9 | AO5: 10=7+8+9 | AT5: 1 | AU5: 2 | AV5: 3 | AW5: 4 | AX5: 5 | AY5: 6=1+2+3+4+5 | AZ5: 7 | BA5: 8 | BB5: 9 | BC5: 10=7+8+9 | BH5: 1 | BI5: 2 | BJ5: 3 | BK5: 4 | BL5: 5 | BM5: 6=1+2+3+4+5 | BN5: 7 | BO5: 8 | BP5: 9 | BQ5: 10=7+8+9 | BV5: 1 | BW5: 2 | BX5: 3 | BY5: 4 | BZ5: 5 | CA5: 6=1+2+3+4+5 | CB5: 7 | CC5: 8 | CD5: 9 | CE5: 10=7+8+9 | CJ5: 1 | CK5: 2 | CL5: 3 | CM5: 4 | CN5: 5 | CO5: 6=1+2+3+4+5 | CP5: 7 | CQ5: 8 | CR5: 9 | CS5: 10=7+8+9 | CX5: 1 | CY5: 2 | CZ5: 3 | DA5: 4 | DB5: 5 | DC5: 6=1+2+3+4+5 | DD5: 7 | DE5: 8 | DF5: 9 | DG5: 10=7+8+9 | DL5: 1 | DM5: 2 | DN5: 3 | DO5: 4 | DP5: 5 | DQ5: 6=1+2+3+4+5 | DR5: 7 | DS5: 8 | DT5: 9 | DU5: 10=7+8+9 | DZ5: 1 | EA5: 2 | EB5: 3 | EC5: 4 | ED5: 5 | EE5: 6=1+2+3+4+5 | EF5: 7 | EG5: 8 | EH5: 9 | EI5: 10=7+8+9 | EN5: 1 | EO5: 2 | EP5: 3 | EQ5: 4 | ER5: 5 | ES5: 6=1+2+3+4+5 | ET5: 7 | EU5: 8 | EV5: 9 | EW5: 10=7+8+9 | FB5: 1 | FC5: 2 | FD5: 3 | FE5: 4 | FF5: 5 | FG5: 6=1+2+3+4+5 | FH5: 7 | FI5: 8 | FJ5: 9 | FK5: 10=7+8+9 | FP5: 1 | FQ5: 2 | FR5: 3 | FS5: 4 | FT5: 5 | FU5: 6=1+2+3+4+5 | FV5: 7 | FW5: 8 | FX5: 9 | FY5: 10=7+8+9
A6: الربيع والتوفيق | B6: سعودي | C6: ذكر | D6: 2111 | E6: 151 | F6: 182 | G6: 0 | H6: 498 | I6: 2942 | J6: 86 | K6: 597 | L6: 0 | M6: =SUM(J6:L6) -> 683 | O6: الربيع والتوفيق | P6: سعودي | Q6: ذكر | R6: 2122 | S6: 132 | T6: 123 | U6: 0 | V6: 522 | W6: 2122 | X6: 94 | Y6: 752 | Z6: 0 | AA6: =SUM(X6:Z6) -> 846 | AC6: الربيع والتوفيق | AD6: سعودي | AE6: ذكر | AF6: 2155 | AG6: 865 | AH6: 145 | AI6: 0 | AJ6: 388 | AK6: 3553 | AL6: 154 | AM6: 565 | AN6: 0 | AO6: =SUM(AL6:AN6) -> 719 | AQ6: الربيع والتوفيق | AR6: سعودي | AS6: ذكر | AT6: 1520 | AU6: 537 | AV6: 219 | AW6: 0 | AX6: 644 | AY6: 2920 | AZ6: 226 | BA6: 744 | BB6: 0 | BC6: 970 | BE6: الربيع والتوفيق | BF6: سعودي | BG6: ذكر | BH6: 1852 | BI6: 332 | BJ6: 185 | BK6: 0 | BL6: 285 | BM6: 2654 | BN6: 202 | BO6: 544 | BP6: 0 | BQ6: =SUM(BN6:BP6) -> 746 | BS6: الربيع والتوفيق | BT6: سعودي | BU6: ذكر | BV6: 1640 | BW6: 573 | BX6: 78 | BY6: 0 | BZ6: 747 | CA6: 3038 | CB6: 48 | CC6: 744 | CD6: 0 | CE6: =SUM(CB6:CD6) -> 792 | CG6: الربيع والتوفيق | CH6: سعودي | CI6: ذكر | CJ6: 1890 | CK6: 0 | CL6: 173 | CM6: 0 | CN6: 400 | CO6: 597 | CP6: 0 | CQ6: 683 | CR6: 0 | CS6: 683 | CU6: الربيع والتوفيق | CV6: سعودي | CW6: ذكر | CX6: 1640 | CY6: 573 | CZ6: 78 | DA6: 0 | DB6: 747 | DC6: =SUM(CX6:DB6) -> 3038 | DD6: 48 | DE6: 744 | DF6: 0 | DG6: =SUM(DD6:DF6) -> 792 | DI6: الربيع والتوفيق | DJ6: سعودي | DK6: ذكر | DL6: 882 | DM6: 210 | DN6: 123 | DO6: 0 | DP6: 474 | DQ6: =SUM(DL6:DP6) -> 1689 | DR6: 54 | DS6: 356 | DT6: 0 | DU6: =SUM(DR6:DT6) -> 410 | DW6: الربيع والتوفيق | DX6: سعودي | DY6: ذكر | DZ6: 2128 | EA6: 66 | EB6: 0 | EC6: 0 | ED6: 500 | EE6: =SUM(DZ6:ED6) -> 2694 | EF6: 85 | EG6: 586 | EH6: 0 | EI6: =SUM(EF6:EH6) -> 671 | EK6: الربيع والتوفيق | EL6: سعودي | EM6: ذكر | EN6: 0 | EO6: 0 | EP6: 0 | EQ6: 0 | ER6: 0 | ES6: =SUM(EN6:ER6) -> 0 | ET6: 0 | EU6: 0 | EV6: 0 | EW6: =SUM(ET6:EV6) -> 0 | EY6: الربيع والتوفيق | EZ6: سعودي | FA6: ذكر | FB6: 0 | FC6: 0 | FD6: 0 | FE6: 0 | FF6: 0 | FG6: =SUM(FB6:FF6) -> 0 | FH6: 0 | FI6: 0 | FJ6: 0 | FK6: =SUM(FH6:FJ6) -> 0 | FM6: =EY6 -> الربيع والتوفيق | FN6: سعودي | FO6: ذكر | FP6: =SUM(D6+R6+AF6+AT6+BH6+BV6+CJ6+CX6+DL6+DZ6+EN6+FB6) -> 17940 | FQ6: =SUM(E6+S6+AG6+AU6+BI6+BW6+CK6+CY6+DM6+EA6+EO6+FC6) -> 3439 | FR6: =SUM(F6+T6+AH6+AV6+BJ6+BX6+CL6+CZ6+DN6+EB6+EP6+FD6) -> 1306 | FS6: =SUM(G6+U6+AI6+AW6+BK6+BY6+CM6+DA6+DO6+EC6+EQ6+FE6) -> 0 | FT6: =SUM(H6+V6+AJ6+AX6+BL6+BZ6+CN6+DB6+DP6+ED6+ER6+FF6) -> 5205 | FU6: =SUM(FP6:FT6) -> 27890 | FV6: =SUM(J6+X6+AL6+AZ6+BN6+CB6+CP6+DD6+DR6+EF6+ET6+FH6) -> 997 | FW6: =SUM(K6+Y6+AM6+BA6+BO6+CC6+CQ6+DE6+DS6+EG6+EU6+FI6) -> 6315 | FX6: =SUM(L6+Z6+AN6+BB6+BP6+CD6+CR6+DF6+DT6+EH6+EV6+FJ6) -> 0 | FY6: =SUM(FV6:FX6) -> 7312
C7: أنثى | D7: 2698 | E7: 201 | F7: 261 | G7: 5 | H7: 489 | I7: 3654 | J7: 85 | K7: 750 | L7: 0 | M7: =SUM(J7:L7) -> 835 | Q7: أنثى | R7: 2470 | S7: 182 | T7: 219 | U7: 32 | V7: 585 | W7: 2470 | X7: 102 | Y7: 862 | Z7: 0 | AA7: =SUM(X7:Z7) -> 964 | AE7: أنثى | AF7: 2530 | AG7: 777 | AH7: 145 | AI7: 19 | AJ7: 379 | AK7: 3850 | AL7: 95 | AM7: 745 | AN7: 0 | AO7: =SUM(AL7:AN7) -> 840 | AS7: أنثى | AT7: 633 | AU7: 425 | AV7: 274 | AW7: 29 | AX7: 910 | AY7: 2271 | AZ7: 63 | BA7: 1080 | BB7: 0 | BC7: 1143 | BG7: أنثى | BH7: 1208 | BI7: 348 | BJ7: 255 | BK7: 3 | BL7: 301 | BM7: 2115 | BN7: 140 | BO7: 432 | BP7: 0 | BQ7: =SUM(BN7:BP7) -> 572 | BU7: أنثى | BV7: 1380 | BW7: 465 | BX7: 113 | BY7: 15 | BZ7: 824 | CA7: 2797 | CB7: 32 | CC7: 1081 | CD7: 0 | CE7: =SUM(CB7:CD7) -> 1113 | CI7: أنثى | CJ7: 1800 | CK7: 5 | CL7: 265 | CM7: 26 | CN7: 436 | CO7: 750 | CP7: 0 | CQ7: 835 | CR7: 0 | CS7: 835 | CW7: أنثى | CX7: 1380 | CY7: 465 | CZ7: 113 | DA7: 15 | DB7: 824 | DC7: =SUM(CX7:DB7) -> 2797 | DD7: 32 | DE7: 1081 | DF7: 0 | DG7: =SUM(DD7:DF7) -> 1113 | DK7: أنثى | DL7: 1032 | DM7: 223 | DN7: 204 | DO7: 147 | DP7: 520 | DQ7: =SUM(DL7:DP7) -> 2126 | DR7: 88 | DS7: 250 | DT7: 0 | DU7: =SUM(DR7:DT7) -> 338 | DY7: أنثى | DZ7: 2715 | EA7: 60 | EB7: 0 | EC7: 2 | ED7: 216 | EE7: =SUM(DZ7:ED7) -> 2993 | EF7: 81 | EG7: 747 | EH7: 0 | EI7: =SUM(EF7:EH7) -> 828 | EM7: أنثى | EN7: 0 | EO7: 0 | EP7: 0 | EQ7: 0 | ER7: 0 | ES7: =SUM(EN7:ER7) -> 0 | ET7: 0 | EU7: 0 | EV7: 0 | EW7: =SUM(ET7:EV7) -> 0 | FA7: أنثى | FB7: 0 | FC7: 0 | FD7: 0 | FE7: 0 | FF7: 0 | FG7: =SUM(FB7:FF7) -> 0 | FH7: 0 | FI7: 0 | FJ7: 0 | FK7: =SUM(FH7:FJ7) -> 0 | FO7: أنثى | FP7: =SUM(D7+R7+AF7+AT7+BH7+BV7+CJ7+CX7+DL7+DZ7+EN7+FB7) -> 17846 | FQ7: =SUM(E7+S7+AG7+AU7+BI7+BW7+CK7+CY7+DM7+EA7+EO7+FC7) -> 3151 | FR7: =SUM(F7+T7+AH7+AV7+BJ7+BX7+CL7+CZ7+DN7+EB7+EP7+FD7) -> 1849 | FS7: =SUM(G7+U7+AI7+AW7+BK7+BY7+CM7+DA7+DO7+EC7+EQ7+FE7) -> 293 | FT7: =SUM(H7+V7+AJ7+AX7+BL7+BZ7+CN7+DB7+DP7+ED7+ER7+FF7) -> 5484 | FU7: =SUM(FP7:FT7) -> 28623 | FV7: =SUM(J7+X7+AL7+AZ7+BN7+CB7+CP7+DD7+DR7+EF7+ET7+FH7) -> 718 | FW7: =SUM(K7+Y7+AM7+BA7+BO7+CC7+CQ7+DE7+DS7+EG7+EU7+FI7) -> 7863 | FX7: =SUM(L7+Z7+AN7+BB7+BP7+CD7+CR7+DF7+DT7+EH7+EV7+FJ7) -> 0 | FY7: =SUM(FV7:FX7) -> 8581
B8: مجموع السعوديين | D8: 4809 | E8: 352 | F8: 443 | G8: 5 | H8: 987 | I8: 6596 | J8: 171 | K8: 1347 | L8: 0 | M8: =SUM(M6:M7) -> 1518 | P8: مجموع السعوديين | R8: 4592 | S8: 314 | T8: 342 | U8: 32 | V8: 1107 | W8: 4592 | X8: 196 | Y8: 1614 | Z8: 0 | AA8: =SUM(AA6:AA7) -> 1810 | AD8: مجموع السعوديين | AF8: 2350 | AG8: 1642 | AH8: 290 | AI8: 19 | AJ8: 767 | AK8: 7403 | AL8: 249 | AM8: 1310 | AN8: 0 | AO8: =SUM(AO6:AO7) -> 1559 | AR8: مجموع السعوديين | AT8: 2153 | AU8: 962 | AV8: 493 | AW8: 29 | AX8: 1554 | AY8: 5191 | AZ8: 289 | BA8: 1824 | BB8: 0 | BC8: 2113 | BF8: مجموع السعوديين | BH8: 3060 | BI8: 680 | BJ8: 440 | BK8: 3 | BL8: 586 | BM8: 4769 | BN8: 342 | BO8: 976 | BP8: 0 | BQ8: =SUM(BQ6:BQ7) -> 1318 | BT8: مجموع السعوديين | BV8: 3020 | BW8: 1038 | BX8: 191 | BY8: 15 | BZ8: 1571 | CA8: 5835 | CB8: 80 | CC8: 1825 | CD8: 0 | CE8: =SUM(CE6:CE7) -> 1905 | CH8: مجموع السعوديين | CJ8: 3690 | CK8: 5 | CL8: 438 | CM8: 26 | CN8: 836 | CO8: 1347 | CP8: 0 | CQ8: 1518 | CR8: 0 | CS8: 1518 | CV8: مجموع السعوديين | CX8: =SUM(CX6:CX7) -> 3020 | CY8: =SUM(CY6:CY7) -> 1038 | CZ8: =SUM(CZ6:CZ7) -> 191 | DA8: =SUM(DA6:DA7) -> 15 | DB8: =SUM(DB6:DB7) -> 1571 | DC8: =SUM(DC6:DC7) -> 5835 | DD8: =SUM(DD6:DD7) -> 80 | DE8: =SUM(DE6:DE7) -> 1825 | ... DG8: =SUM(DG6:DG7) -> 1905 | DJ8: مجموع السعوديين | DL8: =SUM(DL6:DL7) -> 1914 | DM8: =SUM(DM6:DM7) -> 433 | DN8: =SUM(DN6:DN7) -> 327 | DO8: =SUM(DO6:DO7) -> 147 | DP8: =SUM(DP6:DP7) -> 994 | DQ8: =SUM(DQ6:DQ7) -> 3815 | DR8: =SUM(DR6:DR7) -> 142 | DS8: =SUM(DS6:DS7) -> 606 | ... DU8: =SUM(DU6:DU7) -> 748 | DX8: مجموع السعوديين | DZ8: =SUM(DZ6:DZ7) -> 4843 | EA8: =SUM(EA6:EA7) -> 126 | EB8: =SUM(EB6:EB7) -> 0 | EC8: =SUM(EC6:EC7) -> 2 | ED8: =SUM(ED6:ED7) -> 716 | EE8: =SUM(EE6:EE7) -> 5687 | EF8: =SUM(EF6:EF7) -> 166 | EG8: =SUM(EG6:EG7) -> 1333 | ... EI8: =SUM(EI6:EI7) -> 1499 | EL8: مجموع السعوديين | EN8: =SUM(EN6:EN7) -> 0 | EO8: =SUM(EO6:EO7) -> 0 | EP8: =SUM(EP6:EP7) -> 0 | EQ8: =SUM(EQ6:EQ7) -> 0 | ER8: =SUM(ER6:ER7) -> 0 | ES8: =SUM(ES6:ES7) -> 0 | ET8: =SUM(ET6:ET7) -> 0 | EU8: =SUM(EU6:EU7) -> 0 | ... EW8: =SUM(EW6:EW7) -> 0 | EZ8: مجموع السعوديين | FB8: =SUM(FB6:FB7) -> 0 | FC8: =SUM(FC6:FC7) -> 0 | FD8: =SUM(FD6:FD7) -> 0 | FE8: =SUM(FE6:FE7) -> 0 | FF8: =SUM(FF6:FF7) -> 0 | FG8: =SUM(FG6:FG7) -> 0 | FH8: =SUM(FH6:FH7) -> 0 | FI8: =SUM(FI6:FI7) -> 0 | ... FK8: =SUM(FK6:FK7) -> 0 | FN8: مجموع السعوديين | FP8: =SUM(FP6:FP7) -> 35786 | FQ8: =SUM(FQ6:FQ7) -> 6590 | FR8: =SUM(FR6:FR7) -> 3155 | FS8: =SUM(FS6:FS7) -> 293 | FT8: =SUM(FT6:FT7) -> 10689 | FU8: =SUM(FU6:FU7) -> 56513 | FV8: =SUM(FV6:FV7) -> 1715 | FW8: =SUM(FW6:FW7) -> 14178 | ... FY8: =SUM(FY6:FY7) -> 15893
B9: غير سعودي | C9: ذكر | D9: 308 | E9: 0 | F9: 0 | G9: 0 | H9: 51 | I9: 359 | J9: 1 | K9: 8 | L9: 0 | M9: =SUM(J9:L9) -> 9 | P9: غير سعودي | Q9: ذكر | R9: 213 | S9: 0 | T9: 0 | U9: 0 | V9: 1 | W9: 213 | X9: 29 | Y9: 9 | Z9: 0 | AA9: =SUM(X9:Z9) -> 38 | AD9: غير سعودي | AE9: ذكر | AF9: 0 | AG9: 255 | AH9: 0 | AI9: 0 | AJ9: 47 | AK9: 302 | AL9: 45 | AM9: 215 | AN9: 0 | AO9: =SUM(AL9:AN9) -> 260 | AR9: غير سعودي | AS9: ذكر | AT9: 99 | AU9: 291 | AV9: 0 | AW9: 0 | AX9: 0 | AY9: 390 | AZ9: 31 | BA9: 386 | BB9: 0 | BC9: 417 | BF9: غير سعودي | BG9: ذكر | BH9: 255 | BI9: 73 | BJ9: 0 | BK9: 0 | BL9: 42 | BM9: 370 | BN9: 22 | BO9: 88 | BP9: 0 | BQ9: =SUM(BN9:BP9) -> 110 | BT9: غير سعودي | BU9: ذكر | BV9: 475 | BW9: 153 | BX9: 0 | BY9: 0 | BZ9: 0 | CA9: 628 | CB9: 9 | CC9: 386 | CD9: 0 | CE9: =SUM(CB9:CD9) -> 395 | CH9: غير سعودي | CI9: ذكر | CJ9: 88 | CK9: 0 | CL9: 0 | CM9: 0 | CN9: 73 | CO9: 8 | CP9: 0 | CQ9: 9 | CR9: 0 | CS9: 9 | CV9: غير سعودي | CW9: ذكر | CX9: 475 | CY9: 153 | CZ9: 0 | DA9: 0 | DB9: 0 | DC9: =SUM(CX9:DB9) -> 628 | DD9: 9 | DE9: 386 | DF9: 0 | DG9: =SUM(DD9:DF9) -> 395 | DJ9: غير سعودي | DK9: ذكر | DL9: 416 | DM9: 90 | DN9: 0 | DO9: 0 | DP9: 228 | DQ9: =SUM(DL9:DP9) -> 734 | DR9: 17 | DS9: 0 | DT9: 0 | DU9: =SUM(DR9:DT9) -> 17 | DX9: غير سعودي | DY9: ذكر | DZ9: 506 | EA9: 11 | EB9: 0 | EC9: 0 | ED9: 59 | EE9: =SUM(DZ9:ED9) -> 576 | EF9: 18 | EG9: 173 | EH9: 0 | EI9: =SUM(EF9:EH9) -> 191 | EL9: غير سعودي | EM9: ذكر | EN9: 0 | EO9: 0 | EP9: 0 | EQ9: 0 | ER9: 0 | ES9: =SUM(EN9:ER9) -> 0 | ET9: 0 | EU9: 0 | EV9: 0 | EW9: =SUM(ET9:EV9) -> 0 | EZ9: غير سعودي | FA9: ذكر | FB9: 0 | FC9: 0 | FD9: 0 | FE9: 0 | FF9: 0 | FG9: =SUM(FB9:FF9) -> 0 | FH9: 0 | FI9: 0 | FJ9: 0 | FK9: =SUM(FH9:FJ9) -> 0 | FN9: غير سعودي | FO9: ذكر | FP9: =SUM(D9+R9+AF9+AT9+BH9+BV9+CJ9+CX9+DL9+DZ9+EN9+FB9) -> 2835 | FQ9: =SUM(E9+S9+AG9+AU9+BI9+BW9+CK9+CY9+DM9+EA9+EO9+FC9) -> 1026 | FR9: =SUM(F9+T9+AH9+AV9+BJ9+BX9+CL9+CZ9+DN9+EB9+EP9+FD9) -> 0 | FS9: =SUM(G9+U9+AI9+AW9+BK9+BY9+CM9+DA9+DO9+EC9+EQ9+FE9) -> 0 | FT9: =SUM(H9+V9+AJ9+AX9+BL9+BZ9+CN9+DB9+DP9+ED9+ER9+FF9) -> 501 | FU9: =SUM(FP9:FT9) -> 4362 | FV9: =SUM(J9+X9+AL9+AZ9+BN9+CB9+CP9+DD9+DR9+EF9+ET9+FH9) -> 181 | FW9: =SUM(K9+Y9+AM9+BA9+BO9+CC9+CQ9+DE9+DS9+EG9+EU9+FI9) -> 1660 | FX9: =SUM(L9+Z9+AN9+BB9+BP9+CD9+CR9+DF9+DT9+EH9+EV9+FJ9) -> 0 | FY9: =SUM(FV9:FX9) -> 1841
C10: أنثى | D10: 301 | E10: 0 | F10: 0 | G10: 0 | H10: 42 | I10: 343 | J10: 1 | K10: 8 | L10: 0 | M10: =SUM(J10:L10) -> 9 | Q10: أنثى | R10: 170 | S10: 0 | T10: 0 | U10: 6 | V10: 1 | W10: 170 | X10: 7 | Y10: 9 | Z10: 0 | AA10: =SUM(X10:Z10) -> 16 | AE10: أنثى | AF10: 0 | AG10: 156 | AH10: 0 | AI10: 4 | AJ10: 15 | AK10: 175 | AL10: 30 | AM10: 195 | AN10: 0 | AO10: =SUM(AL10:AN10) -> 225 | AS10: أنثى | AT10: 89 | AU10: 169 | AV10: 0 | AW10: 4 | AX10: 0 | AY10: 262 | AZ10: 39 | BA10: 677 | BB10: 0 | BC10: 716 | BG10: أنثى | BH10: 227 | BI10: 31 | BJ10: 0 | BK10: 0 | BL10: 70 | BM10: 328 | BN10: 11 | BO10: 89 | BP10: 0 | BQ10: =SUM(BN10:BP10) -> 100 | BU10: أنثى | BV10: 453 | BW10: 124 | BX10: 0 | BY10: 4 | BZ10: 0 | CA10: 581 | CB10: 3 | CC10: 677 | CD10: 0 | CE10: =SUM(CB10:CD10) -> 680 | CI10: أنثى | CJ10: 100 | CK10: 0 | CL10: 0 | CM10: 343 | CN10: 110 | CO10: 8 | CP10: 0 | CQ10: 9 | CR10: 0 | CS10: 9 | CW10: أنثى | CX10: 453 | CY10: 142 | CZ10: 0 | DA10: 0 | DB10: 0 | DC10: =SUM(CX10:DB10) -> 595 | DD10: 3 | DE10: 677 | DF10: 0 | DG10: =SUM(DD10:DF10) -> 680 | DK10: أنثى | DL10: 616 | DM10: 147 | DN10: 0 | DO10: 0 | DP10: 200 | DQ10: =SUM(DL10:DP10) -> 963 | DR10: 3 | DS10: 0 | DT10: 0 | DU10: =SUM(DR10:DT10) -> 3 | DY10: أنثى | DZ10: 396 | EA10: 9 | EB10: 0 | EC10: 1 | ED10: 53 | EE10: =SUM(DZ10:ED10) -> 459 | EF10: 10 | EG10: 294 | EH10: 0 | EI10: =SUM(EF10:EH10) -> 304 | EM10: أنثى | EN10: 0 | EO10: 0 | EP10: 0 | EQ10: 0 | ER10: 0 | ES10: =SUM(EN10:ER10) -> 0 | ET10: 0 | EU10: 0 | EV10: 0 | EW10: =SUM(ET10:EV10) -> 0 | FA10: أنثى | FB10: 0 | FC10: 0 | FD10: 0 | FE10: 0 | FF10: 0 | FG10: =SUM(FB10:FF10) -> 0 | FH10: 0 | FI10: 0 | FJ10: 0 | FK10: =SUM(FH10:FJ10) -> 0 | FO10: أنثى | FP10: =SUM(D10+R10+AF10+AT10+BH10+BV10+CJ10+CX10+DL10+DZ10+EN10+FB10) -> 2805 | FQ10: =SUM(E10+S10+AG10+AU10+BI10+BW10+CK10+CY10+DM10+EA10+EO10+FC10) -> 778 | FR10: =SUM(F10+T10+AH10+AV10+BJ10+BX10+CL10+CZ10+DN10+EB10+EP10+FD10) -> 0 | FS10: =SUM(G10+U10+AI10+AW10+BK10+BY10+CM10+DA10+DO10+EC10+EQ10+FE10) -> 362 | FT10: =SUM(H10+V10+AJ10+AX10+BL10+BZ10+CN10+DB10+DP10+ED10+ER10+FF10) -> 491 | FU10: =SUM(FP10:FT10) -> 4436 | FV10: =SUM(J10+X10+AL10+AZ10+BN10+CB10+CP10+DD10+DR10+EF10+ET10+FH10) -> 107 | FW10: =SUM(K10+Y10+AM10+BA10+BO10+CC10+CQ10+DE10+DS10+EG10+EU10+FI10) -> 2635 | FX10: =SUM(L10+Z10+AN10+BB10+BP10+CD10+CR10+DF10+DT10+EH10+EV10+FJ10) -> 0 | FY10: =SUM(FV10:FX10) -> 2742
B11: مجموع غ.سعودي | D11: =SUM(D9:D10) -> 609 | E11: =SUM(E9:E10) -> 0 | F11: =SUM(F9:F10) -> 0 | G11: =SUM(G9:G10) -> 0 | H11: =SUM(H9:H10) -> 93 | I11: =SUM(I9:I10) -> 702 | J11: =SUM(J9:J10) -> 2 | K11: =SUM(K9:K10) -> 16 | ... M11: =SUM(M9:M10) -> 18 | P11: مجموع غ.سعودي | R11: =SUM(R9:R10) -> 383 | S11: =SUM(S9:S10) -> 0 | T11: =SUM(T9:T10) -> 0 | U11: =SUM(U9:U10) -> 6 | V11: =SUM(V9:V10) -> 2 | W11: =SUM(W9:W10) -> 383 | X11: =SUM(X9:X10) -> 36 | Y11: =SUM(Y9:Y10) -> 18 | ... AA11: =SUM(AA9:AA10) -> 54 | AD11: مجموع غ.سعودي | AF11: 0 | AG11: 411 | AH11: 0 | AI11: 4 | AJ11: 62 | AK11: 477 | AL11: 75 | AM11: 410 | AN11: 0 | AO11: =SUM(AO9:AO10) -> 485 | AR11: مجموع غ.سعودي | AT11: =SUM(AT9:AT10) -> 188 | AU11: =SUM(AU9:AU10) -> 460 | AV11: =SUM(AV9:AV10) -> 0 | AW11: =SUM(AW9:AW10) -> 4 | AX11: =SUM(AX9:AX10) -> 0 | AY11: =SUM(AY9:AY10) -> 652 | AZ11: =SUM(AZ9:AZ10) -> 70 | BA11: =SUM(BA9:BA10) -> 1063 | ... BC11: =SUM(BC9:BC10) -> 1133 | BF11: مجموع غ.سعودي | BH11: =SUM(BH9:BH10) -> 482 | BI11: =SUM(BI9:BI10) -> 104 | BJ11: =SUM(BJ9:BJ10) -> 0 | BK11: =SUM(BK9:BK10) -> 0 | BL11: =SUM(BL9:BL10) -> 112 | BM11: =SUM(BM9:BM10) -> 698 | BN11: =SUM(BN9:BN10) -> 33 | BO11: =SUM(BO9:BO10) -> 177 | ... BQ11: =SUM(BQ9:BQ10) -> 210 | BT11: مجموع غ.سعودي | BV11: 928 | BW11: 277 | BX11: 0 | BY11: 4 | BZ11: 0 | CA11: 1209 | CB11: 12 | CC11: 1063 | CD11: 0 | CE11: =SUM(CE9:CE10) -> 1075 | CH11: مجموع غ.سعودي | CJ11: 188 | CK11: 0 | CL11: 0 | CM11: 343 | CN11: 183 | CO11: 16 | CP11: 0 | CQ11: 18 | CR11: 0 | CS11: 18 | CV11: مجموع غ.سعودي | CX11: =SUM(CX9:CX10) -> 928 | CY11: =SUM(CY9:CY10) -> 295 | CZ11: =SUM(CZ9:CZ10) -> 0 | DA11: =SUM(DA9:DA10) -> 0 | DB11: =SUM(DB9:DB10) -> 0 | DC11: =SUM(DC9:DC10) -> 1223 | DD11: =SUM(DD9:DD10) -> 12 | DE11: =SUM(DE9:DE10) -> 1063 | ... DG11: =SUM(DG9:DG10) -> 1075 | DJ11: مجموع غ.سعودي | DL11: =SUM(DL9:DL10) -> 1032 | DM11: =SUM(DM9:DM10) -> 237 | DN11: =SUM(DN9:DN10) -> 0 | DO11: =SUM(DO9:DO10) -> 0 | DP11: =SUM(DP9:DP10) -> 428 | DQ11: =SUM(DQ9:DQ10) -> 1697 | DR11: =SUM(DR9:DR10) -> 20 | DS11: =SUM(DS9:DS10) -> 0 | ... DU11: =SUM(DU9:DU10) -> 20 | DX11: مجموع غ.سعودي | DZ11: =SUM(DZ9:DZ10) -> 902 | EA11: =SUM(EA9:EA10) -> 20 | EB11: =SUM(EB9:EB10) -> 0 | EC11: =SUM(EC9:EC10) -> 1 | ED11: =SUM(ED9:ED10) -> 112 | EE11: =SUM(EE9:EE10) -> 1035 | EF11: =SUM(EF9:EF10) -> 28 | EG11: =SUM(EG9:EG10) -> 467 | ... EI11: =SUM(EI9:EI10) -> 495 | EL11: مجموع غ.سعودي | EN11: =SUM(EN9:EN10) -> 0 | EO11: =SUM(EO9:EO10) -> 0 | EP11: =SUM(EP9:EP10) -> 0 | EQ11: =SUM(EQ9:EQ10) -> 0 | ER11: =SUM(ER9:ER10) -> 0 | ES11: =SUM(ES9:ES10) -> 0 | ET11: =SUM(ET9:ET10) -> 0 | EU11: =SUM(EU9:EU10) -> 0 | ... EW11: =SUM(EW9:EW10) -> 0 | EZ11: مجموع غ.سعودي | FB11: =SUM(FB9:FB10) -> 0 | FC11: =SUM(FC9:FC10) -> 0 | FD11: =SUM(FD9:FD10) -> 0 | FE11: =SUM(FE9:FE10) -> 0 | FF11: =SUM(FF9:FF10) -> 0 | FG11: =SUM(FG9:FG10) -> 0 | FH11: =SUM(FH9:FH10) -> 0 | FI11: =SUM(FI9:FI10) -> 0 | ... FK11: =SUM(FK9:FK10) -> 0 | FN11: مجموع غ.سعودي | FP11: =SUM(FP9:FP10) -> 5640 | FQ11: =SUM(FQ9:FQ10) -> 1804 | FR11: =SUM(FR9:FR10) -> 0 | FS11: =SUM(FS9:FS10) -> 362 | FT11: =SUM(FT9:FT10) -> 992 | FU11: =SUM(FU9:FU10) -> 8798 | FV11: =SUM(FV9:FV10) -> 288 | FW11: =SUM(FW9:FW10) -> 4295 | ... FY11: =SUM(FY9:FY10) -> 4583
A12: المجموع الكلي | D12: =SUM(D11+D8) -> 5418 | E12: =SUM(E11+E8) -> 352 | F12: =SUM(F11+F8) -> 443 | G12: =SUM(G11+G8) -> 5 | H12: =SUM(H11+H8) -> 1080 | I12: =SUM(I8+I11) -> 7298 | J12: =SUM(J11+J8) -> 173 | K12: =SUM(K11+K8) -> 1363 | L12: =SUM(L11+L8) -> 0 | M12: =SUM(M11+M8) -> 1536 | O12: المجموع الكلي | R12: =SUM(R11+R8) -> 4975 | S12: =SUM(S11+S8) -> 314 | T12: =SUM(T11+T8) -> 342 | U12: =SUM(U11+U8) -> 38 | V12: =SUM(V11+V8) -> 1109 | W12: =SUM(W8+W11) -> 4975 | X12: =SUM(X11+X8) -> 232 | Y12: =SUM(Y11+Y8) -> 1632 | Z12: =SUM(Z11+Z8) -> 0 | AA12: =SUM(AA11+AA8) -> 1864 | AC12: المجموع الكلي | AF12: 2350 | AG12: 2053 | AH12: 290 | AI12: 23 | AJ12: 829 | AK12: 7880 | AL12: 324 | AM12: 1720 | AN12: 0 | AO12: =SUM(AO11+AO8) -> 2044 | AQ12: المجموع الكلي | AT12: =SUM(AT11+AT8) -> 2341 | AU12: =SUM(AU11+AU8) -> 1422 | AV12: =SUM(AV11+AV8) -> 493 | AW12: =SUM(AW11+AW8) -> 33 | AX12: =SUM(AX11+AX8) -> 1554 | AY12: =SUM(AY8+AY11) -> 5843 | AZ12: =SUM(AZ11+AZ8) -> 359 | BA12: =SUM(BA11+BA8) -> 2887 | BB12: =SUM(BB11+BB8) -> 0 | BC12: =SUM(BC11+BC8) -> 3246 | BE12: المجموع الكلي | BH12: =SUM(BH11+BH8) -> 3542 | BI12: =SUM(BI11+BI8) -> 784 | BJ12: =SUM(BJ11+BJ8) -> 440 | BK12: =SUM(BK11+BK8) -> 3 | BL12: =SUM(BL11+BL8) -> 698 | BM12: =SUM(BM8+BM11) -> 5467 | BN12: =SUM(BN11+BN8) -> 375 | BO12: =SUM(BO11+BO8) -> 1153 | BP12: =SUM(BP11+BP8) -> 0 | BQ12: =SUM(BQ11+BQ8) -> 1528 | BS12: المجموع الكلي | BV12: 3948 | BW12: 1315 | BX12: 191 | BY12: 19 | BZ12: 1571 | CA12: 7044 | CB12: 92 | CC12: 2888 | CD12: 0 | CE12: =SUM(CE11+CE8) -> 2980 | CG12: المجموع الكلي | CJ12: 3878 | CK12: 5 | CL12: 438 | CM12: 369 | CN12: 1019 | CO12: 1363 | CP12: 0 | CQ12: 1536 | CR12: 0 | CS12: 1536 | CU12: المجموع الكلي | CX12: =SUM(CX11+CX8) -> 3948 | CY12: =SUM(CY11+CY8) -> 1333 | CZ12: =SUM(CZ11+CZ8) -> 191 | DA12: =SUM(DA11+DA8) -> 15 | DB12: =SUM(DB11+DB8) -> 1571 | DC12: =SUM(DC8+DC11) -> 7058 | DD12: =SUM(DD11+DD8) -> 92 | DE12: =SUM(DE11+DE8) -> 2888 | DF12: =SUM(DF11+DF8) -> 0 | DG12: =SUM(DG11+DG8) -> 2980 | DI12: المجموع الكلي | DL12: =SUM(DL11+DL8) -> 2946 | DM12: =SUM(DM11+DM8) -> 670 | DN12: =SUM(DN11+DN8) -> 327 | DO12: =SUM(DO11+DO8) -> 147 | DP12: =SUM(DP11+DP8) -> 1422 | DQ12: =SUM(DQ8+DQ11) -> 5512 | DR12: =SUM(DR11+DR8) -> 162 | DS12: =SUM(DS11+DS8) -> 606 | DT12: =SUM(DT11+DT8) -> 0 | DU12: =SUM(DU11+DU8) -> 768 | DW12: المجموع الكلي | DZ12: =SUM(DZ11+DZ8) -> 5745 | EA12: =SUM(EA11+EA8) -> 146 | EB12: =SUM(EB11+EB8) -> 0 | EC12: =SUM(EC11+EC8) -> 3 | ED12: =SUM(ED11+ED8) -> 828 | EE12: =SUM(EE8+EE11) -> 6722 | EF12: =SUM(EF11+EF8) -> 194 | EG12: =SUM(EG11+EG8) -> 1800 | EH12: =SUM(EH11+EH8) -> 0 | EI12: =SUM(EI11+EI8) -> 1994 | EK12: المجموع الكلي | EN12: =SUM(EN11+EN8) -> 0 | EO12: =SUM(EO11+EO8) -> 0 | EP12: =SUM(EP11+EP8) -> 0 | EQ12: =SUM(EQ11+EQ8) -> 0 | ER12: =SUM(ER11+ER8) -> 0 | ES12: =SUM(ES8+ES11) -> 0 | ET12: =SUM(ET11+ET8) -> 0 | EU12: =SUM(EU11+EU8) -> 0 | EV12: =SUM(EV11+EV8) -> 0 | EW12: =SUM(EW11+EW8) -> 0 | EY12: المجموع الكلي | FB12: =SUM(FB11+FB8) -> 0 | FC12: =SUM(FC11+FC8) -> 0 | FD12: =SUM(FD11+FD8) -> 0 | FE12: =SUM(FE11+FE8) -> 0 | FF12: =SUM(FF11+FF8) -> 0 | FG12: =SUM(FG8+FG11) -> 0 | FH12: =SUM(FH11+FH8) -> 0 | FI12: =SUM(FI11+FI8) -> 0 | FJ12: =SUM(FJ11+FJ8) -> 0 | FK12: =SUM(FK11+FK8) -> 0 | FM12: المجموع الكلي | FP12: =SUM(FP11+FP8) -> 41426 | FQ12: =SUM(FQ11+FQ8) -> 8394 | FR12: =SUM(FR11+FR8) -> 3155 | FS12: =SUM(FS11+FS8) -> 655 | FT12: =SUM(FT11+FT8) -> 11681 | FU12: =SUM(FU8+FU11) -> 65311 | FV12: =SUM(FV11+FV8) -> 2003 | FW12: =SUM(FW11+FW8) -> 18473 | FX12: =SUM(FX11+FX8) -> 0 | FY12: =SUM(FY11+FY8) -> 20476
A13: الجامعه | B13: سعودي | C13: ذكر | D13: 1086 | E13: 259 | F13: 107 | G13: 0 | H13: 239 | I13: 1691 | J13: 19 | K13: 260 | L13: 0 | M13: =SUM(J13:L13) -> 279 | O13: الجامعه | P13: سعودي | Q13: ذكر | R13: 2580 | S13: 148 | T13: 113 | U13: 0 | V13: 250 | W13: 3091 | X13: 11 | Y13: 290 | Z13: 0 | AA13: =SUM(X13:Z13) -> 301 | AC13: الجامعه | AD13: سعودي | AE13: ذكر | AF13: 2499 | AG13: 279 | AH13: 83 | AI13: 0 | AJ13: 223 | AK13: 3084 | AL13: 40 | AM13: 0 | AN13: 0 | AO13: =SUM(AL13:AN13) -> 40 | AQ13: الجامعه | AR13: سعودي | AS13: ذكر | AT13: 2781 | AU13: 209 | AV13: 160 | AW13: 0 | AX13: 259 | AY13: 3409 | AZ13: 30 | BA13: 457 | BB13: 0 | BC13: 487 | BE13: الجامعه | BF13: سعودي | BG13: ذكر | BH13: 1205 | BI13: 114 | BJ13: 71 | BK13: 0 | BL13: 136 | BM13: 1526 | BN13: 17 | BO13: 248 | BP13: 0 | BQ13: =SUM(BN13:BP13) -> 265 | BS13: الجامعه | BT13: سعودي | BU13: ذكر | BV13: 3924 | BW13: 294 | BX13: 140 | BY13: 0 | BZ13: 289 | CA13: 4647 | CC13: 863 | CD13: 0 | CE13: =SUM(CB13:CD13) -> 863 | CG13: الجامعه | CH13: سعودي | CI13: ذكر | CJ13: 1630 | CK13: 214 | CL13: 129 | CM13: 0 | CN13: 266 | CO13: 2239 | CP13: 18 | CQ13: 315 | CR13: 0 | CS13: 333 | CU13: الجامعه | CV13: سعودي | CW13: ذكر | CX13: 3924 | CY13: 294 | CZ13: 140 | DA13: 0 | DB13: 289 | DC13: 4647 | DD13: 890 | DE13: 4863 | DF13: 0 | DG13: =SUM(DD13:DF13) -> 5753 | DI13: الجامعه | DJ13: سعودي | DK13: ذكر | DL13: 1065 | DM13: 36 | DN13: 131 | DO13: 0 | DP13: 210 | DQ13: =SUM(DL13:DP13) -> 1442 | DR13: 12 | DS13: 265 | DT13: 0 | DU13: =SUM(DR13:DT13) -> 277 | DW13: الجامعه | DX13: سعودي | DY13: ذكر | DZ13: 0 | EA13: 0 | EB13: 0 | EC13: 0 | ED13: 0 | EE13: =SUM(DZ13:ED13) -> 0 | EF13: 0 | EG13: 0 | EH13: 0 | EI13: =SUM(EF13:EH13) -> 0 | EK13: الجامعه | EL13: سعودي | EM13: ذكر | EN13: 0 | EO13: 0 | EP13: 0 | EQ13: 0 | ER13: 0 | ES13: =SUM(EN13:ER13) -> 0 | ET13: 0 | EU13: 0 | EV13: 0 | EW13: =SUM(ET13:EV13) -> 0 | EY13: الجامعه | EZ13: سعودي | FA13: ذكر | FB13: 0 | FC13: 0 | FD13: 0 | FE13: 0 | FF13: 0 | FG13: =SUM(FB13:FF13) -> 0 | FH13: 0 | FI13: 0 | FJ13: 0 | FK13: =SUM(FH13:FJ13) -> 0 | FM13: =EY13 -> الجامعه | FN13: سعودي | FO13: ذكر | FP13: =SUM(D13+R13+AF13+AT13+BH13+BV13+CJ13+CX13+DL13+DZ13+EN13+FB13) -> 20694 | FQ13: =SUM(E13+S13+AG13+AU13+BI13+BW13+CK13+CY13+DM13+EA13+EO13+FC13) -> 1847 | FR13: =SUM(F13+T13+AH13+AV13+BJ13+BX13+CL13+CZ13+DN13+EB13+EP13+FD13) -> 1074 | FS13: =SUM(G13+U13+AI13+AW13+BK13+BY13+CM13+DA13+DO13+EC13+EQ13+FE13) -> 0 | FT13: =SUM(H13+V13+AJ13+AX13+BL13+BZ13+CN13+DB13+DP13+ED13+ER13+FF13) -> 2161 | FU13: =SUM(FP13:FT13) -> 25776 | FV13: =SUM(J13+X13+AL13+AZ13+BN13+CB13+CP13+DD13+DR13+EF13+ET13+FH13) -> 1037 | FW13: =SUM(K13+Y13+AM13+BA13+BO13+CC13+CQ13+DE13+DS13+EG13+EU13+FI13) -> 7561 | FX13: =SUM(L13+Z13+AN13+BB13+BP13+CD13+CR13+DF13+DT13+EH13+EV13+FJ13) -> 0 | FY13: =SUM(FV13:FX13) -> 8598
C14: أنثى | D14: 1018 | E14: 127 | F14: 183 | G14: 25 | H14: 265 | I14: 1618 | J14: 0 | K14: 353 | L14: 0 | M14: =SUM(J14:L14) -> 353 | Q14: أنثى | R14: 2125 | S14: 109 | T14: 186 | U14: 20 | V14: 230 | W14: 2670 | X14: 9 | Y14: 372 | Z14: 0 | AA14: =SUM(X14:Z14) -> 381 | AE14: أنثى | AF14: 2898 | AG14: 113 | AH14: 125 | AI14: 19 | AJ14: 233 | AK14: 3388 | AL14: 11 | AM14: 0 | AN14: 0 | AO14: =SUM(AL14:AN14) -> 11 | AS14: أنثى | AT14: 3119 | AU14: 109 | AV14: 238 | AW14: 22 | AX14: 240 | AY14: 3728 | AZ14: 12 | BA14: 544 | BB14: 0 | BC14: 556 | BG14: أنثى | BH14: 1486 | BI14: 75 | BJ14: 102 | BK14: 18 | BL14: 147 | BM14: 1828 | BN14: 6 | BO14: 336 | BP14: 0 | BQ14: =SUM(BN14:BP14) -> 342 | BU14: أنثى | BV14: 4824 | BW14: 137 | BX14: 179 | BY14: 25 | BZ14: 265 | CA14: 998 | CC14: 637 | CD14: 0 | CE14: =SUM(CB14:CD14) -> 637 | CI14: أنثى | CJ14: 1515 | CK14: 108 | CL14: 213 | CM14: 18 | CN14: 239 | CO14: 2093 | CP14: 7 | CQ14: 369 | CR14: 0 | CS14: 376 | CW14: أنثى | CX14: 4824 | CY14: 137 | CZ14: 179 | DA14: 275 | DB14: 265 | DC14: 998 | DD14: 876 | DE14: 6374 | DF14: 0 | DG14: =SUM(DD14:DF14) -> 7250 | DK14: أنثى | DL14: 968 | DM14: 24 | DN14: 161 | DO14: 18 | DP14: 196 | DQ14: =SUM(DL14:DP14) -> 1367 | DR14: 15 | DS14: 360 | DT14: 0 | DU14: =SUM(DR14:DT14) -> 375 | DY14: أنثى | DZ14: 0 | EA14: 0 | EB14: 0 | EC14: 0 | ED14: 0 | EE14: =SUM(DZ14:ED14) -> 0 | EF14: 0 | EG14: 0 | EH14: 0 | EI14: =SUM(EF14:EH14) -> 0 | EM14: أنثى | EN14: 0 | EO14: 0 | EP14: 0 | EQ14: 0 | ER14: 0 | ES14: =SUM(EN14:ER14) -> 0 | ET14: 0 | EU14: 0 | EV14: 0 | EW14: =SUM(ET14:EV14) -> 0 | FA14: أنثى | FB14: 0 | FC14: 0 | FD14: 0 | FE14: 0 | FF14: 0 | FG14: =SUM(FB14:FF14) -> 0 | FH14: 0 | FI14: 0 | FJ14: 0 | FK14: =SUM(FH14:FJ14) -> 0 | FO14: أنثى | FP14: =SUM(D14+R14+AF14+AT14+BH14+BV14+CJ14+CX14+DL14+DZ14+EN14+FB14) -> 22777 | FQ14: =SUM(E14+S14+AG14+AU14+BI14+BW14+CK14+CY14+DM14+EA14+EO14+FC14) -> 939 | FR14: =SUM(F14+T14+AH14+AV14+BJ14+BX14+CL14+CZ14+DN14+EB14+EP14+FD14) -> 1566 | FS14: =SUM(G14+U14+AI14+AW14+BK14+BY14+CM14+DA14+DO14+EC14+EQ14+FE14) -> 440 | FT14: =SUM(H14+V14+AJ14+AX14+BL14+BZ14+CN14+DB14+DP14+ED14+ER14+FF14) -> 2080 | FU14: =SUM(FP14:FT14) -> 27802 | FV14: =SUM(J14+X14+AL14+AZ14+BN14+CB14+CP14+DD14+DR14+EF14+ET14+FH14) -> 936 | FW14: =SUM(K14+Y14+AM14+BA14+BO14+CC14+CQ14+DE14+DS14+EG14+EU14+FI14) -> 9345 | FX14: =SUM(L14+Z14+AN14+BB14+BP14+CD14+CR14+DF14+DT14+EH14+EV14+FJ14) -> 0 | FY14: =SUM(FV14:FX14) -> 10281
B15: مجموع السعوديين | D15: 2104 | E15: 386 | F15: 290 | G15: 25 | H15: 504 | I15: 3309 | J15: 19 | K15: 613 | L15: 0 | M15: =SUM(M13:M14) -> 632 | P15: مجموع السعوديين | R15: 4705 | S15: 257 | T15: 299 | U15: 20 | V15: 480 | W15: 5761 | X15: 20 | Y15: 662 | Z15: 0 | AA15: =SUM(AA13:AA14) -> 682 | AD15: مجموع السعوديين | AF15: 5397 | AG15: 392 | AH15: 208 | AI15: 19 | AJ15: 456 | AK15: 6472 | AL15: 51 | AM15: 0 | AN15: 0 | AO15: =SUM(AO13:AO14) -> 51 | AR15: مجموع السعوديين | AT15: 5900 | AU15: 318 | AV15: 398 | AW15: 22 | AX15: 499 | AY15: 7137 | AZ15: 42 | BA15: 1001 | BB15: 0 | BC15: 1043 | BF15: مجموع السعوديين | BH15: 2691 | BI15: 189 | BJ15: 173 | BK15: 18 | BL15: 283 | BM15: 3354 | BN15: 23 | BO15: 584 | BP15: 0 | BQ15: =SUM(BQ13:BQ14) -> 607 | BT15: مجموع السعوديين | BV15: 8748 | BW15: 431 | BX15: 319 | BY15: 275 | BZ15: 554 | CA15: 5645 | CC15: 1500 | CD15: 0 | CE15: =SUM(CE13:CE14) -> 1500 | CH15: مجموع السعوديين | CJ15: 3145 | CK15: 322 | CL15: 342 | CM15: 18 | CN15: 505 | CO15: 4332 | CP15: 25 | CQ15: 684 | CR15: 0 | CS15: 709 | CV15: مجموع السعوديين | CX15: =SUM(CX13:CX14) -> 8748 | CY15: =SUM(CY13:CY14) -> 431 | CZ15: =SUM(CZ13:CZ14) -> 319 | DA15: =SUM(DA13:DA14) -> 275 | DB15: =SUM(DB13:DB14) -> 554 | DC15: =SUM(DC13:DC14) -> 5645 | DD15: =SUM(DD13:DD14) -> 1766 | DE15: =SUM(DE13:DE14) -> 11237 | ... DG15: =SUM(DG13:DG14) -> 13003 | DJ15: مجموع السعوديين | DL15: =SUM(DL13:DL14) -> 2033 | DM15: =SUM(DM13:DM14) -> 60 | DN15: =SUM(DN13:DN14) -> 292 | DO15: =SUM(DO13:DO14) -> 18 | DP15: =SUM(DP13:DP14) -> 406 | DQ15: =SUM(DQ13:DQ14) -> 2809 | DR15: =SUM(DR13:DR14) -> 27 | DS15: =SUM(DS13:DS14) -> 625 | ... DU15: =SUM(DU13:DU14) -> 652 | DX15: مجموع السعوديين | DZ15: =SUM(DZ13:DZ14) -> 0 | EA15: =SUM(EA13:EA14) -> 0 | EB15: =SUM(EB13:EB14) -> 0 | EC15: =SUM(EC13:EC14) -> 0 | ED15: =SUM(ED13:ED14) -> 0 | EE15: =SUM(EE13:EE14) -> 0 | EF15: =SUM(EF13:EF14) -> 0 | EG15: =SUM(EG13:EG14) -> 0 | ... EI15: =SUM(EI13:EI14) -> 0 | EL15: مجموع السعوديين | EN15: =SUM(EN13:EN14) -> 0 | EO15: =SUM(EO13:EO14) -> 0 | EP15: =SUM(EP13:EP14) -> 0 | EQ15: =SUM(EQ13:EQ14) -> 0 | ER15: =SUM(ER13:ER14) -> 0 | ES15: =SUM(ES13:ES14) -> 0 | ET15: =SUM(ET13:ET14) -> 0 | EU15: =SUM(EU13:EU14) -> 0 | ... EW15: =SUM(EW13:EW14) -> 0 | EZ15: مجموع السعوديين | FB15: =SUM(FB13:FB14) -> 0 | FC15: =SUM(FC13:FC14) -> 0 | FD15: =SUM(FD13:FD14) -> 0 | FE15: =SUM(FE13:FE14) -> 0 | FF15: =SUM(FF13:FF14) -> 0 | FG15: =SUM(FG13:FG14) -> 0 | FH15: =SUM(FH13:FH14) -> 0 | FI15: =SUM(FI13:FI14) -> 0 | ... FK15: =SUM(FK13:FK14) -> 0 | FN15: مجموع السعوديين | FP15: =SUM(FP13:FP14) -> 43471 | FQ15: =SUM(FQ13:FQ14) -> 2786 | FR15: =SUM(FR13:FR14) -> 2640 | FS15: =SUM(FS13:FS14) -> 440 | FT15: =SUM(FT13:FT14) -> 4241 | FU15: =SUM(FU13:FU14) -> 53578 | FV15: =SUM(FV13:FV14) -> 1973 | FW15: =SUM(FW13:FW14) -> 16906 | ... FY15: =SUM(FY13:FY14) -> 18879
B16: غير سعودي | C16: ذكر | D16: 588 | E16: 156 | F16: 0 | G16: 0 | H16: 325 | I16: 1069 | J16: 0 | K16: 94 | L16: 0 | M16: =SUM(J16:L16) -> 94 | P16: غير سعودي | Q16: ذكر | R16: 635 | S16: 105 | T16: 0 | U16: 0 | V16: 350 | W16: 1090 | X16: 5 | Y16: 114 | Z16: 0 | AA16: =SUM(X16:Z16) -> 119 | AD16: غير سعودي | AE16: ذكر | AF16: 978 | AG16: 122 | AH16: 0 | AI16: 0 | AJ16: 0 | AK16: 1100 | AL16: 15 | AM16: 0 | AN16: 0 | AO16: =SUM(AL16:AN16) -> 15 | AR16: غير سعودي | AS16: ذكر | AT16: 487 | AU16: 129 | AV16: 0 | AW16: 0 | AX16: 366 | AY16: 982 | AZ16: 2 | BA16: 236 | BB16: 0 | BC16: 238 | BF16: غير سعودي | BG16: ذكر | BH16: 192 | BI16: 71 | BJ16: 0 | BK16: 0 | BL16: 0 | BM16: 263 | BN16: 5 | BO16: 84 | BP16: 0 | BQ16: =SUM(BN16:BP16) -> 89 | BT16: غير سعودي | BU16: ذكر | BV16: 556 | BW16: 115 | BX16: 0 | BY16: 0 | BZ16: 396 | CA16: 1067 | CC16: 0 | CD16: 0 | CE16: =SUM(CB16:CD16) -> 0 | CH16: غير سعودي | CI16: ذكر | CJ16: 609 | CK16: 119 | CL16: 0 | CM16: 0 | CN16: 386 | CO16: 1114 | CP16: 0 | CQ16: 187 | CR16: 0 | CS16: 187 | CV16: غير سعودي | CW16: ذكر | CX16: 556 | CY16: 115 | CZ16: 0 | DA16: 0 | DB16: 396 | DC16: 1067 | DD16: 337 | DE16: 0 | DF16: 0 | DG16: =SUM(DD16:DF16) -> 337 | DJ16: غير سعودي | DK16: ذكر | DL16: 447 | DM16: 21 | DN16: 0 | DO16: 0 | DP16: 240 | DQ16: =SUM(DL16:DP16) -> 708 | DR16: 5 | DS16: 89 | DT16: 0 | DU16: =SUM(DR16:DT16) -> 94 | DX16: غير سعودي | DY16: ذكر | DZ16: 0 | EA16: 0 | EB16: 0 | EC16: 0 | ED16: 0 | EE16: =SUM(DZ16:ED16) -> 0 | EF16: 0 | EG16: 0 | EH16: 0 | EI16: =SUM(EF16:EH16) -> 0 | EL16: غير سعودي | EM16: ذكر | EN16: 0 | EO16: 0 | EP16: 0 | EQ16: 0 | ER16: 0 | ES16: =SUM(EN16:ER16) -> 0 | ET16: 0 | EU16: 0 | EV16: 0 | EW16: =SUM(ET16:EV16) -> 0 | EZ16: غير سعودي | FA16: ذكر | FB16: 0 | FC16: 0 | FD16: 0 | FE16: 0 | FF16: 0 | FG16: =SUM(FB16:FF16) -> 0 | FH16: 0 | FI16: 0 | FJ16: 0 | FK16: =SUM(FH16:FJ16) -> 0 | FN16: غير سعودي | FO16: ذكر | FP16: =SUM(D16+R16+AF16+AT16+BH16+BV16+CJ16+CX16+DL16+DZ16+EN16+FB16) -> 5048 | FQ16: =SUM(E16+S16+AG16+AU16+BI16+BW16+CK16+CY16+DM16+EA16+EO16+FC16) -> 953 | FR16: =SUM(F16+T16+AH16+AV16+BJ16+BX16+CL16+CZ16+DN16+EB16+EP16+FD16) -> 0 | FS16: =SUM(G16+U16+AI16+AW16+BK16+BY16+CM16+DA16+DO16+EC16+EQ16+FE16) -> 0 | FT16: =SUM(H16+V16+AJ16+AX16+BL16+BZ16+CN16+DB16+DP16+ED16+ER16+FF16) -> 2459 | FU16: =SUM(FP16:FT16) -> 8460 | FV16: =SUM(J16+X16+AL16+AZ16+BN16+CB16+CP16+DD16+DR16+EF16+ET16+FH16) -> 369 | FW16: =SUM(K16+Y16+AM16+BA16+BO16+CC16+CQ16+DE16+DS16+EG16+EU16+FI16) -> 804 | FX16: =SUM(L16+Z16+AN16+BB16+BP16+CD16+CR16+DF16+DT16+EH16+EV16+FJ16) -> 0 | FY16: =SUM(FV16:FX16) -> 1173
C17: أنثى | D17: 758 | E17: 113 | F17: 0 | G17: 5 | H17: 539 | I17: 1415 | J17: 3 | K17: 112 | L17: 0 | M17: =SUM(J17:L17) -> 115 | Q17: أنثى | R17: 741 | S17: 74 | T17: 0 | U17: 5 | V17: 300 | W17: 1120 | X17: 5 | Y17: 82 | Z17: 0 | AA17: =SUM(X17:Z17) -> 87 | AE17: أنثى | AF17: 1035 | AG17: 74 | AH17: 0 | AI17: 5 | AJ17: 0 | AK17: 1114 | AL17: 10 | AM17: 0 | AN17: 0 | AO17: =SUM(AL17:AN17) -> 10 | AS17: أنثى | AT17: 713 | AU17: 194 | AV17: 0 | AW17: 12 | AX17: 305 | AY17: 1224 | AZ17: 4 | BA17: 186 | BB17: 0 | BC17: 190 | BG17: أنثى | BH17: 298 | BI17: 39 | BJ17: 0 | BK17: 4 | BL17: 0 | BM17: 341 | BN17: 0 | BO17: 59 | BP17: 0 | BQ17: =SUM(BN17:BP17) -> 59 | BU17: أنثى | BV17: 547 | BW17: 107 | BX17: 0 | BY17: 10 | BZ17: 334 | CA17: 998 | CC17: 0 | CD17: 0 | CE17: =SUM(CB17:CD17) -> 0 | CI17: أنثى | CJ17: 546 | CK17: 107 | CL17: 0 | CM17: 4 | CN17: 322 | CO17: 979 | CP17: 0 | CQ17: 142 | CR17: 0 | CS17: 142 | CW17: أنثى | CX17: 547 | CY17: 107 | CZ17: 0 | DA17: 10 | DB17: 334 | DC17: 998 | DD17: 259 | DE17: 0 | DF17: 0 | DG17: =SUM(DD17:DF17) -> 259 | DK17: أنثى | DL17: 366 | DM17: 17 | DN17: 0 | DO17: 4 | DP17: 259 | DQ17: =SUM(DL17:DP17) -> 646 | DR17: 0 | DS17: 62 | DT17: 0 | DU17: =SUM(DR17:DT17) -> 62 | DY17: أنثى | DZ17: 0 | EA17: 0 | EB17: 0 | EC17: 0 | ED17: 0 | EE17: =SUM(DZ17:ED17) -> 0 | EF17: 0 | EG17: 0 | EH17: 0 | EI17: =SUM(EF17:EH17) -> 0 | EM17: أنثى | EN17: 0 | EO17: 0 | EP17: 0 | EQ17: 0 | ER17: 0 | ES17: =SUM(EN17:ER17) -> 0 | ET17: 0 | EU17: 0 | EV17: 0 | EW17: =SUM(ET17:EV17) -> 0 | FA17: أنثى | FB17: 0 | FC17: 0 | FD17: 0 | FE17: 0 | FF17: 0 | FG17: =SUM(FB17:FF17) -> 0 | FH17: 0 | FI17: 0 | FJ17: 0 | FK17: =SUM(FH17:FJ17) -> 0 | FO17: أنثى | FP17: =SUM(D17+R17+AF17+AT17+BH17+BV17+CJ17+CX17+DL17+DZ17+EN17+FB17) -> 5551 | FQ17: =SUM(E17+S17+AG17+AU17+BI17+BW17+CK17+CY17+DM17+EA17+EO17+FC17) -> 832 | FR17: =SUM(F17+T17+AH17+AV17+BJ17+BX17+CL17+CZ17+DN17+EB17+EP17+FD17) -> 0 | FS17: =SUM(G17+U17+AI17+AW17+BK17+BY17+CM17+DA17+DO17+EC17+EQ17+FE17) -> 59 | FT17: =SUM(H17+V17+AJ17+AX17+BL17+BZ17+CN17+DB17+DP17+ED17+ER17+FF17) -> 2393 | FU17: =SUM(FP17:FT17) -> 8835 | FV17: =SUM(J17+X17+AL17+AZ17+BN17+CB17+CP17+DD17+DR17+EF17+ET17+FH17) -> 281 | FW17: =SUM(K17+Y17+AM17+BA17+BO17+CC17+CQ17+DE17+DS17+EG17+EU17+FI17) -> 643 | FX17: =SUM(L17+Z17+AN17+BB17+BP17+CD17+CR17+DF17+DT17+EH17+EV17+FJ17) -> 0 | FY17: =SUM(FV17:FX17) -> 924
B18: مجموع غ.سعودي | D18: =SUM(D16:D17) -> 1346 | E18: =SUM(E16:E17) -> 269 | F18: =SUM(F16:F17) -> 0 | G18: =SUM(G16:G17) -> 5 | H18: =SUM(H16:H17) -> 864 | I18: =SUM(I16:I17) -> 2484 | J18: =SUM(J16:J17) -> 3 | K18: =SUM(K16:K17) -> 206 | ... M18: =SUM(M16:M17) -> 209 | P18: مجموع غ.سعودي | R18: =SUM(R16:R17) -> 1376 | S18: =SUM(S16:S17) -> 179 | T18: =SUM(T16:T17) -> 0 | U18: =SUM(U16:U17) -> 5 | V18: =SUM(V16:V17) -> 650 | W18: =SUM(W16:W17) -> 2210 | X18: =SUM(X16:X17) -> 10 | Y18: =SUM(Y16:Y17) -> 196 | ... AA18: =SUM(AA16:AA17) -> 206 | AD18: مجموع غ.سعودي | AF18: 2013 | AG18: 196 | AH18: 0 | AI18: 5 | AJ18: 0 | AK18: 2214 | AL18: 25 | AM18: 0 | AN18: 0 | AO18: =SUM(AO16:AO17) -> 25 | AR18: مجموع غ.سعودي | AT18: 1200 | AU18: 323 | AV18: 0 | AW18: 12 | AX18: 671 | AY18: 2206 | AZ18: 6 | BA18: 422 | BB18: 0 | BC18: 428 | BF18: مجموع غ.سعودي | BH18: =SUM(BH16:BH17) -> 490 | BI18: =SUM(BI16:BI17) -> 110 | BJ18: =SUM(BJ16:BJ17) -> 0 | BK18: =SUM(BK16:BK17) -> 4 | BL18: =SUM(BL16:BL17) -> 0 | BM18: =SUM(BM16:BM17) -> 604 | BN18: =SUM(BN16:BN17) -> 5 | BO18: =SUM(BO16:BO17) -> 143 | ... BQ18: =SUM(BQ16:BQ17) -> 148 | BT18: مجموع غ.سعودي | BV18: 1103 | BW18: 222 | BX18: 0 | BY18: 10 | BZ18: 730 | CA18: 2065 | CC18: 0 | CD18: 0 | CE18: =SUM(CE16:CE17) -> 0 | CH18: مجموع غ.سعودي | CJ18: 1155 | CK18: 226 | CL18: 0 | CM18: 4 | CN18: 708 | CO18: 2093 | CP18: 0 | CQ18: 329 | CR18: 0 | CS18: 329 | CV18: مجموع غ.سعودي | CX18: =SUM(CX16:CX17) -> 1103 | CY18: =SUM(CY16:CY17) -> 222 | CZ18: =SUM(CZ16:CZ17) -> 0 | DA18: =SUM(DA16:DA17) -> 10 | DB18: =SUM(DB16:DB17) -> 730 | DC18: =SUM(DC16:DC17) -> 2065 | DD18: =SUM(DD16:DD17) -> 596 | DE18: =SUM(DE16:DE17) -> 0 | ... DG18: =SUM(DG16:DG17) -> 596 | DJ18: مجموع غ.سعودي | DL18: =SUM(DL16:DL17) -> 813 | DM18: =SUM(DM16:DM17) -> 38 | DN18: =SUM(DN16:DN17) -> 0 | DO18: =SUM(DO16:DO17) -> 4 | DP18: =SUM(DP16:DP17) -> 499 | DQ18: =SUM(DQ16:DQ17) -> 1354 | DR18: =SUM(DR16:DR17) -> 5 | DS18: =SUM(DS16:DS17) -> 151 | ... DU18: =SUM(DU16:DU17) -> 156 | DX18: مجموع غ.سعودي | DZ18: =SUM(DZ16:DZ17) -> 0 | EA18: =SUM(EA16:EA17) -> 0 | EB18: =SUM(EB16:EB17) -> 0 | EC18: =SUM(EC16:EC17) -> 0 | ED18: =SUM(ED16:ED17) -> 0 | EE18: =SUM(EE16:EE17) -> 0 | EF18: =SUM(EF16:EF17) -> 0 | EG18: =SUM(EG16:EG17) -> 0 | ... EI18: =SUM(EI16:EI17) -> 0 | EL18: مجموع غ.سعودي | EN18: =SUM(EN16:EN17) -> 0 | EO18: =SUM(EO16:EO17) -> 0 | EP18: =SUM(EP16:EP17) -> 0 | EQ18: =SUM(EQ16:EQ17) -> 0 | ER18: =SUM(ER16:ER17) -> 0 | ES18: =SUM(ES16:ES17) -> 0 | ET18: =SUM(ET16:ET17) -> 0 | EU18: =SUM(EU16:EU17) -> 0 | ... EW18: =SUM(EW16:EW17) -> 0 | EZ18: مجموع غ.سعودي | FB18: =SUM(FB16:FB17) -> 0 | FC18: =SUM(FC16:FC17) -> 0 | FD18: =SUM(FD16:FD17) -> 0 | FE18: =SUM(FE16:FE17) -> 0 | FF18: =SUM(FF16:FF17) -> 0 | FG18: =SUM(FG16:FG17) -> 0 | FH18: =SUM(FH16:FH17) -> 0 | FI18: =SUM(FI16:FI17) -> 0 | ... FK18: =SUM(FK16:FK17) -> 0 | FN18: مجموع غ.سعودي | FP18: =SUM(FP16:FP17) -> 10599 | FQ18: =SUM(FQ16:FQ17) -> 1785 | FR18: =SUM(FR16:FR17) -> 0 | FS18: =SUM(FS16:FS17) -> 59 | FT18: =SUM(FT16:FT17) -> 4852 | FU18: =SUM(FU16:FU17) -> 17295 | FV18: =SUM(FV16:FV17) -> 650 | FW18: =SUM(FW16:FW17) -> 1447 | ... FY18: =SUM(FY16:FY17) -> 2097
A19: المجموع الكلي | D19: =SUM(D18+D15) -> 3450 | E19: =SUM(E18+E15) -> 655 | F19: =SUM(F18+F15) -> 290 | G19: =SUM(G18+G15) -> 30 | H19: =SUM(H18+H15) -> 1368 | I19: =SUM(I15+I18) -> 5793 | J19: =SUM(J18+J15) -> 22 | K19: =SUM(K18+K15) -> 819 | L19: =SUM(L18+L15) -> 0 | M19: =SUM(M18+M15) -> 841 | O19: المجموع الكلي | R19: =SUM(R18+R15) -> 6081 | S19: =SUM(S18+S15) -> 436 | T19: =SUM(T18+T15) -> 299 | U19: =SUM(U18+U15) -> 25 | V19: =SUM(V18+V15) -> 1130 | W19: =SUM(W15+W18) -> 7971 | X19: =SUM(X18+X15) -> 30 | Y19: =SUM(Y18+Y15) -> 858 | Z19: =SUM(Z18+Z15) -> 0 | AA19: =SUM(AA18+AA15) -> 888 | AC19: المجموع الكلي | AF19: 7410 | AG19: 588 | AH19: 208 | AI19: 24 | AJ19: 456 | AK19: 8686 | AL19: 76 | AM19: 0 | AN19: 0 | AO19: =SUM(AO18+AO15) -> 76 | AQ19: المجموع الكلي | AT19: =SUM(AT18+AT15) -> 7100 | AU19: =SUM(AU18+AU15) -> 641 | AV19: =SUM(AV18+AV15) -> 398 | AW19: =SUM(AW18+AW15) -> 34 | AX19: =SUM(AX18+AX15) -> 1170 | AY19: =SUM(AY15+AY18) -> 9343 | AZ19: =SUM(AZ18+AZ15) -> 48 | BA19: =SUM(BA18+BA15) -> 1423 | BB19: =SUM(BB18+BB15) -> 0 | BC19: =SUM(BC18+BC15) -> 1471 | BE19: المجموع الكلي | BH19: =SUM(BH18+BH15) -> 3181 | BI19: =SUM(BI18+BI15) -> 299 | BJ19: =SUM(BJ18+BJ15) -> 173 | BK19: =SUM(BK18+BK15) -> 22 | BL19: =SUM(BL18+BL15) -> 283 | BM19: =SUM(BM15+BM18) -> 3958 | BN19: =SUM(BN18+BN15) -> 28 | BO19: =SUM(BO18+BO15) -> 727 | BP19: =SUM(BP18+BP15) -> 0 | BQ19: =SUM(BQ18+BQ15) -> 755 | BS19: المجموع الكلي | BV19: 9851 | BW19: 653 | BX19: 319 | BY19: 285 | BZ19: 1284 | CA19: 7710 | CC19: 1500 | CD19: 0 | CE19: =SUM(CE18+CE15) -> 1500 | CG19: المجموع الكلي | CJ19: 4300 | CK19: 548 | CL19: 342 | CM19: 22 | CN19: 1213 | CO19: 6425 | CP19: 25 | CQ19: 1013 | CR19: 0 | CS19: 1038 | CU19: المجموع الكلي | CX19: =SUM(CX18+CX15) -> 9851 | CY19: =SUM(CY18+CY15) -> 653 | CZ19: =SUM(CZ18+CZ15) -> 319 | DA19: =SUM(DA18+DA15) -> 285 | DB19: =SUM(DB18+DB15) -> 1284 | DC19: =SUM(DC15+DC18) -> 7710 | DD19: =SUM(DD18+DD15) -> 2362 | DE19: =SUM(DE18+DE15) -> 11237 | DF19: =SUM(DF18+DF15) -> 0 | DG19: =SUM(DG18+DG15) -> 13599 | DI19: المجموع الكلي | DL19: =SUM(DL18+DL15) -> 2846 | DM19: =SUM(DM18+DM15) -> 98 | DN19: =SUM(DN18+DN15) -> 292 | DO19: =SUM(DO18+DO15) -> 22 | DP19: =SUM(DP18+DP15) -> 905 | DQ19: =SUM(DQ15+DQ18) -> 4163 | DR19: =SUM(DR18+DR15) -> 32 | DS19: =SUM(DS18+DS15) -> 776 | DT19: =SUM(DT18+DT15) -> 0 | DU19: =SUM(DU18+DU15) -> 808 | DW19: المجموع الكلي | DZ19: =SUM(DZ18+DZ15) -> 0 | EA19: =SUM(EA18+EA15) -> 0 | EB19: =SUM(EB18+EB15) -> 0 | EC19: =SUM(EC18+EC15) -> 0 | ED19: =SUM(ED18+ED15) -> 0 | EE19: =SUM(EE15+EE18) -> 0 | EF19: =SUM(EF18+EF15) -> 0 | EG19: =SUM(EG18+EG15) -> 0 | EH19: =SUM(EH18+EH15) -> 0 | EI19: =SUM(EI18+EI15) -> 0 | EK19: المجموع الكلي | EN19: =SUM(EN18+EN15) -> 0 | EO19: =SUM(EO18+EO15) -> 0 | EP19: =SUM(EP18+EP15) -> 0 | EQ19: =SUM(EQ18+EQ15) -> 0 | ER19: =SUM(ER18+ER15) -> 0 | ES19: =SUM(ES15+ES18) -> 0 | ET19: =SUM(ET18+ET15) -> 0 | EU19: =SUM(EU18+EU15) -> 0 | EV19: =SUM(EV18+EV15) -> 0 | EW19: =SUM(EW18+EW15) -> 0 | EY19: المجموع الكلي | FB19: =SUM(FB18+FB15) -> 0 | FC19: =SUM(FC18+FC15) -> 0 | FD19: =SUM(FD18+FD15) -> 0 | FE19: =SUM(FE18+FE15) -> 0 | FF19: =SUM(FF18+FF15) -> 0 | FG19: =SUM(FG15+FG18) -> 0 | FH19: =SUM(FH18+FH15) -> 0 | FI19: =SUM(FI18+FI15) -> 0 | FJ19: =SUM(FJ18+FJ15) -> 0 | FK19: =SUM(FK18+FK15) -> 0 | FM19: المجموع الكلي | FP19: =SUM(FP18+FP15) -> 54070 | FQ19: =SUM(FQ18+FQ15) -> 4571 | FR19: =SUM(FR18+FR15) -> 2640 | FS19: =SUM(FS18+FS15) -> 499 | FT19: =SUM(FT18+FT15) -> 9093 | FU19: =SUM(FU15+FU18) -> 70873 | FV19: =SUM(FV18+FV15) -> 2623 | FW19: =SUM(FW18+FW15) -> 18353 | FX19: =SUM(FX18+FX15) -> 0 | FY19: =SUM(FY18+FY15) -> 20976
A20: السليمانية | B20: سعودي | C20: ذكر | D20: 1023 | E20: 393 | F20: 169 | G20: 0 | H20: 90 | I20: 1675 | J20: 686 | K20: 656 | L20: 510 | M20: =SUM(J20:L20) -> 1852 | O20: السليمانية | P20: سعودي | Q20: ذكر | R20: 2520 | S20: 514 | T20: 132 | U20: 0 | V20: 416 | W20: 1062 | X20: 601 | Y20: 0 | Z20: 873 | AA20: =SUM(X20:Z20) -> 1474 | AC20: السليمانية | AD20: سعودي | AE20: ذكر | AF20: 3495 | AG20: 0 | AH20: 173 | AI20: 0 | AJ20: 0 | AK20: 3668 | AL20: 0 | AM20: 2438 | AN20: 0 | AO20: =SUM(AL20:AN20) -> 2438 | AQ20: السليمانية | AR20: سعودي | AS20: ذكر | AT20: 1258 | AU20: 0 | AV20: 158 | AW20: 0 | AX20: 0 | AY20: 1416 | AZ20: 322 | BA20: 0 | BB20: 636 | BC20: 958 | BE20: السليمانية | BF20: سعودي | BG20: ذكر | BH20: 2855 | BI20: 472 | BJ20: 250 | BK20: 0 | BL20: 49 | BM20: 3626 | BN20: 55 | BO20: 2071 | BP20: 0 | BQ20: =SUM(BN20:BP20) -> 2126 | BS20: السليمانية | BT20: سعودي | BU20: ذكر | BV20: 3422 | BW20: 0 | BX20: 100 | BY20: 0 | BZ20: 0 | CA20: 3522 | CB20: 678 | CC20: 1258 | CD20: 0 | CE20: =SUM(CB20:CD20) -> 1936 | CG20: السليمانية | CH20: سعودي | CI20: ذكر | CJ20: 1098 | CK20: 180 | CL20: 99 | CM20: 0 | CN20: 196 | CO20: 475 | CP20: 265 | CQ20: 2541 | CR20: 621 | CS20: 3427 | CU20: السليمانية | CV20: سعودي | CW20: ذكر | CX20: 3422 | CY20: 0 | CZ20: 100 | DA20: 0 | DB20: 0 | DC20: =SUM(CX20:DB20) -> 3522 | DD20: 678 | DE20: 1258 | DF20: 0 | DG20: =SUM(DD20:DF20) -> 1936 | DI20: السليمانية | DJ20: سعودي | DK20: ذكر | DL20: 5422 | DM20: 255 | DN20: 103 | DO20: 0 | DP20: 250 | DQ20: =SUM(DL20:DP20) -> 6030 | DR20: 50 | DS20: 185 | DT20: 88 | DU20: =SUM(DR20:DT20) -> 323 | DW20: السليمانية | DX20: سعودي | DY20: ذكر | DZ20: 1523 | EA20: 0 | EB20: 99 | EC20: 0 | ED20: 190 | EE20: =SUM(DZ20:ED20) -> 1812 | EF20: 686 | EG20: 656 | EH20: 510 | EI20: =SUM(EF20:EH20) -> 1852 | EK20: السليمانية | EL20: سعودي | EM20: ذكر | EN20: 0 | EO20: 0 | EP20: 0 | EQ20: 0 | ER20: 0 | ES20: =SUM(EN20:ER20) -> 0 | ET20: 0 | EU20: 0 | EV20: 0 | EW20: =SUM(ET20:EV20) -> 0 | EY20: السليمانية | EZ20: سعودي | FA20: ذكر | FB20: 0 | FC20: 0 | FD20: 0 | FE20: 0 | FF20: 0 | FG20: =SUM(FB20:FF20) -> 0 | FH20: 0 | FI20: 0 | FJ20: 0 | FK20: =SUM(FH20:FJ20) -> 0 | FM20: =EY20 -> السليمانية | FN20: سعودي | FO20: ذكر | FP20: =SUM(D20+R20+AF20+AT20+BH20+BV20+CJ20+CX20+DL20+DZ20+EN20+FB20) -> 26038 | FQ20: =SUM(E20+S20+AG20+AU20+BI20+BW20+CK20+CY20+DM20+EA20+EO20+FC20) -> 1814 | FR20: =SUM(F20+T20+AH20+AV20+BJ20+BX20+CL20+CZ20+DN20+EB20+EP20+FD20) -> 1383 | FS20: =SUM(G20+U20+AI20+AW20+BK20+BY20+CM20+DA20+DO20+EC20+EQ20+FE20) -> 0 | FT20: =SUM(H20+V20+AJ20+AX20+BL20+BZ20+CN20+DB20+DP20+ED20+ER20+FF20) -> 1191 | FU20: =SUM(FP20:FT20) -> 30426 | FV20: =SUM(J20+X20+AL20+AZ20+BN20+CB20+CP20+DD20+DR20+EF20+ET20+FH20) -> 4021 | FW20: =SUM(K20+Y20+AM20+BA20+BO20+CC20+CQ20+DE20+DS20+EG20+EU20+FI20) -> 11063 | FX20: =SUM(L20+Z20+AN20+BB20+BP20+CD20+CR20+DF20+DT20+EH20+EV20+FJ20) -> 3238 | FY20: =SUM(FV20:FX20) -> 18322
C21: أنثى | D21: 993 | E21: 308 | F21: 148 | G21: 25 | H21: 106 | I21: 1580 | J21: 532 | K21: 924 | L21: 445 | M21: =SUM(J21:L21) -> 1901 | Q21: أنثى | R21: 2252 | S21: 264 | T21: 150 | U21: 20 | V21: 134 | W21: 548 | X21: 489 | Y21: 0 | Z21: 238 | AA21: =SUM(X21:Z21) -> 727 | AE21: أنثى | AF21: 3175 | AG21: 0 | AH21: 175 | AI21: 20 | AJ21: 0 | AK21: 3370 | AL21: 0 | AM21: 6266 | AN21: 0 | AO21: =SUM(AL21:AN21) -> 6266 | AS21: أنثى | AT21: 1125 | AU21: 0 | AV21: 169 | AW21: 0 | AX21: 0 | AY21: 1294 | AZ21: 158 | BA21: 0 | BB21: 450 | BC21: 608 | BG21: أنثى | BH21: 2697 | BI21: 392 | BJ21: 331 | BK21: 0 | BL21: 55 | BM21: 3475 | BN21: 60 | BO21: 2233 | BP21: 0 | BQ21: =SUM(BN21:BP21) -> 2293 | BU21: أنثى | BV21: 3175 | BW21: 0 | BX21: 175 | BY21: 20 | BZ21: 0 | CA21: 3370 | CB21: 505 | CC21: 4598 | CD21: 0 | CE21: =SUM(CB21:CD21) -> 5103 | CI21: أنثى | CJ21: 1002 | CK21: 125 | CL21: 263 | CM21: 34 | CN21: 225 | CO21: 647 | CP21: 245 | CQ21: 4064 | CR21: 420 | CS21: 4729 | CW21: أنثى | CX21: 3175 | CY21: 0 | CZ21: 175 | DA21: 20 | DB21: 0 | DC21: =SUM(CX21:DB21) -> 3370 | DD21: 505 | DE21: 4598 | DF21: 0 | DG21: =SUM(DD21:DF21) -> 5103 | DK21: أنثى | DL21: 3441 | DM21: 210 | DN21: 100 | DO21: 31 | DP21: 258 | DQ21: =SUM(DL21:DP21) -> 4040 | DR21: 57 | DS21: 145 | DT21: 96 | DU21: =SUM(DR21:DT21) -> 298 | DY21: أنثى | DZ21: 1993 | EA21: 0 | EB21: 141 | EC21: 25 | ED21: 106 | EE21: =SUM(DZ21:ED21) -> 2265 | EF21: 532 | EG21: 924 | EH21: 445 | EI21: =SUM(EF21:EH21) -> 1901 | EM21: أنثى | EN21: 0 | EO21: 0 | EP21: 0 | EQ21: 0 | ER21: 0 | ES21: =SUM(EN21:ER21) -> 0 | ET21: 0 | EU21: 0 | EV21: 0 | EW21: =SUM(ET21:EV21) -> 0 | FA21: أنثى | FB21: 0 | FC21: 0 | FD21: 0 | FE21: 0 | FF21: 0 | FG21: =SUM(FB21:FF21) -> 0 | FH21: 0 | FI21: 0 | FJ21: 0 | FK21: =SUM(FH21:FJ21) -> 0 | FO21: أنثى | FP21: =SUM(D21+R21+AF21+AT21+BH21+BV21+CJ21+CX21+DL21+DZ21+EN21+FB21) -> 23028 | FQ21: =SUM(E21+S21+AG21+AU21+BI21+BW21+CK21+CY21+DM21+EA21+EO21+FC21) -> 1299 | FR21: =SUM(F21+T21+AH21+AV21+BJ21+BX21+CL21+CZ21+DN21+EB21+EP21+FD21) -> 1827 | FS21: =SUM(G21+U21+AI21+AW21+BK21+BY21+CM21+DA21+DO21+EC21+EQ21+FE21) -> 195 | FT21: =SUM(H21+V21+AJ21+AX21+BL21+BZ21+CN21+DB21+DP21+ED21+ER21+FF21) -> 884 | FU21: =SUM(FP21:FT21) -> 27233 | FV21: =SUM(J21+X21+AL21+AZ21+BN21+CB21+CP21+DD21+DR21+EF21+ET21+FH21) -> 3083 | FW21: =SUM(K21+Y21+AM21+BA21+BO21+CC21+CQ21+DE21+DS21+EG21+EU21+FI21) -> 23752 | FX21: =SUM(L21+Z21+AN21+BB21+BP21+CD21+CR21+DF21+DT21+EH21+EV21+FJ21) -> 2094 | FY21: =SUM(FV21:FX21) -> 28929
B22: مجموع السعوديين | D22: 2016 | E22: 701 | F22: 317 | G22: 25 | H22: 196 | I22: 3255 | J22: 1218 | K22: 1580 | L22: 955 | M22: =SUM(M20:M21) -> 3753 | P22: مجموع السعوديين | R22: 4772 | S22: 778 | T22: 282 | U22: 20 | V22: 550 | W22: 1610 | X22: 1090 | Y22: 0 | Z22: 1111 | AA22: =SUM(AA20:AA21) -> 2201 | AD22: مجموع السعوديين | AF22: 6670 | AG22: 0 | AH22: 348 | AI22: 20 | AJ22: 0 | AK22: 7038 | AL22: 0 | AM22: 8704 | AN22: 0 | AO22: =SUM(AO20:AO21) -> 8704 | AR22: مجموع السعوديين | AT22: 2383 | AU22: 0 | AV22: 327 | AW22: 0 | AX22: 0 | AY22: 2710 | AZ22: 480 | BA22: 0 | BB22: 1086 | BC22: 1566 | BF22: مجموع السعوديين | BH22: 5552 | BI22: 864 | BJ22: 581 | BK22: 0 | BL22: 104 | BM22: 7101 | BN22: 115 | BO22: 4304 | BP22: 0 | BQ22: =SUM(BQ20:BQ21) -> 4419 | BT22: مجموع السعوديين | BV22: 6597 | BW22: 0 | BX22: 275 | BY22: 20 | BZ22: 0 | CA22: 6892 | CB22: 1183 | CC22: 5856 | CD22: 0 | CE22: =SUM(CE20:CE21) -> 7039 | CH22: مجموع السعوديين | CJ22: 0 | CK22: 305 | CL22: 362 | CM22: 34 | CN22: 421 | CO22: 1122 | CP22: 510 | CQ22: 6605 | CR22: 1041 | CS22: 8156 | CV22: مجموع السعوديين | CX22: =SUM(CX20:CX21) -> 6597 | CY22: =SUM(CY20:CY21) -> 0 | CZ22: =SUM(CZ20:CZ21) -> 275 | DA22: =SUM(DA20:DA21) -> 20 | DB22: =SUM(DB20:DB21) -> 0 | DC22: =SUM(DC20:DC21) -> 6892 | DD22: =SUM(DD20:DD21) -> 1183 | DE22: =SUM(DE20:DE21) -> 5856 | ... DG22: =SUM(DG20:DG21) -> 7039 | DJ22: مجموع السعوديين | DL22: =SUM(DL20:DL21) -> 8863 | DM22: =SUM(DM20:DM21) -> 465 | DN22: =SUM(DN20:DN21) -> 203 | DO22: =SUM(DO20:DO21) -> 31 | DP22: =SUM(DP20:DP21) -> 508 | DQ22: =SUM(DQ20:DQ21) -> 10070 | DR22: =SUM(DR20:DR21) -> 107 | DS22: =SUM(DS20:DS21) -> 330 | ... DU22: =SUM(DU20:DU21) -> 621 | DX22: مجموع السعوديين | DZ22: =SUM(DZ20:DZ21) -> 3516 | EA22: =SUM(EA20:EA21) -> 0 | EB22: =SUM(EB20:EB21) -> 240 | EC22: =SUM(EC20:EC21) -> 25 | ED22: =SUM(ED20:ED21) -> 296 | EE22: =SUM(EE20:EE21) -> 4077 | EF22: =SUM(EF20:EF21) -> 1218 | EG22: =SUM(EG20:EG21) -> 1580 | ... EI22: =SUM(EI20:EI21) -> 3753 | EL22: مجموع السعوديين | EN22: =SUM(EN20:EN21) -> 0 | EO22: =SUM(EO20:EO21) -> 0 | EP22: =SUM(EP20:EP21) -> 0 | EQ22: =SUM(EQ20:EQ21) -> 0 | ER22: =SUM(ER20:ER21) -> 0 | ES22: =SUM(ES20:ES21) -> 0 | ET22: =SUM(ET20:ET21) -> 0 | EU22: =SUM(EU20:EU21) -> 0 | ... EW22: =SUM(EW20:EW21) -> 0 | EZ22: مجموع السعوديين | FB22: =SUM(FB20:FB21) -> 0 | FC22: =SUM(FC20:FC21) -> 0 | FD22: =SUM(FD20:FD21) -> 0 | FE22: =SUM(FE20:FE21) -> 0 | FF22: =SUM(FF20:FF21) -> 0 | FG22: =SUM(FG20:FG21) -> 0 | FH22: =SUM(FH20:FH21) -> 0 | FI22: =SUM(FI20:FI21) -> 0 | ... FK22: =SUM(FK20:FK21) -> 0 | FN22: مجموع السعوديين | FP22: =SUM(FP20:FP21) -> 49066 | FQ22: =SUM(FQ20:FQ21) -> 3113 | FR22: =SUM(FR20:FR21) -> 3210 | FS22: =SUM(FS20:FS21) -> 195 | FT22: =SUM(FT20:FT21) -> 2075 | FU22: =SUM(FU20:FU21) -> 57659 | FV22: =SUM(FV20:FV21) -> 7104 | FW22: =SUM(FW20:FW21) -> 34815 | ... FY22: =SUM(FY20:FY21) -> 47251
B23: غير سعودي | C23: ذكر | D23: 894 | E23: 299 | F23: 0 | G23: 0 | H23: 150 | I23: 1343 | J23: 255 | K23: 92 | L23: 10 | M23: =SUM(J23:L23) -> 357 | P23: غير سعودي | Q23: ذكر | R23: 852 | S23: 411 | T23: 0 | U23: 0 | V23: 92 | W23: 503 | X23: 247 | Y23: 0 | Z23: 54 | AA23: =SUM(X23:Z23) -> 301 | AD23: غير سعودي | AE23: ذكر | AF23: 1895 | AG23: 0 | AH23: 0 | AI23: 0 | AJ23: 0 | AK23: 1895 | AL23: 0 | AM23: 274 | AN23: 0 | AO23: =SUM(AL23:AN23) -> 274 | AR23: غير سعودي | AS23: ذكر | AT23: 185 | AU23: 0 | AV23: 52 | AW23: 0 | AX23: 0 | AY23: 237 | AZ23: 152 | BA23: 0 | BB23: 60 | BC23: 212 | BF23: غير سعودي | BG23: ذكر | BH23: 656 | BI23: 94 | BJ23: 0 | BK23: 0 | BL23: 0 | BM23: 750 | BN23: 65 | BO23: 637 | BP23: 0 | BQ23: =SUM(BN23:BP23) -> 702 | BT23: غير سعودي | BU23: ذكر | BV23: 1689 | BW23: 0 | BX23: 0 | BY23: 0 | BZ23: 0 | CA23: 1689 | CB23: 279 | CC23: 252 | CD23: 0 | CE23: =SUM(CB23:CD23) -> 531 | CH23: غير سعودي | CI23: ذكر | CJ23: 856 | CK23: 66 | CL23: 0 | CM23: 0 | CN23: 138 | CO23: 204 | CP23: 103 | CQ23: 247 | CR23: 31 | CS23: 381 | CV23: غير سعودي | CW23: ذكر | CX23: 1689 | CY23: 0 | CZ23: 0 | DA23: 0 | DB23: 0 | DC23: =SUM(CX23:DB23) -> 1689 | DD23: 279 | DE23: 252 | DF23: 0 | DG23: =SUM(DD23:DF23) -> 531 | DJ23: غير سعودي | DK23: ذكر | DL23: 420 | DM23: 0 | DN23: 0 | DO23: 0 | DP23: 0 | DQ23: =SUM(DL23:DP23) -> 420 | DR23: 28 | DS23: 5 | DT23: 25 | DU23: =SUM(DR23:DT23) -> 58 | DX23: غير سعودي | DY23: ذكر | DZ23: 894 | EA23: 0 | EB23: 0 | EC23: 0 | ED23: 150 | EE23: =SUM(DZ23:ED23) -> 1044 | EF23: 255 | EG23: 92 | EH23: 10 | EI23: =SUM(EF23:EH23) -> 357 | EL23: غير سعودي | EM23: ذكر | EN23: 0 | EO23: 0 | EP23: 0 | EQ23: 0 | ER23: 0 | ES23: =SUM(EN23:ER23) -> 0 | ET23: 0 | EU23: 0 | EV23: 0 | EW23: =SUM(ET23:EV23) -> 0 | EZ23: غير سعودي | FA23: ذكر | FB23: 0 | FC23: 0 | FD23: 0 | FE23: 0 | FF23: 0 | FG23: =SUM(FB23:FF23) -> 0 | FH23: 0 | FI23: 0 | FJ23: 0 | FK23: =SUM(FH23:FJ23) -> 0 | FN23: غير سعودي | FO23: ذكر | FP23: =SUM(D23+R23+AF23+AT23+BH23+BV23+CJ23+CX23+DL23+DZ23+EN23+FB23) -> 10030 | FQ23: =SUM(E23+S23+AG23+AU23+BI23+BW23+CK23+CY23+DM23+EA23+EO23+FC23) -> 870 | FR23: =SUM(F23+T23+AH23+AV23+BJ23+BX23+CL23+CZ23+DN23+EB23+EP23+FD23) -> 52 | FS23: =SUM(G23+U23+AI23+AW23+BK23+BY23+CM23+DA23+DO23+EC23+EQ23+FE23) -> 0 | FT23: =SUM(H23+V23+AJ23+AX23+BL23+BZ23+CN23+DB23+DP23+ED23+ER23+FF23) -> 530 | FU23: =SUM(FP23:FT23) -> 11482 | FV23: =SUM(J23+X23+AL23+AZ23+BN23+CB23+CP23+DD23+DR23+EF23+ET23+FH23) -> 1663 | FW23: =SUM(K23+Y23+AM23+BA23+BO23+CC23+CQ23+DE23+DS23+EG23+EU23+FI23) -> 1851 | FX23: =SUM(L23+Z23+AN23+BB23+BP23+CD23+CR23+DF23+DT23+EH23+EV23+FJ23) -> 190 | FY23: =SUM(FV23:FX23) -> 3704
C24: أنثى | D24: 627 | E24: 56 | F24: 0 | G24: 0 | H24: 202 | I24: 885 | J24: 163 | K24: 123 | L24: 9 | M24: =SUM(J24:L24) -> 295 | Q24: أنثى | R24: 251 | S24: 231 | T24: 0 | U24: 0 | V24: 629 | W24: 860 | X24: 198 | Y24: 0 | Z24: 18 | AA24: =SUM(X24:Z24) -> 216 | AE24: أنثى | AF24: 1547 | AG24: 0 | AH24: 0 | AI24: 1 | AJ24: 0 | AK24: 1548 | AL24: 0 | AM24: 295 | AN24: 0 | AO24: =SUM(AL24:AN24) -> 295 | AS24: أنثى | AT24: 100 | AU24: 0 | AV24: 4 | AW24: 0 | AX24: 0 | AY24: 104 | AZ24: 88 | BA24: 0 | BB24: 4 | BC24: 92 | BG24: أنثى | BH24: 582 | BI24: 68 | BJ24: 0 | BK24: 5 | BL24: 2 | BM24: 657 | BN24: 54 | BO24: 484 | BP24: 0 | BQ24: =SUM(BN24:BP24) -> 538 | BU24: أنثى | BV24: 1258 | BW24: 0 | BX24: 0 | BY24: 0 | BZ24: 0 | CA24: 1258 | CB24: 194 | CC24: 202 | CD24: 0 | CE24: =SUM(CB24:CD24) -> 396 | CI24: أنثى | CJ24: 554 | CK24: 52 | CL24: 0 | CM24: 0 | CN24: 162 | CO24: 214 | CP24: 116 | CQ24: 584 | CR24: 0 | CS24: 700 | CW24: أنثى | CX24: 1258 | CY24: 0 | CZ24: 0 | DA24: 0 | DB24: 0 | DC24: =SUM(CX24:DB24) -> 1258 | DD24: 194 | DE24: 202 | DF24: 0 | DG24: =SUM(DD24:DF24) -> 396 | DK24: أنثى | DL24: 357 | DM24: 0 | DN24: 0 | DO24: 8 | DP24: 0 | DQ24: =SUM(DL24:DP24) -> 365 | DR24: 25 | DS24: 7 | DT24: 18 | DU24: =SUM(DR24:DT24) -> 50 | DY24: أنثى | DZ24: 627 | EA24: 0 | EB24: 0 | EC24: 0 | ED24: 202 | EE24: =SUM(DZ24:ED24) -> 829 | EF24: 163 | EG24: 123 | EH24: 9 | EI24: =SUM(EF24:EH24) -> 295 | EM24: أنثى | EN24: 0 | EO24: 0 | EP24: 0 | EQ24: 0 | ER24: 0 | ES24: =SUM(EN24:ER24) -> 0 | ET24: 0 | EU24: 0 | EV24: 0 | EW24: =SUM(ET24:EV24) -> 0 | FA24: أنثى | FB24: 0 | FC24: 0 | FD24: 0 | FE24: 0 | FF24: 0 | FG24: =SUM(FB24:FF24) -> 0 | FH24: 0 | FI24: 0 | FJ24: 0 | FK24: =SUM(FH24:FJ24) -> 0 | FO24: أنثى | FP24: =SUM(D24+R24+AF24+AT24+BH24+BV24+CJ24+CX24+DL24+DZ24+EN24+FB24) -> 7161 | FQ24: =SUM(E24+S24+AG24+AU24+BI24+BW24+CK24+CY24+DM24+EA24+EO24+FC24) -> 407 | FR24: =SUM(F24+T24+AH24+AV24+BJ24+BX24+CL24+CZ24+DN24+EB24+EP24+FD24) -> 4 | FS24: =SUM(G24+U24+AI24+AW24+BK24+BY24+CM24+DA24+DO24+EC24+EQ24+FE24) -> 14 | FT24: =SUM(H24+V24+AJ24+AX24+BL24+BZ24+CN24+DB24+DP24+ED24+ER24+FF24) -> 1197 | FU24: =SUM(FP24:FT24) -> 8783 | FV24: =SUM(J24+X24+AL24+AZ24+BN24+CB24+CP24+DD24+DR24+EF24+ET24+FH24) -> 1195 | FW24: =SUM(K24+Y24+AM24+BA24+BO24+CC24+CQ24+DE24+DS24+EG24+EU24+FI24) -> 2020 | FX24: =SUM(L24+Z24+AN24+BB24+BP24+CD24+CR24+DF24+DT24+EH24+EV24+FJ24) -> 58 | FY24: =SUM(FV24:FX24) -> 3273
