Workbook

Sheet القوى العاملة
A2: مراكز شرق جدة | F2: شهر | G2: 1 | H2: 1447 | L2: بيان بالقوى العاملة بالمركز خلال الشهر | S2: مراكز شرق جدة | X2: شهر | Y2: 2 | Z2: 1447 | AD2: بيان بالقوى العاملة بالمركز خلال الشهر | AK2: مراكز شرق جدة | AP2: شهر | AQ2: 3 | AR2: 1447 | AV2: بيان بالقوى العاملة بالمركز خلال الشهر | BC2: مراكز شرق جدة | BH2: شهر | BI2: 4 | BJ2: 1447 | BN2: بيان بالقوى العاملة بالمركز خلال الشهر | BU2: مراكز شرق جدة | BZ2: شهر | CA2: 5 | CB2: 1447 | CF2: بيان بالقوى العاملة بالمركز خلال الشهر | CM2: مراكز شرق جدة | CR2: شهر | CS2: 6 | CT2: 1447 | CX2: بيان بالقوى العاملة بالمركز خلال الشهر | DE2: مراكز شرق جدة | DJ2: شهر | DK2: 7 | DL2: 1447 | DP2: بيان بالقوى العاملة بالمركز خلال الشهر | DW2: مراكز شرق جدة | EB2: شهر | EC2: 8 | ED2: 1447 | EH2: بيان بالقوى العاملة بالمركز خلال الشهر | EO2: مراكز شرق جدة | ET2: شهر | EU2: 9 | EV2: 1447 | EZ2: بيان بالقوى العاملة بالمركز خلال الشهر | FG2: مراكز شرق جدة | FL2: شهر | FM2: 10 | FN2: 1447 | FR2: بيان بالقوى العاملة بالمركز خلال الشهر | FY2: مراكز شرق جدة | GD2: شهر | GE2: 11 | GF2: 1447 | GJ2: بيان بالقوى العاملة بالمركز خلال الشهر | GQ2: مراكز شرق جدة | GV2: شهر | GW2: 12 | GX2: 1447 | HB2: بيان بالقوى العاملة بالمركز خلال الشهر | HI2: =(GQ2) -> مراكز شرق جدة | HM2: عام | HN2: 1447 | HR2: بيان بالقوى العاملة بالمركز
A3: مراكز | B3: الجنسية | C3: الجنس | D3: أطباء | F3: طبيب أسنان | G3: تمريض | H3: قابلة | I3: فني صيدلة | J3: فني مختبر | K3: فني أشعة | L3: مراقب صحي | M3: فني إحصاء | N3: إداري | O3: مستخدم | P3: أخرى | Q3: المجموع | S3: مراكز | T3: الجنسية | U3: الجنس | V3: أطباء | X3: طبيب أسنان | Y3: تمريض | Z3: قابلة | AA3: فني صيدلة | AB3: فني مختبر | AC3: فني أشعة | AD3: مراقب صحي | AE3: فني إحصاء | AF3: إداري | AG3: مستخدم | AH3: أخرى | AI3: المجموع | AK3: مراكز | AL3: الجنسية | AM3: الجنس | AN3: أطباء | AP3: طبيب أسنان | AQ3: تمريض | AR3: قابلة | AS3: فني صيدلة | AT3: فني مختبر | AU3: فني أشعة | AV3: مراقب صحي | AW3: فني إحصاء | AX3: إداري | AY3: مستخدم | AZ3: أخرى | BA3: المجموع | BC3: مراكز | BD3: الجنسية | BE3: الجنس | BF3: أطباء | BH3: طبيب أسنان | BI3: تمريض | BJ3: قابلة | BK3: فني صيدلة | BL3: فني مختبر | BM3: فني أشعة | BN3: مراقب صحي | BO3: فني إحصاء | BP3: إداري | BQ3: مستخدم | BR3: أخرى | BS3: المجموع | BU3: مراكز | BV3: الجنسية | BW3: الجنس | BX3: أطباء | BZ3: طبيب أسنان | CA3: تمريض | CB3: قابلة | CC3: فني صيدلة | CD3: فني مختبر | CE3: فني أشعة | CF3: مراقب صحي | CG3: فني إحصاء | CH3: إداري | CI3: مستخدم | CJ3: أخرى | CK3: المجموع | CM3: مراكز | CN3: الجنسية | CO3: الجنس | CP3: أطباء | CR3: طبيب أسنان | CS3: تمريض | CT3: قابلة | CU3: فني صيدلة | CV3: فني مختبر | CW3: فني أشعة | CX3: مراقب صحي | CY3: فني إحصاء | CZ3: إداري | DA3: مستخدم | DB3: أخرى | DC3: المجموع | DE3: مراكز | DF3: الجنسية | DG3: الجنس | DH3: أطباء | DJ3: طبيب أسنان | DK3: تمريض | DL3: قابلة | DM3: فني صيدلة | DN3: فني مختبر | DO3: فني أشعة | DP3: مراقب صحي | DQ3: فني إحصاء | DR3: إداري | DS3: مستخدم | DT3: أخرى | DU3: المجموع | DW3: مراكز | DX3: الجنسية | DY3: الجنس | DZ3: أطباء | EB3: طبيب أسنان | EC3: تمريض | ED3: قابلة | EE3: فني صيدلة | EF3: فني مختبر | EG3: فني أشعة | EH3: مراقب صحي | EI3: فني إحصاء | EJ3: إداري | EK3: مستخدم | EL3: أخرى | EM3: المجموع | EO3: مراكز | EP3: الجنسية | EQ3: الجنس | ER3: أطباء | ET3: طبيب أسنان | EU3: تمريض | EV3: قابلة | EW3: فني صيدلة | EX3: فني مختبر | EY3: فني أشعة | EZ3: مراقب صحي | FA3: فني إحصاء | FB3: إداري | FC3: مستخدم | FD3: أخرى | FE3: المجموع | FG3: مراكز | FH3: الجنسية | FI3: الجنس | FJ3: أطباء | FL3: طبيب أسنان | FM3: تمريض | FN3: قابلة | FO3: فني صيدلة | FP3: فني مختبر | FQ3: فني أشعة | FR3: مراقب صحي | FS3: فني إحصاء | FT3: إداري | FU3: مستخدم | FV3: أخرى | FW3: المجموع | FY3: مراكز | FZ3: الجنسية | GA3: الجنس | GB3: أطباء | GD3: طبيب أسنان | GE3: تمريض | GF3: قابلة | GG3: فني صيدلة | GH3: فني مختبر | GI3: فني أشعة | GJ3: مراقب صحي | GK3: فني إحصاء | GL3: إداري | GM3: مستخدم | GN3: أخرى | GO3: المجموع | GQ3: مراكز | GR3: الجنسية | GS3: الجنس | GT3: أطباء | GV3: طبيب أسنان | GW3: تمريض | GX3: قابلة | GY3: فني صيدلة | GZ3: فني مختبر | HA3: فني أشعة | HB3: مراقب صحي | HC3: فني إحصاء | HD3: إداري | HE3: مستخدم | HF3: أخرى | HG3: المجموع | HI3: مراكز | HJ3: الجنسية | HK3: الجنس | HL3: أطباء | HN3: طبيب أسنان | HO3: تمريض | HP3: قابلة | HQ3: فني صيدلة | HR3: فني مختبر | HS3: فني أشعة | HT3: مراقب صحي | HU3: فني إحصاء | HV3: إداري | HW3: مستخدم | HX3: أخرى | HY3: المجموع
D4: عام | E4: ط.أسرة | V4: عام | W4: ط.أسرة | AN4: عام | AO4: ط.أسرة | BF4: عام | BG4: ط.أسرة | BX4: عام | BY4: ط.أسرة | CP4: عام | CQ4: ط.أسرة | DH4: عام | DI4: ط.أسرة | DZ4: عام | EA4: ط.أسرة | ER4: عام | ES4: ط.أسرة | FJ4: عام | FK4: ط.أسرة | GB4: عام | GC4: ط.أسرة | GT4: عام | GU4: ط.أسرة | HL4: عام | HM4: ط.أسرة
A5: الربيع والتوفيق | B5: سعودي | C5: ذكر | D5: 6 | E5: 1 | F5: 1 | G5: 2 | H5: 0 | I5: 0 | J5: 2 | K5: 0 | L5: 0 | M5: 0 | N5: 6 | O5: 0 | P5: 4 | Q5: =SUM(D5:P5) -> 22 | S5: الربيع والتوفيق | T5: سعودي | U5: ذكر | V5: 6 | W5: 1 | X5: 1 | Y5: 2 | Z5: 0 | AA5: 0 | AB5: 2 | AC5: 0 | AD5: 0 | AE5: 0 | AF5: 6 | AG5: 0 | AH5: 4 | AI5: =SUM(V5:AH5) -> 22 | AK5: الربيع والتوفيق | AL5: سعودي | AM5: ذكر | AN5: 6 | AO5: 1 | AP5: 1 | AQ5: 2 | AR5: 0 | AS5: 0 | AT5: 2 | AU5: 0 | AV5: 0 | AW5: 0 | AX5: 6 | AY5: 0 | AZ5: 4 | BA5: =SUM(AN5:AZ5) -> 22 | BC5: الربيع والتوفيق | BD5: سعودي | BE5: ذكر | BF5: 6 | BG5: 1 | BH5: 1 | BI5: 2 | BJ5: 0 | BK5: 0 | BL5: 2 | BM5: 0 | BN5: 0 | BO5: 0 | BP5: 6 | BQ5: 0 | BR5: 4 | BS5: =SUM(BF5:BR5) -> 22 | BU5: الربيع والتوفيق | BV5: سعودي | BW5: ذكر | BX5: 6 | BY5: 1 | BZ5: 1 | CA5: 2 | CB5: 0 | CC5: 0 | CD5: 2 | CE5: 0 | CF5: 0 | CG5: 0 | CH5: 6 | CI5: 0 | CJ5: 4 | CK5: =SUM(BX5:CJ5) -> 22 | CM5: الربيع والتوفيق | CN5: سعودي | CO5: ذكر | CP5: 6 | CQ5: 1 | CR5: 1 | CS5: 2 | CT5: 0 | CU5: 0 | CV5: 2 | CW5: 0 | CX5: 0 | CY5: 0 | CZ5: 6 | DA5: 0 | DB5: 4 | DC5: =SUM(CP5:DB5) -> 22 | DE5: الربيع والتوفيق | DF5: سعودي | DG5: ذكر | DH5: 6 | DI5: 1 | DJ5: 1 | DK5: 2 | DL5: 0 | DM5: 0 | DN5: 2 | DO5: 0 | DP5: 0 | DQ5: 0 | DR5: 6 | DS5: 0 | DT5: 4 | DU5: =SUM(DH5:DT5) -> 22 | DW5: الربيع والتوفيق | DX5: سعودي | DY5: ذكر | DZ5: 6 | EA5: 1 | EB5: 1 | EC5: 2 | ED5: 0 | EE5: 0 | EF5: 2 | EG5: 0 | EH5: 0 | EI5: 0 | EJ5: 6 | EK5: 0 | EL5: 4 | EM5: =SUM(DZ5:EL5) -> 22 | EO5: الربيع والتوفيق | EP5: سعودي | EQ5: ذكر | ER5: 6 | ES5: 1 | ET5: 1 | EU5: 2 | EV5: 0 | EW5: 0 | EX5: 2 | EY5: 0 | EZ5: 0 | FA5: 0 | FB5: 6 | FC5: 0 | FD5: 4 | FE5: =SUM(ER5:FD5) -> 22 | FG5: الربيع والتوفيق | FH5: سعودي | FI5: ذكر | FJ5: 6 | FK5: 1 | FL5: 1 | FM5: 2 | FN5: 0 | FO5: 0 | FP5: 2 | FQ5: 0 | FR5: 0 | FS5: 0 | FT5: 6 | FU5: 0 | FV5: 4 | FW5: =SUM(FJ5:FV5) -> 22 | FY5: الربيع والتوفيق | FZ5: سعودي | GA5: ذكر | GB5: 0 | GC5: 0 | GD5: 0 | GE5: 0 | GF5: 0 | GG5: 0 | GH5: 0 | GI5: 0 | GJ5: 0 | GK5: 0 | GL5: 0 | GM5: 0 | GN5: 0 | GO5: =SUM(GB5:GN5) -> 0 | GQ5: الربيع والتوفيق | GR5: سعودي | GS5: ذكر | GT5: 0 | GU5: 0 | GV5: 0 | GW5: 0 | GX5: 0 | GY5: 0 | GZ5: 0 | HA5: 0 | HB5: 0 | HC5: 0 | HD5: 0 | HE5: 0 | HF5: 0 | HG5: =SUM(GT5:HF5) -> 0 | HI5: =GQ5 -> الربيع والتوفيق | HJ5: سعودي | HK5: ذكر | HL5: =SUM(GT5) -> 0 | HM5: =SUM(GU5) -> 0 | HN5: =SUM(GV5) -> 0 | HO5: =SUM(GW5) -> 0 | HP5: =SUM(GX5) -> 0 | HQ5: =SUM(GY5) -> 0 | HR5: =SUM(GZ5) -> 0 | HS5: =SUM(HA5) -> 0 | ... HX5: =SUM(HF5) -> 0 | HY5: =SUM(HL5:HX5) -> 0
C6: أنثى | D6: 3 | E6: 3 | F6: 5 | G6: 20 | H6: 0 | I6: 0 | J6: 0 | K6: 0 | L6: 0 | M6: 0 | N6: 3 | O6: 0 | P6: 6 | Q6: =SUM(D6:P6) -> 40 | U6: أنثى | V6: 3 | W6: 3 | X6: 5 | Y6: 20 | Z6: 0 | AA6: 0 | AB6: 0 | AC6: 0 | AD6: 0 | AE6: 0 | AF6: 3 | AG6: 0 | AH6: 6 | AI6: =SUM(V6:AH6) -> 40 | AM6: أنثى | AN6: 3 | AO6: 3 | AP6: 5 | AQ6: 20 | AR6: 0 | AS6: 0 | AT6: 0 | AU6: 0 | AV6: 0 | AW6: 0 | AX6: 3 | AY6: 0 | AZ6: 6 | BA6: =SUM(AN6:AZ6) -> 40 | BE6: أنثى | BF6: 3 | BG6: 3 | BH6: 5 | BI6: 20 | BJ6: 0 | BK6: 0 | BL6: 0 | BM6: 0 | BN6: 0 | BO6: 0 | BP6: 3 | BQ6: 0 | BR6: 6 | BS6: =SUM(BF6:BR6) -> 40 | BW6: أنثى | BX6: 3 | BY6: 3 | BZ6: 5 | CA6: 20 | CB6: 0 | CC6: 0 | CD6: 0 | CE6: 0 | CF6: 0 | CG6: 0 | CH6: 3 | CI6: 0 | CJ6: 6 | CK6: =SUM(BX6:CJ6) -> 40 | CO6: أنثى | CP6: 3 | CQ6: 3 | CR6: 5 | CS6: 20 | CT6: 0 | CU6: 0 | CV6: 0 | CW6: 0 | CX6: 0 | CY6: 0 | CZ6: 3 | DA6: 0 | DB6: 6 | DC6: =SUM(CP6:DB6) -> 40 | DG6: أنثى | DH6: 3 | DI6: 3 | DJ6: 5 | DK6: 20 | DL6: 0 | DM6: 0 | DN6: 0 | DO6: 0 | DP6: 0 | DQ6: 0 | DR6: 3 | DS6: 0 | DT6: 6 | DU6: =SUM(DH6:DT6) -> 40 | DY6: أنثى | DZ6: 3 | EA6: 3 | EB6: 5 | EC6: 20 | ED6: 0 | EE6: 0 | EF6: 0 | EG6: 0 | EH6: 0 | EI6: 0 | EJ6: 3 | EK6: 0 | EL6: 6 | EM6: =SUM(DZ6:EL6) -> 40 | EQ6: أنثى | ER6: 3 | ES6: 3 | ET6: 5 | EU6: 20 | EV6: 0 | EW6: 0 | EX6: 0 | EY6: 0 | EZ6: 0 | FA6: 0 | FB6: 3 | FC6: 0 | FD6: 6 | FE6: =SUM(ER6:FD6) -> 40 | FI6: أنثى | FJ6: 3 | FK6: 3 | FL6: 5 | FM6: 20 | FN6: 0 | FO6: 0 | FP6: 0 | FQ6: 0 | FR6: 0 | FS6: 0 | FT6: 3 | FU6: 0 | FV6: 6 | FW6: =SUM(FJ6:FV6) -> 40 | GA6: أنثى | GB6: 0 | GC6: 0 | GD6: 0 | GE6: 0 | GF6: 0 | GG6: 0 | GH6: 0 | GI6: 0 | GJ6: 0 | GK6: 0 | GL6: 0 | GM6: 0 | GN6: 0 | GO6: =SUM(GB6:GN6) -> 0 | GS6: أنثى | GT6: 0 | GU6: 0 | GV6: 0 | GW6: 0 | GX6: 0 | GY6: 0 | GZ6: 0 | HA6: 0 | HB6: 0 | HC6: 0 | HD6: 0 | HE6: 0 | HF6: 0 | HG6: =SUM(GT6:HF6) -> 0 | HK6: أنثى | HL6: =SUM(GT6) -> 0 | HM6: =SUM(GU6) -> 0 | HN6: =SUM(GV6) -> 0 | HO6: =SUM(GW6) -> 0 | HP6: =SUM(GX6) -> 0 | HQ6: =SUM(GY6) -> 0 | HR6: =SUM(GZ6) -> 0 | HS6: =SUM(HA6) -> 0 | ... HX6: =SUM(HF6) -> 0 | HY6: =SUM(HL6:HX6) -> 0
B7: غير | C7: ذكر | D7: 0 | E7: 0 | F7: 0 | G7: 0 | H7: 0 | I7: 0 | J7: 0 | K7: 0 | L7: 0 | M7: 0 | N7: 0 | O7: 0 | P7: 0 | Q7: =SUM(D7:P7) -> 0 | T7: غير | U7: ذكر | V7: 0 | W7: 0 | X7: 0 | Y7: 0 | Z7: 0 | AA7: 0 | AB7: 0 | AC7: 0 | AD7: 0 | AE7: 0 | AF7: 0 | AG7: 0 | AH7: 0 | AI7: =SUM(V7:AH7) -> 0 | AL7: غير | AM7: ذكر | AN7: 0 | AO7: 0 | AP7: 0 | AQ7: 0 | AR7: 0 | AS7: 0 | AT7: 0 | AU7: 0 | AV7: 0 | AW7: 0 | AX7: 0 | AY7: 0 | AZ7: 0 | BA7: =SUM(AN7:AZ7) -> 0 | BD7: غير | BE7: ذكر | BF7: 0 | BG7: 0 | BH7: 0 | BI7: 0 | BJ7: 0 | BK7: 0 | BL7: 0 | BM7: 0 | BN7: 0 | BO7: 0 | BP7: 0 | BQ7: 0 | BR7: 0 | BS7: =SUM(BF7:BR7) -> 0 | BV7: غير | BW7: ذكر | BX7: 0 | BY7: 0 | BZ7: 0 | CA7: 0 | CB7: 0 | CC7: 0 | CD7: 0 | CE7: 0 | CF7: 0 | CG7: 0 | CH7: 0 | CI7: 0 | CJ7: 0 | CK7: =SUM(BX7:CJ7) -> 0 | CN7: غير | CO7: ذكر | CP7: 0 | CQ7: 0 | CR7: 0 | CS7: 0 | CT7: 0 | CU7: 0 | CV7: 0 | CW7: 0 | CX7: 0 | CY7: 0 | CZ7: 0 | DA7: 0 | DB7: 0 | DC7: =SUM(CP7:DB7) -> 0 | DF7: غير | DG7: ذكر | DH7: 0 | DI7: 0 | DJ7: 0 | DK7: 0 | DL7: 0 | DM7: 0 | DN7: 0 | DO7: 0 | DP7: 0 | DQ7: 0 | DR7: 0 | DS7: 0 | DT7: 0 | DU7: =SUM(DH7:DT7) -> 0 | DX7: غير | DY7: ذكر | DZ7: 0 | EA7: 0 | EB7: 0 | EC7: 0 | ED7: 0 | EE7: 0 | EF7: 0 | EG7: 0 | EH7: 0 | EI7: 0 | EJ7: 0 | EK7: 0 | EL7: 0 | EM7: =SUM(DZ7:EL7) -> 0 | EP7: غير | EQ7: ذكر | ER7: 0 | ES7: 0 | ET7: 0 | EU7: 0 | EV7: 0 | EW7: 0 | EX7: 0 | EY7: 0 | EZ7: 0 | FA7: 0 | FB7: 0 | FC7: 0 | FD7: 0 | FE7: =SUM(ER7:FD7) -> 0 | FH7: غير | FI7: ذكر | FJ7: 0 | FK7: 0 | FL7: 0 | FM7: 0 | FN7: 0 | FO7: 0 | FP7: 0 | FQ7: 0 | FR7: 0 | FS7: 0 | FT7: 0 | FU7: 0 | FV7: 0 | FW7: =SUM(FJ7:FV7) -> 0 | FZ7: غير | GA7: ذكر | GB7: 0 | GC7: 0 | GD7: 0 | GE7: 0 | GF7: 0 | GG7: 0 | GH7: 0 | GI7: 0 | GJ7: 0 | GK7: 0 | GL7: 0 | GM7: 0 | GN7: 0 | GO7: =SUM(GB7:GN7) -> 0 | GR7: غير | GS7: ذكر | GT7: 0 | GU7: 0 | GV7: 0 | GW7: 0 | GX7: 0 | GY7: 0 | GZ7: 0 | HA7: 0 | HB7: 0 | HC7: 0 | HD7: 0 | HE7: 0 | HF7: 0 | HG7: =SUM(GT7:HF7) -> 0 | HJ7: غير | HK7: ذكر | HL7: =SUM(GT7) -> 0 | HM7: =SUM(GU7) -> 0 | HN7: =SUM(GV7) -> 0 | HO7: =SUM(GW7) -> 0 | HP7: =SUM(GX7) -> 0 | HQ7: =SUM(GY7) -> 0 | HR7: =SUM(GZ7) -> 0 | HS7: =SUM(HA7) -> 0 | ... HX7: =SUM(HF7) -> 0 | HY7: =SUM(HL7:HX7) -> 0
B8: سعودي | C8: أنثى | D8: 0 | E8: 0 | F8: 0 | G8: 0 | H8: 0 | I8: 0 | J8: 0 | K8: 0 | L8: 0 | M8: 0 | N8: 0 | O8: 0 | P8: 0 | Q8: =SUM(D8:P8) -> 0 | T8: سعودي | U8: أنثى | V8: 0 | W8: 0 | X8: 0 | Y8: 0 | Z8: 0 | AA8: 0 | AB8: 0 | AC8: 0 | AD8: 0 | AE8: 0 | AF8: 0 | AG8: 0 | AH8: 0 | AI8: =SUM(V8:AH8) -> 0 | AL8: سعودي | AM8: أنثى | AN8: 0 | AO8: 0 | AP8: 0 | AQ8: 0 | AR8: 0 | AS8: 0 | AT8: 0 | AU8: 0 | AV8: 0 | AW8: 0 | AX8: 0 | AY8: 0 | AZ8: 0 | BA8: =SUM(AN8:AZ8) -> 0 | BD8: سعودي | BE8: أنثى | BF8: 0 | BG8: 0 | BH8: 0 | BI8: 0 | BJ8: 0 | BK8: 0 | BL8: 0 | BM8: 0 | BN8: 0 | BO8: 0 | BP8: 0 | BQ8: 0 | BR8: 0 | BS8: =SUM(BF8:BR8) -> 0 | BV8: سعودي | BW8: أنثى | BX8: 0 | BY8: 0 | BZ8: 0 | CA8: 0 | CB8: 0 | CC8: 0 | CD8: 0 | CE8: 0 | CF8: 0 | CG8: 0 | CH8: 0 | CI8: 0 | CJ8: 0 | CK8: =SUM(BX8:CJ8) -> 0 | CN8: سعودي | CO8: أنثى | CP8: 0 | CQ8: 0 | CR8: 0 | CS8: 0 | CT8: 0 | CU8: 0 | CV8: 0 | CW8: 0 | CX8: 0 | CY8: 0 | CZ8: 0 | DA8: 0 | DB8: 0 | DC8: =SUM(CP8:DB8) -> 0 | DF8: سعودي | DG8: أنثى | DH8: 0 | DI8: 0 | DJ8: 0 | DK8: 0 | DL8: 0 | DM8: 0 | DN8: 0 | DO8: 0 | DP8: 0 | DQ8: 0 | DR8: 0 | DS8: 0 | DT8: 0 | DU8: =SUM(DH8:DT8) -> 0 | DX8: سعودي | DY8: أنثى | DZ8: 0 | EA8: 0 | EB8: 0 | EC8: 0 | ED8: 0 | EE8: 0 | EF8: 0 | EG8: 0 | EH8: 0 | EI8: 0 | EJ8: 0 | EK8: 0 | EL8: 0 | EM8: =SUM(DZ8:EL8) -> 0 | EP8: سعودي | EQ8: أنثى | ER8: 0 | ES8: 0 | ET8: 0 | EU8: 0 | EV8: 0 | EW8: 0 | EX8: 0 | EY8: 0 | EZ8: 0 | FA8: 0 | FB8: 0 | FC8: 0 | FD8: 0 | FE8: =SUM(ER8:FD8) -> 0 | FH8: سعودي | FI8: أنثى | FJ8: 0 | FK8: 0 | FL8: 0 | FM8: 0 | FN8: 0 | FO8: 0 | FP8: 0 | FQ8: 0 | FR8: 0 | FS8: 0 | FT8: 0 | FU8: 0 | FV8: 0 | FW8: =SUM(FJ8:FV8) -> 0 | FZ8: سعودي | GA8: أنثى | GB8: 0 | GC8: 0 | GD8: 0 | GE8: 0 | GF8: 0 | GG8: 0 | GH8: 0 | GI8: 0 | GJ8: 0 | GK8: 0 | GL8: 0 | GM8: 0 | GN8: 0 | GO8: =SUM(GB8:GN8) -> 0 | GR8: سعودي | GS8: أنثى | GT8: 0 | GU8: 0 | GV8: 0 | GW8: 0 | GX8: 0 | GY8: 0 | GZ8: 0 | HA8: 0 | HB8: 0 | HC8: 0 | HD8: 0 | HE8: 0 | HF8: 0 | HG8: =SUM(GT8:HF8) -> 0 | HJ8: سعودي | HK8: أنثى | HL8: =SUM(GT8) -> 0 | HM8: =SUM(GU8) -> 0 | HN8: =SUM(GV8) -> 0 | HO8: =SUM(GW8) -> 0 | HP8: =SUM(GX8) -> 0 | HQ8: =SUM(GY8) -> 0 | HR8: =SUM(GZ8) -> 0 | HS8: =SUM(HA8) -> 0 | ... HX8: =SUM(HF8) -> 0 | HY8: =SUM(HL8:HX8) -> 0
B9: المجموع | D9: =SUM(D5:D8) -> 9 | E9: =SUM(E5:E8) -> 4 | F9: =SUM(F5:F8) -> 6 | G9: =SUM(G5:G8) -> 22 | H9: =SUM(H5:H8) -> 0 | I9: =SUM(I5:I8) -> 0 | J9: =SUM(J5:J8) -> 2 | K9: =SUM(K5:K8) -> 0 | ... Q9: =SUM(Q5:Q8) -> 62 | T9: المجموع | V9: =SUM(V5:V8) -> 9 | W9: =SUM(W5:W8) -> 4 | X9: =SUM(X5:X8) -> 6 | Y9: =SUM(Y5:Y8) -> 22 | Z9: =SUM(Z5:Z8) -> 0 | AA9: =SUM(AA5:AA8) -> 0 | AB9: =SUM(AB5:AB8) -> 2 | AC9: =SUM(AC5:AC8) -> 0 | ... AI9: =SUM(AI5:AI8) -> 62 | AL9: المجموع | AN9: =SUM(AN5:AN8) -> 9 | AO9: =SUM(AO5:AO8) -> 4 | AP9: =SUM(AP5:AP8) -> 6 | AQ9: =SUM(AQ5:AQ8) -> 22 | AR9: =SUM(AR5:AR8) -> 0 | AS9: =SUM(AS5:AS8) -> 0 | AT9: =SUM(AT5:AT8) -> 2 | AU9: =SUM(AU5:AU8) -> 0 | ... BA9: =SUM(BA5:BA8) -> 62 | BD9: المجموع | BF9: =SUM(BF5:BF8) -> 9 | BG9: =SUM(BG5:BG8) -> 4 | BH9: =SUM(BH5:BH8) -> 6 | BI9: =SUM(BI5:BI8) -> 22 | BJ9: =SUM(BJ5:BJ8) -> 0 | BK9: =SUM(BK5:BK8) -> 0 | BL9: =SUM(BL5:BL8) -> 2 | BM9: =SUM(BM5:BM8) -> 0 | ... BS9: =SUM(BS5:BS8) -> 62 | BV9: المجموع | BX9: =SUM(BX5:BX8) -> 9 | BY9: =SUM(BY5:BY8) -> 4 | BZ9: =SUM(BZ5:BZ8) -> 6 | CA9: =SUM(CA5:CA8) -> 22 | CB9: =SUM(CB5:CB8) -> 0 | CC9: =SUM(CC5:CC8) -> 0 | CD9: =SUM(CD5:CD8) -> 2 | CE9: =SUM(CE5:CE8) -> 0 | ... CK9: =SUM(CK5:CK8) -> 62 | CN9: المجموع | CP9: =SUM(CP5:CP8) -> 9 | CQ9: =SUM(CQ5:CQ8) -> 4 | CR9: =SUM(CR5:CR8) -> 6 | CS9: =SUM(CS5:CS8) -> 22 | CT9: =SUM(CT5:CT8) -> 0 | CU9: =SUM(CU5:CU8) -> 0 | CV9: =SUM(CV5:CV8) -> 2 | CW9: =SUM(CW5:CW8) -> 0 | ... DC9: =SUM(DC5:DC8) -> 62 | DF9: المجموع | DH9: =SUM(DH5:DH8) -> 9 | DI9: =SUM(DI5:DI8) -> 4 | DJ9: =SUM(DJ5:DJ8) -> 6 | DK9: =SUM(DK5:DK8) -> 22 | DL9: =SUM(DL5:DL8) -> 0 | DM9: =SUM(DM5:DM8) -> 0 | DN9: =SUM(DN5:DN8) -> 2 | DO9: =SUM(DO5:DO8) -> 0 | ... DU9: =SUM(DU5:DU8) -> 62 | DX9: المجموع | DZ9: =SUM(DZ5:DZ8) -> 9 | EA9: =SUM(EA5:EA8) -> 4 | EB9: =SUM(EB5:EB8) -> 6 | EC9: =SUM(EC5:EC8) -> 22 | ED9: =SUM(ED5:ED8) -> 0 | EE9: =SUM(EE5:EE8) -> 0 | EF9: =SUM(EF5:EF8) -> 2 | EG9: =SUM(EG5:EG8) -> 0 | ... EM9: =SUM(EM5:EM8) -> 62 | EP9: المجموع | ER9: =SUM(ER5:ER8) -> 9 | ES9: =SUM(ES5:ES8) -> 4 | ET9: =SUM(ET5:ET8) -> 6 | EU9: =SUM(EU5:EU8) -> 22 | EV9: =SUM(EV5:EV8) -> 0 | EW9: =SUM(EW5:EW8) -> 0 | EX9: =SUM(EX5:EX8) -> 2 | EY9: =SUM(EY5:EY8) -> 0 | ... FE9: =SUM(FE5:FE8) -> 62 | FH9: المجموع | FJ9: =SUM(FJ5:FJ8) -> 9 | FK9: =SUM(FK5:FK8) -> 4 | FL9: =SUM(FL5:FL8) -> 6 | FM9: =SUM(FM5:FM8) -> 22 | FN9: =SUM(FN5:FN8) -> 0 | FO9: =SUM(FO5:FO8) -> 0 | FP9: =SUM(FP5:FP8) -> 2 | FQ9: =SUM(FQ5:FQ8) -> 0 | ... FW9: =SUM(FW5:FW8) -> 62 | FZ9: المجموع | GB9: =SUM(GB5:GB8) -> 0 | GC9: =SUM(GC5:GC8) -> 0 | GD9: =SUM(GD5:GD8) -> 0 | GE9: =SUM(GE5:GE8) -> 0 | GF9: =SUM(GF5:GF8) -> 0 | GG9: =SUM(GG5:GG8) -> 0 | GH9: =SUM(GH5:GH8) -> 0 | GI9: =SUM(GI5:GI8) -> 0 | ... GO9: =SUM(GO5:GO8) -> 0 | GR9: المجموع | GT9: =SUM(GT5:GT8) -> 0 | GU9: =SUM(GU5:GU8) -> 0 | GV9: =SUM(GV5:GV8) -> 0 | GW9: =SUM(GW5:GW8) -> 0 | GX9: =SUM(GX5:GX8) -> 0 | GY9: =SUM(GY5:GY8) -> 0 | GZ9: =SUM(GZ5:GZ8) -> 0 | HA9: =SUM(HA5:HA8) -> 0 | ... HG9: =SUM(HG5:HG8) -> 0 | HJ9: المجموع | HL9: =SUM(HL5:HL8) -> 0 | HM9: =SUM(HM5:HM8) -> 0 | HN9: =SUM(HN5:HN8) -> 0 | HO9: =SUM(HO5:HO8) -> 0 | HP9: =SUM(HP5:HP8) -> 0 | HQ9: =SUM(HQ5:HQ8) -> 0 | HR9: =SUM(HR5:HR8) -> 0 | HS9: =SUM(HS5:HS8) -> 0 | ... HY9: =SUM(HY5:HY8) -> 0
A10: الجامعة | B10: سعودي | C10: ذكر | D10: 3 | E10: 4 | F10: 2 | G10: 3 | H10: 0 | I10: 0 | J10: 2 | K10: 0 | L10: 0 | M10: 0 | N10: 4 | O10: 0 | P10: 1 | Q10: =SUM(D10:P10) -> 19 | S10: الجامعة | T10: سعودي | U10: ذكر | V10: 3 | W10: 4 | X10: 2 | Y10: 3 | Z10: 0 | AA10: 0 | AB10: 2 | AC10: 0 | AD10: 0 | AE10: 0 | AF10: 4 | AG10: 0 | AH10: 1 | AI10: =SUM(V10:AH10) -> 19 | AK10: الجامعة | AL10: سعودي | AM10: ذكر | AN10: 3 | AO10: 4 | AP10: 2 | AQ10: 3 | AR10: 0 | AS10: 0 | AT10: 2 | AU10: 0 | AV10: 0 | AW10: 0 | AX10: 4 | AY10: 0 | AZ10: 1 | BA10: =SUM(AN10:AZ10) -> 19 | BC10: الجامعة | BD10: سعودي | BE10: ذكر | BF10: 3 | BG10: 4 | BH10: 2 | BI10: 3 | BJ10: 0 | BK10: 0 | BL10: 2 | BM10: 0 | BN10: 0 | BO10: 0 | BP10: 4 | BQ10: 0 | BR10: 1 | BS10: =SUM(BF10:BR10) -> 19 | BU10: الجامعة | BV10: سعودي | BW10: ذكر | BX10: 3 | BY10: 4 | BZ10: 2 | CA10: 3 | CB10: 0 | CC10: 0 | CD10: 2 | CE10: 0 | CF10: 0 | CG10: 0 | CH10: 4 | CI10: 0 | CJ10: 1 | CK10: =SUM(BX10:CJ10) -> 19 | CM10: الجامعة | CN10: سعودي | CO10: ذكر | CP10: 3 | CQ10: 4 | CR10: 2 | CS10: 3 | CT10: 0 | CU10: 0 | CV10: 2 | CW10: 0 | CX10: 0 | CY10: 0 | CZ10: 4 | DA10: 0 | DB10: 1 | DC10: =SUM(CP10:DB10) -> 19 | DE10: الجامعة | DF10: سعودي | DG10: ذكر | DH10: 3 | DI10: 4 | DJ10: 2 | DK10: 3 | DL10: 0 | DM10: 0 | DN10: 2 | DO10: 0 | DP10: 0 | DQ10: 0 | DR10: 4 | DS10: 0 | DT10: 1 | DU10: =SUM(DH10:DT10) -> 19 | DW10: الجامعة | DX10: سعودي | DY10: ذكر | DZ10: 3 | EA10: 4 | EB10: 2 | EC10: 3 | ED10: 0 | EE10: 0 | EF10: 2 | EG10: 0 | EH10: 0 | EI10: 0 | EJ10: 4 | EK10: 0 | EL10: 1 | EM10: =SUM(DZ10:EL10) -> 19 | EO10: الجامعة | EP10: سعودي | EQ10: ذكر | ER10: 3 | ES10: 4 | ET10: 2 | EU10: 3 | EV10: 0 | EW10: 0 | EX10: 2 | EY10: 0 | EZ10: 0 | FA10: 0 | FB10: 4 | FC10: 0 | FD10: 1 | FE10: =SUM(ER10:FD10) -> 19 | FG10: الجامعة | FH10: سعودي | FI10: ذكر | FW10: =SUM(FJ10:FV10) -> 0 | FY10: الجامعة | FZ10: سعودي | GA10: ذكر | GB10: 0 | GC10: 0 | GD10: 0 | GE10: 0 | GF10: 0 | GG10: 0 | GH10: 0 | GI10: 0 | GJ10: 0 | GK10: 0 | GL10: 0 | GM10: 0 | GN10: 0 | GO10: =SUM(GB10:GN10) -> 0 | GQ10: الجامعة | GR10: سعودي | GS10: ذكر | GT10: 0 | GU10: 0 | GV10: 0 | GW10: 0 | GX10: 0 | GY10: 0 | GZ10: 0 | HA10: 0 | HB10: 0 | HC10: 0 | HD10: 0 | HE10: 0 | HF10: 0 | HG10: =SUM(GT10:HF10) -> 0 | HI10: =GQ10 -> الجامعة | HJ10: سعودي | HK10: ذكر | HL10: =SUM(GT10) -> 0 | HM10: =SUM(GU10) -> 0 | HN10: =SUM(GV10) -> 0 | HO10: =SUM(GW10) -> 0 | HP10: =SUM(GX10) -> 0 | HQ10: =SUM(GY10) -> 0 | HR10: =SUM(GZ10) -> 0 | HS10: =SUM(HA10) -> 0 | ... HX10: =SUM(HF10) -> 0 | HY10: =SUM(HL10:HX10) -> 0
C11: أنثى | D11: 1 | E11: 4 | F11: 1 | G11: 19 | H11: 2 | I11: 0 | J11: 0 | K11: 0 | L11: 0 | M11: 0 | N11: 4 | O11: 0 | P11: 10 | Q11: =SUM(D11:P11) -> 41 | U11: أنثى | V11: 1 | W11: 4 | X11: 1 | Y11: 19 | Z11: 2 | AA11: 0 | AB11: 0 | AC11: 0 | AD11: 0 | AE11: 0 | AF11: 4 | AG11: 0 | AH11: 10 | AI11: =SUM(V11:AH11) -> 41 | AM11: أنثى | AN11: 1 | AO11: 4 | AP11: 1 | AQ11: 19 | AR11: 2 | AS11: 0 | AT11: 0 | AU11: 0 | AV11: 0 | AW11: 0 | AX11: 4 | AY11: 0 | AZ11: 10 | BA11: =SUM(AN11:AZ11) -> 41 | BE11: أنثى | BF11: 1 | BG11: 4 | BH11: 1 | BI11: 19 | BJ11: 2 | BK11: 0 | BL11: 0 | BM11: 0 | BN11: 0 | BO11: 0 | BP11: 4 | BQ11: 0 | BR11: 10 | BS11: =SUM(BF11:BR11) -> 41 | BW11: أنثى | BX11: 1 | BY11: 4 | BZ11: 1 | CA11: 19 | CB11: 2 | CC11: 0 | CD11: 0 | CE11: 0 | CF11: 0 | CG11: 0 | CH11: 4 | CI11: 0 | CJ11: 10 | CK11: =SUM(BX11:CJ11) -> 41 | CO11: أنثى | CP11: 1 | CQ11: 4 | CR11: 1 | CS11: 19 | CT11: 2 | CU11: 0 | CV11: 0 | CW11: 0 | CX11: 0 | CY11: 0 | CZ11: 4 | DA11: 0 | DB11: 10 | DC11: =SUM(CP11:DB11) -> 41 | DG11: أنثى | DH11: 1 | DI11: 4 | DJ11: 1 | DK11: 19 | DL11: 2 | DM11: 0 | DN11: 0 | DO11: 0 | DP11: 0 | DQ11: 0 | DR11: 4 | DS11: 0 | DT11: 10 | DU11: =SUM(DH11:DT11) -> 41 | DY11: أنثى | DZ11: 1 | EA11: 4 | EB11: 1 | EC11: 19 | ED11: 2 | EE11: 0 | EF11: 0 | EG11: 0 | EH11: 0 | EI11: 0 | EJ11: 4 | EK11: 0 | EL11: 10 | EM11: =SUM(DZ11:EL11) -> 41 | EQ11: أنثى | ER11: 1 | ES11: 4 | ET11: 1 | EU11: 19 | EV11: 2 | EW11: 0 | EX11: 0 | EY11: 0 | EZ11: 0 | FA11: 0 | FB11: 4 | FC11: 0 | FD11: 10 | FE11: =SUM(ER11:FD11) -> 41 | FI11: أنثى | FW11: =SUM(FJ11:FV11) -> 0 | GA11: أنثى | GB11: 0 | GC11: 0 | GD11: 0 | GE11: 0 | GF11: 0 | GG11: 0 | GH11: 0 | GI11: 0 | GJ11: 0 | GK11: 0 | GL11: 0 | GM11: 0 | GN11: 0 | GO11: =SUM(GB11:GN11) -> 0 | GS11: أنثى | GT11: 0 | GU11: 0 | GV11: 0 | GW11: 0 | GX11: 0 | GY11: 0 | GZ11: 0 | HA11: 0 | HB11: 0 | HC11: 0 | HD11: 0 | HE11: 0 | HF11: 0 | HG11: =SUM(GT11:HF11) -> 0 | HK11: أنثى | HL11: =SUM(GT11) -> 0 | HM11: =SUM(GU11) -> 0 | HN11: =SUM(GV11) -> 0 | HO11: =SUM(GW11) -> 0 | HP11: =SUM(GX11) -> 0 | HQ11: =SUM(GY11) -> 0 | HR11: =SUM(GZ11) -> 0 | HS11: =SUM(HA11) -> 0 | ... HX11: =SUM(HF11) -> 0 | HY11: =SUM(HL11:HX11) -> 0
B12: غير | C12: ذكر | D12: 0 | E12: 0 | F12: 0 | G12: 0 | H12: 0 | I12: 0 | J12: 0 | K12: 0 | L12: 0 | M12: 0 | N12: 0 | O12: 0 | P12: 0 | Q12: =SUM(D12:P12) -> 0 | T12: غير | U12: ذكر | V12: 0 | W12: 0 | X12: 0 | Y12: 0 | Z12: 0 | AA12: 0 | AB12: 0 | AC12: 0 | AD12: 0 | AE12: 0 | AF12: 0 | AG12: 0 | AH12: 0 | AI12: =SUM(V12:AH12) -> 0 | AL12: غير | AM12: ذكر | AN12: 0 | AO12: 0 | AP12: 0 | AQ12: 0 | AR12: 0 | AS12: 0 | AT12: 0 | AU12: 0 | AV12: 0 | AW12: 0 | AX12: 0 | AY12: 0 | AZ12: 0 | BA12: =SUM(AN12:AZ12) -> 0 | BD12: غير | BE12: ذكر | BF12: 0 | BG12: 0 | BH12: 0 | BI12: 0 | BJ12: 0 | BK12: 0 | BL12: 0 | BM12: 0 | BN12: 0 | BO12: 0 | BP12: 0 | BQ12: 0 | BR12: 0 | BS12: =SUM(BF12:BR12) -> 0 | BV12: غير | BW12: ذكر | BX12: 0 | BY12: 0 | BZ12: 0 | CA12: 0 | CB12: 0 | CC12: 0 | CD12: 0 | CE12: 0 | CF12: 0 | CG12: 0 | CH12: 0 | CI12: 0 | CJ12: 0 | CK12: =SUM(BX12:CJ12) -> 0 | CN12: غير | CO12: ذكر | CP12: 0 | CQ12: 0 | CR12: 0 | CS12: 0 | CT12: 0 | CU12: 0 | CV12: 0 | CW12: 0 | CX12: 0 | CY12: 0 | CZ12: 0 | DA12: 0 | DB12: 0 | DC12: =SUM(CP12:DB12) -> 0 | DF12: غير | DG12: ذكر | DH12: 0 | DI12: 0 | DJ12: 0 | DK12: 0 | DL12: 0 | DM12: 0 | DN12: 0 | DO12: 0 | DP12: 0 | DQ12: 0 | DR12: 0 | DS12: 0 | DT12: 0 | DU12: =SUM(DH12:DT12) -> 0 | DX12: غير | DY12: ذكر | DZ12: 0 | EA12: 0 | EB12: 0 | EC12: 0 | ED12: 0 | EE12: 0 | EF12: 0 | EG12: 0 | EH12: 0 | EI12: 0 | EJ12: 0 | EK12: 0 | EL12: 0 | EM12: =SUM(DZ12:EL12) -> 0 | EP12: غير | EQ12: ذكر | ER12: 0 | ES12: 0 | ET12: 0 | EU12: 0 | EV12: 0 | EW12: 0 | EX12: 0 | EY12: 0 | EZ12: 0 | FA12: 0 | FB12: 0 | FC12: 0 | FD12: 0 | FE12: =SUM(ER12:FD12) -> 0 | FH12: غير | FI12: ذكر | FW12: =SUM(FJ12:FV12) -> 0 | FZ12: غير | GA12: ذكر | GB12: 0 | GC12: 0 | GD12: 0 | GE12: 0 | GF12: 0 | GG12: 0 | GH12: 0 | GI12: 0 | GJ12: 0 | GK12: 0 | GL12: 0 | GM12: 0 | GN12: 0 | GO12: =SUM(GB12:GN12) -> 0 | GR12: غير | GS12: ذكر | GT12: 0 | GU12: 0 | GV12: 0 | GW12: 0 | GX12: 0 | GY12: 0 | GZ12: 0 | HA12: 0 | HB12: 0 | HC12: 0 | HD12: 0 | HE12: 0 | HF12: 0 | HG12: =SUM(GT12:HF12) -> 0 | HJ12: غير | HK12: ذكر | HL12: =SUM(GT12) -> 0 | HM12: =SUM(GU12) -> 0 | HN12: =SUM(GV12) -> 0 | HO12: =SUM(GW12) -> 0 | HP12: =SUM(GX12) -> 0 | HQ12: =SUM(GY12) -> 0 | HR12: =SUM(GZ12) -> 0 | HS12: =SUM(HA12) -> 0 | ... HX12: =SUM(HF12) -> 0 | HY12: =SUM(HL12:HX12) -> 0
B13: سعودي | C13: أنثى | D13: 0 | E13: 0 | F13: 0 | G13: 0 | H13: 0 | I13: 0 | J13: 0 | K13: 0 | L13: 0 | M13: 0 | N13: 0 | O13: 0 | P13: 0 | Q13: =SUM(D13:P13) -> 0 | T13: سعودي | U13: أنثى | V13: 0 | W13: 0 | X13: 0 | Y13: 0 | Z13: 0 | AA13: 0 | AB13: 0 | AC13: 0 | AD13: 0 | AE13: 0 | AF13: 0 | AG13: 0 | AH13: 0 | AI13: =SUM(V13:AH13) -> 0 | AL13: سعودي | AM13: أنثى | AN13: 0 | AO13: 0 | AP13: 0 | AQ13: 0 | AR13: 0 | AS13: 0 | AT13: 0 | AU13: 0 | AV13: 0 | AW13: 0 | AX13: 0 | AY13: 0 | AZ13: 0 | BA13: =SUM(AN13:AZ13) -> 0 | BD13: سعودي | BE13: أنثى | BF13: 0 | BG13: 0 | BH13: 0 | BI13: 0 | BJ13: 0 | BK13: 0 | BL13: 0 | BM13: 0 | BN13: 0 | BO13: 0 | BP13: 0 | BQ13: 0 | BR13: 0 | BS13: =SUM(BF13:BR13) -> 0 | BV13: سعودي | BW13: أنثى | BX13: 0 | BY13: 0 | BZ13: 0 | CA13: 0 | CB13: 0 | CC13: 0 | CD13: 0 | CE13: 0 | CF13: 0 | CG13: 0 | CH13: 0 | CI13: 0 | CJ13: 0 | CK13: =SUM(BX13:CJ13) -> 0 | CN13: سعودي | CO13: أنثى | CP13: 0 | CQ13: 0 | CR13: 0 | CS13: 0 | CT13: 0 | CU13: 0 | CV13: 0 | CW13: 0 | CX13: 0 | CY13: 0 | CZ13: 0 | DA13: 0 | DB13: 0 | DC13: =SUM(CP13:DB13) -> 0 | DF13: سعودي | DG13: أنثى | DH13: 0 | DI13: 0 | DJ13: 0 | DK13: 0 | DL13: 0 | DM13: 0 | DN13: 0 | DO13: 0 | DP13: 0 | DQ13: 0 | DR13: 0 | DS13: 0 | DT13: 0 | DU13: =SUM(DH13:DT13) -> 0 | DX13: سعودي | DY13: أنثى | DZ13: 0 | EA13: 0 | EB13: 0 | EC13: 0 | ED13: 0 | EE13: 0 | EF13: 0 | EG13: 0 | EH13: 0 | EI13: 0 | EJ13: 0 | EK13: 0 | EL13: 0 | EM13: =SUM(DZ13:EL13) -> 0 | EP13: سعودي | EQ13: أنثى | ER13: 0 | ES13: 0 | ET13: 0 | EU13: 0 | EV13: 0 | EW13: 0 | EX13: 0 | EY13: 0 | EZ13: 0 | FA13: 0 | FB13: 0 | FC13: 0 | FD13: 0 | FE13: =SUM(ER13:FD13) -> 0 | FH13: سعودي | FI13: أنثى | FW13: =SUM(FJ13:FV13) -> 0 | FZ13: سعودي | GA13: أنثى | GB13: 0 | GC13: 0 | GD13: 0 | GE13: 0 | GF13: 0 | GG13: 0 | GH13: 0 | GI13: 0 | GJ13: 0 | GK13: 0 | GL13: 0 | GM13: 0 | GN13: 0 | GO13: =SUM(GB13:GN13) -> 0 | GR13: سعودي | GS13: أنثى | GT13: 0 | GU13: 0 | GV13: 0 | GW13: 0 | GX13: 0 | GY13: 0 | GZ13: 0 | HA13: 0 | HB13: 0 | HC13: 0 | HD13: 0 | HE13: 0 | HF13: 0 | HG13: =SUM(GT13:HF13) -> 0 | HJ13: سعودي | HK13: أنثى | HL13: =SUM(GT13) -> 0 | HM13: =SUM(GU13) -> 0 | HN13: =SUM(GV13) -> 0 | HO13: =SUM(GW13) -> 0 | HP13: =SUM(GX13) -> 0 | HQ13: =SUM(GY13) -> 0 | HR13: =SUM(GZ13) -> 0 | HS13: =SUM(HA13) -> 0 | ... HX13: =SUM(HF13) -> 0 | HY13: =SUM(HL13:HX13) -> 0
B14: المجموع | D14: =SUM(D10:D13) -> 4 | E14: =SUM(E10:E13) -> 8 | F14: =SUM(F10:F13) -> 3 | G14: =SUM(G10:G13) -> 22 | H14: =SUM(H10:H13) -> 2 | I14: =SUM(I10:I13) -> 0 | J14: =SUM(J10:J13) -> 2 | K14: =SUM(K10:K13) -> 0 | ... Q14: =SUM(Q10:Q13) -> 60 | T14: المجموع | V14: =SUM(V10:V13) -> 4 | W14: =SUM(W10:W13) -> 8 | X14: =SUM(X10:X13) -> 3 | Y14: =SUM(Y10:Y13) -> 22 | Z14: =SUM(Z10:Z13) -> 2 | AA14: =SUM(AA10:AA13) -> 0 | AB14: =SUM(AB10:AB13) -> 2 | AC14: =SUM(AC10:AC13) -> 0 | ... AI14: =SUM(AI10:AI13) -> 60 | AL14: المجموع | AN14: =SUM(AN10:AN13) -> 4 | AO14: =SUM(AO10:AO13) -> 8 | AP14: =SUM(AP10:AP13) -> 3 | AQ14: =SUM(AQ10:AQ13) -> 22 | AR14: =SUM(AR10:AR13) -> 2 | AS14: =SUM(AS10:AS13) -> 0 | AT14: =SUM(AT10:AT13) -> 2 | AU14: =SUM(AU10:AU13) -> 0 | ... BA14: =SUM(BA10:BA13) -> 60 | BD14: المجموع | BF14: =SUM(BF10:BF13) -> 4 | BG14: =SUM(BG10:BG13) -> 8 | BH14: =SUM(BH10:BH13) -> 3 | BI14: =SUM(BI10:BI13) -> 22 | BJ14: =SUM(BJ10:BJ13) -> 2 | BK14: =SUM(BK10:BK13) -> 0 | BL14: =SUM(BL10:BL13) -> 2 | BM14: =SUM(BM10:BM13) -> 0 | ... BS14: =SUM(BS10:BS13) -> 60 | BV14: المجموع | BX14: =SUM(BX10:BX13) -> 4 | BY14: =SUM(BY10:BY13) -> 8 | BZ14: =SUM(BZ10:BZ13) -> 3 | CA14: =SUM(CA10:CA13) -> 22 | CB14: =SUM(CB10:CB13) -> 2 | CC14: =SUM(CC10:CC13) -> 0 | CD14: =SUM(CD10:CD13) -> 2 | CE14: =SUM(CE10:CE13) -> 0 | ... CK14: =SUM(CK10:CK13) -> 60 | CN14: المجموع | CP14: =SUM(CP10:CP13) -> 4 | CQ14: =SUM(CQ10:CQ13) -> 8 | CR14: =SUM(CR10:CR13) -> 3 | CS14: =SUM(CS10:CS13) -> 22 | CT14: =SUM(CT10:CT13) -> 2 | CU14: =SUM(CU10:CU13) -> 0 | CV14: =SUM(CV10:CV13) -> 2 | CW14: =SUM(CW10:CW13) -> 0 | ... DC14: =SUM(DC10:DC13) -> 60 | DF14: المجموع | DH14: =SUM(DH10:DH13) -> 4 | DI14: =SUM(DI10:DI13) -> 8 | DJ14: =SUM(DJ10:DJ13) -> 3 | DK14: =SUM(DK10:DK13) -> 22 | DL14: =SUM(DL10:DL13) -> 2 | DM14: =SUM(DM10:DM13) -> 0 | DN14: =SUM(DN10:DN13) -> 2 | DO14: =SUM(DO10:DO13) -> 0 | ... DU14: =SUM(DU10:DU13) -> 60 | DX14: المجموع | DZ14: =SUM(DZ10:DZ13) -> 4 | EA14: =SUM(EA10:EA13) -> 8 | EB14: =SUM(EB10:EB13) -> 3 | EC14: =SUM(EC10:EC13) -> 22 | ED14: =SUM(ED10:ED13) -> 2 | EE14: =SUM(EE10:EE13) -> 0 | EF14: =SUM(EF10:EF13) -> 2 | EG14: =SUM(EG10:EG13) -> 0 | ... EM14: =SUM(EM10:EM13) -> 60 | EP14: المجموع | ER14: =SUM(ER10:ER13) -> 4 | ES14: =SUM(ES10:ES13) -> 8 | ET14: =SUM(ET10:ET13) -> 3 | EU14: =SUM(EU10:EU13) -> 22 | EV14: =SUM(EV10:EV13) -> 2 | EW14: =SUM(EW10:EW13) -> 0 | EX14: =SUM(EX10:EX13) -> 2 | EY14: =SUM(EY10:EY13) -> 0 | ... FE14: =SUM(FE10:FE13) -> 60 | FH14: المجموع | FJ14: =SUM(FJ10:FJ13) -> 0 | FK14: =SUM(FK10:FK13) -> 0 | FL14: =SUM(FL10:FL13) -> 0 | FM14: =SUM(FM10:FM13) -> 0 | FN14: =SUM(FN10:FN13) -> 0 | FO14: =SUM(FO10:FO13) -> 0 | FP14: =SUM(FP10:FP13) -> 0 | FQ14: =SUM(FQ10:FQ13) -> 0 | ... FW14: =SUM(FW10:FW13) -> 0 | FZ14: المجموع | GB14: =SUM(GB10:GB13) -> 0 | GC14: =SUM(GC10:GC13) -> 0 | GD14: =SUM(GD10:GD13) -> 0 | GE14: =SUM(GE10:GE13) -> 0 | GF14: =SUM(GF10:GF13) -> 0 | GG14: =SUM(GG10:GG13) -> 0 | GH14: =SUM(GH10:GH13) -> 0 | GI14: =SUM(GI10:GI13) -> 0 | ... GO14: =SUM(GO10:GO13) -> 0 | GR14: المجموع | GT14: =SUM(GT10:GT13) -> 0 | GU14: =SUM(GU10:GU13) -> 0 | GV14: =SUM(GV10:GV13) -> 0 | GW14: =SUM(GW10:GW13) -> 0 | GX14: =SUM(GX10:GX13) -> 0 | GY14: =SUM(GY10:GY13) -> 0 | GZ14: =SUM(GZ10:GZ13) -> 0 | HA14: =SUM(HA10:HA13) -> 0 | ... HG14: =SUM(HG10:HG13) -> 0 | HJ14: المجموع | HL14: =SUM(HL10:HL13) -> 0 | HM14: =SUM(HM10:HM13) -> 0 | HN14: =SUM(HN10:HN13) -> 0 | HO14: =SUM(HO10:HO13) -> 0 | HP14: =SUM(HP10:HP13) -> 0 | HQ14: =SUM(HQ10:HQ13) -> 0 | HR14: =SUM(HR10:HR13) -> 0 | HS14: =SUM(HS10:HS13) -> 0 | ... HY14: =SUM(HY10:HY13) -> 0
A15: السليمانية | B15: سعودي | C15: ذكر | D15: 0 | E15: 10 | F15: 3 | G15: 5 | H15: 0 | I15: 0 | K15: 0 | L15: 0 | M15: 0 | N15: 1 | O15: 1 | P15: 0 | Q15: =SUM(D15:P15) -> 20 | S15: السليمانية | T15: سعودي | U15: ذكر | V15: 0 | W15: 10 | X15: 3 | Y15: 5 | Z15: 0 | AA15: 0 | AC15: 0 | AD15: 0 | AE15: 0 | AF15: 1 | AG15: 1 | AH15: 0 | AI15: =SUM(V15:AH15) -> 20 | AK15: السليمانية | AL15: سعودي | AM15: ذكر | AN15: 0 | AO15: 10 | AP15: 3 | AQ15: 5 | AR15: 0 | AS15: 0 | AU15: 0 | AV15: 0 | AW15: 0 | AX15: 1 | AY15: 1 | AZ15: 0 | BA15: =SUM(AN15:AZ15) -> 20 | BC15: السليمانية | BD15: سعودي | BE15: ذكر | BF15: 0 | BG15: 10 | BH15: 3 | BI15: 5 | BJ15: 0 | BK15: 0 | BM15: 0 | BN15: 0 | BO15: 0 | BP15: 1 | BQ15: 1 | BR15: 0 | BS15: =SUM(BF15:BR15) -> 20 | BU15: السليمانية | BV15: سعودي | BW15: ذكر | BX15: 0 | BY15: 10 | BZ15: 3 | CA15: 5 | CB15: 0 | CC15: 0 | CE15: 0 | CF15: 0 | CG15: 0 | CH15: 1 | CI15: 1 | CJ15: 0 | CK15: =SUM(BX15:CJ15) -> 20 | CM15: السليمانية | CN15: سعودي | CO15: ذكر | CP15: 0 | CQ15: 10 | CR15: 3 | CS15: 5 | CT15: 0 | CU15: 0 | CW15: 0 | CX15: 0 | CY15: 0 | CZ15: 1 | DA15: 1 | DB15: 0 | DC15: =SUM(CP15:DB15) -> 20 | DE15: السليمانية | DF15: سعودي | DG15: ذكر | DH15: 0 | DI15: 10 | DJ15: 3 | DK15: 5 | DL15: 0 | DM15: 0 | DO15: 0 | DP15: 0 | DQ15: 0 | DR15: 1 | DS15: 1 | DT15: 0 | DU15: =SUM(DH15:DT15) -> 20 | DW15: السليمانية | DX15: سعودي | DY15: ذكر | DZ15: 0 | EA15: 10 | EB15: 3 | EC15: 5 | ED15: 0 | EE15: 0 | EG15: 0 | EH15: 0 | EI15: 0 | EJ15: 1 | EK15: 1 | EL15: 0 | EM15: =SUM(DZ15:EL15) -> 20 | EO15: السليمانية | EP15: سعودي | EQ15: ذكر | ER15: 0 | ES15: 10 | ET15: 3 | EU15: 5 | EV15: 0 | EW15: 0 | EY15: 0 | EZ15: 0 | FA15: 0 | FB15: 1 | FC15: 1 | FD15: 0 | FE15: =SUM(ER15:FD15) -> 20 | FG15: السليمانية | FH15: سعودي | FI15: ذكر | FJ15: 0 | FK15: 10 | FL15: 3 | FM15: 5 | FN15: 0 | FO15: 0 | FQ15: 0 | FR15: 0 | FS15: 0 | FT15: 1 | FU15: 1 | FV15: 0 | FW15: =SUM(FJ15:FV15) -> 20 | FY15: السليمانية | FZ15: سعودي | GA15: ذكر | GB15: 0 | GC15: 0 | GD15: 0 | GE15: 0 | GF15: 0 | GG15: 0 | GH15: 0 | GI15: 0 | GJ15: 0 | GK15: 0 | GL15: 0 | GM15: 0 | GN15: 0 | GO15: =SUM(GB15:GN15) -> 0 | GQ15: السليمانية | GR15: سعودي | GS15: ذكر | GT15: 0 | GU15: 0 | GV15: 0 | GW15: 0 | GX15: 0 | GY15: 0 | GZ15: 0 | HA15: 0 | HB15: 0 | HC15: 0 | HD15: 0 | HE15: 0 | HF15: 0 | HG15: =SUM(GT15:HF15) -> 0 | HI15: =GQ15 -> السليمانية | HJ15: سعودي | HK15: ذكر | HL15: =SUM(GT15) -> 0 | HM15: =SUM(GU15) -> 0 | HN15: =SUM(GV15) -> 0 | HO15: =SUM(GW15) -> 0 | HP15: =SUM(GX15) -> 0 | HQ15: =SUM(GY15) -> 0 | HR15: =SUM(GZ15) -> 0 | HS15: =SUM(HA15) -> 0 | ... HX15: =SUM(HF15) -> 0 | HY15: =SUM(HL15:HX15) -> 0
C16: أنثى | D16: 0 | E16: 4 | F16: 0 | G16: 25 | H16: 0 | I16: 0 | J16: 1 | K16: 1 | L16: 0 | M16: 0 | N16: 2 | O16: 0 | P16: 0 | Q16: =SUM(D16:P16) -> 33 | U16: أنثى | V16: 0 | W16: 4 | X16: 0 | Y16: 25 | Z16: 0 | AA16: 0 | AB16: 1 | AC16: 1 | AD16: 0 | AE16: 0 | AF16: 2 | AG16: 0 | AH16: 0 | AI16: =SUM(V16:AH16) -> 33 | AM16: أنثى | AN16: 0 | AO16: 4 | AP16: 0 | AQ16: 25 | AR16: 0 | AS16: 0 | AT16: 1 | AU16: 1 | AV16: 0 | AW16: 0 | AX16: 2 | AY16: 0 | AZ16: 0 | BA16: =SUM(AN16:AZ16) -> 33 | BE16: أنثى | BF16: 0 | BG16: 4 | BH16: 0 | BI16: 25 | BJ16: 0 | BK16: 0 | BL16: 1 | BM16: 1 | BN16: 0 | BO16: 0 | BP16: 2 | BQ16: 0 | BR16: 0 | BS16: =SUM(BF16:BR16) -> 33 | BW16: أنثى | BX16: 0 | BY16: 4 | BZ16: 0 | CA16: 25 | CB16: 0 | CC16: 0 | CD16: 1 | CE16: 1 | CF16: 0 | CG16: 0 | CH16: 2 | CI16: 0 | CJ16: 0 | CK16: =SUM(BX16:CJ16) -> 33 | CO16: أنثى | CP16: 0 | CQ16: 4 | CR16: 0 | CS16: 25 | CT16: 0 | CU16: 0 | CV16: 1 | CW16: 1 | CX16: 0 | CY16: 0 | CZ16: 2 | DA16: 0 | DB16: 0 | DC16: =SUM(CP16:DB16) -> 33 | DG16: أنثى | DH16: 0 | DI16: 4 | DJ16: 0 | DK16: 25 | DL16: 0 | DM16: 0 | DN16: 1 | DO16: 1 | DP16: 0 | DQ16: 0 | DR16: 2 | DS16: 0 | DT16: 0 | DU16: =SUM(DH16:DT16) -> 33 | DY16: أنثى | DZ16: 0 | EA16: 4 | EB16: 0 | EC16: 25 | ED16: 0 | EE16: 0 | EF16: 1 | EG16: 1 | EH16: 0 | EI16: 0 | EJ16: 2 | EK16: 0 | EL16: 0 | EM16: =SUM(DZ16:EL16) -> 33 | EQ16: أنثى | ER16: 0 | ES16: 4 | ET16: 0 | EU16: 25 | EV16: 0 | EW16: 0 | EX16: 1 | EY16: 1 | EZ16: 0 | FA16: 0 | FB16: 2 | FC16: 0 | FD16: 0 | FE16: =SUM(ER16:FD16) -> 33 | FI16: أنثى | FJ16: 0 | FK16: 4 | FL16: 0 | FM16: 25 | FN16: 0 | FO16: 0 | FP16: 1 | FQ16: 1 | FR16: 0 | FS16: 0 | FT16: 2 | FU16: 0 | FV16: 0 | FW16: =SUM(FJ16:FV16) -> 33 | GA16: أنثى | GB16: 0 | GC16: 0 | GD16: 0 | GE16: 0 | GF16: 0 | GG16: 0 | GH16: 0 | GI16: 0 | GJ16: 0 | GK16: 0 | GL16: 0 | GM16: 0 | GN16: 0 | GO16: =SUM(GB16:GN16) -> 0 | GS16: أنثى | GT16: 0 | GU16: 0 | GV16: 0 | GW16: 0 | GX16: 0 | GY16: 0 | GZ16: 0 | HA16: 0 | HB16: 0 | HC16: 0 | HD16: 0 | HE16: 0 | HF16: 0 | HG16: =SUM(GT16:HF16) -> 0 | HK16: أنثى | HL16: =SUM(GT16) -> 0 | HM16: =SUM(GU16) -> 0 | HN16: =SUM(GV16) -> 0 | HO16: =SUM(GW16) -> 0 | HP16: =SUM(GX16) -> 0 | HQ16: =SUM(GY16) -> 0 | HR16: =SUM(GZ16) -> 0 | HS16: =SUM(HA16) -> 0 | ... HX16: =SUM(HF16) -> 0 | HY16: =SUM(HL16:HX16) -> 0
B17: غير | C17: ذكر | D17: 0 | E17: 0 | F17: 0 | G17: 0 | H17: 0 | I17: 0 | J17: 0 | K17: 0 | L17: 0 | M17: 0 | N17: 0 | O17: 0 | P17: 0 | Q17: =SUM(D17:P17) -> 0 | T17: غير | U17: ذكر | V17: 0 | W17: 0 | X17: 0 | Y17: 0 | Z17: 0 | AA17: 0 | AB17: 0 | AC17: 0 | AD17: 0 | AE17: 0 | AF17: 0 | AG17: 0 | AH17: 0 | AI17: =SUM(V17:AH17) -> 0 | AL17: غير | AM17: ذكر | AN17: 0 | AO17: 0 | AP17: 0 | AQ17: 0 | AR17: 0 | AS17: 0 | AT17: 0 | AU17: 0 | AV17: 0 | AW17: 0 | AX17: 0 | AY17: 0 | AZ17: 0 | BA17: =SUM(AN17:AZ17) -> 0 | BD17: غير | BE17: ذكر | BF17: 0 | BG17: 0 | BH17: 0 | BI17: 0 | BJ17: 0 | BK17: 0 | BL17: 0 | BM17: 0 | BN17: 0 | BO17: 0 | BP17: 0 | BQ17: 0 | BR17: 0 | BS17: =SUM(BF17:BR17) -> 0 | BV17: غير | BW17: ذكر | BX17: 0 | BY17: 0 | BZ17: 0 | CA17: 0 | CB17: 0 | CC17: 0 | CD17: 0 | CE17: 0 | CF17: 0 | CG17: 0 | CH17: 0 | CI17: 0 | CJ17: 0 | CK17: =SUM(BX17:CJ17) -> 0 | CN17: غير | CO17: ذكر | CP17: 0 | CQ17: 0 | CR17: 0 | CS17: 0 | CT17: 0 | CU17: 0 | CV17: 0 | CW17: 0 | CX17: 0 | CY17: 0 | CZ17: 0 | DA17: 0 | DB17: 0 | DC17: =SUM(CP17:DB17) -> 0 | DF17: غير | DG17: ذكر | DH17: 0 | DI17: 0 | DJ17: 0 | DK17: 0 | DL17: 0 | DM17: 0 | DN17: 0 | DO17: 0 | DP17: 0 | DQ17: 0 | DR17: 0 | DS17: 0 | DT17: 0 | DU17: =SUM(DH17:DT17) -> 0 | DX17: غير | DY17: ذكر | DZ17: 0 | EA17: 0 | EB17: 0 | EC17: 0 | ED17: 0 | EE17: 0 | EF17: 0 | EG17: 0 | EH17: 0 | EI17: 0 | EJ17: 0 | EK17: 0 | EL17: 0 | EM17: =SUM(DZ17:EL17) -> 0 | EP17: غير | EQ17: ذكر | ER17: 0 | ES17: 0 | ET17: 0 | EU17: 0 | EV17: 0 | EW17: 0 | EX17: 0 | EY17: 0 | EZ17: 0 | FA17: 0 | FB17: 0 | FC17: 0 | FD17: 0 | FE17: =SUM(ER17:FD17) -> 0 | FH17: غير | FI17: ذكر | FJ17: 0 | FK17: 0 | FL17: 0 | FM17: 0 | FN17: 0 | FO17: 0 | FP17: 0 | FQ17: 0 | FR17: 0 | FS17: 0 | FT17: 0 | FU17: 0 | FV17: 0 | FW17: =SUM(FJ17:FV17) -> 0 | FZ17: غير | GA17: ذكر | GB17: 0 | GC17: 0 | GD17: 0 | GE17: 0 | GF17: 0 | GG17: 0 | GH17: 0 | GI17: 0 | GJ17: 0 | GK17: 0 | GL17: 0 | GM17: 0 | GN17: 0 | GO17: =SUM(GB17:GN17) -> 0 | GR17: غير | GS17: ذكر | GT17: 0 | GU17: 0 | GV17: 0 | GW17: 0 | GX17: 0 | GY17: 0 | GZ17: 0 | HA17: 0 | HB17: 0 | HC17: 0 | HD17: 0 | HE17: 0 | HF17: 0 | HG17: =SUM(GT17:HF17) -> 0 | HJ17: غير | HK17: ذكر | HL17: =SUM(GT17) -> 0 | HM17: =SUM(GU17) -> 0 | HN17: =SUM(GV17) -> 0 | HO17: =SUM(GW17) -> 0 | HP17: =SUM(GX17) -> 0 | HQ17: =SUM(GY17) -> 0 | HR17: =SUM(GZ17) -> 0 | HS17: =SUM(HA17) -> 0 | ... HX17: =SUM(HF17) -> 0 | HY17: =SUM(HL17:HX17) -> 0
B18: سعودي | C18: أنثى | D18: 0 | E18: 0 | F18: 0 | G18: 0 | H18: 0 | I18: 0 | J18: 0 | K18: 0 | L18: 0 | M18: 0 | N18: 0 | O18: 0 | P18: 0 | Q18: =SUM(D18:P18) -> 0 | T18: سعودي | U18: أنثى | V18: 0 | W18: 0 | X18: 0 | Y18: 0 | Z18: 0 | AA18: 0 | AB18: 0 | AC18: 0 | AD18: 0 | AE18: 0 | AF18: 0 | AG18: 0 | AH18: 0 | AI18: =SUM(V18:AH18) -> 0 | AL18: سعودي | AM18: أنثى | AN18: 0 | AO18: 0 | AP18: 0 | AQ18: 0 | AR18: 0 | AS18: 0 | AT18: 0 | AU18: 0 | AV18: 0 | AW18: 0 | AX18: 0 | AY18: 0 | AZ18: 0 | BA18: =SUM(AN18:AZ18) -> 0 | BD18: سعودي | BE18: أنثى | BF18: 0 | BG18: 0 | BH18: 0 | BI18: 0 | BJ18: 0 | BK18: 0 | BL18: 0 | BM18: 0 | BN18: 0 | BO18: 0 | BP18: 0 | BQ18: 0 | BR18: 0 | BS18: =SUM(BF18:BR18) -> 0 | BV18: سعودي | BW18: أنثى | BX18: 0 | BY18: 0 | BZ18: 0 | CA18: 0 | CB18: 0 | CC18: 0 | CD18: 0 | CE18: 0 | CF18: 0 | CG18: 0 | CH18: 0 | CI18: 0 | CJ18: 0 | CK18: =SUM(BX18:CJ18) -> 0 | CN18: سعودي | CO18: أنثى | CP18: 0 | CQ18: 0 | CR18: 0 | CS18: 0 | CT18: 0 | CU18: 0 | CV18: 0 | CW18: 0 | CX18: 0 | CY18: 0 | CZ18: 0 | DA18: 0 | DB18: 0 | DC18: =SUM(CP18:DB18) -> 0 | DF18: سعودي | DG18: أنثى | DH18: 0 | DI18: 0 | DJ18: 0 | DK18: 0 | DL18: 0 | DM18: 0 | DN18: 0 | DO18: 0 | DP18: 0 | DQ18: 0 | DR18: 0 | DS18: 0 | DT18: 0 | DU18: =SUM(DH18:DT18) -> 0 | DX18: سعودي | DY18: أنثى | DZ18: 0 | EA18: 0 | EB18: 0 | EC18: 0 | ED18: 0 | EE18: 0 | EF18: 0 | EG18: 0 | EH18: 0 | EI18: 0 | EJ18: 0 | EK18: 0 | EL18: 0 | EM18: =SUM(DZ18:EL18) -> 0 | EP18: سعودي | EQ18: أنثى | ER18: 0 | ES18: 0 | ET18: 0 | EU18: 0 | EV18: 0 | EW18: 0 | EX18: 0 | EY18: 0 | EZ18: 0 | FA18: 0 | FB18: 0 | FC18: 0 | FD18: 0 | FE18: =SUM(ER18:FD18) -> 0 | FH18: سعودي | FI18: أنثى | FJ18: 0 | FK18: 0 | FL18: 0 | FM18: 0 | FN18: 0 | FO18: 0 | FP18: 0 | FQ18: 0 | FR18: 0 | FS18: 0 | FT18: 0 | FU18: 0 | FV18: 0 | FW18: =SUM(FJ18:FV18) -> 0 | FZ18: سعودي | GA18: أنثى | GB18: 0 | GC18: 0 | GD18: 0 | GE18: 0 | GF18: 0 | GG18: 0 | GH18: 0 | GI18: 0 | GJ18: 0 | GK18: 0 | GL18: 0 | GM18: 0 | GN18: 0 | GO18: =SUM(GB18:GN18) -> 0 | GR18: سعودي | GS18: أنثى | GT18: 0 | GU18: 0 | GV18: 0 | GW18: 0 | GX18: 0 | GY18: 0 | GZ18: 0 | HA18: 0 | HB18: 0 | HC18: 0 | HD18: 0 | HE18: 0 | HF18: 0 | HG18: =SUM(GT18:HF18) -> 0 | HJ18: سعودي | HK18: أنثى | HL18: =SUM(GT18) -> 0 | HM18: =SUM(GU18) -> 0 | HN18: =SUM(GV18) -> 0 | HO18: =SUM(GW18) -> 0 | HP18: =SUM(GX18) -> 0 | HQ18: =SUM(GY18) -> 0 | HR18: =SUM(GZ18) -> 0 | HS18: =SUM(HA18) -> 0 | ... HX18: =SUM(HF18) -> 0 | HY18: =SUM(HL18:HX18) -> 0
B19: المجموع | D19: =SUM(D15:D18) -> 0 | E19: =SUM(E15:E18) -> 14 | F19: =SUM(F15:F18) -> 3 | G19: =SUM(G15:G18) -> 30 | H19: =SUM(H15:H18) -> 0 | I19: =SUM(I15:I18) -> 0 | J19: =SUM(J15:J18) -> 1 | K19: =SUM(K15:K18) -> 1 | ... Q19: =SUM(Q15:Q18) -> 53 | T19: المجموع | V19: =SUM(V15:V18) -> 0 | W19: =SUM(W15:W18) -> 14 | X19: =SUM(X15:X18) -> 3 | Y19: =SUM(Y15:Y18) -> 30 | Z19: =SUM(Z15:Z18) -> 0 | AA19: =SUM(AA15:AA18) -> 0 | AB19: =SUM(AB15:AB18) -> 1 | AC19: =SUM(AC15:AC18) -> 1 | ... AI19: =SUM(AI15:AI18) -> 53 | AL19: المجموع | AN19: =SUM(AN15:AN18) -> 0 | AO19: =SUM(AO15:AO18) -> 14 | AP19: =SUM(AP15:AP18) -> 3 | AQ19: =SUM(AQ15:AQ18) -> 30 | AR19: =SUM(AR15:AR18) -> 0 | AS19: =SUM(AS15:AS18) -> 0 | AT19: =SUM(AT15:AT18) -> 1 | AU19: =SUM(AU15:AU18) -> 1 | ... BA19: =SUM(BA15:BA18) -> 53 | BD19: المجموع | BF19: =SUM(BF15:BF18) -> 0 | BG19: =SUM(BG15:BG18) -> 14 | BH19: =SUM(BH15:BH18) -> 3 | BI19: =SUM(BI15:BI18) -> 30 | BJ19: =SUM(BJ15:BJ18) -> 0 | BK19: =SUM(BK15:BK18) -> 0 | BL19: =SUM(BL15:BL18) -> 1 | BM19: =SUM(BM15:BM18) -> 1 | ... BS19: =SUM(BS15:BS18) -> 53 | BV19: المجموع | BX19: =SUM(BX15:BX18) -> 0 | BY19: =SUM(BY15:BY18) -> 14 | BZ19: =SUM(BZ15:BZ18) -> 3 | CA19: =SUM(CA15:CA18) -> 30 | CB19: =SUM(CB15:CB18) -> 0 | CC19: =SUM(CC15:CC18) -> 0 | CD19: =SUM(CD15:CD18) -> 1 | CE19: =SUM(CE15:CE18) -> 1 | ... CK19: =SUM(CK15:CK18) -> 53 | CN19: المجموع | CP19: =SUM(CP15:CP18) -> 0 | CQ19: =SUM(CQ15:CQ18) -> 14 | CR19: =SUM(CR15:CR18) -> 3 | CS19: =SUM(CS15:CS18) -> 30 | CT19: =SUM(CT15:CT18) -> 0 | CU19: =SUM(CU15:CU18) -> 0 | CV19: =SUM(CV15:CV18) -> 1 | CW19: =SUM(CW15:CW18) -> 1 | ... DC19: =SUM(DC15:DC18) -> 53 | DF19: المجموع | DH19: =SUM(DH15:DH18) -> 0 | DI19: =SUM(DI15:DI18) -> 14 | DJ19: =SUM(DJ15:DJ18) -> 3 | DK19: =SUM(DK15:DK18) -> 30 | DL19: =SUM(DL15:DL18) -> 0 | DM19: =SUM(DM15:DM18) -> 0 | DN19: =SUM(DN15:DN18) -> 1 | DO19: =SUM(DO15:DO18) -> 1 | ... DU19: =SUM(DU15:DU18) -> 53 | DX19: المجموع | DZ19: =SUM(DZ15:DZ18) -> 0 | EA19: =SUM(EA15:EA18) -> 14 | EB19: =SUM(EB15:EB18) -> 3 | EC19: =SUM(EC15:EC18) -> 30 | ED19: =SUM(ED15:ED18) -> 0 | EE19: =SUM(EE15:EE18) -> 0 | EF19: =SUM(EF15:EF18) -> 1 | EG19: =SUM(EG15:EG18) -> 1 | ... EM19: =SUM(EM15:EM18) -> 53 | EP19: المجموع | ER19: =SUM(ER15:ER18) -> 0 | ES19: =SUM(ES15:ES18) -> 14 | ET19: =SUM(ET15:ET18) -> 3 | EU19: =SUM(EU15:EU18) -> 30 | EV19: =SUM(EV15:EV18) -> 0 | EW19: =SUM(EW15:EW18) -> 0 | EX19: =SUM(EX15:EX18) -> 1 | EY19: =SUM(EY15:EY18) -> 1 | ... FE19: =SUM(FE15:FE18) -> 53 | FH19: المجموع | FJ19: =SUM(FJ15:FJ18) -> 0 | FK19: =SUM(FK15:FK18) -> 14 | FL19: =SUM(FL15:FL18) -> 3 | FM19: =SUM(FM15:FM18) -> 30 | FN19: =SUM(FN15:FN18) -> 0 | FO19: =SUM(FO15:FO18) -> 0 | FP19: =SUM(FP15:FP18) -> 1 | FQ19: =SUM(FQ15:FQ18) -> 1 | ... FW19: =SUM(FW15:FW18) -> 53 | FZ19: المجموع | GB19: =SUM(GB15:GB18) -> 0 | GC19: =SUM(GC15:GC18) -> 0 | GD19: =SUM(GD15:GD18) -> 0 | GE19: =SUM(GE15:GE18) -> 0 | GF19: =SUM(GF15:GF18) -> 0 | GG19: =SUM(GG15:GG18) -> 0 | GH19: =SUM(GH15:GH18) -> 0 | GI19: =SUM(GI15:GI18) -> 0 | ... GO19: =SUM(GO15:GO18) -> 0 | GR19: المجموع | GT19: =SUM(GT15:GT18) -> 0 | GU19: =SUM(GU15:GU18) -> 0 | GV19: =SUM(GV15:GV18) -> 0 | GW19: =SUM(GW15:GW18) -> 0 | GX19: =SUM(GX15:GX18) -> 0 | GY19: =SUM(GY15:GY18) -> 0 | GZ19: =SUM(GZ15:GZ18) -> 0 | HA19: =SUM(HA15:HA18) -> 0 | ... HG19: =SUM(HG15:HG18) -> 0 | HJ19: المجموع | HL19: =SUM(HL15:HL18) -> 0 | HM19: =SUM(HM15:HM18) -> 0 | HN19: =SUM(HN15:HN18) -> 0 | HO19: =SUM(HO15:HO18) -> 0 | HP19: =SUM(HP15:HP18) -> 0 | HQ19: =SUM(HQ15:HQ18) -> 0 | HR19: =SUM(HR15:HR18) -> 0 | HS19: =SUM(HS15:HS18) -> 0 | ... HY19: =SUM(HY15:HY18) -> 0
A20: المطار القديم | B20: سعودي | C20: ذكر | D20: 1 | E20: 2 | F20: 3 | G20: 3 | H20: 0 | I20: 0 | J20: 2 | K20: 0 | L20: 1 | M20: 0 | N20: 6 | O20: 1 | P20: 4 | Q20: =SUM(D20:P20) -> 23 | S20: المطار القديم | T20: سعودي | U20: ذكر | V20: 1 | W20: 2 | X20: 3 | Y20: 3 | Z20: 0 | AA20: 0 | AB20: 2 | AC20: 0 | AD20: 1 | AE20: 0 | AF20: 6 | AG20: 1 | AH20: 4 | AI20: =SUM(V20:AH20) -> 23 | AK20: المطار القديم | AL20: سعودي | AM20: ذكر | AN20: 1 | AO20: 2 | AP20: 3 | AQ20: 3 | AR20: 0 | AS20: 0 | AT20: 2 | AU20: 0 | AV20: 1 | AW20: 0 | AX20: 6 | AY20: 1 | AZ20: 4 | BA20: =SUM(AN20:AZ20) -> 23 | BC20: المطار القديم | BD20: سعودي | BE20: ذكر | BF20: 1 | BG20: 2 | BH20: 3 | BI20: 3 | BJ20: 0 | BK20: 0 | BL20: 2 | BM20: 0 | BN20: 1 | BO20: 0 | BP20: 6 | BQ20: 1 | BR20: 4 | BS20: =SUM(BF20:BR20) -> 23 | BU20: المطار القديم | BV20: سعودي | BW20: ذكر | BX20: 1 | BY20: 2 | BZ20: 3 | CA20: 3 | CB20: 0 | CC20: 0 | CD20: 2 | CE20: 0 | CF20: 1 | CG20: 0 | CH20: 6 | CI20: 1 | CJ20: 4 | CK20: =SUM(BX20:CJ20) -> 23 | CM20: المطار القديم | CN20: سعودي | CO20: ذكر | CP20: 1 | CQ20: 2 | CR20: 3 | CS20: 3 | CT20: 0 | CU20: 0 | CV20: 2 | CW20: 0 | CX20: 1 | CY20: 0 | CZ20: 6 | DA20: 1 | DB20: 4 | DC20: =SUM(CP20:DB20) -> 23 | DE20: المطار القديم | DF20: سعودي | DG20: ذكر | DH20: 1 | DI20: 2 | DJ20: 3 | DK20: 3 | DL20: 0 | DM20: 0 | DN20: 2 | DO20: 0 | DP20: 1 | DQ20: 0 | DR20: 6 | DS20: 1 | DT20: 4 | DU20: =SUM(DH20:DT20) -> 23 | DW20: المطار القديم | DX20: سعودي | DY20: ذكر | DZ20: 1 | EA20: 2 | EB20: 3 | EC20: 3 | ED20: 0 | EE20: 0 | EF20: 2 | EG20: 0 | EH20: 1 | EI20: 0 | EJ20: 6 | EK20: 1 | EL20: 4 | EM20: =SUM(DZ20:EL20) -> 23 | EO20: المطار القديم | EP20: سعودي | EQ20: ذكر | ER20: 1 | ES20: 2 | ET20: 3 | EU20: 3 | EV20: 0 | EW20: 0 | EX20: 2 | EY20: 0 | EZ20: 1 | FA20: 0 | FB20: 6 | FC20: 1 | FD20: 4 | FE20: =SUM(ER20:FD20) -> 23 | FG20: المطار القديم | FH20: سعودي | FI20: ذكر | FJ20: 1 | FK20: 2 | FL20: 3 | FM20: 3 | FN20: 0 | FO20: 0 | FP20: 2 | FQ20: 0 | FR20: 1 | FS20: 0 | FT20: 6 | FU20: 1 | FV20: 4 | FW20: =SUM(FJ20:FV20) -> 23 | FY20: المطار القديم | FZ20: سعودي | GA20: ذكر | GB20: 0 | GC20: 0 | GD20: 0 | GE20: 0 | GF20: 0 | GG20: 0 | GH20: 0 | GI20: 0 | GJ20: 0 | GK20: 0 | GL20: 0 | GM20: 0 | GN20: 0 | GO20: =SUM(GB20:GN20) -> 0 | GQ20: المطار القديم | GR20: سعودي | GS20: ذكر | GT20: 0 | GU20: 0 | GV20: 0 | GW20: 0 | GX20: 0 | GY20: 0 | GZ20: 0 | HA20: 0 | HB20: 0 | HC20: 0 | HD20: 0 | HE20: 0 | HF20: 0 | HG20: =SUM(GT20:HF20) -> 0 | HI20: =GQ20 -> المطار القديم | HJ20: سعودي | HK20: ذكر | HL20: =SUM(GT20) -> 0 | HM20: =SUM(GU20) -> 0 | HN20: =SUM(GV20) -> 0 | HO20: =SUM(GW20) -> 0 | HP20: =SUM(GX20) -> 0 | HQ20: =SUM(GY20) -> 0 | HR20: =SUM(GZ20) -> 0 | HS20: =SUM(HA20) -> 0 | ... HX20: =SUM(HF20) -> 0 | HY20: =SUM(HL20:HX20) -> 0
C21: أنثى | D21: 3 | E21: 2 | F21: 3 | G21: 12 | H21: 0 | I21: 0 | J21: 0 | K21: 0 | L21: 0 | M21: 0 | N21: 9 | O21: 1 | P21: 3 | Q21: =SUM(D21:P21) -> 33 | U21: أنثى | V21: 3 | W21: 2 | X21: 3 | Y21: 12 | Z21: 0 | AA21: 0 | AB21: 0 | AC21: 0 | AD21: 0 | AE21: 0 | AF21: 9 | AG21: 1 | AH21: 3 | AI21: =SUM(V21:AH21) -> 33 | AM21: أنثى | AN21: 3 | AO21: 2 | AP21: 3 | AQ21: 12 | AR21: 0 | AS21: 0 | AT21: 0 | AU21: 0 | AV21: 0 | AW21: 0 | AX21: 9 | AY21: 1 | AZ21: 3 | BA21: =SUM(AN21:AZ21) -> 33 | BE21: أنثى | BF21: 3 | BG21: 2 | BH21: 3 | BI21: 12 | BJ21: 0 | BK21: 0 | BL21: 0 | BM21: 0 | BN21: 0 | BO21: 0 | BP21: 9 | BQ21: 1 | BR21: 3 | BS21: =SUM(BF21:BR21) -> 33 | BW21: أنثى | BX21: 3 | BY21: 2 | BZ21: 3 | CA21: 12 | CB21: 0 | CC21: 0 | CD21: 0 | CE21: 0 | CF21: 0 | CG21: 0 | CH21: 9 | CI21: 1 | CJ21: 3 | CK21: =SUM(BX21:CJ21) -> 33 | CO21: أنثى | CP21: 3 | CQ21: 2 | CR21: 3 | CS21: 12 | CT21: 0 | CU21: 0 | CV21: 0 | CW21: 0 | CX21: 0 | CY21: 0 | CZ21: 9 | DA21: 1 | DB21: 3 | DC21: =SUM(CP21:DB21) -> 33 | DG21: أنثى | DH21: 3 | DI21: 2 | DJ21: 3 | DK21: 12 | DL21: 0 | DM21: 0 | DN21: 0 | DO21: 0 | DP21: 0 | DQ21: 0 | DR21: 9 | DS21: 1 | DT21: 3 | DU21: =SUM(DH21:DT21) -> 33 | DY21: أنثى | DZ21: 3 | EA21: 2 | EB21: 3 | EC21: 12 | ED21: 0 | EE21: 0 | EF21: 0 | EG21: 0 | EH21: 0 | EI21: 0 | EJ21: 9 | EK21: 1 | EL21: 3 | EM21: =SUM(DZ21:EL21) -> 33 | EQ21: أنثى | ER21: 3 | ES21: 2 | ET21: 3 | EU21: 12 | EV21: 0 | EW21: 0 | EX21: 0 | EY21: 0 | EZ21: 0 | FA21: 0 | FB21: 9 | FC21: 1 | FD21: 3 | FE21: =SUM(ER21:FD21) -> 33 | FI21: أنثى | FJ21: 3 | FK21: 2 | FL21: 3 | FM21: 12 | FN21: 0 | FO21: 0 | FP21: 0 | FQ21: 0 | FR21: 0 | FS21: 0 | FT21: 9 | FU21: 1 | FV21: 3 | FW21: =SUM(FJ21:FV21) -> 33 | GA21: أنثى | GB21: 0 | GC21: 0 | GD21: 0 | GE21: 0 | GF21: 0 | GG21: 0 | GH21: 0 | GI21: 0 | GJ21: 0 | GK21: 0 | GL21: 0 | GM21: 0 | GN21: 0 | GO21: =SUM(GB21:GN21) -> 0 | GS21: أنثى | GT21: 0 | GU21: 0 | GV21: 0 | GW21: 0 | GX21: 0 | GY21: 0 | GZ21: 0 | HA21: 0 | HB21: 0 | HC21: 0 | HD21: 0 | HE21: 0 | HF21: 0 | HG21: =SUM(GT21:HF21) -> 0 | HK21: أنثى | HL21: =SUM(GT21) -> 0 | HM21: =SUM(GU21) -> 0 | HN21: =SUM(GV21) -> 0 | HO21: =SUM(GW21) -> 0 | HP21: =SUM(GX21) -> 0 | HQ21: =SUM(GY21) -> 0 | HR21: =SUM(GZ21) -> 0 | HS21: =SUM(HA21) -> 0 | ... HX21: =SUM(HF21) -> 0 | HY21: =SUM(HL21:HX21) -> 0
B22: غير | C22: ذكر | D22: 0 | E22: 0 | F22: 0 | G22: 0 | H22: 0 | I22: 0 | J22: 0 | K22: 0 | L22: 0 | M22: 0 | N22: 0 | O22: 0 | P22: 0 | Q22: =SUM(D22:P22) -> 0 | T22: غير | U22: ذكر | V22: 0 | W22: 0 | X22: 0 | Y22: 0 | Z22: 0 | AA22: 0 | AB22: 0 | AC22: 0 | AD22: 0 | AE22: 0 | AF22: 0 | AG22: 0 | AH22: 0 | AI22: =SUM(V22:AH22) -> 0 | AL22: غير | AM22: ذكر | AN22: 0 | AO22: 0 | AP22: 0 | AQ22: 0 | AR22: 0 | AS22: 0 | AT22: 0 | AU22: 0 | AV22: 0 | AW22: 0 | AX22: 0 | AY22: 0 | AZ22: 0 | BA22: =SUM(AN22:AZ22) -> 0 | BD22: غير | BE22: ذكر | BF22: 0 | BG22: 0 | BH22: 0 | BI22: 0 | BJ22: 0 | BK22: 0 | BL22: 0 | BM22: 0 | BN22: 0 | BO22: 0 | BP22: 0 | BQ22: 0 | BR22: 0 | BS22: =SUM(BF22:BR22) -> 0 | BV22: غير | BW22: ذكر | BX22: 0 | BY22: 0 | BZ22: 0 | CA22: 0 | CB22: 0 | CC22: 0 | CD22: 0 | CE22: 0 | CF22: 0 | CG22: 0 | CH22: 0 | CI22: 0 | CJ22: 0 | CK22: =SUM(BX22:CJ22) -> 0 | CN22: غير | CO22: ذكر | CP22: 0 | CQ22: 0 | CR22: 0 | CS22: 0 | CT22: 0 | CU22: 0 | CV22: 0 | CW22: 0 | CX22: 0 | CY22: 0 | CZ22: 0 | DA22: 0 | DB22: 0 | DC22: =SUM(CP22:DB22) -> 0 | DF22: غير | DG22: ذكر | DH22: 0 | DI22: 0 | DJ22: 0 | DK22: 0 | DL22: 0 | DM22: 0 | DN22: 0 | DO22: 0 | DP22: 0 | DQ22: 0 | DR22: 0 | DS22: 0 | DT22: 0 | DU22: =SUM(DH22:DT22) -> 0 | DX22: غير | DY22: ذكر | DZ22: 0 | EA22: 0 | EB22: 0 | EC22: 0 | ED22: 0 | EE22: 0 | EF22: 0 | EG22: 0 | EH22: 0 | EI22: 0 | EJ22: 0 | EK22: 0 | EL22: 0 | EM22: =SUM(DZ22:EL22) -> 0 | EP22: غير | EQ22: ذكر | ER22: 0 | ES22: 0 | ET22: 0 | EU22: 0 | EV22: 0 | EW22: 0 | EX22: 0 | EY22: 0 | EZ22: 0 | FA22: 0 | FB22: 0 | FC22: 0 | FD22: 0 | FE22: =SUM(ER22:FD22) -> 0 | FH22: غير | FI22: ذكر | FJ22: 0 | FK22: 0 | FL22: 0 | FM22: 0 | FN22: 0 | FO22: 0 | FP22: 0 | FQ22: 0 | FR22: 0 | FS22: 0 | FT22: 0 | FU22: 0 | FV22: 0 | FW22: =SUM(FJ22:FV22) -> 0 | FZ22: غير | GA22: ذكر | GB22: 0 | GC22: 0 | GD22: 0 | GE22: 0 | GF22: 0 | GG22: 0 | GH22: 0 | GI22: 0 | GJ22: 0 | GK22: 0 | GL22: 0 | GM22: 0 | GN22: 0 | GO22: =SUM(GB22:GN22) -> 0 | GR22: غير | GS22: ذكر | GT22: 0 | GU22: 0 | GV22: 0 | GW22: 0 | GX22: 0 | GY22: 0 | GZ22: 0 | HA22: 0 | HB22: 0 | HC22: 0 | HD22: 0 | HE22: 0 | HF22: 0 | HG22: =SUM(GT22:HF22) -> 0 | HJ22: غير | HK22: ذكر | HL22: =SUM(GT22) -> 0 | HM22: =SUM(GU22) -> 0 | HN22: =SUM(GV22) -> 0 | HO22: =SUM(GW22) -> 0 | HP22: =SUM(GX22) -> 0 | HQ22: =SUM(GY22) -> 0 | HR22: =SUM(GZ22) -> 0 | HS22: =SUM(HA22) -> 0 | ... HX22: =SUM(HF22) -> 0 | HY22: =SUM(HL22:HX22) -> 0
B23: سعودي | C23: أنثى | D23: 0 | E23: 0 | F23: 0 | G23: 0 | H23: 0 | I23: 0 | J23: 0 | K23: 0 | L23: 0 | M23: 0 | N23: 0 | O23: 0 | P23: 0 | Q23: =SUM(D23:P23) -> 0 | T23: سعودي | U23: أنثى | V23: 0 | W23: 0 | X23: 0 | Y23: 0 | Z23: 0 | AA23: 0 | AB23: 0 | AC23: 0 | AD23: 0 | AE23: 0 | AF23: 0 | AG23: 0 | AH23: 0 | AI23: =SUM(V23:AH23) -> 0 | AL23: سعودي | AM23: أنثى | AN23: 0 | AO23: 0 | AP23: 0 | AQ23: 0 | AR23: 0 | AS23: 0 | AT23: 0 | AU23: 0 | AV23: 0 | AW23: 0 | AX23: 0 | AY23: 0 | AZ23: 0 | BA23: =SUM(AN23:AZ23) -> 0 | BD23: سعودي | BE23: أنثى | BF23: 0 | BG23: 0 | BH23: 0 | BI23: 0 | BJ23: 0 | BK23: 0 | BL23: 0 | BM23: 0 | BN23: 0 | BO23: 0 | BP23: 0 | BQ23: 0 | BR23: 0 | BS23: =SUM(BF23:BR23) -> 0 | BV23: سعودي | BW23: أنثى | BX23: 0 | BY23: 0 | BZ23: 0 | CA23: 0 | CB23: 0 | CC23: 0 | CD23: 0 | CE23: 0 | CF23: 0 | CG23: 0 | CH23: 0 | CI23: 0 | CJ23: 0 | CK23: =SUM(BX23:CJ23) -> 0 | CN23: سعودي | CO23: أنثى | CP23: 0 | CQ23: 0 | CR23: 0 | CS23: 0 | CT23: 0 | CU23: 0 | CV23: 0 | CW23: 0 | CX23: 0 | CY23: 0 | CZ23: 0 | DA23: 0 | DB23: 0 | DC23: =SUM(CP23:DB23) -> 0 | DF23: سعودي | DG23: أنثى | DH23: 0 | DI23: 0 | DJ23: 0 | DK23: 0 | DL23: 0 | DM23: 0 | DN23: 0 | DO23: 0 | DP23: 0 | DQ23: 0 | DR23: 0 | DS23: 0 | DT23: 0 | DU23: =SUM(DH23:DT23) -> 0 | DX23: سعودي | DY23: أنثى | DZ23: 0 | EA23: 0 | EB23: 0 | EC23: 0 | ED23: 0 | EE23: 0 | EF23: 0 | EG23: 0 | EH23: 0 | EI23: 0 | EJ23: 0 | EK23: 0 | EL23: 0 | EM23: =SUM(DZ23:EL23) -> 0 | EP23: سعودي | EQ23: أنثى | ER23: 0 | ES23: 0 | ET23: 0 | EU23: 0 | EV23: 0 | EW23: 0 | EX23: 0 | EY23: 0 | EZ23: 0 | FA23: 0 | FB23: 0 | FC23: 0 | FD23: 0 | FE23: =SUM(ER23:FD23) -> 0 | FH23: سعودي | FI23: أنثى | FJ23: 0 | FK23: 0 | FL23: 0 | FM23: 0 | FN23: 0 | FO23: 0 | FP23: 0 | FQ23: 0 | FR23: 0 | FS23: 0 | FT23: 0 | FU23: 0 | FV23: 0 | FW23: =SUM(FJ23:FV23) -> 0 | FZ23: سعودي | GA23: أنثى | GB23: 0 | GC23: 0 | GD23: 0 | GE23: 0 | GF23: 0 | GG23: 0 | GH23: 0 | GI23: 0 | GJ23: 0 | GK23: 0 | GL23: 0 | GM23: 0 | GN23: 0 | GO23: =SUM(GB23:GN23) -> 0 | GR23: سعودي | GS23: أنثى | GT23: 0 | GU23: 0 | GV23: 0 | GW23: 0 | GX23: 0 | GY23: 0 | GZ23: 0 | HA23: 0 | HB23: 0 | HC23: 0 | HD23: 0 | HE23: 0 | HF23: 0 | HG23: =SUM(GT23:HF23) -> 0 | HJ23: سعودي | HK23: أنثى | HL23: =SUM(GT23) -> 0 | HM23: =SUM(GU23) -> 0 | HN23: =SUM(GV23) -> 0 | HO23: =SUM(GW23) -> 0 | HP23: =SUM(GX23) -> 0 | HQ23: =SUM(GY23) -> 0 | HR23: =SUM(GZ23) -> 0 | HS23: =SUM(HA23) -> 0 | ... HX23: =SUM(HF23) -> 0 | HY23: =SUM(HL23:HX23) -> 0
B24: المجموع | D24: =SUM(D20:D23) -> 4 | E24: =SUM(E20:E23) -> 4 | F24: =SUM(F20:F23) -> 6 | G24: =SUM(G20:G23) -> 15 | H24: =SUM(H20:H23) -> 0 | I24: =SUM(I20:I23) -> 0 | J24: =SUM(J20:J23) -> 2 | K24: =SUM(K20:K23) -> 0 | ... Q24: =SUM(Q20:Q23) -> 56 | T24: المجموع | V24: =SUM(V20:V23) -> 4 | W24: =SUM(W20:W23) -> 4 | X24: =SUM(X20:X23) -> 6 | Y24: =SUM(Y20:Y23) -> 15 | Z24: =SUM(Z20:Z23) -> 0 | AA24: =SUM(AA20:AA23) -> 0 | AB24: =SUM(AB20:AB23) -> 2 | AC24: =SUM(AC20:AC23) -> 0 | ... AI24: =SUM(AI20:AI23) -> 56 | AL24: المجموع | AN24: =SUM(AN20:AN23) -> 4 | AO24: =SUM(AO20:AO23) -> 4 | AP24: =SUM(AP20:AP23) -> 6 | AQ24: =SUM(AQ20:AQ23) -> 15 | AR24: =SUM(AR20:AR23) -> 0 | AS24: =SUM(AS20:AS23) -> 0 | AT24: =SUM(AT20:AT23) -> 2 | AU24: =SUM(AU20:AU23) -> 0 | ... BA24: =SUM(BA20:BA23) -> 56 | BD24: المجموع | BF24: =SUM(BF20:BF23) -> 4 | BG24: =SUM(BG20:BG23) -> 4 | BH24: =SUM(BH20:BH23) -> 6 | BI24: =SUM(BI20:BI23) -> 15 | BJ24: =SUM(BJ20:BJ23) -> 0 | BK24: =SUM(BK20:BK23) -> 0 | BL24: =SUM(BL20:BL23) -> 2 | BM24: =SUM(BM20:BM23) -> 0 | ... BS24: =SUM(BS20:BS23) -> 56 | BV24: المجموع | BX24: =SUM(BX20:BX23) -> 4 | BY24: =SUM(BY20:BY23) -> 4 | BZ24: =SUM(BZ20:BZ23) -> 6 | CA24: =SUM(CA20:CA23) -> 15 | CB24: =SUM(CB20:CB23) -> 0 | CC24: =SUM(CC20:CC23) -> 0 | CD24: =SUM(CD20:CD23) -> 2 | CE24: =SUM(CE20:CE23) -> 0 | ... CK24: =SUM(CK20:CK23) -> 56 | CN24: المجموع | CP24: =SUM(CP20:CP23) -> 4 | CQ24: =SUM(CQ20:CQ23) -> 4 | CR24: =SUM(CR20:CR23) -> 6 | CS24: =SUM(CS20:CS23) -> 15 | CT24: =SUM(CT20:CT23) -> 0 | CU24: =SUM(CU20:CU23) -> 0 | CV24: =SUM(CV20:CV23) -> 2 | CW24: =SUM(CW20:CW23) -> 0 | ... DC24: =SUM(DC20:DC23) -> 56 | DF24: المجموع | DH24: =SUM(DH20:DH23) -> 4 | DI24: =SUM(DI20:DI23) -> 4 | DJ24: =SUM(DJ20:DJ23) -> 6 | DK24: =SUM(DK20:DK23) -> 15 | DL24: =SUM(DL20:DL23) -> 0 | DM24: =SUM(DM20:DM23) -> 0 | DN24: =SUM(DN20:DN23) -> 2 | DO24: =SUM(DO20:DO23) -> 0 | ... DU24: =SUM(DU20:DU23) -> 56 | DX24: المجموع | DZ24: =SUM(DZ20:DZ23) -> 4 | EA24: =SUM(EA20:EA23) -> 4 | EB24: =SUM(EB20:EB23) -> 6 | EC24: =SUM(EC20:EC23) -> 15 | ED24: =SUM(ED20:ED23) -> 0 | EE24: =SUM(EE20:EE23) -> 0 | EF24: =SUM(EF20:EF23) -> 2 | EG24: =SUM(EG20:EG23) -> 0 | ... EM24: =SUM(EM20:EM23) -> 56 | EP24: المجموع | ER24: =SUM(ER20:ER23) -> 4 | ES24: =SUM(ES20:ES23) -> 4 | ET24: =SUM(ET20:ET23) -> 6 | EU24: =SUM(EU20:EU23) -> 15 | EV24: =SUM(EV20:EV23) -> 0 | EW24: =SUM(EW20:EW23) -> 0 | EX24: =SUM(EX20:EX23) -> 2 | EY24: =SUM(EY20:EY23) -> 0 | ... FE24: =SUM(FE20:FE23) -> 56 | FH24: المجموع | FJ24: =SUM(FJ20:FJ23) -> 4 | FK24: =SUM(FK20:FK23) -> 4 | FL24: =SUM(FL20:FL23) -> 6 | FM24: =SUM(FM20:FM23) -> 15 | FN24: =SUM(FN20:FN23) -> 0 | FO24: =SUM(FO20:FO23) -> 0 | FP24: =SUM(FP20:FP23) -> 2 | FQ24: =SUM(FQ20:FQ23) -> 0 | ... FW24: =SUM(FW20:FW23) -> 56 | FZ24: المجموع | GB24: =SUM(GB20:GB23) -> 0 | GC24: =SUM(GC20:GC23) -> 0 | GD24: =SUM(GD20:GD23) -> 0 | GE24: =SUM(GE20:GE23) -> 0 | GF24: =SUM(GF20:GF23) -> 0 | GG24: =SUM(GG20:GG23) -> 0 | GH24: =SUM(GH20:GH23) -> 0 | GI24: =SUM(GI20:GI23) -> 0 | ... GO24: =SUM(GO20:GO23) -> 0 | GR24: المجموع | GT24: =SUM(GT20:GT23) -> 0 | GU24: =SUM(GU20:GU23) -> 0 | GV24: =SUM(GV20:GV23) -> 0 | GW24: =SUM(GW20:GW23) -> 0 | GX24: =SUM(GX20:GX23) -> 0 | GY24: =SUM(GY20:GY23) -> 0 | GZ24: =SUM(GZ20:GZ23) -> 0 | HA24: =SUM(HA20:HA23) -> 0 | ... HG24: =SUM(HG20:HG23) -> 0 | HJ24: المجموع | HL24: =SUM(HL20:HL23) -> 0 | HM24: =SUM(HM20:HM23) -> 0 | HN24: =SUM(HN20:HN23) -> 0 | HO24: =SUM(HO20:HO23) -> 0 | HP24: =SUM(HP20:HP23) -> 0 | HQ24: =SUM(HQ20:HQ23) -> 0 | HR24: =SUM(HR20:HR23) -> 0 | HS24: =SUM(HS20:HS23) -> 0 | ... HY24: =SUM(HY20:HY23) -> 0
A25: الروابي | B25: سعودي | C25: ذكر | D25: 0 | E25: 0 | F25: 0 | G25: 0 | H25: 0 | I25: 0 | J25: 0 | K25: 0 | L25: 0 | M25: 0 | N25: 0 | O25: 0 | P25: 0 | Q25: =SUM(D25:P25) -> 0 | S25: الروابي | T25: سعودي | U25: ذكر | V25: 0 | W25: 0 | X25: 0 | Y25: 0 | Z25: 0 | AA25: 0 | AB25: 0 | AC25: 0 | AD25: 0 | AE25: 0 | AF25: 0 | AG25: 0 | AH25: 0 | AI25: =SUM(V25:AH25) -> 0 | AK25: الروابي | AL25: سعودي | AM25: ذكر | AN25: 0 | AO25: 0 | AP25: 0 | AQ25: 0 | AR25: 0 | AS25: 0 | AT25: 0 | AU25: 0 | AV25: 0 | AW25: 0 | AX25: 0 | AY25: 0 | AZ25: 0 | BA25: =SUM(AN25:AZ25) -> 0 | BC25: الروابي | BD25: سعودي | BE25: ذكر | BF25: 0 | BG25: 0 | BH25: 0 | BI25: 0 | BJ25: 0 | BK25: 0 | BL25: 0 | BM25: 0 | BN25: 0 | BO25: 0 | BP25: 0 | BQ25: 0 | BR25: 0 | BS25: =SUM(BF25:BR25) -> 0 | BU25: الروابي | BV25: سعودي | BW25: ذكر | BX25: 0 | BY25: 0 | BZ25: 0 | CA25: 0 | CB25: 0 | CC25: 0 | CD25: 0 | CE25: 0 | CF25: 0 | CG25: 0 | CH25: 0 | CI25: 0 | CJ25: 0 | CK25: =SUM(BX25:CJ25) -> 0 | CM25: الروابي | CN25: سعودي | CO25: ذكر | CP25: 0 | CQ25: 0 | CR25: 0 | CS25: 0 | CT25: 0 | CU25: 0 | CV25: 0 | CW25: 0 | CX25: 0 | CY25: 0 | CZ25: 0 | DA25: 0 | DB25: 0 | DC25: =SUM(CP25:DB25) -> 0 | DE25: الروابي | DF25: سعودي | DG25: ذكر | DH25: 0 | DI25: 0 | DJ25: 0 | DK25: 0 | DL25: 0 | DM25: 0 | DN25: 0 | DO25: 0 | DP25: 0 | DQ25: 0 | DR25: 0 | DS25: 0 | DT25: 0 | DU25: =SUM(DH25:DT25) -> 0 | DW25: الروابي | DX25: سعودي | DY25: ذكر | DZ25: 0 | EA25: 0 | EB25: 0 | EC25: 0 | ED25: 0 | EE25: 0 | EF25: 0 | EG25: 0 | EH25: 0 | EI25: 0 | EJ25: 0 | EK25: 0 | EL25: 0 | EM25: =SUM(DZ25:EL25) -> 0 | EO25: الروابي | EP25: سعودي | EQ25: ذكر | ER25: 0 | ES25: 0 | ET25: 0 | EU25: 0 | EV25: 0 | EW25: 0 | EX25: 0 | EY25: 0 | EZ25: 0 | FA25: 0 | FB25: 0 | FC25: 0 | FD25: 0 | FE25: =SUM(ER25:FD25) -> 0 | FG25: الروابي | FH25: سعودي | FI25: ذكر | FJ25: 0 | FK25: 5 | FL25: 0 | FM25: 4 | FN25: 0 | FO25: 0 | FP25: 2 | FQ25: 0 | FR25: 0 | FS25: 0 | FT25: 5 | FU25: 0 | FV25: 1 | FW25: =SUM(FJ25:FV25) -> 17 | FY25: الروابي | FZ25: سعودي | GA25: ذكر | GB25: 0 | GC25: 0 | GD25: 0 | GE25: 0 | GF25: 0 | GG25: 0 | GH25: 0 | GI25: 0 | GJ25: 0 | GK25: 0 | GL25: 0 | GM25: 0 | GN25: 0 | GO25: =SUM(GB25:GN25) -> 0 | GQ25: الروابي | GR25: سعودي | GS25: ذكر | GT25: 0 | GU25: 0 | GV25: 0 | GW25: 0 | GX25: 0 | GY25: 0 | GZ25: 0 | HA25: 0 | HB25: 0 | HC25: 0 | HD25: 0 | HE25: 0 | HF25: 0 | HG25: =SUM(GT25:HF25) -> 0 | HI25: =GQ25 -> الروابي | HJ25: سعودي | HK25: ذكر | HL25: =SUM(GT25) -> 0 | HM25: =SUM(GU25) -> 0 | HN25: =SUM(GV25) -> 0 | HO25: =SUM(GW25) -> 0 | HP25: =SUM(GX25) -> 0 | HQ25: =SUM(GY25) -> 0 | HR25: =SUM(GZ25) -> 0 | HS25: =SUM(HA25) -> 0 | ... HX25: =SUM(HF25) -> 0 | HY25: =SUM(HL25:HX25) -> 0
