Workbook

Sheet الأشعة
A2: 13 ـ نشاط الأشعة شهر | D2: 1 | E2: 1447 | G2: 13 ـ نشاط الأشعة شهر | J2: 2 | K2: 1447 | M2: 13 ـ نشاط الأشعة شهر | P2: 3 | Q2: 1447 | S2: 13 ـ نشاط الأشعة شهر | V2: 4 | W2: 1447 | Y2: 13 ـ نشاط الأشعة شهر | AB2: 5 | AC2: 1447 | AE2: 13 ـ نشاط الأشعة شهر | AH2: 6 | AI2: 1447 | AK2: 13 ـ نشاط الأشعة شهر | AN2: 7 | AO2: 1447 | AQ2: 13 ـ نشاط الأشعة شهر | AT2: 8 | AU2: 1447 | AW2: 13 ـ نشاط الأشعة شهر | AZ2: 9 | BA2: 1447 | BC2: 13 ـ نشاط الأشعة شهر | BF2: 10 | BG2: 1447 | BI2: 13 ـ نشاط الأشعة شهر | BL2: 11 | BM2: 1447 | BO2: 13 ـ نشاط الأشعة شهر | BR2: 12 | BS2: 1447 | BU2: 13 ـ نشاط الأشعة | BX2: عام | BY2: =SUM(BS2) -> 1447
A4: المركز الصحي | B4: المرضى والأفلام | D4: عدد المراجعين | E4: عدد الأفلام | G4: المركز الصحي | H4: المرضى والأفلام | J4: عدد المراجعين | K4: عدد الأفلام | M4: المركز الصحي | N4: المرضى والأفلام | P4: عدد المراجعين | Q4: عدد الأفلام | S4: المركز الصحي | T4: المرضى والأفلام | V4: عدد المراجعين | W4: عدد الأفلام | Y4: المركز الصحي | Z4: المرضى والأفلام | AB4: عدد المراجعين | AC4: عدد الأفلام | AE4: المركز الصحي | AF4: المرضى والأفلام | AH4: عدد المراجعين | AI4: عدد الأفلام | AK4: المركز الصحي | AL4: المرضى والأفلام | AN4: عدد المراجعين | AO4: عدد الأفلام | AQ4: المركز الصحي | AR4: المرضى والأفلام | AT4: عدد المراجعين | AU4: عدد الأفلام | AW4: المركز الصحي | AX4: المرضى والأفلام | AZ4: عدد المراجعين | BA4: عدد الأفلام | BC4: المركز الصحي | BD4: المرضى والأفلام | BF4: عدد المراجعين | BG4: عدد الأفلام | BI4: المركز الصحي | BJ4: المرضى والأفلام | BL4: عدد المراجعين | BM4: عدد الأفلام | BO4: المركز الصحي | BP4: المرضى والأفلام | BR4: عدد المراجعين | BS4: عدد الأفلام | BU4: المركز الصحي | BV4: المرضى والأفلام | BX4: عدد المراجعين | BY4: عدد الأفلام
B5: الجنسية والجنس | H5: الجنسية والجنس | N5: الجنسية والجنس | T5: الجنسية والجنس | Z5: الجنسية والجنس | AF5: الجنسية والجنس | AL5: الجنسية والجنس | AR5: الجنسية والجنس | AX5: الجنسية والجنس | BD5: الجنسية والجنس | BJ5: الجنسية والجنس | BP5: الجنسية والجنس | BV5: الجنسية والجنس
A6: الربيع والتوفيق | B6: سعودي | C6: ذكر | D6: 0 | E6: 0 | G6: الربيع والتوفيق | H6: سعودي | I6: ذكر | J6: 0 | K6: 0 | M6: الربيع والتوفيق | N6: سعودي | O6: ذكر | P6: 0 | Q6: 0 | S6: الربيع والتوفيق | T6: سعودي | U6: ذكر | V6: 0 | W6: 0 | Y6: الربيع والتوفيق | Z6: سعودي | AA6: ذكر | AB6: 0 | AC6: 0 | AE6: الربيع والتوفيق | AF6: سعودي | AG6: ذكر | AH6: 0 | AI6: 0 | AK6: الربيع والتوفيق | AL6: سعودي | AM6: ذكر | AN6: 0 | AO6: 0 | AQ6: الربيع والتوفيق | AR6: سعودي | AS6: ذكر | AT6: 0 | AU6: 0 | AW6: الربيع والتوفيق | AX6: سعودي | AY6: ذكر | AZ6: 0 | BA6: 0 | BC6: الربيع والتوفيق | BD6: سعودي | BE6: ذكر | BF6: 0 | BG6: 0 | BI6: الربيع والتوفيق | BJ6: سعودي | BK6: ذكر | BL6: 0 | BM6: 0 | BO6: الربيع والتوفيق | BP6: سعودي | BQ6: ذكر | BR6: 0 | BS6: 0 | BU6: =BO6 -> الربيع والتوفيق | BV6: سعودي | BW6: ذكر | BX6: =SUM(D6+J6+P6+V6+AB6+AH6+AN6+AT6+AZ6+BF6+BL6+BR6) -> 0 | BY6: =SUM(E6+K6+Q6+W6+AC6+AI6+AO6+AU6+BA6+BG6+BM6+BS6) -> 0
C7: أنثى | D7: 0 | E7: 0 | I7: أنثى | J7: 0 | K7: 0 | O7: أنثى | P7: 0 | Q7: 0 | U7: أنثى | V7: 0 | W7: 0 | AA7: أنثى | AB7: 0 | AC7: 0 | AG7: أنثى | AH7: 0 | AI7: 0 | AM7: أنثى | AN7: 0 | AO7: 0 | AS7: أنثى | AT7: 0 | AU7: 0 | AY7: أنثى | AZ7: 0 | BA7: 0 | BE7: أنثى | BF7: 0 | BG7: 0 | BK7: أنثى | BL7: 0 | BM7: 0 | BQ7: أنثى | BR7: 0 | BS7: 0 | BW7: أنثى | BX7: =SUM(D7+J7+P7+V7+AB7+AH7+AN7+AT7+AZ7+BF7+BL7+BR7) -> 0 | BY7: =SUM(E7+K7+Q7+W7+AC7+AI7+AO7+AU7+BA7+BG7+BM7+BS7) -> 0
B8: مجموع السعوديين | D8: =SUM(D6:D7) -> 0 | E8: =SUM(E6:E7) -> 0 | H8: مجموع السعوديين | J8: =SUM(J6:J7) -> 0 | K8: =SUM(K6:K7) -> 0 | N8: مجموع السعوديين | P8: =SUM(P6:P7) -> 0 | Q8: =SUM(Q6:Q7) -> 0 | T8: مجموع السعوديين | V8: =SUM(V6:V7) -> 0 | W8: =SUM(W6:W7) -> 0 | Z8: مجموع السعوديين | AB8: =SUM(AB6:AB7) -> 0 | AC8: =SUM(AC6:AC7) -> 0 | AF8: مجموع السعوديين | AH8: =SUM(AH6:AH7) -> 0 | AI8: =SUM(AI6:AI7) -> 0 | AL8: مجموع السعوديين | AN8: =SUM(AN6:AN7) -> 0 | AO8: =SUM(AO6:AO7) -> 0 | AR8: مجموع السعوديين | AT8: =SUM(AT6:AT7) -> 0 | AU8: =SUM(AU6:AU7) -> 0 | AX8: مجموع السعوديين | AZ8: =SUM(AZ6:AZ7) -> 0 | BA8: =SUM(BA6:BA7) -> 0 | BD8: مجموع السعوديين | BF8: =SUM(BF6:BF7) -> 0 | BG8: =SUM(BG6:BG7) -> 0 | BJ8: مجموع السعوديين | BL8: =SUM(BL6:BL7) -> 0 | BM8: =SUM(BM6:BM7) -> 0 | BP8: مجموع السعوديين | BR8: =SUM(BR6:BR7) -> 0 | BS8: =SUM(BS6:BS7) -> 0 | BV8: مجموع السعوديين | BX8: =SUM(BX6:BX7) -> 0 | BY8: =SUM(BY6:BY7) -> 0
B9: غير سعودي | C9: ذكر | D9: 0 | E9: 0 | H9: غير سعودي | I9: ذكر | J9: 0 | K9: 0 | N9: غير سعودي | O9: ذكر | P9: 0 | Q9: 0 | T9: غير سعودي | U9: ذكر | V9: 0 | W9: 0 | Z9: غير سعودي | AA9: ذكر | AB9: 0 | AC9: 0 | AF9: غير سعودي | AG9: ذكر | AH9: 0 | AI9: 0 | AL9: غير سعودي | AM9: ذكر | AN9: 0 | AO9: 0 | AR9: غير سعودي | AS9: ذكر | AT9: 0 | AU9: 0 | AX9: غير سعودي | AY9: ذكر | AZ9: 0 | BA9: 0 | BD9: غير سعودي | BE9: ذكر | BF9: 0 | BG9: 0 | BJ9: غير سعودي | BK9: ذكر | BL9: 0 | BM9: 0 | BP9: غير سعودي | BQ9: ذكر | BR9: 0 | BS9: 0 | BV9: غير سعودي | BW9: ذكر | BX9: =SUM(D9+J9+P9+V9+AB9+AH9+AN9+AT9+AZ9+BF9+BL9+BR9) -> 0 | BY9: =SUM(E9+K9+Q9+W9+AC9+AI9+AO9+AU9+BA9+BG9+BM9+BS9) -> 0
C10: أنثى | D10: 0 | E10: 0 | I10: أنثى | J10: 0 | K10: 0 | O10: أنثى | P10: 0 | Q10: 0 | U10: أنثى | V10: 0 | W10: 0 | AA10: أنثى | AB10: 0 | AC10: 0 | AG10: أنثى | AH10: 0 | AI10: 0 | AM10: أنثى | AN10: 0 | AO10: 0 | AS10: أنثى | AT10: 0 | AU10: 0 | AY10: أنثى | AZ10: 0 | BA10: 0 | BE10: أنثى | BF10: 0 | BG10: 0 | BK10: أنثى | BL10: 0 | BM10: 0 | BQ10: أنثى | BR10: 0 | BS10: 0 | BW10: أنثى | BX10: =SUM(D10+J10+P10+V10+AB10+AH10+AN10+AT10+AZ10+BF10+BL10+BR10) -> 0 | BY10: =SUM(E10+K10+Q10+W10+AC10+AI10+AO10+AU10+BA10+BG10+BM10+BS10) -> 0
B11: مجمع الغير سعوديين | D11: =SUM(D9:D10) -> 0 | E11: =SUM(E9:E10) -> 0 | H11: مجمع الغير سعوديين | J11: =SUM(J9:J10) -> 0 | K11: =SUM(K9:K10) -> 0 | N11: مجمع الغير سعوديين | P11: =SUM(P9:P10) -> 0 | Q11: =SUM(Q9:Q10) -> 0 | T11: مجمع الغير سعوديين | V11: =SUM(V9:V10) -> 0 | W11: =SUM(W9:W10) -> 0 | Z11: مجمع الغير سعوديين | AB11: =SUM(AB9:AB10) -> 0 | AC11: =SUM(AC9:AC10) -> 0 | AF11: مجمع الغير سعوديين | AH11: =SUM(AH9:AH10) -> 0 | AI11: =SUM(AI9:AI10) -> 0 | AL11: مجمع الغير سعوديين | AN11: =SUM(AN9:AN10) -> 0 | AO11: =SUM(AO9:AO10) -> 0 | AR11: مجمع الغير سعوديين | AT11: =SUM(AT9:AT10) -> 0 | AU11: =SUM(AU9:AU10) -> 0 | AX11: مجمع الغير سعوديين | AZ11: =SUM(AZ9:AZ10) -> 0 | BA11: =SUM(BA9:BA10) -> 0 | BD11: مجمع الغير سعوديين | BF11: =SUM(BF9:BF10) -> 0 | BG11: =SUM(BG9:BG10) -> 0 | BJ11: مجمع الغير سعوديين | BL11: =SUM(BL9:BL10) -> 0 | BM11: =SUM(BM9:BM10) -> 0 | BP11: مجمع الغير سعوديين | BR11: =SUM(BR9:BR10) -> 0 | BS11: =SUM(BS9:BS10) -> 0 | BV11: مجمع الغير سعوديين | BX11: =SUM(BX9:BX10) -> 0 | BY11: =SUM(BY9:BY10) -> 0
B12: المجموع الكلي | D12: =SUM(D8+D11) -> 0 | E12: =SUM(E8+E11) -> 0 | H12: المجموع الكلي | J12: =SUM(J8+J11) -> 0 | K12: =SUM(K8+K11) -> 0 | N12: المجموع الكلي | P12: =SUM(P8+P11) -> 0 | Q12: =SUM(Q8+Q11) -> 0 | T12: المجموع الكلي | V12: =SUM(V8+V11) -> 0 | W12: =SUM(W8+W11) -> 0 | Z12: المجموع الكلي | AB12: =SUM(AB8+AB11) -> 0 | AC12: =SUM(AC8+AC11) -> 0 | AF12: المجموع الكلي | AH12: =SUM(AH8+AH11) -> 0 | AI12: =SUM(AI8+AI11) -> 0 | AL12: المجموع الكلي | AN12: =SUM(AN8+AN11) -> 0 | AO12: =SUM(AO8+AO11) -> 0 | AR12: المجموع الكلي | AT12: =SUM(AT8+AT11) -> 0 | AU12: =SUM(AU8+AU11) -> 0 | AX12: المجموع الكلي | AZ12: =SUM(AZ8+AZ11) -> 0 | BA12: =SUM(BA8+BA11) -> 0 | BD12: المجموع الكلي | BF12: =SUM(BF8+BF11) -> 0 | BG12: =SUM(BG8+BG11) -> 0 | BJ12: المجموع الكلي | BL12: =SUM(BL8+BL11) -> 0 | BM12: =SUM(BM8+BM11) -> 0 | BP12: المجموع الكلي | BR12: =SUM(BR8+BR11) -> 0 | BS12: =SUM(BS8+BS11) -> 0 | BV12: المجموع الكلي | BX12: =SUM(BX8+BX11) -> 0 | BY12: =SUM(BY8+BY11) -> 0
A13: الجامعة | B13: سعودي | C13: ذكر | D13: 0 | E13: 0 | G13: الجامعة | H13: سعودي | I13: ذكر | J13: 0 | K13: 0 | M13: الجامعة | N13: سعودي | O13: ذكر | P13: 0 | Q13: 0 | S13: الجامعة | T13: سعودي | U13: ذكر | V13: 0 | W13: 0 | Y13: الجامعة | Z13: سعودي | AA13: ذكر | AB13: 0 | AC13: 0 | AE13: الجامعة | AF13: سعودي | AG13: ذكر | AH13: 0 | AI13: 0 | AK13: الجامعة | AL13: سعودي | AM13: ذكر | AN13: 0 | AO13: 0 | AQ13: الجامعة | AR13: سعودي | AS13: ذكر | AT13: 0 | AU13: 0 | AW13: الجامعة | AX13: سعودي | AY13: ذكر | AZ13: 0 | BA13: 0 | BC13: الجامعة | BD13: سعودي | BE13: ذكر | BF13: 0 | BG13: 0 | BI13: الجامعة | BJ13: سعودي | BK13: ذكر | BL13: 0 | BM13: 0 | BO13: الجامعة | BP13: سعودي | BQ13: ذكر | BR13: 0 | BS13: 0 | BU13: =BO13 -> الجامعة | BV13: سعودي | BW13: ذكر | BX13: =SUM(D13+J13+P13+V13+AB13+AH13+AN13+AT13+AZ13+BF13+BL13+BR13) -> 0 | BY13: =SUM(E13+K13+Q13+W13+AC13+AI13+AO13+AU13+BA13+BG13+BM13+BS13) -> 0
C14: أنثى | D14: 0 | E14: 0 | I14: أنثى | J14: 0 | K14: 0 | O14: أنثى | P14: 0 | Q14: 0 | U14: أنثى | V14: 0 | W14: 0 | AA14: أنثى | AB14: 0 | AC14: 0 | AG14: أنثى | AH14: 0 | AI14: 0 | AM14: أنثى | AN14: 0 | AO14: 0 | AS14: أنثى | AT14: 0 | AU14: 0 | AY14: أنثى | AZ14: 0 | BA14: 0 | BE14: أنثى | BF14: 0 | BG14: 0 | BK14: أنثى | BL14: 0 | BM14: 0 | BQ14: أنثى | BR14: 0 | BS14: 0 | BW14: أنثى | BX14: =SUM(D14+J14+P14+V14+AB14+AH14+AN14+AT14+AZ14+BF14+BL14+BR14) -> 0 | BY14: =SUM(E14+K14+Q14+W14+AC14+AI14+AO14+AU14+BA14+BG14+BM14+BS14) -> 0
B15: مجموع السعوديين | D15: =SUM(D13:D14) -> 0 | E15: =SUM(E13:E14) -> 0 | H15: مجموع السعوديين | J15: =SUM(J13:J14) -> 0 | K15: =SUM(K13:K14) -> 0 | N15: مجموع السعوديين | P15: =SUM(P13:P14) -> 0 | Q15: =SUM(Q13:Q14) -> 0 | T15: مجموع السعوديين | V15: =SUM(V13:V14) -> 0 | W15: =SUM(W13:W14) -> 0 | Z15: مجموع السعوديين | AB15: =SUM(AB13:AB14) -> 0 | AC15: =SUM(AC13:AC14) -> 0 | AF15: مجموع السعوديين | AH15: =SUM(AH13:AH14) -> 0 | AI15: =SUM(AI13:AI14) -> 0 | AL15: مجموع السعوديين | AN15: =SUM(AN13:AN14) -> 0 | AO15: =SUM(AO13:AO14) -> 0 | AR15: مجموع السعوديين | AT15: =SUM(AT13:AT14) -> 0 | AU15: =SUM(AU13:AU14) -> 0 | AX15: مجموع السعوديين | AZ15: =SUM(AZ13:AZ14) -> 0 | BA15: =SUM(BA13:BA14) -> 0 | BD15: مجموع السعوديين | BF15: =SUM(BF13:BF14) -> 0 | BG15: =SUM(BG13:BG14) -> 0 | BJ15: مجموع السعوديين | BL15: =SUM(BL13:BL14) -> 0 | BM15: =SUM(BM13:BM14) -> 0 | BP15: مجموع السعوديين | BR15: =SUM(BR13:BR14) -> 0 | BS15: =SUM(BS13:BS14) -> 0 | BV15: مجموع السعوديين | BX15: =SUM(BX13:BX14) -> 0 | BY15: =SUM(BY13:BY14) -> 0
B16: غير سعودي | C16: ذكر | D16: 0 | E16: 0 | H16: غير سعودي | I16: ذكر | J16: 0 | K16: 0 | N16: غير سعودي | O16: ذكر | P16: 0 | Q16: 0 | T16: غير سعودي | U16: ذكر | V16: 0 | W16: 0 | Z16: غير سعودي | AA16: ذكر | AB16: 0 | AC16: 0 | AF16: غير سعودي | AG16: ذكر | AH16: 0 | AI16: 0 | AL16: غير سعودي | AM16: ذكر | AN16: 0 | AO16: 0 | AR16: غير سعودي | AS16: ذكر | AT16: 0 | AU16: 0 | AX16: غير سعودي | AY16: ذكر | AZ16: 0 | BA16: 0 | BD16: غير سعودي | BE16: ذكر | BF16: 0 | BG16: 0 | BJ16: غير سعودي | BK16: ذكر | BL16: 0 | BM16: 0 | BP16: غير سعودي | BQ16: ذكر | BR16: 0 | BS16: 0 | BV16: غير سعودي | BW16: ذكر | BX16: =SUM(D16+J16+P16+V16+AB16+AH16+AN16+AT16+AZ16+BF16+BL16+BR16) -> 0 | BY16: =SUM(E16+K16+Q16+W16+AC16+AI16+AO16+AU16+BA16+BG16+BM16+BS16) -> 0
C17: أنثى | D17: 0 | E17: 0 | I17: أنثى | J17: 0 | K17: 0 | O17: أنثى | P17: 0 | Q17: 0 | U17: أنثى | V17: 0 | W17: 0 | AA17: أنثى | AB17: 0 | AC17: 0 | AG17: أنثى | AH17: 0 | AI17: 0 | AM17: أنثى | AN17: 0 | AO17: 0 | AS17: أنثى | AT17: 0 | AU17: 0 | AY17: أنثى | AZ17: 0 | BA17: 0 | BE17: أنثى | BF17: 0 | BG17: 0 | BK17: أنثى | BL17: 0 | BM17: 0 | BQ17: أنثى | BR17: 0 | BS17: 0 | BW17: أنثى | BX17: =SUM(D17+J17+P17+V17+AB17+AH17+AN17+AT17+AZ17+BF17+BL17+BR17) -> 0 | BY17: =SUM(E17+K17+Q17+W17+AC17+AI17+AO17+AU17+BA17+BG17+BM17+BS17) -> 0
B18: مجمع الغير سعوديين | D18: =SUM(D16:D17) -> 0 | E18: =SUM(E16:E17) -> 0 | H18: مجمع الغير سعوديين | J18: =SUM(J16:J17) -> 0 | K18: =SUM(K16:K17) -> 0 | N18: مجمع الغير سعوديين | P18: =SUM(P16:P17) -> 0 | Q18: =SUM(Q16:Q17) -> 0 | T18: مجمع الغير سعوديين | V18: =SUM(V16:V17) -> 0 | W18: =SUM(W16:W17) -> 0 | Z18: مجمع الغير سعوديين | AB18: =SUM(AB16:AB17) -> 0 | AC18: =SUM(AC16:AC17) -> 0 | AF18: مجمع الغير سعوديين | AH18: =SUM(AH16:AH17) -> 0 | AI18: =SUM(AI16:AI17) -> 0 | AL18: مجمع الغير سعوديين | AN18: =SUM(AN16:AN17) -> 0 | AO18: =SUM(AO16:AO17) -> 0 | AR18: مجمع الغير سعوديين | AT18: =SUM(AT16:AT17) -> 0 | AU18: =SUM(AU16:AU17) -> 0 | AX18: مجمع الغير سعوديين | AZ18: =SUM(AZ16:AZ17) -> 0 | BA18: =SUM(BA16:BA17) -> 0 | BD18: مجمع الغير سعوديين | BF18: =SUM(BF16:BF17) -> 0 | BG18: =SUM(BG16:BG17) -> 0 | BJ18: مجمع الغير سعوديين | BL18: =SUM(BL16:BL17) -> 0 | BM18: =SUM(BM16:BM17) -> 0 | BP18: مجمع الغير سعوديين | BR18: =SUM(BR16:BR17) -> 0 | BS18: =SUM(BS16:BS17) -> 0 | BV18: مجمع الغير سعوديين | BX18: =SUM(BX16:BX17) -> 0 | BY18: =SUM(BY16:BY17) -> 0
B19: المجموع الكلي | D19: =SUM(D15+D18) -> 0 | E19: =SUM(E15+E18) -> 0 | H19: المجموع الكلي | J19: =SUM(J15+J18) -> 0 | K19: =SUM(K15+K18) -> 0 | N19: المجموع الكلي | P19: =SUM(P15+P18) -> 0 | Q19: =SUM(Q15+Q18) -> 0 | T19: المجموع الكلي | V19: =SUM(V15+V18) -> 0 | W19: =SUM(W15+W18) -> 0 | Z19: المجموع الكلي | AB19: =SUM(AB15+AB18) -> 0 | AC19: =SUM(AC15+AC18) -> 0 | AF19: المجموع الكلي | AH19: =SUM(AH15+AH18) -> 0 | AI19: =SUM(AI15+AI18) -> 0 | AL19: المجموع الكلي | AN19: =SUM(AN15+AN18) -> 0 | AO19: =SUM(AO15+AO18) -> 0 | AR19: المجموع الكلي | AT19: =SUM(AT15+AT18) -> 0 | AU19: =SUM(AU15+AU18) -> 0 | AX19: المجموع الكلي | AZ19: =SUM(AZ15+AZ18) -> 0 | BA19: =SUM(BA15+BA18) -> 0 | BD19: المجموع الكلي | BF19: =SUM(BF15+BF18) -> 0 | BG19: =SUM(BG15+BG18) -> 0 | BJ19: المجموع الكلي | BL19: =SUM(BL15+BL18) -> 0 | BM19: =SUM(BM15+BM18) -> 0 | BP19: المجموع الكلي | BR19: =SUM(BR15+BR18) -> 0 | BS19: =SUM(BS15+BS18) -> 0 | BV19: المجموع الكلي | BX19: =SUM(BX15+BX18) -> 0 | BY19: =SUM(BY15+BY18) -> 0
A20: السليمانية | B20: سعودي | C20: ذكر | D20: 510 | E20: 0 | G20: السليمانية | H20: سعودي | I20: ذكر | J20: 873 | K20: 0 | M20: السليمانية | N20: سعودي | O20: ذكر | P20: 0 | Q20: 0 | S20: السليمانية | T20: سعودي | U20: ذكر | V20: 0 | W20: 0 | Y20: السليمانية | Z20: سعودي | AA20: ذكر | AB20: 0 | AC20: 0 | AE20: السليمانية | AF20: سعودي | AG20: ذكر | AH20: 0 | AI20: 0 | AK20: السليمانية | AL20: سعودي | AM20: ذكر | AN20: 0 | AO20: 0 | AQ20: السليمانية | AR20: سعودي | AS20: ذكر | AT20: 0 | AU20: 0 | AW20: السليمانية | AX20: سعودي | AY20: ذكر | AZ20: 57 | BA20: 57 | BC20: السليمانية | BD20: سعودي | BE20: ذكر | BF20: 510 | BG20: 0 | BI20: السليمانية | BJ20: سعودي | BK20: ذكر | BL20: 0 | BM20: 0 | BO20: السليمانية | BP20: سعودي | BQ20: ذكر | BR20: 0 | BS20: 0 | BU20: =BO20 -> السليمانية | BV20: سعودي | BW20: ذكر | BX20: =SUM(D20+J20+P20+V20+AB20+AH20+AN20+AT20+AZ20+BF20+BL20+BR20) -> 1950 | BY20: =SUM(E20+K20+Q20+W20+AC20+AI20+AO20+AU20+BA20+BG20+BM20+BS20) -> 57
C21: أنثى | D21: 445 | E21: 0 | I21: أنثى | J21: 238 | K21: 0 | O21: أنثى | P21: 0 | Q21: 0 | U21: أنثى | V21: 0 | W21: 0 | AA21: أنثى | AB21: 0 | AC21: 0 | AG21: أنثى | AH21: 0 | AI21: 0 | AM21: أنثى | AN21: 0 | AO21: 0 | AS21: أنثى | AT21: 0 | AU21: 0 | AY21: أنثى | AZ21: 74 | BA21: 74 | BE21: أنثى | BF21: 445 | BG21: 0 | BK21: أنثى | BL21: 0 | BM21: 0 | BQ21: أنثى | BR21: 0 | BS21: 0 | BW21: أنثى | BX21: =SUM(D21+J21+P21+V21+AB21+AH21+AN21+AT21+AZ21+BF21+BL21+BR21) -> 1202 | BY21: =SUM(E21+K21+Q21+W21+AC21+AI21+AO21+AU21+BA21+BG21+BM21+BS21) -> 74
B22: مجموع السعوديين | D22: =SUM(D20:D21) -> 955 | E22: =SUM(E20:E21) -> 0 | H22: مجموع السعوديين | J22: =SUM(J20:J21) -> 1111 | K22: =SUM(K20:K21) -> 0 | N22: مجموع السعوديين | P22: =SUM(P20:P21) -> 0 | Q22: =SUM(Q20:Q21) -> 0 | T22: مجموع السعوديين | V22: =SUM(V20:V21) -> 0 | W22: =SUM(W20:W21) -> 0 | Z22: مجموع السعوديين | AB22: =SUM(AB20:AB21) -> 0 | AC22: =SUM(AC20:AC21) -> 0 | AF22: مجموع السعوديين | AH22: =SUM(AH20:AH21) -> 0 | AI22: =SUM(AI20:AI21) -> 0 | AL22: مجموع السعوديين | AN22: =SUM(AN20:AN21) -> 0 | AO22: =SUM(AO20:AO21) -> 0 | AR22: مجموع السعوديين | AT22: =SUM(AT20:AT21) -> 0 | AU22: =SUM(AU20:AU21) -> 0 | AX22: مجموع السعوديين | AZ22: =SUM(AZ20:AZ21) -> 131 | BA22: =SUM(BA20:BA21) -> 131 | BD22: مجموع السعوديين | BF22: 955 | BG22: 0 | BJ22: مجموع السعوديين | BL22: =SUM(BL20:BL21) -> 0 | BM22: =SUM(BM20:BM21) -> 0 | BP22: مجموع السعوديين | BR22: =SUM(BR20:BR21) -> 0 | BS22: =SUM(BS20:BS21) -> 0 | BV22: مجموع السعوديين | BX22: =SUM(BX20:BX21) -> 3152 | BY22: =SUM(BY20:BY21) -> 131
B23: غير سعودي | C23: ذكر | D23: 10 | E23: 0 | H23: غير سعودي | I23: ذكر | J23: 54 | K23: 0 | N23: غير سعودي | O23: ذكر | P23: 0 | Q23: 0 | T23: غير سعودي | U23: ذكر | V23: 0 | W23: 0 | Z23: غير سعودي | AA23: ذكر | AB23: 0 | AC23: 0 | AF23: غير سعودي | AG23: ذكر | AH23: 0 | AI23: 0 | AL23: غير سعودي | AM23: ذكر | AN23: 0 | AO23: 0 | AR23: غير سعودي | AS23: ذكر | AT23: 0 | AU23: 0 | AX23: غير سعودي | AY23: ذكر | AZ23: 15 | BA23: 15 | BD23: غير سعودي | BE23: ذكر | BF23: 10 | BG23: 0 | BJ23: غير سعودي | BK23: ذكر | BL23: 0 | BM23: 0 | BP23: غير سعودي | BQ23: ذكر | BR23: 0 | BS23: 0 | BV23: غير سعودي | BW23: ذكر | BX23: =SUM(D23+J23+P23+V23+AB23+AH23+AN23+AT23+AZ23+BF23+BL23+BR23) -> 89 | BY23: =SUM(E23+K23+Q23+W23+AC23+AI23+AO23+AU23+BA23+BG23+BM23+BS23) -> 15
C24: أنثى | D24: 9 | E24: 0 | I24: أنثى | J24: 18 | K24: 0 | O24: أنثى | P24: 0 | Q24: 0 | U24: أنثى | V24: 0 | W24: 0 | AA24: أنثى | AB24: 0 | AC24: 0 | AG24: أنثى | AH24: 0 | AI24: 0 | AM24: أنثى | AN24: 0 | AO24: 0 | AS24: أنثى | AT24: 0 | AU24: 0 | AY24: أنثى | AZ24: 11 | BA24: 11 | BE24: أنثى | BF24: 9 | BG24: 0 | BK24: أنثى | BL24: 0 | BM24: 0 | BQ24: أنثى | BR24: 0 | BS24: 0 | BW24: أنثى | BX24: =SUM(D24+J24+P24+V24+AB24+AH24+AN24+AT24+AZ24+BF24+BL24+BR24) -> 47 | BY24: =SUM(E24+K24+Q24+W24+AC24+AI24+AO24+AU24+BA24+BG24+BM24+BS24) -> 11
B25: مجمع الغير سعوديين | D25: =SUM(D23:D24) -> 19 | E25: =SUM(E23:E24) -> 0 | H25: مجمع الغير سعوديين | J25: =SUM(J23:J24) -> 72 | K25: =SUM(K23:K24) -> 0 | N25: مجمع الغير سعوديين | P25: =SUM(P23:P24) -> 0 | Q25: =SUM(Q23:Q24) -> 0 | T25: مجمع الغير سعوديين | V25: =SUM(V23:V24) -> 0 | W25: =SUM(W23:W24) -> 0 | Z25: مجمع الغير سعوديين | AB25: =SUM(AB23:AB24) -> 0 | AC25: =SUM(AC23:AC24) -> 0 | AF25: مجمع الغير سعوديين | AH25: =SUM(AH23:AH24) -> 0 | AI25: =SUM(AI23:AI24) -> 0 | AL25: مجمع الغير سعوديين | AN25: =SUM(AN23:AN24) -> 0 | AO25: =SUM(AO23:AO24) -> 0 | AR25: مجمع الغير سعوديين | AT25: =SUM(AT23:AT24) -> 0 | AU25: =SUM(AU23:AU24) -> 0 | AX25: مجمع الغير سعوديين | AZ25: =SUM(AZ23:AZ24) -> 26 | BA25: =SUM(BA23:BA24) -> 26 | BD25: مجمع الغير سعوديين | BF25: 19 | BG25: 0 | BJ25: مجمع الغير سعوديين | BL25: =SUM(BL23:BL24) -> 0 | BM25: =SUM(BM23:BM24) -> 0 | BP25: مجمع الغير سعوديين | BR25: =SUM(BR23:BR24) -> 0 | BS25: =SUM(BS23:BS24) -> 0 | BV25: مجمع الغير سعوديين | BX25: =SUM(BX23:BX24) -> 136 | BY25: =SUM(BY23:BY24) -> 26
B26: المجموع الكلي | D26: =SUM(D22+D25) -> 974 | E26: =SUM(E22+E25) -> 0 | H26: المجموع الكلي | J26: =SUM(J22+J25) -> 1183 | K26: =SUM(K22+K25) -> 0 | N26: المجموع الكلي | P26: =SUM(P22+P25) -> 0 | Q26: =SUM(Q22+Q25) -> 0 | T26: المجموع الكلي | V26: =SUM(V22+V25) -> 0 | W26: =SUM(W22+W25) -> 0 | Z26: المجموع الكلي | AB26: =SUM(AB22+AB25) -> 0 | AC26: =SUM(AC22+AC25) -> 0 | AF26: المجموع الكلي | AH26: =SUM(AH22+AH25) -> 0 | AI26: =SUM(AI22+AI25) -> 0 | AL26: المجموع الكلي | AN26: =SUM(AN22+AN25) -> 0 | AO26: =SUM(AO22+AO25) -> 0 | AR26: المجموع الكلي | AT26: =SUM(AT22+AT25) -> 0 | AU26: =SUM(AU22+AU25) -> 0 | AX26: المجموع الكلي | AZ26: =SUM(AZ22+AZ25) -> 157 | BA26: =SUM(BA22+BA25) -> 157 | BD26: المجموع الكلي | BF26: 974 | BG26: 0 | BJ26: المجموع الكلي | BL26: =SUM(BL22+BL25) -> 0 | BM26: =SUM(BM22+BM25) -> 0 | BP26: المجموع الكلي | BR26: =SUM(BR22+BR25) -> 0 | BS26: =SUM(BS22+BS25) -> 0 | BV26: المجموع الكلي | BX26: =SUM(BX22+BX25) -> 3288 | BY26: =SUM(BY22+BY25) -> 157
A27: المطار القديم | B27: سعودي | C27: ذكر | D27: 0 | E27: 0 | G27: المطار القديم | H27: سعودي | I27: ذكر | J27: 0 | K27: 0 | M27: المطار القديم | N27: سعودي | O27: ذكر | P27: 0 | Q27: 0 | S27: المطار القديم | T27: سعودي | U27: ذكر | V27: 0 | W27: 0 | Y27: المطار القديم | Z27: سعودي | AA27: ذكر | AB27: 0 | AC27: 0 | AE27: المطار القديم | AF27: سعودي | AG27: ذكر | AH27: 0 | AI27: 0 | AK27: المطار القديم | AL27: سعودي | AM27: ذكر | AN27: 0 | AO27: 0 | AQ27: المطار القديم | AR27: سعودي | AS27: ذكر | AT27: 0 | AU27: 0 | AW27: المطار القديم | AX27: سعودي | AY27: ذكر | AZ27: 0 | BA27: 0 | BC27: المطار القديم | BD27: سعودي | BE27: ذكر | BF27: 0 | BG27: 0 | BI27: المطار القديم | BJ27: سعودي | BK27: ذكر | BL27: 0 | BM27: 0 | BO27: المطار القديم | BP27: سعودي | BQ27: ذكر | BR27: 0 | BS27: 0 | BU27: =BO27 -> المطار القديم | BV27: سعودي | BW27: ذكر | BX27: =SUM(D27+J27+P27+V27+AB27+AH27+AN27+AT27+AZ27+BF27+BL27+BR27) -> 0 | BY27: =SUM(E27+K27+Q27+W27+AC27+AI27+AO27+AU27+BA27+BG27+BM27+BS27) -> 0
C28: أنثى | D28: 0 | E28: 0 | I28: أنثى | J28: 0 | K28: 0 | O28: أنثى | P28: 0 | Q28: 0 | U28: أنثى | V28: 0 | W28: 0 | AA28: أنثى | AB28: 0 | AC28: 0 | AG28: أنثى | AH28: 0 | AI28: 0 | AM28: أنثى | AN28: 0 | AO28: 0 | AS28: أنثى | AT28: 0 | AU28: 0 | AY28: أنثى | AZ28: 0 | BA28: 0 | BE28: أنثى | BF28: 0 | BG28: 0 | BK28: أنثى | BL28: 0 | BM28: 0 | BQ28: أنثى | BR28: 0 | BS28: 0 | BW28: أنثى | BX28: =SUM(D28+J28+P28+V28+AB28+AH28+AN28+AT28+AZ28+BF28+BL28+BR28) -> 0 | BY28: =SUM(E28+K28+Q28+W28+AC28+AI28+AO28+AU28+BA28+BG28+BM28+BS28) -> 0
B29: مجموع السعوديين | D29: =SUM(D27:D28) -> 0 | E29: =SUM(E27:E28) -> 0 | H29: مجموع السعوديين | J29: =SUM(J27:J28) -> 0 | K29: =SUM(K27:K28) -> 0 | N29: مجموع السعوديين | P29: =SUM(P27:P28) -> 0 | Q29: =SUM(Q27:Q28) -> 0 | T29: مجموع السعوديين | V29: =SUM(V27:V28) -> 0 | W29: =SUM(W27:W28) -> 0 | Z29: مجموع السعوديين | AB29: =SUM(AB27:AB28) -> 0 | AC29: =SUM(AC27:AC28) -> 0 | AF29: مجموع السعوديين | AH29: =SUM(AH27:AH28) -> 0 | AI29: =SUM(AI27:AI28) -> 0 | AL29: مجموع السعوديين | AN29: =SUM(AN27:AN28) -> 0 | AO29: =SUM(AO27:AO28) -> 0 | AR29: مجموع السعوديين | AT29: =SUM(AT27:AT28) -> 0 | AU29: =SUM(AU27:AU28) -> 0 | AX29: مجموع السعوديين | AZ29: =SUM(AZ27:AZ28) -> 0 | BA29: =SUM(BA27:BA28) -> 0 | BD29: مجموع السعوديين | BF29: 0 | BG29: 0 | BJ29: مجموع السعوديين | BL29: =SUM(BL27:BL28) -> 0 | BM29: =SUM(BM27:BM28) -> 0 | BP29: مجموع السعوديين | BR29: =SUM(BR27:BR28) -> 0 | BS29: =SUM(BS27:BS28) -> 0 | BV29: مجموع السعوديين | BX29: =SUM(BX27:BX28) -> 0 | BY29: =SUM(BY27:BY28) -> 0
B30: غير سعودي | C30: ذكر | D30: 0 | E30: 0 | H30: غير سعودي | I30: ذكر | J30: 0 | K30: 0 | N30: غير سعودي | O30: ذكر | P30: 0 | Q30: 0 | T30: غير سعودي | U30: ذكر | V30: 0 | W30: 0 | Z30: غير سعودي | AA30: ذكر | AB30: 0 | AC30: 0 | AF30: غير سعودي | AG30: ذكر | AH30: 0 | AI30: 0 | AL30: غير سعودي | AM30: ذكر | AN30: 0 | AO30: 0 | AR30: غير سعودي | AS30: ذكر | AT30: 0 | AU30: 0 | AX30: غير سعودي | AY30: ذكر | AZ30: 0 | BA30: 0 | BD30: غير سعودي | BE30: ذكر | BF30: 0 | BG30: 0 | BJ30: غير سعودي | BK30: ذكر | BL30: 0 | BM30: 0 | BP30: غير سعودي | BQ30: ذكر | BR30: 0 | BS30: 0 | BV30: غير سعودي | BW30: ذكر | BX30: =SUM(D30+J30+P30+V30+AB30+AH30+AN30+AT30+AZ30+BF30+BL30+BR30) -> 0 | BY30: =SUM(E30+K30+Q30+W30+AC30+AI30+AO30+AU30+BA30+BG30+BM30+BS30) -> 0
C31: أنثى | D31: 0 | E31: 0 | I31: أنثى | J31: 0 | K31: 0 | O31: أنثى | P31: 0 | Q31: 0 | U31: أنثى | V31: 0 | W31: 0 | AA31: أنثى | AB31: 0 | AC31: 0 | AG31: أنثى | AH31: 0 | AI31: 0 | AM31: أنثى | AN31: 0 | AO31: 0 | AS31: أنثى | AT31: 0 | AU31: 0 | AY31: أنثى | AZ31: 0 | BA31: 0 | BE31: أنثى | BF31: 0 | BG31: 0 | BK31: أنثى | BL31: 0 | BM31: 0 | BQ31: أنثى | BR31: 0 | BS31: 0 | BW31: أنثى | BX31: =SUM(D31+J31+P31+V31+AB31+AH31+AN31+AT31+AZ31+BF31+BL31+BR31) -> 0 | BY31: =SUM(E31+K31+Q31+W31+AC31+AI31+AO31+AU31+BA31+BG31+BM31+BS31) -> 0
B32: مجمع الغير سعوديين | D32: =SUM(D30:D31) -> 0 | E32: =SUM(E30:E31) -> 0 | H32: مجمع الغير سعوديين | J32: =SUM(J30:J31) -> 0 | K32: =SUM(K30:K31) -> 0 | N32: مجمع الغير سعوديين | P32: =SUM(P30:P31) -> 0 | Q32: =SUM(Q30:Q31) -> 0 | T32: مجمع الغير سعوديين | V32: =SUM(V30:V31) -> 0 | W32: =SUM(W30:W31) -> 0 | Z32: مجمع الغير سعوديين | AB32: =SUM(AB30:AB31) -> 0 | AC32: =SUM(AC30:AC31) -> 0 | AF32: مجمع الغير سعوديين | AH32: =SUM(AH30:AH31) -> 0 | AI32: =SUM(AI30:AI31) -> 0 | AL32: مجمع الغير سعوديين | AN32: =SUM(AN30:AN31) -> 0 | AO32: =SUM(AO30:AO31) -> 0 | AR32: مجمع الغير سعوديين | AT32: =SUM(AT30:AT31) -> 0 | AU32: =SUM(AU30:AU31) -> 0 | AX32: مجمع الغير سعوديين | AZ32: =SUM(AZ30:AZ31) -> 0 | BA32: =SUM(BA30:BA31) -> 0 | BD32: مجمع الغير سعوديين | BF32: 0 | BG32: 0 | BJ32: مجمع الغير سعوديين | BL32: =SUM(BL30:BL31) -> 0 | BM32: =SUM(BM30:BM31) -> 0 | BP32: مجمع الغير سعوديين | BR32: =SUM(BR30:BR31) -> 0 | BS32: =SUM(BS30:BS31) -> 0 | BV32: مجمع الغير سعوديين | BX32: =SUM(BX30:BX31) -> 0 | BY32: =SUM(BY30:BY31) -> 0
B33: المجموع الكلي | D33: =SUM(D29+D32) -> 0 | E33: =SUM(E29+E32) -> 0 | H33: المجموع الكلي | J33: =SUM(J29+J32) -> 0 | K33: =SUM(K29+K32) -> 0 | N33: المجموع الكلي | P33: =SUM(P29+P32) -> 0 | Q33: =SUM(Q29+Q32) -> 0 | T33: المجموع الكلي | V33: =SUM(V29+V32) -> 0 | W33: =SUM(W29+W32) -> 0 | Z33: المجموع الكلي | AB33: =SUM(AB29+AB32) -> 0 | AC33: =SUM(AC29+AC32) -> 0 | AF33: المجموع الكلي | AH33: =SUM(AH29+AH32) -> 0 | AI33: =SUM(AI29+AI32) -> 0 | AL33: المجموع الكلي | AN33: =SUM(AN29+AN32) -> 0 | AO33: =SUM(AO29+AO32) -> 0 | AR33: المجموع الكلي | AT33: =SUM(AT29+AT32) -> 0 | AU33: =SUM(AU29+AU32) -> 0 | AX33: المجموع الكلي | AZ33: =SUM(AZ29+AZ32) -> 0 | BA33: =SUM(BA29+BA32) -> 0 | BD33: المجموع الكلي | BF33: 0 | BG33: 0 | BJ33: المجموع الكلي | BL33: =SUM(BL29+BL32) -> 0 | BM33: =SUM(BM29+BM32) -> 0 | BP33: المجموع الكلي | BR33: =SUM(BR29+BR32) -> 0 | BS33: =SUM(BS29+BS32) -> 0 | BV33: المجموع الكلي | BX33: =SUM(BX29+BX32) -> 0 | BY33: =SUM(BY29+BY32) -> 0
A34: الروابي | B34: سعودي | C34: ذكر | D34: 0 | E34: 0 | G34: الروابي | H34: سعودي | I34: ذكر | J34: 0 | K34: 0 | M34: الروابي | N34: سعودي | O34: ذكر | P34: 0 | Q34: 0 | S34: الروابي | T34: سعودي | U34: ذكر | V34: 0 | W34: 0 | Y34: الروابي | Z34: سعودي | AA34: ذكر | AB34: 0 | AC34: 0 | AE34: الروابي | AF34: سعودي | AG34: ذكر | AH34: 0 | AI34: 0 | AK34: الروابي | AL34: سعودي | AM34: ذكر | AN34: 0 | AO34: 0 | AQ34: الروابي | AR34: سعودي | AS34: ذكر | AT34: 0 | AU34: 0 | AW34: الروابي | AX34: سعودي | AY34: ذكر | AZ34: 0 | BA34: 0 | BC34: الروابي | BD34: سعودي | BE34: ذكر | BF34: 0 | BG34: 0 | BI34: الروابي | BJ34: سعودي | BK34: ذكر | BL34: 0 | BM34: 0 | BO34: الروابي | BP34: سعودي | BQ34: ذكر | BR34: 0 | BS34: 0 | BU34: =BO34 -> الروابي | BV34: سعودي | BW34: ذكر | BX34: =SUM(D34+J34+P34+V34+AB34+AH34+AN34+AT34+AZ34+BF34+BL34+BR34) -> 0 | BY34: =SUM(E34+K34+Q34+W34+AC34+AI34+AO34+AU34+BA34+BG34+BM34+BS34) -> 0
C35: أنثى | D35: 0 | E35: 0 | I35: أنثى | J35: 0 | K35: 0 | O35: أنثى | P35: 0 | Q35: 0 | U35: أنثى | V35: 0 | W35: 0 | AA35: أنثى | AB35: 0 | AC35: 0 | AG35: أنثى | AH35: 0 | AI35: 0 | AM35: أنثى | AN35: 0 | AO35: 0 | AS35: أنثى | AT35: 0 | AU35: 0 | AY35: أنثى | AZ35: 0 | BA35: 0 | BE35: أنثى | BF35: 0 | BG35: 0 | BK35: أنثى | BL35: 0 | BM35: 0 | BQ35: أنثى | BR35: 0 | BS35: 0 | BW35: أنثى | BX35: =SUM(D35+J35+P35+V35+AB35+AH35+AN35+AT35+AZ35+BF35+BL35+BR35) -> 0 | BY35: =SUM(E35+K35+Q35+W35+AC35+AI35+AO35+AU35+BA35+BG35+BM35+BS35) -> 0
B36: مجموع السعوديين | D36: =SUM(D34:D35) -> 0 | E36: =SUM(E34:E35) -> 0 | H36: مجموع السعوديين | J36: =SUM(J34:J35) -> 0 | K36: =SUM(K34:K35) -> 0 | N36: مجموع السعوديين | P36: =SUM(P34:P35) -> 0 | Q36: =SUM(Q34:Q35) -> 0 | T36: مجموع السعوديين | V36: =SUM(V34:V35) -> 0 | W36: =SUM(W34:W35) -> 0 | Z36: مجموع السعوديين | AB36: =SUM(AB34:AB35) -> 0 | AC36: =SUM(AC34:AC35) -> 0 | AF36: مجموع السعوديين | AH36: =SUM(AH34:AH35) -> 0 | AI36: =SUM(AI34:AI35) -> 0 | AL36: مجموع السعوديين | AN36: =SUM(AN34:AN35) -> 0 | AO36: =SUM(AO34:AO35) -> 0 | AR36: مجموع السعوديين | AT36: =SUM(AT34:AT35) -> 0 | AU36: =SUM(AU34:AU35) -> 0 | AX36: مجموع السعوديين | AZ36: =SUM(AZ34:AZ35) -> 0 | BA36: =SUM(BA34:BA35) -> 0 | BD36: مجموع السعوديين | BF36: 0 | BG36: 0 | BJ36: مجموع السعوديين | BL36: =SUM(BL34:BL35) -> 0 | BM36: =SUM(BM34:BM35) -> 0 | BP36: مجموع السعوديين | BR36: =SUM(BR34:BR35) -> 0 | BS36: =SUM(BS34:BS35) -> 0 | BV36: مجموع السعوديين | BX36: =SUM(BX34:BX35) -> 0 | BY36: =SUM(BY34:BY35) -> 0
B37: غير سعودي | C37: ذكر | D37: 0 | E37: 0 | H37: غير سعودي | I37: ذكر | J37: 0 | K37: 0 | N37: غير سعودي | O37: ذكر | P37: 0 | Q37: 0 | T37: غير سعودي | U37: ذكر | V37: 0 | W37: 0 | Z37: غير سعودي | AA37: ذكر | AB37: 0 | AC37: 0 | AF37: غير سعودي | AG37: ذكر | AH37: 0 | AI37: 0 | AL37: غير سعودي | AM37: ذكر | AN37: 0 | AO37: 0 | AR37: غير سعودي | AS37: ذكر | AT37: 0 | AU37: 0 | AX37: غير سعودي | AY37: ذكر | AZ37: 0 | BA37: 0 | BD37: غير سعودي | BE37: ذكر | BF37: 0 | BG37: 0 | BJ37: غير سعودي | BK37: ذكر | BL37: 0 | BM37: 0 | BP37: غير سعودي | BQ37: ذكر | BR37: 0 | BS37: 0 | BV37: غير سعودي | BW37: ذكر | BX37: =SUM(D37+J37+P37+V37+AB37+AH37+AN37+AT37+AZ37+BF37+BL37+BR37) -> 0 | BY37: =SUM(E37+K37+Q37+W37+AC37+AI37+AO37+AU37+BA37+BG37+BM37+BS37) -> 0
C38: أنثى | D38: 0 | E38: 0 | I38: أنثى | J38: 0 | K38: 0 | O38: أنثى | P38: 0 | Q38: 0 | U38: أنثى | V38: 0 | W38: 0 | AA38: أنثى | AB38: 0 | AC38: 0 | AG38: أنثى | AH38: 0 | AI38: 0 | AM38: أنثى | AN38: 0 | AO38: 0 | AS38: أنثى | AT38: 0 | AU38: 0 | AY38: أنثى | AZ38: 0 | BA38: 0 | BE38: أنثى | BF38: 0 | BG38: 0 | BK38: أنثى | BL38: 0 | BM38: 0 | BQ38: أنثى | BR38: 0 | BS38: 0 | BW38: أنثى | BX38: =SUM(D38+J38+P38+V38+AB38+AH38+AN38+AT38+AZ38+BF38+BL38+BR38) -> 0 | BY38: =SUM(E38+K38+Q38+W38+AC38+AI38+AO38+AU38+BA38+BG38+BM38+BS38) -> 0
B39: مجمع الغير سعوديين | D39: =SUM(D37:D38) -> 0 | E39: =SUM(E37:E38) -> 0 | H39: مجمع الغير سعوديين | J39: =SUM(J37:J38) -> 0 | K39: =SUM(K37:K38) -> 0 | N39: مجمع الغير سعوديين | P39: =SUM(P37:P38) -> 0 | Q39: =SUM(Q37:Q38) -> 0 | T39: مجمع الغير سعوديين | V39: =SUM(V37:V38) -> 0 | W39: =SUM(W37:W38) -> 0 | Z39: مجمع الغير سعوديين | AB39: =SUM(AB37:AB38) -> 0 | AC39: =SUM(AC37:AC38) -> 0 | AF39: مجمع الغير سعوديين | AH39: =SUM(AH37:AH38) -> 0 | AI39: =SUM(AI37:AI38) -> 0 | AL39: مجمع الغير سعوديين | AN39: =SUM(AN37:AN38) -> 0 | AO39: =SUM(AO37:AO38) -> 0 | AR39: مجمع الغير سعوديين | AT39: =SUM(AT37:AT38) -> 0 | AU39: =SUM(AU37:AU38) -> 0 | AX39: مجمع الغير سعوديين | AZ39: =SUM(AZ37:AZ38) -> 0 | BA39: =SUM(BA37:BA38) -> 0 | BD39: مجمع الغير سعوديين | BF39: 0 | BG39: 0 | BJ39: مجمع الغير سعوديين | BL39: =SUM(BL37:BL38) -> 0 | BM39: =SUM(BM37:BM38) -> 0 | BP39: مجمع الغير سعوديين | BR39: =SUM(BR37:BR38) -> 0 | BS39: =SUM(BS37:BS38) -> 0 | BV39: مجمع الغير سعوديين | BX39: =SUM(BX37:BX38) -> 0 | BY39: =SUM(BY37:BY38) -> 0
B40: المجموع الكلي | D40: =SUM(D36+D39) -> 0 | E40: =SUM(E36+E39) -> 0 | H40: المجموع الكلي | J40: =SUM(J36+J39) -> 0 | K40: =SUM(K36+K39) -> 0 | N40: المجموع الكلي | P40: =SUM(P36+P39) -> 0 | Q40: =SUM(Q36+Q39) -> 0 | T40: المجموع الكلي | V40: =SUM(V36+V39) -> 0 | W40: =SUM(W36+W39) -> 0 | Z40: المجموع الكلي | AB40: =SUM(AB36+AB39) -> 0 | AC40: =SUM(AC36+AC39) -> 0 | AF40: المجموع الكلي | AH40: =SUM(AH36+AH39) -> 0 | AI40: =SUM(AI36+AI39) -> 0 | AL40: المجموع الكلي | AN40: =SUM(AN36+AN39) -> 0 | AO40: =SUM(AO36+AO39) -> 0 | AR40: المجموع الكلي | AT40: =SUM(AT36+AT39) -> 0 | AU40: =SUM(AU36+AU39) -> 0 | AX40: المجموع الكلي | AZ40: =SUM(AZ36+AZ39) -> 0 | BA40: =SUM(BA36+BA39) -> 0 | BD40: المجموع الكلي | BF40: 0 | BG40: 0 | BJ40: المجموع الكلي | BL40: =SUM(BL36+BL39) -> 0 | BM40: =SUM(BM36+BM39) -> 0 | BP40: المجموع الكلي | BR40: =SUM(BR36+BR39) -> 0 | BS40: =SUM(BS36+BS39) -> 0 | BV40: المجموع الكلي | BX40: =SUM(BX36+BX39) -> 0 | BY40: =SUM(BY36+BY39) -> 0
A41: قويزة | B41: سعودي | C41: ذكر | D41: 18 | E41: 19 | G41: قويزة | H41: سعودي | I41: ذكر | J41: 19 | K41: 22 | M41: قويزة | N41: سعودي | O41: ذكر | P41: 14 | Q41: 17 | S41: قويزة | T41: سعودي | U41: ذكر | V41: 0 | W41: 0 | Y41: قويزة | Z41: سعودي | AA41: ذكر | AB41: 0 | AC41: 0 | AE41: قويزة | AF41: سعودي | AG41: ذكر | AH41: 0 | AI41: 0 | AK41: قويزة | AL41: سعودي | AM41: ذكر | AN41: 0 | AO41: 0 | AQ41: قويزة | AR41: سعودي | AS41: ذكر | AT41: 9 | AU41: 11 | AW41: قويزة | AX41: سعودي | AY41: ذكر | AZ41: 2 | BA41: 2 | BC41: قويزة | BD41: سعودي | BE41: ذكر | BF41: 18 | BG41: 19 | BI41: قويزة | BJ41: سعودي | BK41: ذكر | BL41: 0 | BM41: 0 | BO41: قويزة | BP41: سعودي | BQ41: ذكر | BR41: 0 | BS41: 0 | BU41: =BO41 -> قويزة | BV41: سعودي | BW41: ذكر | BX41: =SUM(D41+J41+P41+V41+AB41+AH41+AN41+AT41+AZ41+BF41+BL41+BR41) -> 80 | BY41: =SUM(E41+K41+Q41+W41+AC41+AI41+AO41+AU41+BA41+BG41+BM41+BS41) -> 90
C42: أنثى | D42: 16 | E42: 19 | I42: أنثى | J42: 16 | K42: 20 | O42: أنثى | P42: 16 | Q42: 19 | U42: أنثى | V42: 0 | W42: 0 | AA42: أنثى | AB42: 0 | AC42: 0 | AG42: أنثى | AH42: 0 | AI42: 0 | AM42: أنثى | AN42: 0 | AO42: 0 | AS42: أنثى | AT42: 11 | AU42: 13 | AY42: أنثى | AZ42: 1 | BA42: 1 | BE42: أنثى | BF42: 16 | BG42: 19 | BK42: أنثى | BL42: 0 | BM42: 0 | BQ42: أنثى | BR42: 0 | BS42: 0 | BW42: أنثى | BX42: =SUM(D42+J42+P42+V42+AB42+AH42+AN42+AT42+AZ42+BF42+BL42+BR42) -> 76 | BY42: =SUM(E42+K42+Q42+W42+AC42+AI42+AO42+AU42+BA42+BG42+BM42+BS42) -> 91
...

Sheet الإجمالي
A1: 13 ـ الأشعة | B1: شهر | C1: 1 | D1: عام | E1: =SUM(الأشعة!E2) -> 1447 | G1: 13 ـ الأشعة | H1: شهر | I1: 2 | J1: عام | K1: =SUM(الأشعة!K2) -> 1447 | M1: 13 ـ الأشعة | N1: شهر | O1: 3 | P1: عام | Q1: =SUM(الأشعة!Q2) -> 1447 | S1: 13 ـ الأشعة | T1: شهر | U1: 4 | V1: عام | W1: =SUM(الأشعة!W2) -> 1447 | Y1: 13 ـ الأشعة | Z1: شهر | AA1: 5 | AB1: عام | AC1: =SUM(الأشعة!AC2) -> 1447 | AE1: 13 ـ الأشعة | AF1: شهر | AG1: 6 | AH1: عام | AI1: =SUM(الأشعة!AI2) -> 1447 | AK1: 13 ـ الأشعة | AL1: شهر | AM1: 7 | AN1: عام | AO1: =SUM(الأشعة!AO2) -> 1447 | AQ1: 13 ـ الأشعة | AR1: شهر | AS1: 8 | AT1: عام | AU1: =SUM(الأشعة!AU2) -> 1447 | AW1: 13 ـ الأشعة | AX1: شهر | AY1: 9 | AZ1: عام | BA1: =SUM(الأشعة!BA2) -> 1447 | BC1: 13 ـ الأشعة | BD1: شهر | BE1: 10 | BF1: عام | BG1: =SUM(الأشعة!BG2) -> 1447 | BI1: 13 ـ الأشعة | BJ1: شهر | BK1: 11 | BL1: عام | BM1: =SUM(الأشعة!BM2) -> 1447 | BO1: 13 ـ الأشعة | BP1: شهر | BQ1: 12 | BR1: عام | BS1: =SUM(الأشعة!BS2) -> 1447 | BU1: 13 ـ الأشعة | BX1: عام | BY1: =SUM(BS1) -> 1447
A3: المركز الصحي | B3: المرضى والأفلام | D3: عدد المراجعين ( المرضى ) | E3: عدد الأفلام | G3: المركز الصحي | H3: المرضى والأفلام | J3: عدد المراجعين ( المرضى ) | K3: عدد الأفلام | M3: المركز الصحي | N3: المرضى والأفلام | P3: عدد المراجعين ( المرضى ) | Q3: عدد الأفلام | S3: المركز الصحي | T3: المرضى والأفلام | V3: عدد المراجعين ( المرضى ) | W3: عدد الأفلام | Y3: المركز الصحي | Z3: المرضى والأفلام | AB3: عدد المراجعين ( المرضى ) | AC3: عدد الأفلام | AE3: المركز الصحي | AF3: المرضى والأفلام | AH3: عدد المراجعين ( المرضى ) | AI3: عدد الأفلام | AK3: المركز الصحي | AL3: المرضى والأفلام | AN3: عدد المراجعين ( المرضى ) | AO3: عدد الأفلام | AQ3: المركز الصحي | AR3: المرضى والأفلام | AT3: عدد المراجعين ( المرضى ) | AU3: عدد الأفلام | AW3: المركز الصحي | AX3: المرضى والأفلام | AZ3: عدد المراجعين ( المرضى ) | BA3: عدد الأفلام | BC3: المركز الصحي | BD3: المرضى والأفلام | BF3: عدد المراجعين ( المرضى ) | BG3: عدد الأفلام | BI3: المركز الصحي | BJ3: المرضى والأفلام | BL3: عدد المراجعين ( المرضى ) | BM3: عدد الأفلام | BO3: المركز الصحي | BP3: المرضى والأفلام | BR3: عدد المراجعين ( المرضى ) | BS3: عدد الأفلام | BU3: المركز الصحي | BV3: المرضى والأفلام | BX3: عدد المراجعين ( المرضى ) | BY3: عدد الأفلام
B4: الجنسية والجنس | H4: الجنسية والجنس | N4: الجنسية والجنس | T4: الجنسية والجنس | Z4: الجنسية والجنس | AF4: الجنسية والجنس | AL4: الجنسية والجنس | AR4: الجنسية والجنس | AX4: الجنسية والجنس | BD4: الجنسية والجنس | BJ4: الجنسية والجنس | BP4: الجنسية والجنس | BV4: الجنسية والجنس
A5: إجمالي مراكز مستشفى شرق جدة | B5: سعودي | C5: ذكر | D5: =SUM(الأشعة!D95) -> 528 | E5: =SUM(الأشعة!E95) -> 19 | G5: إجمالي مراكز مستشفى شرق جدة | H5: سعودي | I5: ذكر | J5: =SUM(الأشعة!J95) -> 892 | K5: =SUM(الأشعة!K95) -> 22 | M5: إجمالي مراكز مستشفى شرق جدة | N5: سعودي | O5: ذكر | P5: =SUM(الأشعة!P95) -> 14 | Q5: =SUM(الأشعة!Q95) -> 17 | S5: إجمالي مراكز مستشفى شرق جدة | T5: سعودي | U5: ذكر | V5: =SUM(الأشعة!V95) -> 0 | W5: =SUM(الأشعة!W95) -> 0 | Y5: إجمالي مراكز مستشفى شرق جدة | Z5: سعودي | AA5: ذكر | AB5: =SUM(الأشعة!AB95) -> 0 | AC5: =SUM(الأشعة!AC95) -> 0 | AE5: إجمالي مراكز مستشفى شرق جدة | AF5: سعودي | AG5: ذكر | AH5: =SUM(الأشعة!AH95) -> 0 | AI5: =SUM(الأشعة!AI95) -> 0 | AK5: إجمالي مراكز مستشفى شرق جدة | AL5: سعودي | AM5: ذكر | AN5: =SUM(الأشعة!AN95) -> 0 | AO5: =SUM(الأشعة!AO95) -> 0 | AQ5: إجمالي مراكز مستشفى شرق جدة | AR5: سعودي | AS5: ذكر | AT5: =SUM(الأشعة!AT95) -> 9 | AU5: =SUM(الأشعة!AU95) -> 11 | AW5: إجمالي مراكز مستشفى شرق جدة | AX5: سعودي | AY5: ذكر | AZ5: =SUM(الأشعة!AZ95) -> 59 | BA5: =SUM(الأشعة!BA95) -> 59 | BC5: إجمالي مراكز مستشفى شرق جدة | BD5: سعودي | BE5: ذكر | BF5: =SUM(الأشعة!BF95) -> 528 | BG5: =SUM(الأشعة!BG95) -> 19 | BI5: إجمالي مراكز مستشفى شرق جدة | BJ5: سعودي | BK5: ذكر | BL5: =SUM(الأشعة!BL95) -> 0 | BM5: =SUM(الأشعة!BM95) -> 0 | BO5: إجمالي مراكز مستشفى شرق جدة | BP5: سعودي | BQ5: ذكر | BR5: =SUM(الأشعة!BR95) -> 0 | BS5: =SUM(الأشعة!BS95) -> 0 | BU5: إجمالي مراكز مستشفى شرق جدة | BV5: سعودي | BW5: ذكر | BX5: =SUM(الأشعة!BX95) -> 2030 | BY5: =SUM(الأشعة!BY95) -> 147
C6: أنثى | D6: =SUM(الأشعة!D96) -> 461 | E6: =SUM(الأشعة!E96) -> 19 | I6: أنثى | J6: =SUM(الأشعة!J96) -> 254 | K6: =SUM(الأشعة!K96) -> 20 | O6: أنثى | P6: =SUM(الأشعة!P96) -> 16 | Q6: =SUM(الأشعة!Q96) -> 19 | U6: أنثى | V6: =SUM(الأشعة!V96) -> 0 | W6: =SUM(الأشعة!W96) -> 0 | AA6: أنثى | AB6: =SUM(الأشعة!AB96) -> 0 | AC6: =SUM(الأشعة!AC96) -> 0 | AG6: أنثى | AH6: =SUM(الأشعة!AH96) -> 0 | AI6: =SUM(الأشعة!AI96) -> 0 | AM6: أنثى | AN6: =SUM(الأشعة!AN96) -> 0 | AO6: =SUM(الأشعة!AO96) -> 0 | AS6: أنثى | AT6: =SUM(الأشعة!AT96) -> 11 | AU6: =SUM(الأشعة!AU96) -> 13 | AY6: أنثى | AZ6: =SUM(الأشعة!AZ96) -> 75 | BA6: =SUM(الأشعة!BA96) -> 75 | BE6: أنثى | BF6: =SUM(الأشعة!BF96) -> 461 | BG6: =SUM(الأشعة!BG96) -> 19 | BK6: أنثى | BL6: =SUM(الأشعة!BL96) -> 0 | BM6: =SUM(الأشعة!BM96) -> 0 | BQ6: أنثى | BR6: =SUM(الأشعة!BR96) -> 0 | BS6: =SUM(الأشعة!BS96) -> 0 | BW6: أنثى | BX6: =SUM(الأشعة!BX96) -> 1278 | BY6: =SUM(الأشعة!BY96) -> 165
B7: مجموع السعوديين | D7: =SUM(D5:D6) -> 989 | E7: =SUM(E5:E6) -> 38 | H7: مجموع السعوديين | J7: =SUM(J5:J6) -> 1146 | K7: =SUM(K5:K6) -> 42 | N7: مجموع السعوديين | P7: =SUM(P5:P6) -> 30 | Q7: =SUM(Q5:Q6) -> 36 | T7: مجموع السعوديين | V7: =SUM(V5:V6) -> 0 | W7: =SUM(W5:W6) -> 0 | Z7: مجموع السعوديين | AB7: =SUM(AB5:AB6) -> 0 | AC7: =SUM(AC5:AC6) -> 0 | AF7: مجموع السعوديين | AH7: =SUM(AH5:AH6) -> 0 | AI7: =SUM(AI5:AI6) -> 0 | AL7: مجموع السعوديين | AN7: =SUM(AN5:AN6) -> 0 | AO7: =SUM(AO5:AO6) -> 0 | AR7: مجموع السعوديين | AT7: =SUM(AT5:AT6) -> 20 | AU7: =SUM(AU5:AU6) -> 24 | AX7: مجموع السعوديين | AZ7: =SUM(AZ5:AZ6) -> 134 | BA7: =SUM(BA5:BA6) -> 134 | BD7: مجموع السعوديين | BF7: =SUM(BF5:BF6) -> 989 | BG7: =SUM(BG5:BG6) -> 38 | BJ7: مجموع السعوديين | BL7: =SUM(BL5:BL6) -> 0 | BM7: =SUM(BM5:BM6) -> 0 | BP7: مجموع السعوديين | BR7: =SUM(BR5:BR6) -> 0 | BS7: =SUM(BS5:BS6) -> 0 | BV7: مجموع السعوديين | BX7: =SUM(BX5:BX6) -> 3308 | BY7: =SUM(BY5:BY6) -> 312
B8: غير سعودي | C8: ذكر | D8: =SUM(الأشعة!D98) -> 10 | E8: =SUM(الأشعة!E98) -> 0 | H8: غير سعودي | I8: ذكر | J8: =SUM(الأشعة!J98) -> 54 | K8: =SUM(الأشعة!K98) -> 0 | N8: غير سعودي | O8: ذكر | P8: =SUM(الأشعة!P98) -> 0 | Q8: =SUM(الأشعة!Q98) -> 0 | T8: غير سعودي | U8: ذكر | V8: =SUM(الأشعة!V98) -> 0 | W8: =SUM(الأشعة!W98) -> 0 | Z8: غير سعودي | AA8: ذكر | AB8: =SUM(الأشعة!AB98) -> 0 | AC8: =SUM(الأشعة!AC98) -> 0 | AF8: غير سعودي | AG8: ذكر | AH8: =SUM(الأشعة!AH98) -> 0 | AI8: =SUM(الأشعة!AI98) -> 0 | AL8: غير سعودي | AM8: ذكر | AN8: =SUM(الأشعة!AN98) -> 0 | AO8: =SUM(الأشعة!AO98) -> 0 | AR8: غير سعودي | AS8: ذكر | AT8: =SUM(الأشعة!AT98) -> 0 | AU8: =SUM(الأشعة!AU98) -> 0 | AX8: غير سعودي | AY8: ذكر | AZ8: =SUM(الأشعة!AZ98) -> 15 | BA8: =SUM(الأشعة!BA98) -> 15 | BD8: غير سعودي | BE8: ذكر | BF8: =SUM(الأشعة!BF98) -> 10 | BG8: =SUM(الأشعة!BG98) -> 0 | BJ8: غير سعودي | BK8: ذكر | BL8: =SUM(الأشعة!BL98) -> 0 | BM8: =SUM(الأشعة!BM98) -> 0 | BP8: غير سعودي | BQ8: ذكر | BR8: =SUM(الأشعة!BR98) -> 0 | BS8: =SUM(الأشعة!BS98) -> 0 | BV8: غير سعودي | BW8: ذكر | BX8: =SUM(الأشعة!BX98) -> 89 | BY8: =SUM(الأشعة!BY98) -> 15
C9: أنثى | D9: =SUM(الأشعة!D99) -> 9 | E9: =SUM(الأشعة!E99) -> 0 | I9: أنثى | J9: =SUM(الأشعة!J99) -> 18 | K9: =SUM(الأشعة!K99) -> 0 | O9: أنثى | P9: =SUM(الأشعة!P99) -> 0 | Q9: =SUM(الأشعة!Q99) -> 0 | U9: أنثى | V9: =SUM(الأشعة!V99) -> 0 | W9: =SUM(الأشعة!W99) -> 0 | AA9: أنثى | AB9: =SUM(الأشعة!AB99) -> 0 | AC9: =SUM(الأشعة!AC99) -> 0 | AG9: أنثى | AH9: =SUM(الأشعة!AH99) -> 0 | AI9: =SUM(الأشعة!AI99) -> 0 | AM9: أنثى | AN9: =SUM(الأشعة!AN99) -> 0 | AO9: =SUM(الأشعة!AO99) -> 0 | AS9: أنثى | AT9: =SUM(الأشعة!AT99) -> 0 | AU9: =SUM(الأشعة!AU99) -> 0 | AY9: أنثى | AZ9: =SUM(الأشعة!AZ99) -> 11 | BA9: =SUM(الأشعة!BA99) -> 11 | BE9: أنثى | BF9: =SUM(الأشعة!BF99) -> 9 | BG9: =SUM(الأشعة!BG99) -> 0 | BK9: أنثى | BL9: =SUM(الأشعة!BL99) -> 0 | BM9: =SUM(الأشعة!BM99) -> 0 | BQ9: أنثى | BR9: =SUM(الأشعة!BR99) -> 0 | BS9: =SUM(الأشعة!BS99) -> 0 | BW9: أنثى | BX9: =SUM(الأشعة!BX99) -> 47 | BY9: =SUM(الأشعة!BY99) -> 11
B10: مجموع غ.سعوديين | D10: =SUM(D8:D9) -> 19 | E10: =SUM(E8:E9) -> 0 | H10: مجموع غ.سعوديين | J10: =SUM(J8:J9) -> 72 | K10: =SUM(K8:K9) -> 0 | N10: مجموع غ.سعوديين | P10: =SUM(P8:P9) -> 0 | Q10: =SUM(Q8:Q9) -> 0 | T10: مجموع غ.سعوديين | V10: =SUM(V8:V9) -> 0 | W10: =SUM(W8:W9) -> 0 | Z10: مجموع غ.سعوديين | AB10: =SUM(AB8:AB9) -> 0 | AC10: =SUM(AC8:AC9) -> 0 | AF10: مجموع غ.سعوديين | AH10: =SUM(AH8:AH9) -> 0 | AI10: =SUM(AI8:AI9) -> 0 | AL10: مجموع غ.سعوديين | AN10: =SUM(AN8:AN9) -> 0 | AO10: =SUM(AO8:AO9) -> 0 | AR10: مجموع غ.سعوديين | AT10: =SUM(AT8:AT9) -> 0 | AU10: =SUM(AU8:AU9) -> 0 | AX10: مجموع غ.سعوديين | AZ10: =SUM(AZ8:AZ9) -> 26 | BA10: =SUM(BA8:BA9) -> 26 | BD10: مجموع غ.سعوديين | BF10: =SUM(BF8:BF9) -> 19 | BG10: =SUM(BG8:BG9) -> 0 | BJ10: مجموع غ.سعوديين | BL10: =SUM(BL8:BL9) -> 0 | BM10: =SUM(BM8:BM9) -> 0 | BP10: مجموع غ.سعوديين | BR10: =SUM(BR8:BR9) -> 0 | BS10: =SUM(BS8:BS9) -> 0 | BV10: مجموع غ.سعوديين | BX10: =SUM(BX8:BX9) -> 136 | BY10: =SUM(BY8:BY9) -> 26
B11: المجموع الكلي | D11: =SUM(D7+D10) -> 1008 | E11: =SUM(E7+E10) -> 38 | H11: المجموع الكلي | J11: =SUM(J7+J10) -> 1218 | K11: =SUM(K7+K10) -> 42 | N11: المجموع الكلي | P11: =SUM(P7+P10) -> 30 | Q11: =SUM(Q7+Q10) -> 36 | T11: المجموع الكلي | V11: =SUM(V7+V10) -> 0 | W11: =SUM(W7+W10) -> 0 | Z11: المجموع الكلي | AB11: =SUM(AB7+AB10) -> 0 | AC11: =SUM(AC7+AC10) -> 0 | AF11: المجموع الكلي | AH11: =SUM(AH7+AH10) -> 0 | AI11: =SUM(AI7+AI10) -> 0 | AL11: المجموع الكلي | AN11: =SUM(AN7+AN10) -> 0 | AO11: =SUM(AO7+AO10) -> 0 | AR11: المجموع الكلي | AT11: =SUM(AT7+AT10) -> 20 | AU11: =SUM(AU7+AU10) -> 24 | AX11: المجموع الكلي | AZ11: =SUM(AZ7+AZ10) -> 160 | BA11: =SUM(BA7+BA10) -> 160 | BD11: المجموع الكلي | BF11: =SUM(BF7+BF10) -> 1008 | BG11: =SUM(BG7+BG10) -> 38 | BJ11: المجموع الكلي | BL11: =SUM(BL7+BL10) -> 0 | BM11: =SUM(BM7+BM10) -> 0 | BP11: المجموع الكلي | BR11: =SUM(BR7+BR10) -> 0 | BS11: =SUM(BS7+BS10) -> 0 | BV11: المجموع الكلي | BX11: =SUM(BX7+BX10) -> 3444 | BY11: =SUM(BY7+BY10) -> 338
A13: محمد الزهراني | G13: محمد الزهراني | M13: محمد الزهراني | S13: محمد الزهراني | Y13: محمد الزهراني | AE13: محمد الزهراني | AK13: محمد الزهراني | AQ13: محمد الزهراني | AW13: محمد الزهراني | BC13: محمد الزهراني | BI13: محمد الزهراني | BO13: محمد الزهراني | BU13: محمد الزهراني
